Workbook
Name _CC2: [1]Sucs!$L$6
Name CC: [2]Sucs!$L$6
Name CM: [3]BGA!$H$9
Name CU: [2]Sucs!$L$5
Name IP: [2]Sucs!$L$4
Name Ll: [2]Sucs!$L$3
Name MORA: [3]BGA!$H$13
Name N_10: [2]Sucs!$C$5
Name N_200: [2]Sucs!$C$3
Name N_40: [2]Sucs!$C$4
Name TABLA: #REF!

Sheet FORMATO
U4: CLIENTE
U5: DIRECCIÓN **
U6: PROYECTO **
A7: LABORATORIO DE ENSAYO DE MATERIALES | U7: UBICACIÓN **
A8: FORMATO N° F-LEM-P-AG-34.01
U9: RECEPCIÓN N°
D10: MUESTRA | G10: No OT | J10: FECHA ENSAYO | M10: REALIZADO | U10: F. EMISIÓN
U11: OT N°
U13: CÓDIGO DE LA MUESTRA
A14: STANDARD TEST METHOD FOR FLAT PARTICLES, ELONGATED PARTICLES, OR FLAT AND ELONGATED PARTICLES IN COARSE AGGREGATE | U14: FECHA DE RECEPCIÓN
A15: ASTM D4791-19 (Reapproved 2023) | U15: FECHA DE EJECUCIÓN
E17: Método de ensayo: | I17: Tamiz requerido | U17: CANTERA/SONDAJE **
E18: Método A | I18: 3/8 in. | U18: N° MUESTRA **
C19: X | E19: Método B | I19: No. 4 | U19: TIPO DE MUESTRA**
E20: El método A esta destinado para todas las aplicaciones, el método B se realizara a solicitud del cliente (Superpave)
B21: Tamaño de las partículas | D21: Gradación de la muestra (1) - ASTM C136 | I21: Reducción de la mustra de prueba
D22: Muestra original
B23: Abertura Tamiz | D23: Masa Retenido original (g) | F23: (%) Retenido | H23: Criterio Acept. ≥10% (*) | I23: Número Partículas (Aprox. 100) | K23: Masa retenido (g)
B25: Pasa Tamiz | C25: Retenido Tamiz | N25: TMN | P25: Masa mín. (g)
B26: 2 in. | C26: 1 1/2 in. | F26: 4.2455 | N26: 2 in. | P26: 20000
B27: 1 1/2 in. | C27: 1 in. | F27: 18.4156 | N27: 1 1/2 in. | P27: 15000
B28: 1 in. | C28: 3/4 in. | F28: 12.4611 | N28: 1 in. | P28: 10000
B29: 3/4 in. | C29: 1/2 in. | F29: 21.0218 | N29: 3/4 in. | P29: 5000
B30: 1/2 in. | C30: 3/8 in. | F30: 12.2151 | N30: 1/2 in. | P30: 2000
B31: 3/8 in. | C31: No. 4 | F31: 31.6409 | N31: 3/8 in. | P31: 1000
B32: TOTAL | F32: 100 | N32: No. 4 | P32: 1000
B33: (*) Marcar con una Check o Aspa , aquellas mallas a evaluar o descartar; (1)Se realizará de no tener granulometría.
B35: Método A
K36: Método B
B37: Retenido Tamiz | C37: Partículas Planas Grupo 1 Ancho - espesor | G37: Partículas Alargadas Grupo 2 Largo - ancho | K37: Particulas que cumplen los criterios tanto del Grupo 1 como del Grupo 2 Grupo 3 | O37: Partículas Ni Planas Ni Alargadas Grupo 4
C38: Número Partículas | E38: Masa (g) | G38: Número Partículas | I38: Masa (g) | K38: Número Partículas | M38: Masa (g) | O38: Número Partículas | Q38: Masa (g)
B39: 1 1/2 in.
B40: 1 in.
B41: 3/4 in.
B42: 1/2 in.
B43: 3/8 in.
B44: No. 4
B45: Nota: Para el método A: Cumple el criterio del grupo 1 y Grupo 2; Método B: Partículas en la relación de Longitud - Espesor
B47: Codigo equipos utilizados | D47: Dispositivo de calibre proporcional | K47: Balanza 0.1 g
D48: Horno
...

Sheet PLA. Y ALAR.
A2: LABORATORIO DE ENSAYO DE MATERIALES
A3: 1
A5: CLIENTE : | B5: : | C5: =+FORMATO!V4 | K5: CÓDIGO | L5: : | M5: F-LEM-P-AG-34.02
A6: DIRECCIÓN ** : | B6: : | C6: =+FORMATO!V5 | K6: RECEPCIÓN N° | L6: : | M6: =+FORMATO!V9
A7: PROYECTO ** : | B7: : | C7: =+FORMATO!V6 | K7: OT N° | L7: : | M7: =+FORMATO!V11
A8: UBICACIÓN ** : | B8: : | C8: =+FORMATO!V7 | K8: F. EMISIÓN | L8: : | M8: =+FORMATO!V10
A9: ** Datos proporcionados por el cliente
A10: Standard Test Method for Flat Particles, Elongated Particles, or Flat and Elongated Particles in Coarse Aggregate
A11: ASTM D4791-19 (Reapproved 2023)
A13: DATOS DE LA MUESTRA
A14: CANTERA/SONDAJE ** | D14: : | E14: =+FORMATO!V17 | K14: CÓDIGO DE LA MUESTRA | L14: : | M14: =+FORMATO!V13
A15: N° MUESTRA ** | D15: : | E15: =+FORMATO!V18 | K15: FECHA DE RECEPCIÓN | L15: : | M15: =+FORMATO!V14
A16: TIPO DE MUESTRA** | D16: : | E16: =+FORMATO!V19 | K16: FECHA DE EJECUCIÓN | L16: : | M16: =+FORMATO!V15
A17: LUGAR DE ENSAYO | D17: : | E17: LABORATORIO DE ENSAYO DE MATERIALES
A19: Tamaño de partículas | B19: Clasif. Muestra original | E19: Muestra de prueba | F19: Grupo 1 - Particulas Planas | H19: Grupo 2 - Partículas Alargadas | J19: Grupo 3 - Particulas que cumplen los criterios tanto del Grupo 1 como del Grupo 2 | L19: Grupo 4 - Particulas Ni Planas Ni Alargadas
F21: (%) en Masa | G21: PROMEDIO (%) Masa | H21: (%) en Masa | I21: PROMEDIO (%) Masa | J21: (%) en Masa | K21: PROMEDIO (%) Masa | L21: (%) en Masa | N21: PROMEDIO (%) Masa
B22: (%) Retenido | E22: Cant. Partic. (und)
A23: 1 1/2 in. | B23: =+IF(DATOS!E12=0,"--",DATOS!E12) | E23: =IF(DATOS!E12=0,"--",DATOS!F12) | F23: =+IF(DATOS!$F$5="B","--",IF(DATOS!G12=0,"--",IF(DATOS!E12<10,"--",DATOS!M12/DATOS!H12)*100)) | G23: =+IF(DATOS!$F$5="B","--",IF(DATOS!G12=0,"--",IF(DATOS!E12<10,"--",DATOS!N12*DATOS!E12/100))) | H23: =+IF(DATOS!$F$5="B","--",IF(DATOS!G12=0,"--",IF(DATOS!E12<10,"--",(DATOS!R12/DATOS!H12)*100))) | I23: =+IF(DATOS!$F$5="B","--",IF(DATOS!G12=0,"--",IF(DATOS!E12<10,"--",DATOS!S12*DATOS!E12/100))) | J23: =+IF(DATOS!G12=0,"--",IF(DATOS!E12<10,"--",DATOS!W12/DATOS!H12*100)) | K23: =+IF(DATOS!G12=0,"--",IF(DATOS!E12<10,"--",DATOS!X12/DATOS!E12/100)) | L23: =+IF(DATOS!G12=0,"--",IF(DATOS!E12<10,"--",(DATOS!AA12/DATOS!H12)*100)) | N23: =+IF(DATOS!G12=0,"--",DATOS!AB12*DATOS!E12/100)
A24: 1 in. | B24: =+IF(DATOS!E13=0,"--",DATOS!E13) | E24: =IF(DATOS!E13=0,"--",DATOS!F13) | F24: =+IF(DATOS!$F$5="B","--",IF(DATOS!G13=0,"--",IF(DATOS!E13<10,"--",DATOS!M13/DATOS!H13)*100)) | G24: =+IF(DATOS!$F$5="B","--",IF(DATOS!G13=0,"--",IF(DATOS!E13<10,"--",DATOS!N13*DATOS!E13/100))) | H24: =+IF(DATOS!$F$5="B","--",IF(DATOS!G13=0,"--",IF(DATOS!E13<10,"--",(DATOS!R13/DATOS!H13)*100))) | I24: =+IF(DATOS!$F$5="B","--",IF(DATOS!G13=0,"--",IF(DATOS!E13<10,"--",DATOS!S13*DATOS!E13/100))) | J24: =+IF(DATOS!G13=0,"--",IF(DATOS!E13<10,"--",DATOS!W13/DATOS!H13*100)) | K24: =+IF(DATOS!G13=0,"--",IF(DATOS!E13<10,"--",DATOS!X13/DATOS!E13/100)) | L24: =+IF(DATOS!G13=0,"--",IF(DATOS!E13<10,"--",(DATOS!AA13/DATOS!H13)*100)) | N24: =+IF(DATOS!G13=0,"--",DATOS!AB13*DATOS!E13/100)
A25: 3/4 in. | B25: =+IF(DATOS!E14=0,"--",DATOS!E14) | E25: =IF(DATOS!E14=0,"--",DATOS!F14) | F25: =+IF(DATOS!$F$5="B","--",IF(DATOS!G14=0,"--",IF(DATOS!E14<10,"--",DATOS!M14/DATOS!H14)*100)) | G25: =+IF(DATOS!$F$5="B","--",IF(DATOS!G14=0,"--",IF(DATOS!E14<10,"--",DATOS!N14*DATOS!E14/100))) | H25: =+IF(DATOS!$F$5="B","--",IF(DATOS!G14=0,"--",IF(DATOS!E14<10,"--",(DATOS!R14/DATOS!H14)*100))) | I25: =+IF(DATOS!$F$5="B","--",IF(DATOS!G14=0,"--",IF(DATOS!E14<10,"--",DATOS!S14*DATOS!E14/100))) | J25: =+IF(DATOS!G14=0,"--",IF(DATOS!E14<10,"--",DATOS!W14/DATOS!H14*100)) | K25: =+IF(DATOS!G14=0,"--",IF(DATOS!E14<10,"--",DATOS!X14/DATOS!E14/100)) | L25: =+IF(DATOS!G14=0,"--",IF(DATOS!E14<10,"--",(DATOS!AA14/DATOS!H14)*100)) | N25: =+IF(DATOS!G14=0,"--",DATOS!AB14*DATOS!E14/100)
A26: 1/2 in. | B26: =+IF(DATOS!E15=0,"--",DATOS!E15) | E26: =IF(DATOS!E15=0,"--",DATOS!F15) | F26: =+IF(DATOS!$F$5="B","--",IF(DATOS!G15=0,"--",IF(DATOS!E15<10,"--",DATOS!M15/DATOS!H15)*100)) | G26: =+IF(DATOS!$F$5="B","--",IF(DATOS!G15=0,"--",IF(DATOS!E15<10,"--",DATOS!N15*DATOS!E15/100))) | H26: =+IF(DATOS!$F$5="B","--",IF(DATOS!G15=0,"--",IF(DATOS!E15<10,"--",(DATOS!R15/DATOS!H15)*100))) | I26: =+IF(DATOS!$F$5="B","--",IF(DATOS!G15=0,"--",IF(DATOS!E15<10,"--",DATOS!S15*DATOS!E15/100))) | J26: =+IF(DATOS!G15=0,"--",IF(DATOS!E15<10,"--",DATOS!W15/DATOS!H15*100)) | K26: =+IF(DATOS!G15=0,"--",IF(DATOS!E15<10,"--",DATOS!X15/DATOS!E15/100)) | L26: =+IF(DATOS!G15=0,"--",IF(DATOS!E15<10,"--",(DATOS!AA15/DATOS!H15)*100)) | N26: =+IF(DATOS!G15=0,"--",DATOS!AB15*DATOS!E15/100)
A27: 3/8 in. | B27: =+IF(DATOS!E16=0,"--",DATOS!E16) | E27: =IF(DATOS!E16=0,"--",DATOS!F16) | F27: =+IF(DATOS!$F$5="B","--",IF(DATOS!G16=0,"--",IF(DATOS!E16<10,"--",DATOS!M16/DATOS!H16)*100)) | G27: =+IF(DATOS!$F$5="B","--",IF(DATOS!G16=0,"--",IF(DATOS!E16<10,"--",DATOS!N16*DATOS!E16/100))) | H27: =+IF(DATOS!$F$5="B","--",IF(DATOS!G16=0,"--",IF(DATOS!E16<10,"--",(DATOS!R16/DATOS!H16)*100))) | I27: =+IF(DATOS!$F$5="B","--",IF(DATOS!G16=0,"--",IF(DATOS!E16<10,"--",DATOS!S16*DATOS!E16/100))) | J27: =+IF(DATOS!G16=0,"--",IF(DATOS!E16<10,"--",DATOS!W16/DATOS!H16*100)) | K27: =+IF(DATOS!G16=0,"--",IF(DATOS!E16<10,"--",DATOS!X16/DATOS!E16/100)) | L27: =+IF(DATOS!G16=0,"--",IF(DATOS!E16<10,"--",(DATOS!AA16/DATOS!H16)*100)) | N27: =+IF(DATOS!G16=0,"--",DATOS!AB16*DATOS!E16/100)
A28: No. 4 | B28: =+IF(DATOS!E17=0,"--",DATOS!E17) | E28: =IF(DATOS!E17=0,"--",DATOS!F17) | F28: =+IF(DATOS!$F$5="B","--",IF(DATOS!G17=0,"--",IF(DATOS!E17<10,"--",DATOS!M17/DATOS!H17)*100)) | G28: =+IF(DATOS!$F$5="B","--",IF(DATOS!G17=0,"--",IF(DATOS!E17<10,"--",DATOS!N17*DATOS!E17/100))) | H28: =+IF(DATOS!$F$5="B","--",IF(DATOS!G17=0,"--",IF(DATOS!E17<10,"--",(DATOS!R17/DATOS!H17)*100))) | I28: =+IF(DATOS!$F$5="B","--",IF(DATOS!G17=0,"--",IF(DATOS!E17<10,"--",DATOS!S17*DATOS!E17/100))) | J28: =+IF(DATOS!G17=0,"--",IF(DATOS!E17<10,"--",DATOS!W17/DATOS!H17*100)) | K28: =+IF(DATOS!G17=0,"--",IF(DATOS!E17<10,"--",DATOS!X17/DATOS!E17/100)) | L28: =+IF(DATOS!G17=0,"--",IF(DATOS!E17<10,"--",(DATOS!AA17/DATOS!H17)*100)) | N28: =+IF(DATOS!G17=0,"--",DATOS!AB17*DATOS!E17/100)
A29: TOTAL | B29: =+DATOS!E18 | G29: =+SUM(G23:G28) | I29: =+SUM(I23:I28) | K29: =+SUM(K23:K28) | N29: =+SUM(N23:N28)
A31: Relación Dimensional | G31: =+DATOS!F3
A32: Método de ensayo | G32: =+DATOS!F5
A33: Partículas Planas y Alargadas % masa | G33: =100-N29
A35: Nota :
A36: - Los datos de identificación de la muestra son proporcionados por el cliente.
A37: - Los resultados corresponden sólo a los ensayos realizados sobre la muestra proporcionada por el cliente.
A38: - Los resultados de los ensayos no deben ser utilizados como una certificación de conformidad con normas de productos o como certificado del sistema de calidad de Geofal SAC.
A39: - Prohibida la reproducción total o parcial del presente informe de ensayo sin la autorización escrita de Geofal S.A.C.
A40: - Este informe de ensayo, al estar en el marco de la acreditación del INACAL - DA, se encuentra dentro del ámbito de reconocimiento multilateral/mutuo de los miembros firmantes de IAAC e ILAC.
A42: Observaciones:
A48: Página 1 de 1
A49: Versión: 02 (11-11-2024) | N49: Fin del Informe

Sheet DATOS
B1: Standard Test Method for Flat Particles, Elongated Particles, or Flat and Elongated Particles in Coarse Aggregate
B3: Relación Dimensional | F3: - | I3: Masa inicial | J3: =+FORMATO!N21 | M3: Declaración de equipos: balanza 15kg a 0.1g
B4: Tamiz requerido: | F4: - | I4: Masa seca | J4: =+FORMATO!N22 | M4: N° | N4: CÓDIGO | P4: CORRECCION | R4: FECHA CALIBRAC. | U4: TECNICO | W4: - | Y4: =+FORMATO!M11
B5: Método de ensayo: | F5: - | I5: Masa seca constante | J5: =+FORMATO!N23 | M5: 1 | N5: =+BALANZA!C11 | P5: =+BALANZA!C7 | R5: =+BALANZA!D12
I6: Perdida de masa seca adicional | J6: =+(J4-J5)/J5*100 | K6: =+IF(J6<1,"cumple","no cumple")
B8: Tamaño de las partículas | C8: Gradación de la muestra | K8: Particulas Planas | P8: Partículas Alargadas | U8: Particulas Planas y Alargadas | Z8: Particulas Ni Planas Ni Alargadas
C10: Muestra Original | F10: Reduccion de la muestra de prueba | K10: Cant. | L10: Masa de partículas | N10: Promedio (%) | P10: Cant. | Q10: Masa de partículas | S10: Promedio (%) | U10: Cant. | V10: Masa de partículas | X10: Promedio (%) | Z10: Cant. | AA10: Masa de partículas | AB10: Promedio (%)
B11: Retenido T. | C11: Masa Retenido (g) | D11: Masa Retenido corregido (g) | E11: (%) Retenido | F11: Número Partic. | G11: Masa (g) | H11: Masa corregida (g) | I11: calculo de porcentaje muestra | J11: Criterio de masa minima | L11: Masa (g) | M11: Masa corregida (g) | N11: (%) en Masa | O11: PROMEDIO (%) Masa | Q11: Masa (g) | R11: Masa corregida (g) | S11: (%) en Masa | T11: PROMEDIO (%) Masa | V11: Masa (g) | W11: Masa corregida (g) | X11: (%) en Masa | Y11: PROMEDIO (%) Masa | AA11: Masa corregida (g) | AB11: (%) en Masa | AC11: PROMEDIO (%) Masa
B12: 1 1/2 in | C12: =+FORMATO!D26 | D12: =C12+($P$5*C12) | E12: =IF(D12="","",((D12/$D$18*100))) | F12: =+FORMATO!I26 | G12: =+FORMATO!K26 | H12: =G12+($P$5*G12) | I12: =IF(G12=0,"--",H12/D12) | J12: =IF(G12=0,"--",IF(I12>=10%,"Cumple","No Cumple")) | K12: =+FORMATO!C39 | L12: =+FORMATO!E39 | M12: =L12+($P$5*L12) | N12: =IF(M12=0,0,(M12/H12*100)) | O12: =IF(M12=0,0,(N12*E12/100)) | P12: =+FORMATO!G39 | Q12: =+FORMATO!I39 | R12: =Q12+($P$5*Q12) | S12: =IF(R12=0,0,(R12/H12*100)) | T12: =IF(R12=0,0,(S12*E12/100)) | U12: 0 | V12: 0 | W12: =V12+($P$5*V12) | X12: =IF(W12=0,0,(W12/H12*100)) | Y12: =IF(W12=0,0,(X12*E12/100)) | Z12: =IF(D12="","",((F12-K12-P12-U12))) | AA12: =IF(H12="","",((H12-M12-R12-W12))) | AB12: =IF(AA12=0,0,(AA12/H12*100)) | AC12: =IF(AA12=0,0,(AB12*E12/100))
B13: 1 in | C13: =+FORMATO!D27 | D13: =C13+($P$5*C13) | E13: =IF(D13="","",((D13/$D$18*100))) | F13: =+FORMATO!I27 | G13: =+FORMATO!K27 | H13: =G13+($P$5*G13) | I13: =IF(G13=0,"--",H13/D13) | J13: =IF(G13=0,"--",IF(I13>=10%,"Cumple","No Cumple")) | K13: =+FORMATO!C40 | L13: =+FORMATO!E40 | M13: =L13+($P$5*L13) | N13: =IF(M13=0,0,(M13/H13*100)) | O13: =IF(M13=0,0,(N13*E13/100)) | P13: =+FORMATO!G40 | Q13: =+FORMATO!I40 | R13: =Q13+($P$5*Q13) | S13: =IF(R13=0,0,(R13/H13*100)) | T13: =IF(R13=0,0,(S13*E13/100)) | U13: 0 | V13: 0 | W13: =V13+($P$5*V13) | X13: =IF(W13=0,0,(W13/H13*100)) | Y13: =IF(W13=0,0,(X13*E13/100)) | Z13: =IF(D13="","",((F13-K13-P13-U13))) | AA13: =IF(H13="","",((H13-M13-R13-W13))) | AB13: =IF(AA13=0,0,(AA13/H13*100)) | AC13: =IF(AA13=0,0,(AB13*E13/100))
B14: 3/4 in | C14: =+FORMATO!D28 | D14: =C14+($P$5*C14) | E14: =IF(D14="","",((D14/$D$18*100))) | F14: =+FORMATO!I28 | G14: =+FORMATO!K28 | H14: =G14+($P$5*G14) | I14: =IF(G14=0,"--",H14/D14) | J14: =IF(G14=0,"--",IF(I14>=10%,"Cumple","No Cumple")) | K14: =+FORMATO!C41 | L14: =+FORMATO!E41 | M14: =L14+($P$5*L14) | N14: =IF(M14=0,0,(M14/H14*100)) | O14: =IF(M14=0,0,(N14*E14/100)) | P14: =+FORMATO!G41 | Q14: =+FORMATO!I41 | R14: =Q14+($P$5*Q14) | S14: =IF(R14=0,0,(R14/H14*100)) | T14: =IF(R14=0,0,(S14*E14/100)) | U14: 0 | V14: 0 | W14: =V14+($P$5*V14) | X14: =IF(W14=0,0,(W14/H14*100)) | Y14: =IF(W14=0,0,(X14*E14/100)) | Z14: =IF(D14="","",((F14-K14-P14-U14))) | AA14: =IF(H14="","",((H14-M14-R14-W14))) | AB14: =IF(AA14=0,0,(AA14/H14*100)) | AC14: =IF(AA14=0,0,(AB14*E14/100))
B15: 1/2 in | C15: =+FORMATO!D29 | D15: =C15+($P$5*C15) | E15: =IF(D15="","",((D15/$D$18*100))) | F15: =+FORMATO!I29 | G15: =+FORMATO!K29 | H15: =G15+($P$5*G15) | I15: =IF(G15=0,"--",H15/D15) | J15: =IF(G15=0,"--",IF(I15>=10%,"Cumple","No Cumple")) | K15: =+FORMATO!C42 | L15: =+FORMATO!E42 | M15: =L15+($P$5*L15) | N15: =IF(M15=0,0,(M15/H15*100)) | O15: =IF(M15=0,0,(N15*E15/100)) | P15: =+FORMATO!G42 | Q15: =+FORMATO!I42 | R15: =Q15+($P$5*Q15) | S15: =IF(R15=0,0,(R15/H15*100)) | T15: =IF(R15=0,0,(S15*E15/100)) | U15: 0 | V15: 0 | W15: =V15+($P$5*V15) | X15: =IF(W15=0,0,(W15/H15*100)) | Y15: =IF(W15=0,0,(X15*E15/100)) | Z15: =IF(D15="","",((F15-K15-P15-U15))) | AA15: =IF(H15="","",((H15-M15-R15-W15))) | AB15: =IF(AA15=0,0,(AA15/H15*100)) | AC15: =IF(AA15=0,0,(AB15*E15/100))
B16: 3/8 in | C16: =+FORMATO!D30 | D16: =C16+($P$5*C16) | E16: =IF(D16="","",((D16/$D$18*100))) | F16: =+FORMATO!I30 | G16: =+FORMATO!K30 | H16: =G16+($P$5*G16) | I16: =IF(G16=0,"--",H16/D16) | J16: =IF(G16=0,"--",IF(I16>=10%,"Cumple","No Cumple")) | K16: =+FORMATO!C43 | L16: =+FORMATO!E43 | M16: =L16+($P$5*L16) | N16: =IF(M16=0,0,(M16/H16*100)) | O16: =IF(M16=0,0,(N16*E16/100)) | P16: =+FORMATO!G43 | Q16: =+FORMATO!I43 | R16: =Q16+($P$5*Q16) | S16: =IF(R16=0,0,(R16/H16*100)) | T16: =IF(R16=0,0,(S16*E16/100)) | U16: 0 | V16: 0 | W16: =V16+($P$5*V16) | X16: =IF(W16=0,0,(W16/H16*100)) | Y16: =IF(W16=0,0,(X16*E16/100)) | Z16: =IF(D16="","",((F16-K16-P16-U16))) | AA16: =IF(H16="","",((H16-M16-R16-W16))) | AB16: =IF(AA16=0,0,(AA16/H16*100)) | AC16: =IF(AA16=0,0,(AB16*E16/100))
B17: N°4 | C17: =+FORMATO!D31 | D17: =C17+($P$5*C17) | E17: =IF(D17="","",((D17/$D$18*100))) | F17: =+FORMATO!I31 | G17: =+FORMATO!K31 | H17: =G17+($P$5*G17) | I17: =IF(G17=0,"--",H17/D17) | J17: =IF(G17=0,"--",IF(I17>=10%,"Cumple","No Cumple")) | K17: =+FORMATO!C44 | L17: =+FORMATO!E44 | M17: =L17+($P$5*L17) | N17: =IF(M17=0,0,(M17/H17*100)) | O17: =IF(M17=0,0,(N17*E17/100)) | P17: =+FORMATO!G44 | Q17: =+FORMATO!I44 | R17: =Q17+($P$5*Q17) | S17: =IF(R17=0,0,(R17/H17*100)) | T17: =IF(R17=0,0,(S17*E17/100)) | U17: 0 | V17: 0 | W17: =V17+($P$5*V17) | X17: =IF(W17=0,0,(W17/H17*100)) | Y17: =IF(W17=0,0,(X17*E17/100)) | Z17: =IF(D17="","",((F17-K17-P17-U17))) | AA17: =IF(H17="","",((H17-M17-R17-W17))) | AB17: =IF(AA17=0,0,(AA17/H17*100)) | AC17: =IF(AA17=0,0,(AB17*E17/100))
B18: TOTAL | D18: =SUM(D12:D17) | E18: =SUM(E12:E17) | F18: =SUM(F12:F17) | H18: =SUM(H12:H17) | O18: =SUM(O12:O17) | T18: =SUM(T12:T17) | Y18: =SUM(Y12:Y17) | AC18: =SUM(AC12:AC17) | AD18: =+O18+T18+Y18+AC18
B19: TMN | D19: =+IF(AND(COUNTA(E12)=1,E12>5),B12,IF(AND(COUNTA(E13)=1,E13>5),B13,IF(AND(COUNTA(E14)=1,E14>5),B14,IF(AND(COUNTA(E15)=1,E15>5),B15,IF(AND(COUNTA(E16)=1,E16>5),B16,IF(AND(COUNTA(E17)=1,E17>5),B17))))))
B20: Cant mín. masa | D20: =+IF(D19="1 1/2 in",15000,IF(D19="1 in",10000,IF(D19="3/4 in",5000,IF(D19="1/2 in",2000,IF(D19="3/8 in",1000,1000))))) | E20: =+IF(D18>=D20,"Cumple","No Cumple")
B21: En la COLUMNA F, el numero de particulas tiene que ser aproximadamente 100 und
B22: En la COLUMNA E, cuando el porcentaje retenido es menos del 10% la masa retenida sera igual a cero

Sheet INCERTIDUMBRE
D1: INFORME DE ESTIMACIÓN DE INCERTIDUMBRE | J1: Código: | K1: F-LEM-P-10.01
J2: Versión: | K2: 3
J3: Fecha: | K3: 46146
J4: Página: | K4: 1 de 1
B6: Método: | C6: Standard Test Method for Flat Particles, Elongated Particles, or Flat and Elongated Particles in Coarse Aggregate
B7: Norma: | C7: ASTM D4791-19 (Reapproved 2023)
B8: Matriz: | C8: Agregados
B9: Mensurando | C9: Determinación de los porcentajes de partículas planas, partículas alargadas o partículas planas y alargadas en agregados gruesos
B11: Paso 1. Definición del proceso de medición | H11: Paso 2. Definición de las variables aleatorias
B13: Variables: | E13: Fórmula:
B15: A = Masa de la partícula
B16: B= Masa retenida
B17: C= Masa prueba
B18: D= Masa total
B20: Equipos a utilizar:
B22: Balanza con resolución de lectura de 0.1g
B24: CÁLCULO: PORCENTAJE DE PARTICULAS PLANAS
B25: Tamaño de tamiz 1 1/2 | J25: Tamaño de tamiz 1 | O25: Tamaño de tamiz 3/4 | T25: Tamaño de tamiz 1/2 | Y25: Tamaño de tamiz 3/8 | AD25: Tamaño de tamiz No 4 | AJ25: CONTRIBUCION
B26: Fuentes | C26: Unidades | D26: Distribución | E26: Valor | F26: Incertidumbre Original | G26: Incertidumbre Estándar u(xi) | H26: Coeficiente de Sensibilidad | I26: Contribución ui(y) | J26: Valor | K26: Incertidumbre Original | L26: Incertidumbre Estándar u(xi) | M26: Coeficiente de Sensibilidad | N26: Contribución ui(y) | O26: Valor | P26: Incertidumbre Original | Q26: Incertidumbre Estándar u(xi) | R26: Coeficiente de Sensibilidad | S26: Contribución ui(y) | T26: Valor | U26: Incertidumbre Original | V26: Incertidumbre Estándar u(xi) | W26: Coeficiente de Sensibilidad | X26: Contribución ui(y) | Y26: Valor | Z26: Incertidumbre Original | AA26: Incertidumbre Estándar u(xi) | AB26: Coeficiente de Sensibilidad | AC26: Contribución ui(y) | AD26: Valor | AE26: Incertidumbre Original | AF26: Incertidumbre Estándar u(xi) | AG26: Coeficiente de Sensibilidad | AH26: Contribución ui(y) | AJ26: Factor de influencia | AK26: valor | AL26: %
D27: --- | E27: =IF(E28=0,"--",(E28*E36*100*1/E32/E40)) | F27: --- | G27: --- | H27: --- | I27: --- | J27: =IF(J28=0,"--",(J28*J36*100*1/J32/J40)) | K27: --- | L27: --- | M27: --- | N27: --- | O27: =IF(O28=0,"--",(O28*O36*100*1/O32/O40)) | P27: --- | Q27: --- | R27: --- | S27: --- | T27: =IF(T28=0,"--",(T28*T36*100*1/T32/T40)) | U27: --- | V27: --- | W27: --- | X27: --- | Y27: =IF(Y28=0,"--",(Y28*Y36*100*1/Y32/Y40)) | Z27: --- | AA27: --- | AB27: --- | AC27: --- | AD27: =IF(AD28=0,"--",(AD28*AD36*100*1/AD32/AD40)) | AE27: --- | AF27: --- | AG27: --- | AH27: --- | AJ27: =+B28 | AK27: =+N28 | AL27: =+AK27/$AK$32
A28: A | B28: Masa partícula | C28: g | D28: --- | E28: =+DATOS!M12 | F28: --- | G28: =SQRT((G29*G29)+(G30*G30)+(G31*G31)) | H28: =IF(E28=0,0,E36*100/E32/E40) | I28: =+H28*G28 | J28: =+DATOS!M13 | K28: --- | L28: =SQRT((L29*L29)+(L30*L30)+(L31*L31)) | M28: =IF(J28=0,0,J36*100/J32/J40) | N28: =+M28*L28 | O28: =+DATOS!M14 | P28: --- | Q28: =SQRT((Q29*Q29)+(Q30*Q30)+(Q31*Q31)) | R28: =IF(O28=0,0,O36*100/O32/O40) | S28: =+R28*Q28 | T28: =+DATOS!M15 | U28: --- | V28: =SQRT((V29*V29)+(V30*V30)+(V31*V31)) | W28: =IF(T28=0,0,T36*100/T32/T40) | X28: =+W28*V28 | Y28: =+DATOS!M16 | Z28: --- | AA28: =SQRT((AA29*AA29)+(AA30*AA30)+(AA31*AA31)) | AB28: =IF(Y28=0,0,Y36*100/Y32/Y40) | AC28: =+AB28*AA28 | AD28: =+DATOS!M17 | AE28: --- | AF28: =SQRT((AF29*AF29)+(AF30*AF30)+(AF31*AF31)) | AG28: =IF(AD28=0,0,AD36*100/AD32/AD40) | AH28: =+AG28*AF28 | AJ28: =+B32 | AK28: =+N32 | AL28: =+AK28/$AK$32
B29: Repetibilidad de la pesada | C29: g | D29: Normal, K=1 | F29: =+BALANZA!D24 | G29: =+F29 | H29: --- | I29: --- | K29: =+BALANZA!D25 | L29: =+K29 | M29: --- | N29: --- | P29: =+BALANZA!D26 | Q29: =+P29 | R29: --- | S29: --- | U29: =+BALANZA!D27 | V29: =+U29 | W29: --- | X29: --- | Z29: =+BALANZA!D28 | AA29: =+Z29 | AB29: --- | AC29: --- | AE29: =+BALANZA!D29 | AF29: =+AE29 | AG29: --- | AH29: --- | AJ29: =+B36 | AK29: =+N36 | AL29: =+AK29/$AK$32
B30: Certificado de Calibración | C30: g | D30: Normal, K=2 | F30: =2*(SQRT(BALANZA!$C$8+BALANZA!$D$8*(POWER(E28,2)))) | G30: =+F30/2 | H30: --- | I30: --- | K30: =2*(SQRT(BALANZA!$C$8+BALANZA!$D$8*(POWER(J28,2)))) | L30: =+K30/2 | M30: --- | N30: --- | P30: =2*(SQRT(BALANZA!$C$8+BALANZA!$D$8*(POWER(O28,2)))) | Q30: =+P30/2 | R30: --- | S30: --- | U30: =2*(SQRT(BALANZA!$C$8+BALANZA!$D$8*(POWER(T28,2)))) | V30: =+U30/2 | W30: --- | X30: --- | Z30: =2*(SQRT(BALANZA!$C$8+BALANZA!$D$8*(POWER(Y28,2)))) | AA30: =+Z30/2 | AB30: --- | AC30: --- | AE30: =2*(SQRT(BALANZA!$C$8+BALANZA!$D$8*(POWER(AD28,2)))) | AF30: =+AE30/2 | AG30: --- | AH30: --- | AJ30: =+B40 | AK30: =+N40 | AL30: =+AK30/$AK$32
B31: Resolución | C31: g | D31: Rectangular | F31: =+BALANZA!$C$10 | G31: =+F31/SQRT(3)/2 | H31: --- | I31: --- | K31: =+BALANZA!$C$10 | L31: =+K31/SQRT(3)/2 | M31: --- | N31: --- | P31: =+BALANZA!$C$10 | Q31: =+P31/SQRT(3)/2 | R31: --- | S31: --- | U31: =+BALANZA!$C$10 | V31: =+U31/SQRT(3)/2 | W31: --- | X31: --- | Z31: =+BALANZA!$C$10 | AA31: =+Z31/SQRT(3)/2 | AB31: --- | AC31: --- | AE31: =+BALANZA!$C$10 | AF31: =+AE31/SQRT(3)/2 | AG31: --- | AH31: --- | AJ31: =+B45 | AK31: =+I45 | AL31: =+AK31/$AK$32
A32: C | B32: Masa de prueba | C32: g | D32: --- | E32: =+DATOS!$H$12 | G32: =SQRT((G33*G33)+(G34*G34)+(G35*G35)) | H32: =IF(E28=0,0,E28*E36*100/E40/E32/E32) | I32: =+H32*G32 | J32: =+DATOS!$H$13 | L32: =SQRT((L33*L33)+(L34*L34)+(L35*L35)) | M32: =IF(J28=0,0,J28*J36*100/J40/J32/J32) | N32: =+M32*L32 | O32: =+DATOS!$H$14 | Q32: =SQRT((Q33*Q33)+(Q34*Q34)+(Q35*Q35)) | R32: =IF(O28=0,0,O28*O36*100/O40/O32/O32) | S32: =+R32*Q32 | T32: =+DATOS!$H$15 | V32: =SQRT((V33*V33)+(V34*V34)+(V35*V35)) | W32: =IF(T28=0,0,T28*T36*100/T40/T32/T32) | X32: =+W32*V32 | Y32: =+DATOS!$H$16 | AA32: =SQRT((AA33*AA33)+(AA34*AA34)+(AA35*AA35)) | AB32: =IF(Y28=0,0,Y28*Y36*100/Y40/Y32/Y32) | AC32: =+AB32*AA32 | AD32: =+DATOS!$H$17 | AF32: =SQRT((AF33*AF33)+(AF34*AF34)+(AF35*AF35)) | AG32: =IF(AD28=0,0,AD28*AD36*100/AD40/AD32/AD32) | AH32: =+AG32*AF32 | AK32: =SUM(AK27:AK31) | AL32: =SUM(AL27:AL31)
B33: Repetibilidad de la pesada | C33: g | D33: Normal, K=1 | F33: =+BALANZA!$F$24 | G33: =+F33 | H33: --- | I33: --- | K33: =+BALANZA!$F$25 | L33: =+K33 | M33: --- | N33: --- | P33: =+BALANZA!$F$26 | Q33: =+P33 | R33: --- | S33: --- | U33: =+BALANZA!$F$27 | V33: =+U33 | W33: --- | X33: --- | Z33: =+BALANZA!$F$28 | AA33: =+Z33 | AB33: --- | AC33: --- | AE33: =+BALANZA!$F$29 | AF33: =+AE33 | AG33: --- | AH33: ---
B34: Certificado de Calibración | C34: g | D34: Normal, K=2 | F34: =2*(SQRT(BALANZA!$C$8+BALANZA!$D$8*(POWER(E32,2)))) | G34: =+F34/2 | H34: --- | I34: --- | K34: =2*(SQRT(BALANZA!$C$8+BALANZA!$D$8*(POWER(J32,2)))) | L34: =+K34/2 | M34: --- | N34: --- | P34: =2*(SQRT(BALANZA!$C$8+BALANZA!$D$8*(POWER(O32,2)))) | Q34: =+P34/2 | R34: --- | S34: --- | U34: =2*(SQRT(BALANZA!$C$8+BALANZA!$D$8*(POWER(T32,2)))) | V34: =+U34/2 | W34: --- | X34: --- | Z34: =2*(SQRT(BALANZA!$C$8+BALANZA!$D$8*(POWER(Y32,2)))) | AA34: =+Z34/2 | AB34: --- | AC34: --- | AE34: =2*(SQRT(BALANZA!$C$8+BALANZA!$D$8*(POWER(AD32,2)))) | AF34: =+AE34/2 | AG34: --- | AH34: ---
B35: Resolución | C35: g | D35: Rectangular | F35: =+BALANZA!$C$10 | G35: =+F35/SQRT(3)/2 | H35: --- | I35: --- | K35: =+BALANZA!$C$10 | L35: =+K35/SQRT(3)/2 | M35: --- | N35: --- | P35: =+BALANZA!$C$10 | Q35: =+P35/SQRT(3)/2 | R35: --- | S35: --- | U35: =+BALANZA!$C$10 | V35: =+U35/SQRT(3)/2 | W35: --- | X35: --- | Z35: =+BALANZA!$C$10 | AA35: =+Z35/SQRT(3)/2 | AB35: --- | AC35: --- | AE35: =+BALANZA!$C$10 | AF35: =+AE35/SQRT(3)/2 | AG35: --- | AH35: ---
A36: B | B36: Masa retenida | C36: g | D36: --- | E36: =+DATOS!$D$12 | G36: =SQRT((G37*G37)+(G38*G38)+(G39*G39)) | H36: =IF(E28=0,0,E28*100/E32/E40) | I36: =+H36*G36 | J36: =+DATOS!$D$13 | L36: =SQRT((L37*L37)+(L38*L38)+(L39*L39)) | M36: =IF(J28=0,0,J28*100/J32/J40) | N36: =+M36*L36 | O36: =+DATOS!$D$14 | Q36: =SQRT((Q37*Q37)+(Q38*Q38)+(Q39*Q39)) | R36: =IF(O28=0,0,O28*100/O32/O40) | S36: =+R36*Q36 | T36: =+DATOS!$D$15 | V36: =SQRT((V37*V37)+(V38*V38)+(V39*V39)) | W36: =IF(T28=0,0,T28*100/T32/T40) | X36: =+W36*V36 | Y36: =+DATOS!$D$16 | AA36: =SQRT((AA37*AA37)+(AA38*AA38)+(AA39*AA39)) | AB36: =IF(Y28=0,0,Y28*100/Y32/Y40) | AC36: =+AB36*AA36 | AD36: =+DATOS!$D$17 | AF36: =SQRT((AF37*AF37)+(AF38*AF38)+(AF39*AF39)) | AG36: =IF(AD28=0,0,AD28*100/AD32/AD40) | AH36: =+AG36*AF36
B37: Repetibilidad de la pesada | C37: g | D37: Normal, K=1 | F37: =+BALANZA!$H$24 | G37: =+F37 | H37: --- | I37: --- | K37: =+BALANZA!$H$25 | L37: =+K37 | M37: --- | N37: --- | P37: =+BALANZA!$H$26 | Q37: =+P37 | R37: --- | S37: --- | U37: =+BALANZA!$H$27 | V37: =+U37 | W37: --- | X37: --- | Z37: =+BALANZA!$H$28 | AA37: =+Z37 | AB37: --- | AC37: --- | AE37: =+BALANZA!$H$29 | AF37: =+AE37 | AG37: --- | AH37: ---
B38: Certificado de Calibración | C38: g | D38: Normal, K=2 | F38: =2*(SQRT(BALANZA!$C$8+BALANZA!$D$8*(POWER(E36,2)))) | G38: =+F38/2 | H38: --- | I38: --- | K38: =2*(SQRT(BALANZA!$C$8+BALANZA!$D$8*(POWER(J36,2)))) | L38: =+K38/2 | M38: --- | N38: --- | P38: =2*(SQRT(BALANZA!$C$8+BALANZA!$D$8*(POWER(O36,2)))) | Q38: =+P38/2 | R38: --- | S38: --- | U38: =2*(SQRT(BALANZA!$C$8+BALANZA!$D$8*(POWER(T36,2)))) | V38: =+U38/2 | W38: --- | X38: --- | Z38: =2*(SQRT(BALANZA!$C$8+BALANZA!$D$8*(POWER(Y36,2)))) | AA38: =+Z38/2 | AB38: --- | AC38: --- | AE38: =2*(SQRT(BALANZA!$C$8+BALANZA!$D$8*(POWER(AD36,2)))) | AF38: =+AE38/2 | AG38: --- | AH38: ---
B39: Resolución | C39: g | D39: Rectangular | F39: =+BALANZA!$C$10 | G39: =+F39/SQRT(3)/2 | H39: --- | I39: --- | K39: =+BALANZA!$C$10 | L39: =+K39/SQRT(3)/2 | M39: --- | N39: --- | P39: =+BALANZA!$C$10 | Q39: =+P39/SQRT(3)/2 | R39: --- | S39: --- | U39: =+BALANZA!$C$10 | V39: =+U39/SQRT(3)/2 | W39: --- | X39: --- | Z39: =+BALANZA!$C$10 | AA39: =+Z39/SQRT(3)/2 | AB39: --- | AC39: --- | AE39: =+BALANZA!$C$10 | AF39: =+AE39/SQRT(3)/2 | AG39: --- | AH39: ---
A40: D | B40: Masa total | C40: g | D40: --- | E40: =+DATOS!$D$18 | G40: =SQRT((G41*G41)+(G42*G42)+(G43*G43)) | H40: =IF(E28=0,0,E28*E36*100/E32/E40/E40) | I40: =+H40*G40 | J40: =+DATOS!$D$18 | L40: =SQRT((L41*L41)+(L42*L42)+(L43*L43)) | M40: =IF(J28=0,0,J28*J36*100/J32/J40/J40) | N40: =+M40*L40 | O40: =+DATOS!$D$18 | Q40: =SQRT((Q41*Q41)+(Q42*Q42)+(Q43*Q43)) | R40: =IF(O28=0,0,O28*O36*100/O32/O40/O40) | S40: =+R40*Q40 | T40: =+DATOS!$D$18 | V40: =SQRT((V41*V41)+(V42*V42)+(V43*V43)) | W40: =IF(T28=0,0,T28*T36*100/T32/T40/T40) | X40: =+W40*V40 | Y40: =+DATOS!$D$18 | AA40: =SQRT((AA41*AA41)+(AA42*AA42)+(AA43*AA43)) | AB40: =IF(Y28=0,0,Y28*Y36*100/Y32/Y40/Y40) | AC40: =+AB40*AA40 | AD40: =+DATOS!$D$18 | AF40: =SQRT((AF41*AF41)+(AF42*AF42)+(AF43*AF43)) | AG40: =IF(AD28=0,0,AD28*AD36*100/AD32/AD40/AD40) | AH40: =+AG40*AF40
B41: Repetibilidad de la pesada | C41: g | D41: Normal, K=1 | F41: =+BALANZA!$K$24 | G41: =+F41 | H41: --- | I41: --- | K41: =+BALANZA!$K$24 | L41: =+K41 | M41: --- | N41: --- | P41: =+BALANZA!$K$24 | Q41: =+P41 | R41: --- | S41: --- | U41: =+BALANZA!$K$24 | V41: =+U41 | W41: --- | X41: --- | Z41: =+BALANZA!$K$24 | AA41: =+Z41 | AB41: --- | AC41: --- | AE41: =+BALANZA!$K$24 | AF41: =+AE41 | AG41: --- | AH41: ---
B42: Certificado de Calibración | C42: g | D42: Normal, K=2 | F42: =2*(SQRT(BALANZA!$C$8+BALANZA!$D$8*(POWER(E40,2)))) | G42: =+F42/2 | H42: --- | I42: --- | K42: =2*(SQRT(BALANZA!$C$8+BALANZA!$D$8*(POWER(J40,2)))) | L42: =+K42/2 | M42: --- | N42: --- | P42: =2*(SQRT(BALANZA!$C$8+BALANZA!$D$8*(POWER(O40,2)))) | Q42: =+P42/2 | R42: --- | S42: --- | U42: =2*(SQRT(BALANZA!$C$8+BALANZA!$D$8*(POWER(T40,2)))) | V42: =+U42/2 | W42: --- | X42: --- | Z42: =2*(SQRT(BALANZA!$C$8+BALANZA!$D$8*(POWER(Y40,2)))) | AA42: =+Z42/2 | AB42: --- | AC42: --- | AE42: =2*(SQRT(BALANZA!$C$8+BALANZA!$D$8*(POWER(AD40,2)))) | AF42: =+AE42/2 | AG42: --- | AH42: ---
B43: Resolución | C43: g | D43: Rectangular | F43: =+BALANZA!$C$10 | G43: =+F43/SQRT(3)/2 | H43: --- | I43: --- | K43: =+BALANZA!$C$10 | L43: =+K43/SQRT(3)/2 | M43: --- | N43: --- | P43: =+BALANZA!$C$10 | Q43: =+P43/SQRT(3)/2 | R43: --- | S43: --- | U43: =+BALANZA!$C$10 | V43: =+U43/SQRT(3)/2 | W43: --- | X43: --- | Z43: =+BALANZA!$C$10 | AA43: =+Z43/SQRT(3)/2 | AB43: --- | AC43: --- | AE43: =+BALANZA!$C$10 | AF43: =+AE43/SQRT(3)/2 | AG43: --- | AH43: ---
B45: factor de presición | C45: % | D45: Norma, K=1 | E45: =+PRECISION!B7 | G45: =E45/SQRT(1) | H45: 1 | I45: =+G45*H45
B46: Incertidumbre Estándar Combinada | H46: % | I46: =SQRT(I45^2+I28^2+I32^2+I36^2+I40^2+N28^2+N32^2+N36^2+S28^2+S32^2+S36^2+X28^2+X32^2+X36^2+AC28^2+AC32^2+AC36^2+AH28^2+AH32^2+AH36^2)
B47: Incertidumbre Expandida, K = 2 | H47: % | I47: =+I46*2
B49: CÁLCULO: PORCENTAJE DE PARTICULAS ALARGADAS
...

Sheet BALANZA
B2: CALIBRACION DE LA BALANZA
B7: Corrección | C7: -3.29e-06
B8: Variables | C8: 0.00416 | D8: 2.43e-10
B9: Ecuación | C9: 2*RAIZ(0.00416+0.000000000243*R2)
B10: Resolución | C10: 0.1 | D10: g
B11: Código | C11: EQP-0046
B12: Fecha ultima calibracion | D12: 46132
B13: ITEM | C13: MES | D13: 20 | E13: 200 | F13: 500 | G13: 1000 | H13: 5000 | I13: 10000 | J13: 11000
C16: DESV STD | D16: 0 | E16: 0 | F16: 0 | G16: 0 | H16: 0 | I16: 0 | J16: 0
B18: Busqueda de Repetibilidad de la masa
D19: =+D13 | E19: =+E13 | F19: =+F13 | G19: =+G13 | H19: =+H13
D20: =D16 | E20: =E16 | F20: =F16 | G20: =G16 | H20: =H16
B22: PLANAS
B23: Tamaño de partículas | C23: Masa particula (g) | D23: repetibilidad masa particula | E23: Masa de prueba (g) | F23: repetibilidad masa de prueba | G23: Masa retenida (g) | H23: repetibilidad masa retenida | J23: Masa total (g) | K23: repetibilidad masa total
B24: 1 1/2 in | C24: =+DATOS!M12 | D24: =IF(C24<=$D$19,$D$20,IF(AND(C24>$D$19,C24<=$E$19),$E$20,IF(AND(C24>$E$19,C24<=$F$19),$F$20,IF(AND(C24>$F$19,C24<=$G$19),$G$20,IF(AND(C24>$G$19,C24<=$H$19),$H$20,$H$20))))) | E24: =+DATOS!H12 | F24: =IF(E24<=$D$19,$D$20,IF(AND(E24>$D$19,E24<=$E$19),$E$20,IF(AND(E24>$E$19,E24<=$F$19),$F$20,IF(AND(E24>$F$19,E24<=$G$19),$G$20,IF(AND(E24>$G$19,E24<=$H$19),$H$20,$H$20))))) | G24: =+DATOS!D12 | H24: =IF(G24<=$D$19,$D$20,IF(AND(G24>$D$19,G24<=$E$19),$E$20,IF(AND(G24>$E$19,G24<=$F$19),$F$20,IF(AND(G24>$F$19,G24<=$G$19),$G$20,IF(AND(G24>$G$19,G24<=$H$19),$H$20,$H$20))))) | J24: =+DATOS!D18 | K24: =IF(J24<=$D$19,$D$20,IF(AND(J24>$D$19,J24<=$E$19),$E$20,IF(AND(J24>$E$19,J24<=$F$19),$F$20,IF(AND(J24>$F$19,J24<=$G$19),$G$20,IF(AND(J24>$G$19,J24<=$H$19),$H$20,$H$20)))))
B25: 1 in | C25: =+DATOS!M13 | D25: =IF(C25<=$D$19,$D$20,IF(AND(C25>$D$19,C25<=$E$19),$E$20,IF(AND(C25>$E$19,C25<=$F$19),$F$20,IF(AND(C25>$F$19,C25<=$G$19),$G$20,IF(AND(C25>$G$19,C25<=$H$19),$H$20,$H$20))))) | E25: =+DATOS!H13 | F25: =IF(E25<=$D$19,$D$20,IF(AND(E25>$D$19,E25<=$E$19),$E$20,IF(AND(E25>$E$19,E25<=$F$19),$F$20,IF(AND(E25>$F$19,E25<=$G$19),$G$20,IF(AND(E25>$G$19,E25<=$H$19),$H$20,$H$20))))) | G25: =+DATOS!D13 | H25: =IF(G25<=$D$19,$D$20,IF(AND(G25>$D$19,G25<=$E$19),$E$20,IF(AND(G25>$E$19,G25<=$F$19),$F$20,IF(AND(G25>$F$19,G25<=$G$19),$G$20,IF(AND(G25>$G$19,G25<=$H$19),$H$20,$H$20)))))
B26: 3/4 in | C26: =+DATOS!M14 | D26: =IF(C26<=$D$19,$D$20,IF(AND(C26>$D$19,C26<=$E$19),$E$20,IF(AND(C26>$E$19,C26<=$F$19),$F$20,IF(AND(C26>$F$19,C26<=$G$19),$G$20,IF(AND(C26>$G$19,C26<=$H$19),$H$20,$H$20))))) | E26: =+DATOS!H14 | F26: =IF(E26<=$D$19,$D$20,IF(AND(E26>$D$19,E26<=$E$19),$E$20,IF(AND(E26>$E$19,E26<=$F$19),$F$20,IF(AND(E26>$F$19,E26<=$G$19),$G$20,IF(AND(E26>$G$19,E26<=$H$19),$H$20,$H$20))))) | G26: =+DATOS!D14 | H26: =IF(G26<=$D$19,$D$20,IF(AND(G26>$D$19,G26<=$E$19),$E$20,IF(AND(G26>$E$19,G26<=$F$19),$F$20,IF(AND(G26>$F$19,G26<=$G$19),$G$20,IF(AND(G26>$G$19,G26<=$H$19),$H$20,$H$20)))))
B27: 1/2 in | C27: =+DATOS!M15 | D27: =IF(C27<=$D$19,$D$20,IF(AND(C27>$D$19,C27<=$E$19),$E$20,IF(AND(C27>$E$19,C27<=$F$19),$F$20,IF(AND(C27>$F$19,C27<=$G$19),$G$20,IF(AND(C27>$G$19,C27<=$H$19),$H$20,$H$20))))) | E27: =+DATOS!H15 | F27: =IF(E27<=$D$19,$D$20,IF(AND(E27>$D$19,E27<=$E$19),$E$20,IF(AND(E27>$E$19,E27<=$F$19),$F$20,IF(AND(E27>$F$19,E27<=$G$19),$G$20,IF(AND(E27>$G$19,E27<=$H$19),$H$20,$H$20))))) | G27: =+DATOS!D15 | H27: =IF(G27<=$D$19,$D$20,IF(AND(G27>$D$19,G27<=$E$19),$E$20,IF(AND(G27>$E$19,G27<=$F$19),$F$20,IF(AND(G27>$F$19,G27<=$G$19),$G$20,IF(AND(G27>$G$19,G27<=$H$19),$H$20,$H$20)))))
B28: 3/8 in | C28: =+DATOS!M16 | D28: =IF(C28<=$D$19,$D$20,IF(AND(C28>$D$19,C28<=$E$19),$E$20,IF(AND(C28>$E$19,C28<=$F$19),$F$20,IF(AND(C28>$F$19,C28<=$G$19),$G$20,IF(AND(C28>$G$19,C28<=$H$19),$H$20,$H$20))))) | E28: =+DATOS!H16 | F28: =IF(E28<=$D$19,$D$20,IF(AND(E28>$D$19,E28<=$E$19),$E$20,IF(AND(E28>$E$19,E28<=$F$19),$F$20,IF(AND(E28>$F$19,E28<=$G$19),$G$20,IF(AND(E28>$G$19,E28<=$H$19),$H$20,$H$20))))) | G28: =+DATOS!D16 | H28: =IF(G28<=$D$19,$D$20,IF(AND(G28>$D$19,G28<=$E$19),$E$20,IF(AND(G28>$E$19,G28<=$F$19),$F$20,IF(AND(G28>$F$19,G28<=$G$19),$G$20,IF(AND(G28>$G$19,G28<=$H$19),$H$20,$H$20)))))
B29: N°4 | C29: =+DATOS!M17 | D29: =IF(C29<=$D$19,$D$20,IF(AND(C29>$D$19,C29<=$E$19),$E$20,IF(AND(C29>$E$19,C29<=$F$19),$F$20,IF(AND(C29>$F$19,C29<=$G$19),$G$20,IF(AND(C29>$G$19,C29<=$H$19),$H$20,$H$20))))) | E29: =+DATOS!H17 | F29: =IF(E29<=$D$19,$D$20,IF(AND(E29>$D$19,E29<=$E$19),$E$20,IF(AND(E29>$E$19,E29<=$F$19),$F$20,IF(AND(E29>$F$19,E29<=$G$19),$G$20,IF(AND(E29>$G$19,E29<=$H$19),$H$20,$H$20))))) | G29: =+DATOS!D17 | H29: =IF(G29<=$D$19,$D$20,IF(AND(G29>$D$19,G29<=$E$19),$E$20,IF(AND(G29>$E$19,G29<=$F$19),$F$20,IF(AND(G29>$F$19,G29<=$G$19),$G$20,IF(AND(G29>$G$19,G29<=$H$19),$H$20,$H$20)))))
B31: ALARGADAS
B32: Tamaño de partículas | C32: Masa particula (g) | D32: repetibilidad masa particula
B33: 1 1/2 in | C33: =+DATOS!R12 | D33: =IF(C33<=$D$19,$D$20,IF(AND(C33>$D$19,C33<=$E$19),$E$20,IF(AND(C33>$E$19,C33<=$F$19),$F$20,IF(AND(C33>$F$19,C33<=$G$19),$G$20,IF(AND(C33>$G$19,C33<=$H$19),$H$20,$H$20)))))
B34: 1 in | C34: =+DATOS!R13 | D34: =IF(C34<=$D$19,$D$20,IF(AND(C34>$D$19,C34<=$E$19),$E$20,IF(AND(C34>$E$19,C34<=$F$19),$F$20,IF(AND(C34>$F$19,C34<=$G$19),$G$20,IF(AND(C34>$G$19,C34<=$H$19),$H$20,$H$20)))))
B35: 3/4 in | C35: =+DATOS!R14 | D35: =IF(C35<=$D$19,$D$20,IF(AND(C35>$D$19,C35<=$E$19),$E$20,IF(AND(C35>$E$19,C35<=$F$19),$F$20,IF(AND(C35>$F$19,C35<=$G$19),$G$20,IF(AND(C35>$G$19,C35<=$H$19),$H$20,$H$20)))))
B36: 1/2 in | C36: =+DATOS!R15 | D36: =IF(C36<=$D$19,$D$20,IF(AND(C36>$D$19,C36<=$E$19),$E$20,IF(AND(C36>$E$19,C36<=$F$19),$F$20,IF(AND(C36>$F$19,C36<=$G$19),$G$20,IF(AND(C36>$G$19,C36<=$H$19),$H$20,$H$20)))))
B37: 3/8 in | C37: =+DATOS!R16 | D37: =IF(C37<=$D$19,$D$20,IF(AND(C37>$D$19,C37<=$E$19),$E$20,IF(AND(C37>$E$19,C37<=$F$19),$F$20,IF(AND(C37>$F$19,C37<=$G$19),$G$20,IF(AND(C37>$G$19,C37<=$H$19),$H$20,$H$20)))))
B38: N°4 | C38: =+DATOS!R17 | D38: =IF(C38<=$D$19,$D$20,IF(AND(C38>$D$19,C38<=$E$19),$E$20,IF(AND(C38>$E$19,C38<=$F$19),$F$20,IF(AND(C38>$F$19,C38<=$G$19),$G$20,IF(AND(C38>$G$19,C38<=$H$19),$H$20,$H$20)))))
B40: PLANAS Y ALARGADAS
B41: Tamaño de partículas | C41: Masa particula (g) | D41: repetibilidad masa particula
B42: 1 1/2 in | C42: =+DATOS!W12 | D42: =IF(C42<=$D$19,$D$20,IF(AND(C42>$D$19,C42<=$E$19),$E$20,IF(AND(C42>$E$19,C42<=$F$19),$F$20,IF(AND(C42>$F$19,C42<=$G$19),$G$20,IF(AND(C42>$G$19,C42<=$H$19),$H$20,$H$20)))))
B43: 1 in | C43: =+DATOS!W13 | D43: =IF(C43<=$D$19,$D$20,IF(AND(C43>$D$19,C43<=$E$19),$E$20,IF(AND(C43>$E$19,C43<=$F$19),$F$20,IF(AND(C43>$F$19,C43<=$G$19),$G$20,IF(AND(C43>$G$19,C43<=$H$19),$H$20,$H$20)))))
B44: 3/4 in | C44: =+DATOS!W14 | D44: =IF(C44<=$D$19,$D$20,IF(AND(C44>$D$19,C44<=$E$19),$E$20,IF(AND(C44>$E$19,C44<=$F$19),$F$20,IF(AND(C44>$F$19,C44<=$G$19),$G$20,IF(AND(C44>$G$19,C44<=$H$19),$H$20,$H$20)))))
B45: 1/2 in | C45: =+DATOS!W15 | D45: =IF(C45<=$D$19,$D$20,IF(AND(C45>$D$19,C45<=$E$19),$E$20,IF(AND(C45>$E$19,C45<=$F$19),$F$20,IF(AND(C45>$F$19,C45<=$G$19),$G$20,IF(AND(C45>$G$19,C45<=$H$19),$H$20,$H$20)))))
B46: 3/8 in | C46: =+DATOS!W16 | D46: =IF(C46<=$D$19,$D$20,IF(AND(C46>$D$19,C46<=$E$19),$E$20,IF(AND(C46>$E$19,C46<=$F$19),$F$20,IF(AND(C46>$F$19,C46<=$G$19),$G$20,IF(AND(C46>$G$19,C46<=$H$19),$H$20,$H$20)))))
B47: N°4 | C47: =+DATOS!W17 | D47: =IF(C47<=$D$19,$D$20,IF(AND(C47>$D$19,C47<=$E$19),$E$20,IF(AND(C47>$E$19,C47<=$F$19),$F$20,IF(AND(C47>$F$19,C47<=$G$19),$G$20,IF(AND(C47>$G$19,C47<=$H$19),$H$20,$H$20)))))
B49: NI PLANAS NI ALARGADAS
B50: Tamaño de partículas | C50: Masa particula (g) | D50: repetibilidad masa particula
B51: 1 1/2 in | C51: =+DATOS!AA12 | D51: =IF(C51<=$D$19,$D$20,IF(AND(C51>$D$19,C51<=$E$19),$E$20,IF(AND(C51>$E$19,C51<=$F$19),$F$20,IF(AND(C51>$F$19,C51<=$G$19),$G$20,IF(AND(C51>$G$19,C51<=$H$19),$H$20,$H$20)))))
B52: 1 in | C52: =+DATOS!AA13 | D52: =IF(C52<=$D$19,$D$20,IF(AND(C52>$D$19,C52<=$E$19),$E$20,IF(AND(C52>$E$19,C52<=$F$19),$F$20,IF(AND(C52>$F$19,C52<=$G$19),$G$20,IF(AND(C52>$G$19,C52<=$H$19),$H$20,$H$20)))))
...

Sheet PRECISION
A3: FACTOR DE PRECISION DEL OPERADOR | G3: FACTOR DE PRECISION DEL OPERADOR | M3: FACTOR DE PRECISION DEL OPERADOR | S3: FACTOR DE PRECISION DEL OPERADOR
A4: Fecha de evaluacion: | B4: 45789 | G4: Fecha de evaluacion: | H4: =+B4 | M4: Fecha de evaluacion: | N4: =+B4 | S4: Fecha de evaluacion: | T4: =+B4
A6: 1-Calcular la Incertidumbre estandar PLANAS | G6: 1-Calcular la Incertidumbre estandar ALARGADA | M6: 1-Calcular la Incertidumbre estandar PLANAS Y ALARGADA | S6: 1-Calcular la Incertidumbre estandar NI PLANAS NI ALARGADA
A7: Varianza Repetibilidad (Sr2 ) | B7: 0.075891511 | G7: Varianza Repetibilidad (Sr2 ) | H7: 0.063650585 | M7: Varianza Repetibilidad (Sr2 ) | N7: 0.043461349 | S7: Varianza Repetibilidad (Sr2 ) | T7: 0.16348214
A8: Varianza entre Laboratorios (SL2) | B8: 0.078947747 | G8: Varianza entre Laboratorios (SL2) | H8: 0.067897698 | M8: Varianza entre Laboratorios (SL2) | N8: 0.047140452 | S8: Varianza entre Laboratorios (SL2) | T8: 0.17459743
