Workbook

Sheet Resumen
A3: LABORATORIO DE ENSAYO DE MATERIALES
A4: FORMATO RESUMEN N° F-LEM-P-CO-12.03
A6: CLIENTE | O6: RECEPCIÓN N°
A7: DIRECCIÓN ** | O7: OT N°
A8: PROYECTO **
A9: UBICACIÓN **
O10: Fecha Recepción
O11: Densidad
A13: Código muestra LEM | B13: Código cliente | C13: Estructura | D13: F'c (kg/cm2) | E13: Fecha Moldeo** | F13: Fecha Rotura | G13: Hora moldeo | H13: Hora rotura | I13: Diametro 1 | J13: Diametro 2 | K13: Longitud 1 | L13: Longitud 2 | M13: Longitud 3 | N13: Carga Máxima (kN) | O13: Tipo fractura | P13: Masa muestra aire (g)

Sheet COMPRESION
A2: LABORATORIO DE ENSAYO DE MATERIALES
A3: 0
A5: CLIENTE | B5: : | C5: =+Resumen!B6 -> 0 | J5: CÓDIGO | K5: : | L5: F-LEM-P-CO-12.02
A6: DIRECCIÓN ** | B6: : | C6: =+Resumen!B7 -> 0 | J6: RECEPCIÓN N° | K6: : | L6: =+Resumen!P6 -> 0
A7: PROYECTO ** | B7: : | C7: =+Resumen!B8 -> 0 | J7: OT N° | K7: : | L7: =+Resumen!P7 -> 0
A8: UBICACIÓN ** | B8: : | C8: =+Resumen!B9 -> 0 | J8: FECHA EMISIÓN | K8: :
A9: **Datos proporcionados y de responsabilidad del cliente
A11: STANDARD TEST METHOD FOR COMPRESSIVE STRENGTH OF CYLINDRICAL CONCRETE SPECIMENS
A12: ASTM C39/C39M-24
A14: IDENTIFICACIÓN DE LA MUESTRA
A16: Estructura** | B16: : | C16: =+Resumen!C14 -> 0 | J16: Fecha Recepción | K16: : | L16: =+Resumen!P10 -> 0
A17: F´c (Kg/cm2) ** | B17: : | C17: =+Resumen!D14 -> 0 | J17: Fecha Moldeo** | K17: : | L17: =+DATOS!C11 -> 0
A18: Tipo muestra | B18: : | C18: =+DATOS!C17 -> Cilindros Moldeados | J18: Fecha Rotura | K18: : | L18: =+DATOS!C13 -> 0
A19: LUGAR DE ENSAYO: Laboratorio de ensayo de materiales | J19: Edad muestra | K19: : | L19: =+DATOS!C15 -> 0 | M19: =+DATOS!E15 -> horas
A21: Código muestra LEM | C21: Código cliente | D21: Diámetro promedio (mm) | F21: Longitud promedio (mm) | G21: Área sección transversal (mm2) | H21: Carga Máxima (kN) | I21: Resistencia Compresión (MPa) | J21: Resistencia Compresión (Kg/cm2) | K21: Tipo fractura | M21: Densidad muestra (kg/m3)
A22: =IF(DATOS!B20="","--",DATOS!B20) -> 0 | C22: =IF(DATOS!C20="","--",DATOS!C20) -> 0 | D22: =+DATOS!D36 -> -6.7762636e-21 | F22: =+DATOS!E36 -> -6.7762636e-21 | G22: =+DATOS!F36 -> 3.6063799e-41 | H22: =+DATOS!G36 -> 0 | I22: =+DATOS!H36 -> 0 | J22: =+I22*10.1972 -> 0 | K22: =+DATOS!I36 -> 0 | M22: =+DATOS!J36 -> 0
A23: =IF(DATOS!B21="","--",DATOS!B21) -> 0 | C23: =IF(DATOS!C21="","--",DATOS!C21) -> 0 | D23: =+DATOS!D37 -> -6.7762636e-21 | F23: =+DATOS!E37 -> -6.7762636e-21 | G23: =+DATOS!F37 -> 3.6063799e-41 | H23: =+DATOS!G37 -> 0 | I23: =+DATOS!H37 -> 0 | J23: =+I23*10.1972 -> 0 | K23: =+DATOS!I37 -> 0 | M23: =+DATOS!J37 -> 0
A24: =IF(DATOS!B22="","--",DATOS!B22) -> 0 | C24: =IF(DATOS!C22="","--",DATOS!C22) -> 0 | D24: =+DATOS!D38 -> -6.7762636e-21 | F24: =+DATOS!E38 -> -6.7762636e-21 | G24: =+DATOS!F38 -> 3.6063799e-41 | H24: =+DATOS!G38 -> 0 | I24: =+DATOS!H38 -> 0 | J24: =+I24*10.1972 -> 0 | K24: =+DATOS!I38 -> 0 | M24: =+DATOS!J38 -> 0
A26: Defecto de la muestra o en la tapa: | F26: =+DATOS!N20 -> -
A28: Nota :
A29: - El cliente es responsable de los datos de identificación de los puntos de ensayo brindados.
A30: - Los resultados expresados se refieren únicamente al ensayo realizado en dicho momento y en las condiciones especificadas en este documento, por lo que GEOFAL S.A.C. no será responsable por los ensayos realizados con la presente muestra en condiciones distintas a las aquí señaladas.
A31: - GEOFAL S.A.C. no se hace responsable por el uso incorrecto o inadecuado del presente informe.
A32: - Los resultados de los ensayos realizados no deben ser utilizados como una certificación de conformidad con normas de producto o como certificado del sistema de calidad de la entidad que lo produce.
A33: - De conformidad con lo dispuesto por el artículo 1321 del Código Civil, queda establecido que en ningún caso la responsabilidad de GEOFAL S.A.C. será mayor al valor del servicio prestado.
A35: Observaciones:
A40: Página 1 de 1
A41: Versión: 04 (26-05-2026) | L41: Fin del Documento

Sheet Hoja2
B3: Código muestra LEM | C3: Código cliente | D3: Diámetro promedio (mm) | E3: Longitud promedio (mm) | F3: Área sección transversal (mm2) | G3: Carga Máxima (kN) | H3: Resistencia Compresión (Mpa) | I3: Densidad muestra (kg/m3) | J3: Tipo fractura
G5: PROMEDIO | H5: =AVERAGE(H4) -> #DIV/0!

Sheet DATOS
B2: STANDARD TEST METHOD FOR COMPRESSIVE STRENGTH OF CYLINDRICAL CONCRETE SPECIMENS1
B3: ASTM C39/C39M-25
B5: Certificado de Calibración: balanza 30kg precisión 1g | H5: Certificado de Calibración: Pie de rey precisión 0.01mm | N5: Certificado de Calibración: Prensa de concreto
B6: Correccion | C6: =+Balanza!C7 -> -1.49e-06 | D6: F.calibracion | E6: =+Balanza!C12 -> 46160 | H6: Correccion | J6: -0.0002 | K6: mm | L6: F.calibracion | M6: 46185 | N6: F.calibracion | O6: 45902 | Q6: =+INCERTIDUMBRE!D50 -> U
B8: IDENTIFICACION DE LA MUESTRA | G8: Resistencia concreto
B9: Estructura | C9: =+Resumen!C14 -> 0 | G9: kg/cm2 | H9: Mpa | K9: REALIZADO POR: | L9: - | N9: EVALUACIÓN DE DEFECTO DE LA MUESTRA
B10: F´c (kg/cm2) | C10: =+Resumen!D14 -> 0 | E10: =+LOOKUP(C10,G10:G16,H10:H16) -> #N/A | G10: 100 | H10: 9.80665 | N10: A | O10: Presencia de grandes huecos de aire
B11: Fecha Moldeo | C11: =+Resumen!E14 -> 0 | G11: 140 | H11: 13.7293 | N11: B | O11: Evidencia de segregación
B12: Hora de Moldeo | C12: =+Resumen!G14 -> 0 | E12: Solo para <3dias | G12: 175 | H12: 17.1616 | N12: C | O12: Las fracturas pasan predominantemente alrededor de la particula gruesa
B13: Fecha Rotura | C13: =+Resumen!F14 -> 0 | G13: 210 | H13: 20.594 | N13: D | O13: Las fracturas pasan a travez del agregado grueso
B14: Hora de ensayo | C14: =+Resumen!H14 -> 0 | E14: Obligatorio <3d | G14: 245 | H14: 24.0263 | N14: E | O14: Desprendimiento tapa adherida
B15: Edad muestra | C15: =+IF(C13-C11<3,(INT(((C13+C14)-(C11+C12))*24)),C13-C11) -> 0 | E15: =+IF(C13-C11<3,"horas","días") -> horas | G15: 280 | H15: 27.4586
B16: Densidad | C16: =+Resumen!P11 -> 0 | G16: 350 | H16: 34.3233
B17: Tipo muestra | C17: Cilindros Moldeados
B19: Código muestra LEM | C19: Código cliente | D19: Diametro 1 | E19: Diametro 2 | F19: Longitud 1 | G19: Longitud 2 | H19: Longitud 3 | I19: Carga Máxima (kN) | J19: Tipo fractura | K19: Masa muestra aire (g) | L19: Parametro Diametro | M19: Defecto de muestra | N19: Evaluación del defecto de muestra
B20: =+Resumen!A14 -> 0 | C20: =+Resumen!B14 -> 0 | D20: =+Resumen!I14 -> 0 | E20: =+Resumen!J14 -> 0 | F20: =+Resumen!K14 -> 0 | G20: =+Resumen!L14 -> 0 | H20: =+Resumen!M14 -> 0 | I20: =+Resumen!N14 -> 0 | J20: =+Resumen!O14 -> 0 | K20: =+Resumen!P14 -> 0 | L20: =+IF(((MAX(D20,E20)-MIN(D20,E20))/D20)*100<2,"Cumple","No Cumple") -> #DIV/0! | M20: =+IF(AND(C15>=28,E10<H36),"ok",IF(C15<28,"--","Evaluar")) -> #N/A | N20: -
B21: =+Resumen!A15 -> 0 | C21: =+Resumen!B15 -> 0 | D21: =+Resumen!I15 -> 0 | E21: =+Resumen!J15 -> 0 | F21: =+Resumen!K15 -> 0 | G21: =+Resumen!L15 -> 0 | H21: =+Resumen!M15 -> 0 | I21: =+Resumen!N15 -> 0 | J21: =+Resumen!O15 -> 0 | K21: =+Resumen!P15 -> 0 | L21: =+IF(((MAX(D21,E21)-MIN(D21,E21))/D21)*100<2,"Cumple","No Cumple") -> #DIV/0! | M21: =+IF(AND(C15>=28,E10<H37),"ok",IF(C15<28,"--","Defecto de muestra")) -> #N/A
B22: =+Resumen!A16 -> 0 | C22: =+Resumen!B16 -> 0 | D22: =+Resumen!I16 -> 0 | E22: =+Resumen!J16 -> 0 | F22: =+Resumen!K16 -> 0 | G22: =+Resumen!L16 -> 0 | H22: =+Resumen!M16 -> 0 | I22: =+Resumen!N16 -> 0 | J22: =+Resumen!O16 -> 0 | K22: =+Resumen!P16 -> 0 | L22: =+IF(((MAX(D22,E22)-MIN(D22,E22))/D22)*100<2,"Cumple","No Cumple") -> #DIV/0! | M22: =+IF(AND(C15>=28,E10<H38),"ok",IF(C15<28,"--","Defecto de muestra")) -> #N/A
I23: 50Kn a 800Kn
D24: =+D20*$D$45+$D$46 -> -6.7762636e-21 | E24: =+E20*$D$45+$D$46 -> -6.7762636e-21 | F24: =+F20*$H$45+$H$46 -> -6.7762636e-21 | G24: =+G20*$H$45+$H$46 -> -6.7762636e-21 | H24: =+H20*$H$45+$H$46 -> -6.7762636e-21
D25: =+D21*$D$49+$D$50 -> -6.7762636e-21 | E25: =+E21*$D$49+$D$50 -> -6.7762636e-21 | F25: =+F21*$H$49+$H$50 -> -6.7762636e-21 | G25: =+G21*$H$49+$H$50 -> -6.7762636e-21 | H25: =+H21*$H$49+$H$50 -> -6.7762636e-21
D26: =+D22*$D$53+$D$54 -> -6.7762636e-21 | E26: =+E22*$D$53+$D$54 -> -6.7762636e-21 | F26: =+F22*$H$53+$H$54 -> -6.7762636e-21 | G26: =+G22*$H$53+$H$54 -> -6.7762636e-21 | H26: =+H22*$H$53+$H$54 -> -6.7762636e-21
D28: CORRECCION DIAMETRO | F28: CORRECCION LONGITUD | I28: CORRECION MASA | K28: F.C. COMPRESION | M28: F'C | O28: F. correc. Compresion | R28: =(STDEV(H36:H38)/AVERAGE(H36:H38))*100 -> #DIV/0!
D29: Diametro 1 | E29: Diametro 2 | F29: Longitud 1 | G29: Longitud 2 | H29: Longitud 3 | I29: Masa aire (g) | J29: Masa aire (kg) | K29: L/D | L29: Factor correccion | O29: L/D | P29: Factor
D30: =+D20+D24 -> -6.7762636e-21 | E30: =+E20+E24 -> -6.7762636e-21 | F30: =+F20+F24 -> -6.7762636e-21 | G30: =+G20+G24 -> -6.7762636e-21 | H30: =+H20+H24 -> -6.7762636e-21 | I30: =+K20+$C$6*K20 -> 0 | J30: =+I30/1000 -> 0 | K30: =+E36/D36 -> 1 | L30: =IF(AND(K30>1.75,K30<=2.2),1,FORECAST(K30,P31:P34,O31:O34)) -> 0.881 | M30: =+L36/$C$10 -> #DIV/0! | O30: SI ES MAYOR > 1.75 | P30: 1
D31: =+D21+D25 -> -6.7762636e-21 | E31: =+E21+E25 -> -6.7762636e-21 | F31: =+F21+F25 -> -6.7762636e-21 | G31: =+G21+G25 -> -6.7762636e-21 | H31: =+H21+H25 -> -6.7762636e-21 | I31: =+K21+$C$6*K21 -> 0 | J31: =+I31/1000 -> 0 | K31: =+E37/D37 -> 1 | L31: =IF(AND(K31>1.75,K31<=2.2),1,FORECAST(K31,P31:P34,O31:O34)) -> 0.881 | M31: =+L37/$C$10 -> #DIV/0! | O31: 1.75 | P31: 0.98
D32: =+D22+D26 -> -6.7762636e-21 | E32: =+E22+E26 -> -6.7762636e-21 | F32: =+F22+F26 -> -6.7762636e-21 | G32: =+G22+G26 -> -6.7762636e-21 | H32: =+H22+H26 -> -6.7762636e-21 | I32: =+K22+$C$6*K22 -> 0 | J32: =+I32/1000 -> 0 | K32: =+E38/D38 -> 1 | L32: =IF(AND(K32>1.75,K32<=2.2),1,FORECAST(K32,P32:P34,O32:O34)) -> 0.875 | M32: =+L38/$C$10 -> #DIV/0! | O32: 1.5 | P32: 0.96
O33: 1.25 | P33: 0.93
D34: Diámetro promedio (mm) | E34: Longitud promedio (mm) | F34: Área sección transversal (mm2) | G34: Carga Máxima (kN) | H34: Resistencia Compresión (Mpa) | I34: Tipo fractura | J34: Densidad muestra (kg/m3) | L34: Resistencia Compresión (kg/cm2) | O34: 1 | P34: 0.87
D36: =+(D30+E30)/2 -> -6.7762636e-21 | E36: =+(F30+G30+H30)/3 -> -6.7762636e-21 | F36: =3.1416*D36^2/4 -> 3.6063799e-41 | G36: =+I20 -> 0 | H36: =(4000*G36/3.1416/D36^2)*L30 -> 0 | I36: =+J20 -> 0 | J36: =IF($C$16="no","---",MROUND((4*(10^9)*J30)/E36/(D36^2)/3.1416,10)) -> 0 | L36: =+H36*10.1972 -> 0
D37: =+(D31+E31)/2 -> -6.7762636e-21 | E37: =+(F31+G31+H31)/3 -> -6.7762636e-21 | F37: =3.1416*D37^2/4 -> 3.6063799e-41 | G37: =+I21 -> 0 | H37: =(4000*G37/3.1416/D37^2)*L31 -> 0 | I37: =+J21 -> 0 | J37: =IF($C$16="no","---",MROUND((4*(10^9)*J31)/E37/(D37^2)/3.1416,10)) -> 0 | L37: =+H37*10.1972 -> 0
D38: =+(D32+E32)/2 -> -6.7762636e-21 | E38: =+(F32+G32+H32)/3 -> -6.7762636e-21 | F38: =3.1416*D38^2/4 -> 3.6063799e-41 | G38: =+I22 -> 0 | H38: =(4000*G38/3.1416/D38^2)*L32 -> 0 | I38: =+J22 -> 0 | J38: =IF($C$16="no","---",MROUND((4*(10^9)*J32)/E38/(D38^2)/3.1416,10)) -> 0 | L38: =+H38*10.1972 -> 0
B41: NO MOVER | J41: Del certificado de Calibracón
J42: ITEM | K42: Valor | L42: Error
B43: =MATCH(D20,K43:K52) -> 1 | C43: =INDEX(J43:L52,B43,2) -> 0 | D43: =INDEX(J43:L52,B43,3) -> 0 | F43: =MATCH(F20,K43:K52) -> 1 | G43: =INDEX(J43:L52,F43,2) -> 0 | H43: =INDEX(J43:L52,F43,3) -> 0 | J43: 1 | K43: 0 | L43: 0
B44: =B43+1 -> 2 | C44: =INDEX(J43:L52,B44,2) -> 50 | D44: =INDEX(J43:L52,B44,3) -> -0.0001 | F44: =F43+1 -> 2 | G44: =INDEX(J43:L52,F44,2) -> 50 | H44: =INDEX(J43:L52,F44,3) -> -0.0001 | J44: 2 | K44: 50 | L44: -0.0001
C45: pendiente | D45: =+SLOPE(D43:D44,C43:C44) -> -2e-06 | G45: pendiente | H45: =+SLOPE(H43:H44,G43:G44) -> -2e-06 | J45: 3 | K45: 100 | L45: 0
C46: intercepto | D46: =+INTERCEPT(D43:D44,C43:C44) -> -6.7762636e-21 | G46: intercepto | H46: =+INTERCEPT(H43:H44,G43:G44) -> -6.7762636e-21 | J46: 4 | K46: 200 | L46: -0.0003
B47: =MATCH(D21,K43:K52) -> 1 | C47: =INDEX(J43:L52,B47,2) -> 0 | D47: =INDEX(J43:L52,B47,3) -> 0 | F47: =MATCH(F21,K43:K52) -> 1 | G47: =INDEX(J43:L52,F47,2) -> 0 | H47: =INDEX(J43:L52,F47,3) -> 0 | J47: 5 | K47: 400 | L47: 0
B48: =B47+1 -> 2 | C48: =INDEX(J43:L52,B48,2) -> 50 | D48: =INDEX(J43:L52,B48,3) -> -0.0001 | F48: =F47+1 -> 2 | G48: =INDEX(J43:L52,F48,2) -> 50 | H48: =INDEX(J43:L52,F48,3) -> -0.0001 | J48: 6 | K48: 450 | L48: 0.01
...

Sheet INCERTIDUMBRE
C1: INFORME DE ESTIMACIÓN DE INCERTIDUMBRE | I1: Código: | J1: F-LEM-P-10.01 | T1: Del Certificado de calibracón
I2: Versión: | J2: 3 | T2: Indice | U2: Valor (mm) | V2: Incertidumbre de medición (U)
I3: Fecha: | J3: 46146
I4: Página: | J4: 1 de 1
T5: 1 | U5: 50 | V5: 0.0082
A6: Método: | B6: STANDARD TEST METHOD FOR COMPRESSIVE STRENGTH OF CYLINDRICAL CONCRETE SPECIMENS | T6: 2 | U6: 100 | V6: 0.0083
A7: Norma: | B7: ASTM C39/C39M-24 | T7: 3 | U7: 200 | V7: 0.0087
A8: Matriz: | B8: Concreto | T8: 4 | U8: 400 | V8: 0.01
A9: Mensurando | B9: Resistencia a la compresión de muestras cilindricas de concreto | T9: 5 | U9: 450 | V9: 0.01
A11: Paso 1. Definición del proceso de medición | F11: Paso 2. Definición de las variables aleatorias
A13: Variables: | D13: Fórmula:
A15: fcm = resistencia a la compresion Mpa | L15: compresion 1 - Diametro | O15: compresion 2 - Diametro | R15: compresion 3 - Diametro
A16: D= Diametro promedio medido, mm | L16: =MATCH(C33,U6:U8) -> #N/A | M16: =INDEX(T6:V8,L16,2) -> #N/A | N16: =INDEX(T6:V8,L16,3) -> #N/A | O16: =MATCH(L33,U6:U8) -> #N/A | P16: =INDEX(T6:V8,O16,2) -> #N/A | Q16: =INDEX(T6:V8,O16,3) -> #N/A | R16: =MATCH(U33,U6:U8) -> #N/A | S16: =INDEX(T6:V8,R16,2) -> #N/A | T16: =INDEX(T6:V8,R16,3) -> #N/A
A17: Pmax= Carga máxima, KN | L17: =L16+1 -> #N/A | M17: =INDEX(T6:V8,L17,2) -> #N/A | N17: =INDEX(T6:V8,L17,3) -> #N/A | O17: =O16+1 -> #N/A | P17: =INDEX(T6:V8,O17,2) -> #N/A | Q17: =INDEX(T6:V8,O17,3) -> #N/A | R17: =R16+1 -> #N/A | S17: =INDEX(T6:V8,R17,2) -> #N/A | T17: =INDEX(T6:V8,R17,3) -> #N/A
L18: pendiente | N18: =+SLOPE(N16:N17,L16:L17) -> #N/A | O18: pendiente | Q18: =+SLOPE(Q16:Q17,O16:O17) -> #N/A | R18: pendiente | T18: =+SLOPE(T16:T17,R16:R17) -> #N/A
L19: intercepto | N19: =+INTERCEPT(N16:N17,L16:L17) -> #N/A | O19: intercepto | Q19: =+INTERCEPT(Q16:Q17,O16:O17) -> #N/A | R19: intercepto | T19: =+INTERCEPT(T16:T17,R16:R17) -> #N/A
A27: CÁLCULO: RESISTENCIA A LA COMPRESIÓN 1 | J27: CÁLCULO: RESISTENCIA A LA COMPRESIÓN 2 | S27: CALCULO: RESISTENCIA A LA COMPRESION 3
A28: Fuentes | B28: und | C28: Valor | D28: Incertidumbre Original | E28: Distribución | F28: Incertidumbre Estándar u(xi) | G28: Coeficiente de Sensibilidad | H28: Contribución ui(y) | J28: Fuentes | K28: und | L28: Valor | M28: Incertidumbre Original | N28: Distribución | O28: Incertidumbre Estándar u(xi) | P28: Coeficiente de Sensibilidad | Q28: Contribución ui(y) | S28: Fuentes | T28: und | U28: Valor | V28: Incertidumbre Original | W28: Distribución | X28: Incertidumbre Estándar u(xi) | Y28: Coeficiente de Sensibilidad | Z28: Contribución ui(y)
A29: Resistencia a la compresión | B29: Mpa | C29: =4000*C30/3.1416/C33/C33 -> 0 | D29: --- | E29: --- | F29: --- | G29: --- | H29: --- | J29: Resistencia a la compresión | K29: Mpa | L29: =4000*L30/3.1416/L33/L33 -> 0 | M29: --- | N29: --- | O29: --- | P29: --- | Q29: --- | S29: Resistencia a la compresión | T29: Mpa | U29: =4000*U30/3.1416/U33/U33 -> 0 | V29: --- | W29: --- | X29: --- | Y29: --- | Z29: ---
A30: Carga máxima | B30: KN | C30: =+DATOS!I20 -> 0 | D30: --- | E30: --- | F30: =SQRT((F31*F31+F32*F32)) -> 4.8800009 | G30: =4000/3.1416/C33/C33 -> 2.7728637e+43 | H30: =+G30*F30 -> 1.3531577e+44 | I30: C | J30: Carga máxima | K30: KN | L30: =+DATOS!I21 -> 0 | M30: --- | N30: --- | O30: =SQRT((O31*O31+O32*O32)) -> 4.8800009 | P30: =4000/3.1416/L33/L33 -> 2.7728637e+43 | Q30: =+P30*O30 -> 1.3531577e+44 | R30: C | S30: Carga máxima | T30: KN | U30: =+DATOS!G38 -> 0 | V30: --- | W30: --- | X30: =SQRT((X31*X31+X32*X32)) -> 0.77000541 | Y30: =4000/3.1416/U33/U33 -> 2.7728637e+43 | Z30: =+Y30*X30 -> 2.1351201e+43 | AA30: C
A31: Certificado de Calibración | B31: KN | D31: - | E31: Norma, K=1 | F31: =+E50 -> -4.88 | J31: Certificado de Calibración | K31: KN | M31: - | N31: Norma, K=1 | O31: =+F50 -> -4.88 | S31: Certificado de Calibración | T31: KN | V31: - | W31: Norma, K=1 | X31: 0.77
A32: Resolución | B32: KN | D32: 0.01 | E32: Rectangular | F32: =+D32/SQRT(3)/2 -> 0.0028867513 | G32: --- | H32: --- | J32: Resolución | K32: KN | M32: 0.01 | N32: Rectangular | O32: =+M32/SQRT(3)/2 -> 0.0028867513 | P32: --- | Q32: --- | S32: Resolución | T32: KN | V32: 0.01 | W32: Rectangular | X32: =+V32/SQRT(3)/2 -> 0.0028867513 | Y32: --- | Z32: ---
A33: Diametro | B33: mm | C33: =+DATOS!D36 -> -6.7762636e-21 | E33: --- | F33: =SQRT((F34*F34)+(F35*F35)+(F36*F36)) -> #N/A | G33: =8000*C30/3.1416/C33/C33/C33 -> 0 | H33: =+G33*F33 -> #N/A | I33: Y | J33: Diametro | K33: mm | L33: =+DATOS!D37 -> -6.7762636e-21 | N33: --- | O33: =SQRT((O34*O34)+(O35*O35)+(O36*O36)) -> #N/A | P33: =8000*L30/3.1416/L33/L33/L33 -> 0 | Q33: =+P33*O33 -> #N/A | R33: Y | S33: Diametro | T33: mm | U33: =+DATOS!D38 -> -6.7762636e-21 | W33: --- | X33: =SQRT((X34*X34)+(X35*X35)+(X36*X36)) -> #N/A | Y33: =8000*U30/3.1416/U33/U33/U33 -> 0 | Z33: =+Y33*X33 -> #N/A | AA33: Y
A34: Repetibilidad | B34: mm | D34: =+PRECISION!$C$76 -> 0.0064086994 | E34: Normal, K=1 | F34: =+D34 -> 0.0064086994 | G34: --- | H34: --- | J34: Repetibilidad | K34: mm | M34: =+PRECISION!$C$76 -> 0.0064086994 | N34: Normal, K=1 | O34: =+M34 -> 0.0064086994 | P34: --- | Q34: --- | S34: Repetibilidad | T34: mm | V34: =+PRECISION!$C$76 -> 0.0064086994 | W34: Normal, K=1 | X34: =+V34 -> 0.0064086994 | Y34: --- | Z34: ---
A35: Certificado de Calibración | B35: mm | D35: =+C33*N18+N19 -> #N/A | E35: Normal, K=1 | F35: =+D35 -> #N/A | G35: --- | H35: --- | J35: Certificado de Calibración | K35: mm | M35: =+L33*Q18+Q19 -> #N/A | N35: Normal, K=1 | O35: =+M35 -> #N/A | P35: --- | Q35: --- | S35: Certificado de Calibración | T35: mm | V35: =+U33*T18+T19 -> #N/A | W35: Normal, K=1 | X35: =+V35 -> #N/A | Y35: --- | Z35: ---
A36: Resolución | B36: mm | D36: 0.01 | E36: Rectangular | F36: =+D36/SQRT(3)/2 -> 0.0028867513 | G36: --- | H36: --- | J36: Resolución | K36: mm | M36: 0.01 | N36: Rectangular | O36: =+M36/SQRT(3)/2 -> 0.0028867513 | P36: --- | Q36: --- | S36: Resolución | T36: mm | V36: 0.01 | W36: Rectangular | X36: =+V36/SQRT(3)/2 -> 0.0028867513 | Y36: --- | Z36: ---
A37: factor de presición | B37: Mpa | C37: =+PRECISION!C5 -> 0.1911 | E37: Norma, K=1 | F37: =C37/SQRT(1) -> 0.1911 | G37: 1 | H37: =+F37*G37 -> 0.1911 | J37: factor de presición | K37: Mpa | L37: =+C37 -> 0.1911 | N37: Norma, K=1 | O37: =L37/SQRT(1) -> 0.1911 | P37: 1 | Q37: =+O37*P37 -> 0.1911 | S37: factor de presición | T37: Mpa | U37: =+C37 -> 0.1911 | W37: Norma, K=1 | X37: =U37/SQRT(1) -> 0.1911 | Y37: 1 | Z37: =+X37*Y37 -> 0.1911
A38: Incertidumbre Estándar Combinada | H38: =SQRT((H30*H30)+(H33*H33)+(H37*H37)) -> #N/A | J38: Incertidumbre Estándar Combinada | Q38: =SQRT((Q30*Q30)+(Q33*Q33)+(Q37*Q37)) -> #N/A | S38: Incertidumbre Estándar Combinada | Z38: =SQRT((Z30*Z30)+(Z33*Z33)+(Z37*Z37)) -> #N/A
A39: Incertidumbre Expandida, K = 2 | G39: Mpa | H39: =+H38*2 -> #N/A | J39: Incertidumbre Expandida, K = 2 | P39: Mpa | Q39: =+Q38*2 -> #N/A | S39: Incertidumbre Expandida, K = 2 | Y39: Mpa | Z39: =+Z38*2 -> #N/A
A42: CONTRIBUCIÓN
A43: Factor de influencia | C43: valor | D43: %
B44: =+A30 -> Carga máxima | C44: =+H30 -> 1.3531577e+44 | D44: =+C44/C47 -> #N/A
B45: =+A33 -> Diametro | C45: =+H33 -> #N/A | D45: =+C45/C47 -> #N/A
B46: =+A37 -> factor de presición | C46: =+H37 -> 0.1911 | D46: =+C46/C47 -> #N/A
C47: =SUM(C44:C46) -> #N/A | D47: =+C47/C47 -> #N/A
C50: Carga KN | D50: U | E50: =+FORECAST(C30,D54:D55,C54:C55) -> -4.88 | F50: =+FORECAST(L30,D54:D55,C54:C55) -> -4.88 | G50: =+FORECAST(U30,D54:D55,C54:C55) -> -4.88
C51: 200 | D51: 0.77
C52: 300 | D52: 0.64
C53: 400 | D53: 0.87
C54: 500 | D54: 0.52
...

Sheet Balanza
B2: CALIBRACION DE LA BALANZA
B7: Correccion | C7: -1.49e-06
B8: Variables | C8: 1.14 | D8: 2.48e-10
B9: Ecuacion | C9: 2*RAIZ(1.14+0.000000000248*R2) | F9: g
B10: Resolucion | C10: 1 | D10: g
B11: Codigo | C11: EQP-0054
B12: F. calibración | C12: 46160
B13: ITEM | C13: MES | D13: 500 | E13: 1000 | F13: 5000 | G13: 10000 | H13: 15000 | I13: 20000
C17: DESV STD | D17: 0 | E17: 0 | F17: 0 | G17: 0 | H17: 0 | I17: 0
B19: Busqueda de Repetibilidad de la masa
D20: =+D13 -> 500 | E20: =+E13 -> 1000 | F20: =+F13 -> 5000 | G20: =+G13 -> 10000 | H20: =+H13 -> 15000 | I20: =+I13 -> 20000
D21: =D17 -> 0 | E21: =E17 -> 0 | F21: =F17 -> 0 | G21: =G17 -> 0 | H21: =H17 -> 0 | I21: =I17 -> 0
B23: ENSAYO DE LA MUESTRA
B24: Densidad
B25: Masa 1 | D25: =+DATOS!I30 -> 0 | E25: =IF(D25<=$D$20,$D$21,IF(AND(D25>$D$20,D25<=$E$20),$E$21,IF(AND(D25>$E$20,D25<=$F$20),$F$21,IF(AND(D25>$F$20,D25<=$G$20),$G$21,IF(AND(D25>$G$20,D25<=$H$20),$H$21,$H$21))))) -> 0
B26: Masa 2 | D26: =+DATOS!I31 -> 0 | E26: =IF(D26<=$D$20,$D$21,IF(AND(D26>$D$20,D26<=$E$20),$E$21,IF(AND(D26>$E$20,D26<=$F$20),$F$21,IF(AND(D26>$F$20,D26<=$G$20),$G$21,IF(AND(D26>$G$20,D26<=$H$20),$H$21,$H$21))))) -> 0
B27: Masa 3 | D27: =+DATOS!I32 -> 0 | E27: =IF(D27<=$D$20,$D$21,IF(AND(D27>$D$20,D27<=$E$20),$E$21,IF(AND(D27>$E$20,D27<=$F$20),$F$21,IF(AND(D27>$F$20,D27<=$G$20),$G$21,IF(AND(D27>$G$20,D27<=$H$20),$H$21,$H$21))))) -> 0

Sheet PRECISION
B2: Factor de precision del operador COMPRESION
B3: Fecha de evaluacion: | C3: 46186
B5: Desviacion Estándar Repetibilidad (Sr) | C5: 0.1911
B6: Desviacion Estándar Reproducibilidad (SR) | C6: 0.32485
B55: REPETIBILIDAD VERNIER
A57: INCERTIDUMBRE ESTANDAR -TIPO A
A58: TALLER DE INCERTIDUMBRE ESTANDAR -TIPO A
A59: Fecha de evaluacion: | B59: 0
A61: 1-Calcular la Incertidumbre estandar
A62: analista(p=2) | C62: MEDIDA
A63: Réplicas de medición (n=6) | C63: 100.02
C64: 100.01
C65: 100
C66: 100.02
C67: 100.01
C68: 100.01
C69: 100.01
C70: 100.01
A71: n | C71: =COUNT(C63:C70) -> 8 | D71: =COUNT(D63:D70) -> 0 | E71: =COUNT(E63:E70) -> 0
A72: p | C72: =COUNTA(C62:E62) -> 1 | D72: =COUNTA(C62:E62) -> 1 | E72: =COUNTA(D62:E62) -> 0
A74: No Datos | C74: =COUNT(C63:C70) -> 8 | D74: =COUNT(D63:D70) -> 0 | E74: =COUNT(E63:E70) -> 0
A75: Promedio (xi) | C75: =AVERAGE(C63:C70) -> 100.01125 | D75: =AVERAGE(D63:D70) -> #DIV/0! | E75: =AVERAGE(E63:E70) -> #DIV/0!
A76: Desviación Estándar (si) | C76: =STDEV(C63:C70) -> 0.0064086994 | D76: =STDEV(D63:D70) -> #DIV/0! | E76: =STDEV(E63:E70) -> #DIV/0!
A77: Varianza (s2i) | C77: =VAR(C63:C70) -> 4.1071429e-05 | D77: =VAR(D63:D70) -> #DIV/0! | E77: =VAR(E63:E70) -> #DIV/0!

Sheet Hoja1
A2: CODIGO | C2: CONCATENADOS | D2: DESCRIPCION | E2: FC | F2: F. MOLDEO | G2: DIA | H2: DIAMETRO | I2: CARGA | J2: AREA | K2: RESIS. CONCRETO | L2: % RESIS | M2: TIPO DE FALLA
A3: 4400 | B3: =+A3+1 -> 4401 | C3: =A3&"-"&B3 -> 4400-4401 | D3: Columnas C-9;5-3/G.H | E3: 350 | F3: 42347 | G3: 7 | H3: 15.05 | I3: 49900 | J3: =H3*H3*PI()/4 -> 177.89465 | K3: =I3/J3 -> 280.5031 | L3: =+K3/E3 -> 0.80143743 | M3: E
C4: =A4&"-"&B4 -> - | E4: 350 | G4: 7 | H4: 15.06 | I4: 50310 | J4: =H4*H4*PI()/4 -> 178.13113 | K4: =I4/J4 -> 282.43238 | L4: =+K4/E4 -> 0.80694967 | M4: F
A5: =+B3+1 -> 4402 | B5: =+A5+1 -> 4403 | C5: =A5&"-"&B5 -> 4402-4403 | E5: 350 | G5: 14 | H5: 15.04 | I5: 56450 | J5: =H5*H5*PI()/4 -> 177.65832 | K5: =I5/J5 -> 317.74476 | L5: =+K5/E5 -> 0.90784216 | M5: F
C6: =A6&"-"&B6 -> - | E6: 350 | G6: 14 | H6: 15 | I6: 59630 | J6: =H6*H6*PI()/4 -> 176.71459 | K6: =I6/J6 -> 337.43677 | L6: =+K6/E6 -> 0.96410507 | M6: F
A7: =+B5+1 -> 4404 | B7: =+A7+1 -> 4405 | C7: =A7&"-"&B7 -> 4404-4405 | E7: 350 | G7: 28 | H7: 15.11 | I7: 65310 | J7: =H7*H7*PI()/4 -> 179.3159 | K7: =I7/J7 -> 364.21755 | L7: =+K7/E7 -> 1.0406216 | M7: F
C8: =A8&"-"&B8 -> - | E8: 350 | G8: 28 | H8: 15.05 | I8: 64730 | J8: =H8*H8*PI()/4 -> 177.89465 | K8: =I8/J8 -> 363.86705 | L8: =+K8/E8 -> 1.0396201 | M8: E
