Workbook

Sheet -------

Sheet FORMATO
D2: LABORATORIO DE ENSAYO DE MATERIALES | T2: CLIENTE
D3: FORMATO N° F-LEM-P-SU-37.01 | T3: DIRECCIÓN **
T4: PROYECTO **
T5: UBICACIÓN **
T7: RECEPCIÓN N°
D8: MUESTRA | F8: N° OT | H8: FECHA DE ENSAYO | K8: REALIZADO | T8: F. EMISIÓN
T9: OT N°
A11: STANDARD TEST METHOD FOR CALIFORNIA BEARING RATIO (CBR) OF LABORATORY-COMPACTED SOILS | T11: CÓDIGO DE LA MUESTRA
A12: NORMA ASTM D1883-21 | T12: FECHA DE RECEPCIÓN
T13: FECHA DE EJECUCIÓN
A14: Sobretamaño mayor a 3/4 in | G14: % | N14: Máxima Densidad Seca (g/cm3)
A15: Masa de grava entre 3/4 in - No. 4 adicionada | G15: g | N15: Optimo Contenido de Humedad (%) | T15: CANTERA/SONDAJE **
A16: Condicion de la muestra | D16: saturado | N16: Temperatura Inicial (C°) | T16: N° MUESTRA **
D17: sin saturar | N17: Temperatura Final (C°) | T17: TIPO DE MUESTRA**
A19: Tamaño máximo de la muestra de prueba (visual) (in):
A20: Descripción de muestra ASTM D2488:
A21: ENSAYO | D21: Especimen N°01 | H21: Especimen N°02 | L21: Especimen N°03
A22: CONDICIÓN | D22: Sin Saturar | F22: Saturado | H22: Sin Saturar | J22: Saturado | L22: Sin Saturar | O22: Saturado
A23: Nº Golpes (56-25-10) | D23: 56 | H23: 25 | L23: 10
A24: Código de Moldes
A25: Temperatura de inicio (°C) (18-24°C)
A26: Temperatura final (°C) (18-24°C)
A27: Masa de molde + suelo moldeado (g)
A28: DETERMINACIÓN DE HUMEDAD
A29: Código tara | S29: C.H. SIN SATURAR | T29: 2500
A30: Masa de tara (g) | S30: =+(D32-(D34-D30))/(D34-D30)*100 -> #DIV/0! | T30: =+IF(D32>T29,"Cumple","No Cumple") -> No Cumple
A31: Masa de suelo húmedo + tara (g) | S31: =+(H32-(H34-H30))/(H34-H30)*100 -> #DIV/0! | T31: =+IF(H32>T29,"Cumple","No Cumple") -> No Cumple
A32: Masa de suelo húmedo (g) (*) | D32: =+D31-D30 -> 0 | F32: =+F31-F30 -> 0 | H32: =+H31-H30 -> 0 | J32: =+J31-J30 -> 0 | L32: =+L31-L30 -> 0 | O32: =+O31-O30 -> 0 | S32: =+(L32-(L34-L30))/(L34-L30)*100 -> #DIV/0! | T32: =+IF(L32>T29,"Cumple","No Cumple") -> No Cumple
A33: Masa de suelo seco + tara (g) | S33: C.H. SATURADO
A34: Masa de suelo seco + tara (g) CONSTANTE | S34: =+(F32-(F34-F30))/(F34-F30)*100 -> #DIV/0!
A35: (*) Según Tabla 1 de la norma ASTM D2216-19. | S35: =+(J32-(J34-J30))/(J34-J30)*100 -> #DIV/0!
A36: LECTURA DE PENETRACIÓN | S36: =+(O32-(O34-O30))/(O34-O30)*100 -> #DIV/0!
A37: Tiempo (minutos) | B37: Penetración | D37: Tensión | E37: Lectura de penetración | L37: HINCHAMIENTO
B38: (in) | C38: (mm) | D38: Estandar SS | E38: lectura Dial kg | G38: lectura Dial kg | I38: lectura Dial kg | L38: Fecha | N38: Hora | O38: Esp. 01 | P38: Esp. 02 | Q38: Esp. 03 | S38: CODIGOS | T38: EQUIPOS UTILIZADOS
D39: psi = lbf/in2 | O39: Expansión (mm) | S39: INS-173 | T39: MOLDE D
A40: 0:00 | B40: 0 | C40: 0 | S40: INS-174 | T40: MOLDE J
A41: 0:30 | B41: 0.025 | C41: 0.64 | S41: INS-175 | T41: MOLDE T
A42: 1:00 | B42: 0.05 | C42: 1.3 | S42: INS-200 | T42: MOLDE A
A43: 1:30 | B43: 0.075 | C43: 1.9 | S43: INS-201 | T43: MOLDE B
A44: 2:00 | B44: 0.1 | C44: 2.5 | D44: 1000 | S44: INS-202 | T44: MOLDE C
...

Sheet INFORME-1
A7: LABORATORIO DE ENSAYO DE MATERIALES
A8: 0
A10: CLIENTE | B10: : | C10: =+FORMATO!U2 -> 0 | N10: CÓDIGO | O10: : | P10: F-LEM-P-SU.37.02
A11: DIRECCIÓN** | B11: : | C11: =+FORMATO!U3 -> 0 | N11: RECEPCIÓN N° | O11: : | P11: =+FORMATO!U7 -> 0
A12: PROYECTO** | B12: : | C12: =+FORMATO!U4 -> 0 | N12: OT N° | O12: : | P12: =+FORMATO!U9 -> 0
A13: UBICACIÓN** | B13: : | C13: =+FORMATO!U5 -> 0 | N13: F. EMISIÓN | O13: : | P13: =+FORMATO!U8 -> 0
A14: ** Datos proporcionados por el cliente
A15: Standard Test Method for California Bearing Ratio (CBR) of Laboratory-Compacted Soils
A16: ASTM D1883-21
A18: CANTERA / SONDAJE (**) | D18: : | E18: =+FORMATO!U15 -> 0 | N18: COD. MUESTRA | O18: : | P18: =+FORMATO!D9 -> 0
A19: N° MUESTRA (**) | D19: : | E19: =+FORMATO!U16 -> 0 | N19: FECHA RECEPCIÓN. | O19: : | P19: =+FORMATO!U12 -> 0
A20: TIPO DE MUESTRA (**) | D20: : | E20: =+FORMATO!U17 -> 0 | N20: FECHA EJECUCIÓN | O20: : | P20: =+FORMATO!U13 -> 0 | R20: =+FORMATO!H9 -> 0
A21: LUGAR DE ENSAYO | D21: : | E21: Laboratorio de ensayo de materiales | N21: REALIZADO POR | O21: : | P21: =+DATOS!D2 -> -
A24: INFORMACIÓN ADICIONAL DE LA MUESTRA
A25: Máxima Densidad Seca (kN/m3) | E25: : | F25: =+DATOS!J2 -> 0 | N25: Método de compactación: | O25: : | P25: =+DATOS!D4 -> -
A26: Contenido de Humedad Óptimo (%) | E26: : | F26: =+DATOS!J3 -> 0 | N26: Método de Preparación: | O26: : | P26: =+DATOS!D5 -> -
A27: Porcentaje de retenido tamiz 3/4" | E27: : | F27: =+DATOS!J4 -> 0 | N27: Peso-Sobrecarga (lbf): | O27: : | P27: 10
A28: Descripción de muestra | N28: Periódo inmersión (hrs) | O28: : | R28: 96+/-2 horas
A29: Contenido Humedad tal como se recibió | F29: - | G29: ASTM D2216-19 | J29: Limites de Atterberg | N29: - | O29: ASTM D4318-17ε1 | S29: ASTM D6913/D6913M-17 (Reapproved 2025) | U29: GR. SUELO
A30: Clasificaciòn de suelo SUCS | F30: - | G30: ASTM D2487-17 (Reapproved 2025) | J30: Analisis granulometrico | N30: - | O30: ASTM C136/C136M-25 | S30: ASTM C136/C136M-25 | U30: GR. AGREGADO
A31: Otros
A33: PESO UNITARIO SECO
A34: Nº GOLPES | F34: =+DATOS!D15 -> 56 | J34: =+DATOS!H15 -> 25 | N34: =+DATOS!L15 -> 10
A35: Condición de la muestra | F35: =+DATOS!D6 -> - | J35: =+DATOS!D6 -> - | N35: =+DATOS!D6 -> -
A36: Densidad seca antes saturar | E36: g/cm3 | F36: =+DATOS!E23 -> #N/A | J36: =+DATOS!I23 -> #N/A | N36: =+DATOS!M23 -> #N/A | R36: CON CUATRO CIFRAS SIGNIFICATIVAS
A37: Peso Unitario seco antes saturar | E37: kN/m3 | F37: =+DATOS!E24 -> #N/A | J37: =+DATOS!I24 -> #N/A | N37: =+DATOS!M24 -> #N/A | R37: CON CUATRO CIFRAS SIGNIFICATIVAS
A38: CONTENIDO DE HUMEDAD DE COMPACTACIÒN
A39: Contenido de humedad (ASTM D2216-19) | E39: % | F39: =+DATOS!E32 -> #DIV/0! | J39: =+DATOS!I32 -> #DIV/0! | N39: =+DATOS!M32 -> #DIV/0! | R39: 0.001
A40: CONTENIDO DE HUMEDAD CAPA SUPERIOR DE 1 in DESPUÉS DEL REMOJO
A41: Contenido de humedad (ASTM D2216-19) | E41: % | F41: =+DATOS!G32 -> #DIV/0! | J41: =+DATOS!K32 -> #DIV/0! | N41: =+DATOS!O32 -> #DIV/0! | R41: 0.001
A42: HINCHAMIENTO
A43: Hinchazón | E43: % | F43: =+DATOS!G40 -> #N/A | J43: =+DATOS!K40 -> #N/A | N43: =+DATOS!O40 -> #N/A | R43: 0.001
A45: FUERZA Y ESFUERZO
A46: Penetración | C46: Tensión Estandar SS | F46: =+F34 -> 56 | J46: =+J34 -> 25 | N46: =+N34 -> 10
A47: (in.) | C47: psi = lbf/in2 | F47: Fuerza total (lbf) | H47: Esfuerzo lbf/in2 | J47: Fuerza total (lbf) | L47: Esfuerzo lbf/in2 | N47: Fuerza total (lbf) | P47: Esfuerzo lbf/in2
A48: =+DATOS!A44 -> 0 | F48: =+DATOS!D44*2.2046 -> 0 | H48: =+DATOS!G44 -> 0 | J48: =+DATOS!H44*2.2046 -> 0 | L48: =+DATOS!K44 -> 0 | N48: =+DATOS!L44*2.2046 -> 0 | P48: =+DATOS!O44 -> 0
A49: =+DATOS!A45 -> 0.025 | F49: =+DATOS!D45*2.2046 -> 0 | H49: =+DATOS!G45 -> 0.78855422 | J49: =+DATOS!H45*2.2046 -> 0 | L49: =+DATOS!K45 -> 0.78855422 | N49: =+DATOS!L45*2.2046 -> 0 | P49: =+DATOS!O45 -> 0.78855422
A50: =+DATOS!A46 -> 0.05 | F50: =+DATOS!D46*2.2046 -> 0 | H50: =+DATOS!G46 -> 0.78855422 | J50: =+DATOS!H46*2.2046 -> 0 | L50: =+DATOS!K46 -> 0.78855422 | N50: =+DATOS!L46*2.2046 -> 0 | P50: =+DATOS!O46 -> 0.78855422
A51: =+DATOS!A47 -> 0.075 | F51: =+DATOS!D47*2.2046 -> 0 | H51: =+DATOS!G47 -> 0.78855422 | J51: =+DATOS!H47*2.2046 -> 0 | L51: =+DATOS!K47 -> 0.78855422 | N51: =+DATOS!L47*2.2046 -> 0 | P51: =+DATOS!O47 -> 0.78855422
A52: =+DATOS!A48 -> 0.1 | C52: 1000 | F52: =+DATOS!D48*2.2046 -> 0 | H52: =+DATOS!G48 -> 0.78855422 | J52: =+DATOS!H48*2.2046 -> 0 | L52: =+DATOS!K48 -> 0.78855422 | N52: =+DATOS!L48*2.2046 -> 0 | P52: =+DATOS!O48 -> 0.78855422
...

Sheet INFORME-2
A1: LABORATORIO DE ENSAYO DE MATERIALES
A2: =+'INFORME-1'!A8:Q8 -> 0
A4: CLIENTE | C4: : | D4: =+'INFORME-1'!C10 -> 0 | O4: CÓDIGO | P4: : | Q4: =+'INFORME-1'!P10 -> F-LEM-P-SU.37.02
A5: DIRECCIÓN** | C5: : | D5: =+'INFORME-1'!C11 -> 0 | O5: RECEPCIÓN N° | P5: : | Q5: =+'INFORME-1'!P11 -> 0
A6: PROYECTO** | C6: : | D6: =+'INFORME-1'!C12 -> 0 | O6: OT N° | P6: : | Q6: =+'INFORME-1'!P12 -> 0
A7: UBICACIÓN** | C7: : | D7: =+'INFORME-1'!C13 -> 0 | O7: F. EMISIÓN | P7: : | Q7: =+'INFORME-1'!P13 -> 0
A9: =+'INFORME-1'!A15 -> Standard Test Method for California Bearing Ratio (CBR) of Laboratory-Compacted Soils | U9: 56 GOLPES | AE9: 25 GOLPES | AO9: 10 GOLPES
A10: =+'INFORME-1'!A16 -> ASTM D1883-21
U11: Necesita corrección | Y11: NO | AE11: Necesita corrección | AI11: NO | AO11: Necesita corrección | AS11: NO
A12: CURVA DE TENSIÒN - PENETRACIÒN
U13: Ecuacion de la recta | X13: Elementos de la recta: | AA13: Punto recta | AE13: Ecuacion de la recta | AH13: Elementos de la recta: | AK13: Punto recta | AO13: Ecuacion de la recta | AR13: Elementos de la recta: | AU13: Punto recta
U14: X1 | V14: Y1 | X14: m = | Y14: =(V17-V15)/(U17-U15) -> 0 | AA14: X | AB14: Y | AE14: X1 | AF14: Y1 | AH14: m = | AI14: =(AF17-AF15)/(AE17-AE15) -> 0 | AK14: X | AL14: Y | AO14: X1 | AP14: Y1 | AR14: m = | AS14: =(AP17-AP15)/(AO17-AO15) -> 0 | AU14: X | AV14: Y
U15: =+DATOS!A49 -> 0.125 | V15: =+DATOS!G49 -> 0.78855422 | X15: Y3= | Y15: 0 | AA15: =IF(Y11="SI",U17,0) -> 0 | AB15: =IF(Y11="SI",V17,0) -> 0 | AE15: =+DATOS!A49 -> 0.125 | AF15: =+DATOS!K49 -> 0.78855422 | AH15: Y3= | AI15: 0 | AK15: =IF(AI11="SI",AE17,0) -> 0 | AL15: =IF(AI11="SI",AF17,0) -> 0 | AO15: =+DATOS!A48 -> 0.1 | AP15: =+DATOS!O48 -> 0.78855422 | AR15: Y3= | AS15: 0 | AU15: =IF(AS11="SI",AO17,0) -> 0 | AV15: =IF(AS11="SI",AP17,0) -> 0
U16: X2 | V16: Y2 | X16: X3 = | Y16: =(Y15-V15)/Y14+U15 -> #DIV/0! | Z16: in | AA16: =IF(Y11="SI",Y16,0) -> 0 | AB16: =+Y15 -> 0 | AE16: X2 | AF16: Y2 | AH16: X3 = | AI16: =(AI15-AF15)/AI14+AE15 -> #DIV/0! | AK16: =IF(AI11="SI",AI16,0) -> 0 | AL16: =+AI15 -> 0 | AO16: X2 | AP16: Y2 | AR16: X3 = | AS16: =(AS15-AP15)/AS14+AO15 -> #DIV/0! | AU16: =IF(AS11="SI",AS16,0) -> 0 | AV16: =+AS15 -> 0
U17: =+DATOS!A52 -> 0.2 | V17: =+DATOS!G52 -> 0.78855422 | AE17: =+DATOS!A52 -> 0.2 | AF17: =+DATOS!K52 -> 0.78855422 | AO17: =+DATOS!A52 -> 0.2 | AP17: =+DATOS!O52 -> 0.78855422
V19: Coeficientes ecuacion polinomio corregido : | AF19: Coeficientes ecuacion polinomio corregido : | AP19: Coeficientes ecuacion polinomio corregido :
U20: x5 | V20: x4 | W20: x3 | X20: x2 | Y20: x | Z20: Cte. | AE20: x5 | AF20: x4 | AG20: x3 | AH20: x2 | AI20: x | AJ20: Cte. | AO20: x5 | AP20: x4 | AQ20: x3 | AR20: x2 | AS20: x | AT20: Cte.
V21: 0 | W21: =+AB45 -> 75.335239 | X21: =+AB44 -> -51.5904 | Y21: =+AB43 -> 9.970604 | Z21: =+AB42 -> 0.27517333 | AF21: 0 | AG21: =+AL45 -> 75.335239 | AH21: =+AL44 -> -51.5904 | AI21: =+AL43 -> 9.970604 | AJ21: =+AL42 -> 0.27517333 | AP21: 0 | AQ21: =+AV45 -> 75.335239 | AR21: =+AV44 -> -51.5904 | AS21: =+AV43 -> 9.970604 | AT21: =+AV42 -> 0.27517333
Y23: x=penetracion | Z23: y= tensiòn | AI23: x=penetracion | AJ23: y= tensiòn | AS23: x=penetracion | AT23: y= tensiòn
W24: Carga para 0.1": | Y24: =IF(Y11="SI",0.1+Y16,0.1) -> 0.1 | Z24: =$U$21*Y24^5+$V$21*Y24^4+$W$21*Y24^3+$X$21*Y24^2+$Y$21*Y24+$Z$21 -> 0.83166497 | AG24: Carga para 0.1": | AI24: =IF(AI11="SI",0.1+AI16,0.1) -> 0.1 | AJ24: =$AE$21*AI24^5+$AF$21*AI24^4+$AG$21*AI24^3+$AH$21*AI24^2+$AI$21*AI24+$AJ$21 -> 0.83166497 | AQ24: Carga para 0.1": | AS24: =IF(AS11="SI",0.1+AS16,0.1) -> 0.1 | AT24: =$AO$21*AS24^5+$AP$21*AS24^4+$AQ$21*AS24^3+$AR$21*AS24^2+$AS$21*AS24+$AT$21 -> 0.83166497
W25: Carga para 0.2": | Y25: =IF(Y11="SI",0.2+Y16,0.2) -> 0.2 | Z25: =$U$21*Y25^5+$V$21*Y25^4+$W$21*Y25^3+$X$21*Y25^2+$Y$21*Y25+$Z$21 -> 0.80836003 | AG25: Carga para 0.2": | AI25: =IF(AI11="SI",0.2+AI16,0.2) -> 0.2 | AJ25: =$AE$21*AI25^5+$AF$21*AI25^4+$AG$21*AI25^3+$AH$21*AI25^2+$AI$21*AI25+$AJ$21 -> 0.80836003 | AQ25: Carga para 0.2": | AS25: =IF(AS11="SI",0.2+AS16,0.2) -> 0.2 | AT25: =$AO$21*AS25^5+$AP$21*AS25^4+$AQ$21*AS25^3+$AR$21*AS25^2+$AS$21*AS25+$AT$21 -> 0.80836003
U27: X (in.) | V27: Y Esfuerzo lbf/in2 | AE27: X (in.) | AF27: Y Esfuerzo lbf/in2 | AO27: X (in.) | AP27: Y Esfuerzo lbf/in2
A28: C.B.R. (0.10 in) 56 Golpes (%): | E28: =+W55 -> 0.083166497 | I28: C.B.R. (0.10 in) 25 Golpes (%): | L28: =+Z55 -> 0.083166497 | N28: C.B.R. (0.10 in) 10 Golpes (%): | Q28: =+AC55 -> 0.083166497 | S28: AL 1% | W28: Xi2 | X28: Xi3 | Y28: Xi4 | Z28: Xi5 | AA28: Xi6 | AB28: XiYi | AC28: Xi2Yi | AD28: Xi3Yi | AG28: Xi2 | AH28: Xi3 | AI28: Xi4 | AJ28: Xi5 | AK28: Xi6 | AL28: XiYi | AM28: Xi2Yi | AN28: Xi3Yi | AQ28: Xi2 | AR28: Xi3 | AS28: Xi4 | AT28: Xi5 | AU28: Xi6 | AV28: XiYi | AW28: Xi2Yi | AX28: Xi3Yi
A29: C.B.R. (0.20 in) 56 Golpes (%): | E29: =+W56 -> 0.053890668 | I29: C.B.R. (0.20 in) 25 Golpes (%): | L29: =+Z56 -> 0.053890668 | N29: C.B.R. (0.20 in) 10 Golpes (%): | Q29: =+AC56 -> 0.053890668 | S29: AL 1% | U29: =IF(Y11="SI",Y16,0) -> 0 | V29: =+Y15 -> 0 | W29: =IF(U29="","",U29^2) -> 0 | X29: =IF(U29="","",U29^3) -> 0 | Y29: =IF(U29="","",U29^4) -> 0 | Z29: =IF(U29="","",U29^5) -> 0 | AA29: =IF(U29="","",U29^6) -> 0 | AB29: =IF(U29="","",U29*V29) -> 0 | AC29: =IF(U29="","",U29^2*V29) -> 0 | AD29: =IF(U29="","",U29^3*V29) -> 0 | AE29: =IF(AI11="SI",AI16,0) -> 0 | AF29: =+AI15 -> 0 | AG29: =IF(AE29="","",AE29^2) -> 0 | AH29: =IF(AE29="","",AE29^3) -> 0 | AI29: =IF(AE29="","",AE29^4) -> 0 | AJ29: =IF(AE29="","",AE29^5) -> 0 | AK29: =IF(AE29="","",AE29^6) -> 0 | AL29: =IF(AE29="","",AE29*AF29) -> 0 | AM29: =IF(AE29="","",AE29^2*AF29) -> 0 | AN29: =IF(AE29="","",AE29^3*AF29) -> 0 | AO29: =IF(AS11="SI",AS16,0) -> 0 | AP29: =+AS15 -> 0 | AQ29: =IF(AO29="","",AO29^2) -> 0 | AR29: =IF(AO29="","",AO29^3) -> 0 | AS29: =IF(AO29="","",AO29^4) -> 0 | AT29: =IF(AO29="","",AO29^5) -> 0 | AU29: =IF(AO29="","",AO29^6) -> 0 | AV29: =IF(AO29="","",AO29*AP29) -> 0 | AW29: =IF(AO29="","",AO29^2*AP29) -> 0 | AX29: =IF(AO29="","",AO29^3*AP29) -> 0
A30: Peso unitario seco (kN/m3) : | E30: =+DATOS!E24 -> #N/A | I30: Peso unitario seco (kN/m3) : | L30: =+DATOS!I24 -> #N/A | N30: Peso unitario seco (kN/m3) : | Q30: =+DATOS!M24 -> #N/A | S30: 4 CIFRAS | U30: =+DATOS!A45 -> 0.025 | V30: =+DATOS!G45 -> 0.78855422 | W30: =IF(U30="","",U30^2) -> 0.000625 | X30: =IF(U30="","",U30^3) -> 1.5625e-05 | Y30: =IF(U30="","",U30^4) -> 3.90625e-07 | Z30: =IF(U30="","",U30^5) -> 9.765625e-09 | AA30: =IF(U30="","",U30^6) -> 2.4414063e-10 | AB30: =IF(U30="","",U30*V30) -> 0.019713856 | AC30: =IF(U30="","",U30^2*V30) -> 0.00049284639 | AD30: =IF(U30="","",U30^3*V30) -> 1.232116e-05 | AE30: =+DATOS!A45 -> 0.025 | AF30: =+DATOS!K45 -> 0.78855422 | AG30: =IF(AE30="","",AE30^2) -> 0.000625 | AH30: =IF(AE30="","",AE30^3) -> 1.5625e-05 | AI30: =IF(AE30="","",AE30^4) -> 3.90625e-07 | AJ30: =IF(AE30="","",AE30^5) -> 9.765625e-09 | AK30: =IF(AE30="","",AE30^6) -> 2.4414063e-10 | AL30: =IF(AE30="","",AE30*AF30) -> 0.019713856 | AM30: =IF(AE30="","",AE30^2*AF30) -> 0.00049284639 | AN30: =IF(AE30="","",AE30^3*AF30) -> 1.232116e-05 | AO30: =+DATOS!A45 -> 0.025 | AP30: =+DATOS!O45 -> 0.78855422 | AQ30: =IF(AO30="","",AO30^2) -> 0.000625 | AR30: =IF(AO30="","",AO30^3) -> 1.5625e-05 | AS30: =IF(AO30="","",AO30^4) -> 3.90625e-07 | AT30: =IF(AO30="","",AO30^5) -> 9.765625e-09 | AU30: =IF(AO30="","",AO30^6) -> 2.4414063e-10 | AV30: =IF(AO30="","",AO30*AP30) -> 0.019713856 | AW30: =IF(AO30="","",AO30^2*AP30) -> 0.00049284639 | AX30: =IF(AO30="","",AO30^3*AP30) -> 1.232116e-05
U31: =+DATOS!A46 -> 0.05 | V31: =+DATOS!G46 -> 0.78855422 | W31: =IF(U31="","",U31^2) -> 0.0025 | X31: =IF(U31="","",U31^3) -> 0.000125 | Y31: =IF(U31="","",U31^4) -> 6.25e-06 | Z31: =IF(U31="","",U31^5) -> 3.125e-07 | AA31: =IF(U31="","",U31^6) -> 1.5625e-08 | AB31: =IF(U31="","",U31*V31) -> 0.039427711 | AC31: =IF(U31="","",U31^2*V31) -> 0.0019713856 | AD31: =IF(U31="","",U31^3*V31) -> 9.8569278e-05 | AE31: =+DATOS!A46 -> 0.05 | AF31: =+DATOS!K46 -> 0.78855422 | AG31: =IF(AE31="","",AE31^2) -> 0.0025 | AH31: =IF(AE31="","",AE31^3) -> 0.000125 | AI31: =IF(AE31="","",AE31^4) -> 6.25e-06 | AJ31: =IF(AE31="","",AE31^5) -> 3.125e-07 | AK31: =IF(AE31="","",AE31^6) -> 1.5625e-08 | AL31: =IF(AE31="","",AE31*AF31) -> 0.039427711 | AM31: =IF(AE31="","",AE31^2*AF31) -> 0.0019713856 | AN31: =IF(AE31="","",AE31^3*AF31) -> 9.8569278e-05 | AO31: =+DATOS!A46 -> 0.05 | AP31: =+DATOS!O46 -> 0.78855422 | AQ31: =IF(AO31="","",AO31^2) -> 0.0025 | AR31: =IF(AO31="","",AO31^3) -> 0.000125 | AS31: =IF(AO31="","",AO31^4) -> 6.25e-06 | AT31: =IF(AO31="","",AO31^5) -> 3.125e-07 | AU31: =IF(AO31="","",AO31^6) -> 1.5625e-08 | AV31: =IF(AO31="","",AO31*AP31) -> 0.039427711 | AW31: =IF(AO31="","",AO31^2*AP31) -> 0.0019713856 | AX31: =IF(AO31="","",AO31^3*AP31) -> 9.8569278e-05
U32: =+DATOS!A47 -> 0.075 | V32: =+DATOS!G47 -> 0.78855422 | W32: =IF(U32="","",U32^2) -> 0.005625 | X32: =IF(U32="","",U32^3) -> 0.000421875 | Y32: =IF(U32="","",U32^4) -> 3.1640625e-05 | Z32: =IF(U32="","",U32^5) -> 2.3730469e-06 | AA32: =IF(U32="","",U32^6) -> 1.7797852e-07 | AB32: =IF(U32="","",U32*V32) -> 0.059141567 | AC32: =IF(U32="","",U32^2*V32) -> 0.0044356175 | AD32: =IF(U32="","",U32^3*V32) -> 0.00033267131 | AE32: =+DATOS!A47 -> 0.075 | AF32: =+DATOS!K47 -> 0.78855422 | AG32: =IF(AE32="","",AE32^2) -> 0.005625 | AH32: =IF(AE32="","",AE32^3) -> 0.000421875 | AI32: =IF(AE32="","",AE32^4) -> 3.1640625e-05 | AJ32: =IF(AE32="","",AE32^5) -> 2.3730469e-06 | AK32: =IF(AE32="","",AE32^6) -> 1.7797852e-07 | AL32: =IF(AE32="","",AE32*AF32) -> 0.059141567 | AM32: =IF(AE32="","",AE32^2*AF32) -> 0.0044356175 | AN32: =IF(AE32="","",AE32^3*AF32) -> 0.00033267131 | AO32: =+DATOS!A47 -> 0.075 | AP32: =+DATOS!O47 -> 0.78855422 | AQ32: =IF(AO32="","",AO32^2) -> 0.005625 | AR32: =IF(AO32="","",AO32^3) -> 0.000421875 | AS32: =IF(AO32="","",AO32^4) -> 3.1640625e-05 | AT32: =IF(AO32="","",AO32^5) -> 2.3730469e-06 | AU32: =IF(AO32="","",AO32^6) -> 1.7797852e-07 | AV32: =IF(AO32="","",AO32*AP32) -> 0.059141567 | AW32: =IF(AO32="","",AO32^2*AP32) -> 0.0044356175 | AX32: =IF(AO32="","",AO32^3*AP32) -> 0.00033267131
N33: PESO UNITARIO SECO 100%: | O33: =+'INFORME-1'!F25 -> 0 | P33: kN/m3 | U33: =+DATOS!A48 -> 0.1 | V33: =+DATOS!G48 -> 0.78855422 | W33: =IF(U33="","",U33^2) -> 0.01 | X33: =IF(U33="","",U33^3) -> 0.001 | Y33: =IF(U33="","",U33^4) -> 0.0001 | Z33: =IF(U33="","",U33^5) -> 1e-05 | AA33: =IF(U33="","",U33^6) -> 1e-06 | AB33: =IF(U33="","",U33*V33) -> 0.078855422 | AC33: =IF(U33="","",U33^2*V33) -> 0.0078855422 | AD33: =IF(U33="","",U33^3*V33) -> 0.00078855422 | AE33: =+DATOS!A48 -> 0.1 | AF33: =+DATOS!K48 -> 0.78855422 | AG33: =IF(AE33="","",AE33^2) -> 0.01 | AH33: =IF(AE33="","",AE33^3) -> 0.001 | AI33: =IF(AE33="","",AE33^4) -> 0.0001 | AJ33: =IF(AE33="","",AE33^5) -> 1e-05 | AK33: =IF(AE33="","",AE33^6) -> 1e-06 | AL33: =IF(AE33="","",AE33*AF33) -> 0.078855422 | AM33: =IF(AE33="","",AE33^2*AF33) -> 0.0078855422 | AN33: =IF(AE33="","",AE33^3*AF33) -> 0.00078855422 | AO33: =+DATOS!A48 -> 0.1 | AP33: =+DATOS!O48 -> 0.78855422 | AQ33: =IF(AO33="","",AO33^2) -> 0.01 | AR33: =IF(AO33="","",AO33^3) -> 0.001 | AS33: =IF(AO33="","",AO33^4) -> 0.0001 | AT33: =IF(AO33="","",AO33^5) -> 1e-05 | AU33: =IF(AO33="","",AO33^6) -> 1e-06 | AV33: =IF(AO33="","",AO33*AP33) -> 0.078855422 | AW33: =IF(AO33="","",AO33^2*AP33) -> 0.0078855422 | AX33: =IF(AO33="","",AO33^3*AP33) -> 0.00078855422
N34: PESO UNITARIO SECO 95%: | O34: =+O33*0.95 -> 0 | P34: kN/m3 | U34: =+DATOS!A49 -> 0.125 | V34: =+DATOS!G49 -> 0.78855422 | W34: =IF(U34="","",U34^2) -> 0.015625 | X34: =IF(U34="","",U34^3) -> 0.001953125 | Y34: =IF(U34="","",U34^4) -> 0.00024414062 | Z34: =IF(U34="","",U34^5) -> 3.0517578e-05 | AA34: =IF(U34="","",U34^6) -> 3.8146973e-06 | AB34: =IF(U34="","",U34*V34) -> 0.098569278 | AC34: =IF(U34="","",U34^2*V34) -> 0.01232116 | AD34: =IF(U34="","",U34^3*V34) -> 0.001540145 | AE34: =+DATOS!A49 -> 0.125 | AF34: =+DATOS!K49 -> 0.78855422 | AG34: =IF(AE34="","",AE34^2) -> 0.015625 | AH34: =IF(AE34="","",AE34^3) -> 0.001953125 | AI34: =IF(AE34="","",AE34^4) -> 0.00024414062 | AJ34: =IF(AE34="","",AE34^5) -> 3.0517578e-05 | AK34: =IF(AE34="","",AE34^6) -> 3.8146973e-06 | AL34: =IF(AE34="","",AE34*AF34) -> 0.098569278 | AM34: =IF(AE34="","",AE34^2*AF34) -> 0.01232116 | AN34: =IF(AE34="","",AE34^3*AF34) -> 0.001540145 | AO34: =+DATOS!A49 -> 0.125 | AP34: =+DATOS!O49 -> 0.78855422 | AQ34: =IF(AO34="","",AO34^2) -> 0.015625 | AR34: =IF(AO34="","",AO34^3) -> 0.001953125 | AS34: =IF(AO34="","",AO34^4) -> 0.00024414062 | AT34: =IF(AO34="","",AO34^5) -> 3.0517578e-05 | AU34: =IF(AO34="","",AO34^6) -> 3.8146973e-06 | AV34: =IF(AO34="","",AO34*AP34) -> 0.098569278 | AW34: =IF(AO34="","",AO34^2*AP34) -> 0.01232116 | AX34: =IF(AO34="","",AO34^3*AP34) -> 0.001540145
N35: C.B.R. (100% P.U.S.) 0.10 in : | O35: =ROUND(IF(E30<O33,E28,(O33-E30)*(L28-E28)/(L30-E30)+E28),2) -> #N/A | P35: % | U35: =+DATOS!A50 -> 0.15 | V35: =+DATOS!G50 -> 0.78855422 | W35: =IF(U35="","",U35^2) -> 0.0225 | X35: =IF(U35="","",U35^3) -> 0.003375 | Y35: =IF(U35="","",U35^4) -> 0.00050625 | Z35: =IF(U35="","",U35^5) -> 7.59375e-05 | AA35: =IF(U35="","",U35^6) -> 1.1390625e-05 | AB35: =IF(U35="","",U35*V35) -> 0.11828313 | AC35: =IF(U35="","",U35^2*V35) -> 0.01774247 | AD35: =IF(U35="","",U35^3*V35) -> 0.0026613705 | AE35: =+DATOS!A50 -> 0.15 | AF35: =+DATOS!K50 -> 0.78855422 | AG35: =IF(AE35="","",AE35^2) -> 0.0225 | AH35: =IF(AE35="","",AE35^3) -> 0.003375 | AI35: =IF(AE35="","",AE35^4) -> 0.00050625 | AJ35: =IF(AE35="","",AE35^5) -> 7.59375e-05 | AK35: =IF(AE35="","",AE35^6) -> 1.1390625e-05 | AL35: =IF(AE35="","",AE35*AF35) -> 0.11828313 | AM35: =IF(AE35="","",AE35^2*AF35) -> 0.01774247 | AN35: =IF(AE35="","",AE35^3*AF35) -> 0.0026613705 | AO35: =+DATOS!A50 -> 0.15 | AP35: =+DATOS!O50 -> 0.78855422 | AQ35: =IF(AO35="","",AO35^2) -> 0.0225 | AR35: =IF(AO35="","",AO35^3) -> 0.003375 | AS35: =IF(AO35="","",AO35^4) -> 0.00050625 | AT35: =IF(AO35="","",AO35^5) -> 7.59375e-05 | AU35: =IF(AO35="","",AO35^6) -> 1.1390625e-05 | AV35: =IF(AO35="","",AO35*AP35) -> 0.11828313 | AW35: =IF(AO35="","",AO35^2*AP35) -> 0.01774247 | AX35: =IF(AO35="","",AO35^3*AP35) -> 0.0026613705
N36: C.B.R. (95% P.U.S.) 0.10 in : | O36: =ROUND(IF(Q30>O34,Q28,(O34-L30)*(Q28-L28)/(Q30-L30)+L28),2) -> #N/A | P36: % | U36: =+DATOS!A51 -> 0.175 | V36: =+DATOS!G51 -> 0.78855422 | W36: =IF(U36="","",U36^2) -> 0.030625 | X36: =IF(U36="","",U36^3) -> 0.005359375 | Y36: =IF(U36="","",U36^4) -> 0.00093789062 | Z36: =IF(U36="","",U36^5) -> 0.00016413086 | AA36: =IF(U36="","",U36^6) -> 2.87229e-05 | AB36: =IF(U36="","",U36*V36) -> 0.13799699 | AC36: =IF(U36="","",U36^2*V36) -> 0.024149473 | AD36: =IF(U36="","",U36^3*V36) -> 0.0042261578 | AE36: =+DATOS!A51 -> 0.175 | AF36: =+DATOS!K51 -> 0.78855422 | AG36: =IF(AE36="","",AE36^2) -> 0.030625 | AH36: =IF(AE36="","",AE36^3) -> 0.005359375 | AI36: =IF(AE36="","",AE36^4) -> 0.00093789062 | AJ36: =IF(AE36="","",AE36^5) -> 0.00016413086 | AK36: =IF(AE36="","",AE36^6) -> 2.87229e-05 | AL36: =IF(AE36="","",AE36*AF36) -> 0.13799699 | AM36: =IF(AE36="","",AE36^2*AF36) -> 0.024149473 | AN36: =IF(AE36="","",AE36^3*AF36) -> 0.0042261578 | AO36: =+DATOS!A51 -> 0.175 | AP36: =+DATOS!O51 -> 0.78855422 | AQ36: =IF(AO36="","",AO36^2) -> 0.030625 | AR36: =IF(AO36="","",AO36^3) -> 0.005359375 | AS36: =IF(AO36="","",AO36^4) -> 0.00093789062 | AT36: =IF(AO36="","",AO36^5) -> 0.00016413086 | AU36: =IF(AO36="","",AO36^6) -> 2.87229e-05 | AV36: =IF(AO36="","",AO36*AP36) -> 0.13799699 | AW36: =IF(AO36="","",AO36^2*AP36) -> 0.024149473 | AX36: =IF(AO36="","",AO36^3*AP36) -> 0.0042261578
N37: C.B.R. (100% P.U.S.) 0.20 in : | O37: =ROUND(IF(E30<O33,E29,(O33-E30)*(L29-E29)/(L30-E30)+E29),2) -> #N/A | P37: % | U37: =+DATOS!A52 -> 0.2 | V37: =+DATOS!G52 -> 0.78855422 | W37: =IF(U37="","",U37^2) -> 0.04 | X37: =IF(U37="","",U37^3) -> 0.008 | Y37: =IF(U37="","",U37^4) -> 0.0016 | Z37: =IF(U37="","",U37^5) -> 0.00032 | AA37: =IF(U37="","",U37^6) -> 6.4e-05 | AB37: =IF(U37="","",U37*V37) -> 0.15771084 | AC37: =IF(U37="","",U37^2*V37) -> 0.031542169 | AD37: =IF(U37="","",U37^3*V37) -> 0.0063084338 | AE37: =+DATOS!A52 -> 0.2 | AF37: =+DATOS!K52 -> 0.78855422 | AG37: =IF(AE37="","",AE37^2) -> 0.04 | AH37: =IF(AE37="","",AE37^3) -> 0.008 | AI37: =IF(AE37="","",AE37^4) -> 0.0016 | AJ37: =IF(AE37="","",AE37^5) -> 0.00032 | AK37: =IF(AE37="","",AE37^6) -> 6.4e-05 | AL37: =IF(AE37="","",AE37*AF37) -> 0.15771084 | AM37: =IF(AE37="","",AE37^2*AF37) -> 0.031542169 | AN37: =IF(AE37="","",AE37^3*AF37) -> 0.0063084338 | AO37: =+DATOS!A52 -> 0.2 | AP37: =+DATOS!O52 -> 0.78855422 | AQ37: =IF(AO37="","",AO37^2) -> 0.04 | AR37: =IF(AO37="","",AO37^3) -> 0.008 | AS37: =IF(AO37="","",AO37^4) -> 0.0016 | AT37: =IF(AO37="","",AO37^5) -> 0.00032 | AU37: =IF(AO37="","",AO37^6) -> 6.4e-05 | AV37: =IF(AO37="","",AO37*AP37) -> 0.15771084 | AW37: =IF(AO37="","",AO37^2*AP37) -> 0.031542169 | AX37: =IF(AO37="","",AO37^3*AP37) -> 0.0063084338
N38: C.B.R. (95% P.U.S.) 0.20 in : | O38: =ROUND(IF(L30<O34,L29,(O34-L30)*(Q29-L29)/(Q30-L30)+L29),2) -> #N/A | P38: % | U38: =+DATOS!A53 -> 0.3 | V38: =+DATOS!G53 -> 0.78855422 | W38: =IF(U38="","",U38^2) -> 0.09 | X38: =IF(U38="","",U38^3) -> 0.027 | Y38: =IF(U38="","",U38^4) -> 0.0081 | Z38: =IF(U38="","",U38^5) -> 0.00243 | AA38: =IF(U38="","",U38^6) -> 0.000729 | AB38: =IF(U38="","",U38*V38) -> 0.23656627 | AC38: =IF(U38="","",U38^2*V38) -> 0.07096988 | AD38: =IF(U38="","",U38^3*V38) -> 0.021290964 | AE38: =+DATOS!A53 -> 0.3 | AF38: =+DATOS!K53 -> 0.78855422 | AG38: =IF(AE38="","",AE38^2) -> 0.09 | AH38: =IF(AE38="","",AE38^3) -> 0.027 | AI38: =IF(AE38="","",AE38^4) -> 0.0081 | AJ38: =IF(AE38="","",AE38^5) -> 0.00243 | AK38: =IF(AE38="","",AE38^6) -> 0.000729 | AL38: =IF(AE38="","",AE38*AF38) -> 0.23656627 | AM38: =IF(AE38="","",AE38^2*AF38) -> 0.07096988 | AN38: =IF(AE38="","",AE38^3*AF38) -> 0.021290964 | AO38: =+DATOS!A53 -> 0.3 | AP38: =+DATOS!O53 -> 0.78855422 | AQ38: =IF(AO38="","",AO38^2) -> 0.09 | AR38: =IF(AO38="","",AO38^3) -> 0.027 | AS38: =IF(AO38="","",AO38^4) -> 0.0081 | AT38: =IF(AO38="","",AO38^5) -> 0.00243 | AU38: =IF(AO38="","",AO38^6) -> 0.000729 | AV38: =IF(AO38="","",AO38*AP38) -> 0.23656627 | AW38: =IF(AO38="","",AO38^2*AP38) -> 0.07096988 | AX38: =IF(AO38="","",AO38^3*AP38) -> 0.021290964
U39: =+DATOS!A54 -> 0.4 | V39: =+DATOS!G54 -> 0.78855422 | W39: =IF(U39="","",U39^2) -> 0.16 | X39: =IF(U39="","",U39^3) -> 0.064 | Y39: =IF(U39="","",U39^4) -> 0.0256 | Z39: =IF(U39="","",U39^5) -> 0.01024 | AA39: =IF(U39="","",U39^6) -> 0.004096 | AB39: =IF(U39="","",U39*V39) -> 0.31542169 | AC39: =IF(U39="","",U39^2*V39) -> 0.12616868 | AD39: =IF(U39="","",U39^3*V39) -> 0.05046747 | AE39: =+DATOS!A54 -> 0.4 | AF39: =+DATOS!K54 -> 0.78855422 | AG39: =IF(AE39="","",AE39^2) -> 0.16 | AH39: =IF(AE39="","",AE39^3) -> 0.064 | AI39: =IF(AE39="","",AE39^4) -> 0.0256 | AJ39: =IF(AE39="","",AE39^5) -> 0.01024 | AK39: =IF(AE39="","",AE39^6) -> 0.004096 | AL39: =IF(AE39="","",AE39*AF39) -> 0.31542169 | AM39: =IF(AE39="","",AE39^2*AF39) -> 0.12616868 | AN39: =IF(AE39="","",AE39^3*AF39) -> 0.05046747 | AO39: =+DATOS!A54 -> 0.4 | AP39: =+DATOS!O54 -> 0.78855422 | AQ39: =IF(AO39="","",AO39^2) -> 0.16 | AR39: =IF(AO39="","",AO39^3) -> 0.064 | AS39: =IF(AO39="","",AO39^4) -> 0.0256 | AT39: =IF(AO39="","",AO39^5) -> 0.01024 | AU39: =IF(AO39="","",AO39^6) -> 0.004096 | AV39: =IF(AO39="","",AO39*AP39) -> 0.31542169 | AW39: =IF(AO39="","",AO39^2*AP39) -> 0.12616868 | AX39: =IF(AO39="","",AO39^3*AP39) -> 0.05046747
U40: =SUM(U29:U39) -> 1.6 | V40: =SUM(V29:V39) -> 7.8855422 | W40: =SUM(W29:W39) -> 0.3775 | X40: =SUM(X29:X39) -> 0.11125 | Y40: =SUM(Y29:Y39) -> 0.037126563 | Z40: =SUM(Z29:Z39) -> 0.013273281 | AA40: =SUM(AA29:AA39) -> 0.0049341221 | AB40: =SUM(AB29:AB39) -> 1.2616868 | ... AX40: =SUM(AX29:AX39) -> 0.087726657
U42: =COUNT(U29:U39) -> 11 | V42: =+U40 -> 1.6 | W42: =+W40 -> 0.3775 | X42: =+X40 -> 0.11125 | Y42: =+V40 -> 7.8855422 | AA42: Cte. | AB42: {=MMULT(U47:X50,Y47:Y50)} -> 0.27517333 | AE42: =COUNT(AE29:AE39) -> 11 | AF42: =+AE40 -> 1.6 | AG42: =+AG40 -> 0.3775 | AH42: =+AH40 -> 0.11125 | AI42: =+AF40 -> 7.8855422 | AK42: Cte. | AL42: {=MMULT(AE47:AH50,AI47:AI50)} -> 0.27517333 | AO42: =COUNT(AO29:AO39) -> 11 | AP42: =+AO40 -> 1.6 | AQ42: =+AQ40 -> 0.3775 | AR42: =+AR40 -> 0.11125 | AS42: =+AP40 -> 7.8855422 | AU42: Cte. | AV42: {=MMULT(AO47:AR50,AS47:AS50)} -> 0.27517333
U43: =+U40 -> 1.6 | V43: =+W40 -> 0.3775 | W43: =+X40 -> 0.11125 | X43: =+Y40 -> 0.037126563 | Y43: =+AB40 -> 1.2616868 | AA43: X | AB43: 9.970604 | AC43: =+AB43 -> 9.970604 | AE43: =+AE40 -> 1.6 | AF43: =+AG40 -> 0.3775 | AG43: =+AH40 -> 0.11125 | AH43: =+AI40 -> 0.037126563 | AI43: =+AL40 -> 1.2616868 | AK43: X | AL43: 9.970604 | AM43: =+AL43 -> 9.970604 | AO43: =+AO40 -> 1.6 | AP43: =+AQ40 -> 0.3775 | AQ43: =+AR40 -> 0.11125 | AR43: =+AS40 -> 0.037126563 | AS43: =+AV40 -> 1.2616868 | AU43: X | AV43: 9.970604 | AW43: =+AV43 -> 9.970604
U44: =+W40 -> 0.3775 | V44: =+X40 -> 0.11125 | W44: =+Y40 -> 0.037126563 | X44: =+Z40 -> 0.013273281 | Y44: =+AC40 -> 0.29767922 | AA44: X2 | AB44: -51.5904 | AC44: =2*AB44 -> -103.1808 | AE44: =+AG40 -> 0.3775 | AF44: =+AH40 -> 0.11125 | AG44: =+AI40 -> 0.037126563 | AH44: =+AJ40 -> 0.013273281 | AI44: =+AM40 -> 0.29767922 | AK44: X2 | AL44: -51.5904 | AM44: =2*AL44 -> -103.1808 | AO44: =+AQ40 -> 0.3775 | AP44: =+AR40 -> 0.11125 | AQ44: =+AS40 -> 0.037126563 | AR44: =+AT40 -> 0.013273281 | AS44: =+AW40 -> 0.29767922 | AU44: X2 | AV44: -51.5904 | AW44: =2*AV44 -> -103.1808
A45: Nota: | U45: =+X40 -> 0.11125 | V45: =+Y40 -> 0.037126563 | W45: =+Z40 -> 0.013273281 | X45: =+AA40 -> 0.0049341221 | Y45: =+AD40 -> 0.087726657 | AA45: X3 | AB45: 75.335239 | AC45: =3*AB45 -> 226.00572 | AE45: =+AH40 -> 0.11125 | AF45: =+AI40 -> 0.037126563 | AG45: =+AJ40 -> 0.013273281 | AH45: =+AK40 -> 0.0049341221 | AI45: =+AN40 -> 0.087726657 | AK45: X3 | AL45: 75.335239 | AM45: =3*AL45 -> 226.00572 | AO45: =+AR40 -> 0.11125 | AP45: =+AS40 -> 0.037126563 | AQ45: =+AT40 -> 0.013273281 | AR45: =+AU40 -> 0.0049341221 | AS45: =+AX40 -> 0.087726657 | AU45: X3 | AV45: 75.335239 | AW45: =3*AV45 -> 226.00572
A46: - El cliente es responsable de los datos de identificación de los puntos de ensayo brindados.
...

Sheet DATOS
A2: Personal Autorizado | D2: - | F2: =+FORMATO!K9 -> 0 | G2: Máxima Densidad Seca (kN/m3) | K2: 0.02 | L2: BALANZA | O2: FECHA | Q2: DATOS DEL MOLDE | W2: Altura de la muestra (mm) | AA2: PISTON mm
A3: Tiene SUCS | D3: - | G3: Contenido de Humedad Óptimo (%) | L3: N° | M3: Corrección de Lectura | O3: calibracion | Q3: N° | R3: MASA (g) | S3: VOLUMEN (cm3) | T3: ALTURA (mm) | U3: DIAMETRO (mm) | W3: =+D17 -> 0 | X3: =+H17 -> 0 | Y3: =+L17 -> 0 | AA3: CANT. | AB3: DIAMETRO
A4: Metodo de Compactación: | D4: - | G4: Porcentaje de retenido tamiz 3/4" | K4: 0.1 | L4: 1 | M4: =+Balanza!C11 -> EQP-0054 | N4: =+Balanza!C7 -> -1.49e-06 | O4: =+Balanza!D12 -> 46160 | Q4: D | R4: 8178 | S4: 2122.2 | T4: 116.5 | U4: 152.295 | V4: INS-173 | W4: =VLOOKUP(D17,Q4:T21,4,FALSE) -> #N/A | X4: =VLOOKUP(H17,Q4:T21,4,FALSE) -> #N/A | Y4: =VLOOKUP(L17,Q4:T21,4,FALSE) -> #N/A | AA4: 1 | AB4: 49.6
A5: Metodo de preparación: | D5: - | L5: 2 | M5: =+Balanza!M11 -> EQP-0046 | N5: =+Balanza!M7 -> -3.29e-06 | O5: =+Balanza!O12 -> 46132 | Q5: J | R5: 7715 | S5: 2119.4 | T5: 116.35 | U5: 152.295 | V5: INS-174 | AA5: 2 | AB5: 49.61
A6: Condición de la muestra | D6: - | Q6: T | R6: 8378 | S6: 2121.3 | T6: 116.62 | U6: 152.185 | V6: INS-175 | AA6: 3 | AB6: 49.6
L7: Correccion del dial | N7: 1 | Q7: A | R7: 8105 | S7: 2125 | T7: 116.59 | U7: 152.335 | V7: INS-200 | AA7: 4 | AB7: 49.6
A8: Diámetro de pistón | C8: mm | D8: =+AB9+INCERT!D80 -> 49.603845 | F8: Verificacion 13-06-26 | Q8: B | R8: 7581 | S8: 2126.1 | T8: 116.69 | U8: 152.315 | V8: INS-201 | AA8: 5 | AB8: 49.61
A9: Area de Pistón | C9: cm² | D9: =((D8^2)*PI()/4)/100 -> 19.325047 | Q9: C | R9: 8172 | S9: 2124.6 | T9: 116.67 | U9: 152.27 | V9: INS-202 | AA9: PROMEDIO | AB9: =+AVERAGE(AB4:AB8) -> 49.604
A10: Temperatura Inicial-Compactación: | C10: ºC | D10: =+FORMATO!D25 -> 0 | F10: =+IF(AND(D10>18,D10<24),"conforme","Temperatura Fuera del rango") -> Temperatura Fuera del rango | Q10: E | R10: 7844 | S10: 2126.1 | T10: 116.7 | U10: 152.305 | V10: INS-203
A11: Temperatura máxima Final-Compactación: | C11: ºC | D11: =+FORMATO!D26 -> 0 | F11: =+IF(AND(D11>18,D11<24),"conforme","Temperatura Fuera del rango") -> Temperatura Fuera del rango | Q11: H | R11: 7874 | S11: 2127.8 | T11: 116.69 | U11: 152.375 | V11: INS-204
Q12: L | R12: 8010 | S12: 2125.8 | T12: 116.69 | U12: 152.3 | V12: INS-205
A14: DENSIDAD Y PESO UNITARIO SECO
A15: Nº GOLPES | D15: 56 | H15: 25 | L15: 10
A16: Condicion de la muestra | D16: Sin Saturar | F16: Saturado | H16: Sin Saturar | J16: Saturado | L16: Sin Saturar | N16: Saturado
A17: Código de molde | D17: =+FORMATO!D24 -> 0 | H17: =+FORMATO!H24 -> 0 | L17: =+FORMATO!L24 -> 0
A18: Masa de molde+suelo moldeado | C18: g | D18: =+FORMATO!D27 -> 0 | E18: =+D18+$N$4*D18 -> 0 | F18: =+FORMATO!F27 -> 0 | G18: =+F18+$N$4*F18 -> 0 | H18: =+FORMATO!H27 -> 0 | I18: =+H18+$N$4*H18 -> 0 | J18: =+FORMATO!J27 -> 0 | K18: =+J18+$N$4*J18 -> 0 | L18: =+FORMATO!L27 -> 0 | M18: =+L18+$N$4*L18 -> 0 | N18: =+FORMATO!O27 -> 0 | O18: =+N18+$N$4*N18 -> 0
A19: Masa de molde | C19: g | E19: =VLOOKUP($D$17,$Q$4:$S$21,2,FALSE) -> #N/A | G19: =VLOOKUP($D$17,$Q$4:$S$21,2,FALSE) -> #N/A | I19: =VLOOKUP($H$17,$Q$4:$S$21,2,FALSE) -> #N/A | K19: =VLOOKUP($H$17,$Q$4:$S$21,2,FALSE) -> #N/A | M19: =VLOOKUP($L$17,$Q$4:$S$21,2,FALSE) -> #N/A | O19: =VLOOKUP($L$17,$Q$4:$S$21,2,FALSE) -> #N/A
A20: Contenido de humedad | C20: % | E20: =+E32 -> #DIV/0! | G20: =+G32 -> #DIV/0! | I20: =+I32 -> #DIV/0! | K20: =+K32 -> #DIV/0! | M20: =+M32 -> #DIV/0! | O20: =+O32 -> #DIV/0!
A21: Masa seca del suelo compactado | C21: g | E21: =(E18-E19)/(1+(E20/100)) -> #N/A | G21: =(G18-G19)/(1+(G20/100)) -> #N/A | I21: =(I18-I19)/(1+(I20/100)) -> #N/A | K21: =(K18-K19)/(1+(K20/100)) -> #N/A | M21: =(M18-M19)/(1+(M20/100)) -> #N/A | O21: =(O18-O19)/(1+(O20/100)) -> #N/A
A22: Volumen de molde | C22: cm3 | E22: =VLOOKUP($D$17,$Q$4:$S$21,3,FALSE) -> #N/A | G22: =VLOOKUP($D$17,$Q$4:$S$21,3,FALSE) -> #N/A | I22: =VLOOKUP($H$17,$Q$4:$S$21,3,FALSE) -> #N/A | K22: =VLOOKUP($H$17,$Q$4:$S$21,3,FALSE) -> #N/A | M22: =VLOOKUP($L$17,$Q$4:$S$21,3,FALSE) -> #N/A | O22: =VLOOKUP($L$17,$Q$4:$S$21,3,FALSE) -> #N/A
A23: Densidad seca | C23: g/cm3 | E23: =+E21/E22 -> #N/A | G23: =+G21/G22 -> #N/A | I23: =+I21/I22 -> #N/A | K23: =+K21/K22 -> #N/A | M23: =+M21/M22 -> #N/A | O23: =+O21/O22 -> #N/A
A24: Peso unitario seco | C24: kN/m3 | E24: =MROUND(9.8066*E23,0.02) -> #N/A | G24: =MROUND(9.8066*G23,0.02) -> #N/A | I24: =MROUND(9.8066*I23,0.02) -> #N/A | K24: =MROUND(9.8066*K23,0.02) -> #N/A | M24: =MROUND(9.8066*M23,0.02) -> #N/A | O24: =MROUND(9.8066*O23,0.02) -> #N/A
A25: DETERMINACION DE LA HUMEDAD DE COMPACTACION | Q25: =+J3-0.5 -> -0.5 | R25: =+J3+0.5 -> 0.5
A26: Código tara | C26: - | D26: =+FORMATO!D29 -> 0 | F26: =+FORMATO!F29 -> 0 | H26: =+FORMATO!H29 -> 0 | J26: =+FORMATO!J29 -> 0 | L26: =+FORMATO!L29 -> 0 | N26: =+FORMATO!O29 -> 0
A27: Masa de tara | C27: g | D27: =+FORMATO!D30 -> 0 | E27: =+D27+$N$5*D27 -> 0 | F27: =+FORMATO!F30 -> 0 | G27: =+F27+$N$5*F27 -> 0 | H27: =+FORMATO!H30 -> 0 | I27: =+H27+$N$5*H27 -> 0 | J27: =+FORMATO!J30 -> 0 | K27: =+J27+$N$5*J27 -> 0 | L27: =+FORMATO!L30 -> 0 | M27: =+L27+$N$5*L27 -> 0 | N27: =+FORMATO!O30 -> 0 | O27: =+N27+$N$5*N27 -> 0 | Q27: Masa minima humedad (g) | S27: 2500
A28: Masa de suelo húmedo + tara | C28: g | D28: =+FORMATO!D31 -> 0 | E28: =+D28+$N$5*D28 -> 0 | F28: =+FORMATO!F31 -> 0 | G28: =+F28+$N$5*F28 -> 0 | H28: =+FORMATO!H31 -> 0 | I28: =+H28+$N$5*H28 -> 0 | J28: =+FORMATO!J31 -> 0 | K28: =+J28+$N$5*J28 -> 0 | L28: =+FORMATO!L31 -> 0 | M28: =+L28+$N$5*L28 -> 0 | N28: =+FORMATO!O31 -> 0 | O28: =+N28+$N$5*N28 -> 0 | Q28: =+D26 -> 0 | R28: =+D28-D27 -> 0 | S28: =+IF(R28>$S$27,"cumple","no cumple") -> no cumple
A29: Masa de suelo seco + tara | C29: g | D29: =+FORMATO!D33 -> 0 | E29: =+D29+$N$5*D29 -> 0 | F29: =+FORMATO!F33 -> 0 | G29: =+F29+$N$5*F29 -> 0 | H29: =+FORMATO!H33 -> 0 | I29: =+H29+$N$5*H29 -> 0 | J29: =+FORMATO!J33 -> 0 | K29: =+J29+$N$5*J29 -> 0 | L29: =+FORMATO!L33 -> 0 | M29: =+L29+$N$5*L29 -> 0 | N29: =+FORMATO!O33 -> 0 | O29: =+N29+$N$5*N29 -> 0 | Q29: =+H26 -> 0 | R29: =+H28-H27 -> 0 | S29: =+IF(R29>$S$27,"cumple","no cumple") -> no cumple
A30: Masa de suelo seco + tara CONSTANTE | C30: g | D30: =+FORMATO!D34 -> 0 | E30: =+D30+$N$5*D30 -> 0 | F30: =+FORMATO!F34 -> 0 | G30: =+F30+$N$5*F30 -> 0 | H30: =+FORMATO!H34 -> 0 | I30: =+H30+$N$5*H30 -> 0 | J30: =+FORMATO!J34 -> 0 | K30: =+J30+$N$5*J30 -> 0 | L30: =+FORMATO!L34 -> 0 | M30: =+L30+$N$5*L30 -> 0 | N30: =+FORMATO!O34 -> 0 | O30: =+N30+$N$5*N30 -> 0 | Q30: =+L26 -> 0 | R30: =+L28-L27 -> 0 | S30: =+IF(R30>$S$27,"cumple","no cumple") -> no cumple
A31: Masa de agua | C31: g | E31: =+E28-E30 -> 0 | G31: =+G28-G30 -> 0 | I31: =+I28-I30 -> 0 | K31: =+K28-K30 -> 0 | M31: =+M28-M30 -> 0 | O31: =+O28-O30 -> 0
A32: Contenido de humedad | C32: % | E32: =+(E31/(E30-E27))*100 -> #DIV/0! | G32: =+(G31/(G30-G27))*100 -> #DIV/0! | I32: =+(I31/(I30-I27))*100 -> #DIV/0! | K32: =+(K31/(K30-K27))*100 -> #DIV/0! | M32: =+(M31/(M30-M27))*100 -> #DIV/0! | O32: =+(O31/(O30-O27))*100 -> #DIV/0!
A33: HINCHAMIENTO
A34: FECHA | B34: HORA | C34: TIEMPO | D34: DIAL (0.001 in) | F34: EXPANSION | H34: DIAL (0.001 in) | J34: EXPANSION | L34: DIAL (0.001 in) | N34: EXPANSION
C35: Hr. | F35: mm | G35: % | J35: mm | K35: % | N35: mm | O35: %
A36: 0 | B36: =IF(A36="","","11:00:00") -> 11:00:00 | C36: 0 | D36: =+FORMATO!O40 -> 0 | F36: =IF(D36="","",(D36-$D$36)*0.001*2.54*10) -> 0 | G36: =IF(F36="","",F36/$W$4*100) -> #N/A | H36: =+FORMATO!P40 -> 0 | J36: =IF(H36="","",(H36-$H$36)*0.001*2.54*10) -> 0 | K36: =IF(J36="","",J36/$W$4*100) -> #N/A | L36: =+FORMATO!Q40 -> 0 | N36: =IF(L36="","",(L36-$L$36)*0.001*2.54*10) -> 0 | O36: =IF(N36="","",N36/$W$4*100) -> #N/A
A37: =IF(A36="","",1+A36) -> 1 | B37: =B36 -> 11:00:00 | C37: 24 | D37: =+FORMATO!O41 -> 0 | F37: =IF(D37="","",(D37-$D$36)*0.001*2.54*10) -> 0 | G37: =IF(F37="","",F37/$W$4*100) -> #N/A | H37: =+FORMATO!P41 -> 0 | J37: =IF(H37="","",(H37-$H$36)*0.001*2.54*10) -> 0 | K37: =IF(J37="","",J37/$W$4*100) -> #N/A | L37: =+FORMATO!Q41 -> 0 | N37: =IF(L37="","",(L37-$L$36)*0.001*2.54*10) -> 0 | O37: =IF(N37="","",N37/$W$4*100) -> #N/A
A38: =IF(A37="","",1+A37) -> 2 | B38: =B37 -> 11:00:00 | C38: 48 | D38: =+FORMATO!O42 -> 0 | F38: =IF(D38="","",(D38-$D$36)*0.001*2.54*10) -> 0 | G38: =IF(F38="","",F38/$W$4*100) -> #N/A | H38: =+FORMATO!P42 -> 0 | J38: =IF(H38="","",(H38-$H$36)*0.001*2.54*10) -> 0 | K38: =IF(J38="","",J38/$W$4*100) -> #N/A | L38: =+FORMATO!Q42 -> 0 | N38: =IF(L38="","",(L38-$L$36)*0.001*2.54*10) -> 0 | O38: =IF(N38="","",N38/$W$4*100) -> #N/A
A39: =IF(A38="","",1+A38) -> 3 | B39: =B38 -> 11:00:00 | C39: 72 | D39: =+FORMATO!O43 -> 0 | F39: =IF(D39="","",(D39-$D$36)*0.001*2.54*10) -> 0 | G39: =IF(F39="","",F39/$W$4*100) -> #N/A | H39: =+FORMATO!P43 -> 0 | J39: =IF(H39="","",(H39-$H$36)*0.001*2.54*10) -> 0 | K39: =IF(J39="","",J39/$W$4*100) -> #N/A | L39: =+FORMATO!Q43 -> 0 | N39: =IF(L39="","",(L39-$L$36)*0.001*2.54*10) -> 0 | O39: =IF(N39="","",N39/$W$4*100) -> #N/A
A40: =IF(A39="","",1+A39) -> 4 | B40: =B39 -> 11:00:00 | C40: 96 | D40: =+FORMATO!O44 -> 0 | F40: =IF(D40="","",(D40-$D$36)*0.001*2.54*10) -> 0 | G40: =IF(F40="","",F40/$W$4*100) -> #N/A | H40: =+FORMATO!P44 -> 0 | J40: =IF(H40="","",(H40-$H$36)*0.001*2.54*10) -> 0 | K40: =IF(J40="","",J40/$W$4*100) -> #N/A | L40: =+FORMATO!Q44 -> 0 | N40: =IF(L40="","",(L40-$L$36)*0.001*2.54*10) -> 0 | O40: =IF(N40="","",N40/$W$4*100) -> #N/A
A41: LECTURA DE PENETRACION
A42: Penetración | C42: Tension Estandar SS | D42: =+D15 -> 56 | H42: =+H15 -> 25 | L42: =+L15 -> 10
...

Sheet INCERT
D1: INFORME DE ESTIMACIÓN DE INCERTIDUMBRE | K1: Código: | L1: F-LEM-P-10.01
K2: Versión: | L2: 3
K3: Fecha: | L3: 46146
K4: Página: | L4: 1 de 1
B6: Método: | C6: Standard Test Method for California Bearing Ratio (CBR) of Laboratory-Compacted Soils
B7: Norma: | C7: ASTM D1883-21
B8: Matriz: | C8: Suelo
B9: Mensurando: | C9: Determinación de la relación de carga de California (CBR) de muestras compactadas de laboratorio
B11: Paso 1. Definición del proceso de medición | L11: Paso 1. Definición del proceso de medición
B13: Variables: | E13: Fórmula: | H13: Paso 2. Definición de las variables aleatorias | L13: Variables: | Q13: Fórmula: | S13: Paso 2. Definición de las variables aleatorias
B14: F = fuerza, kg, | L14: Msac = masa seca de suelo compactado, g,
B15: A = area del pizon, cm2 | L15: Mm + ws = masa húmeda de suelo moldeado más masa del molde, g,
L16: Mm = masa del molde, g,
B17: Equipos a utilizar: | L17: wac = determinación del contenido de agua
L18: Vm = volumen del molde cm3
B19: Equipo cbr, 0,1kgf | L19: ρd = densidad seca de la muestra compactada, g/cm3.
L21: Equipos a utilizar:
L23: Balanza con resolución de lectura de 1g
B25: CALCULO: CBR 100% | K25: CALCULO: CBR 100%
B27: Fuentes | C27: Unidades | D27: Valor | E27: Incertidumbre Original | F27: Distribución | G27: Incertidumbre Estándar u(xi) | H27: Coeficiente de Sensibilidad | I27: Contribución ui(y) | K27: Fuentes | L27: Unidades | M27: Valor | N27: Incertidumbre Original | O27: Distribución | P27: Incertidumbre Estándar u(xi) | Q27: Coeficiente de Sensibilidad | R27: Contribución ui(y)
B28: C.B.R. (0.10 in) 56 Golpes (%) | C28: % | D28: =+D29/D32*14.223343334285*100/1000 -> 0.083166519 | K28: C.B.R. (100% P.U.S.) 0.10 in : | L28: % | M28: =+(M33-M30)*(M31-M29)/(M32-M30)+M29 -> #N/A
B29: Fuerza (lectura) | C29: kgf | D29: =+'INFORME-2'!$V$55*D32*0.393701^2*0.453592 -> 1.1299712 | G29: =SQRT((G30*G30+G31*G31)) -> 4.9418355 | H29: =1/D32*14.223343334285*100/1000 -> 0.073600563 | I29: =+H29*G29 -> 0.36372188 | J29: A | K29: C.B.R. (0.10 in) 56 Golpes (%) | L29: % | M29: =+M50 -> 0.083166519 | P29: =+R55 -> 0.36372188 | Q29: =+(M30-M33)/(M32-M30)+1 -> #N/A | R29: =+P29*Q29 -> #N/A
B30: Certificado de Calibración | C30: kgf | E30: =+$D$58 -> -9.8835024 | F30: Norma, K=2 | G30: =+E30/2 -> -4.9417512 | J30: B | K30: Peso unitario seco 56 Golpes (kN/m3) | L30: kN/m3 | M30: =+M70 -> #N/A | P30: =+R78 -> #DIV/0! | Q30: =(+(M31-M29)*(M33-M32)/(M32-M30)^2)*(-1) -> #N/A | R30: =+P30*Q30 -> #DIV/0!
B31: Resolución | C31: kgf | E31: 0.1 | F31: Rectangular | G31: =+E31/SQRT(3)/2 -> 0.028867513 | J31: C | K31: C.B.R. (0.10 in) 25 Golpes (%): | L31: % | M31: =+W50 -> 0.083166519 | P31: =+AB55 -> 0.0021337174 | Q31: =+(M33-M30)/(M32-M30)*(-1) -> #N/A | R31: =+P31*Q31 -> #N/A
B32: Area piston | C32: cm2 | D32: =+DATOS!$D$9 -> 19.325047 | G32: =I54*0.01 -> 0.0043482789 | H32: =14.223343334285*100/1000*D29/(D32^2) -> 0.004303561 | I32: =+H32*G32 -> 1.8713084e-05 | J32: D | K32: Peso unitario seco 25 Golpes (kN/m3) | L32: kN/m3 | M32: =+W70 -> #N/A | P32: =+AB72 -> #DIV/0! | Q32: =((M31-M29)*(M30-M33)/(M32-M30)^2) -> #N/A | R32: =+P32*Q32 -> #DIV/0!
B33: factor de presición | C33: % | D33: =+PRECISION!$C$6 -> 2.0257509 | F33: Norma, K=1 | G33: =D33/SQRT(1) -> 2.0257509 | H33: 1 | I33: =+G33*H33 -> 2.0257509 | J33: E | K33: Peso unitario seco PROCTOR | L33: kN/m3 | M33: =+DATOS!J2 -> 0 | P33: 0.02 | Q33: =+(M31-M29)/(M32-M30) -> #N/A | R33: =+P33*Q33 -> #N/A
B34: Incertidumbre Estándar Combinada | H34: % | I34: =+SQRT(I29^2+I32^2+I33^2) -> 2.0581449 | K34: factor de presición | L34: % | M34: =+PRECISION!$C$6 -> 2.0257509 | O34: Norma, K=1 | P34: =M34/SQRT(1) -> 2.0257509 | Q34: 1 | R34: =+P34*Q34 -> 2.0257509
B35: Incertidumbre Expandida, K = 2 | H35: % | I35: =I34*2 -> 4.1162897 | K35: Incertidumbre Estándar Combinada | Q35: % | R35: =+SQRT(R29^2+R32^2+R31^2+R30^2+R33^2+R34^2) -> #N/A
K36: Incertidumbre Expandida, K = 2 | Q36: % | R36: =R35*2 -> #N/A
B38: Fuentes | C38: Unidades | D38: Valor | E38: Incertidumbre Original | F38: Distribución | G38: Incertidumbre Estándar u(xi) | H38: Coeficiente de Sensibilidad | I38: Contribución ui(y) | K38: Fuentes | L38: Unidades | M38: Valor | N38: Incertidumbre Original | O38: Distribución | P38: Incertidumbre Estándar u(xi) | Q38: Coeficiente de Sensibilidad | R38: Contribución ui(y)
B39: C.B.R. (0.20 in) 56 Golpes (%) | C39: % | D39: =+D40/D43*14.223343334285*100/1500 -> 0.053890683 | K39: C.B.R. (100% P.U.S.) 0.20 in : | L39: % | M39: =+(M44-M41)*(M42-M40)/(M43-M41)+M40 -> #N/A
B40: Fuerza (lectura) | C40: kgf | D40: =+'INFORME-2'!$V$56*D43*0.393701^2*0.453592 -> 1.0983071 | G40: =SQRT((G41*G41+G42*G42)) -> 0.49754323 | H40: =1/D43*14.223343334285*100/1000 -> 0.073600563 | I40: =+H40*G40 -> 0.036619462 | K40: C.B.R. (0.20 in) 56 Golpes (%): | L40: % | M40: =+M59 -> 0.053890683 | P40: =+R64 -> 0.036619467 | Q40: =+(M41-M44)/(M43-M41)+1 -> #N/A | R40: =+P40*Q40 -> #N/A
B41: Certificado de Calibración | C41: kgf | E41: =+$D$59 -> -0.99341016 | F41: Norma, K=2 | G41: =+E41/2 -> -0.49670508 | K41: Peso unitario seco 56 Golpes (kN/m3) | L41: kN/m3 | M41: =+M70 -> #N/A | P41: =+R72 -> #DIV/0! | Q41: =(+(M42-M40)*(M44-M43)/(M43-M41)^2)*(-1) -> #N/A | R41: =+P41*Q41 -> #DIV/0!
B42: Resolución | C42: kgf | E42: 0.1 | F42: Rectangular | G42: =+E42/SQRT(3)/2 -> 0.028867513 | K42: C.B.R. (0.20 in) 25 Golpes (%): | L42: % | M42: =+W59 -> 0.053890683 | P42: =+AB64 -> #DIV/0! | Q42: =+(M44-M41)/(M43-M41)*(-1) -> #N/A | R42: =+P42*Q42 -> #DIV/0!
B43: Area piston | C43: cm2 | D43: =+DATOS!$D$9 -> 19.325047 | G43: =I54*0.01 -> 0.0043482789 | H43: =14.223343334285*100/1000*D40/(D43^2) -> 0.0041829665 | I43: =+H43*G43 -> 1.8188705e-05 | K43: Peso unitario seco 25 Golpes (kN/m3) | L43: kN/m3 | M43: =+W70 -> #N/A | P43: =+AB72 -> #DIV/0! | Q43: =((M42-M40)*(M41-M44)/(M43-M41)^2) -> #N/A | R43: =+P43*Q43 -> #DIV/0!
B44: factor de presición | C44: % | D44: =+PRECISION!$C$6 -> 2.0257509 | F44: Norma, K=1 | G44: =D44/SQRT(1) -> 2.0257509 | H44: 1 | I44: =+G44*H44 -> 2.0257509 | K44: Peso unitario seco PROCTOR | L44: kN/m3 | M44: =+DATOS!J2 -> 0 | P44: 0.02 | Q44: =+(M42-M40)/(M43-M41) -> #N/A | R44: =+P44*Q44 -> #N/A
B45: Incertidumbre Estándar Combinada | H45: % | I45: =+SQRT(I40^2+I43^2+I44^2) -> 2.0260818 | K45: factor de presición | L45: % | M45: =+PRECISION!$C$6 -> 2.0257509 | O45: Norma, K=1 | P45: =M45/SQRT(1) -> 2.0257509 | Q45: 1 | R45: =+P45*Q45 -> 2.0257509
B46: Incertidumbre Expandida, K = 2 | H46: % | I46: =I45*2 -> 4.0521637 | K46: Incertidumbre Estándar Combinada | Q46: % | R46: =+SQRT(R40^2+R43^2+R42^2+R41^2+R44^2+R45^2) -> #N/A
K47: Incertidumbre Expandida, K = 2 | Q47: % | R47: =R46*2 -> #N/A
B48: Fuentes | C48: Unidades | D48: Valor | E48: Incertidumbre Original | F48: Distribución | G48: Incertidumbre Estándar u(xi) | H48: Coeficiente de Sensibilidad | I48: Contribución ui(y)
...

Sheet Balanza
B2: CALIBRACION DE LA BALANZA | N2: CALIBRACION DE LA BALANZA
B7: Correccion | C7: -1.49e-06 | L7: Corrección | M7: -3.29e-06
B8: Variables | C8: 1.14 | D8: 2.48e-10 | L8: Variables | M8: 0.00416 | N8: 2.43e-10
B9: Ecuacion | C9: 2*RAIZ(1.14+0.000000000248*R2) | L9: Ecuación | M9: 2*RAIZ(0.00416+0.000000000243*R2)
B10: Resolucion | C10: 1 | D10: g | L10: Resolución | M10: 0.1 | N10: g
B11: Codigo | C11: EQP-0054 | L11: Código | M11: EQP-0046
B12: Fecha de calibración | D12: 46160 | L12: Fecha última calibración | O12: 46132
B13: ITEM | C13: MES | D13: 500 | E13: 1000 | F13: 5000 | G13: 10000 | H13: 15000 | I13: 20000 | L13: ITEM | M13: MES | N13: 200 | O13: 500 | P13: 1000 | Q13: 5000 | R13: 10000
C17: DESV STD | D17: 0 | E17: 0 | F17: 0 | G17: 0 | H17: 0 | I17: 0 | M17: DESV STD | N17: 0 | O17: 0 | P17: 0 | Q17: 0 | R17: 0
B19: Busqueda de Repetibilidad de la masa | L19: Busqueda de Repetibilidad de la masa
D20: =+D13 -> 500 | E20: =+E13 -> 1000 | F20: =+F13 -> 5000 | G20: =+G13 -> 10000 | H20: =+H13 -> 15000 | I20: 20000
D21: =D17 -> 0 | E21: =E17 -> 0 | F21: =F17 -> 0 | G21: =G17 -> 0 | H21: =H17 -> 0 | I21: =I17 -> 0 | N21: =+N13 -> 200 | O21: =+O13 -> 500 | P21: =+P13 -> 1000 | Q21: =+Q13 -> 5000 | R21: =+R13 -> 10000
N22: =N17 -> 0 | O22: =O17 -> 0 | P22: =P17 -> 0 | Q22: =Q17 -> 0 | R22: =R17 -> 0
B23: ENSAYO DE LA MUESTRA | L23: ENSAYO DE LA MUESTRA
B24: Masa de molde+suelo moldeado | D24: =+DATOS!$E$18 -> 0 | E24: =IF(D24<=$D$20,$D$21,IF(AND(D24>$D$20,D24<=$E$20),$E$21,IF(AND(D24>$E$20,D24<=$F$20),$F$21,IF(AND(D24>$F$20,D24<=$G$20),$G$21,IF(AND(D24>$G$20,D24<=$H$20),$H$21,$H$21))))) -> 0 | M24: Tara + suelo húmedo | O24: =+INCERT!M96 -> 0 | P24: =IF(AND(O24<=$R$21,O24>$Q$21),$R$22,IF(AND(O24<=$Q$21,O24>$P$21),$Q$22,IF(AND(O24<=$P$21,O24>$O$21),$P$22,IF(AND(O24<=$O$21,O24>$N$21),$O$22,IF(O24<=$N$21,$N$22))))) -> 0
B25: Masa de molde | D25: =+DATOS!$E$19 -> #N/A | E25: =IF(D25<=$D$20,$D$21,IF(AND(D25>$D$20,D25<=$E$20),$E$21,IF(AND(D25>$E$20,D25<=$F$20),$F$21,IF(AND(D25>$F$20,D25<=$G$20),$G$21,IF(AND(D25>$G$20,D25<=$H$20),$H$21,$H$21))))) -> #N/A | M25: Tara + suelo seco 2 | O25: =+INCERT!M100 -> 0 | P25: =IF(AND(O25<=$R$21,O25>$Q$21),$R$22,IF(AND(O25<=$Q$21,O25>$P$21),$Q$22,IF(AND(O25<=$P$21,O25>$O$21),$P$22,IF(AND(O25<=$O$21,O25>$N$21),$O$22,IF(O25<=$N$21,$N$22))))) -> 0
M26: Peso de tara | O26: =+INCERT!M104 -> 0 | P26: =IF(AND(O26<=$R$21,O26>$Q$21),$R$22,IF(AND(O26<=$Q$21,O26>$P$21),$Q$22,IF(AND(O26<=$P$21,O26>$O$21),$P$22,IF(AND(O26<=$O$21,O26>$N$21),$O$22,IF(O26<=$N$21,$N$22))))) -> 0
B27: Masa de molde+suelo moldeado | D27: =+DATOS!$I$18 -> 0 | E27: =IF(D27<=$D$20,$D$21,IF(AND(D27>$D$20,D27<=$E$20),$E$21,IF(AND(D27>$E$20,D27<=$F$20),$F$21,IF(AND(D27>$F$20,D27<=$G$20),$G$21,IF(AND(D27>$G$20,D27<=$H$20),$H$21,$H$21))))) -> 0
B28: Masa de molde | D28: =+DATOS!$I$19 -> #N/A | E28: =IF(D28<=$D$20,$D$21,IF(AND(D28>$D$20,D28<=$E$20),$E$21,IF(AND(D28>$E$20,D28<=$F$20),$F$21,IF(AND(D28>$F$20,D28<=$G$20),$G$21,IF(AND(D28>$G$20,D28<=$H$20),$H$21,$H$21))))) -> #N/A | M28: Tara + suelo húmedo | O28: =+INCERT!W96 -> 0 | P28: =IF(AND(O28<=$R$21,O28>$Q$21),$R$22,IF(AND(O28<=$Q$21,O28>$P$21),$Q$22,IF(AND(O28<=$P$21,O28>$O$21),$P$22,IF(AND(O28<=$O$21,O28>$N$21),$O$22,IF(O28<=$N$21,$N$22))))) -> 0
M29: Tara + suelo seco 2 | O29: =+INCERT!W100 -> 0 | P29: =IF(AND(O29<=$R$21,O29>$Q$21),$R$22,IF(AND(O29<=$Q$21,O29>$P$21),$Q$22,IF(AND(O29<=$P$21,O29>$O$21),$P$22,IF(AND(O29<=$O$21,O29>$N$21),$O$22,IF(O29<=$N$21,$N$22))))) -> 0
M30: Peso de tara | O30: =+INCERT!W104 -> 0 | P30: =IF(AND(O30<=$R$21,O30>$Q$21),$R$22,IF(AND(O30<=$Q$21,O30>$P$21),$Q$22,IF(AND(O30<=$P$21,O30>$O$21),$P$22,IF(AND(O30<=$O$21,O30>$N$21),$O$22,IF(O30<=$N$21,$N$22))))) -> 0

Sheet PRECISION
B3: Factor de precision CBR | I3: Factor de precision CONTENIDO HUMEDAD
B4: Fecha de evaluacion: | C4: 45789 | I4: Fecha de evaluacion: | J4: 46064
B6: Desviacion Estándar Repetibilidad (Sr) | C6: 2.0257509 | I6: Desviacion Estándar Repetibilidad (Sr) | J6: 0.11030261
B7: Desviacion Estándar Reproducibilidad (SR) | C7: 2.1777537 | I7: Desviacion Estándar Reproducibilidad (SR) | J7: 0.11377365

Sheet PRECISION (2)
B2: INCERTIDUMBRE ESTANDAR -TIPO A | I2: INCERTIDUMBRE ESTANDAR -TIPO A
B3: TALLER DE INCERTIDUMBRE ESTANDAR -TIPO A | I3: TALLER DE INCERTIDUMBRE ESTANDAR -TIPO A
B4: Fecha de evaluacion: | C4: 45625 | I4: Fecha de evaluacion: | J4: 45625
B6: 1-Calcular la Incertidumbre estandar CONTENIDO HUMEDAD | I6: 1-Calcular la Incertidumbre estandar CONTENIDO HUMEDAD
B7: analista(p=2) | C7: DEY-G | E7: DEY-F | I7: analista(p=2) | J7: DEY-CH | L7: DEY-SC
B8: Réplicas de medición (n=9) | C8: 40.95 | E8: 12.92 | I8: Réplicas de medición (n=9) | J8: 22.3 | L8: 7.6
C9: 41.17 | E9: 13.74 | J9: 22.3 | L9: 7.8
C10: 39.67 | E10: 13.68 | J10: 22.9 | L10: 7.7
C11: 38.6 | E11: 12.95 | J11: 22.2 | L11: 7.6
C12: 38.9 | E12: 12.73 | J12: 22.6 | L12: 7.5
C13: 38.91 | E13: 13.52 | J13: 22.4 | L13: 7.8
B20: n | C20: =COUNT(C8:C19) -> 6 | I20: n | J20: =COUNT(J8:J19) -> 6
B21: p | C21: =COUNTA(C7:F7) -> 2 | I21: p | J21: =COUNTA(J7:M7) -> 2
B23: No Datos | C23: =COUNT(C8:C19) -> 6 | D23: =COUNT(D8:D19) -> 0 | E23: =COUNT(E8:E19) -> 6 | F23: =COUNT(F8:F19) -> 0 | I23: No Datos | J23: =COUNT(J8:J19) -> 6 | K23: =COUNT(K8:K19) -> 0 | L23: =COUNT(L8:L19) -> 6 | M23: =COUNT(M8:M19) -> 0
B24: Promedio (xi) | C24: =AVERAGE(C8:C19) -> 39.7 | E24: =AVERAGE(E8:E19) -> 13.256667 | I24: Promedio (xi) | J24: =AVERAGE(J8:J19) -> 22.45 | L24: =AVERAGE(L8:L19) -> 7.6666667
B25: Desviación Estándar (si) | C25: =STDEV(C8:C19) -> 1.1134092 | E25: =STDEV(E8:E19) -> 0.43975751 | I25: Desviación Estándar (si) | J25: =STDEV(J8:J19) -> 0.25884358 | L25: =STDEV(L8:L19) -> 0.12110601
B26: Varianza (s2i) | C26: =VAR(C8:C19) -> 1.23968 | E26: =VAR(E8:E19) -> 0.19338667 | I26: Varianza (s2i) | J26: =VAR(J8:J19) -> 0.067 | L26: =VAR(L8:L19) -> 0.014666667
B28: T1 | C28: =+C23*C24+D23*D24+E23*E24+F23*F24 -> 317.74 | I28: T1 | J28: =+J23*J24+K23*K24+L23*L24+M23*M24 -> 180.7
B29: T2 | C29: =+C23*POWER(C24,2)+D23*POWER(D24,2)+E23*POWER(E24,2)+F23*POWER(F24,2) -> 10510.975 | I29: T2 | J29: =+J23*POWER(J24,2)+K23*POWER(K24,2)+L23*POWER(L24,2)+M23*POWER(M24,2) -> 3376.6817
B30: T3 | C30: =+SUM(C23:F23) -> 12 | I30: T3 | J30: =+SUM(J23:M23) -> 12
B31: T4 | C31: =+POWER(C23,2)+POWER(D23,2)+POWER(E23,2)+POWER(F23,2) -> 72 | I31: T4 | J31: =+POWER(J23,2)+POWER(K23,2)+POWER(L23,2)+POWER(M23,2) -> 72
B32: T5 | C32: =(C20-1)*SUM(C26:F26) -> 7.1653333 | I32: T5 | J32: =(J20-1)*SUM(J26:M26) -> 0.40833333
B33: Varianza Repetibilidad (Sr2 ) | C33: =ABS((C32/(C30-C21))) -> 0.71653333 | I33: Varianza Repetibilidad (Sr2 ) | J33: =ABS((J32/(J30-J21))) -> 0.040833333
B34: Varianza entre Laboratorios (SL2) | C34: =ABS((((C29*C30-(C28^2))/(C30*(C21-1)))-(C33))*((C30*(C21-1))/((C30^2)-C31))) -> 349.50552 | I34: Varianza entre Laboratorios (SL2) | J34: =ABS((((J29*J30-(J28^2))/(J30*(J21-1)))-(J33))*((J30*(J21-1))/((J30^2)-J31))) -> 109.26667
B35: Varianza Reproducibilidad (SR2) | C35: =(C33+C34)/1000000 -> 0.00035022205 | I35: Varianza Reproducibilidad (SR2) | J35: =(J33+J34)/1000000 -> 0.0001093075
B36: Desviacion Estándar Repetibilidad (Sr) | C36: =SQRT(C33) -> 0.84648292 | I36: Desviacion Estándar Repetibilidad (Sr) | J36: =SQRT(J33) -> 0.20207259
B37: Desviacion Estándar Reproducibilidad (SR) | C37: =+SQRT(C33+C34) -> 18.714221 | I37: Desviacion Estándar Reproducibilidad (SR) | J37: =+SQRT(J33+J34) -> 10.455023

Sheet cbr graficos
A1: 1
A2: 1
S29: 3.0572485 | T29: 0 | V29: 4.4910605 | W29: 0 | Z29: 0 | AA29: 4.4910605
S30: 3.0572485 | T30: 1.932 | V30: 4.4910605 | W30: 1.932 | Z30: 1.932 | AA30: 1.932
S32: 2.9835906 | T32: 0 | V32: 4.0982101 | W32: 0 | Z32: 0 | AA32: 4.0982101
S33: 2.9835906 | T33: 1.8354 | V33: 4.0982101 | W33: 1.8354 | Z33: 1.8354 | AA33: 1.8354
J41: 0 | K41: 2.9835906
J43: 1.8354 | K43: 1.8354
J44: 0 | K44: 0
J46: 1.7388 | K46: 1.7388
