Workbook
Name ___CC2: [1]Sucs!$L$6
Name __CC2: [1]Sucs!$L$6
Name _CC1: [2]Sucs!$L$6
Name _CC2: [1]Sucs!$L$6
Name _CU1: [2]Sucs!$L$5
Name _IP1: [2]Sucs!$L$4
Name _L1: #REF!
Name _L1: #REF!
Name _L1: #REF!
Name _L1: #REF!
Name _L1: #REF!
Name _L1: #REF!
Name _L1: #REF!
Name _Ll1: [2]Sucs!$L$3
Name _W1: #REF!
Name _W1: #REF!
Name _W1: #REF!
Name _W1: #REF!
Name _W1: #REF!
Name _W1: #REF!
Name _W1: #REF!
Name Abra: [3]Sucs!$C$3
Name CC: #REF!
Name CC: #REF!
Name CC: #REF!
Name CC: #REF!
Name CC: #REF!
Name CC: 'Sucs '!$L$6
Name CC: #REF!
Name CCf: '[2]Sucs(Fino)'!$L$6
Name CCVB: [4]Sucs!$L$3
Name CM: [5]BGA!$H$9
Name CU: #REF!
Name CU: #REF!
Name CU: #REF!
Name CU: #REF!
Name CU: #REF!
Name CU: 'Sucs '!$L$5
Name CU: #REF!
Name CUf: '[2]Sucs(Fino)'!$L$5
Name hh: #REF!
Name hh: #REF!
Name hh: #REF!
Name hh: #REF!
Name hh: #REF!
Name hh: #REF!
Name IP: #REF!
Name IP: #REF!
Name IP: #REF!
Name IP: #REF!
Name IP: #REF!
Name IP: 'Sucs '!$L$4
Name IP: #REF!
Name IPf: '[2]Sucs(Fino)'!$L$4
Name L: #REF!
Name L: #REF!
Name L: #REF!
Name L: #REF!
Name L: #REF!
Name L: #REF!

Sheet formato
K2: CLIENTE
K3: DIRECCIÓN **
K4: PROYECTO **
A5: LABORATORIO DE ENSAYO DE MATERIALES | K5: UBICACIÓN **
A6: FORMATO N° F-LEM-P-SU-19.01
K7: RECEPCIÓN N°
B8: MUESTRA | C8: N° OT | F8: FECHA DE ENSAYO | H8: REALIZADO | K8: F. EMISIÓN
K9: OT N°
A11: Standard Test Methods for Laboratory Compaction Characteristics of Soil Using Modified Effort (56,000 ft-lbf/ft³ (2,700 kN-m/m³)) | K11: CÓDIGO DE LA MUESTRA
A12: ASTM D1557-12 (Reapproved 2021) | K12: FECHA DE RECEPCIÓN
K13: FECHA DE EJECUCIÓN
A14: Densidad húmeda | C14: und
A15: Prueba Nº | C15: -- | D15: 1 | F15: 2 | G15: 3 | H15: 4 | I15: 5 | K15: CANTERA/SONDAJE **
A16: Número de capas | C16: -- | D16: 5 | F16: 5 | G16: 5 | H16: 5 | I16: 5 | K16: N° MUESTRA **
A17: Número de golpes | C17: -- | K17: TIPO DE MUESTRA**
A18: Masa de suelo húmedo y molde (A) | C18: g
A19: Masa del molde compactación (B) | C19: g
A20: Masa suelo compactado (C=A-B) | C20: g
A21: Volúmen de molde compactación (D) | C21: cm3
A22: Densidad húmeda (X= C/D) | C22: g/cm3
A23: Contenido humedad - Densidad Seca
A24: Tara Nº
A25: Masa recipiente y suelo húmedo (E) | C25: g
A26: Masa recipiente y suelo seco 1 | C26: g
A27: Masa recipiente y suelo seco 2 | C27: g
A28: Masa recipiente y suelo seco 3 (F) | C28: g
A29: Masa de agua (Y= E-F) | C29: g
A30: Masa de recipiente (G) | C30: g
A31: Masa de suelo seco (Z= F-G) | C31: g
A32: Contenido de Humedad moldeo (W= Y/Z*100) | C32: %
A33: Densidad Seca X=(1+(W/100)) | C33: g/cm3
A34: Descripción de la muestra: | D34: * W Perdida de masa seca constante (adicional), para metodo B es < 0.1%
A35: Tipo de muestra | F35: Designaciòn de Tamices | G35: Masa retenida en el tamiz (g) | H35: % Retenido (1)/(2)*100 | I35: % Reten. Acumulado
A36: Condición de la muestra
A37: Tamaño máximo de la particula (in) | F37: 19 mm (¾ in)
A38: Forma de la particula | F38: 9.5 mm (3/8 in)
A39: Clasificación SUCS o Visual | F39: 4.75 mm (No. 4)
A40: Condiciones del ensayo | F40: Menor (No. 4)
A41: Método de ensayo | F41: Total
A42: Método de Preparación
...

Sheet Proctor
A6: LABORATORIO DE ENSAYO DE MATERIALES
A7: 0
A9: CLIENTE | B9: : | C9: =+formato!L2 -> 0 | J9: CÓDIGO | K9: : | L9: F-LEM-P-SU-19.02
A10: DIRECCIÓN ** | B10: : | C10: =+formato!L3 -> 0 | J10: RECEPCIÓN N° | K10: : | L10: =+formato!L7 -> 0
A11: PROYECTO ** | B11: : | C11: =+formato!L4 -> 0 | J11: OT N° | K11: : | L11: =+formato!L9 -> 0
A12: UBICACIÓN ** | B12: : | C12: =+formato!L5 -> 0 | J12: FECHA EMISIÓN: | K12: : | L12: =+formato!L9 -> 0
A13: ** Datos proporcionados por el cliente
A14: STANDARD TEST METHODS FOR LABORATORY COMPACTION CHARACTERISTICS OF SOIL USING MODIFIED EFFORT (56,000 ft-lbf/ft³ (2,700 kN-m/m³))
A15: ASTM D1557-12 (Reapproved 2021)
A17: DATOS DE LA MUESTRA
A18: CANTERA / SONDAJE ** | D18: : | E18: =+formato!L15 -> 0 | J18: CÓDIGO DE LA MUESTRA | K18: : | L18: =+formato!L11 -> 0
A19: N° MUESTRA ** | D19: : | E19: =+formato!L16 -> 0 | J19: FECHA DE RECEPCIÓN | K19: : | L19: =+formato!L12 -> 0
A20: TIPO DE MUESTRA ** | D20: : | E20: =+formato!L17 -> 0 | J20: FECHA DE EJECUCIÓN | K20: : | L20: =+formato!L13 -> 0 | M20: =+formato!F9 -> 0
A21: LUGAR DE ENSAYO | D21: : | E21: Laboratorio de materiales
A23: Ensayo de Granulometria: Porcentaje de la fracción retenida y pasante
E24: Designaciòn de Tamices | F24: Porcentaje Reten. Tamiz (%) | G24: Porcentaje acum. Reten. (%) | H24: Porcentaje que pasa el tamiz (%)
E25: 3/4 in. (19mm) | F25: =+DATOS!F52 -> #DIV/0! | G25: =+DATOS!G52 -> #DIV/0! | H25: =+DATOS!H52 -> #DIV/0!
E26: 3/8 in (9.5 mm) | F26: =+DATOS!F53 -> #DIV/0! | G26: =+DATOS!G53 -> #DIV/0! | H26: =+DATOS!H53 -> #DIV/0! | N26: Curva de 100% saturación
E27: No. 4 (4.75 mm) | F27: =+DATOS!F54 -> #DIV/0! | G27: =+DATOS!G54 -> #DIV/0! | H27: =+DATOS!H54 -> #DIV/0! | N27: gd | O27: wsat
E28: Menor (No. 4) | F28: =+DATOS!F55 -> #DIV/0! | G28: =+DATOS!G55 -> #DIV/0! | H28: =+DATOS!H55 -> #DIV/0! | N28: =+DATOS!K43 -> #DIV/0! | O28: =+DATOS!L43 -> #DIV/0!
A29: Contenido de agua saturación | N29: =+DATOS!K44 -> #DIV/0! | O29: =+DATOS!L44 -> #DIV/0!
A30: Gravedad especifica de sólido del suelo | F30: =+DATOS!F45 -> 2.81 | G30: =+DATOS!G45 -> 2.81 | H30: =+DATOS!H45 -> 2.81 | I30: =+DATOS!I45 -> 2.81 | N30: =+DATOS!K45 -> #DIV/0! | O30: =+DATOS!L45 -> #DIV/0!
A31: contenido de agua saturación (%) | F31: =+DATOS!F46 -> #DIV/0! | G31: =+DATOS!G46 -> #DIV/0! | H31: =+DATOS!H46 -> #DIV/0! | I31: =+DATOS!I46 -> #DIV/0! | N31: =+DATOS!K46 -> #DIV/0! | O31: =+DATOS!L46 -> #DIV/0!
A32: Gravedad especifica de sólido del suelo ASTM D854-14 (*): | G32: =DATOS!F41 -> 0
A33: Densidad húmeda-Densidad Seca-Contenido humedad
A34: Densidad húmeda
A35: Prueba Nº | F35: 1 | G35: 2 | H35: 3 | I35: 4
A36: Número de capas | F36: =+DATOS!F15 -> 5 | G36: =+DATOS!H15 -> 5 | H36: =+DATOS!J15 -> 5 | I36: =+DATOS!L15 -> 5
A37: Número de golpes | F37: =+DATOS!F16 -> 0 | G37: =+DATOS!H16 -> 0 | H37: =+DATOS!J16 -> 0 | I37: =+DATOS!L16 -> 0
A38: Densidad húmeda (g/cm3) | F38: =+DATOS!F21 -> #DIV/0! | G38: =+DATOS!H21 -> #DIV/0! | H38: =+DATOS!J21 -> #DIV/0! | I38: =+DATOS!L21 -> #DIV/0!
A39: Contenido humedad - Densidad Seca
A40: Contenido de Humedad suelo (%) | F40: =+DATOS!F31 -> #DIV/0! | G40: =+DATOS!H31 -> #DIV/0! | H40: =+DATOS!J31 -> #DIV/0! | I40: =+DATOS!L31 -> #DIV/0!
A41: Densidad Seca (g/cm3) | F41: =+DATOS!F32 -> #DIV/0! | G41: =+DATOS!H32 -> #DIV/0! | H41: =+DATOS!J32 -> #DIV/0! | I41: =+DATOS!L32 -> #DIV/0!
A42: Peso unitario seco del suelo kN/m3 | F42: =+DATOS!F33 -> #DIV/0! | G42: =+DATOS!H33 -> #DIV/0! | H42: =+DATOS!J33 -> #DIV/0! | I42: =+DATOS!L33 -> #DIV/0!
J44: Método de Ensayo | N44: VALORES (g/cm3)
J45: =+DATOS!C50 -> #DIV/0! | N45: 0 | O45: =+DATOS!J74 -> #DIV/0!
J46: PESO UNITARIO SECO MÁXIMO | N46: =+DATOS!J75 -> #DIV/0! | O46: =+O45 -> #DIV/0!
J47: =MROUND(N52,0.02) -> #DIV/0! | M47: AL 0.02 | N47: =+N46 -> #DIV/0! | O47: 0
J48: ÓPTIMO CONTENIDO DE AGUA
N49: VALORES (kN/m3)
...

Sheet DATOS
B2: STANDARD TEST METHODS FOR LABORATORY COMPACTION CHARACTERISTICS OF SOIL USING MODIFIED EFFORT (56,000 ft-lbf/ft³ (2,700 kN-m/m³))
B3: ASTM D1557-12(2021)
B5: COMPACTACIÓN | G5: HUMEDAD
B6: Informacion para la Correccion por Certificado de Calibración: balanza 30kg | G6: Informacion para la Correccion por Certificado de Calibración: balanza 15kg | L6: Información para la Corrección por Certificado de Calibración: Balanza 2.2kg | Q6: MOLDE | R6: OPERADORES
B7: Precision Balanza al | D7: 1 | E7: g | G7: Precision Balanza al 0.1g | L7: Precisión de la Balanza al 0.01g | Q7: - | R7: -
B8: Correccion | D8: =+Balanza!$C$7 -> -1.49e-06 | G8: Correccion | I8: =+Balanza!M7 -> -3.29e-06 | L8: Corrección | N8: =+Balanza!U7 -> 3.79e-06
B9: Codigo balanza | D9: =+Balanza!C11 -> EQP-0054 | G9: Codigo balanza | I9: =+Balanza!M11 -> EQP-0046 | L9: CODIGO | N9: =+Balanza!U11 -> EQP-0045
B10: Fecha de calibración | D10: =+Balanza!D12 -> 46160 | G10: Fecha de calibración | I10: =+Balanza!N12 -> 46132 | L10: Fecha | N10: =+Balanza!V12 -> 46132
B12: Compactación | E12: 1 | G12: 2 | I12: 3 | K12: 4 | M12: 5 | Q12: 6 in | R12: 4 in | S12: Molde
E13: DATOS | F13: CORRECCIÓN | G13: DATOS | H13: CORRECCIÓN | I13: DATOS | J13: CORRECCIÓN | K13: DATOS | L13: CORRECCIÓN | M13: DATOS | N13: CORRECCIÓN | Q13: 46112 | R13: 46043 | S13: VERIFICADO
B14: Prueba Nº | E14: 1 | G14: 2 | I14: 3 | K14: 4 | S14: PROX. VERIF.
B15: Número de capas | E15: 5 | F15: =E15 -> 5 | G15: =+E15 -> 5 | H15: =E15 -> 5 | I15: =+E15 -> 5 | J15: =E15 -> 5 | K15: =+E15 -> 5 | L15: =E15 -> 5 | Q15: 56 golpes | R15: 25 golpes | S15: Nº Golpes
B16: Número de golpes | E16: =+formato!D17 -> 0 | F16: =E16 -> 0 | G16: =+formato!F17 -> 0 | H16: =E16 -> 0 | I16: =+formato!G17 -> 0 | J16: =E16 -> 0 | K16: =+formato!H17 -> 0 | L16: =E16 -> 0 | Q16: 6819 | R16: 3875.5 | S16: Masa g
B17: Masa suelo + molde (g) | E17: =+formato!D18 -> 0 | F17: =E17+($D$8*E17) -> 0 | G17: =+formato!F18 -> 0 | H17: =G17+($D$8*G17) -> 0 | I17: =+formato!G18 -> 0 | J17: =I17+($D$8*I17) -> 0 | K17: =+formato!H18 -> 0 | L17: =K17+($D$8*K17) -> 0 | Q17: 2130 | R17: 939.81 | S17: Volumen cm3
B18: Masa molde (g) | E18: =+formato!D19 -> 0 | F18: =E18+($D$8*E18) -> 0 | G18: =+E18 -> 0 | H18: =G18+($D$8*G18) -> 0 | I18: =+E18 -> 0 | J18: =I18+($D$8*I18) -> 0 | K18: =+E18 -> 0 | L18: =K18+($D$8*K18) -> 0
B19: Masa suelo compactado (g) | E19: =+E17-E18 -> 0 | F19: =+F17-F18 -> 0 | G19: =+G17-G18 -> 0 | H19: =+H17-H18 -> 0 | I19: =+I17-I18 -> 0 | J19: =+J17-J18 -> 0 | K19: =+K17-K18 -> 0 | L19: =+L17-L18 -> 0
B20: Volúmen del molde (cm3) | E20: =+formato!D21 -> 0 | F20: =E20 -> 0 | G20: =+E20 -> 0 | H20: =E20 -> 0 | I20: =+E20 -> 0 | J20: =E20 -> 0 | K20: =E20 -> 0 | L20: =E20 -> 0 | Q20: metodo | R20: C | S20: B | T20: A
B21: Densidad húmeda (g/cm3) | E21: =+E19/E20 -> #DIV/0! | F21: =+F19/F20 -> #DIV/0! | G21: =+G19/G20 -> #DIV/0! | H21: =+H19/H20 -> #DIV/0! | I21: =+I19/I20 -> #DIV/0! | J21: =+J19/J20 -> #DIV/0! | K21: =+K19/K20 -> #DIV/0! | L21: =+L19/L20 -> #DIV/0! | O21: 4 digitos | R21: 3/4 | S21: 3/8 | T21: No 4
B22: Humedad (%) | Q22: Peso minimo | R22: 2500g | S22: 500g | T22: 100g
B23: Tara Nº | E23: =+formato!D24 -> 0 | G23: =+formato!F24 -> 0 | I23: =+formato!G24 -> 0 | K23: =+formato!H24 -> 0 | Q23: precision bal | R23: 0.1 g | S23: 0.1g | T23: 0.01g
B24: Tara + suelo húmedo (g) | E24: =+formato!D25 -> 0 | F24: =IF($C$50="A",E24+($I$8*E24),E24+($N$8*E24)) -> #DIV/0! | G24: =+formato!F25 -> 0 | H24: =IF($C$50="A",G24+($I$8*G24),G24+($N$8*G24)) -> #DIV/0! | I24: =+formato!G25 -> 0 | J24: =IF($C$50="A",I24+($I$8*I24),I24+($N$8*I24)) -> #DIV/0! | K24: =+formato!H25 -> 0 | L24: =IF($C$50="A",K24+($I$8*K24),K24+($N$8*K24)) -> #DIV/0! | Q24: peso suelo Hum | R24: =+E24-E29 -> 0 | S24: =+G24-G29 -> 0 | T24: =+I24-I29 -> 0 | U24: =+K24-K29 -> 0
B25: Tara + suelo seco 1(g) | E25: =+formato!D26 -> 0 | F25: =IF($C$50="A",E25+($I$8*E25),E25+($N$8*E25)) -> #DIV/0! | G25: =+formato!F26 -> 0 | H25: =IF($C$50="A",G25+($I$8*G25),G25+($N$8*G25)) -> #DIV/0! | I25: =+formato!G26 -> 0 | J25: =IF($C$50="A",I25+($I$8*I25),I25+($N$8*I25)) -> #DIV/0! | K25: =+formato!H26 -> 0 | L25: =IF($C$50="A",K25+($I$8*K25),K25+($N$8*K25)) -> #DIV/0! | Q25: contenido hum | R25: 3.9 | S25: 5.8 | T25: 7.7 | U25: 8.9
B26: Tara + suelo seco 2 (g) | E26: =+formato!D27 -> 0 | F26: =IF($C$50="A",E26+($I$8*E26),E26+($N$8*E26)) -> #DIV/0! | G26: =+formato!F27 -> 0 | H26: =IF($C$50="A",G26+($I$8*G26),G26+($N$8*G26)) -> #DIV/0! | I26: =+formato!G27 -> 0 | J26: =IF($C$50="A",I26+($I$8*I26),I26+($N$8*I26)) -> #DIV/0! | K26: =+formato!H27 -> 0 | L26: =IF($C$50="A",K26+($I$8*K26),K26+($N$8*K26)) -> #DIV/0! | Q26: peso suelo S | R26: =+(E24+(R25*E29/100))/(R25/100+1) -> 0 | S26: =+(G24+(S25*G29/100))/(S25/100+1) -> 0 | T26: =+(I24+(T25*I29/100))/(T25/100+1) -> 0 | U26: =+(K24+(U25*K29/100))/(U25/100+1) -> 0
B27: Tara + suelo seco 3 (g) | E27: =+formato!D28 -> 0 | F27: =IF($C$50="A",E27+($I$8*E27),E27+($N$8*E27)) -> #DIV/0! | G27: =+formato!F28 -> 0 | H27: =IF($C$50="A",G27+($I$8*G27),G27+($N$8*G27)) -> #DIV/0! | I27: =+formato!G28 -> 0 | J27: =IF($C$50="A",I27+($I$8*I27),I27+($N$8*I27)) -> #DIV/0! | K27: =+formato!H28 -> 0 | L27: =IF($C$50="A",K27+($I$8*K27),K27+($N$8*K27)) -> #DIV/0! | Q27: Peso minimo | R27: =IF(C50="C",2500,IF(C50="B",500,100)) -> #DIV/0!
B28: Masa de agua (g) | E28: =+E24-E27 -> 0 | F28: =+F24-F27 -> #DIV/0! | G28: =+G24-G27 -> 0 | H28: =+H24-H27 -> #DIV/0! | I28: =+I24-I27 -> 0 | J28: =+J24-J27 -> #DIV/0! | K28: =+K24-K27 -> 0 | L28: =+L24-L27 -> #DIV/0!
B29: Masa de tara (g) | E29: =+formato!D30 -> 0 | F29: =IF($C$50="A",E29+($I$8*E29),E29+($N$8*E29)) -> #DIV/0! | G29: =+formato!F30 -> 0 | H29: =IF($C$50="A",G29+($I$8*G29),G29+($N$8*G29)) -> #DIV/0! | I29: =+formato!G30 -> 0 | J29: =IF($C$50="A",I29+($I$8*I29),I29+($N$8*I29)) -> #DIV/0! | K29: =+formato!H30 -> 0 | L29: =IF($C$50="A",K29+($I$8*K29),K29+($N$8*K29)) -> #DIV/0!
B30: Masa de suelo seco (g) | F30: =+F27-F29 -> #DIV/0! | H30: =+H27-H29 -> #DIV/0! | J30: =+J27-J29 -> #DIV/0! | L30: =+L27-L29 -> #DIV/0!
B31: Contenido de Humedad moldeo (%) | F31: =+F28/F30*100 -> #DIV/0! | H31: =+H28/H30*100 -> #DIV/0! | J31: =+J28/J30*100 -> #DIV/0! | L31: =+L28/L30*100 -> #DIV/0! | O31: Reportar al 0.1%
B32: Densidad Seca (g/cm3) | F32: =+F21/(1+F31/100) -> #DIV/0! | H32: =+H21/(1+H31/100) -> #DIV/0! | J32: =+J21/(1+J31/100) -> #DIV/0! | L32: =+L21/(1+L31/100) -> #DIV/0! | O32: 4 digitos
B33: Peso unitario seco del suelo kN/m3 | F33: =+F32*9.8066 -> #DIV/0! | H33: =+H32*9.8066 -> #DIV/0! | J33: =+J32*9.8066 -> #DIV/0! | L33: =+L32*9.8066 -> #DIV/0!
B34: Masa humeda minima | F34: =IF(R24<R27,"No Cumple","Cumple") -> #DIV/0! | H34: =IF(S24<R27,"No Cumple","Cumple") -> #DIV/0! | J34: =IF(T24<R27,"No Cumple","Cumple") -> #DIV/0! | L34: =IF(U24<R27,"No Cumple","Cumple") -> #DIV/0!
B35: Perdida de masa seca constante es < 0.1% | E35: =+(E26-E27)/E27*100 -> #DIV/0! | F35: =+IF(E35<0.1,"Cumple", "No Cumple") -> #DIV/0! | G35: =+(G26-G27)/G27*100 -> #DIV/0! | H35: =+IF(G35<0.1,"Cumple", "No Cumple") -> #DIV/0! | I35: =+(I26-I27)/I27*100 -> #DIV/0! | J35: =+IF(I35<0.1,"Cumple", "No Cumple") -> #DIV/0! | K35: =+(K26-K27)/K27*100 -> #DIV/0! | L35: =+IF(K35<0.1,"Cumple", "No Cumple") -> #DIV/0!
C37: - Contenido de Humedad natural | F37: 0
C38: - Clasificación muestra ASTM D2487-17 | F38: 0
C41: Gravedad especifica de sólido del suelo: | F41: 0 | K41: Curva de 100% saturación | N41: Posicion
K42: gd | L42: wsat
C43: peso unitario del agua | E43: kN/m3 | F43: 9.8066 | G43: =+F43 -> 9.8066 | H43: =+F43 -> 9.8066 | I43: =+F43 -> 9.8066 | K43: =LARGE($F$44:$I$44,N43) -> #DIV/0! | L43: =SMALL($F$46:$I$46,N43) -> #DIV/0! | N43: 1
C44: Peso unitario seco del suelo | E44: kN/m3 | F44: =+F33 -> #DIV/0! | G44: =+H33 -> #DIV/0! | H44: =+J33 -> #DIV/0! | I44: =+L33 -> #DIV/0! | K44: =LARGE($F$44:$I$44,N44) -> #DIV/0! | L44: =SMALL($F$46:$I$46,N44) -> #DIV/0! | N44: 2
C45: Gravedad especifica del suelo | E45: - | F45: 2.81 | G45: =+$F$45 -> 2.81 | H45: =+$F$45 -> 2.81 | I45: =+$F$45 -> 2.81 | K45: =LARGE($F$44:$I$44,N45) -> #DIV/0! | L45: =SMALL($F$46:$I$46,N45) -> #DIV/0! | N45: 3
C46: contenido de agua saturación | E46: % | F46: =+(F43*F45-F44)/F44/F45*100 -> #DIV/0! | G46: =+(G43*G45-G44)/G44/G45*100 -> #DIV/0! | H46: =+(H43*H45-H44)/H44/H45*100 -> #DIV/0! | I46: =+(I43*I45-I44)/I44/I45*100 -> #DIV/0! | K46: =LARGE($F$44:$I$44,N46) -> #DIV/0! | L46: =SMALL($F$46:$I$46,N46) -> #DIV/0! | N46: 4
...

Sheet Incertidumbre
D1: INFORME DE ESTIMACIÓN DE INCERTIDUMBRE | I1: Código: | J1: F-LEM-P-10.01
I2: Versión: | J2: 3
I3: Fecha: | J3: 46146
I4: Página: | J4: 1 de 1
A6: Método: | B6: STANDARD TEST METHODS FOR LABORATORY COMPACTION CHARACTERISTICS OF SOIL USING MODIFIED EFFORT (56,000 ft-lbf/ft³ (2,700 kN-m/m³))
A7: Norma: | B7: ASTM D1557-12 (Reapproved 2021)
A8: Matriz: | B8: Suelo
A9: Mensurando: | B9: Peso unitario seco y óptimo contenido de humedad
A11: Paso 1. Definición del proceso de medición
A13: Variables: | F13: Fórmula:
A15: Mt = Masa de suelo en molde y molde | D15: Masa humeda (Mcms)
A16: Mmd = Masa del molde de compactación | D16: Masa seca ( Mcdc)
A17: V= Volumen de molde de compactación | D17: Masa tara (Mc)
A18: K:Constante de conversión (unidades-densidad)
A20: Equipos a utilizar:
A22: Balanza con resulución de lectura de 0.1g y 0.01g
A24: Paso 2. Definición de las variables aleatorias
A37: CÁLCULO: MÁXIMA DENSIDAD SECA
A38: Fuentes | B38: Unidades | C38: Valor | D38: Incertidumbre Original | E38: Distribución | F38: Incertidumbre Estándar u(xi) | G38: Coeficiente de Sensibilidad | H38: Contribución ui(y) | I38: Valor | J38: Incertidumbre Original | K38: Distribución | L38: Incertidumbre Estándar u(xi) | M38: Coeficiente de Sensibilidad | N38: Contribución ui(y) | O38: Valor | P38: Incertidumbre Original | Q38: Distribución | R38: Incertidumbre Estándar u(xi) | S38: Coeficiente de Sensibilidad | T38: Contribución ui(y) | U38: Valor | V38: Incertidumbre Original | W38: Distribución | X38: Incertidumbre Estándar u(xi) | Y38: Coeficiente de Sensibilidad | Z38: Contribución ui(y)
A39: Maxima Densidad Seca | B39: (g/cm3) | C39: =100*(C40-C44)/C48/(100+C49) -> #DIV/0! | D39: --- | E39: --- | F39: --- | G39: --- | H39: --- | I39: =100*(I40-I44)/I48/(100+I49) -> #DIV/0! | J39: --- | K39: --- | L39: --- | M39: --- | N39: --- | O39: =100*(O40-O44)/O48/(100+O49) -> #DIV/0! | P39: --- | Q39: --- | R39: --- | S39: --- | T39: --- | U39: =100*(U40-U44)/U48/(100+U49) -> #DIV/0! | V39: --- | W39: --- | X39: --- | Y39: --- | Z39: ---
A40: Masa molde + Suelo Humedo | B40: g. | C40: =Balanza!D25 -> 0 | D40: --- | E40: --- | F40: =SQRT((F41*F41)+(F42*F42)+(F43*F43)) -> 1.106044 | G40: =100/(100*C48+C49*C48) -> #DIV/0! | H40: =+G40*F40 -> #DIV/0! | I40: =Balanza!F25 -> 0 | J40: --- | K40: --- | L40: =SQRT((L41*L41)+(L42*L42)+(L43*L43)) -> 1.106044 | M40: =100/(100*I48+I49*I48) -> #DIV/0! | N40: =+M40*L40 -> #DIV/0! | O40: =Balanza!H25 -> 0 | P40: --- | Q40: --- | R40: =SQRT((R41*R41)+(R42*R42)+(R43*R43)) -> 1.106044 | S40: =100/(100*O48+O49*O48) -> #DIV/0! | T40: =+S40*R40 -> #DIV/0! | U40: =Balanza!J25 -> 0 | V40: --- | W40: --- | X40: =SQRT((X41*X41)+(X42*X42)+(X43*X43)) -> 1.106044 | Y40: =100/(100*U48+U49*U48) -> #DIV/0! | Z40: =+Y40*X40 -> #DIV/0!
A41: Repetibilidad de la pesada | B41: g. | D41: =+Balanza!E25 -> 0 | E41: Normal, K=1 | F41: =+D41 -> 0 | G41: --- | H41: --- | J41: =Balanza!G25 -> 0 | K41: Normal, K=1 | L41: =+J41 -> 0 | M41: --- | N41: --- | P41: =Balanza!I25 -> 0 | Q41: Normal, K=1 | R41: =+P41 -> 0 | S41: --- | T41: --- | V41: =Balanza!K25 -> 0 | W41: Normal, K=1 | X41: =+V41 -> 0 | Y41: --- | Z41: ---
A42: Certificado de Calibración | B42: g. | D42: =2*(SQRT(Balanza!$C$8+Balanza!$D$8*(POWER(C40,2)))) -> 2.1354157 | E42: Normal, K=2 | F42: =+D42/2 -> 1.0677078 | G42: --- | H42: --- | J42: =2*(SQRT(Balanza!$C$8+Balanza!$D$8*(POWER(I40,2)))) -> 2.1354157 | K42: Normal, K=2 | L42: =+J42/2 -> 1.0677078 | M42: --- | N42: --- | P42: =2*(SQRT(Balanza!$C$8+Balanza!$D$8*(POWER(O40,2)))) -> 2.1354157 | Q42: Normal, K=2 | R42: =+P42/2 -> 1.0677078 | S42: --- | T42: --- | V42: =2*(SQRT(Balanza!$C$8+Balanza!$D$8*(POWER(U40,2)))) -> 2.1354157 | W42: Normal, K=2 | X42: =+V42/2 -> 1.0677078 | Y42: --- | Z42: ---
A43: Resolución | B43: g. | D43: =Balanza!$C$10 -> 1 | E43: Rectangular | F43: =+D43/SQRT(3)/2 -> 0.28867513 | G43: --- | H43: --- | J43: =Balanza!$C$10 -> 1 | K43: Rectangular | L43: =+J43/SQRT(3)/2 -> 0.28867513 | M43: --- | N43: --- | P43: =Balanza!$C$10 -> 1 | Q43: Rectangular | R43: =+P43/SQRT(3)/2 -> 0.28867513 | S43: --- | T43: --- | V43: =Balanza!$C$10 -> 1 | W43: Rectangular | X43: =+V43/SQRT(3)/2 -> 0.28867513 | Y43: --- | Z43: ---
A44: Masa Molde | B44: g. | C44: =Balanza!D26 -> 0 | E44: --- | F44: =SQRT((F45*F45)+(F46*F46)+(F47*F47)) -> 1.106044 | G44: =1/(100*C48+C49*C48) -> #DIV/0! | H44: =+G44*F44 -> #DIV/0! | I44: =Balanza!F26 -> 0 | K44: --- | L44: =SQRT((L45*L45)+(L46*L46)+(L47*L47)) -> 1.106044 | M44: =1/(100*I48+I49*I48) -> #DIV/0! | N44: =+M44*L44 -> #DIV/0! | O44: =Balanza!H26 -> 0 | Q44: --- | R44: =SQRT((R45*R45)+(R46*R46)+(R47*R47)) -> 1.106044 | S44: =1/(100*O48+O49*O48) -> #DIV/0! | T44: =+S44*R44 -> #DIV/0! | U44: =Balanza!J26 -> 0 | W44: --- | X44: =SQRT((X45*X45)+(X46*X46)+(X47*X47)) -> 1.106044 | Y44: =1/(100*U48+U49*U48) -> #DIV/0! | Z44: =+Y44*X44 -> #DIV/0!
A45: Repetibilidad de la pesada | B45: g. | D45: =Balanza!E26 -> 0 | E45: Normal, K=1 | F45: =+D45 -> 0 | G45: --- | H45: --- | J45: =Balanza!G26 -> 0 | K45: Normal, K=1 | L45: =+J45 -> 0 | M45: --- | N45: --- | P45: =Balanza!I26 -> 0 | Q45: Normal, K=1 | R45: =+P45 -> 0 | S45: --- | T45: --- | V45: =Balanza!K26 -> 0 | W45: Normal, K=1 | X45: =+V45 -> 0 | Y45: --- | Z45: ---
A46: Certificado de Calibración | B46: g. | D46: =2*(SQRT(Balanza!$C$8+Balanza!$D$8*(POWER(C44,2)))) -> 2.1354157 | E46: Normal, K=2 | F46: =+D46/2 -> 1.0677078 | G46: --- | H46: --- | J46: =2*(SQRT(Balanza!$C$8+Balanza!$D$8*(POWER(I44,2)))) -> 2.1354157 | K46: Normal, K=2 | L46: =+J46/2 -> 1.0677078 | M46: --- | N46: --- | P46: =2*(SQRT(Balanza!$C$8+Balanza!$D$8*(POWER(O44,2)))) -> 2.1354157 | Q46: Normal, K=2 | R46: =+P46/2 -> 1.0677078 | S46: --- | T46: --- | V46: =2*(SQRT(Balanza!$C$8+Balanza!$D$8*(POWER(U44,2)))) -> 2.1354157 | W46: Normal, K=2 | X46: =+V46/2 -> 1.0677078 | Y46: --- | Z46: ---
A47: Resolución | B47: g. | D47: =Balanza!$C$10 -> 1 | E47: Rectangular | F47: =+D47/SQRT(3)/2 -> 0.28867513 | G47: --- | H47: --- | J47: =Balanza!$C$10 -> 1 | K47: Rectangular | L47: =+J47/SQRT(3)/2 -> 0.28867513 | M47: --- | N47: --- | P47: =Balanza!$C$10 -> 1 | Q47: Rectangular | R47: =+P47/SQRT(3)/2 -> 0.28867513 | S47: --- | T47: --- | V47: =Balanza!$C$10 -> 1 | W47: Rectangular | X47: =+V47/SQRT(3)/2 -> 0.28867513 | Y47: --- | Z47: ---
A48: Volumen del Molde | B48: cm3 | C48: =+Balanza!D27 -> 0 | E48: --- | F48: =+$H$96/1000 -> 0.76283551 | G48: =+ABS((C44-100*C40)*(100+C49)/POWER(100*C48+C48*C49,2)) -> #DIV/0! | H48: =+G48*F48 -> #DIV/0! | I48: =+C48 -> 0 | K48: --- | L48: =+$H$96/1000 -> 0.76283551 | M48: =+ABS((I44-100*I40)*(100+I49)/POWER(100*I48+I48*I49,2)) -> #DIV/0! | N48: =+M48*L48 -> #DIV/0! | O48: =+C48 -> 0 | Q48: --- | R48: =+$H$96/1000 -> 0.76283551 | S48: =+ABS((O44-100*O40)*(100+O49)/POWER(100*O48+O48*O49,2)) -> #DIV/0! | T48: =+S48*R48 -> #DIV/0! | U48: =+C48 -> 0 | W48: --- | X48: =+$H$96/1000 -> 0.76283551 | Y48: =+ABS((U44-100*U40)*(100+U49)/POWER(100*U48+U48*U49,2)) -> #DIV/0! | Z48: =+Y48*X48 -> #DIV/0!
A49: Contenido humedad | B49: % | C49: =+C57 -> #DIV/0! | F49: =+H71 -> #DIV/0! | G49: =ABS((C44-100*C40)*C48/POWER(100*C48+C49*C48,2)) -> #DIV/0! | H49: =+F49*G49 -> #DIV/0! | I49: =+I57 -> #DIV/0! | L49: =+N71 -> #DIV/0! | M49: =ABS((I44-100*I40)*I48/POWER(100*I48+I49*I48,2)) -> #DIV/0! | N49: =+M49*L49 -> #DIV/0! | O49: =+O57 -> #DIV/0! | R49: =+T71 -> #DIV/0! | S49: =ABS((O44-100*O40)*O48/POWER(100*O48+O49*O48,2)) -> #DIV/0! | T49: =+S49*R49 -> #DIV/0! | U49: =+U57 -> #DIV/0! | X49: =+Z71 -> #DIV/0! | Y49: =ABS((U44-100*U40)*U48/POWER(100*U48+U49*U48,2)) -> #DIV/0! | Z49: =+Y49*X49 -> #DIV/0!
A50: factor de presición MDS | C50: =+precision!B7 -> 0.020947951 | F50: =+C50 -> 0.020947951 | G50: 1 | H50: =+F50*G50 -> 0.020947951 | I50: =+C50 -> 0.020947951 | L50: =+F50 -> 0.020947951 | M50: 1 | N50: =+L50*M50 -> 0.020947951 | O50: =+C50 -> 0.020947951 | R50: =+O50 -> 0.020947951 | S50: 1 | T50: =+R50*S50 -> 0.020947951 | U50: =+C50 -> 0.020947951 | X50: =+U50 -> 0.020947951 | Y50: 1 | Z50: =+X50*Y50 -> 0.020947951
A51: Incertidumbre Estándar Combinada por cada Densidad Humeda (g/cm3) | H51: =SQRT((H40*H40)+(H44*H44)+(H48*H48)+(H49*H49)+(H50*H50)) -> #DIV/0! | N51: =SQRT((N40*N40)+(N44*N44)+(N48*N48)+(N49*N49)+(N50*N50)) -> #DIV/0! | T51: =SQRT((T40*T40)+(T44*T44)+(T48*T48)+(T49*T49)+(T50*T50)) -> #DIV/0! | Z51: =SQRT((Z40*Z40)+(Z44*Z44)+(Z48*Z48)+(Z49*Z49)+(Z50*Z50)) -> #DIV/0!
A52: Incertidumbre Expandida, K = 2 | G52: (g/cm3) | H52: =+(IF(I52=I39,N51,T51))*2 -> #DIV/0! | I52: =+MAX(I39,O39) -> #DIV/0!
A53: Incertidumbre Expandida, K = 2 | G53: KN/M3 | H53: =+H52*9.8066 -> #DIV/0!
A55: CÁLCULO: ÓPTIMO CONTENIDO DE HUMEDAD
A56: Fuentes | B56: Unidades | C56: Valor | D56: Incertidumbre Original | E56: Distribución | F56: Incertidumbre Estándar u(xi) | G56: Coeficiente de Sensibilidad | H56: Contribución ui(y) | I56: Valor | J56: Incertidumbre Original | K56: Distribución | L56: Incertidumbre Estándar u(xi) | M56: Coeficiente de Sensibilidad | N56: Contribución ui(y) | O56: Valor | P56: Incertidumbre Original | Q56: Distribución | R56: Incertidumbre Estándar u(xi) | S56: Coeficiente de Sensibilidad | T56: Contribución ui(y) | U56: Valor | V56: Incertidumbre Original | W56: Distribución | X56: Incertidumbre Estándar u(xi) | Y56: Coeficiente de Sensibilidad | Z56: Contribución ui(y)
A57: Humedad (%) | C57: =+((C58-C62)/(C62-C66)*100) -> #DIV/0! | D57: --- | E57: --- | F57: --- | G57: --- | H57: --- | I57: =+((I58-I62)/(I62-I66)*100) -> #DIV/0! | J57: --- | K57: --- | L57: --- | M57: --- | N57: --- | O57: =+((O58-O62)/(O62-O66)*100) -> #DIV/0! | P57: --- | Q57: --- | R57: --- | S57: --- | T57: --- | U57: =+((U58-U62)/(U62-U66)*100) -> #DIV/0! | V57: --- | W57: --- | X57: --- | Y57: --- | Z57: ---
A58: Masa Humeda y tara | B58: g | C58: =Balanza!O26 -> #DIV/0! | D58: --- | E58: --- | F58: =SQRT((F59*F59)+(F60*F60)+(F61*F61)) -> #DIV/0! | G58: =100/(C62-C66) -> #DIV/0! | H58: =+G58*F58 -> #DIV/0! | I58: =Balanza!Q26 -> #DIV/0! | J58: --- | K58: --- | L58: =SQRT((L59*L59)+(L60*L60)+(L61*L61)) -> #DIV/0! | M58: =100/(I62-I66) -> #DIV/0! | N58: =+M58*L58 -> #DIV/0! | O58: =Balanza!S26 -> #DIV/0! | P58: --- | Q58: --- | R58: =SQRT((R59*R59)+(R60*R60)+(R61*R61)) -> #DIV/0! | S58: =100/(O62-O66) -> #DIV/0! | T58: =+S58*R58 -> #DIV/0! | U58: =Balanza!U26 -> #DIV/0! | V58: --- | W58: --- | X58: =SQRT((X59*X59)+(X60*X60)+(X61*X61)) -> #DIV/0! | Y58: =100/(U62-U66) -> #DIV/0! | Z58: =+Y58*X58 -> #DIV/0!
A59: Repetibilidad de la pesada | B59: g | D59: =+Balanza!P26 -> #DIV/0! | E59: Normal, K=1 | F59: =+D59 -> #DIV/0! | G59: --- | H59: --- | J59: =+Balanza!R26 -> #DIV/0! | K59: Normal, K=1 | L59: =+J59 -> #DIV/0! | M59: --- | N59: --- | P59: =+Balanza!T26 -> #DIV/0! | Q59: Normal, K=1 | R59: =+P59 -> #DIV/0! | S59: --- | T59: --- | V59: =+Balanza!V26 -> #DIV/0! | W59: Normal, K=1 | X59: =+V59 -> #DIV/0! | Y59: --- | Z59: ---
A60: Certificado de Calibración | B60: g | D60: =2*(SQRT(Balanza!$M$8+Balanza!$N$8*(POWER(C58,2)))) -> #DIV/0! | E60: Normal, K=2 | F60: =+D60/2 -> #DIV/0! | G60: --- | H60: --- | J60: =2*(SQRT(Balanza!$M$8+Balanza!$N$8*(POWER(I58,2)))) -> #DIV/0! | K60: Normal, K=2 | L60: =+J60/2 -> #DIV/0! | M60: --- | N60: --- | P60: =2*(SQRT(Balanza!$M$8+Balanza!$N$8*(POWER(O58,2)))) -> #DIV/0! | Q60: Normal, K=2 | R60: =+P60/2 -> #DIV/0! | S60: --- | T60: --- | V60: =2*(SQRT(Balanza!$M$8+Balanza!$N$8*(POWER(U58,2)))) -> #DIV/0! | W60: Normal, K=2 | X60: =+V60/2 -> #DIV/0! | Y60: --- | Z60: ---
...

Sheet Balanza
B2: CALIBRACION DE LA BALANZA | L2: CALIBRACION DE LA BALANZA | V2: CALIBRACION DE LA BALANZA
I6: VALOR ADOPTADO
B7: Correccion | C7: -1.49e-06 | I7: =IF(Incertidumbre!E55=0.1,Balanza!C8,Balanza!M8) -> 0.00416 | J7: =IF(Incertidumbre!E55=0.1,Balanza!D8,Balanza!N8) -> 2.43e-10 | L7: Corrección | M7: -3.29e-06 | T7: Corrección | U7: 3.79e-06
B8: Variables | C8: 1.14 | D8: 2.48e-10 | L8: Variables | M8: 0.00416 | N8: 2.43e-10 | T8: Variables | U8: 4.43e-05 | V8: 2.3e-10
B9: Ecuacion | C9: 2*RAIZ(1.14+0.000000000248*R2) | F9: g | L9: Ecuación | M9: 2*RAIZ(0.00416+0.000000000243*R2) | T9: Ecuación | U9: 2*RAIZ(0.0000443+0.000000000230xR2)
B10: Resolucion | C10: 1 | D10: g | L10: Resolución | M10: 0.1 | N10: g | T10: Resolución | U10: 0.01
B11: Codigo | C11: EQP-0054 | L11: Código | M11: EQP-0046 | T11: Código | U11: EQP-0045
B12: Fecha ultima calibracion | D12: 46160 | L12: Fecha ultima calibracion | N12: 46132 | T12: Fecha ultima calibración | V12: 46132
B13: ITEM | C13: MES | D13: 500 | E13: 1000 | F13: 5000 | G13: 10000 | H13: 15000 | I13: 20000 | L13: ITEM | M13: MES | N13: 200 | O13: 500 | P13: 1000 | Q13: 5000 | R13: 10000 | T13: ITEM | U13: MES | V13: 20 | W13: 200 | X13: 500 | Y13: 1000
C17: DESV STD | D17: 0 | E17: 0 | F17: 0 | G17: 0 | H17: 0 | I17: 0 | M17: DESV STD | N17: 0 | O17: 0 | P17: 0 | Q17: 0 | R17: 0 | U17: DESV STD | V17: 0 | W17: 0 | X17: 0
B19: Busqueda de Repetibilidad de la masa
D20: =+D13 -> 500 | E20: =+E13 -> 1000 | F20: =+F13 -> 5000 | G20: =+G13 -> 10000 | H20: =+H13 -> 15000 | I20: =+I13 -> 20000 | N20: =+N13 -> 200 | O20: =+O13 -> 500 | P20: =+P13 -> 1000 | Q20: =+Q13 -> 5000 | R20: =+R13 -> 10000 | V20: =+V13 -> 20 | W20: =+W13 -> 200 | X20: =+X13 -> 500
D21: =D17 -> 0 | E21: =E17 -> 0 | F21: =F17 -> 0 | G21: =G17 -> 0 | H21: =H17 -> 0 | I21: =I17 -> 0 | N21: =N17 -> 0 | O21: =O17 -> 0 | P21: =P17 -> 0 | Q21: =Q17 -> 0 | R21: =R17 -> 0 | V21: =V17 -> 0 | W21: =W17 -> 0 | X21: =X17 -> 0
B23: ENSAYO DE LA MUESTRA
B24: Densidad humeda
B25: Masa suelo + molde (g) | D25: =+DATOS!F17 -> 0 | E25: =IF(D25<=$D$20,$D$21,IF(AND(D25>$D$20,D25<=$E$20),$E$21,IF(AND(D25>$E$20,D25<=$F$20),$F$21,IF(AND(D25>$F$20,D25<=$G$20),$G$21,IF(AND(D25>$G$20,D25<=$H$20),$H$21,$H$21))))) -> 0 | F25: =+DATOS!H17 -> 0 | G25: =IF(F25<=$D$20,$D$21,IF(AND(F25>$D$20,F25<=$E$20),$E$21,IF(AND(F25>$E$20,F25<=$F$20),$F$21,IF(AND(F25>$F$20,F25<=$G$20),$G$21,IF(AND(F25>$G$20,F25<=$H$20),$H$21,$H$21))))) -> 0 | H25: =+DATOS!J17 -> 0 | I25: =IF(H25<=$D$20,$D$21,IF(AND(H25>$D$20,H25<=$E$20),$E$21,IF(AND(H25>$E$20,H25<=$F$20),$F$21,IF(AND(H25>$F$20,H25<=$G$20),$G$21,IF(AND(H25>$G$20,H25<=$H$20),$H$21,$H$21))))) -> 0 | J25: =+DATOS!L17 -> 0 | K25: =IF(J25<=$D$20,$D$21,IF(AND(J25>$D$20,J25<=$E$20),$E$21,IF(AND(J25>$E$20,J25<=$F$20),$F$21,IF(AND(J25>$F$20,J25<=$G$20),$G$21,IF(AND(J25>$G$20,J25<=$H$20),$H$21,$H$21))))) -> 0 | M25: humedad (%) y densidad seca
B26: Masa molde (g) | D26: =+DATOS!F18 -> 0 | E26: =IF(D26<=$D$20,$D$21,IF(AND(D26>$D$20,D26<=$E$20),$E$21,IF(AND(D26>$E$20,D26<=$F$20),$F$21,IF(AND(D26>$F$20,D26<=$G$20),$G$21,IF(AND(D26>$G$20,D26<=$H$20),$H$21,$H$21))))) -> 0 | F26: =+DATOS!H18 -> 0 | G26: =IF(F26<=$D$20,$D$21,IF(AND(F26>$D$20,F26<=$E$20),$E$21,IF(AND(F26>$E$20,F26<=$F$20),$F$21,IF(AND(F26>$F$20,F26<=$G$20),$G$21,IF(AND(F26>$G$20,F26<=$H$20),$H$21,$H$21))))) -> 0 | H26: =+DATOS!J18 -> 0 | I26: =IF(H26<=$D$20,$D$21,IF(AND(H26>$D$20,H26<=$E$20),$E$21,IF(AND(H26>$E$20,H26<=$F$20),$F$21,IF(AND(H26>$F$20,H26<=$G$20),$G$21,IF(AND(H26>$G$20,H26<=$H$20),$H$21,$H$21))))) -> 0 | J26: =+DATOS!L18 -> 0 | K26: =IF(J26<=$D$20,$D$21,IF(AND(J26>$D$20,J26<=$E$20),$E$21,IF(AND(J26>$E$20,J26<=$F$20),$F$21,IF(AND(J26>$F$20,J26<=$G$20),$G$21,IF(AND(J26>$G$20,J26<=$H$20),$H$21,$H$21))))) -> 0 | M26: Tara + suelo húmedo (g) | O26: =+DATOS!F24 -> #DIV/0! | P26: =IF(O26<=$N$20,$N$21,IF(AND(O26>$N$20,O26<=$O$20),$O$21,IF(AND(O26>$O$20,O26<=$P$20),$P$21,IF(AND(O26>$P$20,O26<=$Q$20),$Q$21,IF(AND(O26>$Q$20,O26<=$R$20),$R$21,$R$21))))) -> #DIV/0! | Q26: =+DATOS!H24 -> #DIV/0! | R26: =IF(Q26<=$N$20,$N$21,IF(AND(Q26>$N$20,Q26<=$O$20),$O$21,IF(AND(Q26>$O$20,Q26<=$P$20),$P$21,IF(AND(Q26>$P$20,Q26<=$Q$20),$Q$21,IF(AND(Q26>$Q$20,Q26<=$R$20),$R$21,$R$21))))) -> #DIV/0! | S26: =+DATOS!J24 -> #DIV/0! | T26: =IF(S26<=$N$20,$N$21,IF(AND(S26>$N$20,S26<=$O$20),$O$21,IF(AND(S26>$O$20,S26<=$P$20),$P$21,IF(AND(S26>$P$20,S26<=$Q$20),$Q$21,IF(AND(S26>$Q$20,S26<=$R$20),$R$21,$R$21))))) -> #DIV/0! | U26: =+DATOS!L24 -> #DIV/0! | V26: =IF(U26<=$N$20,$N$21,IF(AND(U26>$N$20,U26<=$O$20),$O$21,IF(AND(U26>$O$20,U26<=$P$20),$P$21,IF(AND(U26>$P$20,U26<=$Q$20),$Q$21,IF(AND(U26>$Q$20,U26<=$R$20),$R$21,$R$21))))) -> #DIV/0!
B27: Volúmen del molde (cm3) | D27: =+DATOS!F20 -> 0 | F27: =+DATOS!H20 -> 0 | H27: =+DATOS!J20 -> 0 | J27: =+DATOS!L20 -> 0 | M27: Tara + suelo seco 3 (g) | O27: =+DATOS!F27 -> #DIV/0! | P27: =IF(O27<=$N$20,$N$21,IF(AND(O27>$N$20,O27<=$O$20),$O$21,IF(AND(O27>$O$20,O27<=$P$20),$P$21,IF(AND(O27>$P$20,O27<=$Q$20),$Q$21,IF(AND(O27>$Q$20,O27<=$R$20),$R$21,$R$21))))) -> #DIV/0! | Q27: =+DATOS!H27 -> #DIV/0! | R27: =IF(Q27<=$N$20,$N$21,IF(AND(Q27>$N$20,Q27<=$O$20),$O$21,IF(AND(Q27>$O$20,Q27<=$P$20),$P$21,IF(AND(Q27>$P$20,Q27<=$Q$20),$Q$21,IF(AND(Q27>$Q$20,Q27<=$R$20),$R$21,$R$21))))) -> #DIV/0! | S27: =+DATOS!J27 -> #DIV/0! | T27: =IF(S27<=$N$20,$N$21,IF(AND(S27>$N$20,S27<=$O$20),$O$21,IF(AND(S27>$O$20,S27<=$P$20),$P$21,IF(AND(S27>$P$20,S27<=$Q$20),$Q$21,IF(AND(S27>$Q$20,S27<=$R$20),$R$21,$R$21))))) -> #DIV/0! | U27: =+DATOS!L27 -> #DIV/0! | V27: =IF(U27<=$N$20,$N$21,IF(AND(U27>$N$20,U27<=$O$20),$O$21,IF(AND(U27>$O$20,U27<=$P$20),$P$21,IF(AND(U27>$P$20,U27<=$Q$20),$Q$21,IF(AND(U27>$Q$20,U27<=$R$20),$R$21,$R$21))))) -> #DIV/0!
M28: Masa de tara (g) | O28: =+DATOS!F29 -> #DIV/0! | P28: =IF(O28<=$N$20,$N$21,IF(AND(O28>$N$20,O28<=$O$20),$O$21,IF(AND(O28>$O$20,O28<=$P$20),$P$21,IF(AND(O28>$P$20,O28<=$Q$20),$Q$21,IF(AND(O28>$Q$20,O28<=$R$20),$R$21,$R$21))))) -> #DIV/0! | Q28: =+DATOS!H29 -> #DIV/0! | R28: =IF(Q28<=$N$20,$N$21,IF(AND(Q28>$N$20,Q28<=$O$20),$O$21,IF(AND(Q28>$O$20,Q28<=$P$20),$P$21,IF(AND(Q28>$P$20,Q28<=$Q$20),$Q$21,IF(AND(Q28>$Q$20,Q28<=$R$20),$R$21,$R$21))))) -> #DIV/0! | S28: =+DATOS!J29 -> #DIV/0! | T28: =IF(S28<=$N$20,$N$21,IF(AND(S28>$N$20,S28<=$O$20),$O$21,IF(AND(S28>$O$20,S28<=$P$20),$P$21,IF(AND(S28>$P$20,S28<=$Q$20),$Q$21,IF(AND(S28>$Q$20,S28<=$R$20),$R$21,$R$21))))) -> #DIV/0! | U28: =+DATOS!L29 -> #DIV/0! | V28: =IF(U28<=$N$20,$N$21,IF(AND(U28>$N$20,U28<=$O$20),$O$21,IF(AND(U28>$O$20,U28<=$P$20),$P$21,IF(AND(U28>$P$20,U28<=$Q$20),$Q$21,IF(AND(U28>$Q$20,U28<=$R$20),$R$21,$R$21))))) -> #DIV/0!
T30: humedad (%) y densidad seca
T31: Tara + suelo húmedo (g) | V31: =+DATOS!F24 -> #DIV/0! | W31: =IF(V31<=$N$20,$N$21,IF(AND(V31>$N$20,V31<=$O$20),$O$21,IF(AND(V31>$O$20,V31<=$P$20),$P$21,IF(AND(V31>$P$20,V31<=$Q$20),$Q$21,IF(AND(V31>$Q$20,V31<=$R$20),$R$21,$R$21))))) -> #DIV/0! | X31: =+DATOS!H24 -> #DIV/0! | Y31: =IF(X31<=$N$20,$N$21,IF(AND(X31>$N$20,X31<=$O$20),$O$21,IF(AND(X31>$O$20,X31<=$P$20),$P$21,IF(AND(X31>$P$20,X31<=$Q$20),$Q$21,IF(AND(X31>$Q$20,X31<=$R$20),$R$21,$R$21))))) -> #DIV/0! | Z31: =+DATOS!J24 -> #DIV/0! | AA31: =IF(Z31<=$N$20,$N$21,IF(AND(Z31>$N$20,Z31<=$O$20),$O$21,IF(AND(Z31>$O$20,Z31<=$P$20),$P$21,IF(AND(Z31>$P$20,Z31<=$Q$20),$Q$21,IF(AND(Z31>$Q$20,Z31<=$R$20),$R$21,$R$21))))) -> #DIV/0! | AB31: =+DATOS!L24 -> #DIV/0! | AC31: =IF(AB31<=$N$20,$N$21,IF(AND(AB31>$N$20,AB31<=$O$20),$O$21,IF(AND(AB31>$O$20,AB31<=$P$20),$P$21,IF(AND(AB31>$P$20,AB31<=$Q$20),$Q$21,IF(AND(AB31>$Q$20,AB31<=$R$20),$R$21,$R$21))))) -> #DIV/0!
T32: Tara + suelo seco 3 (g) | V32: =+DATOS!F27 -> #DIV/0! | W32: =IF(V32<=$N$20,$N$21,IF(AND(V32>$N$20,V32<=$O$20),$O$21,IF(AND(V32>$O$20,V32<=$P$20),$P$21,IF(AND(V32>$P$20,V32<=$Q$20),$Q$21,IF(AND(V32>$Q$20,V32<=$R$20),$R$21,$R$21))))) -> #DIV/0! | X32: =+DATOS!H27 -> #DIV/0! | Y32: =IF(X32<=$N$20,$N$21,IF(AND(X32>$N$20,X32<=$O$20),$O$21,IF(AND(X32>$O$20,X32<=$P$20),$P$21,IF(AND(X32>$P$20,X32<=$Q$20),$Q$21,IF(AND(X32>$Q$20,X32<=$R$20),$R$21,$R$21))))) -> #DIV/0! | Z32: =+DATOS!J27 -> #DIV/0! | AA32: =IF(Z32<=$N$20,$N$21,IF(AND(Z32>$N$20,Z32<=$O$20),$O$21,IF(AND(Z32>$O$20,Z32<=$P$20),$P$21,IF(AND(Z32>$P$20,Z32<=$Q$20),$Q$21,IF(AND(Z32>$Q$20,Z32<=$R$20),$R$21,$R$21))))) -> #DIV/0! | AB32: =+DATOS!L27 -> #DIV/0! | AC32: =IF(AB32<=$N$20,$N$21,IF(AND(AB32>$N$20,AB32<=$O$20),$O$21,IF(AND(AB32>$O$20,AB32<=$P$20),$P$21,IF(AND(AB32>$P$20,AB32<=$Q$20),$Q$21,IF(AND(AB32>$Q$20,AB32<=$R$20),$R$21,$R$21))))) -> #DIV/0!
B33: PISÓN | T33: Masa de tara (g) | V33: =+DATOS!F29 -> #DIV/0! | W33: =IF(V33<=$N$20,$N$21,IF(AND(V33>$N$20,V33<=$O$20),$O$21,IF(AND(V33>$O$20,V33<=$P$20),$P$21,IF(AND(V33>$P$20,V33<=$Q$20),$Q$21,IF(AND(V33>$Q$20,V33<=$R$20),$R$21,$R$21))))) -> #DIV/0! | X33: =+DATOS!H29 -> #DIV/0! | Y33: =IF(X33<=$N$20,$N$21,IF(AND(X33>$N$20,X33<=$O$20),$O$21,IF(AND(X33>$O$20,X33<=$P$20),$P$21,IF(AND(X33>$P$20,X33<=$Q$20),$Q$21,IF(AND(X33>$Q$20,X33<=$R$20),$R$21,$R$21))))) -> #DIV/0! | Z33: =+DATOS!J29 -> #DIV/0! | AA33: =IF(Z33<=$N$20,$N$21,IF(AND(Z33>$N$20,Z33<=$O$20),$O$21,IF(AND(Z33>$O$20,Z33<=$P$20),$P$21,IF(AND(Z33>$P$20,Z33<=$Q$20),$Q$21,IF(AND(Z33>$Q$20,Z33<=$R$20),$R$21,$R$21))))) -> #DIV/0! | AB33: =+DATOS!L29 -> #DIV/0! | AC33: =IF(AB33<=$N$20,$N$21,IF(AND(AB33>$N$20,AB33<=$O$20),$O$21,IF(AND(AB33>$O$20,AB33<=$P$20),$P$21,IF(AND(AB33>$P$20,AB33<=$Q$20),$Q$21,IF(AND(AB33>$Q$20,AB33<=$R$20),$R$21,$R$21))))) -> #DIV/0!
B34: Peso del Pisón medido (g) | D34: 4529.7 | E34: =IF(D34<$D$20,$D$21,IF(AND(D34>=$D$20,D34<$E$20),$E$21,IF(AND(D34>=$E$20,D34<$F$20),$F$21,IF(AND(D34>=$F$20,D34<$G$20),$G$21,IF(AND(D34>=$G$20,D34<$H$20),$H$21,IF(AND(D34>=$H$20,D34<$I$20),$I$21,IF(AND(D34>=$I$20,D34<$J$20),$J$21))))))) -> 0 | G34: verificación marzo 2026
B35: Molde de 6 in
B36: Promedio Masa del agua | D36: 2130 | E36: =IF(D36<$D$20,$D$21,IF(AND(D36>=$D$20,D36<$E$20),$E$21,IF(AND(D36>=$E$20,D36<$F$20),$F$21,IF(AND(D36>=$F$20,D36<$G$20),$G$21,IF(AND(D36>=$G$20,D36<$H$20),$H$21,IF(AND(D36>=$H$20,D36<$I$20),$I$21,IF(AND(D36>=$I$20,D36<$J$20),$J$21))))))) -> 0 | G36: verificación marzo 2026
B37: Molde de 4 in
B38: Promedio Masa del agua | D38: 937.1 | E38: =IF(D38<$D$20,$D$21,IF(AND(D38>=$D$20,D38<$E$20),$E$21,IF(AND(D38>=$E$20,D38<$F$20),$F$21,IF(AND(D38>=$F$20,D38<$G$20),$G$21,IF(AND(D38>=$G$20,D38<$H$20),$H$21,IF(AND(D38>=$H$20,D38<$I$20),$I$21,IF(AND(D38>=$I$20,D38<$J$20),$J$21))))))) -> 0 | G38: verificación enero 2026

Sheet precision
A3: Factor de precision PROCTOR MODIFICADO | G3: Factor de precision HUMEDAD SUELO
A4: Fecha de evaluacion: | B4: 45807 | G4: Fecha de evaluacion: | H4: 46064
A6: Maxima densidad seca | G6: contenido humedad suelo
A7: Desviacion Estándar Repetibilidad (Sr) | B7: 0.020947951 | G7: Desviacion Estándar Repetibilidad (Sr) | H7: 0.11030261
A8: Desviacion Estándar Reproducibilidad (SR) | B8: 0.021813477 | G8: Desviacion Estándar Reproducibilidad (SR) | H8: 0.11377365

Sheet Correccion
A7: LABORATORIO DE ENSAYO DE MATERIALES
A8: 1
A10: CLIENTE | B10: : | C10: =+Proctor!E9 -> 0 | H10: CÓDIGO | I10: : | J10: F-LEM-P-SU-19.02
A11: DIRECCIÓN ** | B11: : | C11: =+Proctor!E10 -> 0 | H11: N° OT | I11: : | J11: =+Proctor!L10 -> 0
A12: PROYECTO ** | B12: : | C12: =+Proctor!E11 -> 0 | H12: FECHA DE EMISIÓN: | I12: : | J12: =+Proctor!L11 -> 0
A13: UBICACIÓN ** | B13: : | C13: =+Proctor!E12 -> 0
A14: ** Datos proporcionados por el cliente
A15: STANDARD PRACTICE FOR CORRECTION OF UNIT WEIGHT AND WATER CONTENT FOR SOILS CONTAINING OVERSIZE PARTICLES
A16: ASTM D4718
A18: DATOS DE LA MUESTRA
A19: CANTERA / SONDAJE ** | B19: : | C19: =+Proctor!E18 -> 0 | H19: CODIGO DE LA MUESTRA | I19: : | J19: =+Proctor!L18 -> 0 | N19: Tamiz | O19: % Reten. Acumulado
A20: N° MUESTRA ** | B20: : | C20: =+Proctor!E19 -> 0 | H20: FECHA DE RECEPCIÓN | I20: : | J20: =+Proctor!L19 -> 0
A21: TIPO DE MUESTRA** | B21: : | C21: =+Proctor!E20 -> 0 | H21: FECHA DE EJECUCIÓN | I21: : | J21: =+Proctor!L20 -> 0 | N21: 19 mm ( ¾” ) | O21: =+Proctor!G25 -> #DIV/0!
A22: LUGAR DE ENSAYO | B22: : | C22: Laboratorio de Ensayo de Materiales | N22: 9.5 mm ( 3/8” ) | O22: =+Proctor!G26 -> #DIV/0!
A23: 1.0 DATOS DEL ENSAYO DE COMPACTACIÒN | N23: 4.75 mm ( Nº 4 ) | O23: =+Proctor!G27 -> #DIV/0!
B24: 1.1 | C24: Metodo de compactaciòn | H24: =+Proctor!J45 -> #DIV/0! | N24: Menor ( Nº 4 ) | O24: =+Proctor!G28 -> #DIV/0!
B25: 1.2 | C25: Tamaño de tamiz usado para separa la fraccion | G25: =IF(H24="A","mm","In") -> #DIV/0! | H25: =IF(H24="A"," Nº4",IF(H24="B","3/8""",IF(H24="C","3/4"""))) -> #DIV/0!
B26: 1.3 | C26: =IF(H24="A","Porcentaje de la fraccion mas fina <Nº4",IF(H24="B","Porcentaje de la fraccion mas fina <3/8""",IF(H24="C","Porcentaje de la fraccion mas fina <3/4"""))) -> #DIV/0! | F26: Pf | G26: % | H26: =100-H27 -> #DIV/0!
B27: 1.4 | C27: =IF(H24="A","Porcentaje de la fraccion de gran tamaño >Nº4",IF(H24="B","Porcentaje de la fraccion de gran tamaño >3/8""",IF(H24="C","Porcentaje de la fraccion de gran tamaño >3/4"""))) -> #DIV/0! | F27: Pc | G27: % | H27: =IF(H24="A",O23,IF(H24="B",O22,IF(H24="C",O21))) -> #DIV/0!
B28: 1.5 | C28: Contenido de Humedad de la fraccion sobre tamaño | F28: Wc | G28: % | H28: =+Proctor!R40 -> 0
B29: 1.6 | C29: Densidad Especifica de la fraccion de gran tamaño | F29: Gm | G29: gr/cm³ | H29: =+Proctor!R41 -> 0
B30: 1.7 | C30: Optimo Contenido de Humedad (ASTM D1557 ) | F30: Wf | G30: % | H30: =+Proctor!J50 -> #DIV/0!
B31: 1.8 | C31: Maxima Densidad Seca (ASTM D1557 ) | F31: Df | G31: gr/cm³ | H31: =+Proctor!#REF! -> #REF!
B32: 1.9 | C32: Peso Especifico del Agua | F32: Yw | G32: gr/cm³ | H32: 1
A33: 2.0 CALCULO DEL OPTIMO CONTENIDO DE HUMEDAD CORREGIDO
B34: Wt = (Pf*Wf+Pc*Wc)/100
B35: 2.1 | C35: Optimo contenido de Humedad Corregido | F35: Wt | G35: % | H35: =(H26*H30+H27*H28)/100 -> #DIV/0!
A36: 3.0 CALCULO DE LA DENSIDAD SECA CORREGIDA
B37: Dt = 100*Df*Gm*Yw / (Df*Pc+Gm*Yw*Pf)
B38: 3.1 | C38: Maxima Densidad Seca Corregida | F38: Dt | G38: gr/cm³ | H38: =100*H31*H29*H32/(H31*H27+H29*H32*H26) -> #REF!
A40: Estos datos del presente informe de ensayo sólo aplica a las muestra proporcionada por el cliente. La muestra fue identificada por el cliente. Prohibida la reproducción total o parcial del presente informe de ensayo sin la autorización escrita de GEOFAL S.A.C.
J43: Fin del documento
A56: Página 1 de 1
A57: Versión: 01 (17-05-2021)

Sheet A.Granul
N2: Metodo | O2: Fraccionada | X2: Si
N3: Clasificacion | O3: No | X3: No
N4: Metodo | O4: Inorganico | X4: Fraccionada
X5: Global
N6: Grava | O6: =SUM(P18:P27) -> 8182 | P6: =O6 -> 8182 | X6: Inorganico
A7: LABORATORIO DE ENSAYO DE MATERIALES | N7: Arena | O7: 10189 | P7: =O7/(1+T13/100) -> 9686.9964 | X7: Organico
A8: =+K12 -> 1 | N8: total | P8: =SUM(P6:P7) -> 17868.996 | X8: Turba
A10: SOLICITANTE | B10: : | C10: METRO | I10: CÓDIGO | J10: : | K10: F-LEM-P-SU-10.02 | N10: Granulometría (ASTM D-422) | S10: humeda de la fraccion | X10: =Q13 -> 578.9 | Y10: =SUM(P18:P27) -> 8182
A11: PROYECTO | B11: : | C11: CONJUNTO RESIDENCIAL SAN BORJA HOMETOWN | I11: N° OT | J11: : | K11: 150-20 | N11: Datos de ensayo | S11: SH | T11: 608.9 | X11: =Q13-P36 -> 435.2
A12: UBICACIÓN | B12: : | C12: CA. DURERO CDRA. 4 S/N, ALT. LA CDRA 13 DE LA AV. SAN | I12: N° CERT. | J12: : | K12: 1 | N12: Peso Total : | Q12: =IF(O2="Global",T12,IF(O2="Fraccionada",P8)) -> 17868.996 | S12: SS | T12: 578.9 | X12: =Q12-Y10 -> 9686.9964
N13: PesoFraccion Fino | Q13: =IF(O2="Global","--",IF(O2="Fraccionada",T12)) -> 578.9 | S13: % W | T13: =((T11-T12)/T12)*100 -> 5.1822422 | X13: =+X12*X11/X10 -> 7282.3991
A14: METODO DE ENSAYO PARA EL ANALISIS GRANULOMETRICO POR TAMIZADO | N14: Peso muestra lavada : | Q14: =IF(O2="Fraccionada",(X13+Y10),IF(O2="Global",SUM(P18:P35))) -> 15464.399
A15: NORMA NTP 339.128
N16: Malla | P16: Peso | Q16: % Ret | R16: % Ret | S16: % que | T16: Especificaciones
A17: DATOS DE LA MUESTRA | N17: Tamiz | O17: mm. | P17: (gr) | Q17: Parcial | R17: Acum. | S17: Pasa | T17: Afirmado "A"
A18: CANTERA / SONDAJE | B18: : | C18: CANTERA TRAPICHE | I18: COD. MUESTRA | J18: : | N18: 3" | O18: 76.2 | P18: 0 | Q18: =P18/$Q$12*100 -> 0 | R18: =Q18 -> 0 | S18: =100-R18 -> 100
A19: N° MUESTRA | B19: : | C19: M-1 | I19: FECHA RECEP. | J19: : | K19: 43831 | N19: 2 1/2" | O19: 63.5 | P19: 0 | Q19: =P19/$Q$12*100 -> 0 | R19: =+R18+Q19 -> 0 | S19: =100-R19 -> 100
A20: TIPO DE MUESTRA | B20: : | C20: AFIRMADO | I20: FECHA ENSAYO | J20: : | K20: 43844 | N20: 2" | O20: 50.6 | P20: 583 | Q20: =P20/$Q$12*100 -> 3.2626343 | R20: =+R19+Q20 -> 3.2626343 | S20: =100-R20 -> 96.737366 | U20: 100
N21: 1 1/2" | O21: 38.1 | P21: 1146 | Q21: =P21/$Q$12*100 -> 6.4133428 | R21: =+R20+Q21 -> 9.6759771 | S21: =100-R21 -> 90.324023 | U21: 100
N22: 1" | O22: 25.4 | P22: 974 | Q22: =P22/$Q$12*100 -> 5.4507818 | R22: =+R21+Q22 -> 15.126759 | S22: =100-R22 -> 84.873241 | T22: 90 | V22: 100
A23: Tamiz | D23: % que Pasa | F23: Tamaño maximo de las particulas | I23: 2" | N23: 3/4" | O23: 19.05 | P23: 2040 | Q23: =P23/$Q$12*100 -> 11.416422 | R23: =+R22+Q23 -> 26.543181 | S23: =100-R23 -> 73.456819 | T23: 65 | V23: 100
A24: pulg | B24: mm. | N24: 1/2" | O24: 12.7 | P24: 1277 | Q24: =P24/$Q$12*100 -> 7.1464562 | R24: =+R23+Q24 -> 33.689637 | S24: =100-R24 -> 66.310363
A25: 3" | B25: 76.2 | D25: =+S18 -> 100 | N25: 3/8" | O25: 9.525 | P25: 652 | Q25: =P25/$Q$12*100 -> 3.6487779 | R25: =+R24+Q25 -> 37.338415 | S25: =100-R25 -> 62.661585 | T25: 45 | V25: 80
A26: 2" | B26: 50.6 | D26: =+S20 -> 96.737366 | F26: Distribucion granulometrica | N26: 1/4" | O26: 6.35 | P26: 877 | Q26: =P26/$Q$12*100 -> 4.9079421 | R26: =+R25+Q26 -> 42.246357 | S26: =100-R26 -> 57.753643
A27: 1 1/2" | B27: 38.1 | D27: =+S21 -> 90.324023 | N27: No4 | O27: 4.76 | P27: 633 | Q27: =P27/$Q$12*100 -> 3.5424485 | R27: =+R26+Q27 -> 45.788805 | S27: =100-R27 -> 54.211195 | T27: 30 | V27: 65
A28: 1" | B28: 25.4 | D28: =+S22 -> 84.873241 | F28: % GRAVA | G28: =R27 -> 45.788805 | H28: Gruesa | I28: =SUM(Q18:Q23) -> 26.543181 | N28: 8 | O28: 2.36 | P28: 55.3 | Q28: =IF($O$2="Fraccionada",P28*$S$27/Q$13,IF($O$2="Global",P28/$Q$12*100)) -> 5.1785784 | R28: =+R27+Q28 -> 50.967384 | S28: =100-R28 -> 49.032616
A29: 3/4" | B29: 19.05 | D29: =+S23 -> 73.456819 | H29: Fina | I29: =SUM(Q24:Q27) -> 19.245625 | N29: 10 | O29: 2 | P29: 17.9 | Q29: =IF($O$2="Fraccionada",P29*$S$27/Q$13,IF($O$2="Global",P29/$Q$12*100)) -> 1.6762487 | R29: =+R28+Q29 -> 52.643633 | S29: =100-R29 -> 47.356367 | T29: 22 | V29: 52
A30: 3/8" | B30: 9.525 | D30: =+S25 -> 62.661585 | F30: % ARENA | G30: =100-(G28+G33) -> 40.754382 | H30: Gruesa | I30: =SUM(Q28:Q29) -> 6.8548272 | N30: 16 | O30: 1.19 | P30: 74.8 | Q30: =IF($O$2="Fraccionada",P30*$S$27/Q$13,IF($O$2="Global",P30/$Q$12*100)) -> 7.0046594 | R30: =+R29+Q30 -> 59.648292 | S30: =100-R30 -> 40.351708
A31: No4 | B31: 4.76 | D31: =+S27 -> 54.211195 | H31: Media | I31: =SUM(Q30:Q32) -> 20.180536 | N31: 30 | O31: 0.6 | P31: 95.5 | Q31: =IF($O$2="Fraccionada",P31*$S$27/Q$13,IF($O$2="Global",P31/$Q$12*100)) -> 8.9431147 | R31: =+R30+Q31 -> 68.591407 | S31: =100-R31 -> 31.408593 | Z31: =SUM(P18:P26) -> 7549
A32: 8 | B32: 2.36 | D32: =+S28 -> 49.032616 | H32: Fina | I32: =SUM(Q33:Q35) -> 13.719019 | N32: 40 | O32: 0.42 | P32: 45.2 | Q32: =IF($O$2="Fraccionada",P32*$S$27/Q$13,IF($O$2="Global",P32/$Q$12*100)) -> 4.2327621 | R32: =+R31+Q32 -> 72.824169 | S32: =100-R32 -> 27.175831 | T32: 15 | V32: 35 | Z32: =SUM(P27:P35) -> 1068.2
A33: 16 | B33: 1.19 | D33: =+S30 -> 40.351708 | F33: % FINO | G33: =S35 -> 13.456812 | I33: =Q36 -> 13.456812 | N33: 50 | O33: 0.3 | P33: 36.2 | Q33: =IF($O$2="Fraccionada",P33*$S$27/Q$13,IF($O$2="Global",P33/$Q$12*100)) -> 3.3899555 | R33: =+R32+Q33 -> 76.214124 | S33: =100-R33 -> 23.785876
A34: 30 | B34: 0.6 | D34: =+S31 -> 31.408593 | N34: 100 | O34: 0.149 | P34: 63.7 | Q34: =IF($O$2="Fraccionada",P34*$S$27/Q$13,IF($O$2="Global",P34/$Q$12*100)) -> 5.9651979 | R34: =+R33+Q34 -> 82.179322 | S34: =100-R34 -> 17.820678
A35: 40 | B35: 0.42 | D35: =+S32 -> 27.175831 | F35: =IF(O3="No","","Clasificacion SUCS") | H35: =IF(O3="No","",'Sucs '!G4) | N35: 200 | O35: 0.074 | P35: 46.6 | Q35: =IF($O$2="Fraccionada",P35*$S$27/Q$13,IF($O$2="Global",P35/$Q$12*100)) -> 4.3638654 | R35: =+R34+Q35 -> 86.543188 | S35: =100-R35 -> 13.456812 | T35: 5 | V35: 20
A36: 50 | B36: 0.3 | D36: =+S33 -> 23.785876 | N36: < 200 | O36: 0.01 | P36: =IF(O2="Fraccionada",(Q13-(SUM(P28:P35))),IF(O2="Global",(Q12-Q14))) -> 143.7 | Q36: =IF($O$2="Fraccionada",P36*$S$27/Q$13,IF($O$2="Global",P36/$Q$12*100)) -> 13.456812 | R36: =+R35+Q36 -> 100 | S36: =100-R36 -> 0
A37: 100 | B37: 0.149 | D37: =+S34 -> 17.820678 | F37: =IF(O3="No","","Clasificacion AASHTO") | H37: =IF(O3="No","",Aashto!J26) | S37: =MAX(S18:S36) -> 100
A38: 200 | B38: 0.074 | D38: =+S35 -> 13.456812 | N38: D60 | O38: D30 | P38: D10
N39: =IF(AND(S18=60,S19=60),((O18+O19)/2),IF(AND(S18>=60,S19<=60),FORECAST(60,O18:O19,S18:S19),"")) | O39: =IF(AND(S18=30,S19=30),((O18+O19)/2),IF(AND(S18>=30,S19<=30),FORECAST(30,O18:O19,S18:S19),"")) | P39: =IF(AND(S18=10,S19=10),((O18+O19)/2),IF(AND(S18>=10,S19<=10),FORECAST(10,O18:O19,S18:S19),""))
N40: =IF(AND(S19=60,S20=60),((O19+O20)/2),IF(AND(S19>=60,S20<=60),FORECAST(60,O19:O20,S19:S20),"")) | O40: =IF(AND(S19=30,S20=30),((O19+O20)/2),IF(AND(S19>=30,S20<=30),FORECAST(30,O19:O20,S19:S20),"")) | P40: =IF(AND(S19=10,S20=10),((O19+O20)/2),IF(AND(S19>=10,S20<=10),FORECAST(10,O19:O20,S19:S20),""))
N41: =IF(AND(S20=60,S21=60),((O20+O21)/2),IF(AND(S20>=60,S21<=60),FORECAST(60,O20:O21,S20:S21),"")) | O41: =IF(AND(S20=30,S21=30),((O20+O21)/2),IF(AND(S20>=30,S21<=30),FORECAST(30,O20:O21,S20:S21),"")) | P41: =IF(AND(S20=10,S21=10),((O20+O21)/2),IF(AND(S20>=10,S21<=10),FORECAST(10,O20:O21,S20:S21),""))
N42: =IF(AND(S21=60,S22=60),((O21+O22)/2),IF(AND(S21>=60,S22<=60),FORECAST(60,O21:O22,S21:S22),"")) | O42: =IF(AND(S21=30,S22=30),((O21+O22)/2),IF(AND(S21>=30,S22<=30),FORECAST(30,O21:O22,S21:S22),"")) | P42: =IF(AND(S21=10,S22=10),((O21+O22)/2),IF(AND(S21>=10,S22<=10),FORECAST(10,O21:O22,S21:S22),""))
...

Sheet LL-LP
A8: LABORATORIO DE ENSAYO DE MATERIALES
A9: =+K13 -> 10
A11: SOLICITANTE | B11: : | C11: METRO | I11: CÓDIGO | J11: : | K11: F-LEM-P-SU-11.02
A12: PROYECTO | B12: : | C12: CONJUNTO RESIDENCIAL SAN BORJA HOMETOWN | I12: N° OT | J12: : | K12: 150-20
A13: UBICACIÓN | B13: : | C13: CA. DURERO CDRA. 4 S/N, ALT. LA CDRA 13 DE LA AV. SAN | I13: N° CERT. | J13: : | K13: 10
A15: METODO DE ENSAYO PARA DETERMINAR EL LIMITE LIQUIDO, LIMITE PLASTICO E INDICE DE PLASTICIDAD DE SUELOS
A16: NORMA NTP 339.129
A18: DATOS DE LA MUESTRA
A19: CANTERA / SONDAJE | B19: : | C19: CANTERA TRAPICHE | I19: COD. MUESTRA | J19: :
A20: N° MUESTRA | B20: : | C20: M-1 | I20: FECHA RECEP. | J20: : | K20: 43831 | U20: SI
A21: TIPO DE MUESTRA | B21: : | C21: AFIRMADO | I21: FECHA ENSAYO | J21: : | K21: 43844 | U21: NO
D24: LIMITE LIQUIDO | G24: LIMITE PLASTICO | O24: LIMITE LIQUIDO | Q24: NO | R24: LIMITE PLASTICO | T24: NO
B25: Ensayo | D25: =IF($Q$24="NO","",O25) | E25: =IF($Q$24="NO","",P25) | F25: =IF($Q$24="NO","",Q25) | G25: =IF($T$24="NO","",R25) | H25: =IF($T$24="NO","",S25) | N25: Ensayo | O25: 1 | P25: 2 | Q25: 3 | R25: 1 | S25: 2
B26: Recipiente Nº | D26: =IF($Q$24="NO","",O26) | E26: =IF($Q$24="NO","",P26) | F26: =IF($Q$24="NO","",Q26) | G26: =IF($T$24="NO","",R26) | H26: =IF($T$24="NO","",S26) | N26: Recipiente Nº | O26: 5 | P26: 3 | Q26: 4 | R26: 11 | S26: 10
B27: Nº de Golpes | D27: =IF($Q$24="NO","",O27) | E27: =IF($Q$24="NO","",P27) | F27: =IF($Q$24="NO","",Q27) | N27: Nº de Golpes | O27: 34 | P27: 23 | Q27: 14
B28: R + Suelo Hum. | D28: =IF($Q$24="NO","",O28) | E28: =IF($Q$24="NO","",P28) | F28: =IF($Q$24="NO","",Q28) | G28: =IF($T$24="NO","",R28) | H28: =IF($T$24="NO","",S28) | N28: R + Suelo Hum. | O28: 45.75 | P28: 43.9 | Q28: 43.66 | R28: 23.05 | S28: 18.07
B29: R + Suelo Seco | D29: =IF($Q$24="NO","",O29) | E29: =IF($Q$24="NO","",P29) | F29: =IF($Q$24="NO","",Q29) | G29: =IF($T$24="NO","",R29) | H29: =IF($T$24="NO","",S29) | N29: R + Suelo Seco | O29: 41.37 | P29: 40.03 | Q29: 38.78 | R29: 22.63 | S29: 17.48
B30: Peso Recip. | D30: =IF($Q$24="NO","",O30) | E30: =IF($Q$24="NO","",P30) | F30: =IF($Q$24="NO","",Q30) | G30: =IF($T$24="NO","",R30) | H30: =IF($T$24="NO","",S30) | N30: Peso Recip. | O30: 22.74 | P30: 24.18 | Q30: 19.97 | R30: 19.31 | S30: 13.01
B31: Peso Agua | D31: =IF($Q$24="NO","",O31) | E31: =IF($Q$24="NO","",P31) | F31: =IF($Q$24="NO","",Q31) | G31: =IF($T$24="NO","",R31) | H31: =IF($T$24="NO","",S31) | N31: Peso Agua | O31: =+O28-O29 -> 4.38 | P31: =+P28-P29 -> 3.87 | Q31: =+Q28-Q29 -> 4.88 | R31: =+R28-R29 -> 0.42 | S31: =+S28-S29 -> 0.59
B32: Peso S. Seco | D32: =IF($Q$24="NO","",O32) | E32: =IF($Q$24="NO","",P32) | F32: =IF($Q$24="NO","",Q32) | G32: =IF($T$24="NO","",R32) | H32: =IF($T$24="NO","",S32) | N32: Peso S. Seco | O32: =+O29-O30 -> 18.63 | P32: =+P29-P30 -> 15.85 | Q32: =+Q29-Q30 -> 18.81 | R32: =+R29-R30 -> 3.32 | S32: =+S29-S30 -> 4.47
B33: % de Humedad | D33: =IF($Q$24="NO","",O33) | E33: =IF($Q$24="NO","",P33) | F33: =IF($Q$24="NO","",Q33) | G33: =IF($T$24="NO","",R33) | H33: =IF($T$24="NO","",S33) | N33: % de Humedad | O33: =+O31/O32*100 -> 23.510467 | P33: =+P31/P32*100 -> 24.416404 | Q33: =+Q31/Q32*100 -> 25.943647 | R33: =+R31/R32*100 -> 12.650602 | S33: =+S31/S32*100 -> 13.199105
G35: LL | H35: =+IF(Q24="NO","NP",O40) -> NP | N35: Golp. | O35: % Humed
N36: =+D27 | O36: =+D33
N37: =+E27 | O37: =+E33
G38: LP | H38: =+IF(T24="NO","NP",O42) -> NP | N38: =+F27 | O38: =+F33
N39: 25 | O39: 0
N40: 25 | O40: =P41 -> #VALUE! | P40: =+D33/(1.419-0.3*LOG10(D27)) -> #VALUE! | Q40: =+F33/(1.419-0.3*LOG10(F27)) -> #VALUE!
G41: IP | H41: =IF(T24="NO","NP",H35-H38) -> NP | N41: 10 | O41: =+O40 -> #VALUE! | P41: =+AVERAGE(P40:Q40) -> #VALUE!
N42: LP | O42: =AVERAGE(R33:S33) -> 12.924854
A43: Nota :
A44: La muestra fue proporcionada e identificada por el solicitante.
A46: Página 1 de 1
A47: Versión : 01 (02-12-2019)
A50: WEB: www.geofal.com.pe E-MAIL: laboratorio@geofal.com.pe / geofal.sac@gmail.com Av. Marañon 763, Los Olivos-Lima / Teléfono 01 522-1851

Sheet GR-Esp
A8: LABORATORIO DE ENSAYO DE MATERIALES
A9: =J13 -> 1
A11: SOLICITANTE | B11: : | C11: METRO | H11: CÓDIGO | I11: : | J11: F-LEM-P-AG-04.02
A12: PROYECTO | B12: : | C12: CONJUNTO RESIDENCIAL SAN BORJA HOMETOWN | H12: N° OT | I12: : | J12: 15
A13: UBICACIÓN | B13: : | C13: CA. DURERO CDRA. 4 S/N, ALT. LA CDRA 13 DE LA AV. SAN | H13: N° CERT. | I13: : | J13: 1
A15: METODO DE ENSAYO PARA LA DENSIDAD, LA DENSIDAD RELATIVA (PESO ESPECIFICO) Y ABSORCION DEL AGREGADO GRUESO
A16: NORMA NTP 400.021
A18: DATOS DE LA MUESTRA
A19: CANTERA / SONDAJE | B19: : | C19: CANTERA TRAPICHE | H19: COD. MUESTRA | I19: :
A20: N° MUESTRA | B20: : | C20: M-1 | H20: FECHA RECEP. | I20: : | J20: 43831
A21: TIPO DE MUESTRA | B21: : | C21: AFIRMADO | H21: FECHA ENSAYO | I21: : | J21: 43844
C24: DATOS | M24: A | N24: Peso Mat.Sat. Sup. Seca ( En Aire ) (gr) | R24: 935.9
C25: Peso Mat.Sat. Sup. Seca ( En Aire ) (gr) | F25: =+R24 -> 935.9 | M25: B | N25: Peso Mat.Sat. Sup. Seca ( En Agua ) (gr) | R25: 606.5
C26: Peso Mat.Sat. Sup. Seca ( En Agua ) (gr) | F26: =+R25 -> 606.5 | M26: C | N26: Peso material seco en estufa ( 105 ºC )(gr) | R26: 928.2
C27: Peso material seco en estufa ( 105 ºC )(gr) | F27: =+R26 -> 928.2 | M27: D | N27: Gravedad Esp. (OD) ( Base seca ) = C/(A-B) | R27: =R26/(R24-R25) -> 2.8178506
M28: E | N28: Gravedad Esp. (SSD) ( Base saturada) = A/(A-B) | R28: =R24/(R24-R25) -> 2.8412265
C29: Gravedad Especifica | G29: Densidad | M29: F | N29: Gravedad Esp. Aparente ( Base Seca ) = C/(C-B) | R29: =R26/(R26-R25) -> 2.8852969
C30: Gravedad Esp. (OD) ( Base seca ) | F30: =F27/(F25-F26) -> 2.8178506 | G30: =F30*997.5 -> 2810.806 | M30: G | N30: % de absorción = ((A-C)/C*100) | R30: =((R24-R26)/R26*100) -> 0.82956259
C31: Gravedad Esp. (SSD) ( Base saturada) | F31: =F25/(F25-F26) -> 2.8412265 | G31: =F31*997.5 -> 2834.1234
C32: Gravedad Esp. Aparente ( Base Seca ) | F32: =F27/(F27-F26) -> 2.8852969 | G32: =F32*997.5 -> 2878.0836
C33: % de absorción | F33: =((F25-F27)/F27*100) -> 0.82956259 | G33: =+F33 -> 0.82956259
A36: Nota :
A37: La muestra fue proporcionada e identificada por el solicitante.
A50: Página 1 de 1
A51: Versión : 01 (02-12-2019)
A54: WEB: www.geofal.com.pe E-MAIL: laboratorio@geofal.com.pe / geofal.sac@gmail.com Av. Marañon 763, Los Olivos-Lima / Teléfono 01 522-1851

Sheet Sucs 
A1: esa | B1: SISTEMA UNIFICADO DE CLASIFICACION
L2: =+A.Granul!O4 -> Inorganico
B3: N 200= | C3: =+A.Granul!S35 -> 13.456812 | D3: Cu = | E3: =+A.Granul!P60 -> 135.56728 | K3: L.L. | L3: =+IF(N_10="NP",0,N_10) -> 0
B4: N 4= | C4: =+A.Granul!S27 -> 54.211195 | D4: Cc = | E4: =+A.Granul!P61 -> 0.64946683 | F4: CLASIFICACION SUCS | G4: =+Q9 -> GM | K4: I.P. | L4: =+IF(C6="NP",0,C6) -> 0
B5: L.L.= | C5: =+'LL-LP'!H35 -> NP | K5: CU | L5: =IF(OR(E3="----",E3=""),0,E3) -> 135.56728
B6: I.P.= | C6: =+'LL-LP'!H41 -> NP | K6: CC | L6: =IF(OR(E4="----",E4=""),0,E4) -> 0.64946683
B8: DIVISIONES MAYORES | E8: SIMBOLO DE GRUPO | F8: NOMBRES TIPICOS | G8: CRITERIOS DE CLASIFICACION PARA SUELOS GRANULARES | L8: CLASIF | M8: SIMBOLOS DOBLES | O8: SIMBOLOS TRIPLES | P8: CLASIFICACION | Q8: SIMBOLO
B9: Suelos de grano grueso (mas del 50 % del material es mayor en tamaño que el tamiz No 200 | C9: Gravas (mas de la mitad de la fracción gruesa es mayor que el tamiz No 4) | D9: Gravas Limpias (poco o ningun fino) | E9: GW | F9: Gravas bien gradadas, mezclas gravosas, poco o ningun fino | G9: Cu > 4 1 < Cc < 3 | L9: =IF(AND(N_200<50,(100-N_40)>=0.5*(100-N_200),N_200<5,CU>=4,CC>=1,CC<=3),"GW","") | M9: =IF(AND(N_200<50,(100-N_40)>=0.5*(100-N_200),N_200>=5,CU>=4,CC>=1,CC<=3,N_200<12,IP>=7,IP>=0.73*(Ll-20)),"GW-GC","") | N9: =IF(AND(N_200<50,(100-N_40)>=0.5*(100-N_200),N_200>=5,CU>=4,CC>=1,CC<=3,N_200<12,OR(IP<4,IP<0.73*(Ll-20))),"GW-GM","") | O9: =IF(AND(N_200<50,(100-N_40)>=0.5*(100-N_200),N_200>=5,CU>=4,CC>=1,CC<=3,N_200<12,IP>=4,IP<7,IP<0.9*(Ll-8),IP>=0.73*(Ll-20)),"GW-GC-GM","") | P9: =+L9&M9&N9&O9 | Q9: =+P9&P10&P11&P12&P13&P14&P15&P16&P17&P18&P19&P20&P21&P22&P23&P24 -> GM
E10: GP | F10: Gravas pobremente gradadas,`mezclas grava-arena, pocos o ningun fino | G10: No cumple todos los requisitos de gradadcion para GW | L10: =IF(AND(N_200<50,(100-N_40)>=0.5*(100-N_200),N_200<5,OR(CU<4,CC<1,CC>3)),"GP","") | M10: =IF(AND(N_200<50,(100-N_40)>=0.5*(100-N_200),N_200>=5,OR(CU<4,CC<1,CC>3),N_200<12,IP>=7,IP>=0.73*(Ll-20)),"GP-GC","") | N10: =IF(AND(N_200<50,(100-N_40)>=0.5*(100-N_200),N_200>=5,OR(CU<4,CC<1,CC>3),N_200<12,OR(IP<4,IP<0.73*(Ll-20))),"GP-GM","") | O10: =IF(AND(N_200<50,(100-N_40)>=0.5*(100-N_200),N_200>=5,OR(CU<4,CC<1,CC>3),N_200<12,IP>=4,IP<7,IP<0.9*(Ll-8),IP>=0.73*(Ll-20)),"GP-GC-GM","") | P10: =+L10&M10&N10&O10
D11: Gravas con finos (cantidad apre- ciable de finos) | E11: GM | F11: Gravas limosas, mezcla grava- arena-limo | G11: Límites de Atteberg por debajo de la linea A o Ip < 4 | H11: A los materiales sobre la linea A con 4 < Ip < 7 se considera de frontera y se les asigna doble símbolo | L11: =IF(AND(N_200<50,(100-N_40)>=0.5*(100-N_200),N_200>=12,OR(IP<4,IP<0.73*(Ll-20))),"GM","") -> GM | M11: =IF(AND(N_200<50,(100-N_40)>=0.5*(100-N_200),N_200>=12,IP>=4,IP<7,IP>=0.73*(Ll-20)),"GC-GM","") | P11: =+L11&M11&N11&O11 -> GM
E12: GC | F12: Gravas arcillosas, mezcla gravo-areno- arcillosas | G12: Límites de Atteberg por encima de la línea A ó Ip > 7 | L12: =IF(AND(N_200<50,(100-N_40)>=0.5*(100-N_200),N_200>=12,IP>=7,IP>=0.73*(Ll-20)),"GC","") | P12: =+L12&M12&N12&O12
C13: Arenas (mas de la mitad de la fracción gruesa es menor que el tamiz No 4) | D13: Arenas Limpias (poco o ningun fino) | E13: SW | F13: Arenas bien gradadas, arenas gravosas, pocos o ningun fino | G13: Cu > 6 1 < Cc < 3 | L13: =IF(AND(N_200<50,(100-N_40)<0.5*(100-N_200),N_200<5,CU>=6,CC>=1,CC<=3),"SW","") | M13: =IF(AND(N_200<50,(100-N_40)<0.5*(100-N_200),N_200>=5,CU>=6,CC>=1,CC<=3,N_200<12,IP>=7,IP>=0.73*(Ll-20)),"SW-SC","") | N13: =IF(AND(N_200<50,(100-N_40)<0.5*(100-N_200),N_200>=5,CU>=6,CC>=1,CC<=3,N_200<12,OR(IP<4,IP<0.73*(Ll-20))),"SW-SM","") | O13: =IF(AND(N_200<50,(100-N_40)<0.5*(100-N_200),N_200>=5,CU>=6,CC>=1,CC<=3,N_200<12,IP>=4,IP<7,IP<0.9*(Ll-8),IP>=0.73*(Ll-20)),"SW-SC-SM","") | P13: =+L13&M13&N13&O13
E14: SP | F14: Arenas pobremente gradadas, arenas gravosas, pocos o ningun fino | G14: No cumple todos los requisitos de gradadcion para SW | L14: =IF(AND(N_200<50,(100-N_40)<0.5*(100-N_200),N_200<5,OR(CU<6,CC<1,CC>3)),"SP","") | M14: =IF(AND(N_200<50,(100-N_40)<0.5*(100-N_200),N_200>=5,OR(CU<6,CC<1,CC>3),N_200<12,IP>=7,IP>=0.73*(Ll-20)),"SP-SC","") | N14: =IF(AND(N_200<50,(100-N_40)<0.5*(100-N_200),N_200>=5,OR(CU<6,CC<1,CC>3),N_200<12,OR(IP<4,IP<0.73*(Ll-20))),"SP-SM","") | O14: =IF(AND(N_200<50,(100-N_40)<0.5*(100-N_200),N_200>=5,OR(CU<6,CC<1,CC>3),N_200<12,IP>=4,IP<7,IP<0.9*(Ll-8),IP>=0.73*(Ll-20)),"SP-SC-SM","") | P14: =+L14&M14&N14&O14
