Workbook
Name ___CC2: [1]Sucs!$L$6
Name __CC2: [1]Sucs!$L$6
Name _CC1: [2]Sucs!$L$6
Name _CC2: [1]Sucs!$L$6
Name _CU1: [2]Sucs!$L$5
Name _IP1: [2]Sucs!$L$4
Name _L1: #REF!
Name _Ll1: [2]Sucs!$L$3
Name _W1: #REF!
Name Abra: [3]Sucs!$C$3
Name CC: #REF!
Name CCf: '[2]Sucs(Fino)'!$L$6
Name CCVB: [4]Sucs!$L$3
Name CM: [5]BGA!$H$9
Name CU: #REF!
Name CUf: '[2]Sucs(Fino)'!$L$5
Name hh: #REF!
Name IP: #REF!
Name IPf: '[2]Sucs(Fino)'!$L$4
Name L: #REF!
Name LIf: '[2]Sucs(Fino)'!$L$3
Name Ll: #REF!
Name MORA: [5]BGA!$H$13
Name N_10: #REF!
Name N_101: [2]Sucs!$C$5
Name N_10f: '[2]Sucs(Fino)'!$C$5
Name N_200: #REF!
Name N_2001: [2]Sucs!$C$3
Name N_200f: '[2]Sucs(Fino)'!$C$3
Name N_40: #REF!
Name N_401: [2]Sucs!$C$4
Name N_40f: '[2]Sucs(Fino)'!$C$4
Name PC: [4]Sucs!$C$5
Name TABLA: #REF!
Name tipodegranulometria: '[6]G-LL '!$X$2:$X$3
Name tipodemateria: '[6]G-LL '!$X$5:$X$6
Name W: #REF!

Sheet F LEM1
C2: LABORATORIO DE ENSAYO DE MATERIALES | L2: CLIENTE
C3: FORMATO N° F-LEM-P-SU-06.01 | L3: DIRECCIÓN **
L4: PROYECTO **
L5: UBICACIÓN **
D6: No OT | F6: FECHA ENSAYO | G6: REALIZADO POR
L7: RECEPCIÓN N°
L8: F. EMISIÓN
B9: MÉTODO DE ENSAYO ESTÁNDAR PARA LA DENSIDAD Y PESO UNITARIO DEL SUELO IN-SITU MEDIANTE EL MÉTODO DEL CONO DE ARENA | L9: OT N°
B10: NORMA NTP 339.143:1999 (revisada el 2019)
L11: CÓDIGO DE LA MUESTRA
B12: SOLICITANTE : | C12: MAKIBER S. A. SUCURSAL PERÚ | L12: FECHA DE RECEPCIÓN
B13: PROYECTO (*) : | C13: MEJORAMIENTO Y AMPLIACION DE LOS SERVICIOS DE SALUD DEL HOSPITAL DE APOYO DE HUANTA DANIEL ALCIDES CARRIÓN | L13: FECHA DE EJECUCIÓN
B14: UBICACIÓN (*) : | C14: JR. JULIO CESAR TELLO, DISTRITO DE HUANTA, PROVINCIA DE HUANTA, DEPARTAMENTO DE AYACUCHO
L15: CANTERA/SONDAJE **
L16: N° MUESTRA **
B17: DATOS DEL CONO | G17: DATOS DEL MATERIAL COMPACTADO | L17: TIPO DE MUESTRA**
C18: Equipo de densidad N° : | D18: EQ, DENS. 4 | G18: Norma ensayo de Proctor : | H18: -
C19: Masa de arena embudo y placa : | G19: Método de ensayo : | H19: - | M19: =+Datos!Z2 -> ENSAYO PROCTOR | Q19: =+Datos!X2 -> METODO PROCTOR
C20: Densidad de la arena (Q) : | G20: Peso Unitario Seco (kN/ m3) : | M20: - | Q20: -
C21: Volumen calibrado cono : | G21: Humedad Óptima (%) : | M21: =+Datos!Z3 -> ASTM D1557-12 (Reapproved 2021) | Q21: =+Datos!X3 -> C
C22: Lote de arena Nº: | G22: Gravedad específica (P) : | M22: =+Datos!Z4 -> ASTM D698 | Q22: =+Datos!X4 -> B
C23: CONDICIONES AMBIENTALES | M23: =+Datos!Z5 -> NTP 339.141:1999 (Revisado 2014) | Q23: =+Datos!X5 -> A
B24: Temperatura Inicial (ºC): | D24: - | G24: Temperatura Final (ºC): | H24: - | M24: =+Datos!Z6 -> NTP 339.142:1999 (Revisado 2014)
B25: Humedad relativa Inicial (%H.R.): | D25: - | G25: Humedad relativa Final (%H.R.) | H25: -
B27: DESCRIPCIÓN | F27: 1 | G27: 2 | H27: 3 | I27: 4
B28: Verificación pesa patrón 200 g | E28: g | F28: - | G28: - | H28: - | I28: -
B29: Verificación pesa patrón 5 kg | E29: g | F29: - | G29: - | H29: - | I29: -
B30: Ubicación de la prueba (*) | E30: -
B31: Progresiva / Cota / Lado (*) | E31: -
B32: Tipo de muestra (**) (Base, relleno, etc.) | E32: -
B33: Espesor de la capa (*) | E33: cm
B34: Tamaño máximo de grava identificado | E34: -
B35: Tamiz del sobretamaño | E35: -
B36: Descripción visual del suelo (**) | E36: -
B37: Condiciones de entorno (1) | E37: - | F37: - | G37: - | H37: - | I37: -
B39: (1) Transito, vibración, lluvia, contaminación, etc; (*) Dato proporcionado por el cliente; (**) Referencia ASTM D2488; (***) Ref. ASTM D4944 registro con fines de control. NOTA: Los datos consignados en este registro son preliminares de campo, es responsabilidad del cliente asumir los resultados de campo como finales. | K39: =+Datos!Q10 -> EQUIPO | L39: =+Datos!R10 -> CODIGO CONO
K40: =+Datos!Q11 -> EQ.DENS. 1 | L40: =+Datos!R11 -> EQP-0107
B41: CÓDIGOS DE EQUIPOS UTILIZADOS: | D41: Balanza 30 kg | F41: - | G41: Pesa patrón 5 kg | H41: - | K41: =+Datos!Q12 -> EQ.DENS. 2 | L41: =+Datos!R12 -> EQP-0096
D42: Cono | F42: - | G42: Tamiz 3/4 in | H42: - | K42: =+Datos!Q13 -> EQ.DENS. 3 | L42: =+Datos!R13 -> EQP-0034
D43: Termohigrómetro | F43: - | G43: Tamiz 4 in | H43: - | K43: =+Datos!Q14 -> EQ.DENS. 4 | L43: =+Datos!R14 -> EQP-0129
...

Sheet F LEM2
J1: =+'F LEM1'!H22 -> 0
C2: LABORATORIO DE ENSAYO DE MATERIALES
C3: FORMATO N° F-LEM-P-SU-06.01
D6: No OT | F6: FECHA ENSAYO | G6: REALIZADO POR
D7: =+'F LEM1'!D7 -> 0 | F7: =+'F LEM1'!F7 -> 0 | G7: =+'F LEM1'!G7 -> 0
B9: MÉTODO DE ENSAYO ESTÁNDAR PARA LA DENSIDAD Y PESO UNITARIO DEL SUELO IN-SITU MEDIANTE EL MÉTODO DEL CONO DE ARENA
B10: NORMA NTP 339.143:1999 (revisada el 2019)
B11: DESCRIPCIÓN | E11: 1 | F11: 2 | G11: 3 | H11: 4
B12: (A) Masa inicial del cono más arena | D12: g
B13: (B) Masa Residual del cono más arena | D13: g
B14: (C) Masa de arena utilizada en el orificio de prueba, el embudo y la placa base [A-B] | D14: g | E14: =+E12-E13 -> 0 | F14: =+F12-F13 -> 0 | G14: =+G12-G13 -> 0 | H14: =+H12-H13 -> 0
B15: (D) Masa de arena utilizada para llenar el embudo y la placa base (dato lab.) | D15: g | E15: =+'F LEM1'!D19 -> 0 | F15: =+'F LEM1'!D19 -> 0 | G15: =+'F LEM1'!D19 -> 0 | H15: =+'F LEM1'!D19 -> 0
B16: (E) Volumen del orificio de prueba [(C-D)/(Q)] | D16: cm3 | E16: =+(E14-E15)/'F LEM1'!$D$20 -> #DIV/0! | F16: =+(F14-F15)/'F LEM1'!$D$20 -> #DIV/0! | G16: =+(G14-G15)/'F LEM1'!$D$20 -> #DIV/0! | H16: =+(H14-H15)/'F LEM1'!$D$20 -> #DIV/0!
B17: Criterio de Aceptación de mínimos Volumenes | D17: - | E17: =+Datos!F27 -> #DIV/0! | F17: =+Datos!H27 -> #DIV/0! | G17: =+Datos!J27 -> #DIV/0! | H17: =+Datos!L27 -> #DIV/0!
B18: (F) Masa húmeda de material del orificio de prueba | D18: g
B19: (G) Masa seca de material del orificio de prueba [(100*F/(100+w)] | D19: g | E19: =100*E18/(100+E33) -> 0 | F19: =100*F18/(100+F33) -> 0 | G19: =100*G18/(100+G33) -> 0 | H19: =100*H18/(100+H33) -> 0
B20: (H) Masa de sobretamaño | D20: g
B21: (I) Porcentaje de sobretamaño [H*100/F] | D21: % | E21: =+E20*100/E18 -> #DIV/0! | F21: =+F20*100/F18 -> #DIV/0! | G21: =+G20*100/G18 -> #DIV/0! | H21: =+H20*100/H18 -> #DIV/0!
B22: (J) Densidad húmeda [F/E] | D22: g/cm3 | E22: =+E18/E16 -> #DIV/0! | F22: =+F18/F16 -> #DIV/0! | G22: =+G18/G16 -> #DIV/0! | H22: =+H18/H16 -> #DIV/0!
B23: (K) Densidad seca [G/E] | D23: g/cm3 | E23: =+E19/E16 -> #DIV/0! | F23: =+F19/F16 -> #DIV/0! | G23: =+G19/G16 -> #DIV/0! | H23: =+H19/H16 -> #DIV/0!
B24: (L) Peso unitario seco [K*9.802] | D24: kN/m3 | E24: =+E23*9.802 -> #DIV/0! | F24: =+F23*9.802 -> #DIV/0! | G24: =+G23*9.802 -> #DIV/0! | H24: =+H23*9.802 -> #DIV/0!
B26: GRADO DE COMPACTACIÓN
B27: (M) Peso unitario seco laboratorio | D27: kN/m3 | E27: =+'F LEM1'!H20 -> 0 | F27: =+'F LEM1'!H20 -> 0 | G27: =+'F LEM1'!H20 -> 0 | H27: =+'F LEM1'!H20 -> 0
B28: (N) Peso unitario corregido [L*P*9.802*(100-I)/(100*P*9.802-L*I)] | D28: kN/m3 | E28: =IF($J$1="",E24,IF($J$1="-",E24,E24*$J$1*9.802*(100-E21)/(100*$J$1*9.802-E24*E21))) -> #DIV/0! | F28: =IF($J$1="",F24,IF($J$1="-",F24,F24*$J$1*9.802*(100-F21)/(100*$J$1*9.802-F24*F21))) -> #DIV/0! | G28: =IF($J$1="",G24,IF($J$1="-",G24,G24*$J$1*9.802*(100-G21)/(100*$J$1*9.802-G24*G21))) -> #DIV/0! | H28: =IF($J$1="",H24,IF($J$1="-",H24,H24*$J$1*9.802*(100-H21)/(100*$J$1*9.802-H24*H21))) -> #DIV/0!
B29: Porcentaje compactación [(N/(M)*100] | D29: % | E29: =+E28/E27*100 -> #DIV/0! | F29: =+F28/F27*100 -> #DIV/0! | G29: =+G28/G27*100 -> #DIV/0! | H29: =+H28/H27*100 -> #DIV/0!
B30: CRITERIO DE ACEPTACIÓN (*) | D30: %
B32: CONTENIDO DE HUMEDAD
B33: (w*) Contenido de agua SPEEDY (***) | D33: %
B34: (w) Contenido de agua (ASTM D2216) | D34: %
B36: (1) Transito, vibración, lluvia, contaminación, etc; (*) Dato proporcionado por el cliente; (**) Referencia ASTM D2488; (***) Ref. ASTM D4944 registro con fines de control. NOTA: Los datos consignados en este registro son preliminares de campo, es responsabilidad del cliente asumir los resultados de campo como finales.
B37: OBSERVACIONES:
B40: Página 2 de 2
B41: Versión: 06 (2026-05-25)
B43: WEB: www.geofal.com.pe; E-MAIL: laboratorio@geofal.com.pe Av. Marañon 763, Los Olivos-Lima / Teléfono: 01 754-3070

Sheet DENSIDAD
A5: LABORATORIO DE ENSAYO DE MATERIALES
A6: 0
A8: CLIENTE | B8: : | C8: MAKIBER S. A. SUCURSAL PERÚ | I8: CÓDIGO : | J8: F-LEM-P-SU-06.02
A9: DIRECCIÓN ** | B9: : | C9: ING. WILLIAM BEDRIÑANA CARRASCO | I9: FECHA ENSAYO : | J9: =+Datos!D8 -> 0
A10: PROYECTO ** | B10: : | C10: MEJORAMIENTO Y AMPLIACION DE LOS SERVICIOS DE SALUD DEL HOSPITAL DE APOYO DE HUANTA DANIEL ALCIDES CARRIÓN, DISTRITO DE HUANTA, PROVINCIA DE HUANTA, DEPARTAMENTO DE AYACUCHO | I10: FECHA EMISIÓN : | J10: =+'F LEM1'!M8 -> 0
A11: UBICACIÓN ** | B11: : | C11: JR. JULIO CESAR TELLO, DISTRITO DE HUANTA, PROVINCIA DE HUANTA, DEPARTAMENTO DE AYACUCHO
A12: ** Datos proporcionados por el cliente
A14: SUELOS. MÉTODO DE ENSAYO ESTÁNDAR PARA LA DENSIDAD Y PESO UNITARIO DEL SUELO IN-SITU MEDIANTE EL MÉTODO DEL CONO DE ARENA
A15: NTP 339.143 1999 (revisada el 2019)
A17: Datos Cono | I17: Datos material compactado
A18: Identificación Cono N° | D18: : | E18: =+Datos!L2 -> EQ.DENS. 4 | I18: Norma ensayo de Proctor : | J18: ASTM D1557-12 (Reapproved 2021) | K18: =+'F LEM1'!H18 -> -
A19: =+Datos!G5 -> Masa de arena embudo y placa | D19: : | E19: =+Datos!I5 -> 0 | F19: g | I19: Método de ensayo : | J19: C | K19: =+'F LEM1'!H19 -> -
A20: =+Datos!G6 -> Densidad de la arena | D20: : | E20: =+Datos!I6 -> 0 | F20: g/cm3 | I20: Peso Unitario Seco(kN/ m3) : | J20: =+Datos!E4 -> 0
A21: Volumen calibrado cono | D21: : | E21: =+Datos!I7 -> 0 | F21: cm3 | I21: Humedad Optima (%) : | J21: =+Datos!E5 -> 0
I22: Gravedad específica : | J22: =+Datos!E6 -> 0
A24: DESCRIPCIÓN | G24: PRUEBA 1 | H24: PRUEBA 2 | I24: PRUEBA 3 | J24: PRUEBA 4
A25: Ubicación de la prueba** | G25: =+Datos!E13 -> 0 | H25: =+Datos!G13 -> 0 | I25: =+Datos!I13 -> 0 | J25: =+Datos!K13 -> 0
A26: Progresiva/ Cota / Lado** | G26: =+Datos!E14 -> 0 | H26: =+Datos!G14 -> 0 | I26: =+Datos!I14 -> 0 | J26: =+Datos!K14 -> 0
A27: Tipo de Muestra(**) | G27: =+Datos!E15 -> 0 | H27: =+Datos!G15 -> 0 | I27: =+Datos!I15 -> 0 | J27: =+Datos!K15 -> 0
A28: Descripción visual del suelo | G28: =+Datos!E19 -> 0 | H28: =+Datos!G19 -> 0 | I28: =+Datos!I19 -> 0 | J28: =+Datos!K19 -> 0
A29: Espesor de la capa** | F29: cm | G29: =+Datos!E16 -> 0 | H29: =+Datos!G16 -> 0 | I29: =+Datos!I16 -> 0 | J29: =+Datos!K16 -> 0
A30: Volumen del orificio de prueba | F30: cm3 | G30: =Datos!F26 -> #DIV/0! | H30: =Datos!H26 -> #DIV/0! | I30: =Datos!J26 -> #DIV/0! | J30: =Datos!L26 -> #DIV/0!
A31: Tamiz del sobretamaño | G31: =+Datos!E18 -> - | H31: =+Datos!G18 -> - | I31: =+Datos!I18 -> - | J31: =+Datos!K18 -> -
A32: Masa de sobretamaño | F32: g | G32: =+Datos!F30 -> 0 | H32: =+Datos!H30 -> 0 | I32: =+Datos!J30 -> 0 | J32: =+Datos!L30 -> 0
A33: Porcentaje de sobretamaño | F33: % | G33: =+IF(Datos!F31<10, TEXT(ROUND(Datos!F31, 2), "0,00"), TEXT(ROUND(Datos!F31,1),"0,0")) -> #DIV/0! | H33: =+IF(Datos!H31<10, TEXT(ROUND(Datos!H31, 2), "0,00"), TEXT(ROUND(Datos!H31,1),"0,0")) -> #DIV/0! | I33: =+IF(Datos!J31<10, TEXT(ROUND(Datos!J31, 2), "0,00"), TEXT(ROUND(Datos!J31,1),"0,0")) -> #DIV/0! | J33: =+IF(Datos!L31<10, TEXT(ROUND(Datos!L31, 2), "0,00"), TEXT(ROUND(Datos!L31,1),"0,0")) -> #DIV/0!
A34: Densidad húmeda in situ | F34: g/cm3 | G34: =+Datos!F32 -> #DIV/0! | H34: =+Datos!H32 -> #DIV/0! | I34: =+Datos!J32 -> #DIV/0! | J34: =+Datos!L32 -> #DIV/0!
A35: Densidad seca in situ | F35: g/cm3 | G35: =+Datos!F33 -> #DIV/0! | H35: =+Datos!H33 -> #DIV/0! | I35: =+Datos!J33 -> #DIV/0! | J35: =+Datos!L33 -> #DIV/0!
A36: Peso unitario seco in situ | F36: kN/m3 | G36: =+Datos!F34 -> #DIV/0! | H36: =+Datos!H34 -> #DIV/0! | I36: =+Datos!J34 -> #DIV/0! | J36: =+Datos!L34 -> #DIV/0!
A37: GRADO DE COMPACTACIÓN
A38: =+Datos!C38 -> Peso unitario corregido (D4718/D4718M-15(2023)) | F38: kN/m3 | G38: =+Datos!F38 -> #DIV/0! | H38: =+Datos!H38 -> #DIV/0! | I38: =+Datos!J38 -> #DIV/0! | J38: =+Datos!L38 -> #DIV/0!
A39: Porcentaje de compactación | F39: % | G39: =+Datos!F39 -> #DIV/0! | H39: =+Datos!H39 -> #DIV/0! | I39: =+Datos!J39 -> #DIV/0! | J39: =+Datos!L39 -> #DIV/0!
A40: Criterio de aceptación ** | F40: % | G40: =+Datos!F40 -> 0 | H40: =+Datos!H40 -> 0 | I40: =+Datos!J40 -> 0 | J40: =+Datos!L40 -> 0
A41: CONTENIDO DE HUMEDAD
A42: Contenido de agua in situ (ASTM D4944) | F42: % | G42: =+Datos!F43 -> 0 | H42: =+Datos!H43 -> 0 | I42: =+Datos!J43 -> 0 | J42: =+Datos!L43 -> 0
A45: Observaciones:
A50: Página 1 de 1
A51: Versión: 05 (2026-05-26) | J51: Fin del informe

Sheet DENSIDAD NATURAL EMS
A7: LABORATORIO DE ENSAYO DE MATERIALES
A8: 115
A10: CLIENTE | B10: : | J10: CÓDIGO: | K10: F-LEM-P-SU-06.02
A11: DIRECCIÓN ** | B11: : | J11: N° OT: | K11: 185
A12: PROYECTO ** | B12: : | J12: F. EMISIÓN : | K12: 44662
A13: UBICACIÓN ** | B13: :
A14: ** Datos proporcionados por el cliente
A15: MÉTODO DE ENSAYO PARA DETERMINAR LA DENSIDAD Y PESO UNITARIO DEL SUELO IN-SITU MEDIANTE EL MÉTODO DEL CONO DE ARENA
A16: NORMA NTP 339.143
A18: PESO ARENA CONO | D18: : | E18: 1704 | J18: CONO N° : | K18: 2
A19: DENSIDAD ARENA | D19: : | E19: 1.422 | J19: FECHA DE ENSAYO : | K19: 43997
A21: ENSAYO Nº | G21: 1 | O21: DENSIAD NATURAL
A22: UBICACIÓN/CALICATA | O22: UBICACION/CALICATA
A23: CAPA/ESTRATO | O23: CAPA/ESTRATO
A24: Peso Inicial de arena | F24: gr | G24: =+R24 -> 7536 | O24: Peso Inicial de arena | Q24: gr | R24: 7536 | T24: 7000 - 7600
A25: Peso Residual arena | F25: gr | G25: =+R25 -> 3212 | O25: Peso Residual arena | Q25: gr | R25: 3212
A26: Peso arena hueco | F26: gr | G26: =G24-G25-$E$18 -> 2620 | O26: Peso arena hueco | Q26: gr | R26: =R24-R25-$E$18 -> 2620
A27: Volumen hueco | F27: cm3 | G27: =+G26/$E$19 -> 1842.4754 | O27: Volumen hueco | Q27: cm3 | R27: =+R26/$E$19 -> 1842.4754 | T27: 1800 - 2100
A28: Peso Suelo Extraido | F28: gr | G28: =+R28 -> 3594 | O28: Peso Suelo Extraido | Q28: gr | R28: 3594
A29: Densidad húmeda | F29: gr/cm3 | G29: =G28/G27 -> 1.9506366 | O29: Densidad húmeda | Q29: gr/cm3 | R29: =R28/R27 -> 1.9506366
A30: Densidad Seca | F30: gr/cm3 | G30: =+G29/(G34+100)% -> 1.8577492 | O30: Densidad Seca | Q30: gr/cm3 | R30: =+R29/(R32+100)% -> 1.8577492
A31: Peso unitario seco | F31: kN/m3 | G31: =G30*9.8066358553 -> 18.21827 | O31: Peso unitario seco | Q31: kN/m3 | R31: =R30*9.8066358553 -> 18.21827
A32: CONTENIDO DE HUMEDAD | O32: humedad (NTP 339.127) | Q32: % | R32: 5
A33: Con Speedy ( NTP 339.250 ) | F33: % | G33: 7 | O33: DENSIAD CORREGIDA
A34: humedad (NTP 339.127) | F34: % | G34: =+R32 -> 5 | O34: Porcentaje de grava | Q34: % | R34: 50.7
O35: Peso de la grava | Q35: gr | R35: =R28*R34/100 -> 1822.158
A36: =+DENSIDAD!#REF! -> #REF! | O36: Densidad de la grava | Q36: gr/cm3 | R36: 2.642
A37: Los puntos de ensayos fueron ubicados e identificada por el solicitante. | O37: Volumen de grava | Q37: cm3 | R37: =R35/R36 -> 689.68887
A38: Medidor de humedad, marca FORNEY, modelo LA-3405-19. | O38: Peso Suelo | Q38: gr | R38: =R28-R35 -> 1771.842
A39: Balanza, capacidad: 15 kg, marca OHAUS, modelo V11P15T. | O39: Volumen del suelo | Q39: cm3 | R39: =R27-R37 -> 1152.7865
A40: Balanza, capacidad: 500 g, marca OHAUS, modelo YA501. | O40: Densidad húmeda | Q40: gr/cm3 | R40: =+R38/R39 -> 1.5370079
A42: =+DENSIDAD!#REF! -> #REF!
A43: =+DENSIDAD!#REF! -> #REF!
A44: =+DENSIDAD!#REF! -> #REF!
A45: =+DENSIDAD!#REF! -> #REF!
K46: Fin del informe
A51: Página 1 de 1
A52: =+DENSIDAD!A51 -> Versión: 05 (2026-05-26)

Sheet Datos
B1: SUELOS. MÉTODO DE ENSAYO PARA DETERMINAR LA DENSIDAD Y PESO UNITARIO DEL SUELO IN-SITU MEDIANTE EL MÉTODO DEL CONO DE ARENA NTP 339.143 1999 (revisada el 2019) | L1: BALANZA UTILIZADA 30KG
L2: EQ.DENS. 4 | M2: =+LOOKUP(L2,L4:L8,M4:M8) -> EQP-0133 | N2: =+LOOKUP(L2,L4:L7,N4:N7) -> -2.96e-06 | Q2: DATO EQUIPO DENSIDADES | V2: TAMAÑO MAX. GRAVA | W2: TAMIZ SOBRETAMAÑO | X2: METODO PROCTOR | Y2: VOLUMEN MINIMO ORIFICIO | Z2: ENSAYO PROCTOR
C3: INFORMACIÓN MAT. COMPACTADO (proctor) | D3: UND | E3: DATOS | G3: EQUIPO DENSIDADES | I3: EQ.DENS. 4 | J3: =+'F LEM1'!D18 -> EQ, DENS. 4 | L3: EQUIPO | M3: CODIGO BALANZA | N3: CORRECCION | O3: FECHA CALIBRACIÓN | Q3: Equipo cono N° | R3: Masa de arena embudo y placa | S3: ρ arena (g/cm3) | T3: Volumen (cm3) | V3: 1 1/2 in | W3: 3/4 in | X3: C | Y3: 2830 | Z3: ASTM D1557-12 (Reapproved 2021)
C4: Peso unitario seco máximo | D4: kN/m3 | E4: =+'F LEM1'!H20 -> 0 | G4: Identificación cono N° | I4: =+LOOKUP(I3,Q11:Q15,R11:R15) -> EQP-0129 | J4: und | L4: EQ.DENS. 1 | M4: =+#REF! -> #REF! | N4: =+#REF! -> #REF! | O4: =+#REF! -> #REF! | Q4: CONO 1 | R4: 1567 | S4: 1.391 | T4: 1127 | V4: 1 in | W4: 3/8 in | X4: B | Y4: 2120 | Z4: ASTM D698
C5: % humedad óptima | D5: % | E5: =+'F LEM1'!H21 -> 0 | G5: Masa de arena embudo y placa | I5: =+'F LEM1'!D19 -> 0 | J5: g | K5: M2 | L5: EQ.DENS. 2 | M5: =+#REF! -> #REF! | N5: =+#REF! -> #REF! | O5: =+#REF! -> #REF! | Q5: CONO 2 | R5: 1505 | S5: 1.392 | T5: 1081 | V5: 3/4 in | W5: N°4 | X5: A | Y5: 2120 | Z5: NTP 339.141:1999 (Revisado 2014)
C6: Gravedad específica( ASTM C127) | D6: - | E6: =+'F LEM1'!H22 -> 0 | G6: Densidad de la arena | I6: =+'F LEM1'!D20 -> 0 | J6: (g/cm3) | K6: p1 | L6: EQ.DENS. 3 | M6: EQP-0147 | N6: -7.47e-06 | O6: 46086 | Q6: CONO 3 | R6: 1888 | S6: 1.399 | T6: 1349 | V6: 1/2 in | W6: - | X6: - | Y6: 1420 | Z6: NTP 339.142:1999 (Revisado 2014)
C7: DATOS ENSAYO | G7: Volumen calibrado cono | I7: =+'F LEM1'!D21 -> 0 | J7: (cm3) | L7: EQ.DENS. 4 | M7: EQP-0133 | N7: -2.96e-06 | O7: 45931 | Q7: CONO 4 | R7: 1492 | S7: 1.396 | T7: 1069 | V7: 3/8 in | W7: - | X7: - | Y7: 1420 | Z7: -
C8: Fecha de ensayo | D8: =+'F LEM1'!F7 -> 0 | G8: molde calibracion arena | I8: INS-0005 | L8: EQ.DENS. 5 | M8: EQP-0142 | N8: -9.65e-06 | O8: 45981 | Q8: CONO 5 | R8: 1503 | S8: 1.41 | T8: 1066
C9: Ensayado por | D9: - | F9: =+'F LEM1'!G7 -> 0 | Q9: EQUIPO DENSIDADES 15/09/25
Q10: EQUIPO | R10: CODIGO CONO
C11: Descripción | D11: Und | E11: 1 | G11: 2 | I11: 3 | K11: 4 | Q11: EQ.DENS. 1 | R11: EQP-0107
E12: Datos | F12: Corrección | G12: Datos | H12: Corrección | I12: Datos | J12: Corrección | K12: Datos | L12: Corrección | Q12: EQ.DENS. 2 | R12: EQP-0096
C13: Ubicación de la prueba* | E13: =+'F LEM1'!F30 -> 0 | G13: =+'F LEM1'!G30 -> 0 | I13: =+'F LEM1'!H30 -> 0 | K13: =+'F LEM1'!I30 -> 0 | Q13: EQ.DENS. 3 | R13: EQP-0034
C14: Progresiva/ Cota / Lado* | E14: =+'F LEM1'!F31 -> 0 | G14: =+'F LEM1'!G31 -> 0 | I14: =+'F LEM1'!H31 -> 0 | K14: =+'F LEM1'!I31 -> 0 | Q14: EQ.DENS. 4 | R14: EQP-0129
C15: Tipo de Muestra ** | E15: =+'F LEM1'!F32 -> 0 | G15: =+'F LEM1'!G32 -> 0 | I15: =+'F LEM1'!H32 -> 0 | K15: =+'F LEM1'!I32 -> 0 | M15: BASE-SUBBASE-RELLENO-SUBRASANTE | Q15: EQ.DENS. 5 | R15: EQP-0143
C16: Espesor de la capa* | D16: cm | E16: =+'F LEM1'!F33 -> 0 | G16: =+'F LEM1'!G33 -> 0 | I16: =+'F LEM1'!H33 -> 0 | K16: =+'F LEM1'!I33 -> 0
C17: Tamaño Maximo de grava identificado | E17: - | G17: - | I17: - | K17: - | M17: =+'F LEM1'!F34 -> 0
C18: Tamiz del Sobretamaño. | E18: - | G18: - | I18: - | K18: - | M18: =+'F LEM1'!F35 -> 0
C19: Descripción visual del suelo ** | E19: =+'F LEM1'!F36 -> 0 | G19: =+'F LEM1'!G36 -> 0 | I19: =+'F LEM1'!H36 -> 0 | K19: =+'F LEM1'!I36 -> 0 | M19: Grava arenosa color beige
C20: Condiciones de entorno (1) | E20: =+'F LEM1'!F37 -> - | G20: =+'F LEM1'!G37 -> - | I20: =+'F LEM1'!H37 -> - | K20: =+'F LEM1'!I37 -> -
A22: A | C22: Masa inicial del cono mas arena | D22: g | E22: =+'F LEM2'!E12 -> 0 | F22: =E22+($N$2*E22) -> 0 | G22: =+'F LEM2'!F12 -> 0 | H22: =G22+($N$2*G22) -> 0 | I22: =+'F LEM2'!G12 -> 0 | J22: =I22+($N$2*I22) -> 0 | K22: =+'F LEM2'!H12 -> 0 | L22: =K22+($N$2*K22) -> 0
A23: B | C23: Masa Residual del cono mas arena | D23: g | E23: =+'F LEM2'!E13 -> 0 | F23: =E23+($N$2*E23) -> 0 | G23: =+'F LEM2'!F13 -> 0 | H23: =G23+($N$2*G23) -> 0 | I23: =+'F LEM2'!G13 -> 0 | J23: =I23+($N$2*I23) -> 0 | K23: =+'F LEM2'!H13 -> 0 | L23: =K23+($N$2*K23) -> 0
A24: C | B24: M1 | C24: Masa de arena utilizada en el orificio de prueba, el embudo y la placa base | D24: g | F24: =+F22-F23 -> 0 | H24: =+H22-H23 -> 0 | J24: =+J22-J23 -> 0 | L24: =+L22-L23 -> 0
A25: D | B25: M2 | C25: Masa de arena utilizada para llenar el embudo y la placa base | D25: g | F25: =+I5 -> 0 | H25: =+I5 -> 0 | J25: =+I5 -> 0 | L25: =+I5 -> 0
A26: E | B26: V | C26: Volumen del orificio de prueba | D26: cm3 | F26: =+(F24-$F$25)/$I$6 -> #DIV/0! | H26: =+(H24-$H$25)/$I$6 -> #DIV/0! | J26: =+(J24-$J$25)/$I$6 -> #DIV/0! | L26: =+(L24-$L$25)/$I$6 -> #DIV/0! | M26: 4 digitos
C27: Criterio de Aceptación de mínimos Volumenes | E27: =IF(E17="2 in",2830,IF(E17="1 1/2 in",2830,IF(E17="1 in",2120,IF(E17="3/4 in",2120,IF(E17="1/2 in",1420,IF(E17="3/8 in",1420,1420)))))) -> 1420 | F27: =+IF(F26>E27,"Cumple","Justificar") -> #DIV/0! | G27: =IF(G17="2 in",2830,IF(G17="1 1/2 in",2830,IF(G17="1 in",2120,IF(G17="3/4 in",2120,IF(G17="1/2 in",1420,IF(G17="3/8 in",1420,1420)))))) -> 1420 | H27: =+IF(H26>G27,"Cumple","Justificar") -> #DIV/0! | I27: =IF(I17="2 in",2830,IF(I17="1 1/2 in",2830,IF(I17="1 in",2120,IF(I17="3/4 in",2120,IF(I17="1/2 in",1420,IF(I17="3/8 in",1420,1420)))))) -> 1420 | J27: =+IF(J26>I27,"Cumple","Justificar") -> #DIV/0! | K27: =IF(K17="2 in",2830,IF(K17="1 1/2 in",2830,IF(K17="1 in",2120,IF(K17="3/4 in",2120,IF(K17="1/2 in",1420,IF(K17="3/8 in",1420,1420)))))) -> 1420 | L27: =+IF(L26>K27,"Cumple","Justificar") -> #DIV/0!
A28: F | B28: M3 | C28: Masa húmeda de material del orificio de prueba | D28: g | E28: =+'F LEM2'!E18 -> 0 | F28: =E28+($N$2*E28) -> 0 | G28: =+'F LEM2'!F18 -> 0 | H28: =G28+($N$2*G28) -> 0 | I28: =+'F LEM2'!G18 -> 0 | J28: =I28+($N$2*I28) -> 0 | K28: =+'F LEM2'!H18 -> 0 | L28: =K28+($N$2*K28) -> 0
A29: G | B29: M4 | C29: Masa seca de material del orificio de prueba | D29: g | F29: =100*F28/(F43+100) -> 0 | H29: =100*H28/(H43+100) -> 0 | J29: =100*J28/(J43+100) -> 0 | L29: =100*L28/(L43+100) -> 0
A30: H | C30: Masa de sobretamaño | D30: g | E30: =+'F LEM2'!E20 -> 0 | F30: =E30+($N$2*E30) -> 0 | G30: =+'F LEM2'!F20 -> 0 | H30: =G30+($N$2*G30) -> 0 | I30: =+'F LEM2'!G20 -> 0 | J30: =I30+($N$2*I30) -> 0 | K30: =+'F LEM2'!H20 -> 0 | L30: =K30+($N$2*K30) -> 0
A31: I | C31: Porcentaje de Sobretamaño | D31: % | F31: =+(F30/F28)*100 -> #DIV/0! | H31: =+(H30/H28)*100 -> #DIV/0! | J31: =+(J30/J28)*100 -> #DIV/0! | L31: =+(L30/L28)*100 -> #DIV/0! | M31: 3 digitos informe
A32: J | B32: pm | C32: Densidad húmeda in situ | D32: g/cm3 | F32: =+F28/F26 -> #DIV/0! | H32: =+H28/H26 -> #DIV/0! | J32: =+J28/J26 -> #DIV/0! | L32: =+L28/L26 -> #DIV/0! | M32: 3 digito
A33: K | B33: pd | C33: Densidad seca in situ | D33: g/cm3 | F33: =F29/F26 -> #DIV/0! | H33: =H29/H26 -> #DIV/0! | J33: =J29/J26 -> #DIV/0! | L33: =L29/L26 -> #DIV/0! | M33: 3 digito
A34: L | B34: δD | C34: Peso unitario seco in situ | D34: kN/m3 | F34: =+F33*9.802 -> #DIV/0! | H34: =+H33*9.802 -> #DIV/0! | J34: =+J33*9.802 -> #DIV/0! | L34: =+L33*9.802 -> #DIV/0!
B36: GRADO DE COMPACTACIÓN
A37: M | C37: Peso unitario seco laboratorio | D37: kN/m3 | F37: =+$E$4 -> 0 | H37: =+$E$4 -> 0 | J37: =+$E$4 -> 0 | L37: =+$E$4 -> 0 | M37: reporte al 0,1
A38: N | C38: Peso unitario corregido (D4718/D4718M-15(2023)) | D38: kN/m3 | F38: =IF(E6="",F34,IF(E6="-",F34,F34*$E$6*9.802*(100-F31)/((100*$E$6)*9.802-F34*F31))) -> #DIV/0! | H38: =IF(E6="",H34,IF(E6="-",H34,H34*$E$6*9.802*(100-H31)/((100*$E$6)*9.802-H34*H31))) -> #DIV/0! | J38: =IF(E6="",J34,IF(E6="-",J34,J34*$E$6*9.802*(100-J31)/((100*$E$6)*9.802-J34*J31))) -> #DIV/0! | L38: =IF(E6="",L34,IF(E6="-",L34,L34*$E$6*9.802*(100-L31)/((100*$E$6)*9.802-L34*L31))) -> #DIV/0!
C39: Porcentaje compactaciòn | D39: % | F39: =+F38/F37*100 -> #DIV/0! | H39: =+H38/H37*100 -> #DIV/0! | J39: =+J38/J37*100 -> #DIV/0! | L39: =+L38/L37*100 -> #DIV/0!
C40: CRITERIO DE ACEPTACIÓN * | D40: % | F40: =+'F LEM2'!E30 -> 0 | H40: =+'F LEM2'!F30 -> 0 | J40: =+'F LEM2'!G30 -> 0 | L40: =+'F LEM2'!H30 -> 0
B42: CONTENIDO HUMEDAD
B43: W* | C43: Contenido de agua SPEEDY (***) | D43: % | F43: =+'F LEM2'!E33 -> 0 | H43: =+'F LEM2'!F33 -> 0 | J43: =+'F LEM2'!G33 -> 0 | L43: =+'F LEM2'!H33 -> 0
...

Sheet Hoja1
A2: CODIGO | C2: CONCATENADOS | D2: DESCRIPCION | E2: FC | F2: F. MOLDEO | G2: DIA | H2: DIAMETRO | I2: CARGA | J2: AREA | K2: RESIS. CONCRETO | L2: % RESIS | M2: TIPO DE FALLA
A3: 4400 | B3: =+A3+1 -> 4401 | C3: =A3&"-"&B3 -> 4400-4401 | D3: Columnas C-9;5-3/G.H | E3: 350 | F3: 42347 | G3: 7 | H3: 15.05 | I3: 49900 | J3: =H3*H3*PI()/4 -> 177.89465 | K3: =I3/J3 -> 280.5031 | L3: =+K3/E3 -> 0.80143743 | M3: E
C4: =A4&"-"&B4 -> - | E4: 350 | G4: 7 | H4: 15.06 | I4: 50310 | J4: =H4*H4*PI()/4 -> 178.13113 | K4: =I4/J4 -> 282.43238 | L4: =+K4/E4 -> 0.80694967 | M4: F
A5: =+B3+1 -> 4402 | B5: =+A5+1 -> 4403 | C5: =A5&"-"&B5 -> 4402-4403 | E5: 350 | G5: 14 | H5: 15.04 | I5: 56450 | J5: =H5*H5*PI()/4 -> 177.65832 | K5: =I5/J5 -> 317.74476 | L5: =+K5/E5 -> 0.90784216 | M5: F
C6: =A6&"-"&B6 -> - | E6: 350 | G6: 14 | H6: 15 | I6: 59630 | J6: =H6*H6*PI()/4 -> 176.71459 | K6: =I6/J6 -> 337.43677 | L6: =+K6/E6 -> 0.96410507 | M6: F
A7: =+B5+1 -> 4404 | B7: =+A7+1 -> 4405 | C7: =A7&"-"&B7 -> 4404-4405 | E7: 350 | G7: 28 | H7: 15.11 | I7: 65310 | J7: =H7*H7*PI()/4 -> 179.3159 | K7: =I7/J7 -> 364.21755 | L7: =+K7/E7 -> 1.0406216 | M7: F
C8: =A8&"-"&B8 -> - | E8: 350 | G8: 28 | H8: 15.05 | I8: 64730 | J8: =H8*H8*PI()/4 -> 177.89465 | K8: =I8/J8 -> 363.86705 | L8: =+K8/E8 -> 1.0396201 | M8: E
