Workbook
Name _CC2: [1]Sucs!$L$6
Name CC: [2]Sucs!$L$6
Name CC: [3]Sucs!$L$6
Name CM: [4]BGA!$H$9
Name CU: [2]Sucs!$L$5
Name CU: [3]Sucs!$L$5
Name IP: [2]Sucs!$L$4
Name IP: [3]Sucs!$L$4
Name Ll: [2]Sucs!$L$3
Name Ll: [3]Sucs!$L$3
Name MORA: [4]BGA!$H$13
Name N_10: [2]Sucs!$C$5
Name N_10: [3]Sucs!$C$5
Name N_200: [2]Sucs!$C$3
Name N_200: [3]Sucs!$C$3
Name N_40: [2]Sucs!$C$4
Name N_40: [3]Sucs!$C$4
Name TABLA: #REF!
Name TABLA: #REF!
Name TABLA: #REF!

Sheet FORMATO
D2: LABORATORIO DE ENSAYO DE MATERIALES | J2: CLIENTE
D3: FORMATO N° F-LEM-P-AG-35.01 | J3: DIRECCIÓN **
J4: PROYECTO **
J5: UBICACIÓN **
C7: MUESTRA | D7: N° OT | E7: FECHA DE ENSAYO | G7: REALIZADO | J7: RECEPCIÓN N°
J8: F. EMISIÓN
J9: OT N°
B11: STANDARD TEST METHOD FOR DETERMINING THE PERCENTAGE OF FRACTURED PARTICLES IN COARSE AGGREGATE | J11: CÓDIGO DE LA MUESTRA
B12: ASTM D5821-13 (Reapproved 2025) | J12: FECHA DE RECEPCIÓN
J13: FECHA DE EJECUCIÓN
B14: INFORMACIÓN DEL ENSAYO (Marcar "X") | G14: Código equipos utilizados
B15: Método para la determinación del porcentaje de particulas fracturadas | D15: MASA | E15: Recuento | G15: Horno | H15: EQP-0049 | J15: CANTERA/SONDAJE **
B16: Tamaño Maximo Nominal (in) | G16: Balanza 0.1 g | H16: EQP-0046 | J16: N° MUESTRA **
B17: Tamiz especificado (in) (*) | G17: Tamiz especificado | H17: INS-0053 | J17: TIPO DE MUESTRA**
B18: Fraccionada (**) | D18: SI | E18: NO | G18: Tabla peso mínimo Fuente: Norma ASTM D5821-13 (Reapproved 2025)
B19: MUESTRA ORIGINAL DE ENSAYO
B20: (A) Masa de la muestra retenida en el tamiz especificado (g)
B21: (B) Masa de la partícula más grande (g)
B22: Porcentaje en masa de la partícula más grande (%) (***) (B*100/A) | F22: <=1% cumple
B23: Masa de la muestra seca lavada (g)
B24: Masa de la muestra seca lavada constante (g)
B25: Masa de la muestra > 3/8 (g) (****)
B26: Masa de la muestra < 3/8 (g) (****)
B27: (*) El tamiz especificado sera No. 4 o la designada deacuerdo a la gradación.
B28: (**) Fraccionada SI, Para agregados con un TMN de 3/4 in o mayor donde se debe determinar el contenido de partículas de fractura para el material retenido en el tamiz No. 4 o menor, la muestra de prueba se puede separar en el tamiz 3/8 in y la masa se reduce hasta un mínimo de 200 g.
B29: (***) El porcentaje de la partícula más grande no representara más del 1% de masa de muestra de ensayo o la muestra será tan grande como se indica en la tabla 1, lo que sea menor.
B30: (****) Dato registrado solo para método fraccionado.
B31: MUESTRA DE PRUEBA | E31: Partículas con una o más caras fracturadas | G31: Partículas con dos o más caras fracturadas
E32: (1) > 3/8 in o Global | G32: (1) > 3/8 in o Global
A33: F | B33: Masa particulas Fracturadas (g)
A34: N | B34: Masa particulas que no cumplen el criterio especificado (g)
A35: P | B35: Porcentaje de particulas con caras fracturadas (%)
E36: (2) < 3/8 in | G36: (2) < 3/8 in
B37: Masa de la muestra < 3/8 (g), FRACCIÓN MAYOR DE 200 g
A38: F | B38: Masa particulas Fracturadas (g)
A39: N | B39: Masa particulas que no cumplen el criterio especificado (g)
A40: P | B40: Porcentaje de particulas con caras fracturadas (%)
B41: Promedio Ponderado (%)
B42: (1) Si hubo fraccionamiento se considera el material >3/8 in o de lo contrario el material retenido en el tamiz especificado.
B43: (2) Se registrará el material <3/8 in solo si hubo fraccionamiento.
...

Sheet caras fracturadas
A2: LABORATORIO DE ENSAYO DE MATERIALES
A3: 0
A5: CLIENTE | B5: : | C5: =+FORMATO!K2 -> 0 | I5: CÓDIGO | J5: : | K5: F-LEM-P-AG-35.02
A6: DIRECCIÓN ** | B6: : | C6: =+FORMATO!K3 -> 0 | I6: RECEPCIÓN N° | J6: : | K6: =+FORMATO!K7 -> 0
A7: PROYECTO** | B7: : | C7: =+FORMATO!K4 -> 0 | I7: OT N° | J7: : | K7: =+FORMATO!K9 -> 0
A8: UBICACIÓN ** | B8: : | C8: =+FORMATO!K5 -> 0 | I8: FECHA DE EMISIÓN | J8: : | K8: =+FORMATO!K8 -> 0
A9: ** Datos proporcionados por el cliente
A11: Standard Test Method for Determining the Percentage of Fractured Particles in Coarse Aggregate
A12: ASTM D5821-13 (Reapproved 2025)
A14: DATOS DE LA MUESTRA
A15: CANTERA/SONDAJE ** | D15: : | E15: =+FORMATO!K15 -> 0 | I15: CÓDIGO DE LA MUESTRA | J15: : | K15: =+FORMATO!K11 -> 0
A16: N° MUESTRA ** | D16: : | E16: =+FORMATO!K16 -> 0 | I16: FECHA DE RECEPCIÓN | J16: : | K16: =+FORMATO!K12 -> 0
A17: TIPO DE MUESTRA** | D17: : | E17: =+FORMATO!K17 -> 0 | I17: FECHA DE EJECUCIÓN | J17: : | K17: =+FORMATO!K13 -> 0
A18: LUGAR DE ENSAYO | D18: : | E18: Laboratorio de ensayo de materiales
A20: CONDICIÓN DEL ENSAYO
E22: Tamiz especificado (in) | I22: =+Datos!F11 -> 0
E23: Método para la determinación del porcentaje de partículas fracturadas | I23: =+Datos!F8 -> 0
A25: CONDICIÓN DE LA MUESTRA
E27: Tamaño Máximo Nominal (in) | I27: =+Datos!F9 -> 0
A29: DATOS MUESTRA ORIGINAL
E31: Masa total de la muestra de ensayo (g) | I31: =+Datos!G21 -> 0
E32: Masa de la muestra > 3/8 (g) | I32: =IF(Datos!G19=0,"-",Datos!G19) -> -
E33: Masa de la muestra < 3/8 (g) | I33: =IF(Datos!G20=0,"-",Datos!G20) -> -
A35: RESULTADO DEL ENSAYO
E37: Particulas con una o más caras fracturadas (%) | I37: =IF(Datos!G35="","--",Datos!G35) -> #DIV/0!
E38: Particulas con dos o más caras fracturadas (%) | I38: =IF(Datos!I35="","--",Datos!I35) -> #DIV/0!
A40: Nota :
A41: - El cliente es responsable de los datos de identificación de los puntos de ensayo brindados.
A42: - Los resultados expresados se refieren únicamente al ensayo realizado en dicho momento y en las condiciones especificadas en este documento, por lo que GEOFAL S.A.C. no será responsable por los ensayos realizados con la presente muestra en condiciones distintas a las aquí señaladas.
A43: - GEOFAL S.A.C. no se hace responsable por el uso incorrecto o inadecuado del presente informe.
A44: - Los resultados de los ensayos realizados no deben ser utilizados como una certificación de conformidad con normas de producto o como certificado del sistema de calidad de la entidad que lo produce.
A45: - De conformidad con lo dispuesto por el artículo 1321 del Código Civil, queda establecido que en ningún caso la responsabilidad de GEOFAL S.A.C. será mayor al valor del servicio prestado.
A47: Observaciones:
A55: Página 1 de 1
A56: Versión: 04 (2026-06-15) | K56: Fin del Informe

Sheet Datos
B1: Standard Test Method for Determining the Percentage of Fractured Particles in Coarse Aggregate / ASTM D5821-13 (Reapproved 2025)
B3: Declaración de equipos: balanza 15kg a 0.1g | G3: TECNICO
B4: N° | C4: CÓDIGO | D4: CORRECCION | E4: FECHA CALIBRAC. | G4: - | H4: =+FORMATO!G8 -> 0
B5: 1 | C5: =+balanza!C11 -> EQP-0046 | D5: =+balanza!C7 -> -3.29e-06 | E5: =+balanza!D12 -> 46132
B7: INFORMACIÓN DEL ENSAYO | F7: DATOS | G7: CONDICIONES
B8: Metodo para la determinacion del porcentaje de particulas fracturadas | G8: - | J8: Masa mínima
B9: Tamaño Maximo Nominal (in) | F9: =+FORMATO!D16 -> 0 | G9: - | J9: De la Tabla | K9: De la particula mas grande
B10: Fraccionada | F10: - | G10: (*) | J10: =+INDEX(J13:K21,MATCH(F9,J13:J21,0),2) -> #N/A | K10: =F15*100 -> 0
B11: Tamiz especificado (in)
B12: (*) (Fraccionada SI), Para agregados con un TMN de 3/4 in o mayor donde se debe determinar el contenido de partículas de fractura para el material retenido en el tamiz No. 4 o menor, la muestra de prueba se puede separar en el tamiz 3/8. | J12: TMN (in) | K12: Masa Mínima (g)
B13: MUESTRA ORIGINAL DE ENSAYO | F13: DATOS | G13: Masa Corregida | H13: En (%) | J13: 3/8 | K13: 200
B14: Masa de la muestra retenida en el tamiz especificado (g) | F14: =+FORMATO!E20 -> 0 | H14: - | J14: 1/2 | K14: 500
B15: Masa de la partícula más grande (g) | F15: =+FORMATO!E21 -> 0 | H15: - | J15: 3/4 | K15: 1500
B16: Masa mínima | F16: =+IF(F14>MIN(J10:K10),"Cumple","No Cumple") -> #N/A | H16: - | J16: 1 | K16: 3000
B17: Masa de la muestra seca lavada (g) | F17: =+FORMATO!E23 -> 0 | H17: - | J17: 1.5 | K17: 7500
B18: Masa de la muestra seca lavada constante (g) | F18: =+FORMATO!E24 -> 0 | G18: =+F18+$D$5*F18 -> 0 | H18: - | J18: 2 | K18: 15000
B19: Masa de la muestra > 3/8 (g), | F19: =+FORMATO!E25 -> 0 | G19: =+F19+$D$5*F19 -> 0 | H19: =G19/G21*100 -> #DIV/0! | I19: A | J19: 2.5 | K19: 30000
B20: Masa de la muestra < 3/8 (g), | F20: =+FORMATO!E26 -> 0 | G20: =+F20+$D$5*F20 -> 0 | H20: =G20/G21*100 -> #DIV/0! | I20: B | J20: 3 | K20: 60000
B21: Masa total de la muestra de ensayo (g) | G21: =IF(F10="SI",SUM(G19:G20),G18) -> 0 | H21: =IF(F10="SI",SUM(H19:H20),G18/G21*100) -> #DIV/0! | I21: C | J21: 3.5 | K21: 90000
B23: Muestra de prueba | F23: Particulas con una o mas caras fracturadas | G23: Masa Corregida | H23: Particulas con dos o mas caras fracturadas | I23: Masa Corregida | L23: =+(F14-F17)/F17*100 -> #DIV/0!
F24: > 3/8 in o Global | H24: > 3/8 in o Global
A25: F | B25: Masa particulas Fracturadas (g) | F25: =+FORMATO!E33 -> 0 | G25: =+F25+$D$5*F25 -> 0 | H25: =+FORMATO!G33 -> 0 | I25: =+H25+$D$5*H25 -> 0 | K25: =+IF((F25+F26)=F19,"cumple","no cumple") -> cumple
A26: N | B26: Masa particulas que no cumplen el criterio especificado (g) | F26: =+FORMATO!E34 -> 0 | G26: =+F26+$D$5*F26 -> 0 | H26: =+FORMATO!G34 -> 0 | I26: =+H26+$D$5*H26 -> 0 | K26: =+IF((H25+H26)=F19,"cumple","no cumple") -> cumple
A27: P | B27: Porcentaje de particulas con caras fracturadas (%) | G27: =G25/(G25+G26)*100 -> #DIV/0! | I27: =I25/(I25+I26)*100 -> #DIV/0! | J27: P=[F/(F+N)]*100
F29: < 3/8 in | H29: < 3/8 in | I29: < 3/8 in
B30: Masa de la muestra < 3/8 (g), FRACCION MAYOR DE 200GR | F30: =+F31+F32 -> 0 | G30: - | H30: =+H31+H32 -> 0 | I30: - | K30: =IF(F10="NO","-",IF(F20>=F30,"cumple","no cumple")) -> cumple
A31: F1 | B31: Masa particulas Fracturadas (g) | F31: =+FORMATO!E38 -> 0 | G31: =+F31+$D$5*F31 -> 0 | H31: =+FORMATO!G38 -> 0 | I31: =+H31+$D$5*H31 -> 0 | K31: =IF(F10="NO","-",IF(F20>=H30,"cumple","no cumple")) -> cumple
A32: N1 | B32: Masa particulas que no cumplen el criterio especificado (g) | F32: =+FORMATO!E39 -> 0 | G32: =+F32+$D$5*F32 -> 0 | H32: =+FORMATO!G39 -> 0 | I32: =+H32+$D$5*H32 -> 0 | K32: =IF(F10="NO","-",IF((F31+F32=F30),"cumple","no cumple")) -> cumple
A33: P1 | B33: Porcentaje de particulas con caras fracturadas (%) | G33: =IF(F10="NO","",G31/(G31+G32)*100) -> #DIV/0! | I33: =IF(F10="NO","",I31/(I31+I32)*100) -> #DIV/0! | J33: P=[F/(F+N)]*100 | K33: =IF(F10="NO","-",IF((H31+H32=H30),"cumple","no cumple")) -> cumple
B35: Promedio Ponderado (%) | G35: =IF(F10="SI",((G27*H19)+(G33*H20))/100,G27) -> #DIV/0! | I35: =IF(F10="SI",((I27*H19)+(I33*H20))/100,I27) -> #DIV/0!

Sheet incertidumbre
C1: INFORME DE ESTIMACIÓN DE INCERTIDUMBRE | I1: Código: | J1: F-LEM-P-10.01
I2: Versión: | J2: 3
I3: Fecha: | J3: 46146
I4: Página: | J4: 1 de 1
A6: Método: | B6: Standard Test Method for Determining the Percentage of Fractured Particles in Coarse Aggregate
A7: Norma: | B7: ASTM D5821-13 (Reapproved 2017)
A8: Matriz: | B8: Agregados
A9: Mensurando: | B9: Porcentaje de caras fracturada
A11: Paso 1. Definición del proceso de medición | G11: Paso 2. Definición de las variables aleatorias
A13: Variables: | D13: Fórmula:
A16: F = Masa de la particula fracturada
A17: N= Masa particulas que no cumplen el criterio especificado
A20: Equipos a utilizar:
A22: Balanza con resolución de lectura de 0.1g
A24: CÁLCULO: PORCENTAJE DE CARAS FRACTURADAS
A25: Fuentes | B25: Unidades | C25: Valor | D25: Incertidumbre Original | E25: Distribución | F25: Incertidumbre Estándar u(xi) | G25: Coeficiente de Sensibilidad | H25: Contribución ui(y) | I25: =+Datos!F10 -> -
A26: Particulas con una o mas caras fracturadas (%) | C26: =IF(I25="SI",(C36*C27/(C36+C40)+C45*C31/(C45+C49))/(C27+C31)*100,C36/(C36+C40)*100) -> #DIV/0! | D26: --- | E26: --- | F26: --- | G26: --- | H26: --- | J26: Factor de influencia | L26: valor | M26: %
A27: Masa de la muestra > 3/8 (g), | C27: =+Datos!$G$19 -> 0 | D27: --- | E27: --- | F27: =SQRT((F28*F28)+(F29*F29)+(F30*F30)) -> 0.070663522 | G27: =IF(I25="SI",((C36*C31/(C36+C40)/(C27+C31)^2)-(C45*C31/(C45+C49)/(C27+C31)^2))*-1,0) -> 0 | H27: =+G27*F27 -> 0 | I27: A | J27: =+A27 -> Masa de la muestra > 3/8 (g), | L27: =+H27 -> 0 | M27: =+L27/$L$34 -> #DIV/0!
A28: Repetibilidad de la pesada | B28: g | D28: =+balanza!E25 -> 0 | E28: Normal, K=1 | F28: =+D28 -> 0 | G28: --- | H28: --- | J28: =+A31 -> Masa de la muestra < 3/8 (g), | L28: =+H31 -> 0 | M28: =+L28/$L$34 -> #DIV/0!
A29: Certificado de Calibración | B29: g | D29: =2*(SQRT(balanza!$C$8+balanza!$D$8*(POWER(C27,2)))) -> 0.12899612 | E29: Normal, K=2 | F29: =+D29/2 -> 0.064498062 | G29: --- | H29: --- | J29: =+A36 -> Masa particulas Fracturadas (g) | L29: =+H36 -> #DIV/0! | M29: =+L29/$L$34 -> #DIV/0!
A30: Resolución | B30: g | D30: =+balanza!$C$10 -> 0.1 | E30: Rectangular | F30: =+D30/SQRT(3)/2 -> 0.028867513 | G30: --- | H30: --- | J30: =+A40 -> Masa particulas que no cumplen el criterio especificado (g) | L30: =+H40 -> #DIV/0! | M30: =+L30/$L$34 -> #DIV/0!
A31: Masa de la muestra < 3/8 (g), | C31: =+Datos!$F$20 -> 0 | D31: --- | E31: --- | F31: =SQRT((F32*F32)+(F33*F33)+(F34*F34)) -> 0.070663522 | G31: =IF(I25="SI",(-C36*C27/(C36+C40)/(C27+C31)^2)+(C45*C27/(C45+C49)/(C27+C31)^2),0) -> 0 | H31: =+G31*F31 -> 0 | I31: B | J31: =+A45 -> Masa particulas Fracturadas (g) | L31: =+H45 -> 0 | M31: =+L31/$L$34 -> #DIV/0!
A32: Repetibilidad de la pesada | B32: g | D32: =+balanza!E26 -> 0 | E32: Normal, K=1 | F32: =+D32 -> 0 | G32: --- | H32: --- | J32: =+A49 -> Masa particulas que no cumplen el criterio especificado (g) | L32: =+H49 -> 0 | M32: =+L32/$L$34 -> #DIV/0!
A33: Certificado de Calibración | B33: g | D33: =2*(SQRT(balanza!$C$8+balanza!$D$8*(POWER(C31,2)))) -> 0.12899612 | E33: Normal, K=2 | F33: =+D33/2 -> 0.064498062 | G33: --- | H33: --- | J33: =+A53 -> factor de presición | L33: =+H53 -> 0.17096246 | M33: =+L33/$L$34 -> #DIV/0!
A34: Resolución | B34: g | D34: =+balanza!$C$10 -> 0.1 | E34: Rectangular | F34: =+D34/SQRT(3)/2 -> 0.028867513 | G34: --- | H34: --- | L34: =SUM(L27:L33) -> #DIV/0! | M34: =+L34/$L$34 -> #DIV/0!
A35: > 3/8 in o Global
A36: Masa particulas Fracturadas (g) | C36: =+Datos!$F$25 -> 0 | D36: --- | E36: --- | F36: =SQRT((F37*F37)+(F38*F38)+(F39*F39)) -> 0.070663522 | G36: =IF(I25="SI",C27*C40/(C27+C31)/(C36+C40)^2,C40*100/(C36+C40)^2) -> #DIV/0! | H36: =+G36*F36 -> #DIV/0! | I36: F
A37: Repetibilidad de la pesada | B37: g | D37: =+balanza!E27 -> 0 | E37: Normal, K=1 | F37: =+D37 -> 0 | G37: --- | H37: ---
A38: Certificado de Calibración | B38: g | D38: =2*(SQRT(balanza!$C$8+balanza!$D$8*(POWER(C36,2)))) -> 0.12899612 | E38: Normal, K=2 | F38: =+D38/2 -> 0.064498062 | G38: --- | H38: ---
A39: Resolución | B39: g | D39: =+balanza!$C$10 -> 0.1 | E39: Rectangular | F39: =+D39/SQRT(3)/2 -> 0.028867513 | G39: --- | H39: ---
A40: Masa particulas que no cumplen el criterio especificado (g) | C40: =+Datos!$F$26 -> 0 | E40: --- | F40: =SQRT((F41*F41)+(F42*F42)+(F43*F43)) -> 0.070663522 | G40: =IF(I25="SI",C27*C36/(C27+C31)/(C36+C40)^2,C36*100/(C36+C40)^2) -> #DIV/0! | H40: =+G40*F40 -> #DIV/0! | I40: N
A41: Repetibilidad de la pesada | B41: g | D41: =+balanza!E28 -> 0 | E41: Normal, K=1 | F41: =+D41 -> 0 | G41: --- | H41: ---
A42: Certificado de Calibración | B42: g | D42: =2*(SQRT(balanza!$C$8+balanza!$D$8*(POWER(C40,2)))) -> 0.12899612 | E42: Normal, K=2 | F42: =+D42/2 -> 0.064498062 | G42: --- | H42: ---
A43: Resolución | B43: g | D43: =+balanza!$C$10 -> 0.1 | E43: Rectangular | F43: =+D43/SQRT(3)/2 -> 0.028867513 | G43: --- | H43: ---
A44: < 3/8 in
A45: Masa particulas Fracturadas (g) | C45: =+Datos!$F$31 -> 0 | D45: --- | E45: --- | F45: =SQRT((F46*F46)+(F47*F47)+(F48*F48)) -> 0.070663522 | G45: =IF(I25="SI",C31*C45/(C27+C31)/(C45+C49)^2,0) -> 0 | H45: =+G45*F45 -> 0 | I45: F1
A46: Repetibilidad de la pesada | B46: g | D46: =+balanza!E29 -> 0 | E46: Normal, K=1 | F46: =+D46 -> 0 | G46: --- | H46: ---
A47: Certificado de Calibración | B47: g | D47: =2*(SQRT(balanza!$C$8+balanza!$D$8*(POWER(C45,2)))) -> 0.12899612 | E47: Normal, K=2 | F47: =+D47/2 -> 0.064498062 | G47: --- | H47: ---
A48: Resolución | B48: g | D48: =+balanza!$C$10 -> 0.1 | E48: Rectangular | F48: =+D48/SQRT(3)/2 -> 0.028867513 | G48: --- | H48: ---
A49: Masa particulas que no cumplen el criterio especificado (g) | C49: =+Datos!$F$32 -> 0 | D49: --- | E49: --- | F49: =SQRT((F50*F50)+(F51*F51)+(F52*F52)) -> 0.070663522 | G49: =IF(I25="SI",C31*C45/(C27+C31)/(C45+C49)^2,0) -> 0 | H49: =+G49*F49 -> 0 | I49: N1
...

Sheet balanza
B2: CALIBRACION DE LA BALANZA
B7: Corrección | C7: -3.29e-06
B8: Variables | C8: 0.00416 | D8: 2.43e-10
B9: Ecuación | C9: 2*RAIZ(0.00416+0.000000000243*R2)
B10: Resolución | C10: 0.1 | D10: g
B11: Código | C11: EQP-0046
B12: Fecha ultima calibracion | D12: 46132
B13: ITEM | C13: MES | D13: 20 | E13: 200 | F13: 500 | G13: 1000 | H13: 5000 | I13: 10000 | J13: 11000
B14: 1
C17: DESV STD | D17: 0 | E17: 0 | F17: 0 | G17: 0 | H17: 0 | I17: 0 | J17: 0
B19: Busqueda de Repetibilidad de la masa
D20: =+D13 -> 20 | E20: =+E13 -> 200 | F20: =+F13 -> 500 | G20: =+G13 -> 1000 | H20: =+H13 -> 5000 | I20: =+I13 -> 10000 | J20: =+J13 -> 11000
D21: =D17 -> 0 | E21: =E17 -> 0 | F21: =F17 -> 0 | G21: =G17 -> 0 | H21: =H17 -> 0 | I21: =I17 -> 0 | J21: =J17 -> 0
B23: ENSAYO DE LA MUESTRA
B25: Masa de la muestra > 3/8 (g), | D25: =+Datos!$G$19 -> 0 | E25: =IF(D25<=$D$20,$D$21,IF(AND(D25>$D$20,D25<=$E$20),$E$21,IF(AND(D25>$E$20,D25<=$F$20),$F$21,IF(AND(D25>$F$20,D25<=$G$20),$G$21,IF(AND(D25>$G$20,D25<=$H$20),$H$21,$H$21))))) -> 0 | F25: - | G25: -
B26: Masa de la muestra < 3/8 (g), | D26: =+Datos!$F$20 -> 0 | E26: =IF(D26<=$D$20,$D$21,IF(AND(D26>$D$20,D26<=$E$20),$E$21,IF(AND(D26>$E$20,D26<=$F$20),$F$21,IF(AND(D26>$F$20,D26<=$G$20),$G$21,IF(AND(D26>$G$20,D26<=$H$20),$H$21,$H$21))))) -> 0 | F26: - | G26: -
B27: Masa particulas Fracturadas (g) | D27: =+Datos!$F$25 -> 0 | E27: =IF(D27<=$D$20,$D$21,IF(AND(D27>$D$20,D27<=$E$20),$E$21,IF(AND(D27>$E$20,D27<=$F$20),$F$21,IF(AND(D27>$F$20,D27<=$G$20),$G$21,IF(AND(D27>$G$20,D27<=$H$20),$H$21,$H$21))))) -> 0 | F27: =+Datos!$H$25 -> 0 | G27: =IF(F27<=$D$20,$D$21,IF(AND(F27>$D$20,F27<=$E$20),$E$21,IF(AND(F27>$E$20,F27<=$F$20),$F$21,IF(AND(F27>$F$20,F27<=$G$20),$G$21,IF(AND(F27>$G$20,F27<=$H$20),$H$21,$H$21))))) -> 0
B28: Masa particulas que no cumplen el criterio especificado (g) | D28: =+Datos!$F$26 -> 0 | E28: =IF(D28<=$D$20,$D$21,IF(AND(D28>$D$20,D28<=$E$20),$E$21,IF(AND(D28>$E$20,D28<=$F$20),$F$21,IF(AND(D28>$F$20,D28<=$G$20),$G$21,IF(AND(D28>$G$20,D28<=$H$20),$H$21,$H$21))))) -> 0 | F28: =+Datos!$H$26 -> 0 | G28: =IF(F28<=$D$20,$D$21,IF(AND(F28>$D$20,F28<=$E$20),$E$21,IF(AND(F28>$E$20,F28<=$F$20),$F$21,IF(AND(F28>$F$20,F28<=$G$20),$G$21,IF(AND(F28>$G$20,F28<=$H$20),$H$21,$H$21))))) -> 0
B29: Masa particulas Fracturadas (g) | D29: =+Datos!$F$31 -> 0 | E29: =IF(D29<=$D$20,$D$21,IF(AND(D29>$D$20,D29<=$E$20),$E$21,IF(AND(D29>$E$20,D29<=$F$20),$F$21,IF(AND(D29>$F$20,D29<=$G$20),$G$21,IF(AND(D29>$G$20,D29<=$H$20),$H$21,$H$21))))) -> 0 | F29: =+Datos!$H$31 -> 0 | G29: =IF(F29<=$D$20,$D$21,IF(AND(F29>$D$20,F29<=$E$20),$E$21,IF(AND(F29>$E$20,F29<=$F$20),$F$21,IF(AND(F29>$F$20,F29<=$G$20),$G$21,IF(AND(F29>$G$20,F29<=$H$20),$H$21,$H$21))))) -> 0
B30: Masa particulas que no cumplen el criterio especificado (g) | D30: =+Datos!$F$32 -> 0 | E30: =IF(D30<=$D$20,$D$21,IF(AND(D30>$D$20,D30<=$E$20),$E$21,IF(AND(D30>$E$20,D30<=$F$20),$F$21,IF(AND(D30>$F$20,D30<=$G$20),$G$21,IF(AND(D30>$G$20,D30<=$H$20),$H$21,$H$21))))) -> 0 | F30: =+Datos!$H$32 -> 0 | G30: =IF(F30<=$D$20,$D$21,IF(AND(F30>$D$20,F30<=$E$20),$E$21,IF(AND(F30>$E$20,F30<=$F$20),$F$21,IF(AND(F30>$F$20,F30<=$G$20),$G$21,IF(AND(F30>$G$20,F30<=$H$20),$H$21,$H$21))))) -> 0

Sheet precision
A3: FACTOR DE PRECISION OPERADOR
A4: Fecha de evaluacion: | B4: 45789
A6: 1-Calcular la Incertidumbre estandar CON UNA CARA A MAS | G6: 1-Calcular la Incertidumbre estandar CON DOS CARA A MAS
A7: Varianza Repetibilidad (Sr2 ) | B7: 0.17096246 | G7: Varianza Repetibilidad (Sr2 ) | H7: 0.15395667
A8: Varianza entre Laboratorios (SL2) | B8: 0.024584592 | G8: Varianza entre Laboratorios (SL2) | H8: 0.023680741
