Workbook

Sheet FORMATO
M2: CLIENTE
M3: DIRECCIÓN **
M4: PROYECTO **
M5: UBICACIÓN **
A7: LABORATORIO DE ENSAYO DE MATERIALES | M7: RECEPCIÓN N°
A8: FORMATO N° F-LEM-P-AG-26.01 | M8: F. EMISIÓN
M9: OT N°
C10: MUESTRA | D10: No OT | F10: FECHA | H10: REALIZADO
M11: CÓDIGO DE LA MUESTRA
M12: FECHA DE RECEPCIÓN
A13: STANDARD TEST METHOD FOR RESISTANCE TO DEGRADATION OF LARGE-SIZE COARSE AGGREGATE BY ABRASION AND IMPACT IN THE LOS ANGELES MACHINE | M13: FECHA DE EJECUCIÓN
A14: ASTM C535 − 16
M15: CANTERA/SONDAJE **
M16: N° MUESTRA **
B17: DESCRIPCIÓN | D17: UND | E17: DATOS | H17: Se requiere lavado despues de la prueba | M17: TIPO DE MUESTRA**
B18: Masa muestra inicial | D18: g | H18: TMN
B19: Masa muestra inicial seca | D19: g | H19: Masa de las 12 esferas mayor 4975g y menor 5025g
B20: Masa muestra inicial seca constante | D20: g
B27: Ref. ASTM C535-16
B28: TAMIZ (in) | E28: GRADACIONES (Masa en cada tamiz, g)
B29: Pasante | C29: Retenido | E29: 1 | G29: 2 | I29: 3
B30: 3 | C30: 2.5 | G30: - | I30: -
B31: 2.5 | C31: 2 | G31: - | I31: -
B32: 2 | C32: 1.5 | I32: -
B33: 1.5 | C33: 1 | E33: -
B34: 1 | C34: 0.75 | E34: - | G34: -
B35: Total (*)
A37: ITEM | B37: DESCRIPCIÓN | D37: UND | E37: Gradación 1 | G37: Gradación 2 | I37: Gradación 3
A38: a | B38: Masa original de la muestra de prueba | D38: g
A39: b | B39: Masa retenida en el tamiz No. 12 | D39: g
A40: c | B40: Masa lavada seca retenida en el tamiz No. 12 | D40: g
A41: d | B41: Masa lavada seca constante retenida en el tamiz No. 12, <0.1% | D41: g
A42: e | B42: Diferencia masa gradación y retenida tamiz No.12 o seca. | D42: g
A43: f | B43: Desgate (e/a *100) | D43: %
B44: Perdida de masa por lavado (b-d)/a*100 < 0.2% | D44: %
B46: Codigo de Equipo utilizado | C46: Horno | G46: Balanza
C47: Máquina Los Angeles | G47: Malla No. 12
A49: Nota:
A54: Página 1 de 1
A55: Versión: 02 (08-10-2024)
...

Sheet INFORME
A6: LABORATORIO DE ENSAYO DE MATERIALES
A7: 0
A9: CLIENTE | B9: : | C9: =+FORMATO!N2 -> 0 | H9: CÓDIGO | I9: : | J9: F-LEM-P-AG-26.02
A10: DIRECCION ** | B10: : | C10: =+FORMATO!N3 -> 0 | H10: RECEPCIÓN N° | I10: : | J10: =+FORMATO!N7 -> 0
A11: PROYECTO ** | B11: : | C11: =+FORMATO!N4 -> 0 | H11: N° OT | I11: : | J11: =+FORMATO!N9 -> 0
A12: UBICACIÓN ** | B12: : | C12: =+FORMATO!N5 -> 0 | H12: F. EMISIÓN | I12: : | J12: =+FORMATO!N8 -> 0
A13: ** Datos proporcionados por el cliente
A14: STANDARD TEST METHOD FOR RESISTANCE TO DEGRADATION OF LARGE-SIZE COARSE AGGREGATE BY ABRASION AND IMPACT IN THE LOS ANGELES MACHINE
A15: ASTM C535-16 (Reapproved 2024)
A17: DATOS DE LA MUESTRA
A18: CANTERA/SONDAJE ** | D18: : | E18: =+FORMATO!N15 -> 0 | H18: CÓDIGO DE LA MUESTRA | I18: : | J18: =+FORMATO!N11 -> 0
A19: N° MUESTRA ** | D19: : | E19: =+FORMATO!N16 -> 0 | H19: FECHA DE RECEPCIÓN | I19: : | J19: =+FORMATO!N12 -> 0 | Q19: -
A20: TIPO DE MUESTRA** | D20: : | E20: =+FORMATO!N17 -> 0 | H20: FECHA DE EJECUCIÓN | I20: : | J20: =+FORMATO!N13 -> 0 | Q20: 1
A21: LUGAR DE ENSAYO | D21: : | E21: Laboratorio de ensayo de Materiales | Q21: 2
Q22: 3
E23: DESCRIPCIÓN | G23: UND | H23: DATOS
E24: Masa original de la muestra de prueba | G24: g | H24: =+DATOS!F24 -> 0
E25: Masa final de la muestra de prueba | G25: g | H25: =+DATOS!G26 -> 0
E26: Pérdida por abrasión | G26: % | H26: =+DATOS!F29 -> #DIV/0!
A29: Descripción de la muestra:
A30: Tamaño máximo nominal (in) | G30: =+DATOS!J10 -> 0
A31: Gradación de la muestra de prueba | G31: =+DATOS!J9 -> -
A33: Nota:
A34: - El cliente es responsable de los datos de identificación de los puntos de ensayo brindados.
A35: - Los resultados expresados se refieren únicamente al ensayo realizado en dicho momento y en las condiciones especificadas en este documento, por lo que GEOFAL S.A.C. no será responsable por los ensayos realizados con la presente muestra en condiciones distintas a las aquí señaladas.
A36: - GEOFAL S.A.C. no se hace responsable por el uso incorrecto o inadecuado del presente informe.
A37: - Los resultados de los ensayos realizados no deben ser utilizados como una certificación de conformidad con normas de producto o como certificado del sistema de calidad de la entidad que lo produce.
A38: - De conformidad con lo dispuesto por el artículo 1321 del Código Civil, queda establecido que en ningún caso la responsabilidad de GEOFAL S.A.C. será mayor al valor del servicio prestado.
A40: Observaciones:
A50: Página 1 de 1
A51: Versión: 04 (2026-06-15) | J51: Fin del Informe

Sheet DATOS
A1: STANDARD TEST METHOD FOR RESISTANCE TO DEGRADATION OF LARGE-SIZE COARSE AGGREGATE BY ABRASION AND IMPACT IN THE LOS ANGELES MACHINE ASTM C535-16 (Reapproved 2024) | T1: CLASIFICACION DE LA MUESTRA DE PRUEBA
A2: Informacion para la Correccion por Certificado de Calibración: balanza 30kg
A3: Precision Balanza al | C3: 1 | D3: g
A4: Correccion | C4: =+balanza!C7 -> -1.49e-06
A5: Codigo balanza | C5: =+balanza!C11 -> EQP-0054
A6: Fecha de calibración | C6: =+balanza!D12 -> 46160
B8: DESCRIPCIÓN | D8: UND | E8: DATOS | I8: Agregado requiere lavado | J8: -
B9: Masa muestra inicial | D9: g | E9: =+FORMATO!E18 -> 0 | I9: Gradación | J9: -
B10: Masa muestra inicial seca | D10: g | E10: =+FORMATO!E19 -> 0 | I10: TMN | J10: =+FORMATO!J18 -> 0
B11: Masa muestra inicial seca constante | D11: g | E11: =+FORMATO!E20 -> 0 | I11: Masa de las 12 esferas | J11: =+FORMATO!J19 -> 0 | K11: =IF(AND(J11>=4975,J11<=5025),"Cumple","No Cumple") -> No Cumple
B12: Verificacion de Masa seca constante | E12: =(E10-E11)/E11*100 -> #DIV/0! | F12: =IF(E12<0.1,"cumple","no cumple") -> #DIV/0! | I12: OPERADORES | J12: - | K12: =+FORMATO!H11 -> 0
B14: TAMIZ (in) | E14: Masa (g) | F14: CORRECCIÓN | G14: CONDICION DE MASA | I14: Masa especificada (g)
B15: Pasante | C15: Retenido | I15: minima | J15: maximo
B16: 3 | C16: 2.5 | F16: =E16+C4*E16 -> 0 | G16: =IF(J9="-","",IF(J9=2,"",IF(J9=3,"",IF(AND(J9=1,AND(F16>=I16,F16<=J16)),"Cumple","No Cumple")))) | I16: =IF(J9=1,2450,"") | J16: =IF(J9=1,2550,"")
B17: 2.5 | C17: 2 | F17: =E17+C4*E17 -> 0 | G17: =IF(J9="-","",IF(J9=2,"",IF(J9=3,"",IF(AND(J9=1,AND(F17>=I17,F17<=J17)),"Cumple","No Cumple")))) | I17: =IF(J9=1,2450,"") | J17: =IF(J9=1,2550,"")
B18: 2 | C18: 1.5 | F18: =E18+C4*E18 -> 0 | G18: =IF(J9="-","",IF(J9=3,"",IF(AND(F18>=I18,F18<=J18),"Cumple","No Cumple"))) | I18: =IF(J9=1,4950,IF(J9=2,4950,"")) | J18: =IF(J9=1,5050,IF(J9=2,5050,""))
B19: 1.5 | C19: 1 | F19: =E19+C4*E19 -> 0 | G19: =IF(J9="-","",IF(J9=1,"",IF(AND(F19>=I19,F19<=J19),"Cumple","No Cumple"))) | I19: =IF(J9=2,4975,IF(J9=3,4975,"")) | J19: =IF(J9=2,5025,IF(J9=3,5025,""))
B20: 1 | C20: 0.75 | F20: =E20+C4*E20 -> 0 | G20: =IF(J9="-","",IF(J9=1,"",IF(J9=2,"",IF(AND(F20>=I20,F20<=J20),"Cumple","No Cumple")))) | I20: =IF(J9=3,4975,"") | J20: =IF(J9=3,5025,"")
B21: TOTAL | E21: =SUM(E16:E20) -> 0 | F21: =SUM(F16:F20) -> 0 | G21: =IF(J9="-","",IF(AND(F21>=I21,F21<=J21),"Cumple","No Cumple")) | I21: =IF(J9="-","",IF(J9=1,9900,IF(J9=2,9925,IF(J9=3,9950)))) | J21: =IF(J9="-","",IF(J9=1,10100,IF(J9=2,10075,IF(J9=3,10050))))
A23: ITEM | B23: DESCRIPCIÓN | D23: UND | E23: Gradación | F23: CORRECCIÓN
A24: a | B24: Masa original de la muestra de prueba | D24: g | F24: =+F21 -> 0
A25: b | B25: Masa retenida en el tamiz No. 12 | D25: g | F25: =E25+$C$4*E25 -> 0
A26: c | B26: Masa lavada seca retenida en el tamiz No. 12 | D26: g | F26: =E26+$C$4*E26 -> 0 | G26: =+IF(J8="NO",F25,F27) -> 0
A27: d | B27: Masa lavada seca constante retenida en el tamiz No. 12 | D27: g | F27: =E27+$C$4*E27 -> 0
A28: e | B28: Diferencia masa gradación y retenida tamiz No. 12 o seca. | D28: g | F28: =IF(J8="no",F24-F25,F24-F27) -> 0
A29: f | B29: Desgate (e/a *100) | D29: % | F29: =(F28/F24)*100 -> #DIV/0!
B30: Perdida de masa por lavado | D30: % | E30: =IF(J8="NO","",(E25-E27)/E21*100) -> #DIV/0! | F30: =IF(J8="NO","",IF(E30<0.2,"cumple","no cumple")) -> #DIV/0!
B31: Verificacion de Masa seca constante | E31: =IF(J8="NO","",(E26-E27)/E27*100) -> #DIV/0! | F31: =IF(J8="NO","",IF(E31<0.1,"cumple","no cumple")) -> #DIV/0!

Sheet incertidumbre
C1: INFORME DE ESTIMACIÓN DE INCERTIDUMBRE | I1: Código: | J1: F-LEM-P-10.01
I2: Versión: | J2: 3
I3: Fecha: | J3: 46146
I4: Página: | J4: 1 de 1
A6: Método: | B6: STANDARD TEST METHODS FOR RESISTANCE TO DEGRADATION OF LARGE-SIZE COARSE AGGREGATE BY ABRASION AND IMPACT IN THE LSO ANGELES MACHINE
A7: Norma: | B7: ASTM C535-16 (Reapproved 2024)
A8: Matriz: | B8: Agregados
A9: Mensurando: | B9: Resistencia a la degradación
A11: Paso 1. Definición del proceso de medición | E11: Paso 2. Definición de las variables aleatorias
A13: Variables:
A15: PA = Perdida abrasión
A16: C= Masa de la muestra de prueba
A17: Y= Masa final de la muestra
I18: 18SAM*
A19: Equipos a utilizar:
A21: Balanza con resolución de lectura de 1g
A23: Fórmula:
A27: CÁLCULO: RESISTENCIA A LA DEGRADACION AGREGADOS GRAN TAMAÑO
A28: Fuentes | B28: Unidades | C28: Valor | D28: Incertidumbre Original | E28: Distribución | F28: Incertidumbre Estándar u(xi) | G28: Coeficiente de Sensibilidad | H28: Contribución ui(y)
A29: Pérdida por abrasión (%) | C29: =+(C30-C34)/C30*100 -> #DIV/0! | D29: --- | E29: --- | F29: --- | G29: --- | H29: ---
A30: Masa de la muestra de prueba | B30: g | C30: =+DATOS!F24 -> 0 | D30: --- | E30: --- | F30: =SQRT((F31*F31)+(F32*F32)+(F33*F33)) -> 1.106044 | G30: =100*C34/C30/C30 -> #DIV/0! | H30: =+G30*F30 -> #DIV/0! | I30: C
A31: Repetibilidad de la pesada | B31: g | D31: =+balanza!E24 -> 0 | E31: Normal, K=1 | F31: =+D31 -> 0 | G31: --- | H31: ---
A32: Certificado de Calibración | B32: g | D32: =2*(SQRT(balanza!$C$8+balanza!$D$8*(POWER(C30,2)))) -> 2.1354157 | E32: Normal, K=2 | F32: =+D32/2 -> 1.0677078 | G32: --- | H32: ---
A33: Resolución | B33: g | D33: =+balanza!C10 -> 1 | E33: Rectangular | F33: =+D33/SQRT(3)/2 -> 0.28867513 | G33: --- | H33: ---
A34: Masa final de la muestra | B34: g | C34: =+DATOS!G26 -> 0 | E34: --- | F34: =SQRT((F35*F35)+(F36*F36)+(F37*F37)) -> 1.106044 | G34: =100/C30 -> #DIV/0! | H34: =+G34*F34 -> #DIV/0! | I34: Y
A35: Repetibilidad de la pesada | B35: g | D35: =+balanza!E25 -> 0 | E35: Normal, K=1 | F35: =+D35 -> 0 | G35: --- | H35: ---
A36: Certificado de Calibración | B36: g | D36: =2*(SQRT(balanza!$C$8+balanza!$D$8*(POWER(C34,2)))) -> 2.1354157 | E36: Normal, K=2 | F36: =+D36/2 -> 1.0677078 | G36: --- | H36: ---
A37: Resolución | B37: g | D37: =+balanza!C10 -> 1 | E37: Rectangular | F37: =+D37/SQRT(3)/2 -> 0.28867513 | G37: --- | H37: ---
A38: factor de presición | B38: % | C38: =+precision!B7 -> 0.0090531621 | E38: Norma, K=1 | F38: =C38/SQRT(1) -> 0.0090531621 | G38: 1 | H38: =+F38*G38 -> 0.0090531621
A39: Incertidumbre Estándar Combinada | G39: % | H39: =SQRT((H30*H30)+(H34*H34)+(H38*H38)) -> #DIV/0!
A40: Incertidumbre Expandida, K = 2 | G40: % | H40: =+H39*2 -> #DIV/0!
A43: CONTRIBUCIÓN
A44: Factor de influencia | C44: valor | D44: %
B45: =+A30 -> Masa de la muestra de prueba | C45: =+H30 -> #DIV/0! | D45: =+C45/$C$48 -> #DIV/0!
B46: =+A34 -> Masa final de la muestra | C46: =+H34 -> #DIV/0! | D46: =+C46/$C$48 -> #DIV/0!
B47: =+A38 -> factor de presición | C47: =+H38 -> 0.0090531621 | D47: =+C47/$C$48 -> #DIV/0!
C48: =SUM(C45:C47) -> #DIV/0! | D48: =+C48/$C$48 -> #DIV/0!
A51: REVISADO POR: | B51: FABIAN LA ROSA | E51: APROBADO POR: | G51: IRMA COAQUIRA
A53: FECHA DE REVISIÓN: | B53: 45604 | E53: FECHA DE APROBACIÓN: | G53: 45605

Sheet balanza
B2: CALIBRACION DE LA BALANZA
B7: Correccion | C7: -1.49e-06
B8: Variables | C8: 1.14 | D8: 2.48e-10
B9: Ecuacion | C9: 2*RAIZ(1.14+0.000000000248*R2) | F9: g
B10: Resolucion | C10: 1 | D10: g
B11: Codigo | C11: EQP-0054
B12: Fecha de calibración | D12: 46160
B13: ITEM | C13: MES | D13: 500 | E13: 1000 | F13: 5000 | G13: 10000 | H13: 15000 | I13: 20000
C17: DESV STD | D17: 0 | E17: 0 | F17: 0 | G17: 0 | H17: 0
B19: Busqueda de Repetibilidad de la masa
D20: =+D13 -> 500 | E20: =+E13 -> 1000 | F20: =+F13 -> 5000 | G20: =+G13 -> 10000 | H20: =+H13 -> 15000
D21: =D17 -> 0 | E21: =E17 -> 0 | F21: =F17 -> 0 | G21: =G17 -> 0 | H21: =H17 -> 0
B23: ENSAYO DE LA MUESTRA
B24: Masa de la muestra de prueba | D24: =+DATOS!F24 -> 0 | E24: =IF(D24<=$D$20,$D$21,IF(AND(D24>$D$20,D24<=$E$20),$E$21,IF(AND(D24>$E$20,D24<=$F$20),$F$21,IF(AND(D24>$F$20,D24<=$G$20),$G$21,IF(AND(D24>$G$20,D24<=$H$20),$H$21,$H$21))))) -> 0
B25: Masa final de la muestra (Lavada seca constante) | D25: =+DATOS!G26 -> 0 | E25: =IF(D25<=$D$20,$D$21,IF(AND(D25>$D$20,D25<=$E$20),$E$21,IF(AND(D25>$E$20,D25<=$F$20),$F$21,IF(AND(D25>$F$20,D25<=$G$20),$G$21,IF(AND(D25>$G$20,D25<=$H$20),$H$21,$H$21))))) -> 0

Sheet precision
A3: FACTOR PRECISION OPERADOR
A4: Fecha de evaluacion: | B4: 45790
A6: 1-Calcular la Incertidumbre estandar bajo condiciones de reproducibilidad
A7: Varianza Repetibilidad (Sr2 ) | B7: 0.0090531621
A8: Varianza entre Laboratorios (SL2) | B8: 0.0017951818

Sheet Hoja1
A2: CODIGO | C2: CONCATENADOS | D2: DESCRIPCION | E2: FC | F2: F. MOLDEO | G2: DIA | H2: DIAMETRO | I2: CARGA | J2: AREA | K2: RESIS. CONCRETO | L2: % RESIS | M2: TIPO DE FALLA
A3: 4400 | B3: =+A3+1 -> 4401 | C3: =A3&"-"&B3 -> 4400-4401 | D3: Columnas C-9;5-3/G.H | E3: 350 | F3: 42347 | G3: 7 | H3: 15.05 | I3: 49900 | J3: =H3*H3*PI()/4 -> 177.89465 | K3: =I3/J3 -> 280.5031 | L3: =+K3/E3 -> 0.80143743 | M3: E
C4: =A4&"-"&B4 -> - | E4: 350 | G4: 7 | H4: 15.06 | I4: 50310 | J4: =H4*H4*PI()/4 -> 178.13113 | K4: =I4/J4 -> 282.43238 | L4: =+K4/E4 -> 0.80694967 | M4: F
A5: =+B3+1 -> 4402 | B5: =+A5+1 -> 4403 | C5: =A5&"-"&B5 -> 4402-4403 | E5: 350 | G5: 14 | H5: 15.04 | I5: 56450 | J5: =H5*H5*PI()/4 -> 177.65832 | K5: =I5/J5 -> 317.74476 | L5: =+K5/E5 -> 0.90784216 | M5: F
C6: =A6&"-"&B6 -> - | E6: 350 | G6: 14 | H6: 15 | I6: 59630 | J6: =H6*H6*PI()/4 -> 176.71459 | K6: =I6/J6 -> 337.43677 | L6: =+K6/E6 -> 0.96410507 | M6: F
A7: =+B5+1 -> 4404 | B7: =+A7+1 -> 4405 | C7: =A7&"-"&B7 -> 4404-4405 | E7: 350 | G7: 28 | H7: 15.11 | I7: 65310 | J7: =H7*H7*PI()/4 -> 179.3159 | K7: =I7/J7 -> 364.21755 | L7: =+K7/E7 -> 1.0406216 | M7: F
C8: =A8&"-"&B8 -> - | E8: 350 | G8: 28 | H8: 15.05 | I8: 64730 | J8: =H8*H8*PI()/4 -> 177.89465 | K8: =I8/J8 -> 363.86705 | L8: =+K8/E8 -> 1.0396201 | M8: E
