Workbook

Sheet FORMATO
L2: CLIENTE
L3: DIRECCIÓN **
L4: PROYECTO **
L5: UBICACIÓN **
A7: LABORATORIO DE ENSAYO DE MATERIALES | L7: RECEPCIÓN N°
A8: FORMATO N° F-LEM-P-AG-36.01 | L8: F. EMISIÓN
L9: OT N°
C10: MUESTRA | E10: N° OT | F10: FECHA DE ENSAYO | G10: REALIZADO
L11: CÓDIGO DE LA MUESTRA
L12: FECHA DE RECEPCIÓN
A13: STANDARD TEST METHOD FOR RESISTANCE TO DEGRADATION OF SMALL-SIZE COARSE AGGREGATE BY ABRASION AND IMPACT IN THE LOS ANGELES MACHINE | L13: FECHA DE EJECUCIÓN
A14: ASTM C131/C131M-20
L15: CANTERA/SONDAJE **
A16: MUESTRA DE PRUEBA ANTES DEL FRACCIONAMIENTO | D16: UND | E16: DATO | G16: Se requiere lavado despues de la prueba (colocado en maquina angeles) | L16: N° MUESTRA **
A17: Masa muestra inicial | D17: g | G17: SI | H17: NO | L17: TIPO DE MUESTRA**
A18: Masa muestra inicial seca despues del lavado | D18: g
A19: Masa muestra inicial seca constante despues del lavado | D19: g | G19: N° revoluciones | H19: 500
A27: TAMIZ (in) | E27: GRADACIONES (Masa en cada tamiz, g)
A28: Pasante | C28: Retenido | E28: A | F28: B | G28: C | H28: D
A29: 1.5 | C29: 1 | F29: - | G29: - | H29: -
A30: 1 | C30: 0.75 | F30: - | G30: - | H30: -
A31: 0.75 | C31: 0.5 | G31: - | H31: -
A32: 0.5 | C32: 0.375 | G32: - | H32: -
A33: 0.375 | C33: 0.25 | E33: - | F33: -
A34: 0.25 | C34: No. 4 | E34: - | F34: - | H34: -
A35: No. 4 | C35: No. 8 | E35: - | F35: - | G35: -
A36: Total (*) | E36: =SUM(E29:E32) -> 0 | F36: =SUM(F31:F32) -> 0 | G36: =SUM(G33:G34) -> 0 | H36: =+H35 -> 0
A38: Item | B38: DESCRIPCIÓN | D38: UND | E38: Gradación A | F38: Gradación B | G38: Gradación C | H38: Gradación D
A39: 1 | B39: Numero de esferas | E39: 12 | F39: 11 | G39: 8 | H39: 6
A40: 2 | B40: Masa requerida de las esferas | D40: g | E40: 4975 - 5025 | F40: 4555 - 4605 | G40: 3310 - 3350 | H40: 2485 - 2515
A41: 3 | B41: Masa de esferas en conjunto | D41: g
A42: a | B42: Masa de la muestra de prueba original | D42: g | F42: 0 | G42: 0 | H42: 0
A43: b | B43: Masa final de la muestra de prueba | D43: g
A44: c | B44: Masa final de la muestra (Lavada seca) | D44: g
A45: d | B45: Masa final de la muestra (Lavada seca constante) | D45: g
A46: e | B46: Pérdida por abrasión ((a-d)/a *100) | D46: %
A47: f | B47: Perdida de masa por lavado ((b-d)/a)*100 (*) | D47: %
B48: (*) la perdida por lavado no superara en mas del 0.2% de la muestra original
B49: Codigo Equipo utilizado | C49: Horno | F49: Malla No. 12
C50: Máquina Los Angeles | F50: Malla No. 4
...

Sheet INFORME
A2: LABORATORIO DE ENSAYO DE MATERIALES
A3: 0
A5: CLIENTE | B5: : | C5: =+FORMATO!M2 -> 0 | H5: CÓDIGO | I5: : | J5: F-LEM-P-AG-36.02
A6: DIRECCION ** | B6: : | C6: =+FORMATO!M3 -> 0 | H6: RECEPCIÓN N° | I6: : | J6: =+FORMATO!M7 -> 0
A7: PROYECTO ** | B7: : | C7: =+FORMATO!M4 -> 0 | H7: OT N° | I7: : | J7: =+FORMATO!M9 -> 0
A8: UBICACIÓN ** | B8: : | C8: =+FORMATO!M5 -> 0 | H8: F. EMISIÓN | I8: : | J8: =+FORMATO!M8 -> 0
A9: ** Datos proporcionados por el cliente
A10: STANDARD TEST METHOD FOR RESISTANCE TO DEGRADATION OF SMALL-SIZE COARSE AGGREGATE BY ABRASION AND IMPACT IN THE LOS ANGELES MACHINE
A11: ASTM C131/C131M-20
A12: DATOS DE LA MUESTRA
A13: CANTERA/SONDAJE ** | D13: : | E13: =+FORMATO!M15 -> 0 | H13: CÓDIGO DE LA MUESTRA | I13: : | J13: =+FORMATO!C11 -> 0
A14: N° MUESTRA ** | D14: : | E14: =+FORMATO!M16 -> 0 | H14: FECHA DE RECEPCIÓN | I14: : | J14: =+FORMATO!M12 -> 0 | O14: -
A15: TIPO DE MUESTRA** | D15: : | E15: =+FORMATO!M17 -> 0 | H15: FECHA DE EJECUCIÓN | I15: : | J15: =+FORMATO!M13 -> 0 | O15: 1
A16: LUGAR DE ENSAYO | D16: : | E16: Laboratorio de ensayo de Materiales
O17: 3
E18: DESCRIPCIÓN | G18: UND | H18: DATOS
E19: Masa de la muestra de prueba original | G19: g | H19: =ROUND(DATOS!M30,0) -> #VALUE!
E20: Masa final de la muestra de prueba | G20: g | H20: =+DATOS!M33
E21: Pérdida por abrasión | G21: % | H21: =+DATOS!M34
A24: Descripción de la muestra:
A25: Tamaño máximo nominal (in) | G25: =+DATOS!H16 -> 0
A26: Gradación de la muestra de prueba | G26: =+DATOS!H12 -> -
A28: Nota:
A29: - El cliente es responsable de los datos de identificación de los puntos de ensayo brindados.
A30: - Los resultados expresados se refieren únicamente al ensayo realizado en dicho momento y en las condiciones especificadas en este documento, por lo que GEOFAL S.A.C. no será responsable por los ensayos realizados con la presente muestra en condiciones distintas a las aquí señaladas.
A31: - GEOFAL S.A.C. no se hace responsable por el uso incorrecto o inadecuado del presente informe.
A32: - Los resultados de los ensayos realizados no deben ser utilizados como una certificación de conformidad con normas de producto o como certificado del sistema de calidad de la entidad que lo produce.
A33: - De conformidad con lo dispuesto por el artículo 1321 del Código Civil, queda establecido que en ningún caso la responsabilidad de GEOFAL S.A.C. será mayor al valor del servicio prestado.
A35: Observaciones:
A43: Página 1 de 1
A44: Versión: 02 (2026-06-15) | J44: Fin del Informe

Sheet DATOS
A2: STANDARD TEST METHOD FOR RESISTANCE TO DEGRADATION OF SMALL-SIZE COARSE AGGREGATE BY ABRASION AND IMPACT IN THE LOS ANGELES MACHINE
A3: ASTM C131/C131M-20
A5: Informacion para la Correccion por Certificado de Calibración: balanza 30kg
A6: Precision Balanza al | C6: =+balanza!C10 -> 1 | D6: g
A7: Correccion | C7: =+balanza!C7 -> -1.49e-06
A8: Codigo balanza | C8: =+balanza!C11 -> EQP-0054
A9: Fecha de calibración | C9: =+balanza!D12 -> 46160
H11: DEL ENSAYO | I11: NORMA | M11: CLASIFICACION DE LA MUESTRA DE PRUEBA
B12: DESCRIPCIÓN | D12: UND | E12: DATOS | G12: gradación | H12: - | I12: -
B13: Masa muestra inicial | D13: g | E13: =+FORMATO!E17 -> 0 | G13: Numero esfera | I13: =+IF(H13=P34,"Cumple","No Cumple") -> #N/A
B14: Masa muestra inicial seca | D14: g | E14: =+FORMATO!E18 -> 0 | G14: Masa esfera | H14: =+FORMATO!E41 -> 0 | I14: =IF(AND(O34=H12,H14>Q34,H14<R34),"Cumple","No Cumple") -> #N/A
B15: Masa muestra inicial seca constante | D15: g | E15: =+FORMATO!E19 -> 0 | G15: OPERADORES | I15: =+FORMATO!G11 -> 0
B16: Verificacion de Masa seca constante | E16: =(E14-E15)/E15*100 -> #DIV/0! | F16: =IF(E16<0.1,"cumple","no cumple") -> #DIV/0! | G16: TMN
B18: TAMIZ (in) | E18: GRADACIONES (Masa en cada tamiz, g) | M18: cumplimiento masa minima
B19: Pasante | C19: Retenido | E19: A | F19: Corrección (A) | G19: B | H19: Corrección (B) | I19: C | J19: Corrección (C) | K19: D | L19: Corrección (D) | M19: Gradación (A) | N19: Gradación (B) | O19: Gradación (C) | P19: Gradación (D)
B20: 1.5 | C20: 1 | E20: =+FORMATO!E29 -> 0 | F20: =+E20+$C$7*E20 -> 0 | G20: - | H20: - | I20: - | J20: - | K20: - | L20: - | M20: =IF(E20="","",IF(AND(E20<=1275,E20>=1225),"cumple","no cumple")) -> no cumple
B21: 1 | C21: 0.75 | E21: =+FORMATO!E30 -> 0 | F21: =+E21+$C$7*E21 -> 0 | G21: - | H21: - | I21: - | J21: - | K21: - | L21: - | M21: =IF(E21="","",IF(AND(E21<=1275,E21>=1225),"cumple","no cumple")) -> no cumple
B22: 0.75 | C22: 0.5 | E22: =+FORMATO!E31 -> 0 | F22: =+E22+$C$7*E22 -> 0 | G22: =+FORMATO!F31 -> 0 | H22: =+G22+$C$7*G22 -> 0 | I22: - | J22: - | K22: - | L22: - | M22: =IF(E22="","",IF(AND(E22<=1260,E22>=1240),"cumple","no cumple")) -> no cumple | N22: =IF(G22="","",IF(AND(G22<=2510,G22>=2490),"cumple","no cumple")) -> no cumple
B23: 0.5 | C23: 0.375 | E23: =+FORMATO!E32 -> 0 | F23: =+E23+$C$7*E23 -> 0 | G23: =+FORMATO!F32 -> 0 | H23: =+G23+$C$7*G23 -> 0 | I23: - | J23: - | K23: - | L23: - | M23: =IF(E23="","",IF(AND(E23<=1260,E23>=1240),"cumple","no cumple")) -> no cumple | N23: =IF(G23="","",IF(AND(G23<=2510,G23>=2490),"cumple","no cumple")) -> no cumple
B24: 0.375 | C24: 0.25 | E24: - | F24: - | G24: - | H24: - | I24: =+FORMATO!G33 -> 0 | J24: =+I24+$C$7*I24 -> 0 | K24: - | L24: - | O24: =IF(I24="","",IF(AND(I24<=2510,I24>=2490),"cumple","no cumple")) -> no cumple
B25: 0.25 | C25: No 4 | E25: - | F25: - | G25: - | H25: - | I25: =+FORMATO!G34 -> 0 | J25: =+I25+$C$7*I25 -> 0 | K25: - | L25: - | O25: =IF(I25="","",IF(AND(I25<=2510,I25>=2490),"cumple","no cumple")) -> no cumple
B26: No 4 | C26: No 8 | E26: - | F26: - | G26: - | H26: - | I26: - | J26: - | K26: =+FORMATO!H35 -> 0 | L26: =+K26+$C$7*K26 -> 0 | P26: =IF(K26="","",IF(AND(K26<=5010,K26>=4990),"cumple","no cumple")) -> no cumple
B27: TOTAL | E27: =SUM(E20:E23) -> 0 | F27: =IF(E20="","",SUM(F20:F23)) -> 0 | G27: =SUM(G22:G23) -> 0 | H27: =IF(G22="","",SUM(H22:H23)) -> 0 | I27: =SUM(I23:I26) -> 0 | J27: =IF(I24="","",SUM(J24:J25)) -> 0 | K27: =SUM(K23:K26) -> 0 | L27: =IF(K26="","",SUM(L26)) -> 0 | M27: =IF(E27="","",IF(AND(E27<=5010,E27>=4990),"cumple","no cumple")) -> no cumple | N27: =IF(G27="","",IF(AND(G27<=5010,G27>=4990),"cumple","no cumple")) -> no cumple | O27: =IF(I27="","",IF(AND(I27<=5010,I27>=4990),"cumple","no cumple")) -> no cumple | P27: =IF(K27="","",IF(AND(K27<=5010,K27>=4990),"cumple","no cumple")) -> no cumple
A29: ITEM | B29: DESCRIPCIÓN | D29: UND | E29: Gradación (A) | F29: CORRECCIÓN (A) | G29: Gradación (B) | H29: CORRECCIÓN (B) | I29: Gradación (C) | J29: CORRECCIÓN (C) | K29: Gradación (D) | L29: CORRECCIÓN (D) | O29: GRADACION | P29: N° ESFERA | Q29: MASA MIN | R29: MASA MAX
A30: a | B30: Masa de la muestra de prueba original | D30: g | F30: =+F27 -> 0 | H30: =+H27 -> 0 | J30: =+J27 -> 0 | L30: =+L27 -> 0 | M30: =IF(H12="A",F30,IF(H12="B",H30,IF(H12="C",J30,IF(H12="D",L30,"")))) | O30: A | P30: 12 | Q30: 4975 | R30: 5025
A31: b | B31: Masa final de la muestra de prueba | D31: g | E31: =+FORMATO!E43 -> 0 | G31: =+FORMATO!F43 -> 0 | I31: =+FORMATO!G43 -> 0 | K31: =+FORMATO!H43 -> 0 | O31: B | P31: 11 | Q31: 4555 | R31: 4605
A32: c | B32: Masa final de la muestra (Lavada seca) | D32: g | E32: =+FORMATO!E44 -> 0 | G32: =+FORMATO!F44 -> 0 | I32: =+FORMATO!G44 -> 0 | K32: =+FORMATO!H44 -> 0 | O32: C | P32: 8 | Q32: 3310 | R32: 3350
A33: d | B33: Masa final de la muestra (Lavada seca constante) | D33: g | E33: =+FORMATO!E45 -> 0 | F33: =E33+$C$7*E33 -> 0 | G33: =+FORMATO!F45 -> 0 | H33: =G33+$C$7*G33 -> 0 | I33: =+FORMATO!G45 -> 0 | J33: =I33+$C$7*I33 -> 0 | K33: =+FORMATO!H45 -> 0 | L33: =K33+$C$7*K33 -> 0 | M33: =IF(H12="A",F33,IF(H12="B",H33,IF(H12="C",J33,IF(H12="D",L33,"")))) | O33: D | P33: 6 | Q33: 2485 | R33: 2515
A34: e | B34: Pérdida por abrasión (f/b *100) | D34: % | F34: =IF(F33=0,"---",((F30-F33)/F30)*100) -> --- | H34: =IF(H33=0,"---",((H30-H33)/H30)*100) -> --- | J34: =IF(J33=0,"---",((J30-J33)/J30)*100) -> --- | L34: =IF(L33=0,"---",((L30-L33)/L30)*100) -> --- | M34: =IF(H12="A",F34,IF(H12="B",H34,IF(H12="C",J34,IF(H12="D",L34,"")))) | O34: =+H12 -> - | P34: =LOOKUP(O34,O30:O33,P30:P33) -> #N/A | Q34: =LOOKUP(O34,O30:O33,Q30:Q33) -> #N/A | R34: =LOOKUP(O34,O30:O33,R30:R33) -> #N/A
B35: Verificacion de Masa seca constante | E35: =IF(E27=0,"",(E32-E33)/E33*100) | F35: =IF(E35="","",IF(E35<0.1,"Cumple","No Cumple")) | G35: =IF(G27=0,"",(G32-G33)/G33*100) | H35: =IF(G35="","",IF(G35<0.1,"cumple","no cumple")) | I35: =IF(I27=0,"",(I32-I33)/I33*100) | J35: =IF(I35="","",IF(I35<0.1,"cumple","no cumple")) | K35: =IF(K27=0,"",(K32-K33)/K33*100) | L35: =IF(K35="","",IF(K35<0.1,"cumple","no cumple"))
B36: Perdida de masa por lavado ((b-d)/a)*100 (*) | D36: % | E36: =IF(E27=0,"",((E31-E33)/E27)*100) | F36: =IF(E36="","",IF(E36<=0.2,"Cumple","No Cumple")) | G36: =IF(G27=0,"",((G31-G33)/G27)*100) | H36: =IF(G36="","",IF(G36<=0.2,"Cumple","No Cumple")) | I36: =IF(I27=0,"",((I31-I33)/I27)*100) | J36: =IF(I36="","",IF(I36<=0.2,"Cumple","No Cumple")) | K36: =IF(K27=0,"",((K31-K33)/K27)*100) | L36: =IF(K36="","",IF(K36<=0.2,"Cumple","No Cumple"))

Sheet incertidumbre
C1: INFORME DE ESTIMACIÓN DE INCERTIDUMBRE | I1: Código: | J1: F-LEM-P-10.01
I2: Versión: | J2: 3
I3: Fecha: | J3: 46146
I4: Página: | J4: 1 de 1
A6: Método: | B6: STANDARD TEST METHOD FOR RESISTANCE TO DEGRADATION OF SMALL-SIZE COARSE AGGREGATE BY ABRASION AND IMPACT IN THE LOS ANGELES MACHINE1
A7: Norma: | B7: ASTM C131/C131M-20
A8: Matriz: | B8: Agregados
A9: Mensurando: | B9: Resistencia a la degradación
A11: Paso 1. Definición del proceso de medición
A13: Variables: | D13: Fórmula: | F13: Paso 2. Definición de las variables aleatorias
A16: PA = Perdida abrasión
A17: C= Masa de la muestra de prueba
A18: Y= Masa final de la muestra
A20: Equipos a utilizar:
A22: Balanza con resolución de lectura de 1g
A24: CALCULO: RESISTENCIA A LA DEGRADACION AGREGADOS
A25: Fuentes | B25: Unidades | C25: Valor | D25: Incertidumbre Original | E25: Distribución | F25: Incertidumbre Estándar u(xi) | G25: Coeficiente de Sensibilidad | H25: Contribución ui(y)
A26: Pérdida por abrasión (%) | C26: =+(C27-C31)/C27*100 -> #VALUE! | D26: --- | E26: --- | F26: --- | G26: --- | H26: ---
A27: Masa de la muestra de prueba | B27: g | C27: =+DATOS!M30 | D27: --- | E27: --- | F27: =SQRT((F28*F28)+(F29*F29)+(F30*F30)) -> #VALUE! | G27: =100*C31/C27/C27 -> #VALUE! | H27: =+G27*F27 -> #VALUE! | I27: C
A28: Repetibilidad de la pesada | B28: g | D28: =+balanza!E24 -> 0 | E28: Normal, K=1 | F28: =+D28 -> 0 | G28: --- | H28: ---
A29: Certificado de Calibración | B29: g | D29: =2*(SQRT(balanza!$C$8+balanza!$D$8*(POWER(C27,2)))) -> #VALUE! | E29: Normal, K=2 | F29: =+D29/2 -> #VALUE! | G29: --- | H29: ---
A30: Resolución | B30: g | D30: =+balanza!C10 -> 1 | E30: Rectangular | F30: =+D30/SQRT(3)/2 -> 0.28867513 | G30: --- | H30: ---
A31: Masa final de la muestra | B31: g | C31: =+DATOS!M33 | E31: --- | F31: =SQRT((F32*F32)+(F33*F33)+(F34*F34)) -> #VALUE! | G31: =100/C27 -> #VALUE! | H31: =+G31*F31 -> #VALUE! | I31: Y
A32: Repetibilidad de la pesada | B32: g | D32: =+balanza!E25 -> 0 | E32: Normal, K=1 | F32: =+D32 -> 0 | G32: --- | H32: ---
A33: Certificado de Calibración | B33: g | D33: =2*(SQRT(balanza!$C$8+balanza!$D$8*(POWER(C31,2)))) -> #VALUE! | E33: Normal, K=2 | F33: =+D33/2 -> #VALUE! | G33: --- | H33: ---
A34: Resolución | B34: g | D34: =+balanza!C10 -> 1 | E34: Rectangular | F34: =+D34/SQRT(3)/2 -> 0.28867513 | G34: --- | H34: ---
A35: factor de presición | B35: % | C35: =+precision!B7 -> 0.0096689695 | E35: Norma, K=1 | F35: =C35/SQRT(1) -> 0.0096689695 | G35: 1 | H35: =+F35*G35 -> 0.0096689695
A36: Incertidumbre Estándar Combinada | G36: % | H36: =SQRT((H27*H27)+(H31*H31)+(H35*H35)) -> #VALUE!
A37: Incertidumbre Expandida, K = 2 | G37: % | H37: =+H36*2 -> #VALUE!
A39: CONTRIBUCIÓN
A40: Factor de influencia | C40: valor | D40: %
B41: =+A27 -> Masa de la muestra de prueba | C41: =+H27 -> #VALUE! | D41: =+C41/$C$44 -> #VALUE!
B42: =+A31 -> Masa final de la muestra | C42: =+H31 -> #VALUE! | D42: =+C42/$C$44 -> #VALUE!
B43: =+A35 -> factor de presición | C43: =+H35 -> 0.0096689695 | D43: =+C43/$C$44 -> #VALUE!
C44: =SUM(C41:C43) -> #VALUE! | D44: =SUM(D41:D43) -> #VALUE!
A47: REVISADO POR: | B47: FABIAN LA ROSA | E47: APROBADO POR: | G47: IRMA COAQUIRA
A49: FECHA DE REVISIÓN: | B49: 45414 | E49: FECHA DE APROBACIÓN: | G49: 45414

Sheet balanza
B2: CALIBRACION DE LA BALANZA
B7: Correccion | C7: -1.49e-06
B8: Variables | C8: 1.14 | D8: 2.48e-10
B9: Ecuacion | C9: 2*RAIZ(1.14+0.000000000248*R2) | F9: g
B10: Resolucion | C10: 1 | D10: g
B11: Codigo | C11: EQP-0054
B12: Fecha de calibración | D12: 46160
B13: ITEM | C13: MES | D13: 500 | E13: 1000 | F13: 5000 | G13: 10000 | H13: 15000 | I13: 20000
C17: DESV STD | D17: 0 | E17: 0 | F17: 0 | G17: 0 | H17: 0 | I17: 0
B19: Busqueda de Repetibilidad de la masa
D20: =+D13 -> 500 | E20: =+E13 -> 1000 | F20: =+F13 -> 5000 | G20: =+G13 -> 10000 | H20: =+H13 -> 15000 | I20: 20000
D21: =D17 -> 0 | E21: =E17 -> 0 | F21: =F17 -> 0 | G21: =G17 -> 0 | H21: =H17 -> 0 | I21: =I17 -> 0
B23: ENSAYO DE LA MUESTRA
B24: Masa de la muestra de prueba | D24: =+DATOS!$M$30 | E24: =IF(D24<=$D$20,$D$21,IF(AND(D24>$D$20,D24<=$E$20),$E$21,IF(AND(D24>$E$20,D24<=$F$20),$F$21,IF(AND(D24>$F$20,D24<=$G$20),$G$21,IF(AND(D24>$G$20,D24<=$H$20),$H$21,$H$21))))) -> 0
B25: Masa final de la muestra (Lavada seca constante) | D25: =+DATOS!$M$33 | E25: =IF(D25<=$D$20,$D$21,IF(AND(D25>$D$20,D25<=$E$20),$E$21,IF(AND(D25>$E$20,D25<=$F$20),$F$21,IF(AND(D25>$F$20,D25<=$G$20),$G$21,IF(AND(D25>$G$20,D25<=$H$20),$H$21,$H$21))))) -> 0

Sheet precision
A3: FACTOR DE PRECISION OPERADOR
A4: Fecha de evaluacion: | B4: 45790
A6: 1-Calcular la Incertidumbre estandar
A7: Varianza Repetibilidad (Sr2 ) | B7: 0.0096689695
A8: Varianza entre Laboratorios (SL2) | B8: 0.00013692886

Sheet Hoja1
A2: CODIGO | C2: CONCATENADOS | D2: DESCRIPCION | E2: FC | F2: F. MOLDEO | G2: DIA | H2: DIAMETRO | I2: CARGA | J2: AREA | K2: RESIS. CONCRETO | L2: % RESIS | M2: TIPO DE FALLA
A3: 4400 | B3: =+A3+1 -> 4401 | C3: =A3&"-"&B3 -> 4400-4401 | D3: Columnas C-9;5-3/G.H | E3: 350 | F3: 42347 | G3: 7 | H3: 15.05 | I3: 49900 | J3: =H3*H3*PI()/4 -> 177.89465 | K3: =I3/J3 -> 280.5031 | L3: =+K3/E3 -> 0.80143743 | M3: E
C4: =A4&"-"&B4 -> - | E4: 350 | G4: 7 | H4: 15.06 | I4: 50310 | J4: =H4*H4*PI()/4 -> 178.13113 | K4: =I4/J4 -> 282.43238 | L4: =+K4/E4 -> 0.80694967 | M4: F
A5: =+B3+1 -> 4402 | B5: =+A5+1 -> 4403 | C5: =A5&"-"&B5 -> 4402-4403 | E5: 350 | G5: 14 | H5: 15.04 | I5: 56450 | J5: =H5*H5*PI()/4 -> 177.65832 | K5: =I5/J5 -> 317.74476 | L5: =+K5/E5 -> 0.90784216 | M5: F
C6: =A6&"-"&B6 -> - | E6: 350 | G6: 14 | H6: 15 | I6: 59630 | J6: =H6*H6*PI()/4 -> 176.71459 | K6: =I6/J6 -> 337.43677 | L6: =+K6/E6 -> 0.96410507 | M6: F
A7: =+B5+1 -> 4404 | B7: =+A7+1 -> 4405 | C7: =A7&"-"&B7 -> 4404-4405 | E7: 350 | G7: 28 | H7: 15.11 | I7: 65310 | J7: =H7*H7*PI()/4 -> 179.3159 | K7: =I7/J7 -> 364.21755 | L7: =+K7/E7 -> 1.0406216 | M7: F
C8: =A8&"-"&B8 -> - | E8: 350 | G8: 28 | H8: 15.05 | I8: 64730 | J8: =H8*H8*PI()/4 -> 177.89465 | K8: =I8/J8 -> 363.86705 | L8: =+K8/E8 -> 1.0396201 | M8: E
