Workbook
Name ___CC2: [1]Sucs!$L$6
Name __CC2: [1]Sucs!$L$6
Name _CC1: [2]Sucs!$L$6
Name _CC2: [1]Sucs!$L$6
Name _CU1: [2]Sucs!$L$5
Name _IP1: [2]Sucs!$L$4
Name _L1: #REF!
Name _L1: #REF!
Name _L1: #REF!
Name _Ll1: [2]Sucs!$L$3
Name _W1: #REF!
Name _W1: #REF!
Name _W1: #REF!
Name Abra: [3]Sucs!$C$3
Name CC: #REF!
Name CC: #REF!
Name CC: #REF!
Name CCf: '[2]Sucs(Fino)'!$L$6
Name CCVB: [4]Sucs!$L$3
Name CM: [5]BGA!$H$9
Name CU: #REF!
Name CU: #REF!
Name CU: #REF!
Name CUf: '[2]Sucs(Fino)'!$L$5
Name hh: #REF!
Name hh: #REF!
Name hh: #REF!
Name IP: #REF!
Name IP: #REF!
Name IP: #REF!
Name IPf: '[2]Sucs(Fino)'!$L$4
Name L: #REF!
Name L: #REF!
Name L: #REF!
Name LIf: '[2]Sucs(Fino)'!$L$3
Name Ll: #REF!
Name Ll: #REF!
Name Ll: #REF!
Name MORA: [5]BGA!$H$13
Name N_10: #REF!
Name N_10: #REF!
Name N_10: #REF!
Name N_101: [2]Sucs!$C$5
Name N_10f: '[2]Sucs(Fino)'!$C$5
Name N_200: #REF!
Name N_200: #REF!
Name N_200: #REF!
Name N_2001: [2]Sucs!$C$3
Name N_200f: '[2]Sucs(Fino)'!$C$3
Name N_40: #REF!
Name N_40: #REF!
Name N_40: #REF!
Name N_401: [2]Sucs!$C$4
Name N_40f: '[2]Sucs(Fino)'!$C$4
Name PC: [4]Sucs!$C$5
Name TABLA: #REF!
Name TABLA: #REF!
Name TABLA: #REF!
Name tipodegranulometria: '[6]G-LL '!$X$2:$X$3
Name tipodegranulometria: '[6]G-LL '!$X$2:$X$3

Sheet FORMATO PEG
T2: CLIENTE
T3: DIRECCIÓN **
Q4: TMN | R4: MASA MINIMA | T4: PROYECTO **
Q5: (in.) | R5: (kg) | T5: UBICACIÓN **
Q6: 4 in | R6: 40
A7: LABORATORIO DE ENSAYO DE MATERIALES | Q7: 3 1/2 in | R7: 25 | T7: RECEPCIÓN N°
A8: FORMATO N° F-LEM-P-AG-28.01 | Q8: 3in | R8: 18 | T8: F. EMISIÓN
Q9: 2.5 | R9: 12 | T9: OT N°
E10: MUESTRA | F10: N° OT | H10: FECHA | I10: Realizado | Q10: 2 in | R10: 8
Q11: 1 1/2 in | R11: 5 | T11: CÓDIGO DE LA MUESTRA
Q12: 1in | R12: 4 | T12: FECHA DE RECEPCIÓN
A13: Standard Test Method for Relative Density (Specific Gravity) and Absorption of Coarse Aggregate | Q13: 3/4 in | R13: 3 | T13: FECHA DE EJECUCIÓN
A14: ASTM C127-25 | Q14: 1/2 in | R14: 2
Q15: N°4 | R15: 2 | T15: CANTERA/SONDAJE **
B16: Descripción de la muestra | H16: Equipo utilizado | K16: Código | Q16: Fuente: Norma ASTM C127-24 | T16: N° MUESTRA **
B17: - Tamaño máximo nominal | H17: Balanza 1 g | T17: TIPO DE MUESTRA**
B18: - Agregado Grupo II(Ligero) (*) | E18: SI [ ] NO [ ] | H18: Horno 110 ºC
B19: - Retenido en la malla No 4 (1) | E19: SI [ ] NO [ ] | H19: Termómetro 0.1°C
B20: - Retenido en la malla 1 1 /2 in (2) | E20: SI [ ] NO [ ] | H20: Canastilla
B22: - Fecha/ hora de inmersión Inicial | H22: Tamiz
B23: - Fecha/ hora de inmersión Final | H23: Equipo Gravedad Especifica
B24: (*) Ejm. Pómez(72h ±4h) - P. Inmersión; (1) Uso de malla No. 4 en el ensayo; (2) Realizar Fraccionamiento >15%.
B26: Condiciones del ensayo | K26: Masa retenido de malla 1 1/2 in Porcentaje (%)
B27: - La muestra se secó en horno a masa constante a 110 ± 5°C, antes de saturar | K27: Masa de la muestra inicial total
B28: - La muestra fue ensayada en fracciones | K28: Masa de la fraccion N°01
B29: - Malla de fracción | K29: Masa de la fraccion N°02
B31: REPORTE DE DATOS DE ENSAYO
B33: Descripción | L33: Und | M33: Datos
B34: A | C34: Masa de la muestra secada al horno | L34: g
B35: B | C35: Masa de la muestra secada al horno constante | L35: g
B36: C | C36: Masa de la muestra de ensayo de superficie seca saturada | L36: g
B37: D | C37: Masa aparente de la muestra de prueba sumergida en agua | L37: g
M38: Masa total =
B39: 2° Fracción
B40: Descripción | L40: Und | M40: Datos
B41: A | C41: Masa de la muestra secada al horno | L41: g
B42: B | C42: Masa de la muestra secada al horno constante | L42: g
B43: C | C43: Masa de la muestra de ensayo de superficie seca saturada | L43: g
B44: D | C44: Masa aparente de la muestra de prueba sumergida en agua | L44: g
M45: Masa total =
...

Sheet INFORME
A2: LABORATORIO DE ENSAYO DE MATERIALES
A3: 0
A5: CLIENTE | B5: : | C5: =+'FORMATO PEG'!U2 -> 0 | J5: CÓDIGO | K5: : | L5: F-LEM-P-AG-28.02
A6: DIRECCIÓN ** | B6: : | C6: =+'FORMATO PEG'!U3 -> 0 | J6: RECEPCIÓN N° | K6: : | L6: =+'FORMATO PEG'!U7 -> 0
A7: PROYECTO ** | B7: : | C7: =+'FORMATO PEG'!U4 -> 0 | J7: OT N° | K7: : | L7: =+'FORMATO PEG'!U9 -> 0
A8: UBICACIÓN ** | B8: : | C8: =+'FORMATO PEG'!U5 -> 0 | J8: FECHA EMISIÓN: | K8: : | L8: =+'FORMATO PEG'!U8 -> 0
A9: ** Datos proporcionados por el cliente
A11: Standard Test Method for Relative Density (Specific Gravity) and Absorption of Coarse Aggregate1
A12: ASTM C127-25
A14: DATOS DE LA MUESTRA
A15: CANTERA/SONDAJE ** | D15: : | E15: =+'FORMATO PEG'!U15 -> 0 | J15: CÓDIGO DE LA MUESTRA | K15: : | L15: =+'FORMATO PEG'!U11 -> 0
A16: N° MUESTRA ** | D16: : | E16: =+'FORMATO PEG'!U16 -> 0 | J16: FECHA DE RECEPCIÓN | K16: : | L16: =+'FORMATO PEG'!U12 -> 0
A17: TIPO DE MUESTRA ** | D17: : | E17: =+'FORMATO PEG'!U17 -> 0 | J17: FECHA DE EJECUCIÓN | K17: : | L17: =+'FORMATO PEG'!U13 -> 0 | M17: =+'FORMATO PEG'!H11 -> 0
A18: LUGAR DE ENSAYO | D18: : | E18: LABORATORIO DE ENSAYO MATERIALES
B21: Densidades (gravedad especifica) | I21: Und. | J21: Datos
B22: Densidad relativa (gravedad especifica) (OD) | I22: - | J22: =DATOS!I25 -> FALSE
B23: Densidad relativa (gravedad especifica) (SSD) | I23: - | J23: =DATOS!I26 -> FALSE
B24: Densidad relativa aparente (gravedad especifica) | I24: - | J24: =DATOS!I27 -> FALSE
B25: Absorción | I25: % | J25: =DATOS!I28 -> FALSE
A29: Condiciones del ensayo
A30: La muestra se secó en horno a masa constante a 110 ± 5°C, antes de saturar. | J30: {=+'FORMATO PEG'!H27:I27} -> 0 | K30: 0
A31: Tamaño máximo nominal | J31: =+DATOS!E7 -> -
A32: La muestra fue ensayada en fracciones | J32: {=+'FORMATO PEG'!H28:I28} -> 0 | K32: 0
A34: Nota:
A35: - Los datos de identificación de la muestra son proporcionados por el cliente.
A36: - Los resultados corresponden sólo a los ensayos realizados sobre la muestra proporcionada por el cliente.
A37: - Los resultados de los ensayos no deben ser utilizados como una certificación de conformidad con normas de productos o como certificado del sistema de calidad de Geofal SAC.
A38: - Prohibida la reproducción total o parcial del presente informe de ensayo sin la autorización escrita de Geofal S.A.C.
A39: - Este informe de ensayo, al estar en el marco de la acreditación del INACAL - DA, se encuentra dentro del ámbito de reconocimiento multilateral/mutuo de los miembros firmantes de IAAC e ILAC.
A41: Observaciones:
A46: Página 1 de 1
A47: Versión: 03 (2026-01-20) | L47: Fin del Informe

Sheet DATOS
A1: Densidad relativa (peso específico) y absorción del agregado grueso ASTM C127-25
A2: Información para la Corrección por Certificado de Calibración:
A3: Precisión de la Balanza al 0.1g
A4: Corrección | C4: =+Balanza!C7 -> -4.63e-06 | H4: Fecha | J4: =+Balanza!D12 -> 46132
A5: CODIGO | C5: =+Balanza!C11 -> EQP-0050
B7: Tamaño máximo nominal TMN: | E7: - | H7: Numero de fracciones | K7: -
B9: Cantidad mínima: | D9: =+INDEX(P13:Q23,MATCH(E7,P13:P23,0),2) -> #N/A | F9: =+IF(I13/1000>D9,"Cumple","No Cumple") -> #N/A | J9: Técnico | K9: -
A11: Descripción | H11: und | I11: FRACCIÓN 1 | K11: FRACCIÓN 2 | M11: FRACCIÓN 3 | P11: TMN | Q11: MASA MINIMA
I12: datos 1 | J12: datos 1 corrección | K12: datos 2 | L12: datos 2 corrección | M12: datos 3 | N12: datos 3 corrección | P12: (in.) | Q12: (kg)
B13: MUESTRA INICIAL TOTAL | I13: =+'FORMATO PEG'!O27 -> 0 | P13: 4 in | Q13: 40
B14: MASA DE FRACCIÓNES | H14: g | I14: =+'FORMATO PEG'!O28 -> 0 | J14: =I14+($C$4*I14) -> 0 | K14: =+'FORMATO PEG'!O29 -> 0 | L14: =IF($K$7=1,"",K14+($C$4*K14)) -> 0 | N14: =IF($K$7=3,M14+($C$4*M14),"") | P14: 3 1/2 in | Q14: 25
B15: Porcentaje de las fracciones | D15: Confirmación | F15: =+SUM(J15,L15,N15) -> #DIV/0! | H15: % | J15: =+(J14/$I$13)*100 -> #DIV/0! | L15: =+IF($K$7=1,"",(L14/$I$13)*100) -> #DIV/0! | N15: =IF($K$7=3,(N14/$I$13)*100,"") | P15: 3in | Q15: 18
A16: A | B16: Masa de la muestra secada al horno | H16: g | I16: =+'FORMATO PEG'!M34 -> 0 | J16: =I16+($C$4*I16) -> 0 | L16: =IF($K$7=1,"",K16+($C$4*K16)) -> 0 | N16: =IF($K$7=3,M16+($C$4*M16),"") | P16: 2.5 | Q16: 12
A17: B | B17: Masa de la muestra secada al horno constante | H17: g | I17: =+'FORMATO PEG'!M35 -> 0 | J17: =I17+($C$4*I17) -> 0 | L17: =IF($K$7=1,"",K17+($C$4*K17)) -> 0 | N17: =IF($K$7=3,M17+($C$4*M17),"") | P17: 2 in | Q17: 8
A18: C | B18: Masa de la muestra de ensayo de superficie seca saturada en el aire | H18: g | I18: =+'FORMATO PEG'!M36 -> 0 | J18: =I18+($C$4*I18) -> 0 | L18: =IF($K$7=1,"",K18+($C$4*K18)) -> 0 | N18: =IF($K$7=3,M18+($C$4*M18),"") | P18: 1 1/2 in | Q18: 5
A19: D | B19: Masa aparente de la muestra de prueba sumergida en agua | H19: g | I19: =+'FORMATO PEG'!O38 -> 0 | J19: =I19+($C$4*I19) -> 0 | L19: =IF($K$7=1,"",K19+($C$4*K19)) -> 0 | N19: =IF($K$7=3,M19+($C$4*M19),"") | P19: 1in | Q19: 4
A20: E | B20: Densidad relativa (gravedad especifica) (OD) = B/(C-D) | J20: =J17/(J18-J19) -> #DIV/0! | L20: =IF(L19="","",L17/(L18-L19)) -> #DIV/0! | N20: =IF(N19="","",N17/(N18-N19)) | P20: 3/4 in | Q20: 3
A21: F | B21: Densidad relativa (gravedad especifica) (SSD) = C/(C-D) | J21: =J18/(J18-J19) -> #DIV/0! | L21: =IF(L19="","",L18/(L18-L19)) -> #DIV/0! | N21: =IF(N19="","",N18/(N18-N19)) | P21: 1/2 in | Q21: 2
A22: G | B22: Densidad relativa aparente (gravedad especifica) = B/(B-D) | J22: =J17/(J17-J19) -> #DIV/0! | L22: =IF(L19="","",L17/(L17-L19)) -> #DIV/0! | N22: =IF(N19="","",N17/(N17-N19)) | P22: 3/8 in | Q22: 2
A23: H | B23: Absorción = 100((C-B)/B) | H23: % | J23: =(J18-J17)/J17*100 -> #DIV/0! | L23: =IF(L19="","",(L18-L17)/L17*100) -> #DIV/0! | N23: =IF(N19="","",(N18-N17)/N17*100) | P23: N°4 | Q23: 2
P24: N°8
B25: Densidad relativa (gravedad especifica) (OD) PROMEDIO | I25: =IF(K7=1,J20,IF(K7=2,1/(($J$15/100)/J20+($L$15/100)/L20),IF(K7=3,1/(($J$15/100)/J20+($L$15/100)/L20+(N15/100)/N20)))) -> FALSE | P25: - | Q25: =+(I14-I16)/I16*100 -> #DIV/0!
B26: Densidad relativa (gravedad especifica) (SSD) PROMEDIO | I26: =IF(K7=1,J21,IF(K7=2,1/(($J$15/100)/J21+($L$15/100)/L21),IF(K7=3,1/(($J$15/100)/J21+($L$15/100)/L21+(N15/100)/N21)))) -> FALSE
B27: Densidad relativa aparente (gravedad especifica) PROMEDIO | I27: =IF(K7=1,J22,IF(K7=2,1/(($J$15/100)/J22+($L$15/100)/L22),IF(K7=3,1/(($J$15/100)/J22+($L$15/100)/L22+(N15/100)/N22)))) -> FALSE
B28: Absorción (%) PROMEDIO | H28: % | I28: =IF(K7=1,J23,IF(K7=2,1/(($J$15/100)/J23+($L$15/100)/L23),IF(K7=3,1/(($J$15/100)/J23+($L$15/100)/L23+(N15/100)/N23)))) -> FALSE

Sheet Incertidumbre
B1: INFORME DE ESTIMACIÓN DE INCERTIDUMBRE | I1: Código: | J1: F-LEM-P-10.01
I2: Versión: | J2: 2
I3: Fecha: | J3: 44697
I4: Página: | J4: 1 de 1
A6: Método: | B6: =+DATOS!A1 -> Densidad relativa (peso específico) y absorción del agregado grueso ASTM C127-25
A7: Norma: | B7: ASTM C127-24
A8: Revisado por: | B8: Fabian la Rosa
A9: Aprobado por: | B9: Irma Coaquira Layme
A10: Matriz: | B10: Agregado grueso
A11: Mensurando | B11: Densidad relativa (gravedad especifica) y absorción de agregados gruesos
A13: Paso 1. Definicion del proceso de medición
A14: Variables: | F14: Equipos a utilizar:
F15: Balanza con resolución de lectura de 1g
A16: A = Masa de la muestra secada al horno, g | F16: Horno que puea mantener una temperatura uniforme de 110 ± 5°C
A17: B = Masa de la muestra de ensayo de superficie seca saturada en el aire, g
A18: C = Masa aparente de la muestra de prueba sumergida en agua, g | F18: Paso 2. Definición de las variables aleatorias
A21: Fórmula:
A31: OD
A32: Fuentes | B32: Valor | C32: Incertidumbre Original | D32: Unidades | E32: Distribución | F32: Incertidumbre Estándar u(xi) | G32: Coeficiente de Sensibilidad | H32: Contribución ui(y)
A33: Resultado OD: | B33: =+B34/(B38-B42) -> #DIV/0!
A34: =+DATOS!B17 -> Masa de la muestra secada al horno constante | B34: =+DATOS!I17 -> 0 | C34: --- | D34: g | E34: --- | F34: =SQRT((F35*F35)+(F36*F36)+(F37*F37)) -> 0.28867591 | G34: =1/(B38-B42) -> #DIV/0! | H34: =G34*F34 -> #DIV/0! | I34: A
A35: Repetibilidad de la pesada | C35: =Balanza!$G$23 -> 0 | D35: g | E35: Normal, K=1 | F35: =+C35 -> 0 | G35: --- | H35: ---
A36: Certificado de Calibración | C36: =2*(SQRT(Balanza!$C$8+Balanza!$D$8*(POWER(B34,2)))) -> 0.0013416408 | D36: g | E36: Normal, K=2 | F36: =+C36/2 -> 0.00067082039 | G36: --- | H36: --- | L36: Factor de Influencia | N36: Valor | O36: %
A37: Resolución | C37: =Balanza!$C$10 -> 1 | D37: g | E37: Rectangular | F37: =C37/SQRT(3)/2 -> 0.28867513 | G37: --- | H37: --- | M37: =A34 -> Masa de la muestra secada al horno constante | N37: =H34 -> #DIV/0! | O37: =N37*100/$N$41 -> #DIV/0!
A38: =+DATOS!B18 -> Masa de la muestra de ensayo de superficie seca saturada en el aire | B38: =+DATOS!I18 -> 0 | D38: g | E38: --- | F38: =SQRT((F39*F39)+(F40*F40)+(F41*F41)) -> 0.28867591 | G38: =+B34/(B38-B42)^2 -> #DIV/0! | H38: =G38*F38 -> #DIV/0! | I38: B | M38: =A38 -> Masa de la muestra de ensayo de superficie seca saturada en el aire | N38: =H38 -> #DIV/0! | O38: =N38*100/$N$41 -> #DIV/0!
A39: Repetibilidad de la pesada | C39: =Balanza!$G$24 -> 0 | D39: g | E39: Normal, K=1 | F39: =+C39 -> 0 | G39: --- | H39: --- | M39: =A42 -> Masa aparente de la muestra de prueba sumergida en agua | N39: =+H42 -> #DIV/0! | O39: =N39*100/$N$41 -> #DIV/0!
A40: Certificado de Calibración | C40: =2*(SQRT(Balanza!$C$8+Balanza!$D$8*(POWER(B38,2)))) -> 0.0013416408 | D40: g | E40: Normal, K=2 | F40: =+C40/2 -> 0.00067082039 | G40: --- | H40: --- | M40: =A46 -> factor de presición OD | N40: =H46 -> 0.0041539807 | O40: =N40*100/$N$41 -> #DIV/0!
A41: Resolución | C41: =Balanza!$C$10 -> 1 | D41: g | E41: Rectangular | F41: =C41/SQRT(3)/2 -> 0.28867513 | G41: --- | H41: --- | L41: TOTAL | N41: =SUM(N37:N40) -> #DIV/0! | O41: =N41*100/$N$41 -> #DIV/0!
A42: =+DATOS!B19 -> Masa aparente de la muestra de prueba sumergida en agua | B42: =+DATOS!I19 -> 0 | D42: g | E42: --- | F42: =SQRT((F43*F43)+(F44*F44)+(F45*F45)) -> 0.28867591 | G42: =+B34/(B38-B42)^2 -> #DIV/0! | H42: =G42*F42 -> #DIV/0! | I42: C
A43: Repetibilidad de la pesada | C43: =Balanza!$G$25 -> 0 | D43: g | E43: Normal, K=1 | F43: =+C43 -> 0 | G43: --- | H43: ---
A44: Certificado de Calibración | C44: =2*(SQRT(Balanza!$C$8+Balanza!$D$8*(POWER(B42,2)))) -> 0.0013416408 | D44: g | E44: Normal, K=2 | F44: =+C44/2 -> 0.00067082039 | G44: --- | H44: ---
A45: Resolución | C45: =Balanza!$C$10 -> 1 | D45: g | E45: Rectangular | F45: =C45/SQRT(3)/2 -> 0.28867513 | G45: --- | H45: --- | L45: ^
A46: factor de presición OD | B46: =+Precision!B8 -> 0.0041539807 | D46: - | E46: Norma, K=1 | F46: =+B46 -> 0.0041539807 | G46: 1 | H46: =+G46*F46 -> 0.0041539807
C47: Incertidumbre Estándar Combinada OD | H47: =SQRT((H34*H34+(H38*H38)+(H42*H42)+(H46*H46))) -> #DIV/0!
C48: Incertidumbre Expandida OD, K = 2 | H48: =H47*2 -> #DIV/0!
D50: SSD
A51: Resultado SSD: | B51: =+B52/(B52-B56) -> #DIV/0!
A52: =+DATOS!B18 -> Masa de la muestra de ensayo de superficie seca saturada en el aire | B52: =+DATOS!I18 -> 0 | D52: g | E52: --- | F52: =SQRT((F53*F53)+(F54*F54)+(F55*F55)) -> 0.28867591 | G52: =+B56/(B52-B56)^2 -> #DIV/0! | H52: =G52*F52 -> #DIV/0! | I52: B | L52: Factor de Influencia | N52: Valor | O52: %
A53: Repetibilidad de la pesada | C53: =+Balanza!G24 -> 0 | D53: g | E53: Normal, K=1 | F53: =+C53 -> 0 | G53: --- | H53: --- | M53: =+A52 -> Masa de la muestra de ensayo de superficie seca saturada en el aire | N53: =+H52 -> #DIV/0! | O53: =N53*100/$N$56 -> #DIV/0!
A54: Certificado de Calibración | C54: =2*(SQRT(Balanza!$C$8+Balanza!$D$8*(POWER(B52,2)))) -> 0.0013416408 | D54: g | E54: Normal, K=2 | F54: =+C54/2 -> 0.00067082039 | G54: --- | H54: --- | M54: =+A56 -> Masa aparente de la muestra de prueba sumergida en agua | N54: =+H56 -> #DIV/0! | O54: =N54*100/$N$56 -> #DIV/0!
...

Sheet Balanza
B6: CALIBRACION DE LA BALANZA
B7: Correccion | C7: -4.63e-06
B8: Variables | C8: 4.5e-07 | D8: 1.09e-09
B9: Ecuacion | C9: 2*RAIZ(0.000000450+0.00000000109xR2)
B10: Resolucion | C10: 1 | D10: g
B11: Codigo | C11: EQP-0050
B12: fecha calibracion | D12: 46132
B13: ITEM | C13: MES | D13: 500 | E13: 1000 | F13: 5000 | G13: 10000 | H13: 15000
C16: DESV STD | D16: 0 | E16: 0 | F16: 0 | G16: 0 | H16: 0
D18: Busqueda de Repetibilidad de la masa
D20: =+D13 -> 500 | E20: =+E13 -> 1000 | F20: =+F13 -> 5000 | G20: =+G13 -> 10000 | H20: =+H13 -> 15000
D21: =D16 -> 0 | E21: =E16 -> 0 | F21: =F16 -> 0 | G21: =G16 -> 0 | H21: =H16 -> 0
B23: =+DATOS!B17 -> Masa de la muestra secada al horno constante | F23: =+DATOS!I17 -> 0 | G23: =IF(F23<=$D$20,$D$21,IF(AND(F23>$D$20,F23<=$E$20),$E$21,IF(AND(F23>$E$20,F23<=$F$20),$F$21,IF(AND(F23>$F$20,F23<=$G$20),$G$21,IF(AND(F23>$G$20,F23<=$H$20),$H$21,$H$21))))) -> 0 | H23: B
B24: =+DATOS!B18 -> Masa de la muestra de ensayo de superficie seca saturada en el aire | F24: =+DATOS!I18 -> 0 | G24: =IF(F24<=$D$20,$D$21,IF(AND(F24>$D$20,F24<=$E$20),$E$21,IF(AND(F24>$E$20,F24<=$F$20),$F$21,IF(AND(F24>$F$20,F24<=$G$20),$G$21,IF(AND(F24>$G$20,F24<=$H$20),$H$21,$H$21))))) -> 0 | H24: C
B25: =+DATOS!B19 -> Masa aparente de la muestra de prueba sumergida en agua | F25: =+DATOS!I19 -> 0 | G25: =IF(F25<=$D$20,$D$21,IF(AND(F25>$D$20,F25<=$E$20),$E$21,IF(AND(F25>$E$20,F25<=$F$20),$F$21,IF(AND(F25>$F$20,F25<=$G$20),$G$21,IF(AND(F25>$G$20,F25<=$H$20),$H$21,$H$21))))) -> 0 | H25: D

Sheet Precision
A3: Factor de precision del operador
A5: Fecha de evaluacion:
A7: 1-Calcular la Incertidumbre estandar bajo condiciones de reproducibilidad - OD | F7: 1-Calcular la Incertidumbre estandar bajo condiciones de reproducibilidad SSD | K7: 1-Calcular la Incertidumbre estandar bajo condiciones de reproducibilidad APARENTE | P7: 1-Calcular la Incertidumbre estandar bajo condiciones de reproducibilidad ABSORCION
A8: Desviacion Estándar Repetibilidad (Sr) | B8: 0.0041539807 | F8: Desviacion Estándar Repetibilidad (Sr) | G8: 0.0042163702 | K8: Desviacion Estándar Repetibilidad (Sr) | L8: 0.0044397197 | P8: Desviacion Estándar Repetibilidad (Sr) | Q8: 0.029230882
A9: Desviacion Estándar Reproducibilidad (SR) | B9: 0.0045030854 | F9: Desviacion Estándar Reproducibilidad (SR) | G9: 0.0044762749 | K9: Desviacion Estándar Reproducibilidad (SR) | L9: 0.0044855736 | P9: Desviacion Estándar Reproducibilidad (SR) | Q9: 0.061433493
