Workbook
Name ___CC2: [1]Sucs!$L$6
Name __CC2: [1]Sucs!$L$6
Name _CC1: [2]Sucs!$L$6
Name _CC2: [1]Sucs!$L$6
Name _CU1: [2]Sucs!$L$5
Name _IP1: [2]Sucs!$L$4
Name _L1: #REF!
Name _L1: #REF!
Name _L1: #REF!
Name _Ll1: [2]Sucs!$L$3
Name _W1: #REF!
Name _W1: #REF!
Name _W1: #REF!
Name Abra: [3]Sucs!$C$3
Name CC: [4]Sucs!$L$6
Name CC: #REF!
Name CC: [5]Sucs!$L$6
Name CC: #REF!
Name CC: [4]Sucs!$L$6
Name CC: [4]Sucs!$L$6
Name CC: Sucs!$L$6
Name CCf: '[2]Sucs(Fino)'!$L$6
Name CCVB: [6]Sucs!$L$3
Name CM: [7]BGA!$H$9
Name CU: [4]Sucs!$L$5
Name CU: #REF!
Name CU: [5]Sucs!$L$5
Name CU: #REF!
Name CU: [4]Sucs!$L$5
Name CU: [4]Sucs!$L$5
Name CU: Sucs!$L$5
Name CUf: '[2]Sucs(Fino)'!$L$5
Name hh: #REF!
Name hh: #REF!
Name hh: #REF!
Name IP: [4]Sucs!$L$4
Name IP: #REF!
Name IP: [5]Sucs!$L$4
Name IP: #REF!
Name IP: [4]Sucs!$L$4
Name IP: [4]Sucs!$L$4
Name IP: Sucs!$L$4
Name IPf: '[2]Sucs(Fino)'!$L$4
Name L: #REF!
Name L: #REF!
Name L: #REF!
Name LIf: '[2]Sucs(Fino)'!$L$3
Name Ll: [4]Sucs!$L$3
Name Ll: #REF!
Name Ll: [5]Sucs!$L$3
Name Ll: #REF!
Name Ll: [4]Sucs!$L$3
Name Ll: [4]Sucs!$L$3
Name Ll: Sucs!$L$3
Name MORA: [7]BGA!$H$13
Name N_10: [4]Sucs!$C$5
Name N_10: #REF!
Name N_10: [5]Sucs!$C$5
Name N_10: #REF!
Name N_10: [4]Sucs!$C$5

Sheet -------

Sheet Gran
A7: Análisis Mecánico por Tamizado
A8: NORMA ASTM C-136 / MTC E 204-200
A9: Solicitado | B9: : | C9: CAME Contratistas y servicios generales S.A.
A10: Proyecto | B10: : | C10: Mejoramiento de la Carretera JU-1029 tramo PE 22 Pachachaca -Yauli | M10: Certificado Nº | N10: : | O10: 163-14 / SU 02 | R10: Golp. | S10: % Humed
A11: Ubicación | B11: : | C11: Distrito de Yauli - Junin | M11: Ref. Proyecto | N11: : | R11: =+#REF! -> #REF! | S11: =+M20 -> 0
A12: Cantera | B12: : | C12: Agregados GMC S.R.L. (Rio Yauli - Km. 5+700) | M12: Fecha de ensayo | N12: : | O12: 41876 | R12: =+#REF! -> #REF! | S12: =+O20 -> 0
A13: Material | B13: : | C13: Grava para concreto | M13: Hecho por | N13: : | O13: F.L.G. | R13: =+#REF! -> #REF! | S13: =+P20 -> 0
A16: Granulometría (MTC E 204) | F16: Humedad Natural
A17: Datos de ensayo | F17: P Hum | G17: = | H17: 1031 | R17: 25 | S17: 0
A18: Peso Total : | D18: =+SUM(F24:F41) -> 7988.3 | F18: P seco | G18: = | H18: 1017 | R18: 25 | S18: 0 | T18: LL | U18: =+M20/(1.419-0.3*LOG10(#REF!)) -> #REF! | V18: =+O20/(1.419-0.3*LOG10(#REF!)) -> #REF!
A19: Peso muestra lavada : | F19: % W | G19: = | H19: =((H17-H18)/H18)*100 -> 1.3765978 | R19: 10 | S19: =+S18 -> 0 | T19: LL | U19: =+AVERAGE(U18:W18) -> #REF!
D21: : | T21: LP
D22: Malla | F22: Peso | G22: % Ret | H22: % Ret | I22: % que | J22: Gradación | S22: =+AVERAGE(M30:O30) -> #DIV/0! | T22: LP
D23: Tamiz | E23: mm. | F23: (gr) | G23: Parcial | H23: Acum. | I23: Pasa | J23: AG - 4 | U23: Aberturas | W23: AG - 4 | Y23: AG - 5 | AA23: AG - 6 | AC23: AG - 7
D24: 3" | E24: 76.2 | R24: 20.17 | S24: 21.22
D25: 2 1/2" | E25: 63.5 | U25: Pulg. | V25: mm
D26: 2" | E26: 50.6 | I26: =100-H26 -> 100 | K26: 100 | U26: 2 1/2" | V26: 63.5 | Y26: 100 | AC26: 100
D27: 1 1/2" | E27: 38.1 | F27: 0 | G27: =(F27/$D$18*100) -> 0 | H27: =+H26+G27 -> 0 | I27: =100-H27 -> 100 | J27: 95 | L27: 100 | U27: 2" | V27: 50.6 | W27: 100 | Y27: 95 | Z27: 100 | AA27: 100 | AC27: 95 | AD27: 100
D28: 1" | E28: 25.4 | F28: 0 | G28: =(F28/$D$18*100) -> 0 | H28: =+H27+G28 -> 0 | I28: 75.7 | U28: 1 1/2" | V28: 38.1 | W28: 95 | X28: 100 | AA28: 90 | AB28: 100 | AC28: 35 | AD28: 70
D29: 3/4" | E29: 19.05 | F29: 1866 | G29: =(F29/$D$18*100) -> 23.359163 | H29: =+H28+G29 -> 23.359163 | I29: 41.9 | J29: 35 | L29: 70 | S29: =+D18 -> 7988.3 | U29: 1" | V29: 25.4 | Y29: 35 | Z29: 70 | AA29: 20 | AB29: 55 | AC29: 0 | AD29: 15
D30: 1/2" | E30: 12.7 | F30: 2894 | G30: =(F30/$D$18*100) -> 36.227983 | H30: =+H29+G30 -> 59.587146 | I30: 25.6 | S30: =+D18-F42 -> 7988.3 | T30: =SUM(F24:F33) -> 7626 | U30: 3/4" | V30: 19.05 | W30: 35 | X30: 70 | AA30: 0 | AB30: 15
D31: 3/8" | E31: 9.525 | F31: 1632 | G31: =(F31/$D$18*100) -> 20.429879 | H31: =+H30+G31 -> 80.017025 | I31: 23.8 | J31: 10 | L31: 30 | S31: =+#REF!-T30 -> #REF! | U31: 1/2" | V31: 12.7 | Y31: 10 | Z31: 30 | AC31: 0 | AD31: 5
D32: 1/4" | E32: 6.35 | F32: 1042 | G32: =(F32/$D$18*100) -> 13.044077 | H32: =+H31+G32 -> 93.061102 | I32: =100-H32 -> 6.9388981 | S32: =+S31*S30/S29 -> #REF! | U32: 3/8" | V32: 9.525 | W32: 10 | X32: 30 | AA32: 0 | AB32: 5
D33: No4 | E33: 4.76 | F33: 192 | G33: =(F33/$D$18*100) -> 2.4035151 | H33: =+H32+G33 -> 95.464617 | I33: =100-H33 -> 4.535383 | J33: 0 | L33: 5 | U33: 1/4" | V33: 6.35
D34: 8 | E34: 2.36 | F34: 199.9 | G34: =(F34/$D$18*100) -> 2.5024098 | H34: =+H33+G34 -> 97.967027 | I34: =100-H34 -> 2.0329732 | U34: 4 | V34: 4.76 | W34: 0 | X34: 5 | Y34: 0 | Z34: 5
D35: 10 | E35: 2 | F35: 162.4 | G35: =(F35/$D$18*100) -> 2.0329732 | H35: =+H34+G35 -> 100 | I35: =100-H35 -> 0 | U35: 8 | V35: 2.36
D36: 16 | E36: 1.19 | H36: 100 | U36: 10 | V36: 2
D37: 30 | E37: 0.6 | H37: 100 | U37: 16 | V37: 1.19
D38: 40 | E38: 0.42 | H38: 100 | S38: =SUM(F35:F41) -> 162.4 | U38: 30 | V38: 0.6
D39: 50 | E39: 0.3 | H39: 100 | U39: 40 | V39: 0.42
D40: 100 | E40: 0.149 | H40: 100 | U40: 50 | V40: 0.3
D41: 200 | E41: 0.074 | H41: 100 | U41: 100 | V41: 0.149
D42: < 200 | U42: 200 | V42: 0.074
A45: Clasificación SUCS | D45: =+Sucs!G4 -> GP | F45: L.L : | G45: NP | I45: Módulo de Fineza
A46: Clasificación AASHTO | D46: A-1-a (0) | F46: I.P : | G46: NP | J46: M.F. = | K46: =+(H27+H29+H31+H33+H34+H36+H37+H39+H40)/100 -> 6.9680783
R50: Diametro efectivos
R51: D10
R52: 0 | S52: 10
R53: =+R52 -> 0 | S53: 10
R54: =+R53 -> 0 | S54: 0
...

Sheet G_E
A7: Gravedad Especifica y Absorcion de los Agregados
A8: NORMA ASTM C-127/ MTC E 206-200
A10: Solicitado | C10: : | D10: =+Gran!C9 -> CAME Contratistas y servicios generales S.A. | G10: Certificado N° | H10: : | I10: 55-14 / AG 09
A11: Proyecto | C11: : | D11: =+Gran!C10 -> Mejoramiento de la Carretera JU-1029 tramo PE 22 Pachachaca -Yauli | G11: Ref. Proyecto | H11: :
A12: Ubicación | C12: : | D12: =+Gran!C11 -> Distrito de Yauli - Junin | G12: Fecha de ensayo | H12: : | I12: =+Gran!O12 -> 41876
A13: =+Gran!A12 -> Cantera | C13: : | D13: =+Gran!C12 -> Agregados GMC S.R.L. (Rio Yauli - Km. 5+700) | G13: Hecho por | H13: : | I13: =+Gran!O13 -> F.L.G.
A14: Material | C14: : | D14: =+Gran!C13 -> Grava para concreto
A16: AGREGADO FINO
A18: A | B18: Peso Mat. Sat. Sup. Seco ( en Aire ) (gr) | E18: 125.2 | F18: 125
A19: B | B19: Peso Frasco + agua | E19: 660.5 | F19: 660
A20: C | B20: Peso Frasco + agua + A (gr) | E20: =+E19+E18 -> 785.7 | F20: =+F19+F18 -> 785
A21: D | B21: Peso del Mat. + agua en el frasco (gr) | E21: 733.4 | F21: 733
A22: E | B22: Vol de masa + vol de vacío = C-D (gr) | E22: =+E20-E21 -> 52.3 | F22: =+F20-F21 -> 52
A23: F | B23: Pe. De Mat. Seco en estufa (105ºC) (gr) | E23: 118.6 | F23: 119
A24: G | B24: Vol de masa = E - ( A - F ) (gr) | E24: =+E22-(E18-E23) -> 45.7 | F24: =+F22-(F18-F23) -> 46 | H24: PROMEDIO
B25: Pe bulk ( Base seca ) = F/E | E25: =+E23/E22 -> 2.2676864 | F25: =+F23/F22 -> 2.2884615 | H25: =+AVERAGE(D25:H25) -> 2.278074
B26: Pe bulk ( Base saturada ) = A/E | E26: =+E18/E22 -> 2.3938815 | F26: =+F18/F22 -> 2.4038462 | H26: =+AVERAGE(D26:H26) -> 2.3988638
B27: Pe aparente ( Base Seca ) = F/G | E27: =+E23/E24 -> 2.595186 | F27: =+F23/F24 -> 2.5869565 | H27: =+AVERAGE(D27:H27) -> 2.5910713
B28: % de absorción = ((A - F)/F)*100 | E28: =((E18-E23)/E23)*100 -> 5.5649241 | F28: =((F18-F23)/F23)*100 -> 5.0420168 | H28: =+AVERAGE(D28:H28) -> 5.3034705
A30: AGREGADO GRUESO
A32: A | B32: Peso Mat.Sat. Sup. Seca ( En Aire ) (gr) | E32: 848.3
A33: B | B33: Peso Mat.Sat. Sup. Seca ( En Agua ) (gr) | E33: 531.1
A34: C | B34: Vol. de masa + vol de vacíos = A-B (gr) | E34: =+E32-E33 -> 317.2
A35: D | B35: Peso material seco en estufa ( 105 ºC )(gr) | E35: 841
A36: E | B36: Vol. de masa = C- ( A - D ) (gr) | E36: =+E34-(E32-E35) -> 309.9 | H36: PROMEDIO
B37: Pe bulk ( Base seca ) = D/C | E37: =+E35/E34 -> 2.6513241 | H37: =+AVERAGE(E37:G37) -> 2.6513241
B38: Pe bulk ( Base saturada) = A/C | E38: =+E32/E34 -> 2.674338 | H38: =+AVERAGE(E38:G38) -> 2.674338
B39: Pe Aparente ( Base Seca ) = D/E | E39: =+E35/E36 -> 2.7137786 | H39: =+AVERAGE(E39:G39) -> 2.7137786
B40: % de absorción = (( A - D ) / D * 100 ) | E40: =((E32-E35)/E35*100) -> 0.86801427 | H40: =+AVERAGE(E40:G40) -> 0.86801427
A53: WEB: www.geofal.com.pe E-MAIL: geofal.sac@gmail.com / laboratorio@geofal.com.pe

Sheet PU-S
A7: Peso Unitario Suelto de los Agregados
A8: NORMA ASTM C-29/ MTC E 203-200
A10: Solicitado | B10: : | C10: =+Gran!C9 -> CAME Contratistas y servicios generales S.A. | G10: Certificado N° | I10: : | J10: 54-14 / AG 11
A11: Proyecto | B11: : | C11: =+Gran!C10 -> Mejoramiento de la Carretera JU-1029 tramo PE 22 Pachachaca -Yauli | G11: Ref. Proyecto | I11: :
A12: Ubicación | B12: : | C12: =+Gran!C11 -> Distrito de Yauli - Junin | G12: Fecha de ensayo | I12: : | J12: =+Gran!O12 -> 41876
A13: =+Gran!A12 -> Cantera | B13: : | C13: =+Gran!C12 -> Agregados GMC S.R.L. (Rio Yauli - Km. 5+700) | G13: Hecho por | I13: : | J13: =+Gran!O13 -> F.L.G.
A14: Material | B14: : | C14: =+Gran!C13 -> Grava para concreto
A16: DATOS DE LA MUESTRA
A17: Material | B17: :
A18: Cantera | B18: :
A19: Muestreo | B19: :
A20: AGREGADO GRUESO
A21: Prueba N° | E21: 1 | F21: 2 | G21: 3 | I21: 4
A22: Peso del recipiente + suelo | E22: 15801 | F22: 15816 | G22: 15810 | J22: gr
A23: Peso del recipiente | E23: 6665 | F23: =+E23 -> 6665 | G23: =+E23 -> 6665 | J23: gr
A24: Peso del suelo | E24: =E22-E23 -> 9136 | F24: =F22-F23 -> 9151 | G24: =G22-G23 -> 9145 | J24: gr
A25: Volumen del Recipiente | E25: 5626 | F25: =+E25 -> 5626 | G25: =+E25 -> 5626 | J25: cm3
A26: Peso unitario suelo | E26: =+E24/E25 -> 1.6238891 | F26: =+F24/F25 -> 1.6265553 | G26: =+G24/G25 -> 1.6254888
A27: Contenido de humedad | E27: 1.3 | F27: =+E27 -> 1.3 | G27: =+E27 -> 1.3
A28: Peso del suelo Humedo | E28: =+E26/(1+(E27/100)) -> 1.6030494 | F28: =+F26/(1+(F27/100)) -> 1.6056814 | G28: =+G26/(1+(G27/100)) -> 1.6046286
F30: PROMEDIO P.U.S | I30: =AVERAGE(E28:I28) -> 1.6044532
A59: WEB: www.geofal.com.pe E-MAIL: geofal.sac@gmail.com / laboratorio@geofal.com.pe

Sheet PU-C
A7: Peso Unitario Compactado de los Agregados
A8: NORMA ASTM C-29/ MTC E 203-200
A10: Solicitado | B10: : | C10: =+Gran!C9 -> CAME Contratistas y servicios generales S.A. | G10: Certificado N° | H10: : | I10: 55-14 / AG 11
A11: Proyecto | B11: : | C11: =+Gran!C10 -> Mejoramiento de la Carretera JU-1029 tramo PE 22 Pachachaca -Yauli | G11: Ref. Proyecto | H11: :
A12: Ubicación | B12: : | C12: =+Gran!C11 -> Distrito de Yauli - Junin | G12: Fecha de ensayo | H12: : | I12: =+Gran!O12 -> 41876
A13: =+Gran!A12 -> Cantera | B13: : | C13: =+Gran!C12 -> Agregados GMC S.R.L. (Rio Yauli - Km. 5+700) | G13: Hecho por | H13: : | I13: =+Gran!O13 -> F.L.G.
A14: Material | B14: : | C14: =+Gran!C13 -> Grava para concreto
A16: DATOS DE LA MUESTRA
A17: Material | B17: :
A18: Cantera | B18: :
A19: Muestreo | B19: :
A20: AGREGADO GRUESO
A21: Prueba N° | E21: 1 | F21: 2 | G21: 3 | I21: 4
A22: Peso del recipiente + suelo Compactado | E22: 16276 | F22: 16280 | G22: 16201 | I22: gr
A23: Peso del recipiente | E23: 6665 | F23: =+E23 -> 6665 | G23: =+E23 -> 6665 | I23: gr
A24: Peso del suelo Compactado | E24: =E22-E23 -> 9611 | F24: =F22-F23 -> 9615 | G24: =G22-G23 -> 9536 | I24: gr
A25: Volumen del Recipiente | E25: 5626 | F25: =+E25 -> 5626 | G25: =+E25 -> 5626 | I25: cm3
A26: Peso unitario suelo Compactado | E26: =+E24/E25 -> 1.7083185 | F26: =+F24/F25 -> 1.7090295 | G26: =+G24/G25 -> 1.6949876
A27: Contenido de humedad | E27: 1.3 | F27: =+E27 -> 1.3 | G27: =+E27 -> 1.3
A28: Peso del suelo Compactado Humedo | E28: =+E26/(1+(E27/100)) -> 1.6863954 | F28: =+F26/(1+(F27/100)) -> 1.6870972 | G28: =+G26/(1+(G27/100)) -> 1.6732355
F30: PROMEDIO P.U.C | H30: =AVERAGE(E28:I28) -> 1.6822427
A58: WEB: www.geofal.com.pe E-MAIL: geofal.sac@gmail.com / laboratorio@geofal.com.pe

Sheet % que pasa # 200
A9: CANTIDAD DE MATERIAL FINO QUE PASA POR EL TAMIZ (Nº 200)
A10: MTC E- 202-1999 -AASTHO T 11
A11: LABORATORIO MECANICA DE SUELOS, CONCRETOS Y PAVIMENTOS
A12: Obra | C12: =+'[4]G-Con'!C7 -> Mejoramiento y ampliacion de los sistemas de agua potable, alcantarillado y tratamiento de aguas residuales
A13: =+'[4]G-Con'!A8 -> Ubicación | C13: =+'[4]G-Con'!C8 -> Jaen-Cajamarca-Peru
A14: =+'[4]G-Con'!A12 -> Estructura | C14: Grava 1" Triturada para Concreto
A15: =+'[4]G-Con'!A9 -> Certificado | C15: =Gran!#REF! -> #REF!
E19: DATOS DEL MATERIAL
A21: Hecho Por | C21: =Gran!H14 -> 0
A22: Revisado | C22: =Gran!#REF! -> #REF!
A23: Fecha | C23: =Gran!#REF! -> #REF!
A26: Cantera | C26: Grupo Olano
A27: Material | C27: =C14 -> Grava 1" Triturada para Concreto
A28: Muestreo | C28: Acopio-Planta
A31: RESULTADO
A34: A | B34: Peso de la muestra seca............................................................... | G34: 6747.5 | H34: Grs.
A36: B | B36: Peso de la muestra seca despues de lavado................................... | G36: 6740.1 | H36: Grs.
D41: % QUE PASA LA Nº 200 | F41: =+((G34-G36)/G34*100)/100 -> 0.0010967025

Sheet D_S
B7: DURABILIDAD AL SULFATO DE SODIO
B8: AASHTO T-104 (MTC E-209) ASTM C-88
B10: =+[9]I_O!A11 -> Cantera | C10: Mapacho | L10: Nº REGISTRO :
B11: =+[9]I_O!A12 -> Muestra | C11: =+Gran!C13 -> Grava para concreto | L11: TECNICO : | M11: =+Gran!H14 -> 0
L12: ING. RESP. : | M12: =+Gran!#REF! -> #REF!
B13: =+[9]I_O!A14 -> Fecha | C13: =+Gran!#REF! -> #REF! | I13: m. | L13: FECHA : | M13: =+C13 -> #REF!
L14: SOLUCIÓN : | M14: Na2SO4
B17: TABLA 1 DATOS DEL ENSAYO
B19: TAMIZ | D19: Peso de | E19: Tamaño | F19: Tamiz que | G19: Granulometria | I19: PESO DE FRACCION | K19: Pasante después | M19: PERDIDA EN
B20: ASTM E-11 | D20: fracción | E20: del | F20: determina | G20: original retenido | I20: Antes del | J20: Después | K20: del ensayo | M20: PESO
D21: gr | E21: árido | F21: pérdida | G21: % | I21: ensayo | J21: del ensayo | K21: % | M21: %
B23: INTEMPRERISMO DEL AGREGADO GRUESO
B25: 2 1/2" | C25: 2" | D25: =+[10]G_LL!$C$25 -> 0 | E25: 63.5 | F25: =+C25 -> 2"
B26: 2" | C26: 1 1/2" | D26: =+Gran!F27 -> 0 | E26: 50.6 | F26: =+C26 -> 1 1/2" | G26: =+D26/$D$32*100 -> 0
B27: 1 1/2" | C27: 1" | D27: =+Gran!F28 -> 0 | E27: 38.1 | F27: =+C27 -> 1" | G27: =+D27/$D$32*100 -> 0 | I27: 1014.1 | J27: 1002.2 | K27: =(I27-J27)/I27*100 -> 1.1734543 | M27: =(G27*K27)/100 -> 0
B28: 1" | C28: 3/4" | D28: =+Gran!F29 -> 1866 | E28: 25.4 | F28: =+C28 -> 3/4" | G28: =+D28/$D$32*100 -> 28.341434 | I28: 504.6 | J28: 503.2 | K28: =(I28-J28)/I28*100 -> 0.27744748 | M28: =(G28*K28)/100 -> 0.078632595
B29: 3/4" | C29: 1/2" | D29: =+Gran!F30 -> 2894 | E29: 19.05 | F29: =+C29 -> 1/2" | G29: =+D29/$D$32*100 -> 43.955043 | I29: 673.6 | J29: 668.7 | K29: =(I29-J29)/I29*100 -> 0.72743468 | M29: =(G29*K29)/100 -> 0.31974422
B30: 1/2" | C30: 3/8" | D30: =+Gran!F31 -> 1632 | E30: 12.7 | F30: =+C30 -> 3/8" | G30: =+D30/$D$32*100 -> 24.787363 | I30: 331.9 | J30: 325.3 | K30: =(I30-J30)/I30*100 -> 1.9885508 | M30: =(G30*K30)/100 -> 0.4929093
B31: 3/8" | C31: Nº 4 | D31: =+Gran!F33 -> 192 | E31: 4.76 | F31: =+C31 -> Nº 4 | G31: =+D31/$D$32*100 -> 2.9161604 | I31: 300.2 | J31: 294.5 | K31: =(I31-J31)/I31*100 -> 1.8987342 | M31: =(G31*K31)/100 -> 0.055370134
B32: TOTALES | D32: =SUM(D25:D31) -> 6584 | G32: =SUM(G25:H31) -> 100 | M32: =SUM(M27:N31) -> 0.94665625
B34: INTEMPERISMO DEL AGREGADO FINO
B36: 3/8"
B37: Nº 4
B38: Nº 8
B39: Nº 16
B40: Nº 30
B41: Nº 50
B42: < Nº 100
B43: TOTALES
B45: TABLA 2 EXAMEN CUALITATIVO DEL AGREGADO GRUESO
B48: TAMIZ | D48: FRACTURADAS | F48: FISURADAS | H48: ASTILLADAS | J48: EXFOLIADAS | L48: PARTICULAS ANTES
B49: ASTM E-11 | D49: Nº | E49: % | F49: Nº | G49: % | H49: Nº | I49: % | J49: Nº | K49: % | L49: DEL ENSAYO
B50: 2 1/2" | C50: 1 1/2" | D50: 0 | E50: =+D50/$M$50*100 -> 0 | F50: 0 | G50: =+F50/$M$50*100 -> 0 | H50: 0 | I50: =+H50/$M$50*100 -> 0 | J50: 0 | K50: =+J50/$M$50*100 -> 0 | M50: 1
B51: 1 1/2" | C51: 3/4" | D51: 0 | E51: =+D51/$M$51*100 -> 0 | F51: 0 | G51: =+F51/$M$51*100 -> 0 | H51: 0 | I51: =+H51/$M$51*100 -> 0 | J51: 0 | K51: =+J51/$M$51*100 -> 0 | M51: 1
B53: OBSERVACIONES:
B55: Ciclos: | E55: 5
B56: Fecha de inicio de ensayo: | E56: =+M13 -> #REF!
B57: Fecha final de ensayo: | E57: =+M13+5 -> #REF!
B58: Densidad de solución | D58: gr/l | E58: 1.16
B59: Temperatura de solución ºC | E59: 25
...

Sheet FORMATO
O2: CLIENTE
O3: DIRECCIÓN **
O4: PROYECTO **
O5: UBICACIÓN **
A7: LABORATORIO DE ENSAYO DE MATERIALES | O7: RECEPCIÓN N°
A8: FORMATO N° F-LEM-P-AG-23.01 | O8: F. EMISIÓN
O9: OT N°
C10: MUESTRA | E10: N° OT | G10: FECHA DE ENSAYO | I10: REALIZADO
O11: CÓDIGO DE LA MUESTRA
O12: FECHA DE RECEPCIÓN
O13: FECHA DE EJECUCIÓN
A14: Standard Test Method for Materials Finer than 75-μm (No. 200) Sieve in Mineral Aggregates by Washing
A15: ASTM C117-23 | O15: CANTERA/SONDAJE **
O16: N° MUESTRA **
C17: Marca con "X" | O17: TIPO DE MUESTRA**
D18: Procedimiento A: lavado con agua | H18: Tamaño máximo nominal muestra (visual) (in):
D19: Procedimiento B: lavado con agente humectante
B21: Nº | C21: DESCRIPCIÓN | I21: UND. | J21: DATOS
B22: A | C22: Masa del recipiente | I22: g
B23: B | C23: Masa del recipiente+ muestra seca | I23: g
B24: C | C24: Masa del recipiente+ muestra seca constante | I24: g
B25: D | C25: Masa seca original de la muestra | H25: (C - A) | I25: g
B26: E | C26: masa del recipiente + muestra seca despues del lavado | I26: g
B27: F | C27: masa del recipiente + muestra seca despues del lavado, constante | I27: g
B28: G | C28: Masa seca de la muestra después del lavado | H28: (F - A) | I28: g
B29: H | C29: Porcentaje de material mas fino que un tamiz 75 µm (N° 200) por lavado | H29: (D-G)/D*100 | I29: %
C30: Perdida adicional de la masa seca <1%
B32: Equipo utilizado | E32: Código | H32: Tamaño máximo nominal | L32: Peso mínimo (g)
B33: Balanza 0.1 g | H33: No. 4 o menos | L33: 300
B34: Horno 110ºC | H34: Más grande No. 4 hasta 3/8 in | L34: 1000
B35: Tamiz No. 200 | H35: Más grande 3/8 in hasta 3/4 in | L35: 2500
B36: Tamiz No. 16 | H36: Más grande 3/4 in | L36: 5000
H37: Fuente: Elaboración propia en base a la Norma ASTM C117-23.
A39: Observaciones:
A45: Página 1 de 1
A46: Versión: 04 (01-02-2024) | G46: Prohibido reproducir sin autorización
A48: WEB: www.geofal.com.pe E-MAIL: laboratorio@geofal.com.pe / geofal.sac@gmail.com Av. Marañon 763, Los Olivos-Lima / Teléfono 01 522-1851

Sheet > Tamiz 200
A4: LABORATORIO DE ENSAYO DE MATERIALES
A5: 0
A8: CLIENTE | B8: : | C8: =+FORMATO!P2 -> 0 | L8: CÓDIGO | M8: : | N8: F-LEM-P-AG-23.02
A9: DIRECCIÓN ** | B9: : | C9: =+FORMATO!P3 -> 0 | L9: RECEPCIÓN N° | M9: : | N9: =+FORMATO!P7 -> 0
A10: PROYECTO ** | B10: : | C10: =+FORMATO!P4 -> 0 | L10: OT N° | M10: : | N10: =+FORMATO!P9 -> 0
A11: UBICACIÓN ** | B11: : | C11: =+FORMATO!P5 -> 0 | K11: FECHA EMISIÓN | M11: : | N11: =+FORMATO!P8 -> 0
A12: ** Datos proporcionados por el cliente
A13: Standard Test Method for Materials Finer than 75-µm (No. 200) Sieve in Mineral Aggregates by Washing
A14: ASTM C117-23
A16: DATOS DE LA MUESTRA
A17: CANTERA / SONDAJE ** | D17: : | E17: =+FORMATO!P15 -> 0 | L17: CÓDIGO DE LA MUESTRA | M17: : | N17: =+FORMATO!P11 -> 0
A18: N° MUESTRA ** | D18: : | E18: =+FORMATO!P16 -> 0 | L18: FECHA DE RECEPCIÓN | M18: : | N18: =+FORMATO!P12 -> 0
A19: TIPO DE MUESTRA | D19: : | E19: =+FORMATO!P17 -> 0 | L19: FECHA DE EJECUCIÓN | M19: : | N19: =+FORMATO!P13 -> 0 | P19: =+FORMATO!G11 -> 0
A20: LUGAR DE ENSAYO | D20: : | E20: Laboratorio de ensayo de materiales
D22: DESCRIPCIÓN | I22: Und. | J22: DATOS
D23: Masa seca original de la muestra | I23: g | J23: =+'DATOS ENS'!H14 -> 0
D24: Masa seca de la muestra después del lavado | I24: g | J24: =+'DATOS ENS'!H17 -> 0
D25: Porcentaje de material mas fino que un tamiz 75 µm (No. 200) por lavado | I25: % | J25: =+IF('DATOS ENS'!H18<10,FIXED('DATOS ENS'!H18,1),FIXED('DATOS ENS'!H18,0)) -> #DIV/0!
A28: Condiciones del ensayo:
A29: Se utilizó el procedimiento: | F29: "A" lavado con agua
A31: Descripción de la muestra:
A32: Tamaño máximo nominal (in) | F32: =+'DATOS ENS'!N11 -> 0
A33: Forma de la particula | F33: =+'DATOS ENS'!N12 -> -
A35: Nota:
A36: - El cliente es responsable de los datos de identificación de los puntos de ensayo brindados.
A37: - Los resultados expresados se refieren únicamente al ensayo realizado en dicho momento y en las condiciones especificadas en este documento, por lo que GEOFAL S.A.C. no será responsable por los ensayos realizados con la presente muestra en condiciones distintas a las aquí señaladas.
A38: - GEOFAL S.A.C. no se hace responsable por el uso incorrecto o inadecuado del presente informe.
A39: - Los resultados de los ensayos realizados no deben ser utilizados como una certificación de conformidad con normas de producto o como certificado del sistema de calidad de la entidad que lo produce.
A40: - De conformidad con lo dispuesto por el artículo 1321 del Código Civil, queda establecido que en ningún caso la responsabilidad de GEOFAL S.A.C. será mayor al valor del servicio prestado.
A42: Observaciones:
A49: Página 1 de 1
A50: Versión: 08 (2026-06-15) | N50: Fin del Informe

Sheet DATOS ENS
B2: Standard Test Method for Materials Finer than 75-µm (No. 200) Sieve in Mineral Aggregates by Washing
B3: ASTM C117-23
B5: Informacion para la Correccion por Certificado de Calibración: | H5: OPERADORES
B6: Precision de la balanza al 0.1 g | G6: =+Balanza!C7 -> -3.29e-06 | H6: - | I6: =+FORMATO!I11 -> 0
B7: CODIGO | G7: =+Balanza!C11 -> EQP-0046
B8: Fecha | G8: =+Balanza!C12 -> 46132
B10: DESCRIPCION | G10: DATOS | H10: CORRECCION | K10: Descripción de la muestra:
B11: Masa del recipiente | F11: g | G11: =+FORMATO!J22 -> 0 | H11: =G11+($G$6*G11) -> 0 | K11: Tamaño máximo nominal (in) | N11: =+FORMATO!L18 -> 0
B12: Masa del recipiente+ muestra seca | F12: g | G12: =+FORMATO!J23 -> 0 | H12: =G12+($G$6*G12) -> 0 | K12: Forma de la particula | N12: -
B13: Masa del recipiente+ muestra seca constante | F13: g | G13: =+FORMATO!J24 -> 0 | H13: =G13+($G$6*G13) -> 0 | K13: Masa de la muestra ensayada | N13: =+G14 -> 0
B14: Masa seca original de la muestra | F14: g | G14: =+G13-G11 -> 0 | H14: =+H13-H11 -> 0 | K14: LA MASA DE LA MUESTRA DE ENSAYO DESPUES DEL SECADO, DEBE CUMPLIR CON LA MASA MINIMA:
B15: masa del recipiente + muestra seca despues del lavado | F15: g | G15: =+FORMATO!J26 -> 0 | H15: =G15+($G$6*G15) -> 0 | K15: Tamaño maximo nominal | N15: Peso mínimo (g) | O15: Balanza | P15: Agregado
B16: masa del recipiente + muestra seca despues del lavado, constante | F16: g | G16: =+FORMATO!J27 -> 0 | H16: =G16+($G$6*G16) -> 0
B17: Masa seca de la muestra después del lavado | F17: g | G17: =+G16-G11 -> 0 | H17: =+H16-H11 -> 0 | K17: No. 4 o menos | N17: 300 | O17: 0.1 | P17: Ag. Fino
B18: Porcentaje de material mas fino que un tamiz 75 µm (N° 200) por lavado | F18: % | G18: =+((G14-G17)/G14)*100 -> #DIV/0! | H18: =+((H14-H17)/H14)*100 -> #DIV/0! | K18: Mas grande No. 4 hasta 3/8 | N18: 1000 | O18: 0.1 | P18: Ag. Grueso
K19: Mas grande 3/8 hasta 3/4 | N19: 2500 | O19: 0.1
B20: Perdida adicional de la masa seca original < 0.1% | H20: =(H12-H13)/H13*100 -> #DIV/0! | I20: =IF(H20<0.1,"cumple","no cumple") -> #DIV/0! | K20: Mas grande 3/4 | N20: 5000 | O20: 0.1
B21: Perdida adicional de la masa seca despues del lavado < 0.1% | H21: =(H15-H16)/H16*100 -> #DIV/0! | I21: =IF(H21<0.1,"cumple","no cumple") -> #DIV/0!
B22: *Reportar el resultado al 0.1% mas cercano, excepto cuando el resultado sea mayor a 10%, entonces reportar al entero mas cercano.

Sheet Incertidumbre
B1: INFORME DE ESTIMACIÓN DE INCERTIDUMBRE | I1: Código: | J1: F-LEM-P-10.01
I2: Versión: | J2: 3
I3: Fecha: | J3: 46146
I4: Página: | J4: 1 de 1
A6: Método: | B6: Standard Test Method for Materials Finer than 75-µm (No. 200) Sieve in Mineral Aggregates by Washing
A7: Norma: | B7: ASTM C117-23
A8: Matriz: | B8: Agregado
A9: Mensurando: | B9: Material que pasa el tamiz de 75-µm (No. 200) en agregados mediante lavado
A11: Paso 1. Definición del proceso de medición
A13: Variables: | G13: Fórmula:
A15: A = porcentaje de material más fino que un tamiz de 75 μm (No. 200) por lavado
A16: B = masa seca original de la muestra, g
A17: C = masa seca de la muestra después del lavado, g
A19: Equipos a utilizar:
A21: Balanza con resolución de lectura de 0.1g
A23: Paso 2. Definición de las variables aleatorias
A32: CALCULOS
A33: Fuentes | B33: Valor | C33: Incertidumbre Original | D33: Unidades | E33: Distribución | F33: Incertidumbre Estándar u(xi) | G33: Coeficiente de Sensibilidad | H33: Contribución ui(y)
A34: Malla No. 200 (%) | B34: =+(B35-B39)/B35*100 -> #DIV/0! | C34: --- | D34: --- | E34: --- | F34: --- | G34: --- | H34: ---
A35: Masa seca | B35: =+Balanza!G27 -> 0 | C35: --- | D35: g | E35: --- | F35: =SQRT((F36*F36)+(F37*F37)+(F38*F38)) -> 0.070663522 | G35: =100*B39/B35/B35 -> #DIV/0! | H35: =G35*F35 -> #DIV/0! | I35: B
A36: Repetibilidad de la pesada | C36: =Balanza!H27 -> 0 | D36: g | E36: Normal, K=1 | F36: =C36 -> 0 | G36: --- | H36: ---
A37: Certificado de Calibración | C37: =2*(SQRT(Balanza!$C$8+Balanza!$D$8*(POWER(B35,2)))) -> 0.12899612 | D37: g | E37: Normal, K=2 | F37: =C37/2 -> 0.064498062 | G37: --- | H37: ---
A38: Resolución | C38: =Balanza!$C$10 -> 0.1 | D38: g | E38: Rectangular | F38: =C38/SQRT(3)/2 -> 0.028867513 | G38: --- | H38: ---
A39: Masa lavado seca | B39: =+Balanza!G28 -> 0 | D39: g | E39: --- | F39: =SQRT((F40*F40)+(F41*F41)+(F42*F42)) -> 0.070663522 | G39: =100/B35 -> #DIV/0! | H39: =+G39*F39 -> #DIV/0! | I39: C
A40: Repetibilidad de la pesada | C40: =Balanza!H28 -> 0 | D40: g | E40: Normal, K=1 | F40: =C40 -> 0 | G40: --- | H40: ---
A41: Certificado de Calibración | C41: =2*(SQRT(Balanza!$C$8+Balanza!$D$8*(POWER(B39,2)))) -> 0.12899612 | D41: g | E41: Normal, K=2 | F41: =C41/2 -> 0.064498062 | G41: --- | H41: ---
A42: Resolución | C42: =Balanza!$C$10 -> 0.1 | D42: g | E42: Rectangular | F42: =C42/SQRT(3)/2 -> 0.028867513 | G42: --- | H42: ---
A43: factor de presición | B43: =+Precision!B21 -> 0.13703203 | E43: Norma, K=1 | F43: =B43/SQRT(1) -> 0.13703203 | G43: 1 | H43: =+G43*F43 -> 0.13703203
A44: Incertidumbre Estándar Combinada | D44: % | F44: =SQRT((H35*H35)+(H39*H39)+(H43*H43)) -> #DIV/0!
A45: Incertidumbre Expandida, K = 2 | D45: % | F45: =F44*2 -> #DIV/0!
B48: Factor de Influencia | C48: Valor | D48: %
B49: =A35 -> Masa seca | C49: =H35 -> #DIV/0! | D49: =+C49/$C$52*100 -> #DIV/0!
B50: =A39 -> Masa lavado seca | C50: =H39 -> #DIV/0! | D50: =+C50/$C$52*100 -> #DIV/0!
B51: =A43 -> factor de presición | C51: =H43 -> 0.13703203 | D51: =+C51/$C$52*100 -> #DIV/0!
C52: =SUM(C49:C51) -> #DIV/0! | D52: =+C52/$C$52*100 -> #DIV/0!
A58: REVISADO POR: | B58: FABIAN LA ROSA | E58: APROBADO POR: | G58: IRMA COAQUIRA
A60: FECHA DE REVISIÓN: | B60: 44944 | E60: FECHA DE APROBACIÓN: | G60: 44944

Sheet Balanza
B5: CALIBRACION DE LA BALANZA
B7: Correccion | C7: -3.29e-06
B8: Variables | C8: 0.00416 | D8: 2.43e-10
B9: Ecuacion | C9: 2*RAIZ(0.00416+0.000000000243*R2)
B10: Resolucion | C10: 0.1
B11: Codigo | C11: EQP-0046
B12: Calibración | C12: 46132
B14: ITEM | C14: MES | D14: 20 | E14: 200 | F14: 500 | G14: 1000 | H14: 5000 | I14: 10000
C18: DESV STD | D18: 0 | E18: 0 | F18: 0 | G18: 0 | H18: 0 | I18: 0
D20: Busqueda de Repetibilidad de la masa
D22: =+D14 -> 20 | E22: =+E14 -> 200 | F22: =+F14 -> 500 | G22: =+G14 -> 1000 | H22: =+H14 -> 5000 | I22: =+I14 -> 10000
D23: =D18 -> 0 | E23: =E18 -> 0 | F23: =F18 -> 0 | G23: =G18 -> 0 | H23: =H18 -> 0 | I23: =I18 -> 0
D25: DATOS DEL ENSAYO
F27: Masa de la muestra seca constante(g) | G27: =ABS('DATOS ENS'!H14) -> 0 | H27: =IF(AND(G27<=$I$22,G27>$H$22),$I$23,IF(AND(G27<=$H$22,G27>$G$22),$H$23,IF(AND(G27<=$G$22,G27>$F$22),$G$23,IF(AND(G27<=$F$22,G27>$E$22),$F$23,IF(AND(G27<=$E$22,G27>$D$22),$E$23,IF(G27<=$D$22,$D$23)))))) -> 0
F28: Masa de la muestra lavada y seca constante(g) | G28: =+'DATOS ENS'!H17 -> 0 | H28: =IF(AND(G28<=$I$22,G28>$H$22),$I$23,IF(AND(G28<=$H$22,G28>$G$22),$H$23,IF(AND(G28<=$G$22,G28>$F$22),$G$23,IF(AND(G28<=$F$22,G28>$E$22),$F$23,IF(AND(G28<=$E$22,G28>$D$22),$E$23,IF(G28<=$D$22,$D$23)))))) -> 0

Sheet Precision
A4: FACTOR DE PRECISION DEL OPERADOR
A6: Fecha de evaluacion: | B6: 46112
A8: 1-Calcular la Incertidumbre estandar bajo condiciones de reproducibilidad Malla No. 200
A10: T1 | B10: =+#REF!*#REF!+#REF!*#REF! -> #REF!
A11: T2 | B11: =+#REF!*POWER(#REF!,2)+#REF!*POWER(#REF!,2) -> #REF!
A12: T3 | B12: =+SUM(#REF!) -> #REF!
A13: T4 | B13: =+POWER(#REF!,2)+POWER(#REF!,2) -> #REF!
A14: T5 | B14: =(#REF!-1)*SUM(#REF!) -> #REF!
A15: Varianza Repetibilidad (Sr2 ) | B15: =ABS((B14/(B12-#REF!))) -> #REF!
A16: Varianza entre Laboratorios (SL2) | B16: =ABS((((B11*B12-(B10^2))/(B12*(#REF!-1)))-(B15))*((B12*(#REF!-1))/((B12^2)-B13))) -> #REF!
A17: Varianza Reproducibilidad (SR2) | B17: =(B15+B16)/1000000 -> #REF!
A18: Desviacion Estándar Repetibilidad (Sr) | B18: =SQRT(B15) -> #REF!
A19: Desviacion Estándar Reproducibilidad (SR) | B19: =+SQRT(B15+B16) -> #REF!
A21: Desviacion Estándar Repetibilidad (Sr) | B21: 0.13703203
A22: Desviacion Estándar Reproducibilidad (SR) | B22: 0.14388782

Sheet CHATAS
B9: PARTICULAS CHATAS Y ALARGADAS EN AGREGADO GRUESO
B10: MTC E221 - ASTM D 4791-89
B12: Estructura | C12: =+Gran!C13 -> Grava para concreto | H12: HECHO POR : | I12: =+Gran!H14 -> 0
B13: Muestra | C13: Planta | H13: REVISADO : | I13: =+Gran!#REF! -> #REF!
B15: Fecha | C15: =+Gran!#REF! -> #REF!
B20: TAMIZ | D20: TOTALES | F20: PARTICULAS CHATAS | H20: PARTICULAS ALARGADAS
B21: PASA | C21: RETIENE
D22: Nº | E22: PESO | F22: Nº | G22: PESO | H22: Nº | I22: PESO
D23: PIEZAS | E23: grs. | F23: PIEZAS | G23: grs. | H23: PIEZAS | I23: grs.
B24: 2 1/2" | C24: 2"
B25: 2" | C25: 1 1/2"
B26: 1 1/2" | C26: 1" | E26: 2000 | G26: 0 | I26: 0
B27: 1" | C27: 3/4" | E27: 1500 | G27: 0 | I27: 0
B28: 3/4" | C28: 1/2" | E28: 1200 | G28: 32.5 | I28: 0
B29: 1/2" | C29: 3/8" | E29: 500 | G29: 23 | I29: 27.5
B30: 3/8" | C30: 1/4" | E30: 300 | G30: 17 | I30: 18
B31: TOTALES | E31: =SUM(E24:E30) -> 5500 | G31: =SUM(G24:G30) -> 72.5 | I31: =SUM(I24:I30) -> 45.5
B33: CONTENIDO | C33: % | F33: =G31/E31*100 -> 1.3181818 | H33: =I31/E31*100 -> 0.82727273
B36: TOTAL DE PARTICULAS CHATAS Y ALARGADAS | F36: = | G36: =F33+H33 -> 2.1454545 | H36: %
B38: ESPECIFICACION DE OBRA (Máximo) | F38: = | G38: 15 | H38: %
B41: OBSERVACIONES:

Sheet Sucs
A1: esa | B1: SISTEMA UNIFICADO DE CLASIFICACION
B3: N 200= | C3: =ROUND(Gran!I41,2) -> 0 | D3: Cu = | E3: =+Gran!T56 -> --- | K3: L.L. | L3: =+IF(N_10="NP",0,N_10) -> 0
B4: N 4= | C4: =IF(Gran!I33="",100,ROUND(Gran!I33,2)) -> 4.54 | D4: Cc = | E4: =+Gran!T59 -> --- | F4: CLASIFICACION SUCS | G4: =+Q9 -> GP | K4: I.P. | L4: =+IF(C6="NP",0,C6) -> 0
B5: L.L.= | C5: =IF(Gran!G45="NP","NP",ROUND(Gran!G45,2)) -> NP | K5: CU | L5: =IF(OR(E3="----",E3=""),0,E3) -> ---
B6: I.P.= | C6: =IF(Gran!G46="NP","NP",ROUND(Gran!G46,2)) -> NP | K6: CC | L6: =IF(OR(E4="----",E4=""),0,E4) -> ---
B8: DIVISIONES MAYORES | E8: SIMBOLO DE GRUPO | F8: NOMBRES TIPICOS | G8: CRITERIOS DE CLASIFICACION PARA SUELOS GRANULARES | L8: CLASIF | M8: SIMBOLOS DOBLES | O8: SIMBOLOS TRIPLES | P8: CLASIFICACION | Q8: SIMBOLO
B9: Suelos de grano grueso (mas del 50 % del material es mayor en tamaño que el tamiz No 200 | C9: Gravas (mas de la mitad de la fracción gruesa es mayor que el tamiz No 4) | D9: Gravas Limpias (poco o ningun fino) | E9: GW | F9: Gravas bien gradadas, mezclas gravosas, poco o ningun fino | G9: Cu > 4 1 < Cc < 3 | L9: =IF(AND(N_200<50,(100-N_40)>=0.5*(100-N_200),N_200<5,CU>=4,CC>=1,CC<=3),"GW","") | M9: =IF(AND(N_200<50,(100-N_40)>=0.5*(100-N_200),N_200>=5,CU>=4,CC>=1,CC<=3,N_200<12,IP>=7,IP>=0.73*(Ll-20)),"GW-GC","") | N9: =IF(AND(N_200<50,(100-N_40)>=0.5*(100-N_200),N_200>=5,CU>=4,CC>=1,CC<=3,N_200<12,OR(IP<4,IP<0.73*(Ll-20))),"GW-GM","") | O9: =IF(AND(N_200<50,(100-N_40)>=0.5*(100-N_200),N_200>=5,CU>=4,CC>=1,CC<=3,N_200<12,IP>=4,IP<7,IP<0.9*(Ll-8),IP>=0.73*(Ll-20)),"GW-GC-GM","") | P9: =+L9&M9&N9&O9 | Q9: =+P9&P10&P11&P12&P13&P14&P15&P16&P17&P18&P19&P20&P21&P22&P23&P24 -> GP
E10: GP | F10: Gravas pobremente gradadas,`mezclas grava-arena, pocos o ningun fino | G10: No cumple todos los requisitos de gradadcion para GW | L10: =IF(AND(N_200<50,(100-N_40)>=0.5*(100-N_200),N_200<5,OR(CU<4,CC<1,CC>3)),"GP","") -> GP | M10: =IF(AND(N_200<50,(100-N_40)>=0.5*(100-N_200),N_200>=5,OR(CU<4,CC<1,CC>3),N_200<12,IP>=7,IP>=0.73*(Ll-20)),"GP-GC","") | N10: =IF(AND(N_200<50,(100-N_40)>=0.5*(100-N_200),N_200>=5,OR(CU<4,CC<1,CC>3),N_200<12,OR(IP<4,IP<0.73*(Ll-20))),"GP-GM","") | O10: =IF(AND(N_200<50,(100-N_40)>=0.5*(100-N_200),N_200>=5,OR(CU<4,CC<1,CC>3),N_200<12,IP>=4,IP<7,IP<0.9*(Ll-8),IP>=0.73*(Ll-20)),"GP-GC-GM","") | P10: =+L10&M10&N10&O10 -> GP
D11: Gravas con finos (cantidad apre- ciable de finos) | E11: GM | F11: Gravas limosas, mezcla grava- arena-limo | G11: Límites de Atteberg por debajo de la linea A o Ip < 4 | H11: A los materiales sobre la linea A con 4 < Ip < 7 se considera de frontera y se les asigna doble símbolo | L11: =IF(AND(N_200<50,(100-N_40)>=0.5*(100-N_200),N_200>=12,OR(IP<4,IP<0.73*(Ll-20))),"GM","") | M11: =IF(AND(N_200<50,(100-N_40)>=0.5*(100-N_200),N_200>=12,IP>=4,IP<7,IP>=0.73*(Ll-20)),"GC-GM","") | P11: =+L11&M11&N11&O11
E12: GC | F12: Gravas arcillosas, mezcla gravo-areno- arcillosas | G12: Límites de Atteberg por encima de la línea A ó Ip > 7 | L12: =IF(AND(N_200<50,(100-N_40)>=0.5*(100-N_200),N_200>=12,IP>=7,IP>=0.73*(Ll-20)),"GC","") | P12: =+L12&M12&N12&O12
C13: Arenas (mas de la mitad de la fracción gruesa es menor que el tamiz No 4) | D13: Arenas Limpias (poco o ningun fino) | E13: SW | F13: Arenas bien gradadas, arenas gravosas, pocos o ningun fino | G13: Cu > 6 1 < Cc < 3 | L13: =IF(AND(N_200<50,(100-N_40)<0.5*(100-N_200),N_200<5,CU>=6,CC>=1,CC<=3),"SW","") | M13: =IF(AND(N_200<50,(100-N_40)<0.5*(100-N_200),N_200>=5,CU>=6,CC>=1,CC<=3,N_200<12,IP>=7,IP>=0.73*(Ll-20)),"SW-SC","") | N13: =IF(AND(N_200<50,(100-N_40)<0.5*(100-N_200),N_200>=5,CU>=6,CC>=1,CC<=3,N_200<12,OR(IP<4,IP<0.73*(Ll-20))),"SW-SM","") | O13: =IF(AND(N_200<50,(100-N_40)<0.5*(100-N_200),N_200>=5,CU>=6,CC>=1,CC<=3,N_200<12,IP>=4,IP<7,IP<0.9*(Ll-8),IP>=0.73*(Ll-20)),"SW-SC-SM","") | P13: =+L13&M13&N13&O13
E14: SP | F14: Arenas pobremente gradadas, arenas gravosas, pocos o ningun fino | G14: No cumple todos los requisitos de gradadcion para SW | L14: =IF(AND(N_200<50,(100-N_40)<0.5*(100-N_200),N_200<5,OR(CU<6,CC<1,CC>3)),"SP","") | M14: =IF(AND(N_200<50,(100-N_40)<0.5*(100-N_200),N_200>=5,OR(CU<6,CC<1,CC>3),N_200<12,IP>=7,IP>=0.73*(Ll-20)),"SP-SC","") | N14: =IF(AND(N_200<50,(100-N_40)<0.5*(100-N_200),N_200>=5,OR(CU<6,CC<1,CC>3),N_200<12,OR(IP<4,IP<0.73*(Ll-20))),"SP-SM","") | O14: =IF(AND(N_200<50,(100-N_40)<0.5*(100-N_200),N_200>=5,OR(CU<6,CC<1,CC>3),N_200<12,IP>=4,IP<7,IP<0.9*(Ll-8),IP>=0.73*(Ll-20)),"SP-SC-SM","") | P14: =+L14&M14&N14&O14
D15: Arenas con finos (cantidad apre- ciable de finos) | E15: SM | F15: Arenas limosas mezcla de arena-limo | G15: Límites de Atteberg por debajo de la linea A ó Ip < 4 | H15: Si el material está en la zona sombreada con 4 < Ip < 7 se considera de frontera y se les asigna doble símbolo | L15: =IF(AND(N_200<50,(100-N_40)<0.5*(100-N_200),N_200>=12,OR(IP<4,IP<0.73*(Ll-20))),"SM","") | M15: =IF(AND(N_200<50,(100-N_40)<0.5*(100-N_200),N_200>=12,IP>=4,IP<7,IP>=0.73*(Ll-20)),"SC-SM","") | P15: =+L15&M15&N15&O15
E16: SC | F16: Arenas arcillosas, mezclas arena-arcilla | G16: Límites de Atteberg por encima de la linea A ó Ip > 7 | L16: =IF(AND(N_200<50,(100-N_40)<0.5*(100-N_200),N_200>=12,IP>=7,IP>=0.73*(Ll-20)),"SC","") | P16: =+L16&M16&N16&O16
B17: Suelos de grano fino (mas del 50 % del material pasa el tamiz No 200 | C17: limos y arcillas (Límite líquido wl<50 | E17: ML | F17: Limos inorgánicos y arena muy finas, polvo de roca, arenas finas limosas o arcillosas, o limos arcillosos con poca plasticidad | G17: 1, Determinar el porcentaje de arenas y gravas de la curva granulometrica. 2, Dependiendo del porcentaje de fino (fracción menor que el tamiz No 200 los suelos gruesos se clasifican como sigue: Menos del 5% - GW, GP, SW, SP Mas del 12 % - GM, GC, SM, SC De 5 a 12 % - casos frontera que requieren doble símbolo | L17: =IF(AND(N_200>=50,Ll<50,OR(IP<4,AND(IP<0.73*(Ll-20),IP<10))),"ML","") | P17: =+L17&M17&N17&O17
E18: CL | F18: Arcillas inorganicas de plasticidad baja a media, arcillas gravosas, arcillas arenosas, arcillas limosas, arcillas magras. | L18: =IF(AND(N_200>=50,Ll<50,IP>=7,IP>=0.73*(Ll-20)),"CL","") | P18: =+L18&M18&N18&O18
E19: OL | F19: Limos organicos, arcillas limosas orgánicas de baja plasticidad | L19: =IF(AND(N_200>=50,Ll<50,IP>=10,IP<0.73*(Ll-20)),"OL","") | P19: =+L19&M19&N19&O19
C20: limos y arcillas (Límite líquido wl>50 | E20: MH | F20: Limos inorganicos, suelos limosos o arenosos finos micaceos o diatomaceos, suelos elasticos. | L20: =IF(AND(N_200>=50,Ll>=50,IP>0,IP<=16),"MH","") | P20: =+L20&M20&N20&O20
E21: CH | F21: Arcillas organicas de alta plasticidad, arcillas grasas. | L21: =IF(AND(N_200>=50,Ll>=50,IP>=0.73*(Ll-20)),"CH","") | P21: =+L21&M21&N21&O21
E22: OH | F22: Arcillas organicas de plasticidad media a alta, limos orgánicos | L22: =IF(AND(N_200>=50,Ll>=50,IP>16,IP<0.73*(Ll-20)),"OH","") | P22: =+L22&M22&N22&O22
C23: Suelos Altamen- te orgá- nicos | E23: Pt | F23: Turba o otros suelos altamente organicos | L23: =IF(AND(N_200>=50,IP>=0.73*(Ll-20),IP>=4,IP<7,IP<0.9*(Ll-8)),"CL-ML","") | P23: =+L23&M23&N23&O23
P24: =+L24&M24&N24&O24

Sheet Aashto
B4: CLASIFICACION GENERAL | D4: MATERIALES GRANULARES (35% O MENOS DEL TOTAL PASA EL TAMIZ NO 200) | K4: MATERIALES LIMO-ARCILLOSOS (MAS DEL 35% DEL TOTAL PASA EL TAMIZ No 200)
B5: CLASIFICACION DE GRUPO | D5: A-1 | F5: A-3 | G5: A-2 | K5: A-4 | L5: A-5 | M5: A-6 | N5: A-7
D6: A-1-a | E6: A-1-b | G6: A-2-4 | H6: A-2-5 | I6: A-2-6 | J6: A-2-7 | N6: A-7-5 | O6: A-7-6
B8: Porcentaje de material
B9: que pasa el tamiz
B11: No 10 | C11: =+IF(Gran!I34="",100,ROUND(Gran!I34,1)) -> 2 | D11: 50 max
B12: No 40 | C12: =+IF(Gran!I37="",100,ROUND(Gran!I37,1)) -> 100 | D12: 30 max | E12: 50 max | F12: 51 min
B13: No 200 | C13: =ROUND(Gran!I41,1) -> 0 | D13: 15 max | E13: 25 max | F13: 10 max | G13: 35 max | H13: 35 max | I13: 35 max | J13: 35 max | K13: 36 min | L13: 36 min | M13: 36 min | N13: 36 min | O13: 36 min
B16: Caracteristicas de la
B17: fraccion que pasa el
B18: tamiz No 40
B20: Limite líquido | C20: =IF(Gran!G45="NP","NP",ROUND(Gran!G45,1)) -> NP | G20: 40 max | H20: 41 min | I20: 40 max | J20: 41 min | K20: 40 max | L20: 41 min | M20: 40 max | N20: 41 min | O20: 41 min
B21: Indice plástico | C21: =IF(Gran!G46="NP","NP",ROUND(Gran!G46,1)) -> NP | D21: 6 max | E21: 6 max | F21: N.P. | G21: 10 max | H21: 10 max | I21: 11 min | J21: 11 min | K21: 10 max | L21: 10 max | M21: 11 min | N21: 11`min | O21: 11`min
B23: Indice de Grupo | C23: =+D38 -> 0 | D23: 0 | F23: 0 | G23: 0 | I23: 4 max | K23: 8 max | L23: 12 max | M23: 16 max | N23: 20 max | O23: 20 max
E26: CLASIFICACION AASHTO : | J26: =+D31&" "&F38 -> A-3 (0)
D29: =IF(AND(C11<=50,C12<=30,C13<=15,OR(C21<=6,C21="NP"),C23<=0),D6,"--") -> -- | E29: =IF(AND(C12<=50,C13<=25,OR(C21<=6,C21="NP"),C23<=0),E6,"--") -> -- | F29: =IF(AND(C12>50,C13<=10,OR(C20="N.P.",C20="NP",C20=0),OR(C21="N.P.",C21="NP",C21=0),C23<=0),F5,"--") -> A-3 | G29: =IF(AND(C13<=35,OR(C20<=40,C20="NP"),OR(C21<=10,C21="NP"),C23<=0),G6,"--") -> A-2-4 | H29: =IF(AND(C13<=35,C20>40,C20<>"NP",C21<=10,C21<>"NP",C23<=0),H6,"--") -> -- | I29: =IF(AND(C13<=35,C20<=40,C20<>"NP",C23<=4,C21>10,C21<>"NP"),I6,"--") -> -- | J29: =IF(AND(C13<=35,C20>40,C20<>"NP",C21>10,C23<=4,C21<>"NP"),J6,"--") -> -- | K29: =IF(AND(C13>35,OR(C20<=40,C20="NP"),OR(C21<=10,C21="NP"),C23<=8),K5,"--") -> -- | L29: =IF(AND(C13>35,C20>40,C20<>"NP",C21<=10,C21<>"NP",C23<=12),L5,"--") -> -- | M29: =IF(AND(C13>35,C20<=40,C21>10,C23<=16,C21<>"NP"),M5,"--") -> -- | N29: =IF(AND(C13>35,C20<>"NP",C20>40,C21<>"NP",C21>10,C23<=20),IF(C20-C21>30,N6,"--"),"--") -> -- | O29: =IF(AND(C13>35,C20>40,C20<>"NP",C21>10,C21<>"NP",C23<=20),IF(C20-C21<=30,O6,"--"),"--") -> --
D30: =IF(D29<>"--",D29,"") | E30: =IF(AND(D29="--",E29<>"--"),E29,"") | F30: =IF(AND(D29="--",E29="--",F29<>"--"),F29,"") -> A-3 | G30: =IF(AND(D29="--",E29="--",F29="--",G29<>"--"),G29,"") | H30: =IF(AND(D29="--",E29="--",F29="--",G29="--",H29<>"--"),H29,"") | I30: =IF(AND(D29="--",E29="--",F29="--",G29="--",H29="--",I29<>"--"),I29,"") | J30: =IF(AND(D29="--",E29="--",F29="--",G29="--",H29="--",I29="--",J29<>"--"),J29,"") | K30: =IF(K29<>"--",K29,"") | L30: =IF(AND(K29="--",L29<>"--"),L29,"") | M30: =IF(AND(K29="--",L29="--",M29<>"--"),M29,"") | N30: =IF(AND(K29="--",L29="--",M29="--",N29<>"--"),N29,"") | O30: =IF(AND(K29="--",L29="--",M29="--",N29="--",O29<>"--"),O29,"")
D31: =+D30&E30&F30&G30&H30&I30&J30&K30&L30&M30&N30&O30 -> A-3
C33: A | D33: =+IF(C13>75,40,IF(C13<35,1,IF(C13<40,40-C13,C13-40))) -> 1
C34: B | D34: =+IF(C13>55,40,IF(C13<15,1,C13-15)) -> 1
C35: C | D35: =+IF(C20="NP",1,IF(C20>60,20,IF(C20<40,1,C20-40))) -> 1
C36: D | D36: =+IF(C21="NP",1,IF(C21>30,20,IF(C21<10,1,C21-10))) -> 1
C38: =0.2*D33+0.005*D33*D35+0.01*D34*D36 -> 0.215 | D38: =ROUND(C38,0) -> 0 | F38: =+"("&D38&")" -> (0)

Sheet Apoyo 2
A1: =+D1 -> 76.2 | B1: 0 | C1: 3" | D1: 76.2 | E1: 0 | F1: 100 | G1: =+Gran!F24 -> 0 | H1: =+G1/Gran!$D$18*100 -> 0 | I1: =+H1 -> 0 | J1: =100-I1 -> 100 | L1: ESPECIFICACIONES
A2: =+A1 -> 76.2 | B2: 100 | C2: 2 1/2" | D2: 63.5 | E2: 0 | F2: 100 | G2: =+Gran!F25 -> 0 | H2: =+G2/Gran!$D$18*100 -> 0 | I2: =+H2+I1 -> 0 | J2: =100-I2 -> 100 | L2: Nº Malla | M2: Abertura mm. | N2: Especificaciones "B" | P2: % Que Pasa
C3: 2" | D3: 50.6 | E3: 0 | F3: 100 | G3: =+Gran!F26 -> 0 | H3: =+G3/Gran!$D$18*100 -> 0 | I3: =+H3+I2 -> 0 | J3: =100-I3 -> 100 | L3: =+C3 -> 2" | M3: =+D3 -> 50.6 | N3: =+Gran!K26 -> 100 | O3: =+Gran!K26 -> 100 | P3: =+J3 -> 100
A4: =+D2 -> 63.5 | B4: 0 | C4: 1 1/2" | D4: 38.1 | E4: 0 | F4: 100 | G4: =+Gran!F27 -> 0 | H4: =+G4/Gran!$D$18*100 -> 0 | I4: =+H4+I3 -> 0 | J4: =100-I4 -> 100 | L4: =+C4 -> 1 1/2" | M4: =+D4 -> 38.1 | N4: =+Gran!J27 -> 95 | O4: =+Gran!L27 -> 100 | P4: =+J4 -> 100
A5: =+A4 -> 63.5 | B5: 100 | C5: 1" | D5: 25.4 | E5: 0 | F5: 100 | G5: =+Gran!F28 -> 0 | H5: =+G5/Gran!$D$18*100 -> 0 | I5: =+H5+I4 -> 0 | J5: =100-I5 -> 100 | L5: =+C5 -> 1" | M5: =+D5 -> 25.4 | N5: =+Gran!J28 -> 0 | O5: =+Gran!L28 -> 0 | P5: =+J5 -> 100
C6: 3/4" | D6: 19.05 | E6: 0 | F6: 100 | G6: =+Gran!F29 -> 1866 | H6: =+G6/Gran!$D$18*100 -> 23.359163 | I6: =+H6+I5 -> 23.359163 | J6: =100-I6 -> 76.640837 | L6: =+C6 -> 3/4" | M6: =+D6 -> 19.05 | N6: =+Gran!J29 -> 35 | O6: =+Gran!L29 -> 70 | P6: =+J6 -> 76.640837
A7: =+D3 -> 50.6 | B7: 0 | C7: 1/2" | D7: 12.7 | E7: 0 | F7: 100 | G7: =+Gran!F30 -> 2894 | H7: =+G7/Gran!$D$18*100 -> 36.227983 | I7: =+H7+I6 -> 59.587146 | J7: =100-I7 -> 40.412854 | L7: =+C7 -> 1/2" | M7: =+D7 -> 12.7 | N7: =+Gran!J31 -> 10 | O7: =+Gran!L31 -> 30 | P7: =+J7 -> 40.412854
A8: =+A7 -> 50.6 | B8: 100 | C8: 3/8" | D8: 9.525 | E8: 0 | F8: 100 | G8: =+Gran!F31 -> 1632 | H8: =+G8/Gran!$D$18*100 -> 20.429879 | I8: =+H8+I7 -> 80.017025 | J8: =100-I8 -> 19.982975 | L8: =+C8 -> 3/8" | M8: =+D8 -> 9.525 | N8: =+Gran!J33 -> 0 | O8: =+Gran!L33 -> 5 | P8: =+J8 -> 19.982975
C9: 1/4" | D9: 6.35 | E9: 0 | F9: 100 | I9: =+I8 -> 80.017025 | J9: =+(J8+J10)/2 -> 18.781218 | L9: =+C9 -> 1/4" | M9: =+D9 -> 6.35 | N9: =+Gran!J34 -> 0 | O9: =+Gran!L34 -> 0 | P9: =+J9 -> 18.781218
A10: =+D4 -> 38.1 | B10: 0 | C10: No4 | D10: 4.76 | E10: 0 | F10: 100 | G10: =+Gran!F33 -> 192 | H10: =+G10/Gran!$D$18*100 -> 2.4035151 | I10: =+H10+I9 -> 82.42054 | J10: =100-I10 -> 17.57946 | L10: =+C10 -> No4 | M10: =+D10 -> 4.76 | N10: =+Gran!J37 -> 0 | O10: =+Gran!L37 -> 0 | P10: =+J10 -> 17.57946
A11: =+A10 -> 38.1 | B11: 100 | C11: 8 | D11: 2.38 | E11: 0 | F11: 100 | I11: =+I10 -> 82.42054 | J11: =+(J10+J12)/2 -> 16.328255 | L11: =+C11 -> 8 | M11: =+D11 -> 2.38 | N11: =+Gran!J41 -> 0 | O11: =+Gran!L41 -> 0 | P11: =+J11 -> 16.328255
C12: 10 | D12: 2 | E12: 0 | F12: 100 | G12: =+Gran!F34 -> 199.9 | H12: =+G12/Gran!$D$18*100 -> 2.5024098 | I12: =+H12+I11 -> 84.92295 | J12: =100-I12 -> 15.07705 | L12: =+C12 -> 10 | M12: =+D12 -> 2 | P12: =+J12 -> 15.07705
A13: =+D5 -> 25.4 | B13: 0 | C13: 16 | D13: 1.19 | E13: 0 | F13: 100 | I13: =+I12 -> 84.92295 | J13: =+(J12+J14)/2 -> 14.060564 | L13: =+C13 -> 16 | M13: =+D13 -> 1.19 | P13: =+J13 -> 14.060564
A14: =+A13 -> 25.4 | B14: 100 | C14: 20 | D14: 0.84 | E14: 0 | F14: 100 | G14: =+Gran!F35 -> 162.4 | H14: =+G14/Gran!$D$18*100 -> 2.0329732 | I14: =+H14+I13 -> 86.955923 | J14: =100-I14 -> 13.044077 | L14: =+C14 -> 20 | M14: =+D14 -> 0.84 | P14: =+J14 -> 13.044077
C15: 30 | D15: 0.59 | E15: 0 | F15: 100 | I15: =+I14 -> 86.955923 | J15: =+(J14+J16)/2 -> 13.044077 | L15: =+C15 -> 30 | M15: =+D15 -> 0.59 | P15: =+J15 -> 13.044077
A16: =+D6 -> 19.05 | B16: 0 | C16: 40 | D16: 0.42 | E16: 0 | F16: 100 | G16: =+Gran!F37 -> 0 | H16: =+G16/Gran!$D$18*100 -> 0 | I16: =+H16+I15 -> 86.955923 | J16: =100-I16 -> 13.044077 | L16: =+C16 -> 40 | M16: =+D16 -> 0.42 | P16: =+J16 -> 13.044077
A17: =+A16 -> 19.05 | B17: 100 | C17: 50 | D17: 0.3 | E17: 0 | F17: 100 | I17: =+I16 -> 86.955923 | J17: =+(J16+J18)/2 -> 13.044077 | L17: =+C17 -> 50 | M17: =+D17 -> 0.3 | P17: =+J17 -> 13.044077
C18: 60 | D18: 0.25 | E18: 0 | F18: 100 | G18: =+Gran!F38 -> 0 | H18: =+G18/Gran!$D$18*100 -> 0 | I18: =+H18+I17 -> 86.955923 | J18: =100-I18 -> 13.044077 | L18: =+C18 -> 60 | M18: =+D18 -> 0.25 | P18: =+J18 -> 13.044077
A19: =+D7 -> 12.7 | B19: 0 | C19: 80 | D19: 0.18 | E19: 0 | F19: 100 | G19: =Gran!F39 -> 0 | H19: =+G19/Gran!$D$18*100 -> 0 | I19: =+H19+I18 -> 86.955923 | J19: =100-I19 -> 13.044077 | L19: =+C19 -> 80 | M19: =+D19 -> 0.18 | P19: =+J19 -> 13.044077
A20: =+A19 -> 12.7 | B20: 100 | C20: 100 | D20: 0.149 | E20: 0 | F20: 100 | G20: =+Gran!F40 -> 0 | H20: =+G20/Gran!$D$18*100 -> 0 | I20: =+H20+I19 -> 86.955923 | J20: =100-I20 -> 13.044077 | L20: =+C20 -> 100 | M20: =+D20 -> 0.149 | P20: =+J20 -> 13.044077
C21: 200 | D21: 0.074 | E21: 0 | F21: 100 | G21: =+Gran!F41 -> 0 | H21: =+G21/Gran!$D$18*100 -> 0 | I21: =+H21+I20 -> 86.955923 | J21: =100-I21 -> 13.044077 | L21: =+C21 -> 200 | M21: =+D21 -> 0.074 | P21: =+J21 -> 13.044077
A22: =+D8 -> 9.525 | B22: 0 | D22: =+M22 -> #REF! | E22: 0 | F22: 100 | M22: =#REF! -> #REF! | P22: =+#REF! -> #REF!
A23: =+A22 -> 9.525 | B23: 100 | D23: =+M23 -> #REF! | E23: 0 | F23: 100 | M23: =+#REF! -> #REF! | P23: =+#REF! -> #REF!
D24: =+M24 -> #REF! | E24: 0 | F24: 100 | M24: =+#REF! -> #REF! | P24: =+#REF! -> #REF!
A25: =+D9 -> 6.35 | B25: 0 | D25: =+M25 -> #REF! | E25: 0 | F25: 100 | M25: =+#REF! -> #REF! | P25: =+#REF! -> #REF!
A26: =+A25 -> 6.35 | B26: 100 | D26: =+M26 -> #REF! | E26: 0 | F26: 100 | M26: =+#REF! -> #REF! | P26: =+#REF! -> #REF!
D27: =+M27 -> #REF! | E27: 0 | F27: 100 | M27: =+#REF! -> #REF! | P27: =+#REF! -> #REF!
A28: =+D10 -> 4.76 | B28: 0 | D28: =+M28 -> #REF! | E28: 0 | F28: 100 | M28: =+#REF! -> #REF! | P28: =+#REF! -> #REF!
A29: =+A28 -> 4.76 | B29: 100 | D29: =+M29 -> #REF! | E29: 0 | F29: 100 | M29: =+#REF! -> #REF! | P29: =+#REF! -> #REF!
D30: =+M30 -> #REF! | E30: 0 | F30: 100 | M30: =+#REF! -> #REF! | P30: =+#REF! -> #REF!
A31: =+D11 -> 2.38 | B31: 0
A32: =+A31 -> 2.38 | B32: 100
A34: =+D12 -> 2 | B34: 0
A35: =+A34 -> 2 | B35: 100
A37: =+D13 -> 1.19 | B37: 0
A38: =+A37 -> 1.19 | B38: 100
A40: =+D14 -> 0.84 | B40: 0
A41: =+A40 -> 0.84 | B41: 100
A43: =+D15 -> 0.59 | B43: 0
A44: =+A43 -> 0.59 | B44: 100
...

Sheet Sedimentación
A1: CONIRSA S.A.
A6: ANÁLISIS GRANULOMÉTRICO POR MEDIO DEL HIDRÓMETRO (MTC E 109)
A9: Hito | C9: : | D9: =#REF! -> #REF!
A10: Muestra | C10: : | D10: =#REF! -> #REF!
A11: Prof (m.) | C11: : | D11: =#REF! -> #REF!
A12: Fecha | C12: : | D12: =#REF! -> #REF!
A14: Hidrómetro tipo A ó 151-H (gr/cc)
A15: Tiempo (min) | B15: Temp. (ºC) | C15: R | D15: Cm | E15: Ct | F15: R' | G15: P (%) | H15: F | I15: P' (%) | J15: Diametro | K15: Kl | L15: Kj | M15: Kn | N15: Diam Corr.(mm) | O15: Mat. Sedim. (%) | P15: Ta | Q15: Td | R15: Kna | S15: Knd | T15: aa | U15: ad | V15: Kja | W15: Kjd
J16: Equiv.
A17: 1 | B17: 24 | C17: 17.5 | D17: 0.5 | E17: 1.0199 | F17: =+E17-D17+C17 -> 18.0199 | G17: =+F17*$D$31/$D$28*100 -> 17.978936 | H17: =+$D$29/100 -> 0.020329732 | I17: =+H17*G17 -> 0.36550696 | J17: 0.078 | K17: =+(253.85-F17)/461.54 -> 0.51096351 | L17: =+($D$31-T17)*(W17-V17)/(U17-T17)+V17 -> 0.99683527 | M17: =+(B17-P17)*(S17-R17)/(Q17-P17)+R17 -> 0.94762 | N17: =+M17*L17*K17*J17 -> 0.037648017 | O17: =+$D$30-I17 -> -0.36550696 | P17: 23.9 | Q17: 24.4 | R17: 0.9489 | S17: 0.9425 | T17: 0.9933 | U17: 0.9889 | V17: 0.991 | W17: 0.9852
A18: 2 | B18: 24 | C18: 16.5 | D18: 0.5 | E18: 1.0199 | F18: =+E18-D18+C18 -> 17.0199 | G18: =+F18*$D$31/$D$28*100 -> 16.98121 | H18: =+$D$29/100 -> 0.020329732 | I18: =+H18*G18 -> 0.34522344 | J18: 0.055 | K18: =+(253.85-F18)/461.54 -> 0.51313017 | L18: =+($D$31-T18)*(W18-V18)/(U18-T18)+V18 -> 0.99683527 | M18: =+(B18-P18)*(S18-R18)/(Q18-P18)+R18 -> 0.94762 | N18: =+M18*L18*K18*J18 -> 0.026659246 | O18: =+I17-I18 -> 0.020283518 | P18: 23.9 | Q18: 24.4 | R18: 0.9489 | S18: 0.9425 | T18: =+T17 -> 0.9933 | U18: =+U17 -> 0.9889 | V18: =+V17 -> 0.991 | W18: =+W17 -> 0.9852
A19: 5 | B19: 24 | C19: 14.5 | D19: 0.5 | E19: 1.0199 | F19: =+E19-D19+C19 -> 15.0199 | G19: =+F19*$D$31/$D$28*100 -> 14.985756 | H19: =+$D$29/100 -> 0.020329732 | I19: =+H19*G19 -> 0.30465641 | J19: 0.035 | K19: =+(253.85-F19)/461.54 -> 0.51746349 | L19: =+($D$31-T19)*(W19-V19)/(U19-T19)+V19 -> 0.99683527 | M19: =+(B19-P19)*(S19-R19)/(Q19-P19)+R19 -> 0.94783333 | N19: =+M19*L19*K19*J19 -> 0.017112093 | O19: =+I18-I19 -> 0.040567036 | P19: 23.3 | Q19: 23.9 | R19: 0.9553 | S19: 0.9489 | T19: =+T18 -> 0.9933 | U19: =+U18 -> 0.9889 | V19: =+V18 -> 0.991 | W19: =+W18 -> 0.9852
A20: 10 | B20: 24 | C20: 13 | D20: 0.5 | E20: 1.0199 | F20: =+E20-D20+C20 -> 13.5199 | G20: =+F20*$D$31/$D$28*100 -> 13.489166 | H20: =+$D$29/100 -> 0.020329732 | I20: =+H20*G20 -> 0.27423113 | J20: =(J19+J21)/2 -> 0.0275 | K20: =+(253.85-F20)/461.54 -> 0.52071348 | L20: =+($D$31-T20)*(W20-V20)/(U20-T20)+V20 -> 0.99683527 | M20: =+(B20-P20)*(S20-R20)/(Q20-P20)+R20 -> 0.94783333 | N20: =+M20*L20*K20*J20 -> 0.01352966 | O20: =+I19-I20 -> 0.030425277 | P20: 23.3 | Q20: 23.9 | R20: 0.9553 | S20: 0.9489 | T20: =+T19 -> 0.9933 | U20: =+U19 -> 0.9889 | V20: =+V19 -> 0.991 | W20: =+W19 -> 0.9852
A21: 15 | B21: 24 | C21: 13 | D21: 0.5 | E21: 1.0199 | F21: =+E21-D21+C21 -> 13.5199 | G21: =+F21*$D$31/$D$28*100 -> 13.489166 | H21: =+$D$29/100 -> 0.020329732 | I21: =+H21*G21 -> 0.27423113 | J21: 0.02 | K21: =+(253.85-F21)/461.54 -> 0.52071348 | L21: =+($D$31-T21)*(W21-V21)/(U21-T21)+V21 -> 0.99683527 | M21: =+(B21-P21)*(S21-R21)/(Q21-P21)+R21 -> 0.94648 | N21: =+M21*L21*K21*J21 -> 0.0098257035 | O21: =+I20-I21 -> 0 | P21: 22.8 | Q21: 23.3 | R21: 0.9616 | S21: 0.9553 | T21: =+T20 -> 0.9933 | U21: =+U20 -> 0.9889 | V21: =+V20 -> 0.991 | W21: =+W20 -> 0.9852
A22: 30 | B22: 24.5 | C22: 12 | D22: 0.5 | E22: 1.1399 | F22: =+E22-D22+C22 -> 12.6399 | G22: =+F22*$D$31/$D$28*100 -> 12.611166 | H22: =+$D$29/100 -> 0.020329732 | I22: =+H22*G22 -> 0.25638164 | J22: 0.014 | K22: =+(253.85-F22)/461.54 -> 0.52262014 | L22: =+($D$31-T22)*(W22-V22)/(U22-T22)+V22 -> 0.99683527 | M22: =+(B22-P22)*(S22-R22)/(Q22-P22)+R22 -> 0.94018 | N22: =+M22*L22*K22*J22 -> 0.0068572279 | O22: =+I21-I22 -> 0.017849496 | P22: 22.8 | Q22: 23.3 | R22: 0.9616 | S22: 0.9553 | T22: =+T21 -> 0.9933 | U22: =+U21 -> 0.9889 | V22: =+V21 -> 0.991 | W22: =+W21 -> 0.9852
A23: 60 | B23: 24.5 | C23: 11.5 | D23: 0.5 | E23: 1.1399 | F23: =+E23-D23+C23 -> 12.1399 | G23: =+F23*$D$31/$D$28*100 -> 12.112303 | H23: =+$D$29/100 -> 0.020329732 | I23: =+H23*G23 -> 0.24623988 | J23: 0.01 | K23: =+(253.85-F23)/461.54 -> 0.52370347 | L23: =+($D$31-T23)*(W23-V23)/(U23-T23)+V23 -> 0.99683527 | M23: =+(B23-P23)*(S23-R23)/(Q23-P23)+R23 -> 0.93938 | N23: =+M23*L23*K23*J23 -> 0.0049039966 | O23: =+I22-I23 -> 0.010141759 | P23: 21.7 | Q23: 22.2 | R23: 0.9741 | S23: 0.9679 | T23: =+T22 -> 0.9933 | U23: =+U22 -> 0.9889 | V23: =+V22 -> 0.991 | W23: =+W22 -> 0.9852
A24: 240 | B24: 24 | C24: 9.5 | D24: 0.5 | E24: 1.0199 | F24: =+E24-D24+C24 -> 10.0199 | G24: =+F24*$D$31/$D$28*100 -> 9.9971223 | H24: =+$D$29/100 -> 0.020329732 | I24: =+H24*G24 -> 0.20323882 | J24: 0.005 | K24: =+(253.85-F24)/461.54 -> 0.52829679 | L24: =+($D$31-T24)*(W24-V24)/(U24-T24)+V24 -> 0.99683527 | M24: =+(B24-P24)*(S24-R24)/(Q24-P24)+R24 -> 0.94558 | N24: =+M24*L24*K24*J24 -> 0.0024898297 | O24: =+I23-I24 -> 0.043001058 | P24: 21.7 | Q24: 22.2 | R24: 0.9741 | S24: 0.9679 | T24: =+T23 -> 0.9933 | U24: =+U23 -> 0.9889 | V24: =+V23 -> 0.991 | W24: =+W23 -> 0.9852
A25: 1440 | B25: 24 | C25: 8 | D25: 0.5 | E25: 1.0199 | F25: =+E25-D25+C25 -> 8.5199 | G25: =+F25*$D$31/$D$28*100 -> 8.5005322 | H25: =+$D$29/100 -> 0.020329732 | I25: =+H25*G25 -> 0.17281354 | J25: 0.002 | K25: =+(253.85-F25)/461.54 -> 0.53154678 | L25: =+($D$31-T25)*(W25-V25)/(U25-T25)+V25 -> 0.99683527 | M25: =+(B25-P25)*(S25-R25)/(Q25-P25)+R25 -> 0.94434 | N25: =+M25*L25*K25*J25 -> 0.0010007446 | O25: =+I24-I25 -> 0.030425277 | P25: 20.6 | Q25: 21.1 | R25: 0.9865 | S25: 0.9803 | T25: =+T24 -> 0.9933 | U25: =+U24 -> 0.9889 | V25: =+V24 -> 0.991 | W25: =+W24 -> 0.9852
A27: Hora inicio : | D27: 08:16:00 a.m. | F27: Pe de solidos (Gs) : | I27: 2.66 | J27: (MTC E 113)
A28: Pss(gr) : | D28: 100 | F28: Limite Liquido(%) : | I28: =+Gran!G45 -> NP | K28: Limo (0.074mm - 0.005mm) : | N28: =+D30-I23 -> -0.24623988 | O28: %
A29: (%) Pasa Nº10 : | D29: =+Gran!I34 -> 2.0329732 | F29: Limite Plastico(%) : | I29: =+Gran!P30 -> 0 | K29: Arcilla(0.005mm - 0.001mm) : | N29: =+I23-I25 -> 0.073426334 | O29: %
A30: (%) Pasa Nº200 : | D30: =+Gran!I41 -> 0 | F30: Indice plasticidad(%) : | I30: =+Gran!G46 -> NP | K30: Coloide (menor a 0.001mm) : | N30: =+I25 -> 0.17281354 | O30: %
A31: Coefi. "a" : | D31: =0.622641509*I27/(I27-1) -> 0.99772676 | F31: Clasificación SUCS : | I31: =+Gran!D45 -> GP
A54: % pasa Nº200 : | C54: =+D30 -> 0
A55: % pasa 0.005 : | C55: 0.54
A56: % pasa 0.001 : | C56: 0

Sheet H.N
A1: CONIRSA S.A.
A6: HUMEDAD NATURAL (MTC E 108)
A12: =+#REF! -> #REF! | B12: =+#REF! -> #REF!
A13: =+#REF! -> #REF! | B13: =+#REF! -> #REF!
A14: =+#REF! -> #REF! | B14: =+#REF! -> #REF!
A16: =+#REF! -> #REF!
A17: =+#REF! -> #REF! | B17: =+#REF! -> #REF!
A18: =+#REF! -> #REF! | B18: =+#REF! -> #REF!
A19: =+#REF! -> #REF! | B19: =+#REF! -> #REF!
A20: =+#REF! -> #REF! | B20: =+#REF! -> #REF!
A21: DATOS
A23: Nº de Ensayo | C23: 1
A24: Peso de Mat. Humedo + Tara (gr.) | C24: 138.4
A25: Peso de Mat. Seco + Tara (gr.) | C25: 112
A26: Peso de Tara (gr.)
A27: Peso de Agua (gr.) | C27: =+C24-C25 -> 26.4
A28: Peso Mat. Seco (gr.) | C28: =+C25-C26 -> 112
A29: Humedad Natural (%) | C29: =+C27/C28*100 -> 23.571429
A30: Promedio de Humedad (%) | B30: =AVERAGE(B29:D29)/100 -> 0.23571429
A32: OBSERVACIONES:

Sheet Caras Fracturadas
A9: PORCENTAJE DE CARAS FRACTURADAS EN LOS AGREGADOS
A10: MTC E- 210-1999
A11: LABORATORIO MECANICA DE SUELOS, CONCRETOS Y PAVIMENTOS
A12: OBRA | B12: =Gran!C7 -> 0
A13: =Gran!A9 -> Solicitado | B13: =Gran!C9 -> CAME Contratistas y servicios generales S.A. | F13: =+'[11]G-LL'!F9 -> Hecho por : | G13: =+'[11]G-LL'!H9 -> F. L. G
A14: =Gran!A12 -> Cantera | B14: Acopio-Planta | F14: =+'[11]G-LL'!F10 -> Revisado : | G14: =+'[11]G-LL'!H10 -> I. C. L.
A15: =+'[11]G-LL'!A9 -> Certificado | B15: =Gran!#REF! -> #REF! | F15: FECHA | G15: =Gran!#REF! -> #REF!
A17: =Gran!A13 -> Material | B17: =Gran!C13 -> Grava para concreto
A18: =A14 -> Cantera | B18: =B14 -> Acopio-Planta
A19: Cantero | B19: Grupo Olano
A21: Con dos o más Caras fracturadas
A22: Tamaño del Agregado | C22: A | D22: B | E22: C | F22: D | G22: E
A23: Pasa Tamiz | B23: Retenido T. | C23: (g) | D23: (g) | E23: ( B/A)*100) | F23: % Parcial | G23: CxD | H23: Observaciones
A25: 1 1/2" | B25: 1" | C25: =+Gran!F28 -> 0 | D25: 1188 | E25: =+((D25/C25)*100) -> #DIV/0! | F25: =+Gran!G28 -> 0 | G25: =+E25*F25 -> #DIV/0!
A26: 1" | B26: 3/4" | C26: =+Gran!F29 -> 1866 | D26: 3406 | E26: =+((D26/C26)*100) -> 182.52947 | F26: =+Gran!G29 -> 23.359163 | G26: =+E26*F26 -> 4263.7357
A27: 3/4" | B27: 1/2" | C27: =+Gran!F30 -> 2894 | D27: 2080 | E27: =+((D27/C27)*100) -> 71.87284 | F27: =+Gran!G30 -> 36.227983 | G27: =+E27*F27 -> 2603.8081
A28: 1/2" | B28: 3/8" | C28: =+Gran!F31 -> 1632 | D28: 270 | E28: =+((D28/C28)*100) -> 16.544118 | F28: =+Gran!G31 -> 20.429879 | G28: =+E28*F28 -> 337.99432
A29: Total: | C29: =SUM(C25:C28) -> 6392 | F29: =SUM(F25:F28) -> 80.017025 | G29: =SUM(G25:G28) -> #DIV/0!
A31: Porcentaje con dos o más caras fracturadas = | E31: TOTAL E | F31: =+G29/F29 -> #DIV/0! | G31: %
E32: TOTAL D

Sheet Chatas y Alarga.
A1: MINISTERIO DE TRANSPORTE COMUNICACIÓN VIVIENDA Y CONSTRUCCION
A2: PROVIAS NACIONAL
A3: CARRETERA : INTEROCEANICA
A4: TRAMO III : Pte. INAMPARI - IÑAPARI Km. 300+000 AL Km. 714+490
A5: CONTRATISTA : CONCESIONARIA IIRSA SUR
A6: SUPERVISION :
A9: PORCENTAJE DE CHATAS Y ALARGADAS EN LOS AGREGADOS
A10: MTC E- 210-1999
A12: =+#REF! -> #REF! | B12: =+#REF! -> #REF!
A13: =+#REF! -> #REF! | B13: =+#REF! -> #REF!
A14: =+#REF! -> #REF! | B14: =+#REF! -> #REF!
A16: =+#REF! -> #REF! | E16: =+#REF! -> #REF! | F16: =+#REF! -> #REF!
A17: =+#REF! -> #REF! | B17: =+#REF! -> #REF!
A18: =+#REF! -> #REF! | B18: =+#REF! -> #REF!
A19: =+#REF! -> #REF! | B19: =+#REF! -> #REF!
A23: Tamaño del Agregado | C23: A | D23: B | E23: C | F23: D | G23: E
A24: Pasa Tamiz | B24: Retenido T. | C24: (g) | D24: (g) | E24: ( B/A)*100) | F24: % Parcial | G24: CxD | H24: Observaciones
A26: 1 1/2" | B26: 1" | C26: =+Gran!F28 -> 0 | D26: 125 | E26: =+((D26/C26)*100) -> #DIV/0! | F26: =+Gran!G28 -> 0 | G26: =+E26*F26 -> #DIV/0!
A27: 1" | B27: 3/4" | C27: =+Gran!F29 -> 1866 | D27: 164 | E27: =+((D27/C27)*100) -> 8.7888532 | F27: =+Gran!G29 -> 23.359163 | G27: =+E27*F27 -> 205.30025
A28: 3/4" | B28: 1/2" | C28: =+Gran!F30 -> 2894 | D28: 203 | E28: =+((D28/C28)*100) -> 7.0145128 | F28: =+Gran!G30 -> 36.227983 | G28: =+E28*F28 -> 254.12165
A29: 1/2" | B29: 3/8" | C29: =+Gran!F31 -> 1632 | D29: 198 | E29: =+((D29/C29)*100) -> 12.132353 | F29: =+Gran!G31 -> 20.429879 | G29: =+E29*F29 -> 247.8625
A30: Total: | C30: =SUM(C26:C29) -> 6392 | F30: =SUM(F26:F29) -> 80.017025 | G30: =SUM(G26:G29) -> #DIV/0!
A32: Porcentaje de chatas y alargadas = | E32: TOTAL E | F32: =+G30/F30 -> #DIV/0! | G32: %
E33: TOTAL D
