Workbook
Name ___CC2: [1]Sucs!$L$6
Name __CC2: [1]Sucs!$L$6
Name _CC1: [2]Sucs!$L$6
Name _CC2: [1]Sucs!$L$6
Name _CU1: [2]Sucs!$L$5
Name _IP1: [2]Sucs!$L$4
Name _L1: #REF!
Name _L1: #REF!
Name _L1: #REF!
Name _Ll1: [2]Sucs!$L$3
Name _W1: #REF!
Name _W1: #REF!
Name _W1: #REF!
Name Abra: [3]Sucs!$C$3
Name CC: #REF!
Name CC: #REF!
Name CC: #REF!
Name CCf: '[2]Sucs(Fino)'!$L$6
Name CCVB: [4]Sucs!$L$3
Name CM: [5]BGA!$H$9
Name CU: #REF!
Name CU: #REF!
Name CU: #REF!
Name CUf: '[2]Sucs(Fino)'!$L$5
Name hh: #REF!
Name hh: #REF!
Name hh: #REF!
Name IP: #REF!
Name IP: #REF!
Name IP: #REF!
Name IPf: '[2]Sucs(Fino)'!$L$4
Name L: #REF!
Name L: #REF!
Name L: #REF!
Name LIf: '[2]Sucs(Fino)'!$L$3
Name Ll: #REF!
Name Ll: #REF!
Name Ll: #REF!
Name MORA: [5]BGA!$H$13
Name N_10: #REF!
Name N_10: #REF!
Name N_10: #REF!
Name N_101: [2]Sucs!$C$5
Name N_10f: '[2]Sucs(Fino)'!$C$5
Name N_200: #REF!
Name N_200: #REF!
Name N_200: #REF!
Name N_2001: [2]Sucs!$C$3
Name N_200f: '[2]Sucs(Fino)'!$C$3
Name N_40: #REF!
Name N_40: #REF!
Name N_40: #REF!
Name N_401: [2]Sucs!$C$4
Name N_40f: '[2]Sucs(Fino)'!$C$4
Name PC: [4]Sucs!$C$5
Name TABLA: #REF!
Name TABLA: #REF!
Name TABLA: #REF!
Name tipodegranulometria: '[6]G-LL '!$X$2:$X$3
Name tipodegranulometria: '[6]G-LL '!$X$2:$X$3

Sheet INFORME NTP
A7: LABORATORIO DE ENSAYO DE MATERIALES
A8: =+K13 -> 10
A10: CLIENTE | B10: : | C10: METRO
A11: DIRECCION ** | B11: : | C11: LIMA - AV. JAGSKSHD / PONER LA DIRECCION O DIRECCION FISCAL | I11: CÓDIGO | J11: : | K11: F-LEM-P-SU-11.02
A12: PROYECTO ** | B12: : | C12: CONJUNTO RESIDENCIAL SAN BORJA HOMETOWN | I12: N° OT | J12: : | K12: 150
A13: UBICACIÓN ** | B13: : | C13: CA. DURERO CDRA. 4 S/N, ALT. LA CDRA 13 DE LA AV. SAN | I13: N° INFORME. | J13: : | K13: 10
A14: ** Datos proporcionados por el cliente
A15: METODO DE ENSAYO PARA DETERMINAR EL LIMITE LIQUIDO, LIMITE PLASTICO E INDICE DE PLASTICIDAD DE SUELOS
A16: NORMA NTP 339.129 | N16: INGRESAMOS LOS DATOS
A17: DATOS DE LA MUESTRA | N17: Recipiente Nº | O17: 5 | P17: 3 | Q17: 4 | R17: 11 | S17: 10 | T17: Informacion para la Correccion por Certificado de Calibración:
I18: CODIGO DE LA MUESTRA | J18: : | K18: 83 | N18: Nº de Golpes | O18: 34 | P18: 23 | Q18: 14 | T18: Codigo de Balanza al 0.1g | V18: Variable 1
A19: CANTERA / SONDAJE ** | B19: : | C19: C-1 | I19: FECHA DE RECEPCIÓN | J19: : | K19: 43831 | N19: R + Suelo Hum. | O19: 45.75 | P19: 43.9 | Q19: 43.66 | R19: 23.05 | S19: 18.07 | T19: CODIGO | V19: 5.17e-07
A20: N° MUESTRA ** | B20: : | C20: M-1 | I20: FECHA DE EJECUCIÓN | J20: : | K20: 43844 | N20: R + Suelo Seco | O20: 41.37 | P20: 40.03 | Q20: 38.78 | R20: 22.63 | S20: 17.48 | T20: Fecha | U20: 44090
A21: TIPO DE MUESTRA** | B21: : | C21: SUELO | I21: FECHA DE EMISIÓN | J21: : | K21: 43845 | N21: R + Suelo Seco 1 | O21: 41.37 | P21: 40.03 | Q21: 38.78 | R21: 22.63 | S21: 17.48
A22: LUGAR DE ENSAYO | B22: : | C22: Laboratorio de Ensayo de Materiales | N22: Peso Recip. | O22: 22.74 | P22: 24.18 | Q22: 19.97 | R22: 19.31 | S22: 13.01
D24: LIMITE LIQUIDO | G24: LIMITE PLASTICO | N24: CORRECCION | O24: LIMITE LIQUIDO | Q24: SI | R24: LIMITE PLASTICO | T24: SI
A25: Ensayo | D25: =IF($Q$24="NO","",O25) -> 1 | E25: =IF($Q$24="NO","",P25) -> 2 | F25: =IF($Q$24="NO","",Q25) -> 3 | G25: =IF($T$24="NO","",R25) -> 1 | H25: =IF($T$24="NO","",S25) -> 2 | N25: Ensayo | O25: 1 | P25: 2 | Q25: 3 | R25: 1 | S25: 2
A26: Recipiente Nº | D26: =IF($Q$24="NO","",O26) -> 5 | E26: =IF($Q$24="NO","",P26) -> 3 | F26: =IF($Q$24="NO","",Q26) -> 4 | G26: =IF($T$24="NO","",R26) -> 11 | H26: =IF($T$24="NO","",S26) -> 10 | N26: Recipiente Nº | O26: =O17 -> 5 | P26: =P17 -> 3 | Q26: =Q17 -> 4 | R26: =R17 -> 11 | S26: =S17 -> 10
A27: Nº de Golpes | D27: =IF($Q$24="NO","",O27) -> 34 | E27: =IF($Q$24="NO","",P27) -> 23 | F27: =IF($Q$24="NO","",Q27) -> 14 | N27: Nº de Golpes | O27: =O18 -> 34 | P27: =P18 -> 23 | Q27: =Q18 -> 14
A28: Masa del Recipiente + Suelo Humedo | D28: =IF($Q$24="NO","",O28) -> 45.749976 | E28: =IF($Q$24="NO","",P28) -> 43.899977 | F28: =IF($Q$24="NO","",Q28) -> 43.659977 | G28: =IF($T$24="NO","",R28) -> 23.049988 | H28: =IF($T$24="NO","",S28) -> 18.069991 | N28: R + Suelo Hum. | O28: =O19-($V$19*O19) -> 45.749976 | P28: =P19-($V$19*P19) -> 43.899977 | Q28: =Q19-($V$19*Q19) -> 43.659977 | R28: =R19-($V$19*R19) -> 23.049988 | S28: =S19-($V$19*S19) -> 18.069991
A29: Masa del Recipiente + Suelo Seco | D29: =IF($Q$24="NO","",O29) -> 41.369979 | E29: =IF($Q$24="NO","",P29) -> 40.029979 | F29: =IF($Q$24="NO","",Q29) -> 38.77998 | G29: =IF($T$24="NO","",R29) -> 22.629988 | H29: =IF($T$24="NO","",S29) -> 17.479991 | N29: R + Suelo Seco | O29: =O20-($V$19*O20) -> 41.369979 | P29: =P20-($V$19*P20) -> 40.029979 | Q29: =Q20-($V$19*Q20) -> 38.77998 | R29: =R20-($V$19*R20) -> 22.629988 | S29: =S20-($V$19*S20) -> 17.479991
A30: Masa del Recipiente | D30: =IF($Q$24="NO","",O31) -> 22.739988 | E30: =IF($Q$24="NO","",P31) -> 24.179987 | F30: =IF($Q$24="NO","",Q31) -> 19.96999 | G30: =IF($T$24="NO","",R31) -> 19.30999 | H30: =IF($T$24="NO","",S31) -> 13.009993 | N30: R + Suelo Seco 1 | O30: =O21-($V$19*O21) -> 41.369979 | P30: =P21-($V$19*P21) -> 40.029979 | Q30: =Q21-($V$19*Q21) -> 38.77998 | R30: =R21-($V$19*R21) -> 22.629988 | S30: =S21-($V$19*S21) -> 17.479991
A31: Masa del Agua | D31: =IF($Q$24="NO","",O32) -> 4.3799977 | E31: =IF($Q$24="NO","",P32) -> 3.869998 | F31: =IF($Q$24="NO","",Q32) -> 4.8799975 | G31: =IF($T$24="NO","",R32) -> 0.41999978 | H31: =IF($T$24="NO","",S32) -> 0.58999969 | N31: Peso Recip. | O31: =O22-($V$19*O22) -> 22.739988 | P31: =P22-($V$19*P22) -> 24.179987 | Q31: =Q22-($V$19*Q22) -> 19.96999 | R31: =R22-($V$19*R22) -> 19.30999 | S31: =S22-($V$19*S22) -> 13.009993
A32: Masa del Suelo Seco | D32: =IF($Q$24="NO","",O33) -> 18.62999 | E32: =IF($Q$24="NO","",P33) -> 15.849992 | F32: =IF($Q$24="NO","",Q33) -> 18.80999 | G32: =IF($T$24="NO","",R33) -> 3.3199983 | H32: =IF($T$24="NO","",S33) -> 4.4699977 | N32: Peso Agua | O32: =+O28-O30 -> 4.3799977 | P32: =+P28-P30 -> 3.869998 | Q32: =+Q28-Q30 -> 4.8799975 | R32: =+R28-R30 -> 0.41999978 | S32: =+S28-S30 -> 0.58999969
A33: % de Humedad | D33: =IF($Q$24="NO","",O34) -> 23.510467 | E33: =IF($Q$24="NO","",P34) -> 24.416404 | F33: =IF($Q$24="NO","",Q34) -> 25.943647 | G33: =IF($T$24="NO","",R34) -> 12.650602 | H33: =IF($T$24="NO","",S34) -> 13.199105 | N33: Peso S. Seco | O33: =O30-O31 -> 18.62999 | P33: =P30-P31 -> 15.849992 | Q33: =Q30-Q31 -> 18.80999 | R33: =R30-R31 -> 3.3199983 | S33: =S30-S31 -> 4.4699977
N34: % de Humedad | O34: =+O32/O33*100 -> 23.510467 | P34: =+P32/P33*100 -> 24.416404 | Q34: =+Q32/Q33*100 -> 25.943647 | R34: =+R32/R33*100 -> 12.650602 | S34: =+S32/S33*100 -> 13.199105
N35: Golp. | O35: % Humed
G36: Limite Liquido | I36: =+IF(Q24="NO","NP",ROUND(O49,0)) -> 24 | N36: =+D27 -> 34 | O36: =+D33 -> 23.510467
N37: =+E27 -> 23 | O37: =+E33 -> 24.416404
G38: Limite Plástico | I38: =+IF(T24="NO","NP",ROUND(O42,0)) -> 13 | N38: =+F27 -> 14 | O38: =+F33 -> 25.943647
N39: 25 | O39: 0
G40: Índice de Plasticidad | I40: =IF(T24="NO","NP",I36-I38) -> 11 | N40: 25 | O40: =P41 -> 24.315696 | P40: =+D33/(1.419-0.3*LOG10(D27)) -> 24.501393 | Q40: =+F33/(1.419-0.3*LOG10(F27)) -> 24.129998
N41: 10 | O41: =+O40 -> 24.315696 | P41: =+AVERAGE(P40:Q40) -> 24.315696
N42: LP | O42: =AVERAGE(R34:S34) -> 12.924854
A44: Observaciones:
N45: 25 | O45: =LOG10(N45) -> 1.39794
O46: =O18 -> 34 | P46: =P27 -> 23 | Q46: =Q27 -> 14
A47: Página 1 de 2 | N47: LOG GOLPES | O47: =LOG10(N36) -> 1.5314789 | P47: =LOG10(N37) -> 1.3617278 | Q47: =LOG10(N38) -> 1.146128
A48: Versión : 02 (02-01-2021) | N48: Humedad | O48: =O34 -> 23.510467 | P48: =P34 -> 24.416404 | Q48: =Q34 -> 25.943647
N49: Limite Liquido: | O49: =TREND(O48:Q48,O47:Q47,O45) -> 24.296606
...

Sheet FORMATO
P2: CLIENTE
P3: DIRECCIÓN **
P4: PROYECTO **
P5: UBICACIÓN **
A7: LABORATORIO DE ENSAYO DE MATERIALES | P7: RECEPCIÓN N°
A8: FORMATO N° F-LEM-P-SU-23.01 | P8: F. EMISIÓN
P9: OT N°
C10: MUESTRA | E10: No OT | H10: FECHA ENSAYO | J10: REALIZADO
P11: CÓDIGO DE LA MUESTRA
P12: FECHA DE RECEPCIÓN
A13: Standard Test Methods for Liquid Limit, Plastic Limit, and Plasticity Index of Soils | P13: FECHA DE EJECUCIÓN
A14: ASTM D4318-17ε1
P15: CANTERA/SONDAJE **
B16: Condiciones del ensayo | P16: N° MUESTRA **
B17: Método de ensayo en el Límite Líquido | P17: TIPO DE MUESTRA**
B18: Herramienta de ranurado para el límite líquido
B19: Dispositivo para el limite liquido
B20: Método de laminación para el Límite Plástico
B21: Contenido de humedad de muestra inicial (%)
B22: Proceso de selección en caso de muestras Intacta, se retiró lentes de arena
B23: Método de preparación de la muestra de ensayo
B24: Método de eliminación de partículas más grandes que el tamiz No. 40
B25: X | C25: Lavado por el tamiz No. 40 | I25: Mecánicamente empujado a través del tamiz No. 40
C26: Tamizado en seco por el tamiz No. 40 | I26: Mezclado en placa de vidrio y eliminación de partículas de arena medianas
B28: Descripción de la muestra: | O28: LIMITE LIQUIDO
B29: Tipo de muestra | O29: LN(N) | P29: N | Q29: Humedad
B30: Condición de la muestra | O30: =+LN(P30) -> #NUM! | P30: =+G38 -> 0 | Q30: =+G45 -> #DIV/0!
B31: Tamaño máximo de particula, Visual (in) | O31: =+LN(P31) -> #NUM! | P31: =+I38 -> 0 | Q31: =+I45 -> #DIV/0!
B32: Porcentaje estimado de muestra retenido en el tamiz No. 40 (%) | O32: =+LN(P32) -> #NUM! | P32: =+J38 -> 0 | Q32: =+J45 -> #DIV/0!
B33: Forma de la particula | P33: Wpromedio | Q33: =AVERAGE(Q30:Q32) -> #DIV/0!
B35: Descripción | G35: LIMITE LIQUIDO | K35: LIMITE PLASTICO
G36: 1 | I36: 2 | J36: 3 | K36: 1 | L36: 2 | O36: Verificar aquí el grafico Min.095 y Max.1.00
B37: A | C37: Recipiente Nº | O37: =RSQ(Q30:Q32,O30:O32) -> #DIV/0! | P37: =IF(O37<=0.95,"NO CONFORME","CONFORME") -> #DIV/0!
B38: B | C38: Nº de Golpes
B39: C | C39: Masa del recipiente y suelo Humedo | F39: g | O39: LIMITE PLASTICO
B40: D | C40: Masa del recipiente y suelo Seco | F40: g | O40: =+IF(P40>=6,"Cumple","No cumple") -> No cumple | P40: =+K39-K42 -> 0 | Q40: =+IF(R40>=6,"Cumple","No cumple") -> No cumple | R40: =+L39-L42 -> 0
B41: E | C41: Masa del recipiente y suelo Seco 1 | F41: g
B42: F | C42: Masa del Recipiente | F42: g | O42: PARAMETRO DE CONTROL LIMITE PLASTICO
B43: G | C43: Masa del Agua(C-E) | F43: g | G43: =+G39-G41 -> 0 | I43: =+I39-I41 -> 0 | J43: =+J39-J41 -> 0 | K43: =+K39-K41 -> 0 | L43: =+L39-L41 -> 0 | O43: Parametro calculado | Q43: Limites diferencia Norma | S43: Control
B44: H | C44: Masa del Suelo Seco (E-F) | F44: g | G44: =+G41-G42 -> 0 | I44: =+I41-I42 -> 0 | J44: =+J41-J42 -> 0 | K44: =+K41-K42 -> 0 | L44: =+L41-L42 -> 0 | O44: 1S | P44: d2s | Q44: 1S | R44: d2s
...

Sheet INFORME LIMITE
A2: LABORATORIO DE ENSAYO DE MATERIALES | AJ2: SI
A3: 0 | AJ3: NO
A5: CLIENTE | B5: : | C5: =+FORMATO!Q2 -> 0 | L5: CÓDIGO | M5: : | N5: F-LEM-P-SU-23.02
A6: DIRECCIÓN ** | B6: : | C6: =+FORMATO!Q3 -> 0 | L6: RECEPCIÓN N° | M6: : | N6: =+FORMATO!Q7 -> 0
A7: PROYECTO ** | B7: : | C7: =+FORMATO!Q4 -> 0 | L7: OT N° | M7: : | N7: =+FORMATO!Q9 -> 0
A8: UBICACIÓN ** | B8: : | C8: =+FORMATO!Q5 -> 0 | L8: FECHA EMISIÓN | M8: : | N8: =+FORMATO!Q8 -> 0
A9: ** Datos proporcionados por el cliente
A10: Standard Test Methods for Liquid Limit, Plastic Limit and Plasticity Index of Soils
A11: ASTM D4318-17ε1
A13: DATOS DE LA MUESTRA
A14: CANTERA/SONDAJE ** | D14: : | E14: =+FORMATO!Q15 -> 0 | L14: CODIGO DE LA MUESTRA | M14: : | N14: =+FORMATO!C11 -> 0
A15: N° MUESTRA ** | D15: : | E15: =+FORMATO!Q16 -> 0 | L15: FECHA DE RECEPCIÓN | M15: : | N15: =+FORMATO!Q12 -> 0
A16: TIPO DE MUESTRA | D16: : | E16: =+FORMATO!Q17 -> 0 | L16: FECHA DE EJECUCIÓN | M16: : | N16: =+FORMATO!Q13 -> 0 | O16: =+FORMATO!H11 -> 0
A17: LUGAR DE ENSAYO | D17: : | E17: Laboratorio de Ensayo de Materiales
U19: Descripcion | V19: LIMITE LIQUIDO | Y19: LIMITE PLASTICO
A20: DESCRIPCIÓN | F20: und | G20: LÍMITE LÍQUIDO | J20: LÍMITE PLÁSTICO | V20: =+DATOS!C12 -> - | Y20: =+DATOS!I12 -> -
A21: Nº Ensayo | F21: Nº | G21: =IF($V$20="NO",V21,IF($V$20="-","",V21)) | H21: =IF($V$20="NO",W21,IF($V$20="-","",W21)) | I21: =IF($V$20="NO",X21,IF($V$20="-","",X21)) | J21: =IF($Y$20="NO",Y21,IF($Y$20="-","",Y21)) | K21: =IF($Y$20="NO",Z21,IF($Y$20="-","",Z21)) | U21: Ensayo | V21: 1 | W21: 2 | X21: 3 | Y21: 1 | Z21: 2
A22: Nº Recipiente | F22: Nº | G22: =IF($V$20="NO","--",IF($V$20="-","",V22)) | H22: =IF($V$20="NO","--",IF($V$20="-","",W22)) | I22: =IF($V$20="NO","--",IF($V$20="-","",X22)) | J22: =IF($Y$20="NO","--",IF($Y$20="-","",Y22)) | K22: =IF($Y$20="NO","--",IF($Y$20="-","",Z22)) | U22: Recipiente Nº | V22: =+DATOS!D15 -> 0 | W22: =+DATOS!F15 -> 0 | X22: =+DATOS!H15 -> 0 | Y22: =+DATOS!J15 -> 0 | Z22: =+DATOS!L15 -> 0
A23: Nº de Golpes | F23: Nº | G23: =IF($V$20="NO","--",IF($V$20="-","",V23)) | H23: =IF($V$20="NO","--",IF($V$20="-","",W23)) | I23: =IF($V$20="NO","--",IF($V$20="-","",X23)) | U23: Nº de Golpes | V23: =+DATOS!D16 -> 0 | W23: =+DATOS!F16 -> 0 | X23: =+DATOS!H16 -> 0 | Y23: - | Z23: -
A24: Masa del recipiente y suelo Humedo | F24: g | G24: =IF($V$20="NO","--",IF($V$20="-","",V24)) | H24: =IF($V$20="NO","--",IF($V$20="-","",W24)) | I24: =IF($V$20="NO","--",IF($V$20="-","",X24)) | J24: =IF($Y$20="NO","--",IF($Y$20="-","",Y24)) | K24: =IF($Y$20="NO","--",IF($Y$20="-","",Z24)) | U24: R + Suelo Hum. | V24: =+DATOS!D17 -> 0 | W24: =+DATOS!F17 -> 0 | X24: =+DATOS!H17 -> 0 | Y24: =+DATOS!J17 -> 0 | Z24: =+DATOS!L17 -> 0
A25: Masa del recipiente y suelo Seco | F25: g | G25: =IF($V$20="NO","--",IF($V$20="-","",V26)) | H25: =IF($V$20="NO","--",IF($V$20="-","",W26)) | I25: =IF($V$20="NO","--",IF($V$20="-","",X26)) | J25: =IF($Y$20="NO","--",IF($Y$20="-","",Y26)) | K25: =IF($Y$20="NO","--",IF($Y$20="-","",Z26)) | U25: R + Suelo Seco | V25: =+DATOS!D18 -> 0 | W25: =+DATOS!F18 -> 0 | X25: =+DATOS!H18 -> 0 | Y25: =+DATOS!J18 -> 0 | Z25: =+DATOS!L18 -> 0
A26: Masa del Recipiente | F26: g | G26: =IF($V$20="NO","--",IF($V$20="-","",V27)) | H26: =IF($V$20="NO","--",IF($V$20="-","",W27)) | I26: =IF($V$20="NO","--",IF($V$20="-","",X27)) | J26: =IF($Y$20="NO","--",IF($Y$20="-","",Y27)) | K26: =IF($Y$20="NO","--",IF($Y$20="-","",Z27)) | U26: R + Suelo Seco 1 | V26: =+DATOS!D19 -> 0 | W26: =+DATOS!F19 -> 0 | X26: =+DATOS!H19 -> 0 | Y26: =+DATOS!J19 -> 0 | Z26: =+DATOS!L19 -> 0
A27: Masa del Agua | F27: g | G27: =IF($V$20="NO","--",IF($V$20="-","",V28)) | H27: =IF($V$20="NO","--",IF($V$20="-","",W28)) | I27: =IF($V$20="NO","--",IF($V$20="-","",X28)) | J27: =IF($Y$20="NO","--",IF($Y$20="-","",Y28)) | K27: =IF($Y$20="NO","--",IF($Y$20="-","",Z28)) | U27: Peso Recip. | V27: =+DATOS!D20 -> 0 | W27: =+DATOS!F20 -> 0 | X27: =+DATOS!H20 -> 0 | Y27: =+DATOS!J20 -> 0 | Z27: =+DATOS!L20 -> 0
A28: Masa del Suelo Seco | F28: g | G28: =IF($V$20="NO","--",IF($V$20="-","",V29)) | H28: =IF($V$20="NO","--",IF($V$20="-","",W29)) | I28: =IF($V$20="NO","--",IF($V$20="-","",X29)) | J28: =IF($Y$20="NO","--",IF($Y$20="-","",Y29)) | K28: =IF($Y$20="NO","--",IF($Y$20="-","",Z29)) | U28: Peso Agua | V28: =+DATOS!D21 -> 0 | W28: =+DATOS!F21 -> 0 | X28: =+DATOS!H21 -> 0 | Y28: =+DATOS!J21 -> 0 | Z28: =+DATOS!L21 -> 0
A29: Contenido de Humedad | F29: % | G29: =IF($V$20="NO","--",IF($V$20="-","",V30)) | H29: =IF($V$20="NO","--",IF($V$20="-","",W30)) | I29: =IF($V$20="NO","--",IF($V$20="-","",X30)) | J29: =IF($V$20="NO","--",IF($V$20="-","",Y30)) | K29: =IF($V$20="NO","--",IF($V$20="-","",Z30)) | U29: Peso S. Seco | V29: =+DATOS!D22 -> 0 | W29: =+DATOS!F22 -> 0 | X29: =+DATOS!H22 -> 0 | Y29: =+DATOS!J22 -> 0 | Z29: =+DATOS!L22 -> 0
U30: % de Humedad | V30: =+DATOS!D23 -> #DIV/0! | W30: =+DATOS!F23 -> #DIV/0! | X30: =+DATOS!H23 -> #DIV/0! | Y30: =+DATOS!J23 -> #DIV/0! | Z30: =+DATOS!L23 -> #DIV/0!
U31: Promedio | Y31: =AVERAGE(Y30:Z30) -> #DIV/0!
J32: Límite Liquido | L32: =IF(V20="-","",IF(V20="NO","NP",ROUND(V42,0)))
U33: Golp. | V33: % Humed | X33: LN(N) | Y33: N | Z33: Humedad
J34: Límite Plástico | L34: =IF(V20="-","",IF(Y20="NO","NP",ROUND(Y31,0))) | U34: =G23 | V34: =G29 | X34: =+LN(Y34) -> #VALUE! | Y34: =G23 | Z34: =G29
U35: =H23 | V35: =H29 | X35: =+LN(Y35) -> #VALUE! | Y35: =H23 | Z35: =H29
J36: Índice de Plasticidad | L36: =IF(Y20="-","",IF(Y20="NO","NP",L32-L34)) | U36: =I23 | V36: =I29 | X36: =+LN(Y36) -> #VALUE! | Y36: =I23 | Z36: =I29
U37: 25 | V37: 0 | Y37: Wpromedio | Z37: =AVERAGE(Z34:Z36) -> #DIV/0!
U38: 25 | V38: =+Z42 -> #VALUE!
U39: 10 | V39: =+V38 -> #VALUE! | Y39: Pendiente | Z39: =SLOPE(Z34:Z36,X34:X36) -> #VALUE!
Y40: Intercepto | Z40: =INTERCEPT(Z34:Z36,X34:X36) -> #VALUE!
U42: Según grafica | X42: L. L. según ecuacion | Z42: =(Z39*LN(25)+Z40) -> #VALUE!
A45: Página 1 de 2
A46: Versión: 07 (12-06-2026)
A51: Condiciones del ensayo
...

Sheet DATOS
B2: Standard Test Methods for Liquid Limit, Plastic Limit and Plasticity Index of Soils
B3: ASTM D4318-17ε1
B5: Información para la Corrección por Certificado de Calibración: Balanza 2.2kg | H5: OPERADORES
B6: Precisión de la Balanza al 0.01g | H6: - | I6: =+FORMATO!J11 -> 0
B7: Corrección | D7: =+Balanza!B8 -> 3.79e-06
B8: CODIGO | D8: EQP-0045
B9: Fecha | D9: =+Balanza!C13 -> 46132
B11: Descripcion | C11: LIMITE LIQUIDO | I11: LIMITE PLASTICO
C12: - | I12: -
C13: DATOS | D13: CORRECCIÓN | E13: DATOS | F13: CORRECCIÓN | G13: DATOS | H13: CORRECCIÓN | I13: DATOS | J13: CORRECCIÓN | K13: DATOS | L13: CORRECCIÓN
B14: Ensayo | C14: 1 | D14: 1 | E14: 2 | F14: 2 | G14: 3 | H14: 3 | I14: 1 | J14: 1 | K14: 2 | L14: 2
B15: Recipiente Nº | C15: =+FORMATO!G37 -> 0 | D15: =C15 -> 0 | E15: =+FORMATO!I37 -> 0 | F15: =E15 -> 0 | G15: =+FORMATO!J37 -> 0 | H15: =G15 -> 0 | I15: =+FORMATO!K37 -> 0 | J15: =I15 -> 0 | K15: =+FORMATO!L37 -> 0 | L15: =K15 -> 0
B16: Nº de Golpes | C16: =+FORMATO!G38 -> 0 | D16: =C16 -> 0 | E16: =+FORMATO!I38 -> 0 | F16: =E16 -> 0 | G16: =+FORMATO!J38 -> 0 | H16: =G16 -> 0 | I16: - | J16: - | K16: - | L16: -
B17: Masa del recipiente y suelo Humedo | C17: =+FORMATO!G39 -> 0 | D17: =C17+($D$7*C17) -> 0 | E17: =+FORMATO!I39 -> 0 | F17: =E17+($D$7*E17) -> 0 | G17: =+FORMATO!J39 -> 0 | H17: =G17+($D$7*G17) -> 0 | I17: =+FORMATO!K39 -> 0 | J17: =I17+($D$7*I17) -> 0 | K17: =+FORMATO!L39 -> 0 | L17: =K17+($D$7*K17) -> 0
B18: Masa del recipiente y suelo Seco | C18: =+FORMATO!G40 -> 0 | D18: =C18+($D$7*C18) -> 0 | E18: =+FORMATO!I40 -> 0 | F18: =E18+($D$7*E18) -> 0 | G18: =+FORMATO!J40 -> 0 | H18: =G18+($D$7*G18) -> 0 | I18: =+FORMATO!K40 -> 0 | J18: =I18+($D$7*I18) -> 0 | K18: =+FORMATO!L40 -> 0 | L18: =K18+($D$7*K18) -> 0
B19: Masa del recipiente y suelo Seco 1 | C19: =+FORMATO!G41 -> 0 | D19: =C19+($D$7*C19) -> 0 | E19: =+FORMATO!I41 -> 0 | F19: =E19+($D$7*E19) -> 0 | G19: =+FORMATO!J41 -> 0 | H19: =G19+($D$7*G19) -> 0 | I19: =+FORMATO!K41 -> 0 | J19: =I19+($D$7*I19) -> 0 | K19: =+FORMATO!L41 -> 0 | L19: =K19+($D$7*K19) -> 0
B20: Masa del Recipiente | C20: =+FORMATO!G42 -> 0 | D20: =C20+($D$7*C20) -> 0 | E20: =+FORMATO!I42 -> 0 | F20: =E20+($D$7*E20) -> 0 | G20: =+FORMATO!J42 -> 0 | H20: =G20+($D$7*G20) -> 0 | I20: =+FORMATO!K42 -> 0 | J20: =I20+($D$7*I20) -> 0 | K20: =+FORMATO!L42 -> 0 | L20: =K20+($D$7*K20) -> 0
B21: Masa del Agua | C21: =+C17-C19 -> 0 | D21: =+D17-D19 -> 0 | E21: =+E17-E19 -> 0 | F21: =+F17-F19 -> 0 | G21: =+G17-G19 -> 0 | H21: =+H17-H19 -> 0 | I21: =+I17-I19 -> 0 | J21: =+J17-J19 -> 0 | ... L21: =+L17-L19 -> 0
B22: Masa del Suelo Seco | C22: =C19-C20 -> 0 | D22: =D19-D20 -> 0 | E22: =E19-E20 -> 0 | F22: =F19-F20 -> 0 | G22: =G19-G20 -> 0 | H22: =H19-H20 -> 0 | I22: =I19-I20 -> 0 | J22: =J19-J20 -> 0 | ... L22: =L19-L20 -> 0
B23: % de Humedad | C23: =+C21/C22*100 -> #DIV/0! | D23: =+D21/D22*100 -> #DIV/0! | E23: =+E21/E22*100 -> #DIV/0! | F23: =+F21/F22*100 -> #DIV/0! | G23: =+G21/G22*100 -> #DIV/0! | H23: =+H21/H22*100 -> #DIV/0! | I23: =+I21/I22*100 -> #DIV/0! | J23: =+J21/J22*100 -> #DIV/0! | ... L23: =+L21/L22*100 -> #DIV/0!
B24: Promedio | I24: =+AVERAGE(J23,L23) -> #DIV/0!
B26: Perdida de masa seca constante (adicional), para metodo B es < 0.1% | C26: =+IF(D26<0.1,"Cumple","No cumple") -> #DIV/0! | D26: =(D18-D19)/D19*100 -> #DIV/0! | E26: =+IF(F26<0.1,"Cumple","No cumple") -> #DIV/0! | F26: =(F18-F19)/F19*100 -> #DIV/0! | G26: =+IF(H26<0.1,"Cumple","No cumple") -> #DIV/0! | H26: =(H18-H19)/H19*100 -> #DIV/0! | I26: =+IF(J26<0.1,"Cumple","No cumple") -> #DIV/0! | J26: =(J18-J19)/J19*100 -> #DIV/0! | K26: =+IF(L26<0.1,"Cumple","No cumple") -> #DIV/0! | L26: =(L18-L19)/L19*100 -> #DIV/0!
B27: Masa de suelo humedo, minimo 6g | I27: =+IF(J27>=6,"Cumple","No cumple") -> No cumple | J27: =+J17-J20 -> 0 | K27: =+IF(L27>=6,"Cumple","No cumple") -> No cumple | L27: =+L17-L20 -> 0
B29: LN(N) | C29: N | D29: Humedad | I29: PARAMETRO DE CONTROL LIMITE PLASTICO
B30: =+LN(C30) -> #NUM! | C30: =+D16 -> 0 | D30: =+D23 -> #DIV/0! | I30: Parametro calculado | K30: Limites diferencia Norma | M30: Control
B31: =+LN(C31) -> #NUM! | C31: =+F16 -> 0 | D31: =+F23 -> #DIV/0! | I31: 1S | J31: d2s | K31: 1S | L31: d2s
B32: =+LN(C32) -> #NUM! | C32: =+H16 -> 0 | D32: =+H23 -> #DIV/0! | I32: =+STDEV(J23,L23) -> #DIV/0! | J32: =ROUNDDOWN(I32*2.8,0) -> #DIV/0! | K32: 0.5 | L32: 1 | M32: =IF(J32<L32, "cumple", "no cumple") -> #DIV/0!
C33: Wpromedio | D33: =AVERAGE(D30:D32) -> #DIV/0!
B35: Pendiente | C35: =SLOPE(D30:D32,B30:B32) -> #DIV/0!
B36: Intercepto | C36: =INTERCEPT(D30:D32,B30:B32) -> #DIV/0!
B38: L. L. según ecuacion | D38: =(C35*LN(25)+C36) -> #DIV/0!
B40: Verificar aquí el grafico Min.095 y Max.1.00 | C40: =RSQ(D30:D32,B30:B32) -> #DIV/0! | D40: =IF(C40<=0.95,"NO CONFORME","CONFORME") -> #DIV/0!

Sheet Incertidumbre
B1: INFORME DE ESTIMACIÓN DE INCERTIDUMBRE | I1: Código: | J1: F-LEM-P-10.01
I2: Versión: | J2: 3
I3: Fecha: | J3: 46146
I4: Página: | J4: 1 de 1
A6: Método: | B6: Standard Test Methods for Liquid Limit, Plastic Limit and Plasticity Index of Soils
A7: Norma: | B7: ASTM D4318-17ε1
A8: Matriz: | B8: Suelo
A9: Mensurando: | B9: Contenido de agua de un suelo en el limite arbitrario entre los estados semiliquido y plastico (Limite liquido), plástico a semisólido (Limite plastico)
A12: Paso 1. Definición del proceso de medición
A14: Variables: | D14: Fórmula:
A16: Masa humeda (Mcms)
A17: Masa seca ( Mcdc)
A18: Masa tara (Mc)
A20: Equipos a utilizar:
A22: Balanza con resulución de lectura de 0.01g
A24: Paso 2. Definición de las variables aleatorias
A36: LÍMITE LÍQUIDO | B36: W1 | H36: W2 | O36: W3
A37: Fuentes | B37: Valor | C37: Incertidumbre Original | D37: Distribución | E37: Incertidumbre Estándar u(xi) | F37: Coeficiente de Sensibilidad | G37: Contribución ui(y) | H37: Fuentes | I37: Valor | J37: Incertidumbre Original | K37: Distribución | L37: Incertidumbre Estándar u(xi) | M37: Coeficiente de Sensibilidad | N37: Contribución ui(y) | O37: Fuentes | P37: Valor | Q37: Incertidumbre Original | R37: Distribución | S37: Incertidumbre Estándar u(xi) | T37: Coeficiente de Sensibilidad | U37: Contribución ui(y)
A38: HUMEDAD | B38: =+((B39-B43)/(B43-B47)*100) -> #DIV/0! | D38: --- | H38: HUMEDAD | I38: =+((I39-I43)/(I43-I47)*100) -> #DIV/0! | K38: --- | O38: HUMEDAD | P38: =+((P39-P43)/(P43-P47)*100) -> #DIV/0! | R38: ---
A39: M. Humeda | B39: =Balanza!B26 -> 0 | D39: --- | E39: =SQRT((E40*E40)+(E41*E41)+(E42*E42)) -> #VALUE! | F39: =100/(B43-B47) -> #DIV/0! | G39: =+E39*F39 -> #VALUE! | H39: M. Humeda | I39: =+Balanza!D26 -> 0 | K39: --- | L39: =SQRT((L40*L40)+(L41*L41)+(L42*L42)) -> #VALUE! | M39: =100/(I43-I47) -> #DIV/0! | N39: =(L39*L39)*(M39*M39) -> #VALUE! | O39: M. Humeda | P39: =Balanza!F26 -> 0 | R39: --- | S39: =SQRT((S40*S40)+(S41*S41)+(S42*S42)) -> #VALUE! | T39: =100/(P43-P47) -> #DIV/0! | U39: =(S39*S39)*(T39*T39) -> #VALUE!
A40: Repetibilidad de la pesada | C40: =Balanza!C26 -> 0 | D40: Normal, K=1 | E40: =C40 -> 0 | F40: --- | G40: --- | H40: Repetibilidad de la pesada | J40: =Balanza!E26 -> 0 | K40: Normal, K=1 | L40: =J40 -> 0 | M40: --- | N40: --- | O40: Repetibilidad de la pesada | Q40: =Balanza!G26 -> 0 | R40: Normal, K=1 | S40: =Q40 -> 0 | T40: --- | U40: ---
A41: Certificado de Calibración | C41: =2*(SQRT(Balanza!$B$9+Balanza!$C$9*(POWER(B39,2)))) -> 0.013311649 | D41: Normal, K=2 (/2) | E41: =C41/2 -> 0.0066558245 | F41: --- | G41: --- | H41: Certificado de Calibración | J41: =2*(SQRT(Balanza!$B$9+Balanza!$C$9*(POWER(I39,2)))) -> 0.013311649 | K41: Normal, K=2 (/2) | L41: =J41/2 -> 0.0066558245 | M41: --- | N41: --- | O41: Certificado de Calibración | Q41: =2*(SQRT(Balanza!$B$9+Balanza!$C$9*(POWER(P39,2)))) -> 0.013311649 | R41: Normal, K=2 (/2) | S41: =Q41/2 -> 0.0066558245 | T41: --- | U41: ---
A42: Resolución | C42: =Balanza!$B$11 -> 0.01 | D42: Rectangular | E42: =C42/SQRT(3)/2 -> #VALUE! | F42: --- | G42: --- | H42: Resolución | J42: =Balanza!$B$11 -> 0.01 | K42: Rectangular | L42: =J42/SQRT(3)/2 -> #VALUE! | M42: --- | N42: --- | O42: Resolución | Q42: =Balanza!$B$11 -> 0.01 | R42: Rectangular | S42: =Q42/SQRT(3)/2 -> #VALUE! | T42: --- | U42: ---
A43: M. Seca | B43: =Balanza!B27 -> 0 | D43: --- | E43: =SQRT((E44*E44)+(E45*E45)+(E46*E46)) -> #VALUE! | F43: =((B39-B47)*100)/(POWER((B43-B47),2)) -> #DIV/0! | G43: =+E43*F43 -> #VALUE! | H43: M. Seca | I43: =+Balanza!D27 -> 0 | K43: --- | L43: =SQRT((L44*L44)+(L45*L45)+(L46*L46)) -> #VALUE! | M43: =((I39-I47)*100)/(POWER((I43-I47),2)) -> #DIV/0! | N43: =(L43*L43)*(M43*M43) -> #VALUE! | O43: M. Seca | P43: =Balanza!F27 -> 0 | R43: --- | S43: =SQRT((S44*S44)+(S45*S45)+(S46*S46)) -> #VALUE! | T43: =((P39-P47)*100)/(POWER((P43-P47),2)) -> #DIV/0! | U43: =(S43*S43)*(T43*T43) -> #VALUE!
A44: Repetibilidad de la pesada | C44: =Balanza!C27 -> 0 | D44: Normal, K=1 | E44: =C44 -> 0 | F44: --- | G44: --- | H44: Repetibilidad de la pesada | J44: =Balanza!E27 -> 0 | K44: Normal, K=1 | L44: =J44 -> 0 | M44: --- | N44: --- | O44: Repetibilidad de la pesada | Q44: =Balanza!G27 -> 0 | R44: Normal, K=1 | S44: =Q44 -> 0 | T44: --- | U44: ---
A45: Certificado de Calibración | C45: =2*(SQRT(Balanza!$B$9+Balanza!$C$9*(POWER(B43,2)))) -> 0.013311649 | D45: Normal, K=2 (/2) | E45: =C45/2 -> 0.0066558245 | F45: --- | G45: --- | H45: Certificado de Calibración | J45: =2*(SQRT(Balanza!$B$9+Balanza!$C$9*(POWER(I43,2)))) -> 0.013311649 | K45: Normal, K=2 (/2) | L45: =J45/2 -> 0.0066558245 | M45: --- | N45: --- | O45: Certificado de Calibración | Q45: =2*(SQRT(Balanza!$B$9+Balanza!$C$9*(POWER(P43,2)))) -> 0.013311649 | R45: Normal, K=2 (/2) | S45: =Q45/2 -> 0.0066558245 | T45: --- | U45: ---
A46: Resolución | C46: =Balanza!$B$11 -> 0.01 | D46: Rectangular | E46: =C46/SQRT(3)/2 -> #VALUE! | F46: --- | G46: --- | H46: Resolución | J46: =Balanza!$B$11 -> 0.01 | K46: Rectangular | L46: =J46/SQRT(3)/2 -> #VALUE! | M46: --- | N46: --- | O46: Resolución | Q46: =Balanza!$B$11 -> 0.01 | R46: Rectangular | S46: =Q46/SQRT(3)/2 -> #VALUE! | T46: --- | U46: ---
A47: M. tara | B47: =Balanza!B28 -> 0 | D47: --- | E47: =SQRT((E48*E48)+(E49*E49)+(E50*E50)) -> #VALUE! | F47: =((B39-B43)*100)/(POWER((B43-B47),2)) -> #DIV/0! | G47: =+E47*F47 -> #VALUE! | H47: M. tara | I47: =+Balanza!D28 -> 0 | K47: --- | L47: =SQRT((L48*L48)+(L49*L49)+(L50*L50)) -> #VALUE! | M47: =((I39-I43)*100)/(POWER((I43-I47),2)) -> #DIV/0! | N47: =(L47*L47)*(M47*M47) -> #VALUE! | O47: M. tara | P47: =Balanza!F28 -> 0 | R47: --- | S47: =SQRT((S48*S48)+(S49*S49)+(S50*S50)) -> #VALUE! | T47: =((P39-P43)*100)/(POWER((P43-P47),2)) -> #DIV/0! | U47: =(S47*S47)*(T47*T47) -> #VALUE!
A48: Repetibilidad de la pesada | C48: =Balanza!C28 -> 0 | D48: Normal, K=1 | E48: =C48 -> 0 | F48: --- | G48: --- | H48: Repetibilidad de la pesada | J48: =Balanza!E28 -> 0 | K48: Normal, K=1 | L48: =J48 -> 0 | M48: --- | N48: --- | O48: Repetibilidad de la pesada | Q48: =Balanza!G28 -> 0 | R48: Normal, K=1 | S48: =Q48 -> 0 | T48: --- | U48: ---
A49: Certificado de Calibración | C49: =2*(SQRT(Balanza!$B$9+Balanza!$C$9*(POWER(B47,2)))) -> 0.013311649 | D49: Normal, K=2 (/2) | E49: =C49/2 -> 0.0066558245 | F49: --- | G49: --- | H49: Certificado de Calibración | J49: =2*(SQRT(Balanza!$B$9+Balanza!$C$9*(POWER(I47,2)))) -> 0.013311649 | K49: Normal, K=2 (/2) | L49: =J49/2 -> 0.0066558245 | M49: --- | N49: --- | O49: Certificado de Calibración | Q49: =2*(SQRT(Balanza!$B$9+Balanza!$C$9*(POWER(P47,2)))) -> 0.013311649 | R49: Normal, K=2 (/2) | S49: =Q49/2 -> 0.0066558245 | T49: --- | U49: ---
A50: Resolución | C50: =Balanza!$B$11 -> 0.01 | D50: Rectangular | E50: =C50/SQRT(3)/2 -> #VALUE! | F50: --- | G50: --- | H50: Resolución | J50: =Balanza!$B$11 -> 0.01 | K50: Rectangular | L50: =J50/SQRT(3)/2 -> #VALUE! | M50: --- | N50: --- | O50: Resolución | Q50: =Balanza!$B$11 -> 0.01 | R50: Rectangular | S50: =Q50/SQRT(3)/2 -> #VALUE! | T50: --- | U50: ---
A51: N | E51: =+SQRT(E52*E52+E53*E53) -> 0.1500444 | F51: 1 | G51: =+E51*F51 -> 0.1500444 | H51: N | L51: =+SQRT(L52*L52+L53*L53) -> 0.1500444 | M51: 1 | N51: =+L51*M51 -> 0.1500444 | O51: N | S51: =+SQRT(S52*S52+S53*S53) -> 0.1500444 | T51: 1 | U51: =+S51*T51 -> 0.1500444
A52: Aporte golpe | C52: =Balanza!$E$55 -> 0.15 | D52: Normal, K=1 | E52: =+C52 -> 0.15 | F52: --- | G52: --- | H52: Aporte golpe | J52: =Balanza!$E$55 -> 0.15 | K52: Normal, K=1 | L52: =+J52 -> 0.15 | M52: --- | N52: --- | O52: Aporte golpe | Q52: =Balanza!$E$55 -> 0.15 | R52: Normal, K=1 | S52: =+Q52 -> 0.15 | T52: --- | U52: ---
A53: certificado de calibracion cronometro | C53: =Balanza!$I$32 -> 0.0073 | D53: Normal, K=2 (/2) | E53: =C53/2 -> 0.00365 | F53: --- | G53: --- | H53: certificado de calibracion cronometro | J53: =Balanza!$I$32 -> 0.0073 | K53: Normal, K=2 (/2) | L53: =J53/2 -> 0.00365 | M53: --- | N53: --- | O53: certificado de calibracion cronometro | Q53: =Balanza!$I$32 -> 0.0073 | R53: Normal, K=2 (/2) | S53: =Q53/2 -> 0.00365 | T53: --- | U53: ---
A54: F presicion | B54: =+Precision!B6 -> 0.48709342 | C54: =+B54 -> 0.48709342 | E54: =+C54 -> 0.48709342 | F54: 1 | G54: =+E54*F54 -> 0.48709342 | H54: F presicion | I54: =+B54 -> 0.48709342 | J54: =+I54 -> 0.48709342 | L54: =+J54 -> 0.48709342 | M54: 1 | N54: =+L54*M54 -> 0.48709342 | O54: F presicion | P54: =+B54 -> 0.48709342 | Q54: =+P54 -> 0.48709342 | S54: =+Q54 -> 0.48709342 | T54: 1 | U54: =+S54*T54 -> 0.48709342
A55: Incertidumbre estandar combinada | F55: % | G55: =+SQRT(G39*G39+G43*G43+G47*G47+G51*G51+G54*G54) -> #VALUE! | N55: =+SQRT(N39*N39+N43*N43+N47*N47+N51*N51+N54*N54) -> #VALUE! | U55: =+SQRT(U39*U39+U43*U43+U47*U47+U51*U51+U54*U54) -> #VALUE!
A56: Incertidumbre Expandida LP | F56: % | G56: =N55*2 -> #VALUE!
A58: LÍMITE PLÁSTICO
A59: Fuentes | B59: Valor | C59: Incertidumbre Original | D59: Distribución | E59: Incertidumbre Estándar u(xi) | F59: Coeficiente de Sensibilidad | G59: Contribución ui(y) | H59: Fuentes | I59: Valor | J59: Incertidumbre Original | K59: Distribución | L59: Incertidumbre Estándar u(xi) | M59: Coeficiente de Sensibilidad | N59: Contribución ui(y)
A60: HUMEDADES | B60: =+((B61-B65)/(B65-B69)*100) -> #DIV/0! | D60: --- | H60: HUMEDADES | I60: =+((I61-I65)/(I65-I69)*100) -> #DIV/0! | K60: ---
...

Sheet Balanza
A6: CALIBRACION DE LA BALANZA
A8: Corrección | B8: 3.79e-06
A9: Variables | B9: 4.43e-05 | C9: 2.3e-10
A10: Ecuación | B10: 2*RAIZ(0.0000443+0.000000000230xR2)
A11: Resolución | B11: 0.01
A12: Código | B12: EQP-0045
A13: Fecha ultima calibración | C13: 46132
A14: ÍTEM | B14: MES | C14: 20 | D14: 200 | E14: 500 | F14: 1000
A15: 1
A17: =COUNT(A15:A15) -> 1 | B17: DESV STD | C17: 0 | D17: 0 | E17: 0 | F17: 0
B19: Busqueda de Repetibilidad de la masa
C21: =+C14 -> 20 | D21: =+D14 -> 200 | E21: =+E14 -> 500 | F21: 1000
C22: =C17 -> 0 | D22: =D17 -> 0 | E22: =E17 -> 0 | F22: =F17 -> 0
B24: Limite Liquido | H24: Limite Plastico
A25: Nº de Golpes | B25: =+DATOS!D16 -> 0 | D25: =+DATOS!F16 -> 0 | F25: =+DATOS!H16 -> 0
A26: R + Suelo Hum. | B26: =DATOS!D17 -> 0 | C26: =IF(B26<=$C$21,$C$22,IF(AND(B26>$C$21,B26<=$D$21),$D$22,IF(AND(B26>$D$21,B26<=$E$21),$E$22,IF(AND(B26>$E$21,B26<=$F$21),$F$22,IF(AND(B26>$F$21,B26<=$G$21),$G$22,IF(AND(B26>$G$22,B26<=$H$21),$H$22,IF(AND(B26>$H$22,B26<=$I$21),$I$22,IF(AND(B26>$I$21,B26<=$J$21),$J$22,IF(AND(B26>$J$21,B26<=$K$21),$K$22,$K$22))))))))) -> 0 | D26: =DATOS!F17 -> 0 | E26: =IF(D26<=$C$21,$C$22,IF(AND(D26>$C$21,D26<=$D$21),$D$22,IF(AND(D26>$D$21,D26<=$E$21),$E$22,IF(AND(D26>$E$21,D26<=$F$21),$F$22,IF(AND(D26>$F$21,D26<=$G$21),$G$22,IF(AND(D26>$G$22,D26<=$H$21),$H$22,IF(AND(D26>$H$22,D26<=$I$21),$I$22,IF(AND(D26>$I$21,D26<=$J$21),$J$22,IF(AND(D26>$J$21,D26<=$K$21),$K$22,$K$22))))))))) -> 0 | F26: =DATOS!H17 -> 0 | G26: =IF(F26<=$C$21,$C$22,IF(AND(F26>$C$21,F26<=$D$21),$D$22,IF(AND(F26>$D$21,F26<=$E$21),$E$22,IF(AND(F26>$E$21,F26<=$F$21),$F$22,IF(AND(F26>$F$21,F26<=$G$21),$G$22,IF(AND(F26>$G$22,F26<=$H$21),$H$22,IF(AND(F26>$H$22,F26<=$I$21),$I$22,IF(AND(F26>$I$21,F26<=$J$21),$J$22,IF(AND(F26>$J$21,F26<=$K$21),$K$22,$K$22))))))))) -> 0 | H26: =DATOS!J17 -> 0 | I26: =IF(H26<=$C$21,$C$22,IF(AND(H26>$C$21,H26<=$D$21),$D$22,IF(AND(H26>$D$21,H26<=$E$21),$E$22,IF(AND(H26>$E$21,H26<=$F$21),$F$22,IF(AND(H26>$F$21,H26<=$G$21),$G$22,IF(AND(H26>$G$22,H26<=$H$21),$H$22,IF(AND(H26>$H$22,H26<=$I$21),$I$22,IF(AND(H26>$I$21,H26<=$J$21),$J$22,IF(AND(H26>$J$21,H26<=$K$21),$K$22,$K$22))))))))) -> 0 | J26: =DATOS!L17 -> 0 | K26: =IF(J26<=$C$21,$C$22,IF(AND(J26>$C$21,J26<=$D$21),$D$22,IF(AND(J26>$D$21,J26<=$E$21),$E$22,IF(AND(J26>$E$21,J26<=$F$21),$F$22,IF(AND(J26>$F$21,J26<=$G$21),$G$22,IF(AND(J26>$G$22,J26<=$H$21),$H$22,IF(AND(J26>$H$22,J26<=$I$21),$I$22,IF(AND(J26>$I$21,J26<=$J$21),$J$22,IF(AND(J26>$J$21,J26<=$K$21),$K$22,$K$22))))))))) -> 0
A27: R + Suelo Seco 1 | B27: =DATOS!D19 -> 0 | C27: =IF(B27<=$C$21,$C$22,IF(AND(B27>$C$21,B27<=$D$21),$D$22,IF(AND(B27>$D$21,B27<=$E$21),$E$22,IF(AND(B27>$E$21,B27<=$F$21),$F$22,IF(AND(B27>$F$21,B27<=$G$21),$G$22,IF(AND(B27>$G$22,B27<=$H$21),$H$22,IF(AND(B27>$H$22,B27<=$I$21),$I$22,IF(AND(B27>$I$21,B27<=$J$21),$J$22,IF(AND(B27>$J$21,B27<=$K$21),$K$22,$K$22))))))))) -> 0 | D27: =DATOS!F19 -> 0 | E27: =IF(D27<=$C$21,$C$22,IF(AND(D27>$C$21,D27<=$D$21),$D$22,IF(AND(D27>$D$21,D27<=$E$21),$E$22,IF(AND(D27>$E$21,D27<=$F$21),$F$22,IF(AND(D27>$F$21,D27<=$G$21),$G$22,IF(AND(D27>$G$22,D27<=$H$21),$H$22,IF(AND(D27>$H$22,D27<=$I$21),$I$22,IF(AND(D27>$I$21,D27<=$J$21),$J$22,IF(AND(D27>$J$21,D27<=$K$21),$K$22,$K$22))))))))) -> 0 | F27: =DATOS!H19 -> 0 | G27: =IF(F27<=$C$21,$C$22,IF(AND(F27>$C$21,F27<=$D$21),$D$22,IF(AND(F27>$D$21,F27<=$E$21),$E$22,IF(AND(F27>$E$21,F27<=$F$21),$F$22,IF(AND(F27>$F$21,F27<=$G$21),$G$22,IF(AND(F27>$G$22,F27<=$H$21),$H$22,IF(AND(F27>$H$22,F27<=$I$21),$I$22,IF(AND(F27>$I$21,F27<=$J$21),$J$22,IF(AND(F27>$J$21,F27<=$K$21),$K$22,$K$22))))))))) -> 0 | H27: =DATOS!J19 -> 0 | I27: =IF(H27<=$C$21,$C$22,IF(AND(H27>$C$21,H27<=$D$21),$D$22,IF(AND(H27>$D$21,H27<=$E$21),$E$22,IF(AND(H27>$E$21,H27<=$F$21),$F$22,IF(AND(H27>$F$21,H27<=$G$21),$G$22,IF(AND(H27>$G$22,H27<=$H$21),$H$22,IF(AND(H27>$H$22,H27<=$I$21),$I$22,IF(AND(H27>$I$21,H27<=$J$21),$J$22,IF(AND(H27>$J$21,H27<=$K$21),$K$22,$K$22))))))))) -> 0 | J27: =DATOS!L19 -> 0 | K27: =IF(J27<=$C$21,$C$22,IF(AND(J27>$C$21,J27<=$D$21),$D$22,IF(AND(J27>$D$21,J27<=$E$21),$E$22,IF(AND(J27>$E$21,J27<=$F$21),$F$22,IF(AND(J27>$F$21,J27<=$G$21),$G$22,IF(AND(J27>$G$22,J27<=$H$21),$H$22,IF(AND(J27>$H$22,J27<=$I$21),$I$22,IF(AND(J27>$I$21,J27<=$J$21),$J$22,IF(AND(J27>$J$21,J27<=$K$21),$K$22,$K$22))))))))) -> 0
A28: Peso Recip. | B28: =DATOS!D20 -> 0 | C28: =IF(B28<=$C$21,$C$22,IF(AND(B28>$C$21,B28<=$D$21),$D$22,IF(AND(B28>$D$21,B28<=$E$21),$E$22,IF(AND(B28>$E$21,B28<=$F$21),$F$22,IF(AND(B28>$F$21,B28<=$G$21),$G$22,IF(AND(B28>$G$22,B28<=$H$21),$H$22,IF(AND(B28>$H$22,B28<=$I$21),$I$22,IF(AND(B28>$I$21,B28<=$J$21),$J$22,IF(AND(B28>$J$21,B28<=$K$21),$K$22,$K$22))))))))) -> 0 | D28: =DATOS!F20 -> 0 | E28: =IF(D28<=$C$21,$C$22,IF(AND(D28>$C$21,D28<=$D$21),$D$22,IF(AND(D28>$D$21,D28<=$E$21),$E$22,IF(AND(D28>$E$21,D28<=$F$21),$F$22,IF(AND(D28>$F$21,D28<=$G$21),$G$22,IF(AND(D28>$G$22,D28<=$H$21),$H$22,IF(AND(D28>$H$22,D28<=$I$21),$I$22,IF(AND(D28>$I$21,D28<=$J$21),$J$22,IF(AND(D28>$J$21,D28<=$K$21),$K$22,$K$22))))))))) -> 0 | F28: =DATOS!H20 -> 0 | G28: =IF(F28<=$C$21,$C$22,IF(AND(F28>$C$21,F28<=$D$21),$D$22,IF(AND(F28>$D$21,F28<=$E$21),$E$22,IF(AND(F28>$E$21,F28<=$F$21),$F$22,IF(AND(F28>$F$21,F28<=$G$21),$G$22,IF(AND(F28>$G$22,F28<=$H$21),$H$22,IF(AND(F28>$H$22,F28<=$I$21),$I$22,IF(AND(F28>$I$21,F28<=$J$21),$J$22,IF(AND(F28>$J$21,F28<=$K$21),$K$22,$K$22))))))))) -> 0 | H28: =DATOS!J20 -> 0 | I28: =IF(H28<=$C$21,$C$22,IF(AND(H28>$C$21,H28<=$D$21),$D$22,IF(AND(H28>$D$21,H28<=$E$21),$E$22,IF(AND(H28>$E$21,H28<=$F$21),$F$22,IF(AND(H28>$F$21,H28<=$G$21),$G$22,IF(AND(H28>$G$22,H28<=$H$21),$H$22,IF(AND(H28>$H$22,H28<=$I$21),$I$22,IF(AND(H28>$I$21,H28<=$J$21),$J$22,IF(AND(H28>$J$21,H28<=$K$21),$K$22,$K$22))))))))) -> 0 | J28: =DATOS!L20 -> 0 | K28: =IF(J28<=$C$21,$C$22,IF(AND(J28>$C$21,J28<=$D$21),$D$22,IF(AND(J28>$D$21,J28<=$E$21),$E$22,IF(AND(J28>$E$21,J28<=$F$21),$F$22,IF(AND(J28>$F$21,J28<=$G$21),$G$22,IF(AND(J28>$G$22,J28<=$H$21),$H$22,IF(AND(J28>$H$22,J28<=$I$21),$I$22,IF(AND(J28>$I$21,J28<=$J$21),$J$22,IF(AND(J28>$J$21,J28<=$K$21),$K$22,$K$22))))))))) -> 0
C31: Velocidad de Golpe | G31: Calibracion cronometro
C32: prueba | D32: tiempo (s) | E32: Nº Golpes | G32: Fecha de Calibración: | H32: 45485 | I32: 0.0073 | J32: EQP-0077
C33: 1 | D33: 13 | E33: 26
C34: 2 | D34: 13 | E34: 26
C35: 3 | D35: 13 | E35: 25
C36: 4 | D36: 13 | E36: 26
C37: 5 | D37: 13 | E37: 25
C38: 6 | D38: 13 | E38: 26
C39: 7 | D39: 13 | E39: 27
C40: 8 | D40: 13 | E40: 25
C41: 9 | D41: 13 | E41: 25
C42: 10 | D42: 13 | E42: 26
C43: 11 | D43: 13 | E43: 27
C44: 12 | D44: 13 | E44: 26
... C52: 20 | D52: 13 | E52: 25
B54: =COUNT(C33:C52) -> 20 | C54: desviacion estandar | E54: =+STDEV(E33:E53) -> 0.67082039
B55: incertidumbre | E55: =E54/SQRT(B54) -> 0.15

Sheet Hoja1
A2: CODIGO | C2: CONCATENADOS | D2: DESCRIPCION | E2: FC | F2: F. MOLDEO | G2: DIA | H2: DIAMETRO | I2: CARGA | J2: AREA | K2: RESIS. CONCRETO | L2: % RESIS | M2: TIPO DE FALLA
A3: 4400 | B3: =+A3+1 -> 4401 | C3: =A3&"-"&B3 -> 4400-4401 | D3: Columnas C-9;5-3/G.H | E3: 350 | F3: 42347 | G3: 7 | H3: 15.05 | I3: 49900 | J3: =H3*H3*PI()/4 -> 177.89465 | K3: =I3/J3 -> 280.5031 | L3: =+K3/E3 -> 0.80143743 | M3: E
C4: =A4&"-"&B4 -> - | E4: 350 | G4: 7 | H4: 15.06 | I4: 50310 | J4: =H4*H4*PI()/4 -> 178.13113 | K4: =I4/J4 -> 282.43238 | L4: =+K4/E4 -> 0.80694967 | M4: F
A5: =+B3+1 -> 4402 | B5: =+A5+1 -> 4403 | C5: =A5&"-"&B5 -> 4402-4403 | E5: 350 | G5: 14 | H5: 15.04 | I5: 56450 | J5: =H5*H5*PI()/4 -> 177.65832 | K5: =I5/J5 -> 317.74476 | L5: =+K5/E5 -> 0.90784216 | M5: F
C6: =A6&"-"&B6 -> - | E6: 350 | G6: 14 | H6: 15 | I6: 59630 | J6: =H6*H6*PI()/4 -> 176.71459 | K6: =I6/J6 -> 337.43677 | L6: =+K6/E6 -> 0.96410507 | M6: F
A7: =+B5+1 -> 4404 | B7: =+A7+1 -> 4405 | C7: =A7&"-"&B7 -> 4404-4405 | E7: 350 | G7: 28 | H7: 15.11 | I7: 65310 | J7: =H7*H7*PI()/4 -> 179.3159 | K7: =I7/J7 -> 364.21755 | L7: =+K7/E7 -> 1.0406216 | M7: F
C8: =A8&"-"&B8 -> - | E8: 350 | G8: 28 | H8: 15.05 | I8: 64730 | J8: =H8*H8*PI()/4 -> 177.89465 | K8: =I8/J8 -> 363.86705 | L8: =+K8/E8 -> 1.0396201 | M8: E

Sheet curva
A1: ENSAYO
A2: Nº de golpes | C2: =DATOS!D16 -> 0 | D2: =DATOS!F16 -> 0 | E2: =DATOS!H16 -> 0
A3: Logaritmo de N° de golpes | C3: =LOG(C2) -> #NUM! | D3: =LOG(D2) -> #NUM! | E3: =LOG(E2) -> #NUM!
A4: Peso tara | C4: =DATOS!D20 -> 0 | D4: =DATOS!F20 -> 0 | E4: =DATOS!H20 -> 0
A5: Peso tara + muestra húmeda | C5: =DATOS!D17 -> 0 | D5: =DATOS!F17 -> 0 | E5: =DATOS!H17 -> 0
A6: Peso tara + muestra seca | C6: =DATOS!D19 -> 0 | D6: =DATOS!F19 -> 0 | E6: =DATOS!H19 -> 0
A7: Peso de agua | C7: 3.99 | D7: 4.1 | E7: 4.17
A8: Contenido de humedad | C8: =((C5-C6)/(C6-C4))*100 -> #DIV/0! | D8: =((D5-D6)/(D6-D4))*100 -> #DIV/0! | E8: =((E5-E6)/(E6-E4))*100 -> #DIV/0!
A9: W% corregidas a la recta | C9: =+C37 -> #NUM! | D9: =+C38 -> #NUM! | E9: =+C39 -> #NUM!
G20: Del grafico se obtiene | K20: igualando pendientes | M20: m=m
A27: L. L. según modelo matematico | C27: =(((25-D37)/(D39-D37))*(C39-C37))+C37 -> #NUM!
A29: L. L. según ecuacion | C29: =+B42*LN(25)+B43 -> 36.246601
A31: RESUMEN
A33: PROMEDIO DE N | C33: =AVERAGE(C2:E2) -> 0 | L33: =-3.666*LN(25)+48.047 -> 36.246601 | M33: 36.4666
A34: Valor de N (x) | C34: 25 | L34: =-0.1389*25+39.822 -> 36.3495 | M34: 36.5695
A36: N | B36: Humedad | C36: Wn ajustado a la curva
A37: =C2 -> 0 | B37: =C8 -> #DIV/0! | C37: =+$B$42*D37+$B$43 -> #NUM! | D37: =+LN(A37) -> #NUM!
A38: =D2 -> 0 | B38: =D8 -> #DIV/0! | C38: =+$B$42*D38+$B$43 -> #NUM! | D38: =+LN(A38) -> #NUM!
A39: =E2 -> 0 | B39: =E8 -> #DIV/0! | C39: =+$B$42*D39+$B$43 -> #NUM! | D39: =+LN(A39) -> #NUM!
A40: Wpromedio | B40: =AVERAGE(B37:B39) -> #DIV/0!
A42: Pendiente | B42: -3.666
A43: Intercepto | B43: 48.047
A46: Estimacion de la incertidumbre de Grafica
A48: (Wo- Wpromedio)² | C48: =POWER(C27-B40,2) -> #NUM! | E48: =(25-C29)*(25-C29) -> 126.48604
A50: para cálculo de (Wo- Wpromedio)²
B52: N: Escala logaritmica (para el calculo)
B53: N | C53: (Wn - Wpromedio)²
B54: =C3 -> #NUM! | C54: =POWER((C37-$B$40),2) -> #NUM!
B55: =D3 -> #NUM! | C55: =POWER((C38-$B$40),2) -> #NUM!
B56: =E3 -> #NUM! | C56: =POWER((C39-$B$40),2) -> #NUM!
C57: =SUM(C54:C56) -> #NUM!
A60: para cálculo de Curva
B62: N | C62: residuo
B63: =C2 -> 0 | C63: =POWER(C37-B37,2) -> #NUM!
B64: 28 | C64: =POWER(C38-B38,2) -> #NUM!
B65: 21 | C65: =POWER(C39-B39,2) -> #NUM!
B67: Sumatoria residuo | C67: =SQRT(SUM(C63:C65)/4) -> #NUM!
A69: Incertidumbre | B69: u(C(w)) | C69: =(C67/B43*(SQRT((1)+(1/6)+(C48/C57)))) -> #NUM! | D69: %

Sheet Precision
A3: Factor de precision del operador LIMITE LIQUIDO | G3: Factor de precision del operador LIMITE PLASTICO
A4: Fecha de evaluacion: | B4: 46070 | G4: Fecha de evaluacion: | H4: 46070
A6: Desviacion Estándar Repetibilidad (Sr) | B6: 0.48709342 | G6: Desviacion Estándar Repetibilidad (Sr) | H6: 0.37576293
A7: Desviacion Estándar Reproducibilidad (SR) | B7: 30.426107 | G7: Desviacion Estándar Reproducibilidad (SR) | H7: 13.539615
