Workbook
Name ____CC2: [1]Sucs!$L$6
Name ___CC2: [1]Sucs!$L$6
Name __CC2: [1]Sucs!$L$6
Name _CC1: [2]Sucs!$L$6
Name _CC2: [1]Sucs!$L$6
Name _CU1: [2]Sucs!$L$5
Name _IP1: [2]Sucs!$L$4
Name _L1: #N/A
Name _L1: #N/A
Name _L1: #N/A
Name _L1: #N/A
Name _L1: #N/A
Name _L1: #N/A
Name _L1: #N/A
Name _L1: #N/A
Name _Ll1: [2]Sucs!$L$3
Name _W1: #N/A
Name _W1: #N/A
Name _W1: #N/A
Name _W1: #N/A
Name _W1: #N/A
Name _W1: #N/A
Name _W1: #N/A
Name _W1: #N/A
Name A_impresión_IM: #N/A
Name A_impresión_IM: #N/A
Name A_impresión_IM: #N/A
Name Abra: [3]Sucs!$C$3
Name borrado: [4]!borrado
Name borrado: [4]!borrado
Name borrado: [4]!borrado
Name borrado: [4]!borrado
Name CC: #N/A
Name CC: #N/A
Name CC: #N/A
Name CC: #N/A
Name CC: #N/A
Name CC: #N/A
Name CC: #N/A
Name CC: #N/A
Name CC: #N/A
Name CCf: '[2]Sucs(Fino)'!$L$6
Name CCVB: [5]Sucs!$L$3
Name CM: [6]BGA!$H$9
Name CM: [7]BGA!$H$9
Name CU: #N/A
Name CU: #N/A
Name CU: #N/A
Name CU: #N/A
Name CU: #N/A
Name CU: #N/A
Name CU: #N/A
Name CU: #N/A
Name CU: #N/A
Name CUf: '[2]Sucs(Fino)'!$L$5
Name d: #N/A
Name d: #N/A
Name d: #N/A
Name d: #N/A
Name GAUS: #N/A

Sheet FORMATO
L2: CLIENTE
L3: DIRECCIÓN **
L4: PROYECTO **
L5: UBICACIÓN **
A7: LABORATORIO DE ENSAYO DE MATERIALES | L7: RECEPCIÓN N°
A8: FORMATO N° F-LEM-P-AG-19.01 | L8: F. EMISIÓN
L9: OT N°
B10: MUESTRA | D10: No OT | F10: FECHA ENSAYO | H10: REALIZADO
H11: - | L11: CÓDIGO DE LA MUESTRA
L12: FECHA DE RECEPCIÓN
A13: Standard Test Method for Sieve Analysis of Fine and Coarse Aggregates | L13: FECHA DE EJECUCIÓN
A14: ASTM C136/C136M-25
L15: CANTERA/SONDAJE **
A16: Tipo de muestra | G16: Malla | H16: Abertura | I16: Masa ret. | L16: N° MUESTRA **
A17: Tamaño máximo de la particula, Visual (in) | G17: Tamiz | H17: (mm) | I17: (g) | L17: TIPO DE MUESTRA**
A18: Forma de la particula | G18: 3 in | H18: 75
G19: 2 1/2 in | H19: 63
A20: Granulometría Global | G20: 2 in | H20: 50
A21: Masa muestra húmedo inicial total | C21: g | G21: 1 1/2 in | H21: 37.5
A22: Masa muestra seca | C22: g | G22: 1 in | H22: 25
A23: Masa muestra seca constante | C23: g | G23: 3/4 in | H23: 19
A24: Masa muestra seca lavada | C24: g | G24: 1/2 in | H24: 12.5
G25: 3/8 in | H25: 9.5
A26: Granulometria fraccionada | G26: No. 4 | H26: 4.75
A27: Masa muestra húmedo inicial total | C27: g | G27: No. 8 | H27: 2.36
A28: Masa muestra seco inicial total | C28: g | G28: No. 10 | H28: 2
A29: Grueso | G29: No. 16 | H29: 1.18
A30: Masa muestra seca | C30: g | G30: No. 30 | H30: 0.6
A31: Masa muestra seca constante | C31: g | G31: No. 40 | H31: 0.425
A32: Fino | G32: No. 50 | H32: 0.3
A33: Masa muestra humedo Fino | C33: g | G33: No. 100 | H33: 0.15
A34: Masa muestra seco Fino | C34: g | G34: No. 200 | H34: 0.075
A35: Masa muestra húmedo Fracción | C35: g | G35: < 200 | H35: 0.01
A36: Masa muestra seco Fracción | C36: g | H36: Tabla de pesos minimos Ag. Grueso
A37: Masa muestra seco constante Fracción | C37: g
A38: Contenido humedad Fracción | C38: %
A39: Masa muestra seco lavado Fracción | C39: g
A41: Error máximo permitido 0.3%
A42: Masa muestra ANTES tamizado (g)
A43: Masa muestra DESPUÉS tamizado (g)
...

Sheet GRANULOMETRIA (2)
A6: LABORATORIO DE ENSAYO DE MATERIALES
A7: 1
A9: CLIENTE** | B9: : | K9: CÓDIGO: | L9: F-LEM-P-AG-19.02
A10: DIRECCIÓN ** | B10: : | K10: RECEPCIÓN N°: | L10: 1
A11: PROYECTO ** | B11: : | K11: FECHA DE EMISIÓN:
A12: UBICACIÓN ** | B12: :
A13: **Datos proporcionados por el cliente
A14: Standard Test Method for Sieve Analysis of Fine and Coarse Aggregates
A15: ASTM C136/C136M − 19
A17: DATOS DE LA MUESTRA
A18: CANTERA/SONDAJE ** : | K18: CÓDIGO DE LA MUESTRA: | L18: 1
A19: N° MUESTRA ** : | K19: FECHA DE RECEPCIÓN:
A20: TIPO DE MUESTRA : | K20: FECHA DE EJECUCIÓN:
A21: LUGAR DE ENSAYO : | D21: Laboratorio de Materiales
D23: Designación de Tamices | F23: Material total retenido en cada tamiz (%) | G23: Material retenido entre tamices consecutivos (%) | H23: Material total que pasa por cada tamiz (%) | J23: Caracteristicas de la Muestra | AA23: Tamaño de abretura del tamiz | AC23: Material total que pasa por cada tamiz (%)
D24: Alternativo | E24: Estándar | AA24: in. | AB24: mm.
D25: 3 in. | E25: 75 mm | F25: =+datos!F28 -> #DIV/0! | G25: =+datos!G28 -> #DIV/0! | H25: =+AC25 -> #DIV/0! | J25: T.M (in.) | K25: =+datos!I19 -> #DIV/0! | AA25: 3 | AB25: 75 | AC25: =+datos!H28 -> #DIV/0!
D26: 2 1/2 in. | E26: 63 mm | F26: =+datos!F29 -> #DIV/0! | G26: =+datos!G29 -> #DIV/0! | H26: =+AC26 -> #DIV/0! | J26: T.M.N (in.) | K26: =+datos!I20 -> #DIV/0! | AA26: 2.5 | AB26: 63 | AC26: =+datos!H29 -> #DIV/0!
D27: 2 in. | E27: 50 mm | F27: =+datos!F30 -> #DIV/0! | G27: =+datos!G30 -> #DIV/0! | H27: =+AC27 -> #DIV/0! | J27: Mod. Fineza | K27: =+datos!I21 -> #DIV/0! | O27: Grava (%) | P27: =+datos!I22 -> #DIV/0! | AA27: 2 | AB27: 50 | AC27: =+datos!H30 -> #DIV/0!
D28: 1 1/2 in. | E28: 37.5 mm | F28: =+datos!F31 -> #DIV/0! | G28: =+datos!G31 -> #DIV/0! | H28: =+AC28 -> #DIV/0! | O28: Arena (%) | P28: =+datos!I23 -> #DIV/0! | AA28: 1.5 | AB28: 37.5 | AC28: =+datos!H31 -> #DIV/0!
D29: 1 in. | E29: 25.0 mm | F29: =+datos!F32 -> #DIV/0! | G29: =+datos!G32 -> #DIV/0! | H29: =+AC29 -> #DIV/0! | O29: Fino (%) | P29: =+datos!I24 -> #DIV/0! | AA29: 1 | AB29: 25 | AC29: =+datos!H32 -> #DIV/0!
D30: 3/4 in. | E30: 19.0 mm | F30: =+datos!F33 -> #DIV/0! | G30: =+datos!G33 -> #DIV/0! | H30: =+AC30 -> #DIV/0! | AA30: 0.75 | AB30: 19 | AC30: =+datos!H33 -> #DIV/0!
D31: 1/2 in. | E31: 12.5 mm | F31: =+datos!F34 -> #DIV/0! | G31: =+datos!G34 -> #DIV/0! | H31: =+AC31 -> #DIV/0! | AA31: 0.5 | AB31: 12.5 | AC31: =+datos!H34 -> #DIV/0!
D32: 3/8 in. | E32: 9.5 mm | F32: =+datos!F35 -> #DIV/0! | G32: =+datos!G35 -> #DIV/0! | H32: =+AC32 -> #DIV/0! | AA32: 0.375 | AB32: 9.5 | AC32: =+datos!H35 -> #DIV/0!
D33: No.4 | E33: 4.75 mm | F33: =+datos!F36 -> #DIV/0! | G33: =+datos!G36 -> #DIV/0! | H33: =+AC33 -> #DIV/0! | AA33: No4 | AB33: 4.75 | AC33: =+datos!H36 -> #DIV/0!
D34: No.8 | E34: 2.36 mm | F34: =+datos!F37 -> FALSE | G34: =+datos!G37 -> #DIV/0! | H34: =+AC34 -> #DIV/0! | AA34: 8 | AB34: 2.36 | AC34: =+datos!H37 -> #DIV/0!
D35: No.10 | E35: 2.00 mm | F35: =+datos!F38 -> FALSE | G35: =+datos!G38 -> #DIV/0! | H35: =+AC35 -> #DIV/0! | AA35: 10 | AB35: 2 | AC35: =+datos!H38 -> #DIV/0!
D36: No.16 | E36: 1.18 mm | F36: =+datos!F39 -> FALSE | G36: =+datos!G39 -> #DIV/0! | H36: =+AC36 -> #DIV/0! | AA36: 16 | AB36: 1.18 | AC36: =+datos!H39 -> #DIV/0!
D37: No. 30 | E37: 600 µm | F37: =+datos!F40 -> FALSE | G37: =+datos!G40 -> #DIV/0! | H37: =+AC37 -> #DIV/0! | AA37: 30 | AB37: 0.6 | AC37: =+datos!H40 -> #DIV/0!
D38: No.40 | E38: 425 µm | F38: =+datos!F41 -> FALSE | G38: =+datos!G41 -> #DIV/0! | H38: =+AC38 -> #DIV/0! | AA38: 40 | AB38: 0.425 | AC38: =+datos!H41 -> #DIV/0!
D39: No.50 | E39: 300 µm | F39: =+datos!F42 -> FALSE | G39: =+datos!G42 -> #DIV/0! | H39: =+AC39 -> #DIV/0! | AA39: 50 | AB39: 0.3 | AC39: =+datos!H42 -> #DIV/0!
D40: No.100 | E40: 150 µm | F40: =+datos!F43 -> FALSE | G40: =+datos!G43 -> #DIV/0! | H40: =+AC40 -> #DIV/0! | AA40: 100 | AB40: 0.15 | AC40: =+datos!H43 -> #DIV/0!
D41: No. 200 | E41: 75 µm | F41: =+datos!F44 -> FALSE | G41: =+datos!G44 -> #DIV/0! | H41: =IF($AC$41<10,FIXED((AC41),1),FIXED((AC41),0)) -> #DIV/0! | AA41: 200 | AB41: 0.075 | AC41: =+datos!H44 -> #DIV/0!
A57: Nota:
A58: - Los datos de identificación de la muestra son proporcionados por el cliente.
A59: - Los resultados corresponden sólo a los ensayos realizados sobre la muestra proporcionada por el cliente.
A60: - Los resultados de los ensayos no deben ser utilizados como una certificación de conformidad con normas de productos o como certificado del sistema de calidad de Geofal SAC.
A61: - Prohibida la reproducción total o parcial del presente informe de ensayo sin la autorización escrita de Geofal S.A.C.
A62: - Este informe de ensayo, al estar en el marco de la acreditación del INACAL - DA, se encuentra dentro del ámbito de reconocimiento multilateral/mutuo de los miembros firmantes de IAAC e ILAC.
A63: Observaciones:
...

Sheet GRANULOMETRIA (3)
A6: LABORATORIO DE ENSAYO DE MATERIALES
A7: 1
A9: CLIENTE** | B9: : | C9: =+FORMATO!M2 -> 0 | K9: CÓDIGO: | L9: F-LEM-P-AG-19.02
A10: DIRECCIÓN ** | B10: : | C10: =+FORMATO!M3 -> 0 | K10: RECEPCIÓN N°: | L10: =+FORMATO!M7 -> 0
A11: PROYECTO ** | B11: : | C11: =+FORMATO!M4 -> 0 | K11: OT N°: | L11: =+FORMATO!M9 -> 0
A12: UBICACIÓN ** | B12: : | C12: =+FORMATO!M5 -> 0 | K12: FECHA DE EMISIÓN: | L12: =+FORMATO!M8 -> 0
A13: **Datos proporcionados por el cliente
A14: Standard Test Method for Sieve Analysis of Fine and Coarse Aggregates
A15: ASTM C136/C136M − 25
A17: DATOS DE LA MUESTRA
A18: CANTERA/SONDAJE ** : | D18: =+FORMATO!M15 -> 0 | K18: CÓDIGO DE LA MUESTRA: | L18: =+FORMATO!M11 -> 0
A19: N° MUESTRA ** : | D19: =+FORMATO!M16 -> 0 | K19: FECHA DE RECEPCIÓN: | L19: =+FORMATO!M12 -> 0
A20: TIPO DE MUESTRA : | D20: =+FORMATO!B16 -> 0 | K20: FECHA DE EJECUCIÓN: | L20: =+FORMATO!M13 -> 0 | M20: =+FORMATO!F11 -> 0
A21: LUGAR DE ENSAYO : | D21: Laboratorio de Materiales
D23: Designación de Tamices | F23: Material total retenido en cada tamiz (%) | G23: Material retenido entre tamices consecutivos (%) | H23: Material total que pasa por cada tamiz (%) | J23: Caracteristicas de la Muestra | N23: Caracteristicas de la Muestra | Z23: Tamaño de abretura del tamiz | AB23: Material total que pasa por cada tamiz (%)
D24: Alternativo | E24: Estándar | Z24: in. | AA24: mm.
D25: 3 in. | E25: 75 mm | F25: =+datos!F28 -> #DIV/0! | G25: =+datos!G28 -> #DIV/0! | H25: =+AB25 -> #DIV/0! | J25: Módulo de fineza | K25: =+datos!I21 -> #DIV/0! | N25: T.M (in.) | O25: =+datos!I19 -> #DIV/0! | Z25: 3 | AA25: 75 | AB25: =+datos!H28 -> #DIV/0!
D26: 2 1/2 in. | E26: 63 mm | F26: =+datos!F29 -> #DIV/0! | G26: =+datos!G29 -> #DIV/0! | H26: =+AB26 -> #DIV/0! | N26: T.M.N (in.) | O26: =+datos!I20 -> #DIV/0! | Z26: 2.5 | AA26: 63 | AB26: =+datos!H29 -> #DIV/0!
D27: 2 in. | E27: 50 mm | F27: =+datos!F30 -> #DIV/0! | G27: =+datos!G30 -> #DIV/0! | H27: =+AB27 -> #DIV/0! | N27: Grava (%) | O27: =+datos!I22 -> #DIV/0! | Z27: 2 | AA27: 50 | AB27: =+datos!H30 -> #DIV/0!
D28: 1 1/2 in. | E28: 37.5 mm | F28: =+datos!F31 -> #DIV/0! | G28: =+datos!G31 -> #DIV/0! | H28: =+AB28 -> #DIV/0! | N28: Arena (%) | O28: =+datos!I23 -> #DIV/0! | Z28: 1.5 | AA28: 37.5 | AB28: =+datos!H31 -> #DIV/0!
D29: 1 in. | E29: 25.0 mm | F29: =+datos!F32 -> #DIV/0! | G29: =+datos!G32 -> #DIV/0! | H29: =+AB29 -> #DIV/0! | N29: Fino (%) | O29: =+datos!I24 -> #DIV/0! | Z29: 1 | AA29: 25 | AB29: =+datos!H32 -> #DIV/0!
D30: 3/4 in. | E30: 19.0 mm | F30: =+datos!F33 -> #DIV/0! | G30: =+datos!G33 -> #DIV/0! | H30: =+AB30 -> #DIV/0! | Z30: 0.75 | AA30: 19 | AB30: =+datos!H33 -> #DIV/0!
D31: 1/2 in. | E31: 12.5 mm | F31: =+datos!F34 -> #DIV/0! | G31: =+datos!G34 -> #DIV/0! | H31: =+AB31 -> #DIV/0! | Z31: 0.5 | AA31: 12.5 | AB31: =+datos!H34 -> #DIV/0!
D32: 3/8 in. | E32: 9.5 mm | F32: =+datos!F35 -> #DIV/0! | G32: =+datos!G35 -> #DIV/0! | H32: =+AB32 -> #DIV/0! | Z32: 0.375 | AA32: 9.5 | AB32: =+datos!H35 -> #DIV/0!
D33: No.4 | E33: 4.75 mm | F33: =+datos!F36 -> #DIV/0! | G33: =+datos!G36 -> #DIV/0! | H33: =+AB33 -> #DIV/0! | Z33: No4 | AA33: 4.75 | AB33: =+datos!H36 -> #DIV/0!
D34: No.8 | E34: 2.36 mm | F34: =+datos!F37 -> FALSE | G34: =+datos!G37 -> #DIV/0! | H34: =+AB34 -> #DIV/0! | Z34: 8 | AA34: 2.36 | AB34: =+datos!H37 -> #DIV/0!
D35: No.10 | E35: 2.00 mm | F35: =+datos!F38 -> FALSE | G35: =+datos!G38 -> #DIV/0! | H35: =+AB35 -> #DIV/0! | Z35: 10 | AA35: 2 | AB35: =+datos!H38 -> #DIV/0!
D36: No.16 | E36: 1.18 mm | F36: =+datos!F39 -> FALSE | G36: =+datos!G39 -> #DIV/0! | H36: =+AB36 -> #DIV/0! | Z36: 16 | AA36: 1.18 | AB36: =+datos!H39 -> #DIV/0!
D37: No. 30 | E37: 600 µm | F37: =+datos!F40 -> FALSE | G37: =+datos!G40 -> #DIV/0! | H37: =+AB37 -> #DIV/0! | Z37: 30 | AA37: 0.6 | AB37: =+datos!H40 -> #DIV/0!
D38: No.40 | E38: 425 µm | F38: =+datos!F41 -> FALSE | G38: =+datos!G41 -> #DIV/0! | H38: =+AB38 -> #DIV/0! | Z38: 40 | AA38: 0.425 | AB38: =+datos!H41 -> #DIV/0!
D39: No.50 | E39: 300 µm | F39: =+datos!F42 -> FALSE | G39: =+datos!G42 -> #DIV/0! | H39: =+AB39 -> #DIV/0! | Z39: 50 | AA39: 0.3 | AB39: =+datos!H42 -> #DIV/0!
D40: No.100 | E40: 150 µm | F40: =+datos!F43 -> FALSE | G40: =+datos!G43 -> #DIV/0! | H40: =+AB40 -> #DIV/0! | Z40: 100 | AA40: 0.15 | AB40: =+datos!H43 -> #DIV/0!
D41: No. 200 | E41: 75 µm | F41: =+datos!F44 -> FALSE | G41: =+datos!G44 -> #DIV/0! | H41: =IF($AB$41<10,FIXED((AB41),1),FIXED((AB41),0)) -> #DIV/0! | Z41: 200 | AA41: 0.075 | AB41: =+datos!H44 -> #DIV/0!
A57: Nota:
A58: - El cliente es responsable de los datos de identificación de los puntos de ensayo brindados.
A59: - Los resultados expresados se refieren únicamente al ensayo realizado en dicho momento y en las condiciones especificadas en este documento, por lo que GEOFAL S.A.C. no será responsable por los ensayos realizados con la presente muestra en condiciones distintas a las aquí señaladas.
A60: - GEOFAL S.A.C. no se hace responsable por el uso incorrecto o inadecuado del presente informe.
A61: - Los resultados de los ensayos realizados no deben ser utilizados como una certificación de conformidad con normas de producto o como certificado del sistema de calidad de la entidad que lo produce.
A62: - De conformidad con lo dispuesto por el artículo 1321 del Código Civil, queda establecido que en ningún caso la responsabilidad de GEOFAL S.A.C. será mayor al valor del servicio prestado.
A63: Observaciones:
...

Sheet datos
B1: Standard Test Method for Sieve Analysis of Fine and Coarse Aggregates
B2: ASTM C136/C136M − 25
B3: Información para la Corrección por Certificado de Calibración:
B4: Precisión de la Balanza al 0.1g
B5: Corrección | D5: =+Balanza!B8 -> -3.29e-06
B6: CODIGO | D6: =+Balanza!B12 -> EQP-0046
B7: Fecha | D7: 46132
B9: Tipo Agregado | C9: - | F9: OPERADORES
B10: Metodo | C10: - | F10: - | G10: =+FORMATO!H11 -> 0
B12: Detrminacion de la masa inicial | G12: humeda de la fraccion
C13: Masa humeda | D13: Corregido | E13: Masa seca | H13: Original | I13: Corregido
B14: Grava | C14: =+FORMATO!D30 -> 0 | D14: =C14+($D$5*C14) -> 0 | E14: =D14 -> 0 | F14: =SUM(E28:E45) -> 0 | G14: Masa Humeda | H14: =+IF(C10="Global",FORMATO!D21,FORMATO!D35) -> 0 | I14: =H14+($D$5*H14) -> 0
B15: Arena | C15: =+FORMATO!D33 -> 0 | D15: =C15+($D$5*C15) -> 0 | E15: =D15/(1+I16/100) -> #DIV/0! | G15: Masa Seca | H15: =+IF(C10="Global",FORMATO!D22,FORMATO!D36) -> 0 | I15: =H15+($D$5*H15) -> 0
B16: total | E16: =SUM(E14:E15) -> #DIV/0! | F16: =IF(C10="Global",H15,IF(C10="Fraccionada",E16)) -> FALSE | G16: % Humedad | H16: =((H14-H15)/H15)*100 -> #DIV/0! | I16: =((I14-I15)/I15)*100 -> #DIV/0!
B18: Datos de ensayo | H18: Caracteristicas de la Muestra
B19: Masa Total | E19: =IF(C9="Grueso",F14,F16) -> FALSE | H19: T.M (in.) | I19: =IF(C9="Fino","- -",T39) -> #DIV/0!
B20: Masa Fraccion Fino | E20: =IF(C10="Global","--",IF(C10="Fraccionada",I15)) -> FALSE | H20: T.M.N (in.) | I20: =IF(C9="Fino","- -",P39) -> #DIV/0!
B21: Masa Muestra Lavada seco | E21: =+IF(C10="Global",FORMATO!D24,FORMATO!D39) -> 0 | H21: Mod. Fineza | I21: =(G43+G42+G40+G39+G37+G36+G35+G33+G31)/100 -> #DIV/0!
B22: Masa Despues del tamizado | E22: =IF(C10="Global",SUM(E28:E45),SUM(E37:E45)) -> 0 | H22: Grava (%) | I22: =+G36 -> #DIV/0!
B23: Diferencia | E23: =ABS(E21-E22) -> 0 | H23: Arena (%) | I23: =100-(I22+I24) -> #DIV/0!
B24: error de tamizado | E24: =E23/E21*100 -> #DIV/0! | F24: =+IF(E24<=0.3,"cumple","no cumple") -> #DIV/0! | H24: Fino (%) | I24: =+H44 -> #DIV/0!
B26: Tamaño de abretura del tamiz | D26: Masa retenido en cada tamiz | E26: CORRECCION | F26: Total de material retenido en cada tamiz (%) | G26: Material retenido entre tamices consecutivo (%)) | H26: Material total que pasa por cada tamiz (%)
B27: in. | C27: mm. | D27: (gr)
B28: 3 | C28: 75 | D28: =+FORMATO!I18 -> 0 | E28: =D28+($D$5*D28) -> 0 | F28: =E28/$E$19*100 -> #DIV/0! | G28: =F28 -> #DIV/0! | H28: =100-G28 -> #DIV/0! | N28: =IF(G28>=5,1,0) -> #DIV/0! | O28: =IF(N28=0,1,-0.5) -> #DIV/0! | P28: =O28 -> #DIV/0! | Q28: =+B28 -> 3 | R28: =IF(D28<100,1,0) -> 1 | S28: =IF(H28=100,1,-0.5) -> #DIV/0! | T28: =S28 -> #DIV/0! | U28: =+Q28 -> 3
B29: 2.5 | C29: 63 | D29: =+FORMATO!I19 -> 0 | E29: =D29+($D$5*D29) -> 0 | F29: =E29/$E$19*100 -> #DIV/0! | G29: =+G28+F29 -> #DIV/0! | H29: =100-G29 -> #DIV/0! | N29: =IF(G29>=5,1,0) -> #DIV/0! | O29: =IF(N29=0,1,-0.5) -> #DIV/0! | P29: =P28+O29 -> #DIV/0! | Q29: =+B29 -> 2.5 | R29: =IF(D29<100,1,0) -> 1 | S29: =IF(H29=100,1,-0.5) -> #DIV/0! | T29: =T28+S29 -> #DIV/0! | U29: =+Q29 -> 2.5
B30: 2 | C30: 50 | D30: =+FORMATO!I20 -> 0 | E30: =D30+($D$5*D30) -> 0 | F30: =E30/$E$19*100 -> #DIV/0! | G30: =+G29+F30 -> #DIV/0! | H30: =100-G30 -> #DIV/0! | N30: =IF(G30>=5,1,0) -> #DIV/0! | O30: =IF(N30=0,1,-0.5) -> #DIV/0! | P30: =P29+O30 -> #DIV/0! | Q30: =+B30 -> 2 | R30: =IF(D30<100,1,0) -> 1 | S30: =IF(H30=100,1,-0.5) -> #DIV/0! | T30: =T29+S30 -> #DIV/0! | U30: =+Q30 -> 2
B31: 1.5 | C31: 37.5 | D31: =+FORMATO!I21 -> 0 | E31: =D31+($D$5*D31) -> 0 | F31: =E31/$E$19*100 -> #DIV/0! | G31: =+G30+F31 -> #DIV/0! | H31: =100-G31 -> #DIV/0! | N31: =IF(G31>=5,1,0) -> #DIV/0! | O31: =IF(N31=0,1,-0.5) -> #DIV/0! | P31: =P30+O31 -> #DIV/0! | Q31: =+B31 -> 1.5 | R31: =IF(D31<100,1,0) -> 1 | S31: =IF(H31=100,1,-0.5) -> #DIV/0! | T31: =T30+S31 -> #DIV/0! | U31: =+Q31 -> 1.5
B32: 1 | C32: 25 | D32: =+FORMATO!I22 -> 0 | E32: =D32+($D$5*D32) -> 0 | F32: =E32/$E$19*100 -> #DIV/0! | G32: =+G31+F32 -> #DIV/0! | H32: =100-G32 -> #DIV/0! | N32: =IF(G32>=5,1,0) -> #DIV/0! | O32: =IF(N32=0,1,-0.5) -> #DIV/0! | P32: =P31+O32 -> #DIV/0! | Q32: =+B32 -> 1 | R32: =IF(D32<100,1,0) -> 1 | S32: =IF(H32=100,1,-0.5) -> #DIV/0! | T32: =T31+S32 -> #DIV/0! | U32: =+Q32 -> 1
B33: 0.75 | C33: 19 | D33: =+FORMATO!I23 -> 0 | E33: =D33+($D$5*D33) -> 0 | F33: =E33/$E$19*100 -> #DIV/0! | G33: =+G32+F33 -> #DIV/0! | H33: =100-G33 -> #DIV/0! | N33: =IF(G33>=5,1,0) -> #DIV/0! | O33: =IF(N33=0,1,-0.5) -> #DIV/0! | P33: =P32+O33 -> #DIV/0! | Q33: =+B33 -> 0.75 | R33: =IF(D33<100,1,0) -> 1 | S33: =IF(H33=100,1,-0.5) -> #DIV/0! | T33: =T32+S33 -> #DIV/0! | U33: =+Q33 -> 0.75
B34: 0.5 | C34: 12.5 | D34: =+FORMATO!I24 -> 0 | E34: =D34+($D$5*D34) -> 0 | F34: =E34/$E$19*100 -> #DIV/0! | G34: =+G33+F34 -> #DIV/0! | H34: =100-G34 -> #DIV/0! | N34: =IF(G34>=5,1,0) -> #DIV/0! | O34: =IF(N34=0,1,-0.5) -> #DIV/0! | P34: =P33+O34 -> #DIV/0! | Q34: =+B34 -> 0.5 | R34: =IF(D34<100,1,0) -> 1 | S34: =IF(H34=100,1,-0.5) -> #DIV/0! | T34: =T33+S34 -> #DIV/0! | U34: =+Q34 -> 0.5
B35: 0.375 | C35: 9.5 | D35: =+FORMATO!I25 -> 0 | E35: =D35+($D$5*D35) -> 0 | F35: =E35/$E$19*100 -> #DIV/0! | G35: =+G34+F35 -> #DIV/0! | H35: =100-G35 -> #DIV/0! | N35: =IF(G35>=5,1,0) -> #DIV/0! | O35: =IF(N35=0,1,-0.5) -> #DIV/0! | P35: =P34+O35 -> #DIV/0! | Q35: =+B35 -> 0.375 | S35: =IF(H35=100,1,-0.5) -> #DIV/0! | T35: =T34+S35 -> #DIV/0! | U35: =+Q35 -> 0.375
B36: No4 | C36: 4.75 | D36: =+FORMATO!I26 -> 0 | E36: =D36+($D$5*D36) -> 0 | F36: =E36/$E$19*100 -> #DIV/0! | G36: =+G35+F36 -> #DIV/0! | H36: =100-G36 -> #DIV/0! | N36: =IF(G36>=5,1,0) -> #DIV/0! | O36: =IF(N36=0,1,-0.5) -> #DIV/0! | P36: =P35+O36 -> #DIV/0! | Q36: =+B36 -> No4 | S36: =IF(H36=100,1,-0.5) -> #DIV/0! | T36: =T35+S36 -> #DIV/0! | U36: =+Q36 -> No4
B37: 8 | C37: 2.36 | D37: =+FORMATO!I27 -> 0 | E37: =D37+($D$5*D37) -> 0 | F37: =IF($C$10="Fraccionada",E37*$H$36/E$20,IF($C$10="Global",E37/$E$19*100)) -> FALSE | G37: =+G36+F37 -> #DIV/0! | H37: =100-G37 -> #DIV/0! | N37: =SUM(N28:N36) -> #DIV/0!
B38: 10 | C38: 2 | D38: =+FORMATO!I28 -> 0 | E38: =D38+($D$5*D38) -> 0 | F38: =IF($C$10="Fraccionada",E38*$H$36/E$20,IF($C$10="Global",E38/$E$19*100)) -> FALSE | G38: =+G37+F38 -> #DIV/0! | H38: =100-G38 -> #DIV/0! | O38: MAXIMO | P38: =MAX(P28:P36) -> #DIV/0! | S38: MAXIMO | T38: =MAX(T28:T36) -> #DIV/0!
B39: 16 | C39: 1.18 | D39: =+FORMATO!I29 -> 0 | E39: =D39+($D$5*D39) -> 0 | F39: =IF($C$10="Fraccionada",E39*$H$36/E$20,IF($C$10="Global",E39/$E$19*100)) -> FALSE | G39: =+G38+F39 -> #DIV/0! | H39: =100-G39 -> #DIV/0! | O39: TMN | P39: =IF(N37=0,"<No .4",VLOOKUP(1,N28:Q36,4,0)) -> #DIV/0! | S39: TM | T39: =VLOOKUP(T38,T28:U36,2,0) -> #DIV/0!
B40: 30 | C40: 0.6 | D40: =+FORMATO!I30 -> 0 | E40: =D40+($D$5*D40) -> 0 | F40: =IF($C$10="Fraccionada",E40*$H$36/E$20,IF($C$10="Global",E40/$E$19*100)) -> FALSE | G40: =+G39+F40 -> #DIV/0! | H40: =100-G40 -> #DIV/0!
B41: 40 | C41: 0.425 | D41: =+FORMATO!I31 -> 0 | E41: =D41+($D$5*D41) -> 0 | F41: =IF($C$10="Fraccionada",E41*$H$36/E$20,IF($C$10="Global",E41/$E$19*100)) -> FALSE | G41: =+G40+F41 -> #DIV/0! | H41: =100-G41 -> #DIV/0!
B42: 50 | C42: 0.3 | D42: =+FORMATO!I32 -> 0 | E42: =D42+($D$5*D42) -> 0 | F42: =IF($C$10="Fraccionada",E42*$H$36/E$20,IF($C$10="Global",E42/$E$19*100)) -> FALSE | G42: =+G41+F42 -> #DIV/0! | H42: =100-G42 -> #DIV/0!
B43: 100 | C43: 0.15 | D43: =+FORMATO!I33 -> 0 | E43: =D43+($D$5*D43) -> 0 | F43: =IF($C$10="Fraccionada",E43*$H$36/E$20,IF($C$10="Global",E43/$E$19*100)) -> FALSE | G43: =+G42+F43 -> #DIV/0! | H43: =100-G43 -> #DIV/0!
B44: 200 | C44: 0.075 | D44: =+FORMATO!I34 -> 0 | E44: =D44+($D$5*D44) -> 0 | F44: =IF($C$10="Fraccionada",E44*$H$36/E$20,IF($C$10="Global",E44/$E$19*100)) -> FALSE | G44: =+G43+F44 -> #DIV/0! | H44: =100-G44 -> #DIV/0!
...

Sheet Incertidumbre
B1: INFORME DE ESTIMACIÓN DE INCERTIDUMBRE | J1: Código: | K1: F-LEM-P-10.01
J2: Versión: | K2: 3
J3: Fecha: | K3: 46146
J4: Página: | K4: 1 de 1
A6: Método: | B6: Standard Test Method for Sieve Analysis of Fine and Coarse Aggregates
A7: Norma: | B7: ASTM C136/C136M-19
A8: Matriz: | B8: Agregado fino o Grueso
A9: Mensurando: | B9: Masa de agregado que pasa a travez de un tamiz
A11: Paso 1. Definición del proceso de medición
A13: Variables: | F13: Fórmula:
A15: % Pasa: % pasa el tamiz anterior
A16: Mret: Masa retenida
A17: Mtotal: Masa total
A19: Equipos a utilizar:
A21: Balanza con resolución de lectura de 0.1g
A22: Tamices
A24: Paso 2. Definición de las variables aleatorias
A35: CÁLCULOS
A36: Fuentes | B36: Valor | C36: Incertidumbre original | D36: Distribución | E36: Incertidumbre Estándar u(xi) | F36: Coeficiente de Sensibilidad | G36: Contribución ui(y) | H36: Incertidumbre Estándar Combinada | I36: Incertidumbre Expandida
A38: Tamiz 3 in | B38: =+(1-(B40/B44))*100 -> #DIV/0! | H38: =SQRT(G40*G40+(G48*G48)+(G44*G44)+(G50*G50)) -> #DIV/0! | I38: =IF(B40=0,"---",(H38*2)) -> ---
A40: M ret acumulado 3 in (g) | B40: =+Balanza!D30 -> 0 | D40: --- | E40: =SQRT((E41*E41)+(E42*E42)+(E43*E43)) -> 0.070663522 | F40: =(100/B44) -> #DIV/0! | G40: =(E40*F40) -> #DIV/0!
A41: Repetibilidad de la pesada | C41: =Balanza!E30 -> 0 | D41: Normal, K=1 | E41: =C41 -> 0
A42: Certificado de Calibración | C42: =2*(SQRT(Balanza!$B$9+Balanza!$C$9*(POWER(B40,2)))) -> 0.12899612 | D42: Normal, K=2 | E42: =C42/2 -> 0.064498062 | I42: =A40 -> M ret acumulado 3 in (g) | J42: =G40 -> #DIV/0!
A43: Resolución | C43: =+Balanza!$B$11 -> 0.1 | D43: Rectangular | E43: =(C43/SQRT(3)/2) -> 0.028867513 | I43: =A48 -> Abertura de Tamiz 3 in (mm) | J43: =G48 -> 0.009
A44: M total (g) | B44: =+Balanza!$C$26 -> FALSE | D44: --- | E44: =SQRT((E45*E45)+(E46*E46)+(E47*E47)) -> 0.070663522 | F44: =(100*B40)/POWER(B44,2) -> #DIV/0! | G44: =(E44*F44) -> #DIV/0! | I44: =A44 -> M total (g) | J44: =G44 -> #DIV/0!
A45: Repetibilidad de la pesada | C45: =+Balanza!$D$26 -> 0 | D45: Normal, K=1 | E45: =C45 -> 0 | I45: =A50 -> Factor de presición 3 in | J45: =G50 -> 0
A46: Certificado de Calibración | C46: =2*(SQRT(Balanza!$B$9+Balanza!$C$9*(POWER(B44,2)))) -> 0.12899612 | D46: Normal, K=2 | E46: =C46/2 -> 0.064498062
A47: Resolución | C47: =+Balanza!$B$11 -> 0.1 | D47: Rectangular | E47: =(C47/SQRT(3)/2) -> 0.028867513
A48: Abertura de Tamiz 3 in (mm) | B48: 75 | D48: --- | E48: =+SQRT(E49^2) -> 0.009 | F48: 1 | G48: =(E48*F48) -> 0.009
A49: Certificado de Calibración | C49: =+Balanza!L28 -> 0.018 | D49: Normal, K=2 | E49: =C49/2 -> 0.009
A50: Factor de presición 3 in | B50: =+Balanza!B53 -> 0 | D50: Norma, K=1 | E50: =B50/SQRT(1) -> 0 | F50: 1 | G50: =(E50*F50) -> 0
A52: Tamiz 2 1/2 in | B52: =+(1-(B54/B58))*100 -> #DIV/0! | H52: =SQRT(G54*G54+(G62*G62)+(G58*G58)+(G64*G64)) -> #DIV/0! | I52: =IF(B54=0,"---",(H52*2)) -> ---
A54: M ret acumulado 2 1/2 in (g) | B54: =+Balanza!D31 -> 0 | D54: --- | E54: =SQRT((E55*E55)+(E56*E56)+(E57*E57)) -> 0.070663522 | F54: =(100/B58) -> #DIV/0! | G54: =(E54*F54) -> #DIV/0!
A55: Repetibilidad de la pesada | C55: =Balanza!E31 -> 0 | D55: Normal, K=1 | E55: =C55 -> 0
A56: Certificado de Calibración | C56: =2*(SQRT(Balanza!$B$9+Balanza!$C$9*(POWER(B54,2)))) -> 0.12899612 | D56: Normal, K=2 | E56: =C56/2 -> 0.064498062 | I56: =A54 -> M ret acumulado 2 1/2 in (g) | J56: =G54 -> #DIV/0!
A57: Resolución | C57: =+Balanza!$B$11 -> 0.1 | D57: Rectangular | E57: =(C57/SQRT(3)/2) -> 0.028867513 | I57: =A62 -> Abertura de Tamiz 2 1/2 in (mm) | J57: =G62 -> 0.009
A58: M total (g) | B58: =+Balanza!$C$26 -> FALSE | D58: --- | E58: =SQRT((E59*E59)+(E60*E60)+(E61*E61)) -> 0.070663522 | F58: =(100*B54)/POWER(B58,2) -> #DIV/0! | G58: =(E58*F58) -> #DIV/0! | I58: =A58 -> M total (g) | J58: =G58 -> #DIV/0!
A59: Repetibilidad de la pesada | C59: =+Balanza!$D$26 -> 0 | D59: Normal, K=1 | E59: =C59 -> 0 | I59: =A64 -> Factor de presición 2 1/2 in | J59: =G64 -> 0
A60: Certificado de Calibración | C60: =2*(SQRT(Balanza!$B$9+Balanza!$C$9*(POWER(B58,2)))) -> 0.12899612 | D60: Normal, K=2 | E60: =C60/2 -> 0.064498062
A61: Resolución | C61: =+Balanza!$B$11 -> 0.1 | D61: Rectangular | E61: =(C61/SQRT(3)/2) -> 0.028867513
...

Sheet Balanza
A7: CALIBRACION DE LA BALANZA
A8: Corrección | B8: -3.29e-06
A9: Variables | B9: 0.00416 | C9: 2.43e-10
A10: Ecuación | B10: 2*RAIZ(0.00416+0.000000000243*R2)
A11: Resolución | B11: 0.1 | C11: g
A12: Código | B12: EQP-0046
A13: Fecha ultima calibracion | C13: 46132
A15: ITEM | B15: MES | C15: 20 | D15: 200 | E15: 500 | F15: 1000 | G15: 5000 | H15: 10000
B19: DESV STD | C19: 0 | D19: 0 | E19: 0 | F19: 0 | G19: 0 | H19: 0
C21: Busqueda de Repetibilidad de la masa
K22: CALIBRACION TAMICES
C23: =+C15 -> 20 | D23: =+D15 -> 200 | E23: =+E15 -> 500 | F23: =+F15 -> 1000 | G23: =+G15 -> 5000 | H23: =+H15 -> 10000
C24: =C19 -> 0 | D24: =D19 -> 0 | E24: =E19 -> 0 | F24: =F19 -> 0 | G24: =G19 -> 0 | H24: =H19 -> 0 | K24: Fecha de Calibracion: | M24: 44628
B26: M. total | C26: =+datos!E19 -> FALSE | D26: =IF(C26<=$C$23,$C$24,IF(AND(C26>$C$23,C26<=$D$23),$D$24,IF(AND(C26>$D$23,C26<=$E$23),$E$24,IF(AND(C26>$E$23,C26<=$F$23),$F$24,IF(AND(C26>$F$23,C26<=$G$23),$G$24,IF(AND(C26>$G$23,C26<=$H$23),$H$24,$H$24)))))) -> 0
B27: =+datos!C10 -> - | C27: =+datos!E20 -> FALSE | D27: =IF(C27<=$C$23,$C$24,IF(AND(C27>$C$23,C27<=$D$23),$D$24,IF(AND(C27>$D$23,C27<=$E$23),$E$24,IF(AND(C27>$E$23,C27<=$F$23),$F$24,IF(AND(C27>$F$23,C27<=$G$23),$G$24,IF(AND(C27>$G$23,C27<=$H$23),$H$24,$H$24)))))) -> 0 | K27: TAMIZ | L27: U(x) (mm) | M27: Datos del certificado
B28: TAMICES | C28: Masa Retenida (g) | D28: Retenida Acumulado (g) | E28: Repetib. | K28: 3 " | L28: =M28/1000 -> 0.018 | M28: 18 | N28: um
K29: 2 1/2 " | L29: =M29/1000 -> 0.018 | M29: 18 | N29: um
B30: 3 " | C30: =+datos!E28 -> 0 | D30: =C30 -> 0 | E30: =IF(D30<=$C$23,$C$24,IF(AND(D30>$C$23,D30<=$D$23),$D$24,IF(AND(D30>$D$23,D30<=$E$23),$E$24,IF(AND(D30>$E$23,D30<=$F$23),$F$24,IF(AND(D30>$F$23,D30<=$G$23),$G$24,IF(AND(D30>$G$23,D30<=$H$23),$H$24,$H$24)))))) -> 0 | K30: 2 " | L30: =M30/1000 -> 0.018 | M30: 18 | N30: um
B31: 2 1/2 " | C31: =+datos!E29 -> 0 | D31: =D30+C31 -> 0 | E31: =IF(D31<=$C$23,$C$24,IF(AND(D31>$C$23,D31<=$D$23),$D$24,IF(AND(D31>$D$23,D31<=$E$23),$E$24,IF(AND(D31>$E$23,D31<=$F$23),$F$24,IF(AND(D31>$F$23,D31<=$G$23),$G$24,IF(AND(D31>$G$23,D31<=$H$23),$H$24,$H$24)))))) -> 0 | K31: 1 1/2 " | L31: =M31/1000 -> 0.018 | M31: 18 | N31: um
B32: 2 " | C32: =+datos!E30 -> 0 | D32: =D31+C32 -> 0 | E32: =IF(D32<=$C$23,$C$24,IF(AND(D32>$C$23,D32<=$D$23),$D$24,IF(AND(D32>$D$23,D32<=$E$23),$E$24,IF(AND(D32>$E$23,D32<=$F$23),$F$24,IF(AND(D32>$F$23,D32<=$G$23),$G$24,IF(AND(D32>$G$23,D32<=$H$23),$H$24,$H$24)))))) -> 0 | K32: 1 " | L32: =M32/1000 -> 0.018 | M32: 18 | N32: um
B33: 1 1/2 " | C33: =+datos!E31 -> 0 | D33: =D32+C33 -> 0 | E33: =IF(D33<=$C$23,$C$24,IF(AND(D33>$C$23,D33<=$D$23),$D$24,IF(AND(D33>$D$23,D33<=$E$23),$E$24,IF(AND(D33>$E$23,D33<=$F$23),$F$24,IF(AND(D33>$F$23,D33<=$G$23),$G$24,IF(AND(D33>$G$23,D33<=$H$23),$H$24,$H$24)))))) -> 0 | K33: 3/4" | L33: =M33/1000 -> 0.018 | M33: 18 | N33: um
B34: 1 " | C34: =+datos!E32 -> 0 | D34: =D33+C34 -> 0 | E34: =IF(D34<=$C$23,$C$24,IF(AND(D34>$C$23,D34<=$D$23),$D$24,IF(AND(D34>$D$23,D34<=$E$23),$E$24,IF(AND(D34>$E$23,D34<=$F$23),$F$24,IF(AND(D34>$F$23,D34<=$G$23),$G$24,IF(AND(D34>$G$23,D34<=$H$23),$H$24,$H$24)))))) -> 0 | K34: 1/2" | L34: =M34/1000 -> 0.018 | M34: 18 | N34: um
B35: 3/4" | C35: =+datos!E33 -> 0 | D35: =D34+C35 -> 0 | E35: =IF(D35<=$C$23,$C$24,IF(AND(D35>$C$23,D35<=$D$23),$D$24,IF(AND(D35>$D$23,D35<=$E$23),$E$24,IF(AND(D35>$E$23,D35<=$F$23),$F$24,IF(AND(D35>$F$23,D35<=$G$23),$G$24,IF(AND(D35>$G$23,D35<=$H$23),$H$24,$H$24)))))) -> 0 | K35: 3/8" | L35: =M35/1000 -> 0.018 | M35: 18 | N35: um
B36: 1/2" | C36: =+datos!E34 -> 0 | D36: =D35+C36 -> 0 | E36: =IF(D36<=$C$23,$C$24,IF(AND(D36>$C$23,D36<=$D$23),$D$24,IF(AND(D36>$D$23,D36<=$E$23),$E$24,IF(AND(D36>$E$23,D36<=$F$23),$F$24,IF(AND(D36>$F$23,D36<=$G$23),$G$24,IF(AND(D36>$G$23,D36<=$H$23),$H$24,$H$24)))))) -> 0 | K36: No.4 | L36: =M36/1000 -> 0.018 | M36: 18 | N36: um
B37: 3/8" | C37: =+datos!E35 -> 0 | D37: =D36+C37 -> 0 | E37: =IF(D37<=$C$23,$C$24,IF(AND(D37>$C$23,D37<=$D$23),$D$24,IF(AND(D37>$D$23,D37<=$E$23),$E$24,IF(AND(D37>$E$23,D37<=$F$23),$F$24,IF(AND(D37>$F$23,D37<=$G$23),$G$24,IF(AND(D37>$G$23,D37<=$H$23),$H$24,$H$24)))))) -> 0 | K37: No.8 | L37: =M37/1000 -> 0.0065 | M37: 6.5 | N37: um
B38: No.4 | C38: =+datos!E36 -> 0 | D38: =D37+C38 -> 0 | E38: =IF(D38<=$C$23,$C$24,IF(AND(D38>$C$23,D38<=$D$23),$D$24,IF(AND(D38>$D$23,D38<=$E$23),$E$24,IF(AND(D38>$E$23,D38<=$F$23),$F$24,IF(AND(D38>$F$23,D38<=$G$23),$G$24,IF(AND(D38>$G$23,D38<=$H$23),$H$24,$H$24)))))) -> 0 | K38: No.10 | L38: =M38/1000 -> 0.011 | M38: 11 | N38: um
B39: No.8 | C39: =+datos!E37 -> 0 | D39: =IF(B27="Fraccionada",C39,D38+C39) -> 0 | E39: =IF(D39<=$C$23,$C$24,IF(AND(D39>$C$23,D39<=$D$23),$D$24,IF(AND(D39>$D$23,D39<=$E$23),$E$24,IF(AND(D39>$E$23,D39<=$F$23),$F$24,IF(AND(D39>$F$23,D39<=$G$23),$G$24,IF(AND(D39>$G$23,D39<=$H$23),$H$24,$H$24)))))) -> 0 | K39: No.16 | L39: =M39/1000 -> 0.0054 | M39: 5.4 | N39: um
B40: No.10 | C40: =+datos!E38 -> 0 | D40: =D39+C40 -> 0 | E40: =IF(D40<=$C$23,$C$24,IF(AND(D40>$C$23,D40<=$D$23),$D$24,IF(AND(D40>$D$23,D40<=$E$23),$E$24,IF(AND(D40>$E$23,D40<=$F$23),$F$24,IF(AND(D40>$F$23,D40<=$G$23),$G$24,IF(AND(D40>$G$23,D40<=$H$23),$H$24,$H$24)))))) -> 0 | K40: No.30 | L40: =M40/1000 -> 0.0035 | M40: 3.5 | N40: um
B41: No.16 | C41: =+datos!E39 -> 0 | D41: =D40+C41 -> 0 | E41: =IF(D41<=$C$23,$C$24,IF(AND(D41>$C$23,D41<=$D$23),$D$24,IF(AND(D41>$D$23,D41<=$E$23),$E$24,IF(AND(D41>$E$23,D41<=$F$23),$F$24,IF(AND(D41>$F$23,D41<=$G$23),$G$24,IF(AND(D41>$G$23,D41<=$H$23),$H$24,$H$24)))))) -> 0 | K41: No.40 | L41: =M41/1000 -> 0.0027 | M41: 2.7 | N41: um
B42: No. 30 | C42: =+datos!E40 -> 0 | D42: =D41+C42 -> 0 | E42: =IF(D42<=$C$23,$C$24,IF(AND(D42>$C$23,D42<=$D$23),$D$24,IF(AND(D42>$D$23,D42<=$E$23),$E$24,IF(AND(D42>$E$23,D42<=$F$23),$F$24,IF(AND(D42>$F$23,D42<=$G$23),$G$24,IF(AND(D42>$G$23,D42<=$H$23),$H$24,$H$24)))))) -> 0 | K42: No.50 | L42: =M42/1000 -> 0.0025 | M42: 2.5 | N42: um
B43: No.40 | C43: =+datos!E41 -> 0 | D43: =D42+C43 -> 0 | E43: =IF(D43<=$C$23,$C$24,IF(AND(D43>$C$23,D43<=$D$23),$D$24,IF(AND(D43>$D$23,D43<=$E$23),$E$24,IF(AND(D43>$E$23,D43<=$F$23),$F$24,IF(AND(D43>$F$23,D43<=$G$23),$G$24,IF(AND(D43>$G$23,D43<=$H$23),$H$24,$H$24)))))) -> 0 | K43: No.100 | L43: =M43/1000 -> 0.0013 | M43: 1.3 | N43: um
B44: No.50 | C44: =+datos!E42 -> 0 | D44: =D43+C44 -> 0 | E44: =IF(D44<=$C$23,$C$24,IF(AND(D44>$C$23,D44<=$D$23),$D$24,IF(AND(D44>$D$23,D44<=$E$23),$E$24,IF(AND(D44>$E$23,D44<=$F$23),$F$24,IF(AND(D44>$F$23,D44<=$G$23),$G$24,IF(AND(D44>$G$23,D44<=$H$23),$H$24,$H$24)))))) -> 0 | K44: No. 200 | L44: =M44/1000 -> 0.0013 | M44: 1.3
B45: No.100 | C45: =+datos!E43 -> 0 | D45: =D44+C45 -> 0 | E45: =IF(D45<=$C$23,$C$24,IF(AND(D45>$C$23,D45<=$D$23),$D$24,IF(AND(D45>$D$23,D45<=$E$23),$E$24,IF(AND(D45>$E$23,D45<=$F$23),$F$24,IF(AND(D45>$F$23,D45<=$G$23),$G$24,IF(AND(D45>$G$23,D45<=$H$23),$H$24,$H$24)))))) -> 0
B46: No. 200 | C46: =+datos!E44 -> 0 | D46: =D45+C46 -> 0 | E46: =IF(D46<=$C$23,$C$24,IF(AND(D46>$C$23,D46<=$D$23),$D$24,IF(AND(D46>$D$23,D46<=$E$23),$E$24,IF(AND(D46>$E$23,D46<=$F$23),$F$24,IF(AND(D46>$F$23,D46<=$G$23),$G$24,IF(AND(D46>$G$23,D46<=$H$23),$H$24,$H$24)))))) -> 0
B49: DATA DE ASEGURAMIENTO
B50: Fecha evaluacion | D50: 46142
A52: TAMIZ | B52: Desviacion Estándar Repetibilidad (Sr) | C52: Desviacion Estándar Reproducibilidad (SR)
A53: 3 " | B53: 0 | C53: 0
A54: 2 1/2 " | B54: 0 | C54: 0
A55: 2 " | B55: 0 | C55: 0
...

Sheet ASFALTO
A5: LABORATORIO DE ENSAYO DE MATERIALES
A6: =+K12 -> 32 | S6: Informacion para la Correccion por Certificado de Calibración:
S7: Codigo de Balanza al 0.1g | U7: Variable 1
S8: CODIGO | U8: 5.17e-07
A9: CLIENTE | B9: : | C9: METRO | S9: Fecha | T9: 44090
A10: DIRECCION ** | B10: : | C10: LIMA - AV. JAGSKSHD / PONER LA DIRECCION O DIRECCION FISCAL | J10: CÓDIGO | K10: F-LEM-P-AG-03.02
A11: PROYECTO ** | B11: : | C11: CONJUNTO RESIDENCIAL SAN BORJA HOMETOWN | J11: N° OT | K11: 122
A12: UBICACIÓN ** | B12: : | C12: CA. DURERO CDRA. 4 S/N, ALT. LA CDRA 13 DE LA AV. SAN | J12: N° INFORME. | K12: 32
A13: ** Datos proporcionados por el cliente
A14: Standard Test Method for Sieve Analysis of Fine and Coarse Aggregates
A15: ASTM C136/C136M − 19
A17: DATOS DE LA MUESTRA
A18: CANTERA / SONDAJE ** | B18: : | C18: C-1 | J18: CODIGO DE LA MUESTRA: | K18: 83
A19: N° MUESTRA ** | B19: : | C19: M-1 | J19: FECHA DE RECEPCIÓN: | K19: 43831 | U19: Malla | W19: CORRECCION | X19: Peso (gr) | Y19: Ret. Parcial (%) | Z19: Ret Acum. (%) | AA19: que Pasa (%)
A20: TIPO DE MUESTRA** | B20: : | C20: SUELO | J20: FECHA DE EJECUCIÓN: | K20: 43844 | U20: Tamiz | V20: mm.
A21: LUGAR DE ENSAYO | B21: : | C21: Laboratorio de Ensayo de Materiales | J21: FECHA DE EMISIÓN: | K21: 43845 | N21: Peso Grueso | P21: 10134 | Q21: =P21 -> 10134 | U21: 1 1/2" | V21: 38.1 | W21: =X21-($U$8*X21) -> 0 | X21: 0
N22: Peso Fino | P22: 14028 | Q22: =P22/(1+P27/100) -> 13849.98 | U22: 1" | V22: 25.4 | W22: =X22-($U$8*X22) -> 0 | X22: 0
B23: Malla | D23: Peso (gr) | E23: Ret. Parcial (%) | F23: Ret Acum. (%) | G23: que Pasa (%) | I23: Peso Inicial (gr) | N23: Peso Total | Q23: =SUM(Q21:Q22) -> 23983.98 | U23: 3/4" | V23: 19.05 | W23: =X23-($U$8*X23) -> 0 | X23: 0 | AA23: =100-Z23 -> 100
B24: Tamiz | C24: mm. | I24: =+Q23 -> 23983.98 | U24: 1/2" | V24: 12.7 | W24: =X24-($U$8*X24) -> 2855.9985 | X24: 2856 | Y24: =(W24/$I$24)*100 -> 11.907943 | Z24: =+Z23+Y24 -> 11.907943 | AA24: =100-Z24 -> 88.092057
B25: 1 1/2" | C25: 38.1 | D25: =W21 -> 0 | E25: =(D25/$I$24)*100 -> 0 | F25: =+F24+E25 -> 0 | N25: Peso Humedo | P25: 1221.4 | U25: 3/8" | V25: 9.525 | W25: =X25-($U$8*X25) -> 2663.9986 | X25: 2664 | Y25: =(W25/$I$24)*100 -> 11.107409 | Z25: =+Z24+Y25 -> 23.015351 | AA25: =100-Z25 -> 76.984649
B26: 1" | C26: 25.4 | D26: =W22 -> 0 | E26: =(D26/$I$24)*100 -> 0 | F26: =+F25+E26 -> 0 | I26: Distribusion | N26: Peso Seco | P26: 1205.9 | Q26: =Q22/P26 -> 11.485181 | U26: N°4 | V26: 4.76 | W26: =X26-($U$8*X26) -> 4613.9976 | X26: 4614 | Y26: =(W26/$I$24)*100 -> 19.237832 | Z26: =+Z25+Y26 -> 42.253183 | AA26: =100-Z26 -> 57.746817
B27: 3/4" | C27: 19.05 | D27: =W23 -> 0 | E27: =(D27/$I$24)*100 -> 0 | F27: =+F26+E27 -> 0 | G27: =100-F27 -> 100 | I27: Grava | J27: =+F30 -> 42.253183 | N27: Humedad | P27: =((P25-P26)/P26)*100 -> 1.285347 | U27: N° 10 | V27: 2 | W27: =X27-($U$8*X27) -> 402.69979 | X27: 402.7 | Y27: =W27*$G$30/$P$26 -> 19.284046 | Z27: =+Z26+Y27 -> 61.537229 | AA27: =100-Z27 -> 38.462771
B28: 1/2" | C28: 12.7 | D28: =W24 -> 2855.9985 | E28: =(D28/$I$24)*100 -> 11.907943 | F28: =+F27+E28 -> 11.907943 | G28: =100-F28 -> 88.092057 | I28: Arena | J28: =+G30 -> 57.746817 | U28: N° 40 | V28: 0.425 | W28: =X28-($U$8*X28) -> 405.29979 | X28: 405.3 | Y28: =W28*$G$30/$P$26 -> 19.408552 | Z28: =+Z27+Y28 -> 80.945781 | AA28: =100-Z28 -> 19.054219
B29: 3/8" | C29: 9.525 | D29: =W25 -> 2663.9986 | E29: =(D29/$I$24)*100 -> 11.107409 | F29: =+F28+E29 -> 23.015351 | G29: =100-F29 -> 76.984649 | U29: N° 80 | V29: 0.18 | W29: =X29-($U$8*X29) -> 132.69993 | X29: 132.7 | Y29: =W29*$G$30/$P$26 -> 6.3545888 | Z29: =+Z28+Y29 -> 87.30037 | AA29: =100-Z29 -> 12.69963
B30: N°4 | C30: 4.76 | D30: =W26 -> 4613.9976 | E30: =(D30/$I$24)*100 -> 19.237832 | F30: =+F29+E30 -> 42.253183 | G30: =100-F30 -> 57.746817 | M30: MAC - 2 | U30: N° 200 | V30: 0.074 | W30: =X30-($U$8*X30) -> 126.89993 | X30: 126.9 | Y30: =W30*$G$30/$P$26 -> 6.076845 | Z30: =+Z29+Y30 -> 93.377215 | AA30: =100-Z30 -> 6.6227852
B31: N° 10 | C31: 2 | D31: =W27 -> 402.69979 | E31: =D31*$G$30/$P$26 -> 19.284046 | F31: =+F30+E31 -> 61.537229 | G31: =100-F31 -> 38.462771 | M31: Especicifaciones | U31: < 200 | V31: - | W31: =X31-($U$8*X31) -> 138.29993 | X31: =(P26)-SUM(X27:X30) -> 138.3 | Y31: =W31*$G$30/$P$26 -> 6.6227554 | Z31: =+Z30+Y31 -> 99.99997
B32: N° 40 | C32: 0.425 | D32: =W28 -> 405.29979 | E32: =D32*$G$30/$P$26 -> 19.408552 | F32: =+F31+E32 -> 80.945781 | G32: =100-F32 -> 19.054219 | N32: tamiz | O32: Mín. | P32: Máx. | U32: Nota: Si la malla 200 tiene menos del 10% retenido se reportara al 0.1%
B33: N° 80 | C33: 0.18 | D33: =W29 -> 132.69993 | E33: =D33*$G$30/$P$26 -> 6.3545888 | F33: =+F32+E33 -> 87.30037 | G33: =100-F33 -> 12.69963 | M33: =+B25 -> 1 1/2" | N33: =+C25 -> 38.1 | U33: Si la malla 200 tiene mas del 10% retenido se reporta al 1%
B34: N° 200 | C34: 0.074 | D34: =W30 -> 126.89993 | E34: =D34*$G$30/$P$26 -> 6.076845 | F34: =+F33+E34 -> 93.377215 | G34: =100-F34 -> 6.6227852 | M34: =+B26 -> 1" | N34: =+C26 -> 25.4 | T34: =+C26 -> 25.4 | U34: =+T34 -> 25.4 | Z34: faja de trabajo
B35: < 200 | C35: - | D35: =W31 -> 138.29993 | E35: =D35*$G$30/$P$26 -> 6.6227554 | F35: =+F34+E35 -> 99.99997 | M35: =+B27 -> 3/4" | N35: =+C27 -> 19.05 | O35: 100 | P35: 100 | T35: =+C27 -> 19.05 | U35: =+T35 -> 19.05 | Z35: 100 | AA35: 100 | AB35: 100
M36: =+B28 -> 1/2" | N36: =+C28 -> 12.7 | O36: 80 | P36: 100 | T36: =+C28 -> 12.7 | U36: =+T36 -> 12.7 | AA36: 88.9
M37: =+B29 -> 3/8" | N37: =+C29 -> 9.525 | O37: 70 | P37: 88 | T37: =+C29 -> 9.525 | AA37: 78.8
M38: =+B30 -> N°4 | N38: =+C30 -> 4.76 | O38: 51 | P38: 68 | T38: =+C30 -> 4.76 | U38: =+T38 -> 4.76 | AA38: 58.6
M39: =+B31 -> N° 10 | N39: =+C31 -> 2 | O39: 38 | P39: 52 | T39: =+C31 -> 2 | U39: =+T39 -> 2 | AA39: 42.8
M40: =+B32 -> N° 40 | N40: =+C32 -> 0.425 | O40: 17 | P40: 28 | T40: =+C32 -> 0.425 | U40: =+T40 -> 0.425 | AA40: 21
M41: =+B33 -> N° 80 | N41: =+C33 -> 0.18 | O41: 8 | P41: 17 | T41: =+C33 -> 0.18 | U41: =+T41 -> 0.18 | AA41: 11.5
M42: =+B34 -> N° 200 | N42: =+C34 -> 0.074 | O42: 4 | P42: 8 | T42: =+C34 -> 0.074 | U42: =+T42 -> 0.074 | AA42: 5.9
A52: Nota :
A56: Página 1 de 1
A57: Versión : 02 (02-01-2021)
...

Sheet FINO
A7: LABORATORIO DE ENSAYO DE MATERIALES
A8: 1
A10: CLIENTE | B10: METRO
A11: DIRECCION ** | B11: LIMA - AV. JAGSKSHD / PONER LA DIRECCION O DIRECCION FISCAL | J11: CÓDIGO: | K11: F-LEM-P-AG-19.02
A12: PROYECTO ** | B12: CONJUNTO RESIDENCIAL SAN BORJA HOMETOWN | J12: N° OT: | K12: 122
A13: UBICACIÓN ** | B13: CA. DURERO CDRA. 4 S/N, ALT. LA CDRA 13 DE LA AV. SAN | J13: F. EMISIÓN: | K13: 43845 | M13: Malla | O13: Especificaciones ASTM C-33
A14: ** Datos proporcionados por el cliente | M14: Tamiz | N14: mm.
A15: Standard Test Method for Sieve Analysis of Fine and Coarse Aggregates | M15: 3/8" | N15: 9.525
A16: ASTM C136/C136M − 19 | M16: No4 | N16: 4.76
M17: 8 | N17: 2.36
A18: DATOS DE LA MUESTRA | M18: 16 | N18: 1.19
A19: CANTERA / SONDAJE **: | C19: C-1 | J19: CODIGO DE LA MUESTRA: | K19: 83 | M19: 30 | N19: 0.6
A20: N° MUESTRA **: | C20: M-1 | J20: FECHA DE RECEPCIÓN: | K20: 43831 | M20: 50 | N20: 0.3
A21: TIPO DE MUESTRA**: | C21: SUELO | J21: FECHA DE EJECUCIÓN: | K21: 43844 | M21: 100 | N21: 0.149
A22: LUGAR DE ENSAYO: | C22: Laboratorio de Ensayo de Materiales
M24: Peso inicial | P24: 762
B25: Malla | D25: Peso (gr) | E25: Ret. Parcial (%) | F25: Ret Acum. (%) | G25: que Pasa (%) | I25: Peso Inicial (gr) | M25: Malla | O25: CORRECCION | P25: Peso | Q25: % Ret | R25: % Ret | S25: % que
B26: Tamiz | C26: mm. | I26: =+P24 -> 762 | M26: Tamiz | N26: mm. | P26: (gr) | Q26: Parcial | R26: Acum. | S26: Pasa
B27: 3/8" | C27: 9.525 | D27: =SUM(O27:O34) -> #REF! | E27: =D27/$I$26*100 -> #REF! | F27: =E27 -> #REF! | G27: =100-F27 -> #REF! | M27: 3" | N27: 76.2 | O27: =P27-(Y53*P27) -> #REF! | P27: =+#REF! -> #REF! | Q27: =O27/$I$26*100 -> #REF! | R27: =Q27 -> #REF! | S27: =100-R27 -> #REF!
B28: No4 | C28: 4.76 | D28: =SUM(O35:O36) -> 9.3 | E28: =D28/$I$26*100 -> 1.2204724 | F28: =F27+E28 -> #REF! | G28: =100-F28 -> #REF! | I28: Mod. Fineza | M28: 2 1/2" | N28: 63.5 | O28: =P28-(Y54*P28) -> #REF! | P28: =+#REF! -> #REF! | Q28: =O28/$I$26*100 -> #REF! | R28: =R27+Q28 -> #REF! | S28: =100-R28 -> #REF!
B29: 8 | C29: 2.36 | D29: =+O37 -> 70.4 | E29: =D29/$I$26*100 -> 9.2388451 | F29: =F28+E29 -> #REF! | G29: =100-F29 -> #REF! | I29: =(R30+R32+R34+R36+R37+R39+R40+R42+R43)/100 -> #REF! | M29: 2" | N29: 50.6 | O29: =P29-(Y55*P29) -> #REF! | P29: =+#REF! -> #REF! | Q29: =O29/$I$26*100 -> #REF! | R29: =R28+Q29 -> #REF! | S29: =100-R29 -> #REF!
B30: 16 | C30: 1.19 | D30: =SUM(O38:O39) -> 165.1 | E30: =D30/$I$26*100 -> 21.666667 | F30: =F29+E30 -> #REF! | G30: =100-F30 -> #REF! | M30: 1 1/2" | N30: 38.1 | O30: =P30-(Y56*P30) -> #REF! | P30: =+#REF! -> #REF! | Q30: =O30/$I$26*100 -> #REF! | R30: =R29+Q30 -> #REF! | S30: =100-R30 -> #REF!
B31: 30 | C31: 0.6 | D31: =+O40 -> 197.8 | E31: =D31/$I$26*100 -> 25.958005 | F31: =F30+E31 -> #REF! | G31: =100-F31 -> #REF! | M31: 1" | N31: 25.4 | O31: =P31-(Y58*P31) -> 0 | P31: 0 | Q31: =O31/$I$26*100 -> 0 | R31: =R30+Q31 -> #REF! | S31: =100-R31 -> #REF!
B32: 50 | C32: 0.3 | D32: =SUM(O41:O42) -> 154.9 | E32: =D32/$I$26*100 -> 20.328084 | F32: =F31+E32 -> #REF! | G32: =100-F32 -> #REF! | M32: 3/4" | N32: 19.05 | O32: =P32-(Y59*P32) -> 0 | P32: 0 | Q32: =O32/$I$26*100 -> 0 | R32: =R31+Q32 -> #REF! | S32: =100-R32 -> #REF!
B33: 100 | C33: 0.149 | D33: =+O43 -> 86.2 | E33: =D33/$I$26*100 -> 11.312336 | F33: =F32+E33 -> #REF! | G33: =100-F33 -> #REF! | M33: 1/2" | N33: 12.7 | O33: =P33-(Y60*P33) -> 0 | P33: 0 | Q33: =O33/$I$26*100 -> 0 | R33: =R32+Q33 -> #REF! | S33: =100-R33 -> #REF!
B34: 200 | C34: 0.074 | D34: =+O44 -> 28.6 | E34: =D34/$I$26*100 -> 3.7532808 | F34: =F33+E34 -> #REF! | G34: =100-F34 -> #REF! | M34: 3/8" | N34: 9.525 | O34: =P34-(Y61*P34) -> 0 | P34: 0 | Q34: =O34/$I$26*100 -> 0 | R34: =R33+Q34 -> #REF! | S34: =100-R34 -> #REF!
B35: Fondo | D35: =I26-SUM(D27:D34) -> #REF! | E35: =D35/$I$26*100 -> #REF! | F35: =F34+E35 -> #REF! | M35: 1/4" | N35: 6.35 | O35: =P35-(Y62*P35) -> 0 | P35: 0 | Q35: =O35/$I$26*100 -> 0 | R35: =R34+Q35 -> #REF! | S35: =100-R35 -> #REF!
M36: No4 | N36: 4.76 | O36: =P36-(Y63*P36) -> 9.3 | P36: 9.3 | Q36: =O36/$I$26*100 -> 1.2204724 | R36: =R35+Q36 -> #REF! | S36: =100-R36 -> #REF!
M37: 8 | N37: 2.36 | O37: =P37-(Y64*P37) -> 70.4 | P37: 70.4 | Q37: =O37/$I$26*100 -> 9.2388451 | R37: =R36+Q37 -> #REF! | S37: =100-R37 -> #REF!
M38: 10 | N38: 2 | O38: =P38-(Y65*P38) -> 30.5 | P38: 30.5 | Q38: =O38/$I$26*100 -> 4.0026247 | R38: =R37+Q38 -> #REF! | S38: =100-R38 -> #REF!
M39: 16 | N39: 1.19 | O39: =P39-(Y66*P39) -> 134.6 | P39: 134.6 | Q39: =O39/$I$26*100 -> 17.664042 | R39: =R38+Q39 -> #REF! | S39: =100-R39 -> #REF!
M40: 30 | N40: 0.6 | O40: =P40-(Y67*P40) -> 197.8 | P40: 197.8 | Q40: =O40/$I$26*100 -> 25.958005 | R40: =R39+Q40 -> #REF! | S40: =100-R40 -> #REF!
M41: 40 | N41: 0.42 | O41: =P41-(Y68*P41) -> 92.7 | P41: 92.7 | Q41: =O41/$I$26*100 -> 12.165354 | R41: =R40+Q41 -> #REF! | S41: =100-R41 -> #REF!
M42: 50 | N42: 0.3 | O42: =P42-(Y69*P42) -> 62.2 | P42: 62.2 | Q42: =O42/$I$26*100 -> 8.1627297 | R42: =R41+Q42 -> #REF! | S42: =100-R42 -> #REF!
M43: 100 | N43: 0.149 | O43: =P43-(Y70*P43) -> 86.2 | P43: 86.2 | Q43: =O43/$I$26*100 -> 11.312336 | R43: =R42+Q43 -> #REF! | S43: =100-R43 -> #REF!
M44: 200 | N44: 0.074 | O44: =P44-(Y71*P44) -> 28.6 | P44: 28.6 | Q44: =O44/$I$26*100 -> 3.7532808 | R44: =R43+Q44 -> #REF! | S44: =100-R44 -> #REF!
M45: < 200 | N45: 0.01 | O45: =P45-(Y72*P45) -> #REF! | P45: =I26-SUM(P27:P44) -> #REF! | Q45: =O45/$I$26*100 -> #REF! | R45: =R44+Q45 -> #REF!
M47: Nota: Si la malla 200 tiene menos del 10% retenido se reportara al 0.1%
M48: Si la malla 200 tiene mas del 10% retenido se reporta al 1%
A51: Página 1 de 2 | W51: Informacion para la Correccion por Certificado de Calibración:
...

Sheet GRAVA
A5: LABORATORIO DE ENSAYO DE MATERIALES
A6: =+K12 -> 44 | Q6: Informacion para la Correccion por Certificado de Calibración:
Q7: Codigo de Balanza al 0.1g | S7: Variable 1
Q8: CODIGO | S8: 5.17e-07
A9: CLIENTE | B9: METRO | Q9: Fecha | R9: 44090
A10: DIRECCION ** | B10: LIMA - AV. JAGSKSHD / PONER LA DIRECCION O DIRECCION FISCAL | J10: CÓDIGO | K10: F-LEM-P-AG-03.02
A11: PROYECTO ** | B11: CONJUNTO RESIDENCIAL SAN BORJA HOMETOWN | J11: N° OT | K11: 202
A12: UBICACIÓN ** | B12: CA. DURERO CDRA. 4 S/N, ALT. LA CDRA 13 DE LA AV. SAN | J12: N° INFORME. | K12: 44
A13: ** Datos proporcionados por el cliente
A14: Standard Test Method for Sieve Analysis of Fine and Coarse Aggregates
A15: ASTM C136/C136M − 19
A17: DATOS DE LA MUESTRA | J17: CODIGO DE LA MUESTRA: | K17: 83
A18: CANTERA / SONDAJE ** | C18: C-1 | J18: FECHA DE RECEPCIÓN: | K18: 43831
A19: N° MUESTRA ** | C19: M-1 | J19: FECHA DE EJECUCIÓN: | K19: 43844
A20: TIPO DE MUESTRA** | C20: SUELO | J20: FECHA DE EMISIÓN: | K20: 43845
A21: LUGAR DE ENSAYO | C21: Laboratorio de Ensayo de Materiales
M22: Peso inicial | P22: =SUM(O25:O42) -> 9543.9951 | R22: TM | S22: =+Z37 -> 0.75 | AA22: TMN
B23: Malla | D23: Peso (gr) | E23: Ret. Parcial (%) | F23: Ret Acum. (%) | G23: que Pasa (%) | I23: Peso Inicial (gr) | M23: Malla | O23: CORRECCION | P23: Peso | Q23: % Ret | R23: % Ret | S23: % que | AA23: =+Z38 -> 0.5
B24: Tamiz | C24: mm. | I24: =+P22 -> 9543.9951 | M24: Tamiz | N24: mm. | P24: (gr) | Q24: Parcial | R24: Acum. | S24: Pasa
B25: 2 1/2" | C25: 63.5 | D25: =SUM(O25:O26) -> 0 | E25: =D25/$I$24*100 -> 0 | F25: =E25 -> 0 | G25: =100-F25 -> 100 | M25: 3 | N25: 76.2 | O25: =P25-($S$8*P25) -> 0 | P25: 0 | Q25: =O25/$I$24*100 -> 0 | R25: =Q25 -> 0 | S25: =100-R25 -> 100 | U25: =IF(AND(S25<100,R25>=5,R25<=15),M25,"") | W25: =+U25&V25 | X25: =IF(R25>=5,1,0) -> 0 | Y25: =IF(X25=0,1,-0.5) -> 1 | Z25: =Y25 -> 1 | AA25: 3
B26: 2" | C26: 50.6 | D26: =+O27 -> 0 | E26: =D26/$I$24*100 -> 0 | F26: =F25+E26 -> 0 | G26: =100-F26 -> 100 | I26: Mod. Fineza | M26: 2.5 | N26: 63.5 | O26: =P26-($S$8*P26) -> 0 | P26: 0 | Q26: =O26/$I$24*100 -> 0 | R26: =R25+Q26 -> 0 | S26: =100-R26 -> 100 | U26: =IF(AND(S26<100,R26>=5,R26<=15),M26,"") | W26: =+U26&V26 | X26: =IF(R26>=5,1,0) -> 0 | Y26: =IF(X26=0,1,-0.5) -> 1 | Z26: =Z25+Y26 -> 2 | AA26: 2.5
B27: 1 1/2" | C27: 38.1 | D27: =+O28 -> 0 | E27: =D27/$I$24*100 -> 0 | F27: =F26+E27 -> 0 | G27: =100-F27 -> 100 | I27: =(R28+R30+R32+R34+R35+R37+R38+R40+R41)/100 -> 6.8505868 | M27: 2 | N27: 50.6 | O27: =P27-($S$8*P27) -> 0 | P27: 0 | Q27: =O27/$I$24*100 -> 0 | R27: =R26+Q27 -> 0 | S27: =100-R27 -> 100 | U27: =IF(AND(S27<100,R27>=5,R27<=15),M27,"") | W27: =+U27&V27 | X27: =IF(R27>=5,1,0) -> 0 | Y27: =IF(X27=0,1,-0.5) -> 1 | Z27: =Z26+Y27 -> 3 | AA27: 2
B28: 1" | C28: 25.4 | D28: =+O29 -> 0 | E28: =D28/$I$24*100 -> 0 | F28: =F27+E28 -> 0 | G28: =100-F28 -> 100 | M28: 1.5 | N28: 38.1 | O28: =P28-($S$8*P28) -> 0 | P28: 0 | Q28: =O28/$I$24*100 -> 0 | R28: =R27+Q28 -> 0 | S28: =100-R28 -> 100 | U28: =IF(AND(S28<100,R28>=5,R28<=15),M28,"") | W28: =+U28&V28 | X28: =IF(R28>=5,1,0) -> 0 | Y28: =IF(X28=0,1,-0.5) -> 1 | Z28: =Z27+Y28 -> 4 | AA28: 1.5
B29: 3/4" | C29: 19.05 | D29: =+O30 -> 97.999949 | E29: =D29/$I$24*100 -> 1.0268231 | F29: =F28+E29 -> 1.0268231 | G29: =100-F29 -> 98.973177 | I29: TMN | M29: 1 | N29: 25.4 | O29: =P29-($S$8*P29) -> 0 | P29: 0 | Q29: =O29/$I$24*100 -> 0 | R29: =R28+Q29 -> 0 | S29: =100-R29 -> 100 | U29: =IF(AND(S29<100,R29>=5,R29<=15),M29,"") | W29: =+U29&V29 | X29: =IF(R29>=5,1,0) -> 0 | Y29: =IF(X29=0,1,-0.5) -> 1 | Z29: =Z28+Y29 -> 5 | AA29: 1
B30: 1/2" | C30: 12.7 | D30: =+O31 -> 5151.9973 | E30: =D30/$I$24*100 -> 53.981559 | F30: =F29+E30 -> 55.008382 | G30: =100-F30 -> 44.991618 | I30: =+Z38 -> 0.5 | M30: 0.75 | N30: 19.05 | O30: =P30-($S$8*P30) -> 97.999949 | P30: 98 | Q30: =O30/$I$24*100 -> 1.0268231 | R30: =R29+Q30 -> 1.0268231 | S30: =100-R30 -> 98.973177 | U30: =IF(AND(S30<100,R30>=5,R30<=15),M30,"") | W30: =+U30&V30 | X30: =IF(R30>=5,1,0) -> 0 | Y30: =IF(X30=0,1,-0.5) -> 1 | Z30: =Z29+Y30 -> 6 | AA30: 0.75
B31: 3/8" | C31: 9.525 | D31: =+O32 -> 2789.9986 | E31: =D31/$I$24*100 -> 29.233026 | F31: =F30+E31 -> 84.241408 | G31: =100-F31 -> 15.758592 | M31: 0.5 | N31: 12.7 | O31: =P31-($S$8*P31) -> 5151.9973 | P31: 5152 | Q31: =O31/$I$24*100 -> 53.981559 | R31: =R30+Q31 -> 55.008382 | S31: =100-R31 -> 44.991618 | U31: =IF(AND(S31<100,R31>=5,R31<=15),M31,"") | W31: =+U31&V31 | X31: =IF(R31>=5,1,0) -> 1 | Y31: =IF(X31=0,1,-0.5) -> -0.5 | Z31: =Z30+Y31 -> 5.5 | AA31: 0.5
B32: N° 4 | C32: 4.76 | D32: =SUM(O33:O34) -> 1483.9992 | E32: =D32/$I$24*100 -> 15.549036 | F32: =F31+E32 -> 99.790444 | G32: =100-F32 -> 0.20955574 | M32: 0.375 | N32: 9.525 | O32: =P32-($S$8*P32) -> 2789.9986 | P32: 2790 | Q32: =O32/$I$24*100 -> 29.233026 | R32: =R31+Q32 -> 84.241408 | S32: =100-R32 -> 15.758592 | U32: =IF(AND(S32<100,R32>=5,R32<=15),M32,"") | W32: =+U32&V32 | X32: =IF(R32>=5,1,0) -> 1 | Y32: =IF(X32=0,1,-0.5) -> -0.5 | Z32: =Z31+Y32 -> 5 | AA32: 0.375
B33: N°8 | C33: 2.36 | D33: =+O35 -> 19.99999 | E33: =D33/$I$24*100 -> 0.20955574 | F33: =F32+E33 -> 100 | G33: =100-F33 -> 0 | M33: 0.25 | N33: 6.35 | O33: =P33-($S$8*P33) -> 1378.9993 | P33: 1379 | Q33: =O33/$I$24*100 -> 14.448868 | R33: =R32+Q33 -> 98.690277 | S33: =100-R33 -> 1.3097234 | U33: =IF(AND(S33<100,R33>=5,R33<=15),M33,"") | W33: =+U33&V33 | X33: =IF(R33>=5,1,0) -> 1 | Y33: =IF(X33=0,1,-0.5) -> -0.5 | Z33: =Z32+Y33 -> 4.5 | AA33: 0.25
B34: Fondo | D34: =I24-SUM(D25:D33) -> 0 | E34: =D34/$I$24*100 -> 0 | F34: =F33+E34 -> 100 | M34: No4 | N34: 4.76 | O34: =P34-($S$8*P34) -> 104.99995 | P34: 105 | Q34: =O34/$I$24*100 -> 1.1001676 | R34: =R33+Q34 -> 99.790444 | S34: =100-R34 -> 0.20955574 | X34: =IF(R34>=5,1,0) -> 1 | Y34: =IF(X34=0,1,-0.5) -> -0.5 | Z34: =Z33+Y34 -> 4 | AA34: No4
M35: 8 | N35: 2.36 | O35: =P35-($S$8*P35) -> 19.99999 | P35: 20 | Q35: =O35/$I$24*100 -> 0.20955574 | R35: =R34+Q35 -> 100 | S35: =100-R35 -> 0
M36: 10 | N36: 2 | O36: =P36-($S$8*P36) -> 0 | P36: 0 | Q36: =O36/$I$24*100 -> 0 | R36: =R35+Q36 -> 100 | S36: =100-R36 -> 0 | Y36: MAXIMO | Z36: =MAX(Z25:Z34) -> 6
M37: 16 | N37: 1.19 | O37: =P37-($S$8*P37) -> 0 | P37: 0 | Q37: =O37/$I$24*100 -> 0 | R37: =R36+Q37 -> 100 | S37: =100-R37 -> 0 | Y37: TM | Z37: =VLOOKUP(Z36,Z25:AA34,2,0) -> 0.75
M38: 30 | N38: 0.6 | O38: =P38-($S$8*P38) -> 0 | P38: 0 | Q38: =O38/$I$24*100 -> 0 | R38: =R37+Q38 -> 100 | S38: =100-R38 -> 0 | Y38: TMN | Z38: =VLOOKUP(1,X25:AA34,4,0) -> 0.5
M39: 40 | N39: 0.42 | O39: =P39-($S$8*P39) -> 0 | P39: 0 | Q39: =O39/$I$24*100 -> 0 | R39: =R38+Q39 -> 100 | S39: =100-R39 -> 0
M40: 50 | N40: 0.3 | O40: =P40-($S$8*P40) -> 0 | P40: 0 | Q40: =O40/$I$24*100 -> 0 | R40: =R39+Q40 -> 100 | S40: =100-R40 -> 0
M41: 100 | N41: 0.149 | O41: =P41-($S$8*P41) -> 0 | P41: 0 | Q41: =O41/$I$24*100 -> 0 | R41: =R40+Q41 -> 100 | S41: =100-R41 -> 0
M42: 200 | N42: 0.074 | O42: =P42-($S$8*P42) -> 0 | P42: 0 | Q42: =O42/$I$24*100 -> 0 | R42: =R41+Q42 -> 100 | S42: =100-R42 -> 0
M43: < 200 | N43: 0.01 | O43: =P43-($S$8*P43) -> -0.0049342454 | P43: =I24-SUM(P25:P42) -> -0.004934248 | Q43: =O43/$I$24*100 -> -5.17e-05 | R43: =R42+Q43 -> 99.999948
M45: Nota: Si la malla 200 tiene menos del 10% retenido se reportara al 0.1% | N45: Nota: Si la malla 200 tiene menos del 10% retenido se reportara al 0.1%
M46: Si la malla 200 tiene mas del 10% retenido se reporta al 1% | N46: Si la malla 200 tiene mas del 10% retenido se reporta al 1%
...

Sheet TABLA ASTM C-33
B5: ASTM C-33 | H5: ASTM C-33
B6: gradacion arena para concreto | H6: gradacion grava para concreto
B7: Malla | D7: porcentaje que pasa | H7: TMN | S7: 2 | Y7: 1.5 | AH7: 1 | AN7: 0.75 | AQ7: 0.5
H8: USO | J8: 1 | M8: 2 | P8: 3 | S8: 357 | V8: 4 | Y8: 467 | AB8: 5 | AE8: 56 | AH8: 57 | AK8: 6 | AN8: 67 | AQ8: 7 | AT8: 8
B9: Tamiz | C9: mm. | H9: Tamiz | I9: mm. | J9: 3 1/2" @ 1 1/2" | M9: 2 1/2" @ 1 1/2" | P9: 2" @ 1" | S9: 2" @ N°4 | V9: 1 1/2" @ 3/4" | Y9: 1 1/2" @ N°4 | AB9: 1" @ 1/2" | AE9: 1" @ 3/8" | AH9: 1" @ N° 4 | AK9: 3/4" @ 3/8" | AN9: 3/4" @ N° 4 | AQ9: 1/2" @ N° 4 | AT9: 3/8" @ N°8
B10: 3/8" | C10: 9.525 | E10: 100 | H10: 4 | I10: =H10*2.54*10 -> 101.6 | K10: 100
B11: No4 | C11: 4.76 | D11: 95 | F11: 100 | H11: 3.5 | I11: =H11*2.54*10 -> 88.9 | J11: 90 | L11: 100 | BB11: 3 | BC11: =BB11*2.54*10 -> 76.2
B12: 8 | C12: 2.36 | D12: 80 | F12: 100 | H12: 3 | I12: =H12*2.54*10 -> 76.2 | N12: 100 | BB12: 2.5 | BC12: =BB12*2.54*10 -> 63.5
B13: 16 | C13: 1.19 | D13: 50 | F13: 85 | H13: 2.5 | I13: =H13*2.54*10 -> 63.5 | J13: 25 | L13: 60 | M13: 90 | O13: 100 | Q13: 100 | T13: 100 | BB13: 2 | BC13: =BB13*2.54*10 -> 50.8
B14: 30 | C14: 0.6 | D14: 25 | F14: 60 | H14: 2 | I14: =H14*2.54*10 -> 50.8 | M14: 35 | O14: 70 | P14: 90 | R14: 100 | S14: 95 | U14: 100 | W14: 100 | Z14: 100 | BB14: 1.5 | BC14: =BB14*2.54*10 -> 38.1
B15: 50 | C15: 0.3 | D15: 5 | F15: 30 | H15: 1.5 | I15: =H15*2.54*10 -> 38.1 | J15: 0 | L15: 15 | M15: 0 | O15: 15 | P15: 35 | R15: 70 | V15: 90 | X15: 100 | Y15: 95 | AA15: 100 | AC15: 100 | AF15: 100 | AI15: 100 | BB15: 1 | BC15: =BB15*2.54*10 -> 25.4
B16: 100 | C16: 0.149 | D16: 0 | F16: 10 | H16: 1 | I16: =H16*2.54*10 -> 25.4 | P16: 0 | R16: 15 | S16: 32 | U16: 70 | V16: 20 | X16: 55 | AB16: 90 | AD16: 100 | AE16: 90 | AG16: 100 | AH16: 95 | AJ16: 100 | AL16: 100 | AO16: 100 | BB16: 0.75 | BC16: =BB16*2.54*10 -> 19.05
H17: 0.75 | I17: =H17*2.54*10 -> 19.05 | J17: 0 | L17: 5 | M17: 0 | O17: 5 | V17: 0 | X17: 15 | Y17: 35 | AA17: 70 | AB17: 20 | AD17: 55 | AE17: 40 | AG17: 85 | AK17: 90 | AM17: 100 | AN17: 90 | AP17: 100 | AR17: 100 | BB17: 0.5 | BC17: =BB17*2.54*10 -> 12.7
H18: 0.5 | I18: =H18*2.54*10 -> 12.7 | P18: 0 | R18: 5 | S18: 10 | U18: 30 | AB18: 0 | AD18: 10 | AE18: 10 | AG18: 40 | AH18: 25 | AJ18: 60 | AK18: 20 | AM18: 55 | AQ18: 90 | AS18: 100 | AU18: 100 | BB18: 0.375 | BC18: =BB18*2.54*10 -> 9.525
H19: 0.375 | I19: =H19*2.54*10 -> 9.525 | V19: 0 | X19: 5 | Y19: 10 | AA19: 30 | AB19: 0 | AD19: 5 | AE19: 0 | AG19: 15 | AK19: 0 | AM19: 15 | AN19: 20 | AP19: 55 | AQ19: 40 | AS19: 70 | AT19: 85 | AV19: 100 | BB19: 0.25 | BC19: =BB19*2.54*10 -> 6.35
H20: N° 4 | I20: 4.76 | S20: 0 | U20: 5 | Y20: 0 | AA20: 5 | AE20: 0 | AG20: 5 | AH20: 0 | AJ20: 10 | AK20: 0 | AM20: 5 | AN20: 0 | AP20: 10 | AQ20: 0 | AS20: 10 | AT20: 10 | AV20: 30 | BB20: No4 | BC20: 4.76
H21: N° 8 | I21: 2.36 | AH21: 0 | AJ21: 5 | AN21: 0 | AP21: 5 | AQ21: 0 | AS21: 5 | AT21: 0 | AV21: 10 | BB21: 8 | BC21: 2.36
H22: N° 16 | I22: 1.19 | AT22: 0 | AV22: 5 | BB22: 10 | BC22: 2
H23: N° 50 | I23: 0.3 | BB23: 16 | BC23: 1.19
BB24: 30 | BC24: 0.6
H25: TMN | I25: 0.75 | J25: porcentaje que pasa | AI25: 2 | BB25: 40 | BC25: 0.42
H26: Tamiz | I26: mm. | S26: que Pasa (%) | AI26: 1.5 | BB26: 50 | BC26: 0.3
H27: =IF($I$25=2,H13,IF($I$25=1.5,H14,IF($I$25=1,H15,IF($I$25=0.75,H16,IF($I$25=0.5,H17))))) -> 1 | I27: =H27*2.54*10 -> 25.4 | T27: 100 | AI27: 1 | BB27: 100 | BC27: 0.149
H28: =IF($I$25=2,H14,IF($I$25=1.5,H15,IF($I$25=1,H16,IF($I$25=0.75,H17,IF($I$25=0.5,H18))))) -> 0.75 | I28: =H28*2.54*10 -> 19.05 | K28: 100 | S28: =IF($I$25=2,S14,IF($I$25=1.5,Y15,IF($I$25=1,AH16,IF($I$25=0.75,AN17,IF($I$25=0.5,AQ18))))) -> 90 | U28: =IF($I$25=2,U14,IF($I$25=1.5,AA15,IF($I$25=1,AJ16,IF($I$25=0.75,AP17,IF($I$25=0.5,AS18))))) -> 100 | AI28: 0.75 | BB28: 200 | BC28: 0.074
H29: =IF($I$25=2,H16,IF($I$25=1.5,H17,IF($I$25=1,H18,IF($I$25=0.75,H19,IF($I$25=0.5,H19))))) -> 0.375 | I29: =H29*2.54*10 -> 9.525 | J29: 95 | L29: 100 | S29: =IF($I$25=2,S16,IF($I$25=1.5,Y17,IF($I$25=1,AH18,IF($I$25=0.75,AN19,IF($I$25=0.5,AQ19))))) -> 20 | U29: =IF($I$25=2,U16,IF($I$25=1.5,AA17,IF($I$25=1,AJ18,IF($I$25=0.75,AP19,IF($I$25=0.5,AS19))))) -> 55 | AI29: 0.5
H30: =IF($I$25=2,H18,IF($I$25=1.5,H19,IF($I$25=1,H20,IF($I$25=0.75,H20,IF($I$25=0.5,H20))))) -> N° 4 | I30: =IF(H30="N° 4",I20,IF(H30="N° 8",I21,H30*2.54*10)) -> 4.76 | J30: 80 | L30: 100 | S30: =IF($I$25=2,S18,IF($I$25=1.5,Y19,IF($I$25=1,AH20,IF($I$25=0.75,AN20,IF($I$25=0.5,AQ20))))) -> 0 | U30: =IF($I$25=2,U18,IF($I$25=1.5,AA19,IF($I$25=1,AJ20,IF($I$25=0.75,AP20,IF($I$25=0.5,AS20))))) -> 10
H31: =IF($I$25=2,H20,IF($I$25=1.5,H20,IF($I$25=1,H21,IF($I$25=0.75,H21,IF($I$25=0.5,H21))))) -> N° 8 | I31: =IF(H31="N° 4",I20,IF(H31="N° 8",I21,H31*2.54*10)) -> 2.36 | J31: 50 | L31: 85 | S31: =IF($I$25=2,S20,IF($I$25=1.5,Y20,IF($I$25=1,AH21,IF($I$25=0.75,AN21,IF($I$25=0.5,AQ21))))) -> 0 | U31: =IF($I$25=2,U20,IF($I$25=1.5,AA20,IF($I$25=1,AJ21,IF($I$25=0.75,AP21,IF($I$25=0.5,AS21))))) -> 5
J34: 0 | L34: 10
