Workbook
Name ___CC2: [1]Sucs!$L$6
Name __CC2: [1]Sucs!$L$6
Name _CC1: [2]Sucs!$L$6
Name _CC2: [1]Sucs!$L$6
Name _CU1: [2]Sucs!$L$5
Name _IP1: [2]Sucs!$L$4
Name _L1: #REF!
Name _L1: #REF!
Name _L1: #REF!
Name _Ll1: [2]Sucs!$L$3
Name _W1: #REF!
Name _W1: #REF!
Name _W1: #REF!
Name Abra: [3]Sucs!$C$3
Name CC: #REF!
Name CC: #REF!
Name CC: #REF!
Name CCf: '[2]Sucs(Fino)'!$L$6
Name CCVB: [4]Sucs!$L$3
Name CM: [5]BGA!$H$9
Name CU: #REF!
Name CU: #REF!
Name CU: #REF!
Name CUf: '[2]Sucs(Fino)'!$L$5
Name hh: #REF!
Name hh: #REF!
Name hh: #REF!
Name IP: #REF!
Name IP: #REF!
Name IP: #REF!
Name IPf: '[2]Sucs(Fino)'!$L$4
Name L: #REF!
Name L: #REF!
Name L: #REF!
Name LIf: '[2]Sucs(Fino)'!$L$3
Name Ll: #REF!
Name Ll: #REF!
Name Ll: #REF!
Name MORA: [5]BGA!$H$13
Name N_10: #REF!
Name N_10: #REF!
Name N_10: #REF!
Name N_101: [2]Sucs!$C$5
Name N_10f: '[2]Sucs(Fino)'!$C$5
Name N_200: #REF!
Name N_200: #REF!
Name N_200: #REF!
Name N_2001: [2]Sucs!$C$3
Name N_200f: '[2]Sucs(Fino)'!$C$3
Name N_40: #REF!
Name N_40: #REF!
Name N_40: #REF!
Name N_401: [2]Sucs!$C$4
Name N_40f: '[2]Sucs(Fino)'!$C$4
Name PC: [4]Sucs!$C$5
Name TABLA: #REF!
Name TABLA: #REF!
Name TABLA: #REF!
Name tipodegranulometria: '[6]G-LL '!$X$2:$X$3
Name tipodegranulometria: '[6]G-LL '!$X$2:$X$3

Sheet FORMATO
L2: CLIENTE
L3: DIRECCIÓN **
L4: PROYECTO **
L5: UBICACIÓN **
A7: LABORATORIO DE ENSAYO DE MATERIALES | L7: RECEPCIÓN N°
A8: FORMATO N° F-LEM-P-AG-18.01 | L8: F. EMISIÓN
L9: OT N°
C10: MUESTRA | D10: N° OT | E10: FECHA DE ENSAYO | F10: REALIZADO
L11: CÓDIGO DE LA MUESTRA
L12: FECHA DE RECEPCIÓN
A13: Standard Test Method for Relative Density (Specific Gravity) and Absorption of Fine Aggregate | L13: FECHA DE EJECUCIÓN
A14: ASTM C128-25
B15: Especimen de prueba | L15: CANTERA/SONDAJE **
B16: Masa humeda | E16: Fecha / hora de inmersión (*) | L16: N° MUESTRA **
B17: Masa seca | E17: Fecha / hora de salida inmersión (*) | L17: TIPO DE MUESTRA**
B18: Masa seca constante | E18: Temp. del pignometro y contenido (**)
E19: Temp. Durante la calibración (**)
B20: (*)deje reposar 24hr ± 4hr, cuando se trabaja con agregados livianos 72hr ± 4hr revolviendo 1 minuto cada 24hr
B21: (**) 23.0 °C ± 2.0 °C
B22: Descripción | F22: Und. | G22: Ensayo
B23: S | C23: Masa de muestra saturada de superficie seca y densidad relativa | F23: g
B24: C | C24: Masa del picnómetro lleno de muestra y agua, hasta la marca de calibración | F24: g
B25: B | C25: Masa del picnómetro lleno de agua, hasta la marca de calibración, | F25: g
B26: d | C26: Recipiente | F26: g
B27: e | C27: Masa del recipiente | F27: g
B28: f | C28: Masa del recipiente más muestra secada al horno | F28: g
B29: g | C29: Masa del recipiente más muestra secada al horno constante | F29: g
B30: A | C30: Masa de la muestra secada al horno = a - d | F30: g
B31: - | C31: Densidad relativa (gravedad especifica) (OD) = A / (B + S - C) | F31: -
B32: - | C32: Densidad relativa (gravedad especifica) (SSD) = S / (B + S - C) | F32: -
B33: - | C33: Densidad relativa aparente (gravedad especifica) = A / (B + A - C) | F33: -
B34: - | C34: Absorción (%) = 100 [(S - A) / A] | F34: %
A37: Condiciones del ensayo
A38: La muestra se secó en horno a masa constante a 110 ± 5°C, antes de saturar. (Si o No)
D40: Equipo utilizado | E40: Código
D41: Balanza 0.1 g
D42: Horno 110ºC
D43: Termómetro
D44: Picnómetro
D45: Molde (tronco cónico) y pisón
...

Sheet INFORME
A4: LABORATORIO DE ENSAYO DE MATERIALES
A5: 0
A7: CLIENTE | B7: : | C7: =+FORMATO!M2 -> 0 | J7: CÓDIGO | K7: : | L7: F-LEM-P-AG-18.02
A8: DIRECCIÓN ** | B8: : | C8: =+FORMATO!M3 -> 0 | J8: RECEPCIÓN N° | K8: : | L8: =+FORMATO!M7 -> 0
A9: PROYECTO ** | B9: : | C9: =+FORMATO!M4 -> 0 | J9: FECHA EMISIÓN: | K9: : | L9: =+FORMATO!M8 -> 0
A10: UBICACIÓN ** | B10: : | C10: =+FORMATO!M5 -> 0
A11: ** Datos proporcionados por el cliente
A13: Standard Test Method for Relative Density (Specific Gravity) and Absorption of Fine Aggregate
A14: ASTM C128-25
A16: DATOS DE LA MUESTRA
A17: CANTERA/SONDAJE ** | D17: : | E17: =+FORMATO!M15 -> 0 | J17: CÓDIGO DE LA MUESTRA | K17: : | L17: =+FORMATO!M11 -> 0
A18: N° MUESTRA ** | D18: : | E18: =+FORMATO!M16 -> 0 | J18: FECHA DE RECEPCIÓN | K18: : | L18: =+FORMATO!M12 -> 0
A19: TIPO DE MUESTRA | D19: : | E19: =+FORMATO!M17 -> 0 | J19: FECHA DE EJECUCIÓN | K19: : | L19: =+FORMATO!M13 -> 0 | M19: =+FORMATO!E11 -> 0
A20: LUGAR DE ENSAYO | D20: : | E20: LABORATORIO DE ENSAYO DE MATERIALES
B22: Descripción | I22: Und. | J22: Datos
B23: Masa de la muestra secada al horno | I23: g | J23: =+'DATOS ENSAYO'!K18 -> 0
B24: Masa del picnómetro lleno de agua, hasta la marca de calibración | I24: g | J24: =+'DATOS ENSAYO'!K14 -> 0
B25: Masa del picnómetro lleno de muestra y agua, hasta la marca de calibración | I25: g | J25: =+'DATOS ENSAYO'!K13 -> 0
B26: Masa de muestra saturada de superficie seca y densidad relativa | I26: g | J26: =+'DATOS ENSAYO'!K12 -> 0
B28: Densidad relativa (gravedad especifica)
B29: Densidad relativa (gravedad especifica) (OD) | I29: - | J29: =+'DATOS ENSAYO'!K20 -> #DIV/0!
B30: Densidad relativa (gravedad especifica) (SSD) | I30: - | J30: =+'DATOS ENSAYO'!K21 -> #DIV/0!
B31: Densidad relativa aparente (gravedad especifica) | I31: - | J31: =+'DATOS ENSAYO'!K22 -> #DIV/0!
B32: Absorción (%) | I32: % | J32: =+'DATOS ENSAYO'!K23 -> #DIV/0!
A35: Condiciones del ensayo
A36: La muestra se secó en horno a masa constante a 110 ± 5°C, antes de saturar. | J36: =+FORMATO!G38 -> 0
A37: Nota:
A38: - Los datos de identificación de la muestra son proporcionados por el cliente.
A39: - Los resultados corresponden sólo a los ensayos realizados sobre la muestra proporcionada por el cliente.
A40: '- Los resultados de los ensayos no deben ser utilizados como una certificación de conformidad con normas de productos o como certificado del sistema de calidad de Geofal SAC.
A41: - Prohibida la reproducción total o parcial del presente informe de ensayo sin la autorización escrita de Geofal S.A.C.
A42: - Este informe de ensayo, al estar en el marco de la acreditación del INACAL - DA, se encuentra dentro del ámbito de reconocimiento multilateral/mutuo de los miembros firmantes de IAAC e ILAC.
A43: Observaciones:
A48: Página 1 de 1
A49: Versión: 09 (2026-01-20) | L49: Fin del Informe

Sheet DATOS ENSAYO
B2: Standard Test Method for Relative Density (Specific Gravity) and Absorption of Fine Aggregate
B3: ASTM C128-25
B5: Información para la Corrección por Certificado de Calibración: | K5: OPERADORES
B6: Precisión de la Balanza al 0.1g | K6: - | L6: =+FORMATO!F11 -> 0
B7: Corrección | D7: =+Balanza!C7 -> -2.46e-05
B8: CODIGO | D8: =+Balanza!C11 -> EQP-0090
B9: Fecha | D9: =+Balanza!C12 -> 46160
B11: Descripción | I11: und | J11: datos | K11: datos corrección
B12: S | C12: Masa de muestra saturada de superficie seca y densidad relativa | I12: g | J12: =+FORMATO!G23 -> 0 | K12: =J12+($D$7*J12) -> 0
B13: C | C13: Masa del picnómetro lleno de muestra y agua, hasta la marca de calibración | I13: g | J13: =+FORMATO!G24 -> 0 | K13: =J13+($D$7*J13) -> 0
B14: B | C14: Masa del picnómetro lleno de agua, hasta la marca de calibración, | I14: g | J14: =+FORMATO!G25 -> 0 | K14: =J14+($D$7*J14) -> 0
B15: d | C15: Recipiente | I15: g | J15: =+FORMATO!G26 -> 0 | K15: =J15+($D$7*J15) -> 0
B16: e | C16: Masa del recipiente | I16: g | J16: =+FORMATO!G27 -> 0 | K16: =J16+($D$7*J16) -> 0
B17: f | C17: Masa del recipiente más muestra secada al horno | I17: g | J17: =+FORMATO!G28 -> 0 | K17: =J17+($D$7*J17) -> 0
B18: g | C18: Masa del recipiente más muestra secada al horno constante | I18: g | J18: =+FORMATO!G29 -> 0 | K18: =J18+($D$7*J18) -> 0
B19: A | C19: Masa de la muestra secada al horno = a - d | I19: g | J19: =J18-J16 -> 0 | K19: =K18-K16 -> 0
B20: - | C20: Densidad relativa (gravedad especifica) (OD) = A / (B + S - C) | I20: - | J20: =J19/(J14+J12-J13) -> #DIV/0! | K20: =K19/(K14+K12-K13) -> #DIV/0!
B21: - | C21: Densidad relativa (gravedad especifica) (SSD) = S / (B + S - C) | I21: - | J21: =J12/(J14+J12-J13) -> #DIV/0! | K21: =K12/(K14+K12-K13) -> #DIV/0!
B22: - | C22: Densidad relativa aparente (gravedad especifica) = A / (B + A - C) | I22: - | J22: =J19/(J14+J19-J13) -> #DIV/0! | K22: =K19/(K14+K19-K13) -> #DIV/0!
B23: - | C23: Absorción (%) = 100 [(S - A) / A] | I23: % | J23: =100*((J12-J19)/J19) -> #DIV/0! | K23: =100*((K12-K19)/K19) -> #DIV/0!

Sheet Incertidumbre
B1: INFORME DE ESTIMACIÓN DE INCERTIDUMBRE | I1: Código: | J1: F-LEM-P-10.01
I2: Versión: | J2: 3
I3: Fecha: | J3: 46146
I4: Página: | J4: 1 de 1
A6: Método: | B6: Standard Test Method for Relative Density (Specific Gravity) and Absorption of Fine Aggregate
A7: Norma: | B7: ASTM C128-22
A8: Matriz: | B8: Agregado Fino
A9: Mensurando: | B9: Gravedad específica OD, gravedad específica SSD, gravedad específica aparente y absorción
A11: Paso 1. Definición del proceso de medición
A13: Variables: | G13: Fórmula:
A15: A = Masa de la muestra secada al horno, g
A16: B = masa del picnómetro lleno de agua, hasta la marca de calibración, g
A17: C = masa de picnómetro lleno de muestra y agua hasta la marca de calibración, g
A18: S = masa de muestra saturada de superficie seca (utilizada en el procedimiento gravimétrico para densidad y densidad relativa (gravedad específica), o para absorción con ambos procedimientos), g
A20: Equipos a utilizar:
A22: Balanza con resolución de lectura de 0.1g
A23: Horno que puea mantener una temperatura uniforme de 110 ± 5°C
A24: Picnómetro
A26: Paso 2. Definición de las variables aleatorias
A39: OD
A40: Fuentes | B40: Valor | C40: Incertidumbre Original | D40: Unidades | E40: Distribución | F40: Incertidumbre Estándar u(xi) | G40: Coeficiente de Sensibilidad | H40: Contribución ui(y)
A41: Resultado OD: | B41: =B42/(B46+B54-B50) -> #DIV/0!
A42: =Balanza!E25 -> Peso material seco en estufa | B42: =Balanza!$F$25 -> 0 | C42: --- | D42: g | E42: --- | F42: =SQRT((F43*F43)+(F44*F44)+(F45*F45)) -> 0.051413358 | G42: =1/(B46+B54-B50) -> #DIV/0! | H42: =G42*F42 -> #DIV/0! | I42: A
A43: Repetibilidad de la pesada | C43: =Balanza!$G$25 -> 0 | D43: g | E43: Normal, K=1 | F43: =+C43 -> 0 | G43: --- | H43: ---
A44: Certificado de Calibración | C44: =2*(SQRT(Balanza!$C$8+Balanza!$D$8*(POWER(B42,2)))) -> 0.08508819 | D44: g | E44: Normal, K=2 | F44: =+C44/2 -> 0.042544095 | G44: --- | H44: --- | J44: Factor de Influencia | L44: Valor | M44: %
A45: Resolución | C45: =Balanza!$C$10 -> 0.1 | D45: g | E45: Rectangular | F45: =C45/SQRT(3)/2 -> 0.028867513 | G45: --- | H45: --- | K45: =A42 -> Peso material seco en estufa | L45: =H42 -> #DIV/0! | M45: =L45*100/$L$50 -> #DIV/0!
A46: =Balanza!E26 -> Peso picnometro+agua | B46: =Balanza!$F$26 -> 0 | D46: g | E46: --- | F46: =SQRT((F47*F47)+(F48*F48)+(F49*F49)) -> 0.051413358 | G46: =B42/POWER((B46+B54-B50),2) -> #DIV/0! | H46: =G46*F46 -> #DIV/0! | I46: B | K46: =A46 -> Peso picnometro+agua | L46: =H46 -> #DIV/0! | M46: =L46*100/$L$50 -> #DIV/0!
A47: Repetibilidad de la pesada | C47: =Balanza!$G$26 -> 0 | D47: g | E47: Normal, K=1 | F47: =+C47 -> 0 | G47: --- | H47: --- | K47: =A50 -> Peso picnometro+material+agua | L47: =+H50 -> #DIV/0! | M47: =L47*100/$L$50 -> #DIV/0!
A48: Certificado de Calibración | C48: =2*(SQRT(Balanza!$C$8+Balanza!$D$8*(POWER(B46,2)))) -> 0.08508819 | D48: g | E48: Normal, K=2 | F48: =+C48/2 -> 0.042544095 | G48: --- | H48: --- | K48: =A54 -> Peso material saturado sup. Seca | L48: =H54 -> #DIV/0! | M48: =L48*100/$L$50 -> #DIV/0!
A49: Resolución | C49: =Balanza!$C$10 -> 0.1 | D49: g | E49: Rectangular | F49: =C49/SQRT(3)/2 -> 0.028867513 | G49: --- | H49: --- | K49: =A58 -> factor de presición OD | L49: =H58 -> 0.0076899556 | M49: =L49*100/$L$50 -> #DIV/0!
A50: =Balanza!E27 -> Peso picnometro+material+agua | B50: =Balanza!$F$27 -> 0 | D50: g | E50: --- | F50: =SQRT((F51*F51)+(F52*F52)+(F53*F53)) -> 0.051413358 | G50: =+B42/POWER((B46+B54-B50),2) -> #DIV/0! | H50: =G50*F50 -> #DIV/0! | I50: C | L50: =SUM(L45:L49) -> #DIV/0! | M50: =L50*100/$L$50 -> #DIV/0!
A51: Repetibilidad de la pesada | C51: =Balanza!$G$27 -> 0 | D51: g | E51: Normal, K=1 | F51: =+C51 -> 0 | G51: --- | H51: ---
A52: Certificado de Calibración | C52: =2*(SQRT(Balanza!$C$8+Balanza!$D$8*(POWER(B50,2)))) -> 0.08508819 | D52: g | E52: Normal, K=2 | F52: =+C52/2 -> 0.042544095 | G52: --- | H52: ---
A53: Resolución | C53: =Balanza!$C$10 -> 0.1 | D53: g | E53: Rectangular | F53: =C53/SQRT(3)/2 -> 0.028867513 | G53: --- | H53: ---
A54: =Balanza!E28 -> Peso material saturado sup. Seca | B54: =Balanza!$F$28 -> 0 | D54: g | E54: --- | F54: =SQRT((F55*F55)+(F56*F56)+(F57*F57)) -> 0.051413358 | G54: =B42/POWER((B54+B46-B50),2) -> #DIV/0! | H54: =G54*F54 -> #DIV/0! | I54: S
A55: Repetibilidad de la pesada | C55: =Balanza!$G$28 -> 0 | D55: g | E55: Normal, K=1 | F55: =+C55 -> 0 | G55: --- | H55: ---
A56: Certificado de Calibración | C56: =2*(SQRT(Balanza!$C$8+Balanza!$D$8*(POWER(B54,2)))) -> 0.08508819 | D56: g | E56: Normal, K=2 | F56: =+C56/2 -> 0.042544095 | G56: --- | H56: ---
A57: Resolución | C57: =Balanza!$C$10 -> 0.1 | D57: g | E57: Rectangular | F57: =C57/SQRT(3)/2 -> 0.028867513 | G57: --- | H57: ---
A58: factor de presición OD | B58: =+Precision!B19 -> 0.0076899556 | E58: Norma, K=1 | F58: =+B58 -> 0.0076899556 | G58: 1 | H58: =+G58*F58 -> 0.0076899556
C59: Incertidumbre Estándar Combinada OD | H59: =SQRT((H42*H42+(H46*H46)+(H50*H50)+(H54*H54)+(H58*H58))) -> #DIV/0!
...

Sheet Balanza
B6: CALIBRACION DE LA BALANZA
B7: Correccion | C7: -2.46e-05
B8: Variables | C8: 0.00181 | D8: 2.15e-10
B9: Ecuacion | C9: 2*RAIZ(0.00181+0.000000000215xR2)
B10: Resolucion | C10: 0.1
B11: Codigo | C11: EQP-0090
B12: Calibración | C12: 46160
B14: ITEM | C14: MES | D14: 20 | E14: 200 | F14: 500 | G14: 1000 | H14: 1200
C18: DESV STD | D18: 0 | E18: 0 | F18: 0 | G18: 0 | H18: 0
D20: Busqueda de Repetibilidad de la masa
D22: 20 | E22: 200 | F22: 500 | G22: 1000 | H22: 5000
D23: =D18 -> 0 | E23: =E18 -> 0 | F23: =F18 -> 0 | G23: =G18 -> 0 | H23: =H18 -> 0
E25: Peso material seco en estufa | F25: =+'DATOS ENSAYO'!K19 -> 0 | G25: =IF(F25<=$D$22,$D$23,IF(AND(F25>$D$22,F25<=$E$22),$E$23,IF(AND(F25>$E$22,F25<=$F$22),$F$23,IF(AND(F25>$F$22,F25<=$G$22),$G$23,IF(AND(F25>$G$22,F25<=$H$22),$H$23,$H$23))))) -> 0 | H25: A
E26: Peso picnometro+agua | F26: =+'DATOS ENSAYO'!K14 -> 0 | G26: =IF(F26<=$D$22,$D$23,IF(AND(F26>$D$22,F26<=$E$22),$E$23,IF(AND(F26>$E$22,F26<=$F$22),$F$23,IF(AND(F26>$F$22,F26<=$G$22),$G$23,IF(AND(F26>$G$22,F26<=$H$22),$H$23,$H$23))))) -> 0 | H26: B
E27: Peso picnometro+material+agua | F27: =+'DATOS ENSAYO'!K13 -> 0 | G27: =IF(F27<=$D$22,$D$23,IF(AND(F27>$D$22,F27<=$E$22),$E$23,IF(AND(F27>$E$22,F27<=$F$22),$F$23,IF(AND(F27>$F$22,F27<=$G$22),$G$23,IF(AND(F27>$G$22,F27<=$H$22),$H$23,$H$23))))) -> 0 | H27: C
E28: Peso material saturado sup. Seca | F28: =+'DATOS ENSAYO'!K12 -> 0 | G28: =IF(F28<=$D$22,$D$23,IF(AND(F28>$D$22,F28<=$E$22),$E$23,IF(AND(F28>$E$22,F28<=$F$22),$F$23,IF(AND(F28>$F$22,F28<=$G$22),$G$23,IF(AND(F28>$G$22,F28<=$H$22),$H$23,$H$23))))) -> 0 | H28: S

Sheet Precision
A3: FACTOR DE PRECISION DEL OPERADOR
A5: Fecha de evaluacion: | B5: 46161
A7: 1-Calcular la Incertidumbre estandar bajo condiciones de reproducibilidad - OD | F7: 1-Calcular la Incertidumbre estandar bajo condiciones de reproducibilidad SSD | K7: 1-Calcular la Incertidumbre estandar bajo condiciones de reproducibilidad APARENTE | P7: 1-Calcular la Incertidumbre estandar bajo condiciones de reproducibilidad ABSORCION
A9: T1 | B9: =+#REF!*#REF!+#REF!*#REF! -> #REF! | F9: T1 | G9: =+#REF!*#REF!+#REF!*#REF! -> #REF! | K9: T1 | L9: =+#REF!*#REF!+#REF!*#REF! -> #REF! | P9: T1 | Q9: =+#REF!*#REF!+#REF!*#REF! -> #REF!
A10: T2 | B10: =+#REF!*POWER(#REF!,2)+#REF!*POWER(#REF!,2) -> #REF! | F10: T2 | G10: =+#REF!*POWER(#REF!,2)+#REF!*POWER(#REF!,2) -> #REF! | K10: T2 | L10: =+#REF!*POWER(#REF!,2)+#REF!*POWER(#REF!,2) -> #REF! | P10: T2 | Q10: =+#REF!*POWER(#REF!,2)+#REF!*POWER(#REF!,2) -> #REF!
A11: T3 | B11: =+SUM(#REF!) -> #REF! | F11: T3 | G11: =+SUM(#REF!) -> #REF! | K11: T3 | L11: =+SUM(#REF!) -> #REF! | P11: T3 | Q11: =+SUM(#REF!) -> #REF!
A12: T4 | B12: =+POWER(#REF!,2)+POWER(#REF!,2) -> #REF! | F12: T4 | G12: =+POWER(#REF!,2)+POWER(#REF!,2) -> #REF! | K12: T4 | L12: =+POWER(#REF!,2)+POWER(#REF!,2) -> #REF! | P12: T4 | Q12: =+POWER(#REF!,2)+POWER(#REF!,2) -> #REF!
A13: T5 | B13: =(#REF!-1)*SUM(#REF!) -> #REF! | F13: T5 | G13: =(#REF!-1)*SUM(#REF!) -> #REF! | K13: T5 | L13: =(#REF!-1)*SUM(#REF!) -> #REF! | P13: T5 | Q13: =(#REF!-1)*SUM(#REF!) -> #REF!
A14: Varianza Repetibilidad (Sr2 ) | B14: =ABS((B13/(B11-#REF!))) -> #REF! | F14: Varianza Repetibilidad (Sr2 ) | G14: =ABS((G13/(G11-#REF!))) -> #REF! | K14: Varianza Repetibilidad (Sr2 ) | L14: =ABS((L13/(L11-#REF!))) -> #REF! | P14: Varianza Repetibilidad (Sr2 ) | Q14: =ABS((Q13/(Q11-#REF!))) -> #REF!
A15: Varianza entre Laboratorios (SL2) | B15: =ABS((((B10*B11-(B9^2))/(B11*(#REF!-1)))-(B14))*((B11*(#REF!-1))/((B11^2)-B12))) -> #REF! | F15: Varianza entre Laboratorios (SL2) | G15: =ABS((((G10*G11-(G9^2))/(G11*(#REF!-1)))-(G14))*((G11*(#REF!-1))/((G11^2)-G12))) -> #REF! | K15: Varianza entre Laboratorios (SL2) | L15: =ABS((((L10*L11-(L9^2))/(L11*(#REF!-1)))-(L14))*((L11*(#REF!-1))/((L11^2)-L12))) -> #REF! | P15: Varianza entre Laboratorios (SL2) | Q15: =ABS((((Q10*Q11-(Q9^2))/(Q11*(#REF!-1)))-(Q14))*((Q11*(#REF!-1))/((Q11^2)-Q12))) -> #REF!
A16: Varianza Reproducibilidad (SR2) | B16: =(B14+B15)/1000000 -> #REF! | F16: Varianza Reproducibilidad (SR2) | G16: =(G14+G15)/1000000 -> #REF! | K16: Varianza Reproducibilidad (SR2) | L16: =(L14+L15)/1000000 -> #REF! | P16: Varianza Reproducibilidad (SR2) | Q16: =(Q14+Q15)/1000000 -> #REF!
A17: Desviacion Estándar Repetibilidad (Sr) | B17: =SQRT(B14) -> #REF! | F17: Desviacion Estándar Repetibilidad (Sr) | G17: =SQRT(G14) -> #REF! | K17: Desviacion Estándar Repetibilidad (Sr) | L17: =SQRT(L14) -> #REF! | P17: Desviacion Estándar Repetibilidad (Sr) | Q17: =SQRT(Q14) -> #REF!
A18: Desviacion Estándar Reproducibilidad (SR) | B18: =+SQRT(B14+B15) -> #REF! | F18: Desviacion Estándar Reproducibilidad (SR) | G18: =+SQRT(G14+G15) -> #REF! | K18: Desviacion Estándar Reproducibilidad (SR) | L18: =+SQRT(L14+L15) -> #REF! | P18: Desviacion Estándar Reproducibilidad (SR) | Q18: =+SQRT(Q14+Q15) -> #REF!
A19: Desviacion Estándar Repetibilidad (Sr) | B19: 0.0076899556 | F19: Desviacion Estándar Repetibilidad (Sr) | G19: 0.0064549722 | K19: Desviacion Estándar Repetibilidad (Sr) | L19: 0.0064718944 | P19: Desviacion Estándar Repetibilidad (Sr) | Q19: 0.091503643
A20: Desviacion Estándar Reproducibilidad (SR) | B20: 0.0077348455 | F20: Desviacion Estándar Reproducibilidad (SR) | G20: 0.006615778 | K20: Desviacion Estándar Reproducibilidad (SR) | L20: 0.0065331464 | P20: Desviacion Estándar Reproducibilidad (SR) | Q20: 0.10671087

Sheet Hoja1
A2: CODIGO | C2: CONCATENADOS | D2: DESCRIPCION | E2: FC | F2: F. MOLDEO | G2: DIA | H2: DIAMETRO | I2: CARGA | J2: AREA | K2: RESIS. CONCRETO | L2: % RESIS | M2: TIPO DE FALLA
A3: 4400 | B3: =+A3+1 -> 4401 | C3: =A3&"-"&B3 -> 4400-4401 | D3: Columnas C-9;5-3/G.H | E3: 350 | F3: 42347 | G3: 7 | H3: 15.05 | I3: 49900 | J3: =H3*H3*PI()/4 -> 177.89465 | K3: =I3/J3 -> 280.5031 | L3: =+K3/E3 -> 0.80143743 | M3: E
C4: =A4&"-"&B4 -> - | E4: 350 | G4: 7 | H4: 15.06 | I4: 50310 | J4: =H4*H4*PI()/4 -> 178.13113 | K4: =I4/J4 -> 282.43238 | L4: =+K4/E4 -> 0.80694967 | M4: F
A5: =+B3+1 -> 4402 | B5: =+A5+1 -> 4403 | C5: =A5&"-"&B5 -> 4402-4403 | E5: 350 | G5: 14 | H5: 15.04 | I5: 56450 | J5: =H5*H5*PI()/4 -> 177.65832 | K5: =I5/J5 -> 317.74476 | L5: =+K5/E5 -> 0.90784216 | M5: F
C6: =A6&"-"&B6 -> - | E6: 350 | G6: 14 | H6: 15 | I6: 59630 | J6: =H6*H6*PI()/4 -> 176.71459 | K6: =I6/J6 -> 337.43677 | L6: =+K6/E6 -> 0.96410507 | M6: F
A7: =+B5+1 -> 4404 | B7: =+A7+1 -> 4405 | C7: =A7&"-"&B7 -> 4404-4405 | E7: 350 | G7: 28 | H7: 15.11 | I7: 65310 | J7: =H7*H7*PI()/4 -> 179.3159 | K7: =I7/J7 -> 364.21755 | L7: =+K7/E7 -> 1.0406216 | M7: F
C8: =A8&"-"&B8 -> - | E8: 350 | G8: 28 | H8: 15.05 | I8: 64730 | J8: =H8*H8*PI()/4 -> 177.89465 | K8: =I8/J8 -> 363.86705 | L8: =+K8/E8 -> 1.0396201 | M8: E
