Workbook
Name ___CC2: [1]Sucs!$L$6
Name __CC2: [1]Sucs!$L$6
Name _CC1: [2]Sucs!$L$6
Name _CC2: [1]Sucs!$L$6
Name _CU1: [2]Sucs!$L$5
Name _IP1: [2]Sucs!$L$4
Name _L1: #REF!
Name _L1: #REF!
Name _L1: #REF!
Name _Ll1: [2]Sucs!$L$3
Name _W1: #REF!
Name _W1: #REF!
Name _W1: #REF!
Name Abra: [3]Sucs!$C$3
Name CC: #REF!
Name CC: #REF!
Name CC: #REF!
Name CCf: '[2]Sucs(Fino)'!$L$6
Name CCVB: [4]Sucs!$L$3
Name CM: [5]BGA!$H$9
Name CU: #REF!
Name CU: #REF!
Name CU: #REF!
Name CUf: '[2]Sucs(Fino)'!$L$5
Name hh: #REF!
Name hh: #REF!
Name hh: #REF!
Name IP: #REF!
Name IP: #REF!
Name IP: #REF!
Name IPf: '[2]Sucs(Fino)'!$L$4
Name L: #REF!
Name L: #REF!
Name L: #REF!
Name LIf: '[2]Sucs(Fino)'!$L$3
Name Ll: #REF!
Name Ll: #REF!
Name Ll: #REF!
Name MORA: [5]BGA!$H$13
Name N_10: #REF!
Name N_10: #REF!
Name N_10: #REF!
Name N_101: [2]Sucs!$C$5
Name N_10f: '[2]Sucs(Fino)'!$C$5
Name N_200: #REF!
Name N_200: #REF!
Name N_200: #REF!
Name N_2001: [2]Sucs!$C$3
Name N_200f: '[2]Sucs(Fino)'!$C$3
Name N_40: #REF!
Name N_40: #REF!
Name N_40: #REF!
Name N_401: [2]Sucs!$C$4
Name N_40f: '[2]Sucs(Fino)'!$C$4
Name PC: [4]Sucs!$C$5
Name TABLA: #REF!
Name TABLA: #REF!
Name TABLA: #REF!
Name tipodegranulometria: '[6]G-LL '!$X$2:$X$3
Name tipodegranulometria: '[6]G-LL '!$X$2:$X$3

Sheet informe NTP
A7: LABORATORIO DE ENSAYO DE MATERIALES
A8: =K13 -> 15
A10: CLIENTE | B10: : | C10: METRO
A11: DIRECCION ** | B11: : | C11: LIMA - AV. JAGSKSHD / PONER LA DIRECCION O DIRECCION FISCAL | I11: CÓDIGO | J11: : | K11: F-LEM-P-SU.12.02
A12: PROYECTO ** | B12: : | C12: CONJUNTO RESIDENCIAL SAN BORJA HOMETOWN | I12: N° OT | J12: : | K12: 15
A13: UBICACIÓN ** | B13: : | C13: CA. DURERO CDRA. 4 S/N, ALT. LA CDRA 13 DE LA AV. SAN | I13: N° INFORME. | J13: : | K13: 15
A14: ** Datos proporcionados por el cliente
A15: METODO DE ENSAYO PARA DETERMINAR EL CONTENIDO DE HUMEDAD DE UN SUELO
A16: NORMA NTP 339.127
A17: DATOS DE LA MUESTRA:
I18: CODIGO DE LA MUESTRA | J18: : | K18: 83 | P18: Informacion para la Correccion por Certificado de Calibración:
A19: CANTERA / SONDAJE ** | B19: : | C19: C-1 | I19: FECHA DE RECEPCIÓN | J19: : | K19: 43831 | P19: Codigo de Balanza al 0.1g | R19: Variable 1
A20: N° MUESTRA ** | B20: : | C20: M-1 | I20: FECHA DE EJECUCIÓN | J20: : | K20: 43844 | P20: CODIGO | R20: 5.17e-07
A21: TIPO DE MUESTRA** | B21: : | C21: SUELO | I21: FECHA DE EMISIÓN | J21: : | K21: 43845 | P21: Fecha | Q21: 44090
A22: LUGAR DE ENSAYO | B22: : | C22: Laboratorio de Ensayo de Materiales
B24: N° de ensayo | G24: N° | H24: =+R24 -> 1 | P24: N° de ensayo | Q24: N° | R24: 1 | S24: CORRECCION | U24: 2 | V24: CORRECCION | W24: Se realiza el Ensayo N° 2, por cada ORDEN DE TRABAJO
B25: Tara Nº | G25: N° | H25: =+R25 -> 1 | P25: Tara Nº | Q25: N° | R25: 1 | U25: 2
B26: Masa de la Tara + suelo húmedo | G26: g | H26: =S26 -> 794.69959 | P26: Tara + suelo húmedo | Q26: g | R26: 794.7 | S26: =R26-($R$20*R26) -> 794.69959 | U26: 793.7 | V26: =U26-($R$20*U26) -> 793.69959
B27: Masa de la Tara + suelo seco | G27: g | H27: =S27 -> 775.7996 | P27: Tara + suelo seco | Q27: g | R27: 775.8 | S27: =R27-($R$20*R27) -> 775.7996 | U27: 775.8 | V27: =U27-($R$20*U27) -> 775.7996
B28: Masa de la Tara + suelo seco (constante 1) | G28: g | H28: =S28 -> 775.7996 | P28: Tara + suelo seco 1 | Q28: g | R28: 775.8 | S28: =R28-($R$20*R28) -> 775.7996 | U28: 775.8 | V28: =U28-($R$20*U28) -> 775.7996
B29: Masa de la Tara + suelo seco (constante 2) | G29: g | H29: =S29 -> 775.7996 | P29: Tara + suelo seco 2 | Q29: g | R29: 775.8 | S29: =R29-($R$20*R29) -> 775.7996 | U29: 775.8 | V29: =U29-($R$20*U29) -> 775.7996
B30: Masa de agua | G30: g | H30: =+H26-H29 -> 18.89999 | P30: Peso de agua | Q30: g | R30: =+R26-R29 -> 18.9 | S30: =+S26-S29 -> 18.89999 | U30: =+U26-U29 -> 17.9 | V30: =+V26-V29 -> 17.899991
B31: Masa de tara | G31: g | H31: =S31 -> 163.19992 | P31: Peso de tara | Q31: g | R31: 163.2 | S31: =R31-($R$20*R31) -> 163.19992 | U31: 163.2 | V31: =U31-($R$20*U31) -> 163.19992
B32: Masa de suelo seco | G32: g | H32: =+H29-H31 -> 612.59968 | P32: Peso de suelo seco | Q32: g | R32: =+R29-R31 -> 612.6 | S32: =+S29-S31 -> 612.59968 | U32: =+U29-U31 -> 612.6 | V32: =+V29-V31 -> 612.59968
B33: HUMEDAD * | G33: % | H33: =ROUND(S33,0) -> 3 | P33: Humedad | Q33: % | R33: =+R30/R32*100 -> 3.0852106 | S33: =+S30/S32*100 -> 3.0852106 | U33: =+U30/U32*100 -> 2.9219719 | V33: =+V30/V32*100 -> 2.9219719
B34: * Reporte al 1%, indicado por la Norma de ensayo. | P34: TABLA PESO MINIMO HUMEDAD | R34: Peso mínimo B -- A | S34: MARCA CON X
A36: Condiciones del ensayo (indicado en la Norma de ensayo | P36: Fino | Q36: N°10 | R36: 20 - 20
A37: a) Se excluyó algún material de la muestra de ensayo? (Si/No) | I37: No | P37: Arena | Q37: N°4 | R37: 100 - 20
A38: b) El método de secado diferente a 110°C? (Si/No) | I38: No | P38: GRAVAS | Q38: 0.375 | R38: 500 - 50 | S38: X
A39: c) La muestra de ensayo presenta más de un tipo de suelo (estratificado, etc.) (Si/No) | I39: No | Q39: 0.75 | R39: 2500-250
Q40: 1.5 | R40: 10000-1000
A41: Caracteristicas de la muestra: | Q41: 3 | R41: 50000-5000
A42: TIPO DE MUESTRA : | D42: SUELO | R42: Tmax = | S42: =IF(AND(S36="",S37="",S38="",S39="",S40="",S41=""),"",IF(S36<>"","N°10",IF(S37<>"","N°4",IF(S38<>"","3/8",IF(S39<>"","3/4",IF(S40<>"","1 1/2","3")))))) -> 3/8
A43: CONDICIÓN DE LA MUESTRA: | D43: ALTERADA | R43: Metodo "0.1%", Aproximación 0,1% (g)= | S43: =IF(S42="","",IF(S42="3",50000,IF(S42="1 1/2",10000,IF(S42="3/4",2500,IF(S42="3/8",500,IF(S42="N°4",100,20)))))) -> 500
A44: TAMAÑO DE PARTICULA (in): | D44: =$S$42 -> 3/8 | R44: Metodo "1%", Aproximación 1% (g)= | S44: =IF(S42="","",IF(S42="3",5000,IF(S42="1 1/2",1000,IF(S42="3/4",250,IF(S42="3/8",50,IF(S42="N°4",20,20)))))) -> 50
A45: FORMA DE PARTICULA: | D45: ANGULAR | R45: Cambie a 0.1%, sólo si el cliente lo pide. Metodo | S45: 0.001
R46: Verificacion si cumple el peso minimo al 1% | S46: =IF(R26="","",IF(AND(S36="",S37="",S38="",S39="",S40="",S41=""),"Falta Especificar Tmax",IF(R26="","",IF(R26-R31>=S43,"Cumple",IF(R26-R31>=S44,"Cumple","No cumple"))))) -> Cumple
A47: Página 1 de 1 | R47: Verificacion si cumple el peso minimo al 0.1% | S47: =IF(R26="","",IF(AND(S36="",S37="",S38="",S39="",S40="",S41=""),"Falta Especificar Tmax",IF(R26="","",IF(R26-R31>=S43,"Cumple",IF(R26-R31>=S43,"Cumple","No cumple"))))) -> Cumple
A48: Versión : 02 (02-01-2021)
A49: Estos datos del presente informe de ensayo sólo aplica a las muestra proporcionada por el cliente. La muestra fue identificada por el cliente.
...

Sheet Resumen
O2: CLIENTE
O3: DIRECCIÓN **
O4: PROYECTO **
O5: UBICACIÓN **
A7: LABORATORIO DE ENSAYO DE MATERIALES | O7: RECEPCIÓN N°
A8: FORMATO N° F-LEM-P-SU-20.01 | O8: F. EMISIÓN
O9: OT N°
D10: MUESTRA | E10: N° OT | G10: FECHA DE ENSAYO | I10: REALIZADO
O11: CÓDIGO DE LA MUESTRA
O12: FECHA DE RECEPCIÓN
O13: FECHA DE EJECUCIÓN
A14: Standard Test Methods for Laboratory Determination of Water (Moisture) Content of Soil and Rock by Mass
A15: ASTM D2216-19 | O15: CANTERA/SONDAJE **
O16: N° MUESTRA **
A17: Condiciones del ensayo | O17: TIPO DE MUESTRA**
A18: - La muestra de ensayo tiene una masa menor que la mínima requerida por la norma. (Si/No)
A19: - La muestra de ensayo presenta más de un tipo de material (capas, etc.) (Si/No)
A20: - La temperatura de secado es diferente a 110 ± 5°C. (Si/No)
A21: - Se excluyó algún material (tamaño y cantidad) de la muestra de prueba. (Si/No)
A22: Descripción material excluido:
A24: Descripción de la muestra
A25: Tipo de muestra: | H25: MÉTODO PRUEBA
A26: Condición de la muestra: | H26: MÉTODO "A" o "B"
A27: Tamaño máximo de la particula (visual) (in):
A28: Forma de la partìcula:
B30: DESCRIPCIÓN | H30: UND | I30: ENSAYO
B31: 1 | C31: N° de ensayo | H31: N°
B32: 2 | C32: Recipiente Nº | H32: N°
B33: 3 | C33: Masa del recipiente y muestra húmeda | H33: g
B34: 4 | C34: Masa del recipiente y muestra seca al horno | H34: g
B35: 5 | C35: Masa del recipiente y muestra seca al horno constante | H35: g
B36: 6 | C36: Masa del recipiente | H36: g
B37: 7 | C37: Masa del agua (3-5) | H37: g
B38: 8 | C38: Masa de muestra seca al horno (5-6) | H38: g
B39: 9 | C39: CONTENIDO DE AGUA (HUMEDAD) * (7/8*100) | H39: %
B41: Método A | H41: Equipo utilizado
B42: Tamaño máximo de la partícula que pasa | E42: Masa mínima | F42: Legibilidad de la balanza | H42: Balanza 0.1 g
B43: 3 in | E43: 5 kg | F43: 0.1 g | H43: Balanza 0.01 g
B44: 1 1/2 in | E44: 1 kg | F44: 0.1 g
B45: 3/4 in | E45: 250 g | F45: 0.1 g | H45: Horno 110ºC
...

Sheet informe ASTM
A2: LABORATORIO DE ENSAYO DE MATERIALES
A3: 0
A5: CLIENTE | B5: : | C5: =+Resumen!P2 -> 0 | L5: CÓDIGO | M5: : | N5: F-LEM-P-SU.20.02
A6: DIRECCIÓN ** | B6: : | C6: =+Resumen!P3 -> 0 | L6: RECEPCIÓN N° | M6: : | N6: =+Resumen!P7 -> 0
A7: PROYECTO ** | B7: : | C7: =+Resumen!P4 -> 0 | L7: OT N° | M7: : | N7: =+Resumen!P9 -> 0
A8: UBICACIÓN ** | B8: : | C8: =+Resumen!P5 -> 0 | L8: FECHA EMISIÓN | M8: : | N8: =+Resumen!P9 -> 0
A9: ** Datos proporcionados por el cliente
A10: Standard Test Methods for Laboratory Determination of Water (Moisture) Content of Soil and Rock by Mass
A11: ASTM D2216-19
A13: DATOS DE LA MUESTRA:
A14: CANTERA/SONDAJE ** | D14: : | E14: =+Resumen!P15 -> 0 | L14: CÓDIGO DE LA MUESTRA | M14: : | N14: =+Resumen!D11 -> 0
A15: N° MUESTRA ** | D15: : | E15: =+Resumen!P16 -> 0 | L15: FECHA DE RECEPCIÓN | M15: : | N15: =+Resumen!P12 -> 0
A16: TIPO DE MUESTRA | D16: : | E16: =+Resumen!E25 -> 0 | L16: FECHA DE EJECUCIÓN | M16: : | N16: =+Resumen!P13 -> 0 | Q16: =+Resumen!G11 -> 0
A17: LUGAR DE ENSAYO | D17: : | E17: LABORATORIO DE ENSAYO DE MATERIALES | L17: REALIZADO POR | M17: : | N17: =+'Datos ensayo'!D15 -> -
D19: Descripción | J19: Und | K19: Datos
D20: N° de ensayo | J20: N° | K20: =+'Datos ensayo'!G17 -> 1
D21: Recipiente Nº | J21: N° | K21: =+'Datos ensayo'!G18 -> 0
D22: Masa del recipiente y muestra húmeda | J22: g | K22: =+'Datos ensayo'!H19 -> 0,00
D23: Masa del recipiente y muestra seca al horno | J23: g | K23: =+'Datos ensayo'!H21 -> 0,00
D24: Masa del recipiente | J24: g | K24: =+'Datos ensayo'!H22 -> 0,00
D25: Masa del agua | J25: g | K25: =+'Datos ensayo'!H23 -> 0,00
D26: Masa de muestra seca al horno | J26: g | K26: =+'Datos ensayo'!H24 -> 0,00
D27: CONTENIDO DE AGUA (HUMEDAD) * | J27: % | K27: =+'Datos ensayo'!H25 -> #DIV/0!
A29: Condiciones del ensayo:
A30: - Método de prueba utilizado | L30: =+Resumen!J26 -> 0
A31: - La muestra de ensayo tiene una masa menor que la mínima requerida por la norma. (Si/No) | L31: =+Resumen!J18 -> 0
A32: - La muestra de ensayo presenta más de un tipo de material (en capas, etc.) (Si/No) | L32: =+Resumen!J19 -> 0
A33: - La temperatura de secado es diferente a 110 ± 5°C. (Si/No) | L33: =+Resumen!J20 -> 0
A34: - Se excluyó algún material (tamaño y cantidad) de la muestra de prueba. (Si/No) | L34: =+Resumen!J21 -> 0
A36: Descripción de la muestra:
A37: Tamaño máximo de partícula (in) | K37: =+Resumen!E27 -> 0
A38: Forma de la particula | K38: =+Resumen!E28 -> 0
A40: Nota:
A41: - El cliente es responsable de los datos de identificación de los puntos de ensayo brindados.
A42: - Los resultados expresados se refieren únicamente al ensayo realizado en dicho momento y en las condiciones especificadas en este documento, por lo que GEOFAL S.A.C. no será responsable por los ensayos realizados con la presente muestra en condiciones distintas a las aquí señaladas.
A43: - GEOFAL S.A.C. no se hace responsable por el uso incorrecto o inadecuado del presente informe.
A44: - Los resultados de los ensayos realizados no deben ser utilizados como una certificación de conformidad con normas de producto o como certificado del sistema de calidad de la entidad que lo produce.
A45: - De conformidad con lo dispuesto por el artículo 1321 del Código Civil, queda establecido que en ningún caso la responsabilidad de GEOFAL S.A.C. será mayor al valor del servicio prestado.
A47: Observaciones:
A51: Página 1 de 1
...

Sheet Datos ensayo
B2: Standard Test Methods for Laboratory Determination of Water (Moisture) Content of Soil and Rock by Mass
B3: ASTM D2216-19
B5: METODO A o B | F5: =+Resumen!J26 -> 0 | H5: METODO A: se reporta al 1%
H6: METODO B: se reporta al 0.1%
B7: PRECISIÓN BALANZA (0.1g o 0.01g) | F7: =+IF(F5="A",0.1,0.01) -> 0.01
F8: =IF(F7=0.1,J9,J10) -> 3.79e-06 | H8: Codigo balanza | I8: Precisiòn | J8: Correccion | K8: F. calibraciòn
B9: Tamaño máximo TM: | D9: =+Resumen!E27 -> 0 | H9: =+Balanza!C7 -> EQP-0046 | I9: 0,1 g | J9: =+Balanza!C3 -> -3.29e-06 | K9: =+Balanza!D8 -> 46132
H10: =+Balanza!K7 -> EQP-0045 | I10: 0,01 g | J10: =+Balanza!K3 -> 3.79e-06 | K10: =+Balanza!L8 -> 46132
B11: Cantidad mínima: | D11: =+INDEX(J19:K28,MATCH(D9,J19:J28,0),2) -> #N/A | E11: =+IF((G19-G22)>D11,"Cumple","No Cumple") -> #N/A
B13: Forma particula | D13: =+Resumen!E28 -> 0
B15: REALIZADO POR | D15: - | E15: =+Resumen!I11 -> 0
A17: 1 | B17: N° de ensayo | F17: N° | G17: 1 | H17: CORRECCION | J17: TM | K17: MASA MINIMA
A18: 2 | B18: Recipiente Nº | F18: N° | G18: =+Resumen!I32 -> 0 | J18: (in.) | K18: (g)
A19: 3 | B19: Masa del recipiente y muestra húmeda | F19: g | G19: =+Resumen!I33 -> 0 | H19: =IF($F$7=0.1,FIXED(G19+$F$8*G19,1),FIXED(G19+$F$8*G19,2)) -> 0,00 | J19: 3 | K19: 5000
A20: 4 | B20: Masa del recipiente y muestra seca al horno | F20: g | G20: =+Resumen!I34 -> 0 | H20: =IF($F$7=0.1,FIXED(G20+$F$8*G20,1),FIXED(G20+$F$8*G20,2)) -> 0,00 | J20: 2 1/2 | K20: 5000
A21: 5 | B21: Masa del recipiente y muestra seca al horno (constante) | F21: g | G21: =+Resumen!I35 -> 0 | H21: =IF($F$7=0.1,FIXED(G21+$F$8*G21,1),FIXED(G21+$F$8*G21,2)) -> 0,00 | J21: 2 | K21: 5000
A22: 6 | B22: Masa del recipiente | F22: g | G22: =+Resumen!I36 -> 0 | H22: =IF($F$7=0.1,FIXED(G22+$F$8*G22,1),FIXED(G22+$F$8*G22,2)) -> 0,00 | J22: 1 1/2 | K22: 1000
A23: 7 | B23: Masa del agua | F23: g | G23: =+G19-G21 -> 0 | H23: =IF($F$7=0.1,FIXED(H19-H21,1),FIXED(H19-H21,2)) -> 0,00 | J23: 1 | K23: 1000
A24: 8 | B24: Masa de muestra seca al horno | F24: g | G24: =+G21-G22 -> 0 | H24: =IF($F$7=0.1,FIXED(H21-H22,1),FIXED(H21-H22,2)) -> 0,00 | J24: 3/4 | K24: 250
A25: 9 | B25: CONTENIDO DE AGUA (HUMEDAD) * | F25: % | G25: =IF(F5="A",FIXED((G23/G24*100),0),FIXED((G23/G24*100),1)) -> #DIV/0! | H25: =IF(F5="A",FIXED((H23/H24*100),0),FIXED((H23/H24*100),1)) -> #DIV/0! | J25: 1/2 | K25: 250
H26: =ABS(H25) -> #DIV/0! | J26: 3/8 | K26: 500
B27: Perdida de masa seca adicional | H27: =(H20-H21)/H21*100 -> #DIV/0! | J27: N°4 | K27: 100
B28: Perdida de masa seca constante (adicional), para metodo A es < 1% | H28: =IF(AND(F5="A",H27<1),"cumple","") -> #DIV/0! | J28: N°10 | K28: 20
B29: Perdida de masa seca constante (adicional), para metodo B es < 0.1% | H29: =IF(AND(F5="B",H27<0.1),"cumple","") -> #DIV/0! | J29: - | K29: -
B31: metodo A
B32: Tamaño maximo de la particula que pasa | F32: masa minima | G32: balanza
B33: 3 in. | F33: 5 kg | G33: 0.1
B34: 1.1/2 in. | F34: 1 kg | G34: 0.1
B35: 3/4 in. | F35: 250 g | G35: 0.1
B36: metodo B
B37: 3/8 in. | F37: 500 g | G37: 0.01
B38: No. 4 | F38: 100 g | G38: 0.01
B39: No. 10 | F39: 20 g | G39: 0.01

Sheet Incertidumbre
C1: INFORME DE ESTIMACIÓN DE INCERTIDUMBRE | I1: Código: | J1: F-LEM-P-10.01
I2: Versión: | J2: 3
I3: Fecha: | J3: 46146
I4: Página: | J4: 1 de 1
A6: Método: | B6: Standard Test Methods for Laboratory Determination of Water (Moisture) Content of Soil and Rock by Mass
A7: Norma: | B7: ASTM D2216-19
A8: Matriz: | B8: Suelo
A9: Mensurando: | B9: Agua presente en la matriz de Suelo
A11: Paso 1. Definición del proceso de medición
A13: Variables: | E13: Fórmula:
A15: Masa humeda (Mcms)
A16: Masa seca ( Mcdc)
A17: Masa tara (Mc)
A19: Equipos a utilizar:
A21: Balanza con resulución de lectura de 0.1g o 0.01g
A23: Paso 2. Definición de las variables aleatorias
A38: CÁLCULOS
A39: Fuentes | B39: Valor | C39: Incertidumbre Original | D39: Unidades | E39: Distribución | F39: Incertidumbre Estándar u(xi) | G39: Coeficiente de Sensibilidad | H39: Contribución ui(y) | I39: =+'Datos ensayo'!F7 -> 0.01
A40: Humedad (%) | B40: =+((B41-B45)/(B45-B49)*100) -> #DIV/0! | C40: --- | D40: --- | E40: --- | F40: --- | G40: --- | H40: ---
A41: Masa Humeda y tara | B41: =Balanza!F23 -> 0 | C41: --- | D41: g | E41: --- | F41: =SQRT((F42*F42)+(F43*F43)+(F44*F44)) -> 0.0072548834 | G41: =100/(B45-B49) -> #DIV/0! | H41: =+G41*F41 -> #DIV/0!
A42: Repetibilidad de la pesada | C42: =IF($I$39=0.1,Balanza!G23,Balanza!N23) -> 0 | D42: g | E42: Normal, K=1 | F42: =+C42 -> 0 | G42: --- | H42: ---
A43: Certificado de Calibración | C43: =IF($I$39=0.1,2*(SQRT(Balanza!$C$4+Balanza!$D$4*(POWER(B41,2)))),2*(SQRT(Balanza!$K$4+Balanza!$L$4*(POWER(B41,2))))) -> 0.013311649 | D43: g | E43: Normal, K=2 (/2) | F43: =+C43/2 -> 0.0066558245 | G43: --- | H43: ---
A44: Resolución | C44: =+$I$39 -> 0.01 | D44: g | E44: Rectangular | F44: =C44/SQRT(3)/2 -> 0.0028867513 | G44: --- | H44: ---
A45: Masa Seca y tara | B45: =Balanza!F24 -> 0 | D45: g | E45: --- | F45: =SQRT((F46*F46)+(F47*F47)+(F48*F48)) -> 0.0072548834 | G45: =((B41-B49)*100)/(POWER((B45-B49),2)) -> #DIV/0! | H45: =+G45*F45 -> #DIV/0!
A46: Repetibilidad de la pesada | C46: =IF($I$39=0.1,Balanza!G24,Balanza!N24) -> 0 | D46: g | E46: Normal, K=1 | F46: =+C46 -> 0 | G46: --- | H46: ---
A47: Certificado de Calibración | C47: =IF($I$39=0.1,2*(SQRT(Balanza!$C$4+Balanza!$D$4*(POWER(B45,2)))),2*(SQRT(Balanza!$K$4+Balanza!$L$4*(POWER(B45,2))))) -> 0.013311649 | D47: g | E47: Normal, K=2 (/2) | F47: =+C47/2 -> 0.0066558245 | G47: --- | H47: ---
A48: Resolución | C48: =+$I$39 -> 0.01 | D48: g | E48: Rectangular | F48: =C48/SQRT(3)/2 -> 0.0028867513 | G48: --- | H48: ---
A49: Masa Tara | B49: =Balanza!F25 -> 0 | D49: g | E49: --- | F49: =SQRT((F50*F50)+(F51*F51)+(F52*F52)) -> 0.0072548834 | G49: =((B41-B45)*100)/(POWER((B45-B49),2)) -> #DIV/0! | H49: =+G49*F49 -> #DIV/0!
A50: Repetibilidad de la pesada | C50: =IF($I$39=0.1,Balanza!G25,Balanza!N25) -> 0 | D50: g | E50: Normal, K=1 | F50: =+C50 -> 0 | G50: --- | H50: ---
A51: Certificado de Calibración | C51: =IF($I$39=0.1,2*(SQRT(Balanza!$C$4+Balanza!$D$4*(POWER(B49,2)))),2*(SQRT(Balanza!$K$4+Balanza!$L$4*(POWER(B49,2))))) -> 0.013311649 | D51: g | E51: Normal, K=2 (/2) | F51: =+C51/2 -> 0.0066558245 | G51: --- | H51: ---
A52: Resolución | C52: =+$I$39 -> 0.01 | D52: g | E52: Rectangular | F52: =C52/SQRT(3)/2 -> 0.0028867513 | G52: --- | H52: ---
A53: factor de presición | B53: =+precision!C7 -> 0.1183216 | D53: % | E53: Norma, K=1 | F53: =B53/SQRT(1) -> 0.1183216 | G53: 1 | H53: =+F53*G53 -> 0.1183216
A54: Incertidumbre Estándar Combinada | D54: % | F54: =SQRT((H41*H41)+(H45*H45)+(H49*H49)+(H53*H53)) -> #DIV/0! | I54: PASO 7
A55: Incertidumbre Expandida, K = 2 | D55: % | F55: =F54*2 -> #DIV/0! | I55: PASO 8
B59: CONTRIBUCIÓN
B60: Factor de Influencia | C60: Valor | D60: %
B61: =A41 -> Masa Humeda y tara | C61: =H41 -> #DIV/0! | D61: =C61*100/$C$65 -> #DIV/0!
B62: =A45 -> Masa Seca y tara | C62: =H45 -> #DIV/0! | D62: =C62*100/$C$65 -> #DIV/0!
B63: =A49 -> Masa Tara | C63: =H49 -> #DIV/0! | D63: =C63*100/$C$65 -> #DIV/0!
B64: =A53 -> factor de presición | C64: =H53 -> 0.1183216 | D64: =C64*100/$C$65 -> #DIV/0!
...

Sheet Balanza
B2: CALIBRACION DE LA BALANZA | J2: CALIBRACION DE LA BALANZA
B3: Correccion | C3: -3.29e-06 | J3: Correccion | K3: 3.79e-06
B4: Variables | C4: 0.00416 | D4: 2.43e-10 | J4: Variables | K4: 4.43e-05 | L4: 2.3e-10
B5: Ecuacion | C5: 2*RAIZ(0.00416+0.000000000243*R2) | J5: Ecuacion | K5: 2*RAIZ(0.0000443+0.000000000230xR2)
B6: Resolucion | C6: 0.1 | D6: g | J6: Resolucion | K6: 0.01
B7: Codigo | C7: EQP-0046 | J7: Codigo | K7: EQP-0045
B8: Fecha calibracion | D8: 46132 | J8: FECHA CALIBRACION | L8: 46132
B12: ÍTEM | C12: MES | D12: 200 | E12: 500 | F12: 1000 | G12: 5000 | H12: 10000 | J12: ÍTEM | K12: MES | L12: 20 | M12: 200 | N12: 500 | O12: 1000
C16: DESV STD | D16: 0 | E16: 0 | F16: 0 | G16: 0 | H16: 0 | K16: DESV STD | L16: 0 | M16: 0 | N16: 0 | O16: 0
C18: Busqueda de Repetibilidad de la masa | J18: Busqueda de Repetibilidad de la masa
D20: =+D12 -> 200 | E20: =+E12 -> 500 | F20: =+F12 -> 1000 | G20: =+G12 -> 5000 | H20: =+H12 -> 10000 | K20: 20 | L20: 200 | M20: 500 | N20: 1000
D21: =D16 -> 0 | E21: =E16 -> 0 | F21: =F16 -> 0 | G21: =G16 -> 0 | H21: =H16 -> 0 | K21: =L16 -> 0 | L21: =M16 -> 0 | M21: =N16 -> 0 | N21: =O16 -> 0
E23: Tara + suelo húmedo | F23: =ABS(+'Datos ensayo'!$H$19) -> 0 | G23: =IF(AND(F23<=$H$20,F23>$G$20),$H$21,IF(AND(F23<=$G$20,F23>$F$20),$G$21,IF(AND(F23<=$F$20,F23>$E$20),$F$21,IF(AND(F23<=$E$20,F23>$D$20),$E$21,IF(F23<=$D$20,$D$21))))) -> 0 | L23: Tara + suelo húmedo | M23: =ABS(+'Datos ensayo'!$H$19) -> 0 | N23: =IF(AND(M23<=$N$20,M23>$M$20),$N$21,IF(AND(M23<=$M$20,M23>$L$20),$M$21,IF(AND(M23<=$L$20,M23>$K$20),$L$21,IF(M23<=$K$20,$K$21)))) -> 0
E24: Tara + suelo seco 2 | F24: =ABS(+'Datos ensayo'!$H$21) -> 0 | G24: =IF(AND(F24<=$H$20,F24>$G$20),$H$21,IF(AND(F24<=$G$20,F24>$F$20),$G$21,IF(AND(F24<=$F$20,F24>$E$20),$F$21,IF(AND(F24<=$E$20,F24>$D$20),$E$21,IF(F24<=$D$20,$D$21))))) -> 0 | L24: Tara + suelo seco 2 | M24: =ABS(+'Datos ensayo'!$H$21) -> 0 | N24: =IF(AND(M24<=$N$20,M24>$M$20),$N$21,IF(AND(M24<=$M$20,M24>$L$20),$M$21,IF(AND(M24<=$L$20,M24>$K$20),$L$21,IF(M24<=$K$20,$K$21)))) -> 0
E25: Peso de tara | F25: =ABS(+'Datos ensayo'!$H$22) -> 0 | G25: =IF(AND(F25<=$H$20,F25>$G$20),$H$21,IF(AND(F25<=$G$20,F25>$F$20),$G$21,IF(AND(F25<=$F$20,F25>$E$20),$F$21,IF(AND(F25<=$E$20,F25>$D$20),$E$21,IF(F25<=$D$20,$D$21))))) -> 0 | L25: Peso de tara | M25: =ABS(+'Datos ensayo'!$H$22) -> 0 | N25: =IF(AND(M25<=$N$20,M25>$M$20),$N$21,IF(AND(M25<=$M$20,M25>$L$20),$M$21,IF(AND(M25<=$L$20,M25>$K$20),$L$21,IF(M25<=$K$20,$K$21)))) -> 0

Sheet precision
B4: Factor de precision del operador CONTENIDO HUMEDAD SUELO
B5: Fecha | C5: 46064
B7: Desviacion Estándar Repetibilidad (Sr) | C7: 0.1183216
B8: Desviacion Estándar Reproducibilidad (SR) | C8: 0.11937336

Sheet Hoja1
A2: CODIGO | C2: CONCATENADOS | D2: DESCRIPCION | E2: FC | F2: F. MOLDEO | G2: DIA | H2: DIAMETRO | I2: CARGA | J2: AREA | K2: RESIS. CONCRETO | L2: % RESIS | M2: TIPO DE FALLA
A3: 4400 | B3: =+A3+1 -> 4401 | C3: =A3&"-"&B3 -> 4400-4401 | D3: Columnas C-9;5-3/G.H | E3: 350 | F3: 42347 | G3: 7 | H3: 15.05 | I3: 49900 | J3: =H3*H3*PI()/4 -> 177.89465 | K3: =I3/J3 -> 280.5031 | L3: =+K3/E3 -> 0.80143743 | M3: E
C4: =A4&"-"&B4 -> - | E4: 350 | G4: 7 | H4: 15.06 | I4: 50310 | J4: =H4*H4*PI()/4 -> 178.13113 | K4: =I4/J4 -> 282.43238 | L4: =+K4/E4 -> 0.80694967 | M4: F
A5: =+B3+1 -> 4402 | B5: =+A5+1 -> 4403 | C5: =A5&"-"&B5 -> 4402-4403 | E5: 350 | G5: 14 | H5: 15.04 | I5: 56450 | J5: =H5*H5*PI()/4 -> 177.65832 | K5: =I5/J5 -> 317.74476 | L5: =+K5/E5 -> 0.90784216 | M5: F
C6: =A6&"-"&B6 -> - | E6: 350 | G6: 14 | H6: 15 | I6: 59630 | J6: =H6*H6*PI()/4 -> 176.71459 | K6: =I6/J6 -> 337.43677 | L6: =+K6/E6 -> 0.96410507 | M6: F
A7: =+B5+1 -> 4404 | B7: =+A7+1 -> 4405 | C7: =A7&"-"&B7 -> 4404-4405 | E7: 350 | G7: 28 | H7: 15.11 | I7: 65310 | J7: =H7*H7*PI()/4 -> 179.3159 | K7: =I7/J7 -> 364.21755 | L7: =+K7/E7 -> 1.0406216 | M7: F
C8: =A8&"-"&B8 -> - | E8: 350 | G8: 28 | H8: 15.05 | I8: 64730 | J8: =H8*H8*PI()/4 -> 177.89465 | K8: =I8/J8 -> 363.86705 | L8: =+K8/E8 -> 1.0396201 | M8: E
