Workbook

Sheet Resumen
A3: LABORATORIO DE ENSAYO DE MATERIALES
A4: FORMATO RESUMEN N° F-LEM-P-CO-12.03
A6: CLIENTE | B6: MAKIBER S. A. SUCURSAL PERÚ
A7: SOLICITANTE | B7: WILLIAM BEDRIÑANA CARRASCO
A8: PROYECTO ** | B8: MEJORAMIENTO Y AMPLIACION DE LOS SERVICIOS DE SALUD DEL HOSPITAL DE APOYO DE HUANTA DANIEL ALCIDES CARRIÓN, DISTRITO DE HUANTA, PROVINCIA DE HUANTA, DEPARTAMENTO DE AYACUCHO
A9: UBICACIÓN ** | B9: JR. JULIO CESAR TELLO, DISTRITO DE HUANTA, PROVINCIA DE HUANTA, DEPARTAMENTO DE AYACUCHO
A12: CONTROL DE PROBETAS | F12: FORMATO COMPRESION
A13: CODIGO MUESTRA LEM | B13: ELEMENTO | C13: F'c (kg/cm2) | D13: FECHA MOLDEO | E13: FECHA ROTURA | F13: Diametro 1 | G13: Diametro 2 | H13: Longitud 1 | I13: Longitud 2 | J13: Longitud 3 | K13: Carga Máxima (kN) | L13: Tipo fractura
A14: HHTA-MURO PERIMETRAL-(EJE-D-N @ 09"-10")-210-459 | B14: MURO PERIMETRAL | C14: 210 | D14: 46202 | E14: 46209 | F14: 150.3 | G14: 150.6 | H14: 300.2 | I14: 300.6 | J14: 300.2 | K14: 392.4 | L14: 2
A15: HHTA-LOSA PAVIMENTACION TRAMO I Y II-(EJE-D-N @ 09"-10")-210-460 | B15: LOSA PAVIMENTACION TRAMO I Y II | C15: 210 | D15: 46202 | E15: 46209 | F15: 150.1 | G15: 150.3 | H15: 300.4 | I15: 300.4 | J15: 300.7 | K15: 397.1 | L15: 2
A16: HHTA-LOSA PAVIMENTACION TRAMO I Y II-(EJE-D-N @ 09"-10")-210-461 | B16: LOSA PAVIMENTACION TRAMO I Y II | C16: 210 | D16: 46202 | E16: 46209 | F16: 150.4 | G16: 150.2 | H16: 301.2 | I16: 301.2 | J16: 300.8 | K16: 406.2 | L16: 3

Sheet COMPRESION
A2: LABORATORIO DE ENSAYO DE MATERIALES
A3: 0
A5: CLIENTE | B5: : | C5: =+Resumen!B6 -> MAKIBER S. A. SUCURSAL PERÚ | J5: CÓDIGO | K5: : | L5: F-LEM-P-CO-12.02
A6: SOLICITANTE ** | B6: : | C6: =+Resumen!B7 -> WILLIAM BEDRIÑANA CARRASCO | J6: FECHA EMISIÓN | K6: : | L6: 0
A7: PROYECTO ** | B7: : | C7: =+Resumen!B8 -> MEJORAMIENTO Y AMPLIACION DE LOS SERVICIOS DE SALUD DEL HOSPITAL DE APOYO DE HUANTA DANIEL ALCIDES CARRIÓN, DISTRITO DE HUANTA, PROVINCIA DE HUANTA, DEPARTAMENTO DE AYACUCHO
A8: UBICACIÓN ** | B8: : | C8: =+Resumen!B9 -> JR. JULIO CESAR TELLO, DISTRITO DE HUANTA, PROVINCIA DE HUANTA, DEPARTAMENTO DE AYACUCHO
A9: **Datos proporcionados y de responsabilidad del cliente
A11: STANDARD TEST METHOD FOR COMPRESSIVE STRENGTH OF CYLINDRICAL CONCRETE SPECIMENS
A12: ASTM C39/C39M-24
A14: IDENTIFICACIÓN DE LA MUESTRA
A16: Elemento** | B16: : | C16: =+Resumen!B14 -> MURO PERIMETRAL | J16: Fecha Moldeo** | K16: : | L16: =+DATOS!C11 -> 46202
A17: F´c (Kg/cm2) ** | B17: : | C17: =+Resumen!C14 -> 210 | J17: Fecha Rotura | K17: : | L17: =+DATOS!C13 -> 46209
A18: Tipo muestra | B18: : | C18: =+DATOS!C17 -> Cilindros Moldeados | J18: Edad muestra (Dias) | K18: : | L18: =+DATOS!C15 -> 7
A19: LUGAR DE ENSAYO: Laboratorio de ensayo de materiales
A21: Código muestra LEM | D21: Diámetro promedio (mm) | F21: Longitud promedio (mm) | G21: Área sección transversal (mm2) | H21: Carga Máxima (kN) | I21: Resistencia Compresión (MPa) | J21: Resistencia Compresión (Kg/cm2) | K21: Tipo fractura
A22: =IF(DATOS!B20="","--",DATOS!B20) -> HHTA-MURO PERIMETRAL-(EJE-D-N @ 09"-10")-210-459 | D22: =+DATOS!D36 -> 150.4498 | F22: =+DATOS!E36 -> 300.33283 | G22: =+DATOS!F36 -> 17777.641 | H22: =+DATOS!G36 -> 392.4 | I22: =+DATOS!H36 -> 22.07267 | J22: =+I22*10.1972 -> 225.07943 | K22: =+DATOS!I36 -> 2
A23: =IF(DATOS!B21="","--",DATOS!B21) -> HHTA-LOSA PAVIMENTACION TRAMO I Y II-(EJE-D-N @ 09"-10")-210-460 | D23: =+DATOS!D37 -> 150.1998 | F23: =+DATOS!E37 -> 300.4995 | G23: =+DATOS!F37 -> 17718.608 | H23: =+DATOS!G37 -> 397.1 | I23: =+DATOS!H37 -> 22.411467 | J23: =+I23*10.1972 -> 228.53421 | K23: =+DATOS!I37 -> 2
A24: =IF(DATOS!B22="","--",DATOS!B22) -> HHTA-LOSA PAVIMENTACION TRAMO I Y II-(EJE-D-N @ 09"-10")-210-461 | D24: =+DATOS!D38 -> 150.2998 | F24: =+DATOS!E38 -> 301.06616 | G24: =+DATOS!F38 -> 17742.209 | H24: =+DATOS!G38 -> 406.2 | I24: =+DATOS!H38 -> 22.894556 | J24: =+I24*10.1972 -> 233.46036 | K24: =+DATOS!I38 -> 3
A27: Observaciones:
C28: Equipos Utilizados en el ensayo:
C29: Identificaión | D29: Nombre | F29: Marca | G29: Modelo | H29: No. Serie | I29: N°Certificado
C30: EQP-0153 | D30: Prensa | F30: ELE Intenational | G30: 36-0690/06 | H30: 36-0690-06-1029 | I30: LF-A-093-2026
A43: Página 1 de 1
A44: Versión: 05 (07-07-2026) | M44: Fin del Documento

Sheet Hoja2
B3: Código muestra LEM | C3: Código cliente | D3: Diámetro promedio (mm) | E3: Longitud promedio (mm) | F3: Área sección transversal (mm2) | G3: Carga Máxima (kN) | H3: Resistencia Compresión (Mpa) | I3: Densidad muestra (kg/m3) | J3: Tipo fractura
G5: PROMEDIO | H5: =AVERAGE(H4) -> #DIV/0!

Sheet DATOS
B2: STANDARD TEST METHOD FOR COMPRESSIVE STRENGTH OF CYLINDRICAL CONCRETE SPECIMENS1
B3: ASTM C39/C39M-25
B5: Certificado de Calibración: balanza 30kg precisión 1g | H5: Certificado de Calibración: Pie de rey precisión 0.01mm
B6: Correccion | C6: =+#REF! -> #REF! | D6: F.calibracion | E6: =+#REF! -> #REF! | H6: Correccion | J6: -0.0002 | K6: mm
B8: IDENTIFICACION DE LA MUESTRA | G8: Resistencia concreto
B9: Estructura | C9: =+Resumen!B14 -> MURO PERIMETRAL | G9: kg/cm2 | H9: Mpa | K9: REALIZADO POR: | L9: - | N9: EVALUACIÓN DE DEFECTO DE LA MUESTRA
B10: F´c (kg/cm2) | C10: =+Resumen!C14 -> 210 | E10: =+LOOKUP(C10,G10:G16,H10:H16) -> 20.594 | G10: 100 | H10: 9.80665 | N10: A | O10: Presencia de grandes huecos de aire
B11: Fecha Moldeo | C11: =+Resumen!D14 -> 46202 | G11: 140 | H11: 13.7293 | N11: B | O11: Evidencia de segregación
B12: Hora de Moldeo | E12: Solo para <3dias | G12: 175 | H12: 17.1616 | N12: C | O12: Las fracturas pasan predominantemente alrededor de la particula gruesa
B13: Fecha Rotura | C13: =+Resumen!E14 -> 46209 | G13: 210 | H13: 20.594 | N13: D | O13: Las fracturas pasan a travez del agregado grueso
B14: Hora de ensayo | E14: Obligatorio <3d | G14: 245 | H14: 24.0263 | N14: E | O14: Desprendimiento tapa adherida
B15: Edad muestra | C15: =+IF(C13-C11<3,(INT(((C13+C14)-(C11+C12))*24)),C13-C11) -> 7 | E15: dias | G15: 280 | H15: 27.4586
B16: Densidad | G16: 350 | H16: 34.3233
B17: Tipo muestra | C17: Cilindros Moldeados
B19: Código muestra LEM | D19: Diametro 1 | E19: Diametro 2 | F19: Longitud 1 | G19: Longitud 2 | H19: Longitud 3 | I19: Carga Máxima (kN) | J19: Tipo fractura | K19: Masa muestra aire (g) | L19: Parametro Diametro | M19: Defecto de muestra | N19: Evaluación del defecto de muestra
B20: =+Resumen!A14 -> HHTA-MURO PERIMETRAL-(EJE-D-N @ 09"-10")-210-459 | D20: =+Resumen!F14 -> 150.3 | E20: =+Resumen!G14 -> 150.6 | F20: =+Resumen!H14 -> 300.2 | G20: =+Resumen!I14 -> 300.6 | H20: =+Resumen!J14 -> 300.2 | I20: =+Resumen!K14 -> 392.4 | J20: =+Resumen!L14 -> 2 | L20: =+IF(((MAX(D20,E20)-MIN(D20,E20))/D20)*100<2,"Cumple","No Cumple") -> Cumple | M20: =+IF(AND(C15>=28,E10<H36),"ok",IF(C15<28,"--","Evaluar")) -> -- | N20: -
B21: =+Resumen!A15 -> HHTA-LOSA PAVIMENTACION TRAMO I Y II-(EJE-D-N @ 09"-10")-210-460 | D21: =+Resumen!F15 -> 150.1 | E21: =+Resumen!G15 -> 150.3 | F21: =+Resumen!H15 -> 300.4 | G21: =+Resumen!I15 -> 300.4 | H21: =+Resumen!J15 -> 300.7 | I21: =+Resumen!K15 -> 397.1 | J21: =+Resumen!L15 -> 2 | L21: =+IF(((MAX(D21,E21)-MIN(D21,E21))/D21)*100<2,"Cumple","No Cumple") -> Cumple | M21: =+IF(AND(C15>=28,E10<H37),"ok",IF(C15<28,"--","Defecto de muestra")) -> --
B22: =+Resumen!A16 -> HHTA-LOSA PAVIMENTACION TRAMO I Y II-(EJE-D-N @ 09"-10")-210-461 | D22: =+Resumen!F16 -> 150.4 | E22: =+Resumen!G16 -> 150.2 | F22: =+Resumen!H16 -> 301.2 | G22: =+Resumen!I16 -> 301.2 | H22: =+Resumen!J16 -> 300.8 | I22: =+Resumen!K16 -> 406.2 | J22: =+Resumen!L16 -> 3 | L22: =+IF(((MAX(D22,E22)-MIN(D22,E22))/D22)*100<2,"Cumple","No Cumple") -> Cumple | M22: =+IF(AND(C15>=28,E10<H38),"ok",IF(C15<28,"--","Defecto de muestra")) -> --
D24: =+D20*$D$45+$D$46 -> -0.0002006 | E24: =+E20*$D$45+$D$46 -> -0.0002012 | F24: =+F20*$H$45+$H$46 -> -0.0005004 | G24: =+G20*$H$45+$H$46 -> -0.0005012 | H24: =+H20*$H$45+$H$46 -> -0.0005004
D25: =+D21*$D$49+$D$50 -> -0.0002002 | E25: =+E21*$D$49+$D$50 -> -0.0002006 | F25: =+F21*$H$49+$H$50 -> -0.0005008 | G25: =+G21*$H$49+$H$50 -> -0.0005008 | H25: =+H21*$H$49+$H$50 -> -0.0005014
D26: =+D22*$D$53+$D$54 -> -0.0002008 | E26: =+E22*$D$53+$D$54 -> -0.0002004 | F26: =+F22*$H$53+$H$54 -> -0.0005024 | G26: =+G22*$H$53+$H$54 -> -0.0005024 | H26: =+H22*$H$53+$H$54 -> -0.0005016
D28: CORRECCION DIAMETRO | F28: CORRECCION LONGITUD | I28: CORRECION MASA | K28: F.C. COMPRESION | M28: F'C | O28: F. correc. Compresion | R28: =(STDEV(H36:H37)/AVERAGE(H36:H37))*100 -> 1.0770821
D29: Diametro 1 | E29: Diametro 2 | F29: Longitud 1 | G29: Longitud 2 | H29: Longitud 3 | I29: Masa aire (g) | J29: Masa aire (kg) | K29: L/D | L29: Factor correccion | O29: L/D | P29: Factor
D30: =+D20+D24 -> 150.2998 | E30: =+E20+E24 -> 150.5998 | F30: =+F20+F24 -> 300.1995 | G30: =+G20+G24 -> 300.5995 | H30: =+H20+H24 -> 300.1995 | K30: =+E36/D36 -> 1.9962329 | L30: =IF(AND(K30>1.75,K30<=2.2),1,FORECAST(K30,P31:P34,O31:O34)) -> 1 | M30: =+L36/$C$10 -> 1.0718068 | O30: SI ES MAYOR > 1.75 | P30: 1
D31: =+D21+D25 -> 150.0998 | E31: =+E21+E25 -> 150.2998 | F31: =+F21+F25 -> 300.3995 | G31: =+G21+G25 -> 300.3995 | H31: =+H21+H25 -> 300.6995 | K31: =+E37/D37 -> 2.0006651 | L31: =IF(AND(K31>1.75,K31<=2.2),1,FORECAST(K31,P31:P34,O31:O34)) -> 1 | M31: =+L37/$C$10 -> 1.0882581 | O31: 1.75 | P31: 0.98
D32: =+D22+D26 -> 150.3998 | E32: =+E22+E26 -> 150.1998 | F32: =+F22+F26 -> 301.1995 | G32: =+G22+G26 -> 301.1995 | H32: =+H22+H26 -> 300.7995 | K32: =+E38/D38 -> 2.0031042 | L32: =IF(AND(K32>1.75,K32<=2.2),1,FORECAST(K32,P32:P34,O32:O34)) -> 1 | M32: =+L38/$C$10 -> 1.111716 | O32: 1.5 | P32: 0.96
O33: 1.25 | P33: 0.93
D34: Diámetro promedio (mm) | E34: Longitud promedio (mm) | F34: Área sección transversal (mm2) | G34: Carga Máxima (kN) | H34: Resistencia Compresión (Mpa) | I34: Tipo fractura | J34: Densidad muestra (kg/m3) | L34: Resistencia Compresión (kg/cm2) | O34: 1 | P34: 0.87
D36: =+(D30+E30)/2 -> 150.4498 | E36: =+(F30+G30+H30)/3 -> 300.33283 | F36: =3.1416*D36^2/4 -> 17777.641 | G36: =+I20 -> 392.4 | H36: =(4000*G36/3.1416/D36^2)*L30 -> 22.07267 | I36: =+J20 -> 2 | J36: =IF($C$16="no","---",MROUND((4*(10^9)*J30)/E36/(D36^2)/3.1416,10)) -> 0 | L36: =+H36*10.1972 -> 225.07943
D37: =+(D31+E31)/2 -> 150.1998 | E37: =+(F31+G31+H31)/3 -> 300.4995 | F37: =3.1416*D37^2/4 -> 17718.608 | G37: =+I21 -> 397.1 | H37: =(4000*G37/3.1416/D37^2)*L31 -> 22.411467 | I37: =+J21 -> 2 | J37: =IF($C$16="no","---",MROUND((4*(10^9)*J31)/E37/(D37^2)/3.1416,10)) -> 0 | L37: =+H37*10.1972 -> 228.53421
D38: =+(D32+E32)/2 -> 150.2998 | E38: =+(F32+G32+H32)/3 -> 301.06616 | F38: =3.1416*D38^2/4 -> 17742.209 | G38: =+I22 -> 406.2 | H38: =(4000*G38/3.1416/D38^2)*L32 -> 22.894556 | I38: =+J22 -> 3 | J38: =IF($C$16="no","---",MROUND((4*(10^9)*J32)/E38/(D38^2)/3.1416,10)) -> 0 | L38: =+H38*10.1972 -> 233.46036
B41: NO MOVER
J42: ITEM | K42: Valor | L42: Error
B43: =MATCH(D20,K43:K52) -> 3 | C43: =INDEX(J43:L52,B43,2) -> 100 | D43: =INDEX(J43:L52,B43,3) -> -0.0001 | F43: =MATCH(F20,K43:K52) -> 4 | G43: =INDEX(J43:L52,F43,2) -> 200 | H43: =INDEX(J43:L52,F43,3) -> -0.0003 | J43: 1 | K43: 0 | L43: 0
B44: =B43+1 -> 4 | C44: =INDEX(J43:L52,B44,2) -> 200 | D44: =INDEX(J43:L52,B44,3) -> -0.0003 | F44: =F43+1 -> 5 | G44: =INDEX(J43:L52,F44,2) -> 400 | H44: =INDEX(J43:L52,F44,3) -> -0.0007 | J44: 2 | K44: 50 | L44: -0.0002
C45: pendiente | D45: =+SLOPE(D43:D44,C43:C44) -> -2e-06 | G45: pendiente | H45: =+SLOPE(H43:H44,G43:G44) -> -2e-06 | J45: 3 | K45: 100 | L45: -0.0001
C46: intercepto | D46: =+INTERCEPT(D43:D44,C43:C44) -> 0.0001 | G46: intercepto | H46: =+INTERCEPT(H43:H44,G43:G44) -> 0.0001 | J46: 4 | K46: 200 | L46: -0.0003
B47: =MATCH(D21,K43:K52) -> 3 | C47: =INDEX(J43:L52,B47,2) -> 100 | D47: =INDEX(J43:L52,B47,3) -> -0.0001 | F47: =MATCH(F21,K43:K52) -> 4 | G47: =INDEX(J43:L52,F47,2) -> 200 | H47: =INDEX(J43:L52,F47,3) -> -0.0003 | J47: 5 | K47: 400 | L47: -0.0007
B48: =B47+1 -> 4 | C48: =INDEX(J43:L52,B48,2) -> 200 | D48: =INDEX(J43:L52,B48,3) -> -0.0003 | F48: =F47+1 -> 5 | G48: =INDEX(J43:L52,F48,2) -> 400 | H48: =INDEX(J43:L52,F48,3) -> -0.0007 | J48: 6 | K48: 450 | L48: -0.0009
C49: pendiente | D49: =+SLOPE(D47:D48,C47:C48) -> -2e-06 | G49: pendiente | H49: =+SLOPE(H47:H48,G47:G48) -> -2e-06
...

Sheet Hoja1
A2: CODIGO | C2: CONCATENADOS | D2: DESCRIPCION | E2: FC | F2: F. MOLDEO | G2: DIA | H2: DIAMETRO | I2: CARGA | J2: AREA | K2: RESIS. CONCRETO | L2: % RESIS | M2: TIPO DE FALLA
A3: 4400 | B3: =+A3+1 -> 4401 | C3: =A3&"-"&B3 -> 4400-4401 | D3: Columnas C-9;5-3/G.H | E3: 350 | F3: 42347 | G3: 7 | H3: 15.05 | I3: 49900 | J3: =H3*H3*PI()/4 -> 177.89465 | K3: =I3/J3 -> 280.5031 | L3: =+K3/E3 -> 0.80143743 | M3: E
C4: =A4&"-"&B4 -> - | E4: 350 | G4: 7 | H4: 15.06 | I4: 50310 | J4: =H4*H4*PI()/4 -> 178.13113 | K4: =I4/J4 -> 282.43238 | L4: =+K4/E4 -> 0.80694967 | M4: F
A5: =+B3+1 -> 4402 | B5: =+A5+1 -> 4403 | C5: =A5&"-"&B5 -> 4402-4403 | E5: 350 | G5: 14 | H5: 15.04 | I5: 56450 | J5: =H5*H5*PI()/4 -> 177.65832 | K5: =I5/J5 -> 317.74476 | L5: =+K5/E5 -> 0.90784216 | M5: F
C6: =A6&"-"&B6 -> - | E6: 350 | G6: 14 | H6: 15 | I6: 59630 | J6: =H6*H6*PI()/4 -> 176.71459 | K6: =I6/J6 -> 337.43677 | L6: =+K6/E6 -> 0.96410507 | M6: F
A7: =+B5+1 -> 4404 | B7: =+A7+1 -> 4405 | C7: =A7&"-"&B7 -> 4404-4405 | E7: 350 | G7: 28 | H7: 15.11 | I7: 65310 | J7: =H7*H7*PI()/4 -> 179.3159 | K7: =I7/J7 -> 364.21755 | L7: =+K7/E7 -> 1.0406216 | M7: F
C8: =A8&"-"&B8 -> - | E8: 350 | G8: 28 | H8: 15.05 | I8: 64730 | J8: =H8*H8*PI()/4 -> 177.89465 | K8: =I8/J8 -> 363.86705 | L8: =+K8/E8 -> 1.0396201 | M8: E
