Workbook
Name ___CC2: [1]Sucs!$L$6
Name __CC2: [1]Sucs!$L$6
Name _CC1: [2]Sucs!$L$6
Name _CC2: [1]Sucs!$L$6
Name _CU1: [2]Sucs!$L$5
Name _IP1: [2]Sucs!$L$4
Name _L1: #REF!
Name _L1: #REF!
Name _L1: #REF!
Name _Ll1: [2]Sucs!$L$3
Name _W1: #REF!
Name _W1: #REF!
Name _W1: #REF!
Name Abra: [3]Sucs!$C$3
Name CC: #REF!
Name CC: #REF!
Name CC: [4]Sucs!$L$6
Name CCf: '[2]Sucs(Fino)'!$L$6
Name CCVB: [5]Sucs!$L$3
Name CM: [6]BGA!$H$9
Name CU: #REF!
Name CU: #REF!
Name CU: [4]Sucs!$L$5
Name CUf: '[2]Sucs(Fino)'!$L$5
Name hh: #REF!
Name hh: #REF!
Name hh: #REF!
Name IP: #REF!
Name IP: #REF!
Name IP: [4]Sucs!$L$4
Name IPf: '[2]Sucs(Fino)'!$L$4
Name L: #REF!
Name L: #REF!
Name L: #REF!
Name LIf: '[2]Sucs(Fino)'!$L$3
Name Ll: #REF!
Name Ll: #REF!
Name Ll: [4]Sucs!$L$3
Name MORA: [6]BGA!$H$13
Name N_10: #REF!
Name N_10: #REF!
Name N_10: [4]Sucs!$C$5
Name N_101: [2]Sucs!$C$5
Name N_10f: '[2]Sucs(Fino)'!$C$5
Name N_200: #REF!
Name N_200: #REF!
Name N_200: [4]Sucs!$C$3
Name N_2001: [2]Sucs!$C$3
Name N_200f: '[2]Sucs(Fino)'!$C$3
Name N_40: #REF!
Name N_40: #REF!
Name N_40: [4]Sucs!$C$4
Name N_401: [2]Sucs!$C$4
Name N_40f: '[2]Sucs(Fino)'!$C$4
Name PC: [5]Sucs!$C$5
Name TABLA: #REF!
Name TABLA: #REF!
Name TABLA: #REF!
Name tipodegranulometria: '[7]G-LL '!$X$2:$X$3
Name tipodegranulometria: '[7]G-LL '!$X$2:$X$3

Sheet FORMATO
P2: CLIENTE
P3: DIRECCIÓN **
P4: PROYECTO **
P5: UBICACIÓN **
A7: LABORATORIO DE ENSAYO DE MATERIALES | P7: RECEPCIÓN N°
A8: FORMATO N° F-LEM-P-AG-22.01 | P8: F. EMISIÓN
P9: OT N°
C10: MUESTRA | E10: N° OT | G10: FECHA DE ENSAYO | I10: REALIZADO
P11: CÓDIGO DE LA MUESTRA
P12: FECHA DE RECEPCIÓN
A13: Standard Test Method for Bulk Density (“Unit Weight”) and Voids in Aggregate | P13: FECHA DE EJECUCIÓN
A14: ASTM C29/C29M-23
P15: CANTERA/SONDAJE **
C16: Datos del recipiente | J16: Marque el método "X" | P16: N° MUESTRA **
B17: a | C17: Molde | H17: N° | J17: A: Varillado | P17: TIPO DE MUESTRA**
B18: b | C18: Masa de medida | H18: kg | J18: B: Percusión*
B19: c | C19: Volumen de la medida | H19: m³ | J19: C: Suelto
J20: * Desde Molde de 1pie3
C21: Tipo de muestra : | H21: Masa del agregado (g) | O21: IRMA, TIPO DE MUESTRA: AGREGADO FINO, GRUESO O MIXTO
C22: Tamaño máximo nominal agregado (visual) (in): | H22: Masa del agregado seco (g)
H23: Masa del agregado seco constante**(g)
H24: **A masa seco constante inferior a 0.1%
C25: Peso Unitario
C26: Prueba N° | G26: 1 | H26: 2 | J26: 3 | M26: Und.
B27: d | C27: Masa del agregado mas medida
B28: e | C28: Masa del agregado | F28: (d-b)
B29: f | C29: Densidad aparente del agregado | F29: (e/c)
F31: Promedio: Densidad aparente del agregado | M31: kg/m³
C33: Contenido de Vacíos
B34: i | C34: Gravedad especifica base seca | M34: - | O34: IRMA, Densidad relativa (gravedad especifica) (OD) - REALIZAR ENSAYO C127 O C128
B35: j | C35: Densidad del agua | M35: kg/m³
B36: k | C36: % de vacíos | F36: 100*[(i*j)-f]/(i*j) | M36: %
F38: Promedio: % Vacios | M38: %
A40: Capacidad de medidas | H40: Equipo utilizado | K40: Código
H41: Molde
H42: Balanza
H43: Varrilla de apisonamiento
H44: Horno
C45: Fuente: Norma ASTM C29/C29M-17a.
A46: Observaciones:
...

Sheet INFORME
A2: LABORATORIO DE ENSAYO DE MATERIALES
A3: 0
A5: CLIENTE | B5: : | C5: =+FORMATO!Q2 -> 0 | H5: CÓDIGO | I5: : | J5: F-LEM-P-AG-22.02
A6: DIRECCIÓN ** | B6: : | C6: =+FORMATO!Q3 -> 0 | H6: RECEPCIÓN N° | I6: : | J6: =+FORMATO!Q7 -> 0
A7: PROYECTO ** | B7: : | C7: =+FORMATO!Q4 -> 0 | H7: OT N° | I7: : | J7: =+FORMATO!Q9 -> 0
A8: UBICACIÓN ** | B8: : | C8: =+FORMATO!Q5 -> 0 | H8: FECHA DE EMISIÓN | I8: : | J8: =+FORMATO!Q8 -> 0
A9: ** Datos proporcionados por el cliente
A10: Standard Test Method for Bulk Density ("Unit Weight") and Voids in Aggregate
A11: ASTM C29/C29M-23
A13: DATOS DE LA MUESTRA
A14: CANTERA / SONDAJE ** | D14: : | E14: =+FORMATO!Q15 -> 0 | H14: CÓDIGO DE LA MUESTRA | I14: : | J14: =+FORMATO!Q11 -> 0
A15: N° MUESTRA ** | D15: : | E15: =+FORMATO!Q16 -> 0 | H15: FECHA DE RECEPCIÓN | I15: : | J15: =+FORMATO!Q12 -> 0
A16: TIPO DE MUESTRA | D16: : | E16: =+FORMATO!Q17 -> 0 | H16: FECHA DE EJECUCIÓN | I16: : | J16: =+FORMATO!Q13 -> 0 | L16: =+FORMATO!G11 -> 0
A17: LUGAR DE ENSAYO | D17: : | E17: Laboratorio de ensayo de materiales
E19: Datos del molde
E20: Molde | G20: =+DATOS!F18 -> 0 | H20: N°
E21: Masa de medida | G21: =+DATOS!G19 -> 0 | H21: kg
E22: Volumen de la medida | G22: =+DATOS!G20 -> 0 | H22: m³
A24: MÉTODO DE ENSAYO: | F24: =DATOS!B17 -> C Suelto
A26: DENSIDAD APARENTE
A27: Prueba N° | F27: 1 | G27: 2 | H27: 3 | J27: Und.
A28: Masa del agregado mas medida | F28: =+DATOS!F24 -> 0 | G28: =+DATOS!H24 -> 0 | H28: =+DATOS!J24 -> 0 | J28: kg
A29: Masa del agregado | F29: =+DATOS!F25 -> 0 | G29: =+DATOS!H25 -> 0 | H29: =+DATOS!J25 -> 0 | J29: kg
A30: Densidad aparente del agregado | F30: =ROUND(+DATOS!F26,-1) -> #DIV/0! | G30: =ROUND(+DATOS!H26,-1) -> #DIV/0! | H30: =ROUND(+DATOS!J26,-1) -> #DIV/0! | J30: kg/m³ | K30: al 10 kg/m³
E32: Promedio: Densidad aparente del agregado | H32: =ROUND(AVERAGE(F30:H30),-1) -> #DIV/0! | I32: kg/m³ | K32: al 10 kg/m³
A34: CONTENIDO DE VACIOS
A35: Densidad aparente del agregado | F35: =+DATOS!F29 -> #DIV/0! | G35: =+DATOS!H29 -> #DIV/0! | H35: =+DATOS!J29 -> #DIV/0! | J35: kg/m³
A36: Gravedad específica base seca (ASTM C128-22) | F36: =+DATOS!F30 -> 0 | G36: =+DATOS!H30 -> 0 | H36: =+DATOS!J30 -> 0 | J36: -
A37: Densidad del agua | F37: =+DATOS!F31 -> 998 | G37: =+DATOS!H31 -> 998 | H37: =+DATOS!J31 -> 998 | J37: kg/m³
A38: % de Vacios | F38: =ROUND(+DATOS!F32,0) -> #DIV/0! | G38: =ROUND(+DATOS!H32,0) -> #DIV/0! | H38: =ROUND(+DATOS!J32,0) -> #DIV/0! | J38: % | K38: al 1%
F40: Promedio: % Vacios | H40: =ROUND(AVERAGE(F38:H38),0) -> #DIV/0! | I40: % | K40: al 1%
A42: Descripción de la muestra:
A43: Tamaño máximo nominal (in) | F43: =+DATOS!E47 -> 0
A44: Forma de la particula | F44: =+DATOS!E48 -> 0
A46: Nota:
A47: - El cliente es responsable de los datos de identificación de los puntos de ensayo brindados.
A48: - Los resultados expresados se refieren únicamente al ensayo realizado en dicho momento y en las condiciones especificadas en este documento, por lo que GEOFAL S.A.C. no será responsable por los ensayos realizados con la presente muestra en condiciones distintas a las aquí señaladas.
A49: - GEOFAL S.A.C. no se hace responsable por el uso incorrecto o inadecuado del presente informe.
A50: - Los resultados de los ensayos realizados no deben ser utilizados como una certificación de conformidad con normas de producto o como certificado del sistema de calidad de la entidad que lo produce.
A51: - De conformidad con lo dispuesto por el artículo 1321 del Código Civil, queda establecido que en ningún caso la responsabilidad de GEOFAL S.A.C. será mayor al valor del servicio prestado.
...

Sheet DATOS
A2: Standard Test Method for Bulk Density ("Unit Weight") and Voids in Aggregate
A3: ASTM C29/C29M-23
B5: Informacion para la Correccion por Certificado de Calibración: | G5: Capacidad maxima 30kg | I5: =IF(F18<=2,E7,E12) -> -1.49e-06 | K5: OPERADORES
B6: Precisión de la Balanza al 0.001 kg | K6: - | L6: =+FORMATO!I11 -> 0
B7: Corrección | E7: =+Balanza!C8 -> -1.49e-06
B8: CODIGO | E8: =+Balanza!C12 -> EQP-0054
B9: Fecha | E9: =+Balanza!D13 -> 46160
B10: Informacion para la Correccion por Certificado de Calibración: | G10: Capacidad maxima 150kg
B11: Precisión de la Balanza al 0.01kg
B12: Corrección | E12: =+Balanza!N8 -> -7.73e-06
B13: CODIGO | E13: =+Balanza!N12 -> EQP-0059
B14: Fecha | E14: =+Balanza!O13 -> 46160
B16: Método ensayo | D16: Datos del molde | J16: MOLDE | K16: BALANZA
B17: C Suelto | D17: Descripcion | F17: Datos | G17: correccion | H17: und | J17: 1 | K17: 30 kg
D18: Molde | F18: =+FORMATO!G17 -> 0 | G18: - | H18: N° | J18: 2 | K18: 30 kg
D19: Masa de la medida | F19: =+FORMATO!G18 -> 0 | G19: =+IF($F$18<=3,F19+$E$7*F19,F19+$E$12*F19) -> 0 | H19: kg | J19: 3 | K19: 150 kg
D20: Volumen de la medida | F20: =+FORMATO!G19 -> 0 | G20: =F20 -> 0 | H20: m³ | J20: 4 | K20: 150 kg
B22: Prueba N° | E22: 1 | G22: 2 | I22: 3 | K22: Und.
B23: Descripcion | E23: DATOS | F23: CORRECCION | G23: DATOS | H23: CORRECCION | I23: DATOS | J23: CORRECCION
B24: Masa del agregado mas medida | E24: =+FORMATO!G27 -> 0 | F24: =+IF($F$18<=2,E24+$E$7*E24,E24+$E$12*E24) -> 0 | G24: =+FORMATO!H27 -> 0 | H24: =+IF($F$18<=2,G24+$E$7*G24,G24+$E$12*G24) -> 0 | I24: =+FORMATO!J27 -> 0 | J24: =+IF($F$18<=2,I24+$E$7*I24,I24+$E$12*I24) -> 0 | K24: kg
B25: Masa del agregado | E25: =E24-$F$19 -> 0 | F25: =F24-$G$19 -> 0 | G25: =G24-$F$19 -> 0 | H25: =H24-$G$19 -> 0 | I25: =I24-$F$19 -> 0 | J25: =J24-$G$19 -> 0 | K25: kg
B26: Densidad aparente del agregado | E26: =E25/$F$20 -> #DIV/0! | F26: =F25/$G$20 -> #DIV/0! | G26: =G25/$F$20 -> #DIV/0! | H26: =H25/$G$20 -> #DIV/0! | I26: =I25/$F$20 -> #DIV/0! | J26: =J25/$G$20 -> #DIV/0! | K26: kg/m3
B28: CONTENIDO DE VACIOS
B29: Densidad aparente del agregado | F29: =F25/$G$20 -> #DIV/0! | H29: =H25/$G$20 -> #DIV/0! | J29: =J25/$G$20 -> #DIV/0! | K29: kg/m³
B30: Gravedad especifica base seca | F30: =+FORMATO!G34 -> 0 | H30: =+F30 -> 0 | J30: =+F30 -> 0 | K30: - | L30: OD
B31: Densidad del agua | F31: 998 | H31: =+F31 -> 998 | J31: =+F31 -> 998 | K31: kg/m³
B32: % de Vacios | F32: =(100*((F30*F31)-F29)/(F30*F31)) -> #DIV/0! | H32: =(100*((H30*H31)-H29)/(H30*H31)) -> #DIV/0! | J32: =(100*((J30*J31)-J29)/(J30*J31)) -> #DIV/0! | K32: %
B34: En observaciones se colocara | E34: Ref. Informe XX-26 XX, sobre la gravedad especifica
B35: Gravedad especifica base seca(OD) - REALIZAR ENSAYO C127 O C128
B36: Incertidumbre G.E. | D36: 0.01
B38: Tipo de muestra | D38: PARAMETRO DE CONTROL | H38: Control
D39: Parametro calculado | F39: Limites diferencia Norma | J39: DAA
D40: 1S | E40: d2s | F40: 1S | G40: d2s | J40: =+F26 -> #DIV/0!
B41: Agregado grueso | D41: =+STDEV(MAX(J40:J42),MIN(J40:J42)) -> #DIV/0! | E41: =D41*2.8 -> #DIV/0! | F41: 14 | G41: 40 | H41: =IF(E41<G41, "cumple", "no cumple") -> #DIV/0! | J41: =+H26 -> #DIV/0!
B42: Agregado fino | D42: =+STDEV(MAX(J40:J42),MIN(J40:J42)) -> #DIV/0! | E42: =D42*2.8 -> #DIV/0! | F42: 14 | G42: 40 | H42: =IF(E42<G42, "cumple", "no cumple") -> #DIV/0! | J42: =+J26 -> #DIV/0!
B44: =+INFORME!E16 -> 0 | D44: =+IF(B44="Agregado fino",H42,H41) -> #DIV/0!
B46: Descripción de la muestra:
B47: Tamaño máximo nominal (in) | E47: =+FORMATO!G22 -> 0
B48: Forma de la particula | E48: 0

Sheet Incertidumbre
B1: INFORME DE ESTIMACIÓN DE INCERTIDUMBRE | O1: Código: | P1: F-LEM-P-10.01
O2: Versión: | P2: 3
O3: Fecha: | P3: 46146
O4: Página: | P4: 1 de 1
A6: Método: | B6: Standard Test Method for Bulk Density ("Unit Weight") and Voids in Aggregate
A7: Norma: | B7: ASTM C29/C29M-23
A8: Matriz: | B8: Agregado
A9: Mensurando | B9: Peso unitario al aire de las particulas de agregado incluido los vacios
A11: Paso 1. Definicion del proceso de medición
A13: Variables: | F13: Fórmula:
A15: M = densidad aparente del agregado, kg m3
A16: G = masa del agregado más la medida, kg
A17: T = masa de la medida, kg
A18: V = volumen de la medida, m3
A20: M = densidad aparente del agregado, kg/m3
A21: S = gravedad específica a granel (base seca)
A22: W = densidad del agua, 998 kg/m3
A24: Equipos a utilizar:
A26: Balanza con resulución de lectura de 0.001kg o 0.01kg
A28: Paso 2. Definición de las variables aleatorias
A40: DENSIDAD APARENTE
A41: Fuentes | B41: Valor | C41: Incertidumbre Original | D41: Unidades | E41: Distribución | F41: Incertidumbre Estándar u(xi) | G41: Coeficiente de Sensibilidad | H41: Contribución ui(y) | I41: Valor | J41: Incertidumbre Original | K41: Unidades | L41: Distribución | M41: Incertidumbre Estándar u(xi) | N41: Coeficiente de Sensibilidad | O41: Contribución ui(y) | P41: Valor | Q41: Incertidumbre Original | R41: Unidades | S41: Distribución | T41: Incertidumbre Estándar u(xi) | U41: Coeficiente de Sensibilidad | V41: Contribución ui(y)
A42: Peso Unitario (kg/m3) | B42: =+(B43-B47)/B51 -> #DIV/0! | I42: =+(I43-I47)/I51 -> #DIV/0! | P42: =+(P43-P47)/P51 -> #DIV/0!
A43: Masa del agregado mas la medida (Kg) | B43: =+Balanza!D26 -> 0 | C43: G | F43: =SQRT((F44*F44)+(F45*F45)+(F46*F46)) -> 1.106044 | G43: =1/B51 -> #DIV/0! | H43: =+G43*F43 -> #DIV/0! | I43: =Balanza!F26 -> 0 | M43: =SQRT((M44*M44)+(M45*M45)+(M46*M46)) -> 1.106044 | N43: =1/I51 -> #DIV/0! | O43: =+N43*M43 -> #DIV/0! | P43: =Balanza!H26 -> 0 | T43: =SQRT((T44*T44)+(T45*T45)+(T46*T46)) -> 1.106044 | U43: =1/P51 -> #DIV/0! | V43: =+U43*T43 -> #DIV/0!
A44: Repetibilidad de la pesada | C44: =+IF($K$67<=2,Balanza!E26,Balanza!P26) -> 0 | D44: kg | E44: Normal, K=1 | F44: =C44 -> 0 | G44: --- | H44: --- | J44: =+IF($K$67<=2,Balanza!G26,Balanza!R26) -> 0 | K44: g | L44: Normal, K=1 | M44: =J44 -> 0 | N44: --- | O44: --- | Q44: =+IF($K$67<=2,Balanza!I26,Balanza!T26) -> 0 | R44: g | S44: Normal, K=1 | T44: =Q44 -> 0 | U44: --- | V44: ---
A45: Certificado de Calibración | C45: =2*(SQRT(Balanza!$J$8+Balanza!$K$8*(POWER(B43,2)))) -> 2.1354157 | D45: kg | E45: Normal, K=2 (/2) | F45: =C45/2 -> 1.0677078 | G45: --- | H45: --- | J45: =2*(SQRT(Balanza!$J$8+Balanza!$K$8*(POWER(I43,2)))) -> 2.1354157 | K45: g | L45: Normal, K=2 (/2) | M45: =J45/2 -> 1.0677078 | N45: --- | O45: --- | Q45: =2*(SQRT(Balanza!$J$8+Balanza!$K$8*(POWER(P43,2)))) -> 2.1354157 | R45: g | S45: Normal, K=2 (/2) | T45: =Q45/2 -> 1.0677078 | U45: --- | V45: ---
A46: Resolución | C46: =+Balanza!$J$9 -> 1 | D46: kg | E46: Rectangular | F46: =(C46/SQRT(3)/2) -> 0.28867513 | G46: --- | H46: --- | J46: =+Balanza!$J$9 -> 1 | K46: g | L46: Rectangular | M46: =(J46/SQRT(3)/2) -> 0.28867513 | N46: --- | O46: --- | Q46: =+Balanza!$J$9 -> 1 | R46: g | S46: Rectangular | T46: =(Q46/SQRT(3)/2) -> 0.28867513 | U46: --- | V46: ---
A47: Masa de la medida (kg) | B47: =+Balanza!D27 -> 0 | C47: T | F47: =SQRT((F48*F48)+(F49*F49)+(F50*F50)) -> 1.106044 | G47: =1/B51 -> #DIV/0! | H47: =+G47*F47 -> #DIV/0! | I47: =Balanza!F27 -> 0 | M47: =SQRT((M48*M48)+(M49*M49)+(M50*M50)) -> 1.106044 | N47: =1/I51 -> #DIV/0! | O47: =+N47*M47 -> #DIV/0! | P47: =Balanza!H27 -> 0 | T47: =SQRT((T48*T48)+(T49*T49)+(T50*T50)) -> 1.106044 | U47: =1/P51 -> #DIV/0! | V47: =+U47*T47 -> #DIV/0!
A48: Repetibilidad de la pesada | C48: =+IF($K$67<=2,Balanza!E27,Balanza!P27) -> 0 | D48: kg | E48: Normal, K=1 | F48: =C48 -> 0 | G48: --- | H48: --- | J48: =+IF($K$67<=2,Balanza!G27,Balanza!R27) -> 0 | K48: g | L48: Normal, K=1 | M48: =J48 -> 0 | N48: --- | O48: --- | Q48: =+IF($K$67<=2,Balanza!I27,Balanza!T27) -> 0 | R48: g | S48: Normal, K=1 | T48: =Q48 -> 0 | U48: --- | V48: ---
A49: Certificado de Calibración | C49: =2*(SQRT(Balanza!$J$8+Balanza!$K$8*(POWER(B47,2)))) -> 2.1354157 | D49: kg | E49: Normal, K=2 (/2) | F49: =C49/2 -> 1.0677078 | G49: --- | H49: --- | J49: =2*(SQRT(Balanza!$J$8+Balanza!$K$8*(POWER(I47,2)))) -> 2.1354157 | K49: g | L49: Normal, K=2 (/2) | M49: =J49/2 -> 1.0677078 | N49: --- | O49: --- | Q49: =2*(SQRT(Balanza!$J$8+Balanza!$K$8*(POWER(P47,2)))) -> 2.1354157 | R49: g | S49: Normal, K=2 (/2) | T49: =Q49/2 -> 1.0677078 | U49: --- | V49: ---
A50: Resolución | C50: =+Balanza!$J$9 -> 1 | D50: kg | E50: Rectangular | F50: =(C50/SQRT(3)/2) -> 0.28867513 | G50: --- | H50: --- | J50: =+Balanza!$J$9 -> 1 | K50: g | L50: Rectangular | M50: =(J50/SQRT(3)/2) -> 0.28867513 | N50: --- | O50: --- | Q50: =+Balanza!$J$9 -> 1 | R50: g | S50: Rectangular | T50: =(Q50/SQRT(3)/2) -> 0.28867513 | U50: --- | V50: ---
A51: Volumen de la medida (m3) | B51: =+Balanza!D28 -> 0 | C51: V | F51: =+H76 -> 0 | G51: =+ABS((B47-B43)/POWER(B51,2)) -> #DIV/0! | H51: =+F51*G51 -> #DIV/0! | I51: =B51 -> 0 | M51: =+F51 -> 0 | N51: =+ABS((I47-I43)/POWER(I51,2)) -> #DIV/0! | O51: =+N51*M51 -> #DIV/0! | P51: =B51 -> 0 | T51: =+F51 -> 0 | U51: =+ABS((P47-P43)/POWER(P51,2)) -> #DIV/0! | V51: =+U51*T51 -> #DIV/0!
A52: Factor de presicion | B52: =+Precision!B23 -> 3.4123957 | D52: % | E52: Norma, K=1 | F52: =+B52 -> 3.4123957 | G52: 1 | H52: =+F52*G52 -> 3.4123957 | I52: =+B52 -> 3.4123957 | K52: % | L52: Norma, K=1 | M52: =+I52 -> 3.4123957 | N52: 1 | O52: =+M52*N52 -> 3.4123957 | P52: =+B52 -> 3.4123957 | R52: % | S52: Norma, K=1 | T52: =+P52 -> 3.4123957 | U52: 1 | V52: =+T52*U52 -> 3.4123957
A53: Incertidumbre Estándar Combinada | H53: =SQRT((H43*H43)+(H47*H47)+(H51*H51)+(H52*H52)) -> #DIV/0! | O53: =SQRT((O43*O43)+(O47*O47)+(O51*O51)+(O52*O52)) -> #DIV/0! | V53: =SQRT((V43*V43)+(V47*V47)+(V51*V51)+(V52*V52)) -> #DIV/0!
A54: Incertidumbre Expandida, K = 2 | G54: kg/m3 | H54: =MAX(H53:V53)*2 -> #DIV/0!
A56: % VACIOS
A57: Fuentes | B57: Valor | C57: Incertidumbre Original | D57: Unidades | E57: Distribución | F57: Incertidumbre Estándar u(xi) | G57: Coeficiente de Sensibilidad | H57: Contribución ui(y) | I57: Valor | J57: Incertidumbre Original | K57: Unidades | L57: Distribución | M57: Incertidumbre Estándar u(xi) | N57: Coeficiente de Sensibilidad | O57: Contribución ui(y) | P57: Valor | Q57: Incertidumbre Original | R57: Unidades | S57: Distribución | T57: Incertidumbre Estándar u(xi) | U57: Coeficiente de Sensibilidad | V57: Contribución ui(y)
A58: % Vacios | B58: =100*(B60*998-B59)/(B60*998) -> #DIV/0! | I58: =100*(I60*998-I59)/(I60*998) -> #DIV/0! | P58: =100*(P60*998-P59)/(P60*998) -> #DIV/0!
A59: Densidad aparente del agregado | B59: =+B42 -> #DIV/0! | C59: m | D59: kg/m3 | F59: =+H53 -> #DIV/0! | G59: =100/(B60*998) -> #DIV/0! | H59: =+F59*G59 -> #DIV/0! | I59: =+I42 -> #DIV/0! | M59: =+O53 -> #DIV/0! | N59: =100/(I60*998) -> #DIV/0! | O59: =+N59*M59 -> #DIV/0! | P59: =+P42 -> #DIV/0! | T59: =+V53 -> #DIV/0! | U59: =100/(P60*998) -> #DIV/0! | V59: =+U59*T59 -> #DIV/0!
A60: Gravedad especifica | B60: =+DATOS!F30 -> 0 | C60: s | F60: =+DATOS!D36 -> 0.01 | G60: =100*B59/(998*POWER(B60,2)) -> #DIV/0! | H60: =+F60*G60 -> #DIV/0! | I60: =+B60 -> 0 | M60: =+F60 -> 0.01 | N60: =100*I59/(998*POWER(I60,2)) -> #DIV/0! | O60: =+N60*M60 -> #DIV/0! | P60: =+B60 -> 0 | T60: =+F60 -> 0.01 | U60: =100*P59/(998*POWER(P60,2)) -> #DIV/0! | V60: =+U60*T60 -> #DIV/0!
...

Sheet Molde
B2: 8.6 Mida la temperatura del agua al 0.5 °C [1 °F] más cercano y determine su densidad de la Tabla 3, interpolando si es necesario.
D5: Tabla 03. Densidad del agua. | I5: 15.6 | J5: 999.01
I6: 18.3 | J6: 998.54
I7: 21.1 | J7: 997.97
I8: 23 | J8: 997.54
I9: 23.9 | J9: 997.32
I10: 26.7 | J10: 996.59
I11: 29.4 | J11: 995.83
B12: 8.7 Calcule el volumen, V, de la medida. Alternativamente, calcule el factor F para la medida.
B14: NOTA 4 — Para el cálculo de la densidad aparente, el volumen de la medida en unidades SI debe expresarse en metros cúbicos, o el factor como 1/m3. Sin embargo, por conveniencia, el tamaño de la medida puede expresarse en litros.
A18: Considerar que para la medida del volumen del molde:
A19: La verificacion del molde se reliza usando el agua, motivo por el cual el volumen del molde es: la diferencia de la masa del molde + agua y masa del molde.
C23: Masa de agua en el molde: | D23: =+F37 -> 5197.9
B25: Verificacion del molde de Peso Unitario
C27: MOLDE USADO | F27: Promedio | G27: Desviacion estandar | I27: Temperatura del agua (X): | K27: =C35 -> 24.9
A28: Altura del molde : | C28: 4545 | D28: 4545 | E28: 4545 | F28: =AVERAGE(C28:E28) -> 4545
I29: Densidad del Agua (Y): | K29: =(-0.2306*K27)+1002.8 -> 997.05806
A30: Diametro del molde : | C30: 457 | D30: 457 | E30: 457 | F30: =AVERAGE(C30:E30) -> 457
I31: Volumen del Molde: | K31: =+DATOS!F20 -> 0 | L31: m3
A32: Masa del Molde | C32: 3456 | D32: 3456 | E32: 3457 | F32: =AVERAGE(C32:E32) -> 3456.3333 | G32: =STDEV(C32:E32) -> 0.57735027
I33: Volumen corregido por T°: | K33: =K31*K29/1000 -> 0 | L33: m3
A34: Masa del molde y vidrio + Agua | C34: 8654 | D34: 8654.2 | E34: 8654.5 | F34: 8654.1 | G34: =STDEV(C34:E34) -> 0.25166115
A35: T° DE AGUA | C35: 24.9
A37: Masa del agua en molde | C37: =C34-C32 -> 5198 | D37: =D34-D32 -> 5198.2 | E37: =E34-E32 -> 5197.5 | F37: =AVERAGE(C37:E37) -> 5197.9
A39: * COPIAR DE LA PARTE DE ABAJO EL MOLDE SEGÚN EL CODIGO (SOLO EL AMARILLO) QUE AN REGISTRADO EN LABORATORIO
A43: INS -003 | I43: INS - 004 | Q43: INS - 005
C45: MOLDE USADO | F45: Promedio | G45: Desviacion estandar | K45: MOLDE USADO | N45: Promedio | O45: Desviacion estandar | S45: MOLDE USADO | V45: Promedio | W45: Desviacion estandar
A46: Altura del molde : | C46: 149.3 | D46: 148.9 | E46: 149.1 | F46: =AVERAGE(C46:E46) -> 149.1 | I46: Altura del molde : | K46: 230.5 | L46: 230.5 | M46: 230.5 | N46: =AVERAGE(K46:M46) -> 230.5 | Q46: Altura del molde : | S46: 280 | T46: 280 | U46: 280 | V46: =AVERAGE(S46:U46) -> 280
A48: Diametro del molde : | C48: 156.58 | D48: 156.6 | E48: 156.61 | F48: =AVERAGE(C48:E48) -> 156.59667 | I48: Diametro del molde : | K48: 228 | L48: 228 | M48: 228 | N48: =AVERAGE(K48:M48) -> 228 | Q48: Diametro del molde : | S48: 254.4 | T48: 254.5 | U48: 254.5 | V48: =AVERAGE(S48:U48) -> 254.46667
A50: Masa del Molde | C50: 2595 | D50: 2595 | F50: =AVERAGE(C50:E50) -> 2595 | G50: =STDEV(C50:E50) -> 0 | I50: Masa del Molde | K50: 5694 | L50: 5694 | N50: =AVERAGE(K50:M50) -> 5694 | O50: =STDEV(K50:M50) -> 0 | Q50: Masa del Molde | S50: 10564 | T50: 10564 | V50: =AVERAGE(S50:U50) -> 10564 | W50: =STDEV(S50:U50) -> 0
A52: Masa del molde y vidrio + Agua | C52: 5455 | D52: 5455 | F52: 8654.1 | G52: =STDEV(C52:E52) -> 0 | I52: Masa del molde y vidrio + Agua | K52: 15059 | L52: 15054 | N52: 8654.1 | O52: =STDEV(K52:M52) -> 3.5355339 | Q52: Masa del molde y vidrio + Agua | S52: 24664 | T52: 24664 | V52: 8654.1 | W52: =STDEV(S52:U52) -> 0
A53: T° DE AGUA | C53: 23.2 | I53: T° DE AGUA | K53: 9.36 | Q53: T° DE AGUA | S53: 14.1
A57: INS - 0135
C59: MOLDE USADO | F59: Promedio | G59: Desviacion estandar
A60: Altura del molde : | C60: 329 | D60: 329 | E60: 329 | F60: =AVERAGE(C60:E60) -> 329
A62: Diametro del molde : | C62: 331 | D62: 331 | E62: 331 | F62: =AVERAGE(C62:E62) -> 331
A64: Masa del Molde | C64: 188 | D64: 188 | F64: =AVERAGE(C64:E64) -> 188 | G64: =STDEV(C64:E64) -> 0
A66: Masa del molde y vidrio + Agua | C66: 468 | D66: 468 | F66: 8654.1 | G66: =STDEV(C66:E66) -> 0
A67: T° DE AGUA | C67: 23.2

Sheet Balanza
B1: CALIBRACION DE LA BALANZA | M1: CALIBRACION DE LA BALANZA
Q4: 150KG
H5: 30KG
J7: =+DATOS!F18 -> 0
B8: Correccion | C8: -1.49e-06 | J8: =+IF($J$7<=2,C9,N9) -> 1.14 | K8: =+IF($J$7<=2,D9,O9) -> 2.48e-10 | M8: Correccion | N8: -7.73e-06
B9: Variables | C9: 1.14 | D9: 2.48e-10 | J9: =+IF($J$7<=2,C11,N11) -> 1 | M9: Variables | N9: 6.39e-05 | O9: 6.97e-10
B10: Ecuacion | C10: 2*RAIZ(1.14+0.000000000248*R2) | F10: g | M10: Ecuacion | N10: 2*RAIZ(0.0000639+0.000000000697*R2) | Q10: kg
B11: Resolucion | C11: 1 | D11: g | M11: Resolucion | N11: 0.01 | O11: kg
B12: Codigo | C12: EQP-0054 | M12: Codigo | N12: EQP-0059
B13: Fecha de calibración | D13: 46160 | M13: Fecha de calibración | O13: 46160
B14: Item | C14: Mes | D14: 500 | E14: 1000 | F14: 5000 | G14: 10000 | H14: 15000 | I14: 20000 | M14: Item | N14: Mes | O14: 5 | P14: 10 | Q14: 15 | R14: 20 | S14: 30 | T14: 40 | U14: 60
B18: =COUNT(B14:B16) -> 0 | C18: DESV STD | D18: 0 | E18: 0 | F18: 0 | G18: 0 | H18: 0 | I18: 0 | M18: =COUNT(M14:M16) -> 0 | N18: DESV STD | O18: 0 | P18: 0 | Q18: 0 | R18: 0 | S18: 0 | T18: 0 | U18: 0
D20: Busqueda de Repetibilidad de la masa | O20: Busqueda de Repetibilidad de la masa
D22: 500 | E22: 1000 | F22: 5000 | G22: 10000 | H22: 15000 | I22: 20000 | O22: =+O14 -> 5 | P22: =+P14 -> 10 | Q22: =+Q14 -> 15 | R22: =+R14 -> 20 | S22: =+S14 -> 30 | T22: =+T14 -> 40 | U22: =+U14 -> 60 | V22: =+V14 -> 0 | W22: =+W14 -> 0
D23: =D18 -> 0 | E23: =E18 -> 0 | F23: =F18 -> 0 | G23: =G18 -> 0 | H23: =H18 -> 0 | I23: =I18 -> 0 | O23: =O18 -> 0 | P23: =P18 -> 0 | Q23: =Q18 -> 0 | R23: =R18 -> 0 | S23: =S18 -> 0 | T23: =T18 -> 0 | U23: =U18 -> 0 | V23: =V18 -> 0 | W23: =W18 -> 0
D25: Ensayo 1 | F25: Ensayo 2 | H25: Ensayo 3 | O25: Ensayo 1 | Q25: Ensayo 2 | S25: Ensayo 3
C26: Masa del agregado mas la medida (Kg) | D26: =+DATOS!F24 -> 0 | E26: =IF((D26*1000)<=$D$22,$D$23,IF(AND((D26*1000)>$D$22,(D26*1000)<=$E$22),$E$23,IF(AND((D26*1000)>$E$22,(D26*1000)<=$F$22),$F$23,IF(AND((D26*1000)>$F$22,(D26*1000)<=$G$22),$G$23,IF(AND((D26*1000)>$G$22,(D26*1000)<=$H$22),$H$23,IF(AND((D26*1000)>$H$22,(D26*1000)<=$I$22),$I$23,$I$23)))))) -> 0 | F26: =+DATOS!H24 -> 0 | G26: =IF((F26*1000)<=$D$22,$D$23,IF(AND((F26*1000)>$D$22,(F26*1000)<=$E$22),$E$23,IF(AND((F26*1000)>$E$22,(F26*1000)<=$F$22),$F$23,IF(AND((F26*1000)>$F$22,(F26*1000)<=$G$22),$G$23,IF(AND((F26*1000)>$G$22,(F26*1000)<=$H$22),$H$23,IF(AND((F26*1000)>$H$22,(F26*1000)<=$I$22),$I$23,$I$23)))))) -> 0 | H26: =+DATOS!J24 -> 0 | I26: =IF((H26*1000)<=$D$22,$D$23,IF(AND((H26*1000)>$D$22,(H26*1000)<=$E$22),$E$23,IF(AND((H26*1000)>$E$22,(H26*1000)<=$F$22),$F$23,IF(AND((H26*1000)>$F$22,(H26*1000)<=$G$22),$G$23,IF(AND((H26*1000)>$G$22,(H26*1000)<=$H$22),$H$23,IF(AND((H26*1000)>$H$22,(H26*1000)<=$I$22),$I$23,$I$23)))))) -> 0 | N26: Masa del agregado mas la medida (Kg) | O26: =+D26 -> 0 | P26: =IF(O26<=$O$22,$O$23,IF(AND(O26>$O$22,O26<=$P$22),$P$23,IF(AND(O26>$P$22,O26<=$Q$22),$Q$23,IF(AND(O26>$Q$22,O26<=$R$22),$R$23,IF(AND(O26>$R$22,O26<=$S$22),$S$23,IF(AND(O26>$S$22,O26<=$T$22),$T$23,IF(AND(O26>$T$22,O26<=$U$22),$U$23,IF(AND(O26>$U$22,O26<=$V$22),$V$23,IF(AND(O26>$V$22,O26<=$W$22),$W$23,$W$23))))))))) -> 0 | Q26: =+F26 -> 0 | R26: =IF(Q26<=$O$22,$O$23,IF(AND(Q26>$O$22,Q26<=$P$22),$P$23,IF(AND(Q26>$P$22,Q26<=$Q$22),$Q$23,IF(AND(Q26>$Q$22,Q26<=$R$22),$R$23,IF(AND(Q26>$R$22,Q26<=$S$22),$S$23,IF(AND(Q26>$S$22,Q26<=$T$22),$T$23,IF(AND(Q26>$T$22,Q26<=$U$22),$U$23,IF(AND(Q26>$U$22,Q26<=$V$22),$V$23,IF(AND(Q26>$V$22,Q26<=$W$22),$W$23,$W$23))))))))) -> 0 | S26: =+H26 -> 0 | T26: =IF(S26<=$O$22,$O$23,IF(AND(S26>$O$22,S26<=$P$22),$P$23,IF(AND(S26>$P$22,S26<=$Q$22),$Q$23,IF(AND(S26>$Q$22,S26<=$R$22),$R$23,IF(AND(S26>$R$22,S26<=$S$22),$S$23,IF(AND(S26>$S$22,S26<=$T$22),$T$23,IF(AND(S26>$T$22,S26<=$U$22),$U$23,IF(AND(S26>$U$22,S26<=$V$22),$V$23,IF(AND(S26>$V$22,S26<=$W$22),$W$23,$W$23))))))))) -> 0
C27: Masa de la medida (kg) | D27: =+DATOS!G19 -> 0 | E27: =IF((D27*1000)<=$D$22,$D$23,IF(AND((D27*1000)>$D$22,(D27*1000)<=$E$22),$E$23,IF(AND((D27*1000)>$E$22,(D27*1000)<=$F$22),$F$23,IF(AND((D27*1000)>$F$22,(D27*1000)<=$G$22),$G$23,IF(AND((D27*1000)>$G$22,(D27*1000)<=$H$22),$H$23,IF(AND((D27*1000)>$H$22,(D27*1000)<=$I$22),$I$23,$I$23)))))) -> 0 | F27: =+D27 -> 0 | G27: =IF((F27*1000)<=$D$22,$D$23,IF(AND((F27*1000)>$D$22,(F27*1000)<=$E$22),$E$23,IF(AND((F27*1000)>$E$22,(F27*1000)<=$F$22),$F$23,IF(AND((F27*1000)>$F$22,(F27*1000)<=$G$22),$G$23,IF(AND((F27*1000)>$G$22,(F27*1000)<=$H$22),$H$23,IF(AND((F27*1000)>$H$22,(F27*1000)<=$I$22),$I$23,$I$23)))))) -> 0 | H27: =+D27 -> 0 | I27: =IF((H27*1000)<=$D$22,$D$23,IF(AND((H27*1000)>$D$22,(H27*1000)<=$E$22),$E$23,IF(AND((H27*1000)>$E$22,(H27*1000)<=$F$22),$F$23,IF(AND((H27*1000)>$F$22,(H27*1000)<=$G$22),$G$23,IF(AND((H27*1000)>$G$22,(H27*1000)<=$H$22),$H$23,IF(AND((H27*1000)>$H$22,(H27*1000)<=$I$22),$I$23,$I$23)))))) -> 0 | N27: Masa de la medida (kg) | O27: =+D27 -> 0 | P27: =IF(O27<=$O$22,$O$23,IF(AND(O27>$O$22,O27<=$P$22),$P$23,IF(AND(O27>$P$22,O27<=$Q$22),$Q$23,IF(AND(O27>$Q$22,O27<=$R$22),$R$23,IF(AND(O27>$R$22,O27<=$S$22),$S$23,IF(AND(O27>$S$22,O27<=$T$22),$T$23,IF(AND(O27>$T$22,O27<=$U$22),$U$23,IF(AND(O27>$U$22,O27<=$V$22),$V$23,IF(AND(O27>$V$22,O27<=$W$22),$W$23,$W$23))))))))) -> 0 | Q27: =+F27 -> 0 | R27: =IF(Q27<=$O$22,$O$23,IF(AND(Q27>$O$22,Q27<=$P$22),$P$23,IF(AND(Q27>$P$22,Q27<=$Q$22),$Q$23,IF(AND(Q27>$Q$22,Q27<=$R$22),$R$23,IF(AND(Q27>$R$22,Q27<=$S$22),$S$23,IF(AND(Q27>$S$22,Q27<=$T$22),$T$23,IF(AND(Q27>$T$22,Q27<=$U$22),$U$23,IF(AND(Q27>$U$22,Q27<=$V$22),$V$23,IF(AND(Q27>$V$22,Q27<=$W$22),$W$23,$W$23))))))))) -> 0 | S27: =+H27 -> 0 | T27: =IF(S27<=$O$22,$O$23,IF(AND(S27>$O$22,S27<=$P$22),$P$23,IF(AND(S27>$P$22,S27<=$Q$22),$Q$23,IF(AND(S27>$Q$22,S27<=$R$22),$R$23,IF(AND(S27>$R$22,S27<=$S$22),$S$23,IF(AND(S27>$S$22,S27<=$T$22),$T$23,IF(AND(S27>$T$22,S27<=$U$22),$U$23,IF(AND(S27>$U$22,S27<=$V$22),$V$23,IF(AND(S27>$V$22,S27<=$W$22),$W$23,$W$23))))))))) -> 0
C28: Volumen de la medida (m3) | D28: =+DATOS!G20 -> 0 | N28: Volumen de la medida (m3) | O28: =+D28 -> 0

Sheet Precision
A3: FACTOR DE PRECISION OPERADOR
A4: Fecha de evaluacion: | B4: 46112
A6: 1-Calcular la Incertidumbre estandar bajo condiciones de reproducibilidad Suelto C | H6: 1-Calcular la Incertidumbre estandar bajo condiciones de reproducibilidad Compactado A
A7: Desviacion Estándar Repetibilidad (Sr) | B7: 3.4123957 | H7: Desviacion Estándar Repetibilidad (Sr) | I7: 3.6423436
A8: Desviacion Estándar Reproducibilidad (SR) | B8: 3.4843566 | H8: Desviacion Estándar Reproducibilidad (SR) | I8: 3.8670019
A9: T1 | B9: =+#REF!*#REF!+#REF!*#REF! -> #REF! | H9: T1 | I9: =+#REF!*#REF!+#REF!*#REF! -> #REF!
A10: T2 | B10: =+#REF!*POWER(#REF!,2)+#REF!*POWER(#REF!,2) -> #REF! | H10: T2 | I10: =+#REF!*POWER(#REF!,2)+#REF!*POWER(#REF!,2) -> #REF!
A11: T3 | B11: =+SUM(#REF!) -> #REF! | H11: T3 | I11: =+SUM(#REF!) -> #REF!
A12: T4 | B12: =+POWER(#REF!,2)+POWER(#REF!,2) -> #REF! | H12: T4 | I12: =+POWER(#REF!,2)+POWER(#REF!,2) -> #REF!
A13: T5 | B13: =(#REF!-1)*SUM(#REF!) -> #REF! | H13: T5 | I13: =(#REF!-1)*SUM(#REF!) -> #REF!
A14: Varianza Repetibilidad (Sr2 ) | B14: =ABS((B13/(B11-#REF!))) -> #REF! | H14: Varianza Repetibilidad (Sr2 ) | I14: =ABS((I13/(I11-#REF!))) -> #REF!
A15: Varianza entre Laboratorios (SL2) | B15: =ABS((((B10*B11-(B9^2))/(B11*(#REF!-1)))-(B14))*((B11*(#REF!-1))/((B11^2)-B12))) -> #REF! | H15: Varianza entre Laboratorios (SL2) | I15: =ABS((((I10*I11-(I9^2))/(I11*(#REF!-1)))-(I14))*((I11*(#REF!-1))/((I11^2)-I12))) -> #REF!
A16: Varianza Reproducibilidad (SR2) | B16: =(B14+B15)/1000000 -> #REF! | H16: Varianza Reproducibilidad (SR2) | I16: =(I14+I15)/1000000 -> #REF!
A17: Desviacion Estándar Repetibilidad (Sr) | B17: =SQRT(B14) -> #REF! | H17: Desviacion Estándar Repetibilidad (Sr) | I17: =SQRT(I14) -> #REF!
A18: Desviacion Estándar Reproducibilidad (SR) | B18: =+SQRT(B14+B15) -> #REF! | H18: Desviacion Estándar Reproducibilidad (SR) | I18: =+SQRT(I14+I15) -> #REF!
A21: compactado | B21: =+I7 -> 3.6423436
A22: suelto | B22: =+B7 -> 3.4123957
A23: =+DATOS!B17 -> C Suelto | B23: =+IF(A23="A Varillado",B21,B22) -> 3.4123957

Sheet Hoja1
A2: CODIGO | C2: CONCATENADOS | D2: DESCRIPCION | E2: FC | F2: F. MOLDEO | G2: DIA | H2: DIAMETRO | I2: CARGA | J2: AREA | K2: RESIS. CONCRETO | L2: % RESIS | M2: TIPO DE FALLA
A3: 4400 | B3: =+A3+1 -> 4401 | C3: =A3&"-"&B3 -> 4400-4401 | D3: Columnas C-9;5-3/G.H | E3: 350 | F3: 42347 | G3: 7 | H3: 15.05 | I3: 49900 | J3: =H3*H3*PI()/4 -> 177.89465 | K3: =I3/J3 -> 280.5031 | L3: =+K3/E3 -> 0.80143743 | M3: E
C4: =A4&"-"&B4 -> - | E4: 350 | G4: 7 | H4: 15.06 | I4: 50310 | J4: =H4*H4*PI()/4 -> 178.13113 | K4: =I4/J4 -> 282.43238 | L4: =+K4/E4 -> 0.80694967 | M4: F
A5: =+B3+1 -> 4402 | B5: =+A5+1 -> 4403 | C5: =A5&"-"&B5 -> 4402-4403 | E5: 350 | G5: 14 | H5: 15.04 | I5: 56450 | J5: =H5*H5*PI()/4 -> 177.65832 | K5: =I5/J5 -> 317.74476 | L5: =+K5/E5 -> 0.90784216 | M5: F
C6: =A6&"-"&B6 -> - | E6: 350 | G6: 14 | H6: 15 | I6: 59630 | J6: =H6*H6*PI()/4 -> 176.71459 | K6: =I6/J6 -> 337.43677 | L6: =+K6/E6 -> 0.96410507 | M6: F
A7: =+B5+1 -> 4404 | B7: =+A7+1 -> 4405 | C7: =A7&"-"&B7 -> 4404-4405 | E7: 350 | G7: 28 | H7: 15.11 | I7: 65310 | J7: =H7*H7*PI()/4 -> 179.3159 | K7: =I7/J7 -> 364.21755 | L7: =+K7/E7 -> 1.0406216 | M7: F
C8: =A8&"-"&B8 -> - | E8: 350 | G8: 28 | H8: 15.05 | I8: 64730 | J8: =H8*H8*PI()/4 -> 177.89465 | K8: =I8/J8 -> 363.86705 | L8: =+K8/E8 -> 1.0396201 | M8: E
