Workbook
Name CC: [6]Sucs!$L$6
Name CC: Sucs!$L$6
Name _CC2: [3]Sucs!$L$6
Name CM: [1]BGA!$H$9
Name CU: [6]Sucs!$L$5
Name CU: Sucs!$L$5
Name IP: [6]Sucs!$L$4
Name IP: Sucs!$L$4
Name Ll: [6]Sucs!$L$3
Name Ll: Sucs!$L$3
Name MORA: [1]BGA!$H$13
Name N_10: [6]Sucs!$C$5
Name N_10: Sucs!$C$5
Name N_200: [6]Sucs!$C$3
Name N_200: Sucs!$C$3
Name N_40: [6]Sucs!$C$4
Name N_40: Sucs!$C$4
Name TABLA: #REF!
Name TABLA: #REF!
Name TABLA: #REF!
Name TABLA: #REF!

Sheet -------

Sheet Gran-LLyLP
M4: PROVIAS NACIONAL
A5: Análisis Mecánico por Tamizado y Límites de Atterberg
A8: Prog. | C8: Km. 54+710-54+910 | F8: Hecho por : | H8: F.T.V
A9: Registro | C9: SB - 25 | D9: M - 1 | F9: Revisado : | H9: F.K.S | K9: Límite Líquido MTC E 110 | R9: Golp. | S9: % Humed
A10: Estructura | C10: Sub Base Granular | K10: Ensayo | R10: =+M11 -> 0 | S10: =+M18 -> 0
A11: Fecha | C11: 38972 | K11: Nº de Golpes | R11: =+N11 -> 0 | S11: =+N18 -> 0
A12: Lado | C12: IZQ - DER | K12: Recipiente Nº | R12: =+O11 -> 0 | S12: =+O18 -> 0
K13: R + Suelo Hum.
A14: Granulometría (MTC E 204) | F14: Humedad Natural | K14: R + Suelo Seco
A15: Datos de ensayo | K15: Peso Recip. | R15: 25 | S15: 0
A16: Peso Total : | D16: 25681 | F16: P.M.H. = | H16: 384.6 | K16: Peso Agua | R16: 25 | S16: =+V17 -> #NUM! | T16: LL | V16: =+M18/(1.419-0.3*LOG10(M11)) -> #NUM! | W16: =+N18/(1.419-0.3*LOG10(N11)) -> #NUM! | X16: =+O18/(1.419-0.3*LOG10(O11)) -> #NUM!
A17: Peso de fracción : | D17: 491.5 | F17: P.M.S. = | H17: 364 | K17: Peso S. Seco | R17: 10 | S17: =+S16 -> #NUM! | T17: LL | V17: =+AVERAGE(V16:X16) -> #NUM!
A18: Peso de muestra lavada: | D18: =+S30+T28 -> 24395.311 | F18: % W = | H18: =(H16-H17)/H17*100 -> 5.6593407 | K18: % de Humedad
D19: : | T19: LP
K20: Límite Plástico MTC E 111 | S20: =+AVERAGE(M28:N28) -> #DIV/0! | T20: LP
A21: Malla | C21: Peso | D21: % Ret | E21: % Ret | F21: % que | G21: Especifi- | K21: Ensayo
A22: Tamiz | B22: mm. | C22: (gr) | D22: Parcial | E22: Acum. | F22: Pasa | G22: caciones | K22: Recipiente Nº | R22: 20.17 | S22: 21.22
A23: 3" | B23: 76.2 | G23: Gradacion | K23: R + Suelo Hum.
A24: 2 1/2" | B24: 63.5 | C24: 0 | D24: =ROUND(C24/D$16*100,1) -> 0 | E24: =+D24 -> 0 | F24: =100-E24 -> 100 | G24: "A" | K24: R + Suelo Seco
A25: 2" | B25: 50.6 | C25: 0 | D25: =ROUND(C25/D$16*100,1) -> 0 | E25: =+E24+D25 -> 0 | F25: =100-E25 -> 100 | G25: 100 | K25: Peso Recip.
A26: 1 1/2" | B26: 38.1 | C26: 1384 | D26: =ROUND(C26/D$16*100,1) -> 5.4 | E26: =+E25+D26 -> 5.4 | F26: =100-E26 -> 94.6 | I26: 100 | K26: Peso Agua
A27: 1" | B27: 25.4 | C27: 3256 | D27: =ROUND(C27/D$16*100,1) -> 12.7 | E27: =+E26+D27 -> 18.1 | F27: =100-E27 -> 81.9 | K27: Peso S. Seco | S27: =+D17 -> 491.5
A28: 3/4" | B28: 19.05 | C28: 2413 | D28: =ROUND(C28/D$16*100,1) -> 9.4 | E28: =+E27+D28 -> 27.5 | F28: =100-E28 -> 72.5 | K28: % de Humedad | S28: =+D17-C41 -> 425.4 | T28: =SUM(C23:C32) -> 16121
A29: 1/2" | B29: 12.7 | C29: 4064 | D29: =ROUND(C29/D$16*100,1) -> 15.8 | E29: =+E28+D29 -> 43.3 | F29: =100-E29 -> 56.7 | S29: =+D16-T28 -> 9560
A30: 3/8" | B30: 9.525 | C30: 1986 | D30: =ROUND(C30/D$16*100,1) -> 7.7 | E30: =+E29+D30 -> 51 | F30: =100-E30 -> 49 | G30: 30 | I30: 65 | S30: =+S29*S28/S27 -> 8274.3113
A31: 1/4" | B31: 6.35 | C31: 2164 | D31: =ROUND(C31/D$16*100,1) -> 8.4 | E31: =+E30+D31 -> 59.4 | F31: =100-E31 -> 40.6
A32: No4 | B32: 4.76 | C32: 854 | D32: =ROUND(C32/D$16*100,1) -> 3.3 | E32: =+E31+D32 -> 62.7 | F32: =100-E32 -> 37.3 | G32: 25 | I32: 55
A33: 8 | B33: 2.36 | C33: 125 | D33: =ROUND(C33*F$32/D$17,1) -> 9.5 | E33: =+E32+D33 -> 72.2 | F33: =100-E33 -> 27.8
A34: 10 | B34: 2 | C34: 18.6 | D34: =ROUND(C34*F$32/D$17,1) -> 1.4 | E34: =+E33+D34 -> 73.6 | F34: =100-E34 -> 26.4 | G34: 15 | I34: 40
A35: 16 | B35: 1.19 | C35: 85.8 | D35: =ROUND(C35*F$32/D$17,1) -> 6.5 | E35: =+E34+D35 -> 80.1 | F35: =100-E35 -> 19.9
A36: 30 | B36: 0.6 | C36: 96 | D36: =ROUND(C36*F$32/D$17,1) -> 7.3 | E36: =+E35+D36 -> 87.4 | F36: =100-E36 -> 12.6
A37: 40 | B37: 0.42 | C37: 19.6 | D37: =ROUND(C37*F$32/D$17,1) -> 1.5 | E37: =+E36+D37 -> 88.9 | F37: =100-E37 -> 11.1 | G37: 8 | I37: 20
A38: 50 | B38: 0.3 | C38: 23.6 | D38: =ROUND(C38*F$32/D$17,1) -> 1.8 | E38: =+E37+D38 -> 90.7 | F38: =100-E38 -> 9.3
A39: 100 | B39: 0.149 | C39: 25.6 | D39: =ROUND(C39*F$32/D$17,1) -> 1.9 | E39: =+E38+D39 -> 92.6 | F39: =100-E39 -> 7.4
A40: 200 | B40: 0.074 | C40: 31.2 | D40: =ROUND(C40*F$32/D$17,1) -> 2.4 | E40: =+E39+D40 -> 95 | F40: =100-E40 -> 5 | G40: 2 | I40: 8
A41: < 200 | C41: =+D17-SUM(C33:C40) -> 66.1 | D41: =ROUND(C41*F$32/D$17,1) -> 5 | E41: =+E40+D41 -> 100
A43: Clasificación SUCS | D43: GW-GM | F43: L.L : | G43: NP | I43: Máx.Dens.Seca : | L43: =+Proctor!D39 -> 2.265 | M43: % C.B.R.al 95 % - 0.1 " | O43: =+'Grafico CBR'!$N$38 -> 63.58
A44: Clasificación AASHTO | D44: =+Aashto!J26 -> A-1-a (0) | F44: I.P : | G44: NP | I44: Humedad Optima | L44: =+Proctor!D40 -> 7.2 | M44: % C.B.R.al 100 % - 0.1 " | O44: =+'Grafico CBR'!$N$37 -> 101.83
R48: Diametro efectivos
R49: D10
...

Sheet Proctor
F5: PROVIAS NACIONAL
A6: ENSAYO DE PROCTOR MODIFICADO ( MTC E 115 )
A9: =+Datos!#REF! -> #REF! | C9: =+'Gran-LLyLP'!H8 -> F.T.V
A10: =+Datos!#REF! -> #REF! | C10: =+'Gran-LLyLP'!H9 -> F.K.S
A11: =+Datos!#REF! -> #REF! | C11: =+'Gran-LLyLP'!C11:D11 -> 38972
A13: Datos de muestra
A14: Prog. | B14: : | C14: =+'Gran-LLyLP'!C8 -> Km. 54+710-54+910
A15: =+Datos!A10 -> Ubicación : | B15: : | C15: =+'Gran-LLyLP'!C9 -> SB - 25 | D15: =+'Gran-LLyLP'!D9 -> M - 1
A16: =+Datos!A11 -> Cantera : | B16: : | C16: =+'Gran-LLyLP'!C10 -> Sub Base Granular
A17: =+Datos!A12 -> Material : | B17: : | C17: =+'Gran-LLyLP'!C12:D12 -> IZQ - DER
A19: Compactación
A20: Prueba Nº | C20: 1 | D20: 2 | E20: 3 | F20: 4
A21: Número de capas | C21: 5 | D21: 5 | E21: 5 | F21: 5
A22: Número de golpes | C22: 56 | D22: 56 | E22: 56 | F22: 56
A23: Peso suelo + molde (gr.) | C23: 11210 | D23: 11368 | E23: 11506 | F23: 11545
A24: Peso molde (gr.) | C24: 6335 | D24: =+C24 -> 6335 | E24: =+C24 -> 6335 | F24: =+C24 -> 6335
A25: Peso suelo compactado (gr.) | C25: =+C23-C24 -> 4875 | D25: =+D23-D24 -> 5033 | E25: =+E23-E24 -> 5171 | F25: =+F23-F24 -> 5210
A26: Volúmen del molde (cm3) | C26: 2119 | D26: =+C26 -> 2119 | E26: =+D26 -> 2119 | F26: =+E26 -> 2119
A27: Densidad húmeda (gr/cm3) | C27: =+C25/C26 -> 2.3006135 | D27: =+D25/D26 -> 2.375177 | E27: =+E25/E26 -> 2.440302 | F27: =+F25/F26 -> 2.4587069
A29: Humedad (%)
A30: Tara Nº
A31: Tara + suelo húmedo (gr.) | C31: 524.2 | D31: 446.7 | E31: 519.6 | F31: 559.4
A32: Tara + suelo seco (gr.) | C32: 508 | D32: 424.1 | E32: 482 | F32: 506.4
A33: Peso de agua (gr.) | C33: =+C31-C32 -> 16.2 | D33: =+D31-D32 -> 22.6 | E33: =+E31-E32 -> 37.6 | F33: =+F31-F32 -> 53
A34: Peso de tara (gr.)
A35: Peso de suelo seco (gr.) | C35: =+C32-C34 -> 508 | D35: =+D32-D34 -> 424.1 | E35: =+E32-E34 -> 482 | F35: =+F32-F34 -> 506.4
A36: Humedad (%) | C36: =+C33/C35*100 -> 3.1889764 | D36: =+D33/D35*100 -> 5.3289319 | E36: =+E33/E35*100 -> 7.8008299 | F36: =+F33/F35*100 -> 10.466035
A37: Densidad Seca (gr/cm3) | C37: =+C27/(1+C36/100) -> 2.2295148 | D37: =+D27/(1+D36/100) -> 2.2550091 | E37: =+E27/(1+E36/100) -> 2.2637136 | F37: =+F27/(1+F36/100) -> 2.2257583
A39: Máxima Densidad Seca (gr/cm3) : | D39: =+I48 -> 2.265
A40: Optimo Contenido de Humedad (%) : | D40: =+J47 -> 7.2
I47: 0 | J47: 7.2
I48: 2.265 | J48: =+J47 -> 7.2
I49: =+I48 -> 2.265 | J49: 0
B60: CONTRATISTA | E60: SUPERVISION
A64: ------------------------- ----------------------------- | E64: ------------------------- -----------------------------
A65: TEC. RESP. | B65: ING. RESP. | D65: TEC. RESP. | F65: ING. RESP.

Sheet Datos
A7: Relacion de Soporte de California (C.B.R.) (MTC E 132 / NTP 339.145)
A8: Solicitado : | C8: : | D8: Aldesa Construcciones S.A. | L8: Certificado N° | N8: 53-14 / CU-11 | R8: PESO Y VOLUMEN DE MOLDES
A9: Proyecto : | C9: : | D9: Tunel de Puruchuco | L9: Ref. Proyecto | N9: ACSA/CTP-14
A10: Ubicación : | C10: : | D10: Av. Javier Prado S/N Alt. Huaca de Puruchuco | L10: Fecha Ensayo | N10: 41951 | R10: N° | S10: PESO | T10: VOLUMEN
A11: Cantera : | C11: : | D11: Cantera Dorita | L11: Hecho por | N11: Tec. Nelson | R11: 1 | S11: 6085 | T11: 2137.0537
A12: Material : | C12: : | D12: Base Granular | R12: =+R11+1 -> 2 | S12: 5411 | T12: 2134.9035
A13: Máxima Densidad Seca (gr/cm3) | G13: =+'[7]Proctor 1'!$E$35 -> 2.281 | R13: =+R12+1 -> 3 | S13: 5994 | T13: 2151.0901
A14: Optimo Contenido de Humedad (%) | G14: =+'[7]Proctor 1'!$E$36 -> 6.2 | R14: =+R13+1 -> 4 | S14: 4961 | T14: 2144.0662
A15: Compactación | I15: Humedad (%) | R15: =+R14+1 -> 5 | S15: 4863 | T15: 2151.0901
A16: Molde Nº | E16: 15 | F16: 10 | G16: 32 | I16: Tara Nº | R16: =+R15+1 -> 6 | S16: 5197 | T16: 2144.0662
A17: Número de capas | E17: 5 | F17: 5 | G17: 5 | I17: Tara+suelo húmedo (gr.) | L17: 516.3 | M17: 516.3 | N17: 516.3 | R17: =+R16+1 -> 7 | S17: 4937 | T17: 2144.0662
A18: Número de golpes | E18: 56 | F18: 25 | G18: 12 | I18: Tara+suelo seco (gr.) | L18: 485.7 | M18: 485.7 | N18: =+M18 -> 485.7 | R18: =+R17+1 -> 8 | S18: 5250 | T18: 2144.0662
A19: Peso suelo + molde (gr.) | E19: 12341 | F19: 12265 | G19: 12671 | I19: Peso de agua (gr.) | L19: =+L17-L18 -> 30.6 | M19: =+M17-M18 -> 30.6 | N19: =+N17-N18 -> 30.6 | R19: =+R18+1 -> 9 | S19: 4972 | T19: 2146.1864
A20: Peso molde (gr.) | E20: 7078 | F20: 7202 | G20: 7816 | I20: Peso de tara (gr.) | R20: =+R19+1 -> 10 | S20: 5257 | T20: 2137.0537
A21: Peso suelo compactado (gr.) | E21: =+E19-E20 -> 5263 | F21: =+F19-F20 -> 5063 | G21: =+G19-G20 -> 4855 | I21: Peso de suelo seco (gr.) | L21: =+L18-L20 -> 485.7 | M21: =+M18-M20 -> 485.7 | N21: =+N18-N20 -> 485.7 | O21: =+G13*0.95 -> 2.16695 | R21: =+R20+1 -> 11 | S21: 5100 | T21: 2144.0662
A22: Volumen del molde (cm3) | E22: 2161 | F22: 2163 | G22: 2175 | I22: Humedad (%) | L22: =+L19/L21*100 -> 6.3001853 | M22: =+M19/M21*100 -> 6.3001853 | N22: =+N19/N21*100 -> 6.3001853 | R22: =+R21+1 -> 12 | S22: 4842 | T22: 2165.1725
A23: Densidad humeda (gr/cm3) | E23: =+E21/E22 -> 2.4354466 | F23: =+F21/F22 -> 2.3407305 | G23: =+G21/G22 -> 2.2321839 | I23: Densidad Seca (gr/cm3) | L23: =+E23/(1+L22/100) -> 2.2911028 | M23: =+F23/(1+M22/100) -> 2.2020004 | N23: =+G23/(1+N22/100) -> 2.0998871 | R23: 100 | S23: 6286 | T23: 2063
M24: =+L23-M23 -> 0.089102465 | N24: =+M23-N23 -> 0.10211324 | R24: 101 | S24: 7492 | T24: 2180
A25: Aplicación de Carga | R25: 102 | S25: 6279 | T25: 2103
A26: Penetración | C26: Presión | D26: =+$A$56&" "&C56 -> Molde 15 | F26: =+$A$56&" "&D56 -> Molde 10 | H26: =+$A$56&" "&E56 -> Molde 32
A27: (Pulg.) | B27: (mm.) | C27: Patrón | D27: Dial | E27: Presión | F27: Dial | G27: Presión | H27: Dial | I27: Presión | K27: Expansión: | R27: 1 | S27: =+IF($E$16=R11,S11,0) -> 0 | T27: =+IF($E$16=R11,T11,0) -> 0 | U27: =+IF($F$16=R11,S11,0) -> 0 | V27: =+IF($F$16=R11,T11,0) -> 0 | W27: =+IF($G$16=R11,S11,0) -> 0 | X27: =+IF($G$16=R11,T11,0) -> 0
C28: (Kg/cm2) | E28: (Kg/cm2) | G28: (Kg/cm2) | I28: (Kg/cm2) | R28: =+R27+1 -> 2 | S28: =+IF($E$16=R12,S12,0) -> 0 | T28: =+IF($E$16=R12,T12,0) -> 0 | U28: =+IF($F$16=R12,S12,0) -> 0 | V28: =+IF($F$16=R12,T12,0) -> 0 | W28: =+IF($G$16=R12,S12,0) -> 0 | X28: =+IF($G$16=R12,T12,0) -> 0
A29: 0.25 | B29: =+A29*2.54 -> 0.635 | D29: 51 | E29: =(E$63+E$64*D29+E$65*D29*D29)/F$68 -> 12.066464 | F29: 36 | G29: =(E$63+E$64*F29+E$65*F29*F29)/F$68 -> 8.3538746 | H29: 20 | I29: =(E$63+E$64*H29+E$65*H29*H29)/F$68 -> 4.3918873 | J29: =+H32/F32 -> 0.69346734 | K29: Fecha | L29: Expansión (Pulg.) | R29: =+R28+1 -> 3 | S29: =+IF($E$16=R13,S13,0) -> 0 | T29: =+IF($E$16=R13,T13,0) -> 0 | U29: =+IF($F$16=R13,S13,0) -> 0 | V29: =+IF($F$16=R13,T13,0) -> 0 | W29: =+IF($G$16=R13,S13,0) -> 0 | X29: =+IF($G$16=R13,T13,0) -> 0
A30: 0.5 | B30: =+A30*2.54 -> 1.27 | D30: 140 | E30: =(E$63+E$64*D30+E$65*D30*D30)/F$68 -> 34.059184 | F30: 96 | G30: =(E$63+E$64*F30+E$65*F30*F30)/F$68 -> 23.193932 | H30: 66 | I30: =(E$63+E$64*H30+E$65*H30*H30)/F$68 -> 15.777336 | L30: =+E16 -> 15 | M30: =+F16 -> 10 | N30: =+G16 -> 32 | R30: =+R29+1 -> 4 | S30: =+IF($E$16=R14,S14,0) -> 0 | T30: =+IF($E$16=R14,T14,0) -> 0 | U30: =+IF($F$16=R14,S14,0) -> 0 | V30: =+IF($F$16=R14,T14,0) -> 0 | W30: =+IF($G$16=R14,S14,0) -> 0 | X30: =+IF($G$16=R14,T14,0) -> 0 | Z30: INGRESE AQUÍ
A31: 0.75 | B31: =+A31*2.54 -> 1.905 | D31: 226 | E31: =(E$63+E$64*D31+E$65*D31*D31)/F$68 -> 55.253164 | F31: 152 | G31: =(E$63+E$64*F31+E$65*F31*F31)/F$68 -> 37.019871 | H31: 109 | I31: =(E$63+E$64*H31+E$65*H31*H31)/F$68 -> 26.405657 | K31: =+N10 -> 41951 | L31: 0 | M31: 0 | N31: 0 | R31: =+R30+1 -> 5 | S31: =+IF($E$16=R15,S15,0) -> 0 | T31: =+IF($E$16=R15,T15,0) -> 0 | U31: =+IF($F$16=R15,S15,0) -> 0 | V31: =+IF($F$16=R15,T15,0) -> 0 | W31: =+IF($G$16=R15,S15,0) -> 0 | X31: =+IF($G$16=R15,T15,0) -> 0
A32: 1 | B32: =+A32*2.54 -> 2.54 | C32: 70 | D32: 296 | E32: =(E$63+E$64*D32+E$65*D32*D32)/F$68 -> 72.462421 | F32: 199 | G32: =(E$63+E$64*F32+E$65*F32*F32)/F$68 -> 48.605317 | H32: 138 | I32: =(E$63+E$64*H32+E$65*H32*H32)/F$68 -> 33.565629 | K32: =+K31+1 -> 41952 | L32: =+Z33/1000 -> 0 | M32: =+AA33/1000 -> 0.001 | N32: =+AB33/1000 -> 0.003 | R32: =+R31+1 -> 6 | S32: =+IF($E$16=R16,S16,0) -> 0 | T32: =+IF($E$16=R16,T16,0) -> 0 | U32: =+IF($F$16=R16,S16,0) -> 0 | V32: =+IF($F$16=R16,T16,0) -> 0 | W32: =+IF($G$16=R16,S16,0) -> 0 | X32: =+IF($G$16=R16,T16,0) -> 0 | Z32: 0 | AA32: 0 | AB32: 0
A33: 1.5 | B33: =+A33*2.54 -> 3.81 | D33: 412 | E33: =(E$63+E$64*D33+E$65*D33*D33)/F$68 -> 100.89831 | F33: 276 | G33: =(E$63+E$64*F33+E$65*F33*F33)/F$68 -> 67.549305 | H33: 186 | I33: =(E$63+E$64*H33+E$65*H33*H33)/F$68 -> 45.402518 | K33: =+K32+1 -> 41953 | L33: =+Z34/1000 -> 0 | M33: =+AA34/1000 -> 0.001 | N33: =+AB34/1000 -> 0.003 | R33: =+R32+1 -> 7 | S33: =+IF($E$16=R17,S17,0) -> 0 | T33: =+IF($E$16=R17,T17,0) -> 0 | U33: =+IF($F$16=R17,S17,0) -> 0 | V33: =+IF($F$16=R17,T17,0) -> 0 | W33: =+IF($G$16=R17,S17,0) -> 0 | X33: =+IF($G$16=R17,T17,0) -> 0 | Z33: 0 | AA33: 1 | AB33: 3
A34: 2 | B34: =+A34*2.54 -> 5.08 | C34: 104 | D34: 529 | E34: =(E$63+E$64*D34+E$65*D34*D34)/F$68 -> 129.47534 | F34: 355 | G34: =(E$63+E$64*F34+E$65*F34*F34)/F$68 -> 86.938331 | H34: 249 | I34: =(E$63+E$64*H34+E$65*H34*H34)/F$68 -> 60.911758 | K34: =+K33+1 -> 41954 | L34: =+Z35/1000 -> 0 | M34: =+AA35/1000 -> 0.001 | N34: =+AB35/1000 -> 0.003 | R34: =+R33+1 -> 8 | S34: =+IF($E$16=R18,S18,0) -> 0 | T34: =+IF($E$16=R18,T18,0) -> 0 | U34: =+IF($F$16=R18,S18,0) -> 0 | V34: =+IF($F$16=R18,T18,0) -> 0 | W34: =+IF($G$16=R18,S18,0) -> 0 | X34: =+IF($G$16=R18,T18,0) -> 0 | Z34: 0 | AA34: 1 | AB34: 3
A35: 2.5 | B35: =+A35*2.54 -> 6.35 | D35: 662 | E35: =(E$63+E$64*D35+E$65*D35*D35)/F$68 -> 161.8335 | F35: 448 | G35: =(E$63+E$64*F35+E$65*F35*F35)/F$68 -> 109.70237 | H35: 296 | I35: =(E$63+E$64*H35+E$65*H35*H35)/F$68 -> 72.462421 | K35: =+K34+1 -> 41955 | L35: =+Z36/1000 -> 0 | M35: =+AA36/1000 -> 0.002 | N35: =+AB36/1000 -> 0.003 | R35: =+R34+1 -> 9 | S35: =+IF($E$16=R19,S19,0) -> 0 | T35: =+IF($E$16=R19,T19,0) -> 0 | U35: =+IF($F$16=R19,S19,0) -> 0 | V35: =+IF($F$16=R19,T19,0) -> 0 | W35: =+IF($G$16=R19,S19,0) -> 0 | X35: =+IF($G$16=R19,T19,0) -> 0 | Z35: 0 | AA35: 1 | AB35: 3
A36: 3 | B36: =+A36*2.54 -> 7.62 | D36: 761 | E36: =(E$63+E$64*D36+E$65*D36*D36)/F$68 -> 185.83203 | F36: 516 | G36: =(E$63+E$64*F36+E$65*F36*F36)/F$68 -> 126.30527 | H36: 352 | I36: =(E$63+E$64*H36+E$65*H36*H36)/F$68 -> 86.202909 | K36: % EXP. | L36: =+(L35-L31)/4.7*100 -> 0 | M36: =+(M35-M31)/4.7*100 -> 0.042553191 | N36: =+(N35-N31)/4.7*100 -> 0.063829787 | R36: =+R35+1 -> 10 | S36: =+IF($E$16=R20,S20,0) -> 0 | T36: =+IF($E$16=R20,T20,0) -> 0 | U36: =+IF($F$16=R20,S20,0) -> 5257 | V36: =+IF($F$16=R20,T20,0) -> 2137.0537 | W36: =+IF($G$16=R20,S20,0) -> 0 | X36: =+IF($G$16=R20,T20,0) -> 0 | Z36: 0 | AA36: 2 | AB36: 3
A37: 3.5 | B37: =+A37*2.54 -> 8.89 | R37: =+R36+1 -> 11 | S37: =+IF($E$16=R21,S21,0) -> 0 | T37: =+IF($E$16=R21,T21,0) -> 0 | U37: =+IF($F$16=R21,S21,0) -> 0 | V37: =+IF($F$16=R21,T21,0) -> 0 | W37: =+IF($G$16=R21,S21,0) -> 0 | X37: =+IF($G$16=R21,T21,0) -> 0
A38: 4 | B38: =+A38*2.54 -> 10.16 | R38: =+R37+1 -> 12 | S38: =+IF($E$16=R22,S22,0) -> 0 | T38: =+IF($E$16=R22,T22,0) -> 0 | U38: =+IF($F$16=R22,S22,0) -> 0 | V38: =+IF($F$16=R22,T22,0) -> 0 | W38: =+IF($G$16=R22,S22,0) -> 0 | X38: =+IF($G$16=R22,T22,0) -> 0
A39: 4.5 | B39: =+A39*2.54 -> 11.43 | R39: 100 | S39: =+IF($E$16=R23,S23,0) -> 0 | T39: =+IF($E$16=R23,T23,0) -> 0 | U39: =+IF($F$16=R23,S23,0) -> 0 | V39: =+IF($F$16=R23,T23,0) -> 0 | W39: =+IF($G$16=R23,S23,0) -> 0 | X39: =+IF($G$16=R23,T23,0) -> 0
A40: 5 | B40: =+A40*2.54 -> 12.7 | R40: 101 | S40: =+IF($E$16=R24,S24,0) -> 0 | T40: =+IF($E$16=R24,T24,0) -> 0 | U40: =+IF($F$16=R24,S24,0) -> 0 | V40: =+IF($F$16=R24,T24,0) -> 0 | W40: =+IF($G$16=R24,S24,0) -> 0 | X40: =+IF($G$16=R24,T24,0) -> 0
R41: 102 | S41: =+IF($E$16=R25,S25,0) -> 0 | T41: =+IF($E$16=R25,T25,0) -> 0 | U41: =+IF($F$16=R25,S25,0) -> 0 | V41: =+IF($F$16=R25,T25,0) -> 0 | W41: =+IF($G$16=R25,S25,0) -> 0 | X41: =+IF($G$16=R25,T25,0) -> 0
S42: =+SUM(S27:S41) -> 0 | T42: =+SUM(T27:T41) -> 0 | U42: =+SUM(U27:U41) -> 5257 | V42: =+SUM(V27:V41) -> 2137.0537 | W42: =+SUM(W27:W41) -> 0 | X42: =+SUM(X27:X41) -> 0
A52: WEB: www.geofal.com.pe E-MAIL: geofal.sac@gmail.com / laboratorio@geofal.com.pe | R52: 1000 | S52: Lbs/pul2
R53: =+R52/2.54/2.54*0.454 -> 70.370141 | S53: Kg/cm2
A56: Molde | C56: =+E16 -> 15 | D56: =+F16 -> 10 | E56: =+G16 -> 32
A58: Prensa N# 3
...

Sheet Grafico CBR
A7: Relacion de Soporte de California (C.B.R.) (MTC E 132 / NTP 339.145)
A8: Solicitado | C8: : | D8: =+Datos!D8 -> Aldesa Construcciones S.A. | L8: Certificado N° | O8: =+Datos!N8 -> 53-14 / CU-11
A9: Proyecto | C9: : | D9: =+Datos!D9 -> Tunel de Puruchuco | L9: Ref. Proyecto | O9: =+Datos!N9 -> ACSA/CTP-14
A10: Ubicación | C10: : | D10: =+Datos!D10 -> Av. Javier Prado S/N Alt. Huaca de Puruchuco | L10: Fecha de ensayo | O10: =+Datos!N10 -> 41951
A11: Calicata : | C11: : | D11: =+Datos!D11 -> Cantera Dorita | L11: Hecho por | O11: =+Datos!N11 -> Tec. Nelson
A12: Profundidad: | C12: : | D12: =+Datos!D12 -> Base Granular
A13: Máxima Densidad Seca (gr/cm3) : | G13: =+Datos!G13 -> 2.281
A14: Optimo Contenido de Humedad (%) : | G14: =+Datos!G14 -> 6.2
A30: C.B.R. (0.1")-56 Golpes | D30: =+Apoyo!E23/0.7 -> 105.71429 | G30: C.B.R. (0.1")-25 Golpes | J30: =+Apoyo!F23/0.7 -> 71.428571 | L30: C.B.R. (0.1")-12 Golpes | O30: =+Apoyo!G23/0.7 -> 48.571429 | R30: RELLENAR CORRECCION
A31: C.B.R. (0.2")-56 Golpes | D31: =+Apoyo!E29/1.05 -> 123.30985 | G31: C.B.R. (0.2")-25 Golpes | J31: =+Apoyo!F29/1.05 -> 82.798411 | L31: C.B.R. (0.2")-12 Golpes | O31: =+Apoyo!G29/1.05 -> 58.011198 | R31: 56 | S31: 25 | T31: 12
A32: Densidad Seca (gr/cc) : | D32: =+Datos!L23 -> 2.2911028 | G32: Densidad Seca (gr/cc) : | J32: =+Datos!M23 -> 2.2020004 | L32: Densidad Seca (gr/cc) : | O32: =+Datos!N23 -> 2.0998871 | R32: 74 | S32: 50 | T32: 34
A33: DETERMINACION DE C.B.R.
M34: M.D.S. : | N34: =+Datos!G13 -> 2.281
M35: 95% DE M.D.S. : | N35: =+N34*0.95 -> 2.16695
M37: C.B.R. (100% M.D.S.) 0.1" : | N37: =ROUND(IF(D32<N34,D30,(N34-D32)*(J30-D30)/(J32-D32)+D30),2) -> 101.83 | O37: %
M38: C.B.R. (95% M.D.S.) 01" : | N38: =ROUND(IF(O32>N35,O30,(N35-J32)*(O30-J30)/(O32-J32)+J30),2) -> 63.58 | O38: %
A56: WEB: www.geofal.com.pe E-MAIL: geofal.sac@gmail.com / laboratorio@geofal.com.pe

Sheet Apoyo
A1: Penetración | B1: Molde I | C1: Molde II | D1: Molde III
A2: (mm.) | B2: Presión | C2: Presión | D2: Presión
B3: (Kg/cm2) | C3: (Kg/cm2) | D3: (Kg/cm2) | E3: Molde I | F3: Molde II | G3: Molde III
A4: 0 | B4: 0 | C4: 0 | D4: 0 | E4: =+B4 -> 0 | F4: =+C4 -> 0 | G4: =+D4 -> 0
A5: 0.64 | B5: =+Datos!E29 -> 12.066464 | C5: =+Datos!G29 -> 8.3538746 | D5: =+Datos!I29 -> 4.3918873 | E5: =+B5 -> 12.066464 | F5: =+C5 -> 8.3538746 | G5: =+D5 -> 4.3918873
A6: 1.27 | B6: =+Datos!E30 -> 34.059184 | C6: =+Datos!G30 -> 23.193932 | D6: =+Datos!I30 -> 15.777336 | E6: =+B6 -> 34.059184 | F6: =+C6 -> 23.193932 | G6: =+D6 -> 15.777336
A7: 1.91 | B7: =+Datos!E31 -> 55.253164 | C7: =+Datos!G31 -> 37.019871 | D7: =+Datos!I31 -> 26.405657 | E7: =+B7 -> 55.253164 | F7: =+C7 -> 37.019871 | G7: =+D7 -> 26.405657
A8: 2.54 | B8: =+Datos!E32 -> 72.462421 | C8: =+Datos!G32 -> 48.605317 | D8: =+Datos!I32 -> 33.565629 | E8: =+B8 -> 72.462421 | F8: =+C8 -> 48.605317 | G8: =+D8 -> 33.565629
A9: 3.81 | B9: =+Datos!E33 -> 100.89831 | C9: =+Datos!G33 -> 67.549305 | D9: =+Datos!I33 -> 45.402518 | E9: =+B9 -> 100.89831 | F9: =+C9 -> 67.549305 | G9: =+D9 -> 45.402518
A10: 5.08 | B10: =+Datos!E34 -> 129.47534 | C10: =+Datos!G34 -> 86.938331 | D10: =+Datos!I34 -> 60.911758 | E10: =+B10 -> 129.47534 | F10: =+C10 -> 86.938331 | G10: =+D10 -> 60.911758
A11: 6.35 | B11: =+Datos!E35 -> 161.8335 | C11: =+Datos!G35 -> 109.70237 | D11: =+Datos!I35 -> 72.462421 | E11: =+B11 -> 161.8335 | F11: =+C11 -> 109.70237 | G11: =+D11 -> 72.462421
A12: 7.62 | B12: =+Datos!E36 -> 185.83203 | C12: =+Datos!G36 -> 126.30527 | D12: =+Datos!I36 -> 86.202909 | E12: =+B12 -> 185.83203 | F12: =+C12 -> 126.30527 | G12: =+D12 -> 86.202909
A13: 8.89
A14: 10.16
A15: 11.43
A16: 12.7
D17: Correc | E17: 24.753 | F17: 11.391 | G17: 16.775
E18: 3.1761 | F18: 1.365 | G18: 1.9443
E19: =+E18/E17+2.54 -> 2.6683117 | F19: =+F18/F17+2.54 -> 2.6598314 | G19: =+G18/G17+2.54 -> 2.6559046
E20: =+E19 -> 2.6683117 | F20: =+F19 -> 2.6598314 | G20: =+G19 -> 2.6559046
E21: 0 | F21: 0 | G21: 0
E22: 0 | F22: 0 | G22: 0
C23: Cambiar | E23: =+'Grafico CBR'!R32 -> 74 | F23: =+'Grafico CBR'!S32 -> 50 | G23: =+'Grafico CBR'!T32 -> 34
E24: =+E23 -> 74 | F24: =+F23 -> 50 | G24: =+G23 -> 34
E29: =+E10 -> 129.47534 | F29: =+F10 -> 86.938331 | G29: =+G10 -> 60.911758
A34: C.B.R. | D34: C.B.R.(100%) | G34: C.B.R.(95%)
A35: =+Datos!G13 -> 2.281 | B35: =+E23/0.7 -> 105.71429 | D35: =+E23/0.7 -> 105.71429 | E35: 0 | G35: =+'Grafico CBR'!N38 -> 63.58 | H35: 0
A36: =+Datos!M23 -> 2.2020004 | B36: =+F23/0.7 -> 71.428571 | D36: =+D35 -> 105.71429 | E36: =+A35 -> 2.281 | G36: =+G35 -> 63.58 | H36: =0.95*E36 -> 2.16695
A37: =+Datos!N23 -> 2.0998871 | B37: =+G23/0.7 -> 48.571429 | D37: 0 | E37: =+E36 -> 2.281 | G37: 0 | H37: =+H36 -> 2.16695
A39: C.B.R. | D39: C.B.R.(100%) | G39: C.B.R.(95%)
A40: =+A35 -> 2.281 | B40: =+E29/1.04 -> 124.49552 | D40: =+E29/1.04 -> 124.49552 | E40: 0 | G40: 112.4 | H40: 0
A41: =+A36 -> 2.2020004 | B41: =+F29/1.04 -> 83.594549 | D41: =+D40 -> 124.49552 | E41: =+A40 -> 2.281 | G41: =+G40 -> 112.4 | H41: =0.95*E41 -> 2.16695
A42: =+A37 -> 2.0998871 | B42: =+G29/1.04 -> 58.568998 | D42: 0 | E42: =+E41 -> 2.281 | G42: 0 | H42: =+H41 -> 2.16695

Sheet E_A
A7: Equivalente de Arena (NORMA AASHTO T-176 / ASTM D-2419/ MTC E 114)
B9: Solicitado | C9: : | D9: Maquinarias e Ingenieros S.A.C. | H9: Certificado N° | K9: 51-13 / AG-01
B10: Proyecto | C10: : | D10: Obras Exteriores de Sodimac San Juan Lurigancho | H10: Ref. Proyecto | K10: MEI / OES - 13
B11: Ubicación | C11: : | D11: Entre Av. Las Lomas y Jr. Cajamarquilla SJL | H11: Fecha de ensayo | K11: 41528
B12: Estructura | C12: : | D12: Base | H12: Hecho por | K12: =+'[5]CONO 1'!$J$15 -> R. Portillo
B13: Material | C13: : | D13: Afirmado
F15: IDENTIFICACION | K15: Promedio
F16: 1 | G16: 2 | H16: 3 | I16: 4
B17: Tamaño máximo (pasa malla Nº 4) | E17: mm | F17: =+[4]G_LL!B32 -> 4.76 | G17: =+F17 -> 4.76 | H17: =+G17 -> 4.76
B18: Hora de entrada a saturación | E18: 0.0069444444 | F18: 0.45138889 | G18: =+F18+0.002 -> 0.45338889 | H18: =+F18+0.003 -> 0.45438889
B19: Hora de salida de saturación (mas 10") | F19: =+F18+$E$18 -> 0.45833333 | G19: =+G18+$E$18 -> 0.46033333 | H19: =+H18+$E$18 -> 0.46133333
B20: Hora de entrada a decantación | E20: 0.0013888889 | F20: =+F19+$E$20 -> 0.45972222 | G20: =+G19+$E$20 -> 0.46172222 | H20: =+H19+$E$20 -> 0.46272222
B21: Hora de salida de decantación (mas 20") | F21: =+F20+$B$26 -> 0.47361111 | G21: =+G20+$B$26 -> 0.47561111 | H21: =+H20+$B$26 -> 0.47661111
B22: Altura máxima de material fino | E22: mm | F22: 8.9 | G22: 9.3 | H22: 9.41
B23: Altura máxima de la arena | E23: mm | F23: 3.4 | G23: 3.4 | H23: 3.52
B24: Equivalente de Arena | E24: % | F24: =+F23/F22*100 -> 38.202247 | G24: =+G23/G22*100 -> 36.55914 | H24: =+H23/H22*100 -> 37.407014 | K24: =AVERAGE(F24:H24) -> 37.389467
B26: 0.013888889
B27: Observaciones:
A47: WEB: www.geofal.com.pe E-MAIL: geofal.sac@gmail.com / laboratorio@geofal.com.pe

Sheet ABRASION
A7: Abrasion ( Maquina de los Angeles ) (NORMA NTP 400.019 / AASHTO T-96)
A9: Solicitado | B9: : | C9: Maquinarias e Ingenieros S.A.C. | F9: Certificado N° | G9: : | H9: 51-13 / AG-12
A10: Proyecto | B10: : | C10: Obras Exteriores de Sodimac San Juan Lurigancho | F10: Ref. Proyecto | G10: : | H10: MEI / OES - 13
A11: Ubicación | B11: : | C11: Entre Av. Las Lomas y Jr. Cajamarquilla SJL | F11: Fecha Ensayo | G11: : | H11: 41528
A12: Estructura | B12: : | C12: Base | F12: Hecho por | G12: : | H12: =+'[5]CONO 1'!$J$15 -> R. Portillo
A13: Material | B13: : | C13: Afirmado
A16: TAMIZ | D16: GRADACIONES
D17: A | E17: B | F17: C | H17: D
A18: 1 1/2"
A19: 1" | D19: 1252.1
A20: 3/4" | D20: 1253.6
A21: 1/2" | D21: 1251.3 | E21: 2500.1
A22: 3/8" | D22: 1250.6 | E22: 2500.9
A23: 1/4"
A24: No 4
A25: PESO TOTAL | D25: =SUM(D19+D20+D21+D22) -> 5007.6 | E25: =SUM(E21:E24) -> 5001
A26: Retenido en la malla Nº 12 | D26: 3629.6 | E26: 4238.4
A27: Que pasa en la malla Nº 12 | D27: =+D25-D26 -> 1378 | E27: 699.3
A28: No de Esferas | D28: 12 | E28: 11
A29: Peso de las Esferas | E29: 4620
A30: % Desgate | D30: =(D27/D25*100)/100 -> 0.27518172 | E30: =E27/E25*100 -> 13.983203
A31: OBSERVACIONES :
A45: WEB: www.geofal.com.pe E-MAIL: geofal.sac@gmail.com / laboratorio@geofal.com.pe

Sheet G_E
H4: PROVIAS NACIONAL
A7: GRAVEDAD ESPECIFICA Y ABSORCION DE LOS AGREGADOS
A8: (NORMA AASHTO T-84, T-85/ MTC E 113_206 )
A10: LABORATORIO MECANICA DE SUELOS, CONCRETOS Y PAVIMENTOS
A11: OBRA | C11: : | D11: CARRETERA INTEROCEANICA SUR | G11: CERTIFICADO | H11: :
A12: TRAMO | C12: : | D12: URCOS - INAMBARI | G12: TECNICO | H12: =+'Gran-LLyLP'!H8 -> F.T.V
A13: ESTRUCTURA | C13: : | D13: =+'Gran-LLyLP'!C10 -> Sub Base Granular | G13: REVISADO | H13: =+'Gran-LLyLP'!H9 -> F.K.S
G14: FECHA | H14: =+'Gran-LLyLP'!C11 -> 38972
A16: DATOS DE LA MUESTRA
A17: MUESTRA | C17: : | D17: =+D13 -> Sub Base Granular
A18: PROFUNDIDAD | C18: :
A19: PROGRESIVA | C19: : | D19: =+'Gran-LLyLP'!C8 -> Km. 54+710-54+910
A21: AGREGADO FINO
A23: A | B23: Peso Mat. Sat. Sup. Seco ( en Aire ) (gr) | E23: 4364.1 | F23: 200
A24: B | B24: Peso Frasco + agua | E24: 2545.9 | F24: 667.3
A25: C | B25: Peso Frasco + agua + A (gr) | E25: =+E24+E23 -> 6910 | F25: =+F24+F23 -> 867.3
A26: D | B26: Peso del Mat. + agua en el frasco (gr) | E26: 792.5 | F26: 791.9
A27: E | B27: Vol de masa + vol de vacío = C-D (gr) | E27: =+E25-E26 -> 6117.5 | F27: =+F25-F26 -> 75.4
A28: F | B28: Pe. De Mat. Seco en estufa (105ºC) (gr) | E28: 3936.8 | F28: 197.4
A29: G | B29: Vol de masa = E - ( A - F ) (gr) | E29: =+E27-(E23-E28) -> 5690.2 | F29: =+F27-(F23-F28) -> 72.8 | I29: PROMEDIO
B30: Pe bulk ( Base seca ) = F/E | E30: =+E28/E27 -> 0.64353085 | F30: =+F28/F27 -> 2.6180371 | I30: =+AVERAGE(E30:H30) -> 1.630784
B31: Pe bulk ( Base saturada ) = A/E | E31: =+E23/E27 -> 0.71337965 | F31: =+F23/F27 -> 2.6525199 | I31: =+AVERAGE(E31:H31) -> 1.6829498
B32: Pe aparente ( Base Seca ) = F/G | E32: =+E28/E29 -> 0.69185617 | F32: =+F28/F29 -> 2.7115385 | I32: =+AVERAGE(E32:H32) -> 1.7016973
B33: % de absorción = ((A - F)/F)*100 | E33: =((E23-E28)/E28)*100 -> 10.853993 | F33: =((F23-F28)/F28)*100 -> 1.3171226 | I33: =+AVERAGE(E33:H33) -> 6.0855578
A36: AGREGADO GRUESO
A38: A | B38: Peso Mat.Sat. Sup. Seca ( En Aire ) (gr) | E38: 2964.5
A39: B | B39: Peso Mat.Sat. Sup. Seca ( En Agua ) (gr) | E39: 1846
A40: C | B40: Vol. de masa + vol de vacíos = A-B (gr) | E40: =+E38-E39 -> 1118.5
A41: D | B41: Peso material seco en estufa ( 105 ºC )(gr) | E41: 2910.9
A42: E | B42: Vol. de masa = C- ( A - D ) (gr) | E42: =+E40-(E38-E41) -> 1064.9 | I42: PROMEDIO
B43: Pe bulk ( Base seca ) = D/C | E43: =+E41/E40 -> 2.6025034 | I43: =+AVERAGE(E43:G43) -> 2.6025034
B44: Pe bulk ( Base saturada) = A/C | E44: =+E38/E40 -> 2.6504247 | I44: =+AVERAGE(E44:G44) -> 2.6504247
B45: Pe Aparente ( Base Seca ) = D/E | E45: =+E41/E42 -> 2.7334961 | I45: =+AVERAGE(E45:G45) -> 2.7334961
B46: % de absorción = (( A - D ) / D * 100 ) | E46: =((E38-E41)/E41*100) -> 1.8413549 | I46: =+AVERAGE(E46:G46) -> 1.8413549
A48: Observaciones:
A59: ----------------------------- ----------------------------- | F59: ----------------------------- -----------------------------
A60: TEC. RESP. | D60: ING. RESP. | F60: TEC. RESP. | H60: ING. RESP.

Sheet Sucs
A1: esa | B1: SISTEMA UNIFICADO DE CLASIFICACION
B3: N 200= | C3: =ROUND('Gran-LLyLP'!F40,2) -> 5 | D3: Cu = | E3: =+'Gran-LLyLP'!T54 -> 38 | K3: L.L. | L3: =+IF(N_10="NP",0,N_10) -> 0
B4: N 4= | C4: =IF('Gran-LLyLP'!F32="",100,ROUND('Gran-LLyLP'!F32,2)) -> 37.3 | D4: Cc = | E4: =+'Gran-LLyLP'!T57 -> 1.6959267 | F4: CLASIFICACION SUCS | G4: =+Q9 -> GW-GM | K4: I.P. | L4: =+IF(C6="NP",0,C6) -> 0
B5: L.L.= | C5: =IF('Gran-LLyLP'!G43="NP","NP",ROUND('Gran-LLyLP'!G43,2)) -> NP | K5: CU | L5: =IF(OR(E3="----",E3=""),0,E3) -> 38
B6: I.P.= | C6: =IF('Gran-LLyLP'!G44="NP","NP",ROUND('Gran-LLyLP'!G44,2)) -> NP | K6: CC | L6: =IF(OR(E4="----",E4=""),0,E4) -> 1.6959267
B8: DIVISIONES MAYORES | E8: SIMBOLO DE GRUPO | F8: NOMBRES TIPICOS | G8: CRITERIOS DE CLASIFICACION PARA SUELOS GRANULARES | L8: CLASIF | M8: SIMBOLOS DOBLES | O8: SIMBOLOS TRIPLES | P8: CLASIFICACION | Q8: SIMBOLO
B9: Suelos de grano grueso (mas del 50 % del material es mayor en tamaño que el tamiz No 200 | C9: Gravas (mas de la mitad de la fracción gruesa es mayor que el tamiz No 4) | D9: Gravas Limpias (poco o ningun fino) | E9: GW | F9: Gravas bien gradadas, mezclas gravosas, poco o ningun fino | G9: Cu > 4 1 < Cc < 3 | L9: =IF(AND(N_200<50,(100-N_40)>=0.5*(100-N_200),N_200<5,CU>=4,CC>=1,CC<=3),"GW","") | M9: =IF(AND(N_200<50,(100-N_40)>=0.5*(100-N_200),N_200>=5,CU>=4,CC>=1,CC<=3,N_200<12,IP>=7,IP>=0.73*(Ll-20)),"GW-GC","") | N9: =IF(AND(N_200<50,(100-N_40)>=0.5*(100-N_200),N_200>=5,CU>=4,CC>=1,CC<=3,N_200<12,OR(IP<4,IP<0.73*(Ll-20))),"GW-GM","") -> GW-GM | O9: =IF(AND(N_200<50,(100-N_40)>=0.5*(100-N_200),N_200>=5,CU>=4,CC>=1,CC<=3,N_200<12,IP>=4,IP<7,IP<0.9*(Ll-8),IP>=0.73*(Ll-20)),"GW-GC-GM","") | P9: =+L9&M9&N9&O9 -> GW-GM | Q9: =+P9&P10&P11&P12&P13&P14&P15&P16&P17&P18&P19&P20&P21&P22&P23&P24 -> GW-GM
E10: GP | F10: Gravas pobremente gradadas,`mezclas grava-arena, pocos o ningun fino | G10: No cumple todos los requisitos de gradadcion para GW | L10: =IF(AND(N_200<50,(100-N_40)>=0.5*(100-N_200),N_200<5,OR(CU<4,CC<1,CC>3)),"GP","") | M10: =IF(AND(N_200<50,(100-N_40)>=0.5*(100-N_200),N_200>=5,OR(CU<4,CC<1,CC>3),N_200<12,IP>=7,IP>=0.73*(Ll-20)),"GP-GC","") | N10: =IF(AND(N_200<50,(100-N_40)>=0.5*(100-N_200),N_200>=5,OR(CU<4,CC<1,CC>3),N_200<12,OR(IP<4,IP<0.73*(Ll-20))),"GP-GM","") | O10: =IF(AND(N_200<50,(100-N_40)>=0.5*(100-N_200),N_200>=5,OR(CU<4,CC<1,CC>3),N_200<12,IP>=4,IP<7,IP<0.9*(Ll-8),IP>=0.73*(Ll-20)),"GP-GC-GM","") | P10: =+L10&M10&N10&O10
D11: Gravas con finos (cantidad apre- ciable de finos) | E11: GM | F11: Gravas limosas, mezcla grava- arena-limo | G11: Límites de Atteberg por debajo de la linea A o Ip < 4 | H11: A los materiales sobre la linea A con 4 < Ip < 7 se considera de frontera y se les asigna doble símbolo | L11: =IF(AND(N_200<50,(100-N_40)>=0.5*(100-N_200),N_200>=12,OR(IP<4,IP<0.73*(Ll-20))),"GM","") | M11: =IF(AND(N_200<50,(100-N_40)>=0.5*(100-N_200),N_200>=12,IP>=4,IP<7,IP>=0.73*(Ll-20)),"GC-GM","") | P11: =+L11&M11&N11&O11
E12: GC | F12: Gravas arcillosas, mezcla gravo-areno- arcillosas | G12: Límites de Atteberg por encima de la línea A ó Ip > 7 | L12: =IF(AND(N_200<50,(100-N_40)>=0.5*(100-N_200),N_200>=12,IP>=7,IP>=0.73*(Ll-20)),"GC","") | P12: =+L12&M12&N12&O12
C13: Arenas (mas de la mitad de la fracción gruesa es menor que el tamiz No 4) | D13: Arenas Limpias (poco o ningun fino) | E13: SW | F13: Arenas bien gradadas, arenas gravosas, pocos o ningun fino | G13: Cu > 6 1 < Cc < 3 | L13: =IF(AND(N_200<50,(100-N_40)<0.5*(100-N_200),N_200<5,CU>=6,CC>=1,CC<=3),"SW","") | M13: =IF(AND(N_200<50,(100-N_40)<0.5*(100-N_200),N_200>=5,CU>=6,CC>=1,CC<=3,N_200<12,IP>=7,IP>=0.73*(Ll-20)),"SW-SC","") | N13: =IF(AND(N_200<50,(100-N_40)<0.5*(100-N_200),N_200>=5,CU>=6,CC>=1,CC<=3,N_200<12,OR(IP<4,IP<0.73*(Ll-20))),"SW-SM","") | O13: =IF(AND(N_200<50,(100-N_40)<0.5*(100-N_200),N_200>=5,CU>=6,CC>=1,CC<=3,N_200<12,IP>=4,IP<7,IP<0.9*(Ll-8),IP>=0.73*(Ll-20)),"SW-SC-SM","") | P13: =+L13&M13&N13&O13
E14: SP | F14: Arenas pobremente gradadas, arenas gravosas, pocos o ningun fino | G14: No cumple todos los requisitos de gradadcion para SW | L14: =IF(AND(N_200<50,(100-N_40)<0.5*(100-N_200),N_200<5,OR(CU<6,CC<1,CC>3)),"SP","") | M14: =IF(AND(N_200<50,(100-N_40)<0.5*(100-N_200),N_200>=5,OR(CU<6,CC<1,CC>3),N_200<12,IP>=7,IP>=0.73*(Ll-20)),"SP-SC","") | N14: =IF(AND(N_200<50,(100-N_40)<0.5*(100-N_200),N_200>=5,OR(CU<6,CC<1,CC>3),N_200<12,OR(IP<4,IP<0.73*(Ll-20))),"SP-SM","") | O14: =IF(AND(N_200<50,(100-N_40)<0.5*(100-N_200),N_200>=5,OR(CU<6,CC<1,CC>3),N_200<12,IP>=4,IP<7,IP<0.9*(Ll-8),IP>=0.73*(Ll-20)),"SP-SC-SM","") | P14: =+L14&M14&N14&O14
D15: Arenas con finos (cantidad apre- ciable de finos) | E15: SM | F15: Arenas limosas mezcla de arena-limo | G15: Límites de Atteberg por debajo de la linea A ó Ip < 4 | H15: Si el material está en la zona sombreada con 4 < Ip < 7 se considera de frontera y se les asigna doble símbolo | L15: =IF(AND(N_200<50,(100-N_40)<0.5*(100-N_200),N_200>=12,OR(IP<4,IP<0.73*(Ll-20))),"SM","") | M15: =IF(AND(N_200<50,(100-N_40)<0.5*(100-N_200),N_200>=12,IP>=4,IP<7,IP>=0.73*(Ll-20)),"SC-SM","") | P15: =+L15&M15&N15&O15
E16: SC | F16: Arenas arcillosas, mezclas arena-arcilla | G16: Límites de Atteberg por encima de la linea A ó Ip > 7 | L16: =IF(AND(N_200<50,(100-N_40)<0.5*(100-N_200),N_200>=12,IP>=7,IP>=0.73*(Ll-20)),"SC","") | P16: =+L16&M16&N16&O16
B17: Suelos de grano fino (mas del 50 % del material pasa el tamiz No 200 | C17: limos y arcillas (Límite líquido wl<50 | E17: ML | F17: Limos inorgánicos y arena muy finas, polvo de roca, arenas finas limosas o arcillosas, o limos arcillosos con poca plasticidad | G17: 1, Determinar el porcentaje de arenas y gravas de la curva granulometrica. 2, Dependiendo del porcentaje de fino (fracción menor que el tamiz No 200 los suelos gruesos se clasifican como sigue: Menos del 5% - GW, GP, SW, SP Mas del 12 % - GM, GC, SM, SC De 5 a 12 % - casos frontera que requieren doble símbolo | L17: =IF(AND(N_200>=50,Ll<50,OR(IP<4,AND(IP<0.73*(Ll-20),IP<10))),"ML","") | P17: =+L17&M17&N17&O17
E18: CL | F18: Arcillas inorganicas de plasticidad baja a media, arcillas gravosas, arcillas arenosas, arcillas limosas, arcillas magras. | L18: =IF(AND(N_200>=50,Ll<50,IP>=7,IP>=0.73*(Ll-20)),"CL","") | P18: =+L18&M18&N18&O18
E19: OL | F19: Limos organicos, arcillas limosas orgánicas de baja plasticidad | L19: =IF(AND(N_200>=50,Ll<50,IP>=10,IP<0.73*(Ll-20)),"OL","") | P19: =+L19&M19&N19&O19
C20: limos y arcillas (Límite líquido wl>50 | E20: MH | F20: Limos inorganicos, suelos limosos o arenosos finos micaceos o diatomaceos, suelos elasticos. | L20: =IF(AND(N_200>=50,Ll>=50,IP>0,IP<=16),"MH","") | P20: =+L20&M20&N20&O20
E21: CH | F21: Arcillas organicas de alta plasticidad, arcillas grasas. | L21: =IF(AND(N_200>=50,Ll>=50,IP>=0.73*(Ll-20)),"CH","") | P21: =+L21&M21&N21&O21
E22: OH | F22: Arcillas organicas de plasticidad media a alta, limos orgánicos | L22: =IF(AND(N_200>=50,Ll>=50,IP>16,IP<0.73*(Ll-20)),"OH","") | P22: =+L22&M22&N22&O22
C23: Suelos Altamen- te orgá- nicos | E23: Pt | F23: Turba o otros suelos altamente organicos | L23: =IF(AND(N_200>=50,IP>=0.73*(Ll-20),IP>=4,IP<7,IP<0.9*(Ll-8)),"CL-ML","") | P23: =+L23&M23&N23&O23
P24: =+L24&M24&N24&O24

Sheet Aashto
B4: CLASIFICACION GENERAL | D4: MATERIALES GRANULARES (35% O MENOS DEL TOTAL PASA EL TAMIZ NO 200) | K4: MATERIALES LIMO-ARCILLOSOS (MAS DEL 35% DEL TOTAL PASA EL TAMIZ No 200)
B5: CLASIFICACION DE GRUPO | D5: A-1 | F5: A-3 | G5: A-2 | K5: A-4 | L5: A-5 | M5: A-6 | N5: A-7
D6: A-1-a | E6: A-1-b | G6: A-2-4 | H6: A-2-5 | I6: A-2-6 | J6: A-2-7 | N6: A-7-5 | O6: A-7-6
B8: Porcentaje de material
B9: que pasa el tamiz
B11: No 10 | C11: =+IF('Gran-LLyLP'!F33="",100,ROUND('Gran-LLyLP'!F33,1)) -> 27.8 | D11: 50 max
B12: No 40 | C12: =+IF('Gran-LLyLP'!F36="",100,ROUND('Gran-LLyLP'!F36,1)) -> 12.6 | D12: 30 max | E12: 50 max | F12: 51 min
B13: No 200 | C13: =ROUND('Gran-LLyLP'!F40,1) -> 5 | D13: 15 max | E13: 25 max | F13: 10 max | G13: 35 max | H13: 35 max | I13: 35 max | J13: 35 max | K13: 36 min | L13: 36 min | M13: 36 min | N13: 36 min | O13: 36 min
B16: Caracteristicas de la
B17: fraccion que pasa el
B18: tamiz No 40
B20: Limite líquido | C20: =IF('Gran-LLyLP'!G43="NP","NP",ROUND('Gran-LLyLP'!G43,1)) -> NP | G20: 40 max | H20: 41 min | I20: 40 max | J20: 41 min | K20: 40 max | L20: 41 min | M20: 40 max | N20: 41 min | O20: 41 min
B21: Indice plástico | C21: =IF('Gran-LLyLP'!G44="NP","NP",ROUND('Gran-LLyLP'!G44,1)) -> NP | D21: 6 max | E21: 6 max | F21: N.P. | G21: 10 max | H21: 10 max | I21: 11 min | J21: 11 min | K21: 10 max | L21: 10 max | M21: 11 min | N21: 11`min | O21: 11`min
B23: Indice de Grupo | C23: =+D38 -> 0 | D23: 0 | F23: 0 | G23: 0 | I23: 4 max | K23: 8 max | L23: 12 max | M23: 16 max | N23: 20 max | O23: 20 max
E26: CLASIFICACION AASHTO : | J26: =+D31&" "&F38 -> A-1-a (0)
D29: =IF(AND(C11<=50,C12<=30,C13<=15,OR(C21<=6,C21="NP"),C23<=0),D6,"--") -> A-1-a | E29: =IF(AND(C12<=50,C13<=25,OR(C21<=6,C21="NP"),C23<=0),E6,"--") -> A-1-b | F29: =IF(AND(C12>50,C13<=10,OR(C20="N.P.",C20="NP",C20=0),OR(C21="N.P.",C21="NP",C21=0),C23<=0),F5,"--") -> -- | G29: =IF(AND(C13<=35,OR(C20<=40,C20="NP"),OR(C21<=10,C21="NP"),C23<=0),G6,"--") -> A-2-4 | H29: =IF(AND(C13<=35,C20>40,C20<>"NP",C21<=10,C21<>"NP",C23<=0),H6,"--") -> -- | I29: =IF(AND(C13<=35,C20<=40,C20<>"NP",C23<=4,C21>10,C21<>"NP"),I6,"--") -> -- | J29: =IF(AND(C13<=35,C20>40,C20<>"NP",C21>10,C23<=4,C21<>"NP"),J6,"--") -> -- | K29: =IF(AND(C13>35,OR(C20<=40,C20="NP"),OR(C21<=10,C21="NP"),C23<=8),K5,"--") -> -- | L29: =IF(AND(C13>35,C20>40,C20<>"NP",C21<=10,C21<>"NP",C23<=12),L5,"--") -> -- | M29: =IF(AND(C13>35,C20<=40,C21>10,C23<=16,C21<>"NP"),M5,"--") -> -- | N29: =IF(AND(C13>35,C20<>"NP",C20>40,C21<>"NP",C21>10,C23<=20),IF(C20-C21>30,N6,"--"),"--") -> -- | O29: =IF(AND(C13>35,C20>40,C20<>"NP",C21>10,C21<>"NP",C23<=20),IF(C20-C21<=30,O6,"--"),"--") -> --
D30: =IF(D29<>"--",D29,"") -> A-1-a | E30: =IF(AND(D29="--",E29<>"--"),E29,"") | F30: =IF(AND(D29="--",E29="--",F29<>"--"),F29,"") | G30: =IF(AND(D29="--",E29="--",F29="--",G29<>"--"),G29,"") | H30: =IF(AND(D29="--",E29="--",F29="--",G29="--",H29<>"--"),H29,"") | I30: =IF(AND(D29="--",E29="--",F29="--",G29="--",H29="--",I29<>"--"),I29,"") | J30: =IF(AND(D29="--",E29="--",F29="--",G29="--",H29="--",I29="--",J29<>"--"),J29,"") | K30: =IF(K29<>"--",K29,"") | L30: =IF(AND(K29="--",L29<>"--"),L29,"") | M30: =IF(AND(K29="--",L29="--",M29<>"--"),M29,"") | N30: =IF(AND(K29="--",L29="--",M29="--",N29<>"--"),N29,"") | O30: =IF(AND(K29="--",L29="--",M29="--",N29="--",O29<>"--"),O29,"")
D31: =+D30&E30&F30&G30&H30&I30&J30&K30&L30&M30&N30&O30 -> A-1-a
C33: A | D33: =+IF(C13>75,40,IF(C13<35,1,IF(C13<40,40-C13,C13-40))) -> 1
C34: B | D34: =+IF(C13>55,40,IF(C13<15,1,C13-15)) -> 1
C35: C | D35: =+IF(C20="NP",1,IF(C20>60,20,IF(C20<40,1,C20-40))) -> 1
C36: D | D36: =+IF(C21="NP",1,IF(C21>30,20,IF(C21<10,1,C21-10))) -> 1
C38: =0.2*D33+0.005*D33*D35+0.01*D34*D36 -> 0.215 | D38: =ROUND(C38,0) -> 0 | F38: =+"("&D38&")" -> (0)

Sheet Apoyo 2
A1: =+D1 -> 76.2 | B1: 0 | C1: 3" | D1: 76.2 | E1: 0 | F1: 100 | G1: =+'Gran-LLyLP'!C23 -> 0 | H1: =+G1/'Gran-LLyLP'!$D$17*100 -> 0 | I1: =+H1 -> 0 | J1: =100-I1 -> 100 | L1: ESPECIFICACIONES
A2: =+A1 -> 76.2 | B2: 100 | C2: 2 1/2" | D2: 63.5 | E2: 0 | F2: 100 | G2: =+'Gran-LLyLP'!C24 -> 0 | H2: =+G2/'Gran-LLyLP'!$D$17*100 -> 0 | I2: =+H2+I1 -> 0 | J2: =100-I2 -> 100 | L2: Nº Malla | M2: Abertura mm. | N2: Especificaciones "B" | P2: % Que Pasa
C3: 2" | D3: 50.6 | E3: 0 | F3: 100 | G3: =+'Gran-LLyLP'!C25 -> 0 | H3: =+G3/'Gran-LLyLP'!$D$17*100 -> 0 | I3: =+H3+I2 -> 0 | J3: =100-I3 -> 100 | L3: =+C3 -> 2" | M3: =+D3 -> 50.6 | N3: =+'Gran-LLyLP'!H25 -> 0 | O3: =+'Gran-LLyLP'!H25 -> 0 | P3: =+J3 -> 100
A4: =+D2 -> 63.5 | B4: 0 | C4: 1 1/2" | D4: 38.1 | E4: 0 | F4: 100 | G4: =+'Gran-LLyLP'!C26 -> 1384 | H4: =+G4/'Gran-LLyLP'!$D$17*100 -> 281.58698 | I4: =+H4+I3 -> 281.58698 | J4: =100-I4 -> -181.58698 | L4: =+C4 -> 1 1/2" | M4: =+D4 -> 38.1 | N4: =+'Gran-LLyLP'!G26 -> 0 | O4: =+'Gran-LLyLP'!I26 -> 100 | P4: =+J4 -> -181.58698
A5: =+A4 -> 63.5 | B5: 100 | C5: 1" | D5: 25.4 | E5: 0 | F5: 100 | G5: =+'Gran-LLyLP'!C27 -> 3256 | H5: =+G5/'Gran-LLyLP'!$D$17*100 -> 662.46185 | I5: =+H5+I4 -> 944.04883 | J5: =100-I5 -> -844.04883 | L5: =+C5 -> 1" | M5: =+D5 -> 25.4 | N5: =+'Gran-LLyLP'!G27 -> 0 | O5: =+'Gran-LLyLP'!I27 -> 0 | P5: =+J5 -> -844.04883
C6: 3/4" | D6: 19.05 | E6: 0 | F6: 100 | G6: =+'Gran-LLyLP'!C28 -> 2413 | H6: =+G6/'Gran-LLyLP'!$D$17*100 -> 490.94608 | I6: =+H6+I5 -> 1434.9949 | J6: =100-I6 -> -1334.9949 | L6: =+C6 -> 3/4" | M6: =+D6 -> 19.05 | N6: =+'Gran-LLyLP'!G28 -> 0 | O6: =+'Gran-LLyLP'!I28 -> 0 | P6: =+J6 -> -1334.9949
A7: =+D3 -> 50.6 | B7: 0 | C7: 1/2" | D7: 12.7 | E7: 0 | F7: 100 | G7: =+'Gran-LLyLP'!C29 -> 4064 | H7: =+G7/'Gran-LLyLP'!$D$17*100 -> 826.85656 | I7: =+H7+I6 -> 2261.8515 | J7: =100-I7 -> -2161.8515 | L7: =+C7 -> 1/2" | M7: =+D7 -> 12.7 | N7: =+'Gran-LLyLP'!G30 -> 30 | O7: =+'Gran-LLyLP'!I30 -> 65 | P7: =+J7 -> -2161.8515
A8: =+A7 -> 50.6 | B8: 100 | C8: 3/8" | D8: 9.525 | E8: 0 | F8: 100 | G8: =+'Gran-LLyLP'!C30 -> 1986 | H8: =+G8/'Gran-LLyLP'!$D$17*100 -> 404.06918 | I8: =+H8+I7 -> 2665.9207 | J8: =100-I8 -> -2565.9207 | L8: =+C8 -> 3/8" | M8: =+D8 -> 9.525 | N8: =+'Gran-LLyLP'!G32 -> 25 | O8: =+'Gran-LLyLP'!I32 -> 55 | P8: =+J8 -> -2565.9207
C9: 1/4" | D9: 6.35 | E9: 0 | F9: 100 | I9: =+I8 -> 2665.9207 | J9: =+(J8+J10)/2 -> -2652.7976 | L9: =+C9 -> 1/4" | M9: =+D9 -> 6.35 | N9: =+'Gran-LLyLP'!G33 -> 0 | O9: =+'Gran-LLyLP'!I33 -> 0 | P9: =+J9 -> -2652.7976
A10: =+D4 -> 38.1 | B10: 0 | C10: No4 | D10: 4.76 | E10: 0 | F10: 100 | G10: =+'Gran-LLyLP'!C32 -> 854 | H10: =+G10/'Gran-LLyLP'!$D$17*100 -> 173.75381 | I10: =+H10+I9 -> 2839.6745 | J10: =100-I10 -> -2739.6745 | L10: =+C10 -> No4 | M10: =+D10 -> 4.76 | N10: =+'Gran-LLyLP'!G36 -> 0 | O10: =+'Gran-LLyLP'!I36 -> 0 | P10: =+J10 -> -2739.6745
A11: =+A10 -> 38.1 | B11: 100 | C11: 8 | D11: 2.38 | E11: 0 | F11: 100 | I11: =+I10 -> 2839.6745 | J11: =+(J10+J12)/2 -> -2752.3906 | L11: =+C11 -> 8 | M11: =+D11 -> 2.38 | N11: =+'Gran-LLyLP'!G40 -> 2 | O11: =+'Gran-LLyLP'!I40 -> 8 | P11: =+J11 -> -2752.3906
C12: 10 | D12: 2 | E12: 0 | F12: 100 | G12: =+'Gran-LLyLP'!C33 -> 125 | H12: =+G12/'Gran-LLyLP'!$D$17*100 -> 25.43235 | I12: =+H12+I11 -> 2865.1068 | J12: =100-I12 -> -2765.1068 | L12: =+C12 -> 10 | M12: =+D12 -> 2 | P12: =+J12 -> -2765.1068
A13: =+D5 -> 25.4 | B13: 0 | C13: 16 | D13: 1.19 | E13: 0 | F13: 100 | I13: =+I12 -> 2865.1068 | J13: =+(J12+J14)/2 -> -2766.999 | L13: =+C13 -> 16 | M13: =+D13 -> 1.19 | P13: =+J13 -> -2766.999
A14: =+A13 -> 25.4 | B14: 100 | C14: 20 | D14: 0.84 | E14: 0 | F14: 100 | G14: =+'Gran-LLyLP'!C34 -> 18.6 | H14: =+G14/'Gran-LLyLP'!$D$17*100 -> 3.7843337 | I14: =+H14+I13 -> 2868.8911 | J14: =100-I14 -> -2768.8911 | L14: =+C14 -> 20 | M14: =+D14 -> 0.84 | P14: =+J14 -> -2768.8911
C15: 30 | D15: 0.59 | E15: 0 | F15: 100 | I15: =+I14 -> 2868.8911 | J15: =+(J14+J16)/2 -> -2778.6572 | L15: =+C15 -> 30 | M15: =+D15 -> 0.59 | P15: =+J15 -> -2778.6572
A16: =+D6 -> 19.05 | B16: 0 | C16: 40 | D16: 0.42 | E16: 0 | F16: 100 | G16: =+'Gran-LLyLP'!C36 -> 96 | H16: =+G16/'Gran-LLyLP'!$D$17*100 -> 19.532045 | I16: =+H16+I15 -> 2888.4232 | J16: =100-I16 -> -2788.4232 | L16: =+C16 -> 40 | M16: =+D16 -> 0.42 | P16: =+J16 -> -2788.4232
A17: =+A16 -> 19.05 | B17: 100 | C17: 50 | D17: 0.3 | E17: 0 | F17: 100 | I17: =+I16 -> 2888.4232 | J17: =+(J16+J18)/2 -> -2790.4171 | L17: =+C17 -> 50 | M17: =+D17 -> 0.3 | P17: =+J17 -> -2790.4171
C18: 60 | D18: 0.25 | E18: 0 | F18: 100 | G18: =+'Gran-LLyLP'!C37 -> 19.6 | H18: =+G18/'Gran-LLyLP'!$D$17*100 -> 3.9877925 | I18: =+H18+I17 -> 2892.411 | J18: =100-I18 -> -2792.411 | L18: =+C18 -> 60 | M18: =+D18 -> 0.25 | P18: =+J18 -> -2792.411
A19: =+D7 -> 12.7 | B19: 0 | C19: 80 | D19: 0.18 | E19: 0 | F19: 100 | G19: ='Gran-LLyLP'!C38 -> 23.6 | H19: =+G19/'Gran-LLyLP'!$D$17*100 -> 4.8016277 | I19: =+H19+I18 -> 2897.2126 | J19: =100-I19 -> -2797.2126 | L19: =+C19 -> 80 | M19: =+D19 -> 0.18 | P19: =+J19 -> -2797.2126
A20: =+A19 -> 12.7 | B20: 100 | C20: 100 | D20: 0.149 | E20: 0 | F20: 100 | G20: =+'Gran-LLyLP'!C39 -> 25.6 | H20: =+G20/'Gran-LLyLP'!$D$17*100 -> 5.2085453 | I20: =+H20+I19 -> 2902.4212 | J20: =100-I20 -> -2802.4212 | L20: =+C20 -> 100 | M20: =+D20 -> 0.149 | P20: =+J20 -> -2802.4212
C21: 200 | D21: 0.074 | E21: 0 | F21: 100 | G21: =+'Gran-LLyLP'!C40 -> 31.2 | H21: =+G21/'Gran-LLyLP'!$D$17*100 -> 6.3479145 | I21: =+H21+I20 -> 2908.7691 | J21: =100-I21 -> -2808.7691 | L21: =+C21 -> 200 | M21: =+D21 -> 0.074 | P21: =+J21 -> -2808.7691
A22: =+D8 -> 9.525 | B22: 0 | D22: =+M22 -> #REF! | E22: 0 | F22: 100 | M22: =#REF! -> #REF! | P22: =+#REF! -> #REF!
A23: =+A22 -> 9.525 | B23: 100 | D23: =+M23 -> #REF! | E23: 0 | F23: 100 | M23: =+#REF! -> #REF! | P23: =+#REF! -> #REF!
D24: =+M24 -> #REF! | E24: 0 | F24: 100 | M24: =+#REF! -> #REF! | P24: =+#REF! -> #REF!
A25: =+D9 -> 6.35 | B25: 0 | D25: =+M25 -> #REF! | E25: 0 | F25: 100 | M25: =+#REF! -> #REF! | P25: =+#REF! -> #REF!
A26: =+A25 -> 6.35 | B26: 100 | D26: =+M26 -> #REF! | E26: 0 | F26: 100 | M26: =+#REF! -> #REF! | P26: =+#REF! -> #REF!
D27: =+M27 -> #REF! | E27: 0 | F27: 100 | M27: =+#REF! -> #REF! | P27: =+#REF! -> #REF!
A28: =+D10 -> 4.76 | B28: 0 | D28: =+M28 -> #REF! | E28: 0 | F28: 100 | M28: =+#REF! -> #REF! | P28: =+#REF! -> #REF!
A29: =+A28 -> 4.76 | B29: 100 | D29: =+M29 -> #REF! | E29: 0 | F29: 100 | M29: =+#REF! -> #REF! | P29: =+#REF! -> #REF!
D30: =+M30 -> #REF! | E30: 0 | F30: 100 | M30: =+#REF! -> #REF! | P30: =+#REF! -> #REF!
A31: =+D11 -> 2.38 | B31: 0
A32: =+A31 -> 2.38 | B32: 100
A34: =+D12 -> 2 | B34: 0
A35: =+A34 -> 2 | B35: 100
A37: =+D13 -> 1.19 | B37: 0
A38: =+A37 -> 1.19 | B38: 100
A40: =+D14 -> 0.84 | B40: 0
A41: =+A40 -> 0.84 | B41: 100
A43: =+D15 -> 0.59 | B43: 0
A44: =+A43 -> 0.59 | B44: 100
...

Sheet Sedimentación
A1: CONIRSA S.A.
A6: ANÁLISIS GRANULOMÉTRICO POR MEDIO DEL HIDRÓMETRO (MTC E 109)
A9: Hito | C9: : | D9: =Datos!D9 -> Tunel de Puruchuco
A10: Muestra | C10: : | D10: =Datos!D10 -> Av. Javier Prado S/N Alt. Huaca de Puruchuco
A11: Prof (m.) | C11: : | D11: =Datos!D11 -> Cantera Dorita
A12: Fecha | C12: : | D12: =Datos!#REF! -> #REF!
A14: Hidrómetro tipo A ó 151-H (gr/cc)
A15: Tiempo (min) | B15: Temp. (ºC) | C15: R | D15: Cm | E15: Ct | F15: R' | G15: P (%) | H15: F | I15: P' (%) | J15: Diametro | K15: Kl | L15: Kj | M15: Kn | N15: Diam Corr.(mm) | O15: Mat. Sedim. (%) | P15: Ta | Q15: Td | R15: Kna | S15: Knd | T15: aa | U15: ad | V15: Kja | W15: Kjd
J16: Equiv.
A17: 1 | B17: 24 | C17: 17.5 | D17: 0.5 | E17: 1.0199 | F17: =+E17-D17+C17 -> 18.0199 | G17: =+F17*$D$31/$D$28*100 -> 17.978936 | H17: =+$D$29/100 -> 0.278 | I17: =+H17*G17 -> 4.9981443 | J17: 0.078 | K17: =+(253.85-F17)/461.54 -> 0.51096351 | L17: =+($D$31-T17)*(W17-V17)/(U17-T17)+V17 -> 0.99683527 | M17: =+(B17-P17)*(S17-R17)/(Q17-P17)+R17 -> 0.94762 | N17: =+M17*L17*K17*J17 -> 0.037648017 | O17: =+$D$30-I17 -> 0.0018556921 | P17: 23.9 | Q17: 24.4 | R17: 0.9489 | S17: 0.9425 | T17: 0.9933 | U17: 0.9889 | V17: 0.991 | W17: 0.9852
A18: 2 | B18: 24 | C18: 16.5 | D18: 0.5 | E18: 1.0199 | F18: =+E18-D18+C18 -> 17.0199 | G18: =+F18*$D$31/$D$28*100 -> 16.98121 | H18: =+$D$29/100 -> 0.278 | I18: =+H18*G18 -> 4.7207763 | J18: 0.055 | K18: =+(253.85-F18)/461.54 -> 0.51313017 | L18: =+($D$31-T18)*(W18-V18)/(U18-T18)+V18 -> 0.99683527 | M18: =+(B18-P18)*(S18-R18)/(Q18-P18)+R18 -> 0.94762 | N18: =+M18*L18*K18*J18 -> 0.026659246 | O18: =+I17-I18 -> 0.27736804 | P18: 23.9 | Q18: 24.4 | R18: 0.9489 | S18: 0.9425 | T18: =+T17 -> 0.9933 | U18: =+U17 -> 0.9889 | V18: =+V17 -> 0.991 | W18: =+W17 -> 0.9852
A19: 5 | B19: 24 | C19: 14.5 | D19: 0.5 | E19: 1.0199 | F19: =+E19-D19+C19 -> 15.0199 | G19: =+F19*$D$31/$D$28*100 -> 14.985756 | H19: =+$D$29/100 -> 0.278 | I19: =+H19*G19 -> 4.1660402 | J19: 0.035 | K19: =+(253.85-F19)/461.54 -> 0.51746349 | L19: =+($D$31-T19)*(W19-V19)/(U19-T19)+V19 -> 0.99683527 | M19: =+(B19-P19)*(S19-R19)/(Q19-P19)+R19 -> 0.94783333 | N19: =+M19*L19*K19*J19 -> 0.017112093 | O19: =+I18-I19 -> 0.55473608 | P19: 23.3 | Q19: 23.9 | R19: 0.9553 | S19: 0.9489 | T19: =+T18 -> 0.9933 | U19: =+U18 -> 0.9889 | V19: =+V18 -> 0.991 | W19: =+W18 -> 0.9852
A20: 10 | B20: 24 | C20: 13 | D20: 0.5 | E20: 1.0199 | F20: =+E20-D20+C20 -> 13.5199 | G20: =+F20*$D$31/$D$28*100 -> 13.489166 | H20: =+$D$29/100 -> 0.278 | I20: =+H20*G20 -> 3.7499881 | J20: =(J19+J21)/2 -> 0.0275 | K20: =+(253.85-F20)/461.54 -> 0.52071348 | L20: =+($D$31-T20)*(W20-V20)/(U20-T20)+V20 -> 0.99683527 | M20: =+(B20-P20)*(S20-R20)/(Q20-P20)+R20 -> 0.94783333 | N20: =+M20*L20*K20*J20 -> 0.01352966 | O20: =+I19-I20 -> 0.41605206 | P20: 23.3 | Q20: 23.9 | R20: 0.9553 | S20: 0.9489 | T20: =+T19 -> 0.9933 | U20: =+U19 -> 0.9889 | V20: =+V19 -> 0.991 | W20: =+W19 -> 0.9852
A21: 15 | B21: 24 | C21: 13 | D21: 0.5 | E21: 1.0199 | F21: =+E21-D21+C21 -> 13.5199 | G21: =+F21*$D$31/$D$28*100 -> 13.489166 | H21: =+$D$29/100 -> 0.278 | I21: =+H21*G21 -> 3.7499881 | J21: 0.02 | K21: =+(253.85-F21)/461.54 -> 0.52071348 | L21: =+($D$31-T21)*(W21-V21)/(U21-T21)+V21 -> 0.99683527 | M21: =+(B21-P21)*(S21-R21)/(Q21-P21)+R21 -> 0.94648 | N21: =+M21*L21*K21*J21 -> 0.0098257035 | O21: =+I20-I21 -> 0 | P21: 22.8 | Q21: 23.3 | R21: 0.9616 | S21: 0.9553 | T21: =+T20 -> 0.9933 | U21: =+U20 -> 0.9889 | V21: =+V20 -> 0.991 | W21: =+W20 -> 0.9852
A22: 30 | B22: 24.5 | C22: 12 | D22: 0.5 | E22: 1.1399 | F22: =+E22-D22+C22 -> 12.6399 | G22: =+F22*$D$31/$D$28*100 -> 12.611166 | H22: =+$D$29/100 -> 0.278 | I22: =+H22*G22 -> 3.5059043 | J22: 0.014 | K22: =+(253.85-F22)/461.54 -> 0.52262014 | L22: =+($D$31-T22)*(W22-V22)/(U22-T22)+V22 -> 0.99683527 | M22: =+(B22-P22)*(S22-R22)/(Q22-P22)+R22 -> 0.94018 | N22: =+M22*L22*K22*J22 -> 0.0068572279 | O22: =+I21-I22 -> 0.24408387 | P22: 22.8 | Q22: 23.3 | R22: 0.9616 | S22: 0.9553 | T22: =+T21 -> 0.9933 | U22: =+U21 -> 0.9889 | V22: =+V21 -> 0.991 | W22: =+W21 -> 0.9852
A23: 60 | B23: 24.5 | C23: 11.5 | D23: 0.5 | E23: 1.1399 | F23: =+E23-D23+C23 -> 12.1399 | G23: =+F23*$D$31/$D$28*100 -> 12.112303 | H23: =+$D$29/100 -> 0.278 | I23: =+H23*G23 -> 3.3672202 | J23: 0.01 | K23: =+(253.85-F23)/461.54 -> 0.52370347 | L23: =+($D$31-T23)*(W23-V23)/(U23-T23)+V23 -> 0.99683527 | M23: =+(B23-P23)*(S23-R23)/(Q23-P23)+R23 -> 0.93938 | N23: =+M23*L23*K23*J23 -> 0.0049039966 | O23: =+I22-I23 -> 0.13868402 | P23: 21.7 | Q23: 22.2 | R23: 0.9741 | S23: 0.9679 | T23: =+T22 -> 0.9933 | U23: =+U22 -> 0.9889 | V23: =+V22 -> 0.991 | W23: =+W22 -> 0.9852
A24: 240 | B24: 24 | C24: 9.5 | D24: 0.5 | E24: 1.0199 | F24: =+E24-D24+C24 -> 10.0199 | G24: =+F24*$D$31/$D$28*100 -> 9.9971223 | H24: =+$D$29/100 -> 0.278 | I24: =+H24*G24 -> 2.7792 | J24: 0.005 | K24: =+(253.85-F24)/461.54 -> 0.52829679 | L24: =+($D$31-T24)*(W24-V24)/(U24-T24)+V24 -> 0.99683527 | M24: =+(B24-P24)*(S24-R24)/(Q24-P24)+R24 -> 0.94558 | N24: =+M24*L24*K24*J24 -> 0.0024898297 | O24: =+I23-I24 -> 0.58802024 | P24: 21.7 | Q24: 22.2 | R24: 0.9741 | S24: 0.9679 | T24: =+T23 -> 0.9933 | U24: =+U23 -> 0.9889 | V24: =+V23 -> 0.991 | W24: =+W23 -> 0.9852
A25: 1440 | B25: 24 | C25: 8 | D25: 0.5 | E25: 1.0199 | F25: =+E25-D25+C25 -> 8.5199 | G25: =+F25*$D$31/$D$28*100 -> 8.5005322 | H25: =+$D$29/100 -> 0.278 | I25: =+H25*G25 -> 2.3631479 | J25: 0.002 | K25: =+(253.85-F25)/461.54 -> 0.53154678 | L25: =+($D$31-T25)*(W25-V25)/(U25-T25)+V25 -> 0.99683527 | M25: =+(B25-P25)*(S25-R25)/(Q25-P25)+R25 -> 0.94434 | N25: =+M25*L25*K25*J25 -> 0.0010007446 | O25: =+I24-I25 -> 0.41605206 | P25: 20.6 | Q25: 21.1 | R25: 0.9865 | S25: 0.9803 | T25: =+T24 -> 0.9933 | U25: =+U24 -> 0.9889 | V25: =+V24 -> 0.991 | W25: =+W24 -> 0.9852
A27: Hora inicio : | D27: 08:16:00 a.m. | F27: Pe de solidos (Gs) : | I27: 2.66 | J27: (MTC E 113)
A28: Pss(gr) : | D28: 100 | F28: Limite Liquido(%) : | I28: =+'Gran-LLyLP'!G43 -> NP | K28: Limo (0.074mm - 0.005mm) : | N28: =+D30-I23 -> 1.6327798 | O28: %
A29: (%) Pasa Nº10 : | D29: =+'Gran-LLyLP'!F33 -> 27.8 | F29: Limite Plastico(%) : | I29: =+'Gran-LLyLP'!O28 -> 0 | K29: Arcilla(0.005mm - 0.001mm) : | N29: =+I23-I25 -> 1.0040723 | O29: %
A30: (%) Pasa Nº200 : | D30: =+'Gran-LLyLP'!F40 -> 5 | F30: Indice plasticidad(%) : | I30: =+'Gran-LLyLP'!G44 -> NP | K30: Coloide (menor a 0.001mm) : | N30: =+I25 -> 2.3631479 | O30: %
A31: Coefi. "a" : | D31: =0.622641509*I27/(I27-1) -> 0.99772676 | F31: Clasificación SUCS : | I31: =+'Gran-LLyLP'!D43 -> GW-GM
A54: % pasa Nº200 : | C54: =+D30 -> 5
A55: % pasa 0.005 : | C55: 0.54
A56: % pasa 0.001 : | C56: 0

Sheet H.N
A1: CONIRSA S.A.
A6: HUMEDAD NATURAL (MTC E 108)
A12: =+Datos!#REF! -> #REF! | B12: =+Datos!#REF! -> #REF!
A13: =+Datos!#REF! -> #REF! | B13: =+Datos!#REF! -> #REF!
A14: =+Datos!#REF! -> #REF! | B14: =+Datos!#REF! -> #REF!
A16: =+Datos!A8 -> Solicitado :
A17: =+Datos!A9 -> Proyecto : | B17: =+Datos!D9 -> Tunel de Puruchuco
A18: =+Datos!A10 -> Ubicación : | B18: =+Datos!D10 -> Av. Javier Prado S/N Alt. Huaca de Puruchuco
A19: =+Datos!A11 -> Cantera : | B19: =+Datos!D11 -> Cantera Dorita
A20: =+Datos!A12 -> Material : | B20: =+Datos!D12 -> Base Granular
A21: DATOS
A23: Nº de Ensayo | C23: 1
A24: Peso de Mat. Humedo + Tara (gr.) | C24: 138.4
A25: Peso de Mat. Seco + Tara (gr.) | C25: 112
A26: Peso de Tara (gr.)
A27: Peso de Agua (gr.) | C27: =+C24-C25 -> 26.4
A28: Peso Mat. Seco (gr.) | C28: =+C25-C26 -> 112
A29: Humedad Natural (%) | C29: =+C27/C28*100 -> 23.571429
A30: Promedio de Humedad (%) | B30: =AVERAGE(B29:D29)/100 -> 0.23571429
A32: OBSERVACIONES:

Sheet Chatas y Alarga.
V1: 1:2
V2: 1:3
V3: 1:4
V4: 1:5
A8: LABORATORIO DE ENSAYO DE MATERIALES
A9: FORMATO N° F-LEM-P-AG-07.01
A15: METODO DE ENSAYO PARA LA DETERMINACION DEL PORCENTAGE DE PARTICULAS CHATAS O ALARGADAS EN EL AGREGADO GRUESO
A16: NTP 400.040
A22: Tamaño de las particulas | C22: Gradación de la muestra | F22: Particulas Chatas | J22: Particulas Alargadas | N22: Particulas Ni chatas Ni alargadas
A24: Abertura Tamiz | C24: Peso Retenido (gr) | D24: Numero Partic. | E24: (%) Retenido | F24: Peso Retenido (gr) | G24: Numero Partic. | H24: (%) Partic. | I24: (%) Correg. | J24: Peso Retenido (gr) | K24: Numero Partic. | L24: (%) Partic. | M24: (%) Correg. | N24: Peso Retenido (gr) | O24: Numero Partic. | P24: (%) Partic. | Q24: (%) Correg.
A25: Pasa T. | B25: Retenido T.
A26: 2" | B26: 1 1/2" | E26: =IF(C26="","",((C26/$C$31*100))) | H26: =IF(F26="","",((F26/C26*100))) | I26: =IF(F26="","",((F26/$C$31*100))) | L26: =IF(F26="","",((F26/C26*100))) | M26: =IF(J26="","",((J26/$C$31*100))) | N26: =IF(C26="","",((C26-F26-J26))) | P26: =IF(J26="","",((J26/H26*100))) | Q26: =IF(N26="","",((N26/$C$31*100)))
A27: 1 1/2" | B27: 1" | C27: 6252 | E27: =IF(C27="","",((C27/$C$31*100))) -> 46.587183 | F27: 150 | H27: =IF(F27="","",((F27/C27*100))) -> 2.3992322 | I27: =IF(F27="","",((F27/$C$31*100))) -> 1.1177347 | J27: 214 | L27: =IF(F27="","",((F27/C27*100))) -> 2.3992322 | M27: =IF(J27="","",((J27/$C$31*100))) -> 1.5946349 | N27: =IF(C27="","",((C27-F27-J27))) -> 5888 | P27: =IF(J27="","",((J27/H27*100))) -> 8919.52 | Q27: =IF(N27="","",((N27/$C$31*100))) -> 43.874814
A28: 1" | B28: 3/4" | C28: 2568 | E28: =IF(C28="","",((C28/$C$31*100))) -> 19.135618 | F28: 132 | H28: =IF(F28="","",((F28/C28*100))) -> 5.1401869 | I28: =IF(F28="","",((F28/$C$31*100))) -> 0.98360656 | J28: 198 | L28: =IF(F28="","",((F28/C28*100))) -> 5.1401869 | M28: =IF(J28="","",((J28/$C$31*100))) -> 1.4754098 | N28: =IF(C28="","",((C28-F28-J28))) -> 2238 | P28: =IF(J28="","",((J28/H28*100))) -> 3852 | Q28: =IF(N28="","",((N28/$C$31*100))) -> 16.676602
A29: 3/4" | B29: 1/2" | C29: 3125 | E29: =IF(C29="","",((C29/$C$31*100))) -> 23.28614 | F29: 111 | H29: =IF(F29="","",((F29/C29*100))) -> 3.552 | I29: =IF(F29="","",((F29/$C$31*100))) -> 0.8271237 | J29: 154 | L29: =IF(F29="","",((F29/C29*100))) -> 3.552 | M29: =IF(J29="","",((J29/$C$31*100))) -> 1.147541 | N29: =IF(C29="","",((C29-F29-J29))) -> 2860 | P29: =IF(J29="","",((J29/H29*100))) -> 4335.5856 | Q29: =IF(N29="","",((N29/$C$31*100))) -> 21.311475
A30: 1/2" | B30: 3/8" | C30: 1475 | E30: =IF(C30="","",((C30/$C$31*100))) -> 10.991058 | F30: 87 | H30: =IF(F30="","",((F30/C30*100))) -> 5.8983051 | I30: =IF(F30="","",((F30/$C$31*100))) -> 0.64828614 | J30: 113 | L30: =IF(F30="","",((F30/C30*100))) -> 5.8983051 | M30: =IF(J30="","",((J30/$C$31*100))) -> 0.84202683 | N30: =IF(C30="","",((C30-F30-J30))) -> 1275 | P30: =IF(J30="","",((J30/H30*100))) -> 1915.8046 | Q30: =IF(N30="","",((N30/$C$31*100))) -> 9.5007452
A31: TOTAL | C31: =SUM(C26:C30) -> 13420 | E31: =SUM(E26:E30) -> 100 | H31: =SUM(H26:H30) -> 16.989724 | I31: =SUM(I26:I30) -> 3.5767511 | L31: =SUM(L26:L30) -> 16.989724 | M31: =SUM(M26:M30) -> 5.0596125 | P31: =SUM(P26:P30) -> 19022.91 | Q31: =SUM(Q26:Q30) -> 91.363636
A33: Rlación Dimencional | G33: 1:3
A34: Particulas Chatas y Alargadas | G34: =I31+M31 -> 8.6363636
A56: Página 1 de 1
A57: Versión : 02 (02-01-2021)
A59: WEB: www.geofal.com.pe E-MAIL: laboratorio@geofal.com.pe / geofal.sac@gmail.com Av. Marañon 763, Los Olivos-Lima / Teléfono 01 522-1851

Sheet PLANAS Y ALARGADAS
A7: LABORATORIO DE ENSAYO DE MATERIALES
A8: FORMATO N° F-LEM-P-AG-34.01
D10: MUESTRA | G10: No OT | J10: FECHA ENSAYO | M10: REALIZADO
A14: STANDARD TEST METHOD FOR FLAT PARTICLES, ELONGATED PARTICLES, OR FLAT AND ELONGATED PARTICLES IN COARSE AGGREGATE
A15: ASTM D4791-19 (Reapproved 2023)
E17: Método de ensayo: | I17: Tamiz requerido
E18: Método A | I18: 3/8 in.
E19: Método B | I19: No. 4
E20: El método A esta destinado para todas las aplicaciones, el método B se realizara a solicitud del cliente (Superpave)
B21: Tamaño de las partículas | D21: Gradación de la muestra (1) - ASTM C136 | I21: Reducción de la mustra de prueba | N21: Masa inicial
D22: Muestra original | N22: Masa seca
B23: Abertura Tamiz | D23: Masa Retenido original (g) | F23: (%) Retenido | H23: Criterio Acept. ≥10% (*) | I23: Número Partículas (Aprox. 100) | K23: Masa retenido (g) | N23: Masa seca constante
B25: Pasa Tamiz | C25: Retenido Tamiz | N25: TMN | P25: Masa mín. (g)
B26: 2 in. | C26: 1 1/2 in. | N26: 2 in. | P26: 20000
B27: 1 1/2 in. | C27: 1 in. | N27: 1 1/2 in. | P27: 15000
B28: 1 in. | C28: 3/4 in. | N28: 1 in. | P28: 10000
B29: 3/4 in. | C29: 1/2 in. | N29: 3/4 in. | P29: 5000
B30: 1/2 in. | C30: 3/8 in. | N30: 1/2 in. | P30: 2000
B31: 3/8 in. | C31: No. 4 | N31: 3/8 in. | P31: 1000
B32: TOTAL | N32: No. 4 | P32: 1000
B33: (*) Marcar con una Check o Aspa , aquellas mallas a evaluar o descartar; (1)Se realizará de no tener granulometría.
B35: Método A
K36: Método B
B37: Retenido Tamiz | C37: Partículas Planas Grupo 1 Ancho - espesor | G37: Partículas Alargadas Grupo 2 Largo - ancho | K37: Particulas que cumplen los criterios tanto del Grupo 1 como del Grupo 2 Grupo 3 | O37: Partículas Ni Planas Ni Alargadas Grupo 4
C38: Número Partículas | E38: Masa (g) | G38: Número Partículas | I38: Masa (g) | K38: Número Partículas | M38: Masa (g) | O38: Número Partículas | Q38: Masa (g)
B39: 1 1/2 in.
B40: 1 in.
B41: 3/4 in.
B42: 1/2 in.
B43: 3/8 in.
B44: No. 4
B45: Nota: Para el método A: Cumple el criterio del grupo 1 y Grupo 2; Método B: Partículas en la relación de Longitud - Espesor
B47: Codigo equipos utilizados | D47: Dispositivo de calibre proporcional | K47: Balanza 0.1 g
D48: Horno
B49: Nota:
A53: Página 1 de 1
A54: Versión: 02 (11-11-2024)
A56: WEB: www.geofal.com.pe E-MAIL: laboratorio@geofal.com.pe Av. Marañon 763, Los Olivos-Lima / Teléfono 01 754-3070

Sheet Caras Fracturadas
