Workbook
Name _MON_1607936487: 'COT.ESCANEOACERO'!$A$21
Name _MON_1607936487: 'COT.ING'!#REF!
Name _MON_1607936487: 'COTIZACION INACAL ANTIGUO'!#REF!
Name _MON_1607936487: 'COTIZACION INACAL ASF'!#REF!
Name _MON_1607936487: 'COTIZACION INACAL DENSIDAD'!#REF!
Name _MON_1607936487: 'COTIZACION INACAL EQUIPO'!#REF!
Name _MON_1607936487: 'COTIZACION INACAL GH'!#REF!
Name _MON_1607936487: 'COTIZACION INACAL PROBETAS'!#REF!
Name _MON_1607936487: 'COTIZACION INACAL VARIOS'!#REF!
Name _MON_1607936487: 'COTIZACION PERSONAL'!#REF!
Name _MON_1607936487: 'COTIZACION VARIOS '!#REF!
Name _MON_1607936487: D.MEZCLA3!#REF!
Name _MON_1607936487: 'DENS-AG1'!#REF!
Name _MON_1607936487: 'DENS-AG2'!#REF!
Name _MON_1607936487: 'DENS-AG3'!#REF!
Name _MON_1607936487: 'DENS-AG4'!#REF!
Name _MON_1607936487: 'DENS-AG5'!#REF!
Name _MON_1607936487: 'DENS-AG5 (2)'!#REF!
Name _MON_1607936487: ING!#REF!
Name _MON_1607936487: MORT1!#REF!
Name _MON_1607936487: MORT2!#REF!
Name _MON_1607936487: 'PROB6 (2)'!#REF!
Name _MON_1607936487: 'PROB6 (3)'!#REF!
Name _MON_1607936487: 'PROB7 (2)'!#REF!
Name _MON_1607936487: 'PRUEBA 1'!#REF!
Name _MON_1607936487: 'SU-AG1'!#REF!
Name _MON_1607936487: 'SU-AG10'!#REF!
Name _MON_1607936487: 'SU-AG11'!#REF!
Name _MON_1607936487: 'SU-AG12'!#REF!
Name _MON_1607936487: 'SU-AG2'!#REF!
Name _MON_1607936487: 'SU-AG3'!#REF!
Name _MON_1607936487: 'SU-AG4'!#REF!
Name _MON_1607936487: 'SU-AG5'!#REF!
Name _MON_1607936487: 'SU-AG6'!#REF!
Name _MON_1607936487: 'SU-AG7'!#REF!
Name _MON_1607936487: 'SU-AG8'!#REF!
Name _MON_1607936487: 'SU-AG9'!#REF!
Name asar: ENS.!$B$60:$H$167
Name BD_Clientes: 'CLI.'!$B$4:$K$1048576
Name CLIENTE: 'CLI.'!$B$5:$L$65
Name CLIENTE1: 'CLI.'!$B$5:$L$979
Name CLIENTES: 'CLI.'!$B$37:$L$65
Name clientes1: 'CLI.'!$B$5:$L$300
Name CONDICIONES: CONDICIONES!$A$1:$K$58
Name MAMA: 'CLI.'!$B$5:$L$979
Name SERVICIOENSAYOS: 'ENSAYO ANTIGUO'!$B$4:$F$211
Name SERVICIOENSAYOS: ENS.!$B$60:$H$167

Sheet Hoja2
A3: ITEM | B3: Descripcion | F3: ASTM | G3: P.Unitario (S/.)
B4: Agregado grueso
A5: 1 | B5: Granulometria | F5: D 422 | G5: 60
A6: 2 | B6: Abrasion los angeles | F6: C 131 | G6: 115
A7: 3 | B7: Particulas con una cara fracturada | F7: D 5821 | G7: 48
A8: 4 | B8: Particulas con dos cara fracturada | F8: D 5821 | G8: 48
A9: 5 | B9: Particulas chatas y Alargadas | F9: D 4791 | G9: 48
A10: 6 | B10: Pérdidas con sulfatos de Magnesio | F10: C 88 | G10: 245
A11: 7 | B11: Limite Liquido | F11: D 4318 | G11: 30
A12: 8 | B12: Indice de Plasticidad (LL Y LP) | F12: D 4318 | G12: 53
A13: 9 | B13: Equivalencia de Arena | F13: D 2419 | G13: 60
A14: 10 | B14: Sales Solubles totales | F14: D 1888 | G14: 60
A15: 11 | B15: Limite de Plastico | F15: D 4318 | G15: 30
A16: 12 | B16: CBR (incluye proctor) | F16: D 1883 | G16: 245
A17: 13 | B17: Proctor Modificado | F17: D 1557 | G17: 78
A18: 14 | B18: Absorcion y peso especifico | G18: 35
A19: 15 | B19: adherencia (riedel weber) | G19: 115
A20: 16 | B20: Densidades de Campo (minimo 4 puntos por salida) no incluye mov. | F20: D 1556 | G20: 140
A21: 17 | B21: Ensayo de deflectometrica ( viga Benkelman) (x dia) | G21: 1500
B22: Ensayos del Agua
A23: 18 | B23: Contenido de sales solubles totales | F23: D5907 | G23: 60
A24: 19 | B24: Contenido de sulfatos | F24: D516 | G24: 75
A25: 20 | B25: Contenido de cloruros | F25: D512 | G25: 70
A26: 21 | B26: Sólidos en suspensión | F26: D5907 | G26: 35
A27: 22 | B27: Determinación del pH | F27: D1293 | G27: 45
B28: Bitumen
A29: 23 | B29: viscosidad cinematica | F29: D 2170 | G29: 120
A30: 24 | B30: Punto de Inflamacion | F30: D 92 | G30: 75
A31: 25 | B31: Destilacion y determinacion del residuo | F31: D 244 | G31: 65
A32: 26 | B32: ductibilidad | F32: D 113 | G32: 85
A33: 27 | B33: Solubilidad en tricloetileno | F33: D 2042 | G33: 85
A34: 28 | B34: viscosidad saybolt furol | F34: D 244/D88 | G34: 100
A35: 29 | B35: estabilidad de almacenamiento | F35: D 244 | G35: 40
A36: 30 | B36: tamizado malla N°20 | F36: D 244 | G36: 20
A37: 31 | B37: penetracion | F37: D 5 | G37: 75
A38: 32 | B38: ensayo de pelicula delgada (incl. Perdida por calentamiento, penetracion del residuo, ductibilidad del residuo) | F38: D 1754 | G38: 200
A39: 33 | B39: Ensayo de la mancha (Oliensis) | F39: AASHTO T102 | G39: 100
A44: Movilidad | G44: 50

Sheet ensayos en mecanica de suelos
A1: ENSAYO EN SUELOS
A3: Item | B3: Descripción | C3: NTP | D3: ASTM | E3: P.Unit (S/.)
A4: ENSAYO ESTÁNDAR
A5: 1 | B5: Contenido Humedad | C5: 339127 | D5: D2216 | E5: 15
A6: 2 | B6: Análisis granulométrico por tamizado | C6: 339128 | D6: D422 | E6: 60
A7: 3 | B7: Límite líquido | C7: 339129 | D7: D4318 | E7: 25
A8: 4 | B8: Límite plástico | C8: 339129 | D8: D4318 | E8: 25
A9: 5 | B9: Límite de contracción | C9: 339140 | D9: D427 | E9: 45
A10: 6 | B10: Peso volumétrico de suelos cohesivos | C10: 339139 | D10: BS 1377 | E10: 30
A11: 7 | B11: Gravedad específica de sólidos | C11: 339131 | D11: D854 | E11: 35
A12: ENSAYO ESPECIALES
A13: 8 | B13: Corte Directo | C13: 339171 | D13: D3080 | E13: 350
A14: 9 | B14: Compresión no confinada | C14: 339167 | D14: D2166 | E14: 250
A15: 10 | B15: Consolidación unidimensional | C15: 339154 | D15: D2435 | E15: 550
A16: ENSAYO DE COMPACTACION
A17: 11 | B17: Próctor estándar | C17: 339142 | D17: D698 | E17: 85
A18: 12 | B18: Próctor modificado | C18: 339141 | D18: D1557 | E18: 85
A19: 13 | B19: Valor relativo de soporte CBR (incluye proctor) | C19: 339145 | D19: D1883 | E19: 250
A20: 14 | B20: Densidades de Campo (minimo 4 puntos por salida) no incluye mov. | C20: 339143 | D20: D1556 | E20: 30
A21: 15 | B21: Densidad máxima y minima | C21: INVE-136-07 | E21: 120
A22: PRUBAS IN SITU
A23: 16 | B23: Deflexion con Viga Benkelman | C23: MTC E 1002 | E23: 1500/DIA
A25: Servicio de Movilidad | E25: 50

Sheet Ensayos en suelos
A1: ENSAYO QUIMICOS EN SUELOS
A3: item | B3: Descripción | C3: NTP | D3: ASTM | E3: P. Unit (S/.)
A5: 1 | B5: Sales solubles totales | C5: 339.152 | E5: 75
A6: 2 | B6: Contenido de sulfatos solubles | C6: 339.178 | E6: 75
A7: 3 | B7: Contenido de cloruros solubles | C7: 339.177 | E7: 75
A8: 4 | B8: Determinacion del PH | C8: 339.176 | E8: 60
A10: Servicio de Movilidad | E10: 50

Sheet Ensayos en Concreto
A1: ENSAYO EN CONCRETO
A3: item | B3: Descripción | C3: NTP | D3: ASTM | E3: P. Unit (S/.)
A5: 1 | B5: Diseño de Mezclas | C5: REC ACI 211 | E5: 350
A6: 2 | B6: Verificación de Diseño | C6: - | E6: 120
A7: 3 | B7: Control calidad de concreto en obra | C7: Varias | E7: 180
A8: 4 | B8: Exudación | C8: 339077 | D8: C 232 | E8: 60
A9: 5 | B9: Compresión | C9: 339034 | D9: C 39 | E9: 6.5
A10: 6 | B10: Temperatura del concreto fresco | C10: 339184 | D10: C 1064 | E10: 10
A11: 7 | B11: Asentamiento | C11: 339035 | D11: C 143 | E11: 15
A12: 8 | B12: Extracción, tallado y compresión de testigos por corte diamantina | C12: 339059 | D12: C 42 | E12: 170
A13: 9 | B13: Densidad, Absorción y % de Vacíos Concreto Endurecido | C13: 339187 | D13: C642 | E13: 85
A14: 10 | B14: Refrentado con yeso y ensayo de Compresion | C14: REF. 339.037 | D14: REF. C 617 | E14: 30
A15: 11 | B15: Ensayo de esclerometria | D15: C 805 | E15: 30
A17: Servicio de Movilidad | E17: 50

Sheet Ensayos en agregado
A1: ENSAYO EN AGREGADOS
A3: Código | B3: Descripción | C3: NTP | D3: ASTM | E3: P.U. (S/.)
A5: 1 | B5: Equivalente de arena | C5: 339146 | D5: D2419 | E5: 60
A6: 2 | B6: Partículas chatas y alargadas | C6: 400040 | D6: D4791 | E6: 60
A7: 3 | B7: Caras fracturadas | C7: --- | D7: D5821 | E7: 60
A8: 4 | B8: Análisis Granulométrico por tamizado | C8: 400012 | D8: C 136 | E8: 60
A9: 5 | B9: Impurezas Orgánicas (Fino) | C9: 400024 | D9: C 40 | E9: 40
A10: 6 | B10: Terrones de arcilla y partículas friables | C10: 400015 | D10: C 142 | E10: 80
A11: 7 | B11: Material más fino Malla 200 | C11: 400018 | D11: C 117 | E11: 15
A12: 8 | B12: Inalterabilidad (con sulfato de Magnesio) | C12: 400016 | D12: C 88 | E12: 300
A13: 9 | B13: Peso específico y absorción (F, G) | C13: 400022 | D13: C 128 | E13: 40
A14: 10 | B14: Contenido de humedad (F, G o Glb) | C14: 339185 | D14: C 566 | E14: 15
A15: 11 | B15: Peso unitario | C15: 400017 | D15: C 29 | E15: 35
A16: 12 | B16: desgaste por abracion | C16: MTC E 207 | D16: C 131 | E16: 100
A17: 13 | B17: granulometria - fraccion fino | C17: MTC E 204 | D17: C 136 | E17: 60
A18: 14 | B18: granulometria - global | C18: MTC E 204 | D18: C 136 | E18: 60
A19: 15 | B19: diseño de mezclas de agregados | E19: 70
A21: Servicio de Movilidad | E21: 50

Sheet Ensayos en asfalto
A2: ENSAYO EN PAVIMENTO Y ASFALTO
A4: Código | B4: Descripción | C4: NTP | D4: ASTM | E4: P.Unit (S/.)
A5: MEZCLA ASFALTICA
A6: 1 | B6: Lavado asfáltico (incluye tricloroetileno) | D6: D2172 | E6: 200
A7: 2 | B7: Estabilidad Marshall (Incluye: elaboración de briqueta, estabilidad, flujo, % de vacíos) (costo por briqueta) | D7: D1559 | E7: 190
A8: 3 | B8: Densidad de briqueta de mezcla asfáltica | D8: D2726 | E8: 45
A9: 4 | B9: Densidad máxima teórica (Rice) | D9: D2041 | E9: 80
A10: 5 | B10: Porcentaje de vacíos (incluye: densidad de especimen y densidad máxima teórica (Rice)) (costo por briqueta) | D10: --- | E10: 125
A11: 6 | B11: Elaboración de briquetas (juego de 3) | D11: D1559 | E11: 75
A12: 7 | B12: Adherencia en agregado fino (Riedel y Weber) | C12: MTC E220 | E12: 120
A13: 8 | B13: Adherencia en agregado grueso (Revestimiento y desprendimiento) | C13: MTC E521 | D13: D3625 | E13: 120
A14: 9 | B14: Textura del pavimento (Circulo de Arena) | C14: MTC 1005 | D14: E 965 | E14: 30
A15: 10 | B15: Deflexion con Viga Benkelman | C15: MTC E 1002 | E15: 1500/DIA
A16: 11 | B16: extraccion de briquetas por corte diamantina | E16: 140
A17: 12 | B17: Azul de Metileno | E17: 60
A18: 13 | B18: Penetracion | D18: D5 | E18: 75
A19: 14 | B19: Punto de inflamacion | D19: D92 | E19: 75
A20: 15 | B20: solubilidad de tricloroetileno | D20: D2042 | E20: 85
A21: 16 | B21: ensayo de la mancha (oliensis) | D21: AASHTO T102 | E21: 100
A22: 17 | B22: Ductibilidad | D22: D112 | E22: 85
A23: 18 | B23: Pelicula delgada | D23: D1754 | E23: 200
A24: 19 | B24: Punto de ablandamiento | D24: D36 | E24: 75
A25: 20 | B25: Viscosidad saybolt furol | D25: D244 | E25: 100
A26: 21 | B26: Indice de penetracion | D26: D5 | E26: 225
A27: 22 | B27: Peso especifico | D27: D70 | E27: 85
A28: 23 | B28: Viscosidad cinematica | D28: D2170 | E28: 120
A29: 24 | B29: contenido de agua | D29: D95 | E29: 55
... A36: 31 | B36: sedimentacion a los 5 dias | D36: D244 | E36: 70
A38: Servicio de Movilidad | E38: 50

Sheet ENSAYO ANTIGUO
B1: PRECIOS UNITARIOS DEL SERVICIO
A3: SUELOS | B3: CÓDIGO | C3: DESCRIPCION | D3: NORMA | E3: ASTM | F3: PRECIO A | H3: PRECIO B | I3: PRECIO C | J3: COMENTARIOS | K3: NORMA ADQUIRIDA | L3: PROCEDIMIENTO GEOFAL | M3: FORMATO | N3: CERTIFICADO
B4: SU03 | C4: Determinación del pH | D4: NTP 339.176 | E4: D4972 | F4: 60 | G4: 60 | L4: SI
B5: SU04 | C5: Contenido de humedad con Speedy | D5: NTP 339.25 | E5: D4944 | F5: 30 | G5: 60 | L5: SI
B6: SU05 | C6: Corte Directo | D6: NTP 339.171 | E6: D3080 | F6: 350 | G6: 350 | L6: SI
B7: SU06A | C7: Densidad natural, cono de arena 6" | D7: NTP 339.143 | E7: D1556 | F7: 35 | G7: 35 | H7: 35 | I7: 450 | J7: Puede variar de acuerdo cantidad y servicio | L7: SI
B8: SU06B | C8: Densidad natural, cono de arena 12" | D8: NTP 339.143 | E8: D1556 | F8: 80 | G8: 80 | J8: Puede variar de acuerdo cantidad y servicio | L8: SI
B9: SU07 | C9: Valor relativo de soporte CBR | D9: NTP 339.145 | E9: D1883 | F9: 250 | G9: 250 | L9: SI
B10: SU08 | C10: Próctor modificado (OBSOLETO) | D10: NTP 339.141 | E10: D1557 | F10: 120 | G10: 90 | H10: 95 | J10: Puede variar de acuerdo a la prioridad
B11: SU09 | C11: Peso específico relativo de partículas del suelo | D11: NTP 339.131 | E11: D854 | F11: 60 | G11: 50 | L11: SI
B12: SU10 | C12: Análisis granulométrico por tamizado | D12: NTP 339.128 | E12: D422 | F12: 70 | G12: 100 | L12: SI
B13: SU11 | C13: Límite líquido y Limite Plastico | D13: NTP 339.129 | E13: D4318 | F13: 70 | G13: 100 | L13: SI
B14: SU12 | C14: Contenido de humedad (OBSOLETO) | D14: NTP 339.127 | E14: D 2216 | F14: 25 | G14: 25
B15: SU13 | C15: Sales solubles totales | D15: NTP 339.152 | E15: BS 1377 | F15: 70 | G15: 70 | H15: 70 | J15: Puede variar de acuerdo a la prioridad | L15: SI
B16: SU14 | C16: Contenido de cloruros solubles | D16: NTP 339.177 | E16: AASHTO T291 | F16: 90 | G16: 80 | L16: SI
B17: SU15 | C17: Contenido de sulfatos solubles | D17: NTP 339.178 | E17: AASHTO T290 | F17: 100 | G17: 90 | H17: 100 | J17: Puede variar de acuerdo a la prioridad | L17: SI
B18: SU16 | C18: Ensayo de SPT | L18: SI
B19: SU17 | C19: Equivalente de arena (OBSOLETO) | D19: NTP 339.146 | E19: D2419 | F19: 80 | G19: 60
B20: SU18 | C20: Ensayo de Placa de Carga | D20: ASTM D-1194 | F20: 2500 | G20: 2000 | L20: SI
B21: SU19 | C21: Próctor modificado | D21: ASTM D1557 | F21: 120 | G21: 120 | L21: SI
B22: SU20 | C22: Contenido de humedad | D22: ASTM D 2216 | F22: 25 | L22: SI
B23: SU21 | C23: Equivalente de arena | D23: ASTM D2419 | F23: 80 | L23: SI
B24: SU22 | C24: Clasificación suelo SUCS - AASHTO | D24: ASTM D2487 / 3282 | F24: 20 | G24: 30 | L24: SI
B25: SU23 | C25: Límite líquido y Limite Plastico | D25: ASTM D4318 | F25: 70 | L25: SI
B26: SU24 | C26: Análisis granulométrico por tamizado | D26: ASTM D6913 | F26: 70 | L26: SI
B27: SU25 | C27: Clasificación suelo SUCS - AASHTO | D27: NTP 339.134 / 339.135 | F27: 20 | L27: SI
B28: SU26 | C28: Contenido de materia organica | D28: NTP 339.071 | F28: 90
B29: SU27 | C29: Solidos en suspensión | D29: ASTM C1603 | F29: 90
B30: SU28 | C30: Densidad de campo por metodo de reemplazo por agua | D30: ASTM D5030 | F30: - | L30: SI
B31: SU29 | C31: Prueba de Infiltración | D31: ASTM D3385 | F31: - | L31: SI
B32: SU30 | C32: Próctor Estándar | D32: ASTM D698 | F32: 120 | L32: SI
B33: SU31 | C33: Correccion de proctor modificado | D33: ASTM D4718-87 | F33: - | L33: SI
B39: SU21 | C39: CBR insitu | D39: ASTM D-4429 | F39: =2350+1500 -> 3850
B40: ESP01 | C40: Compresión Triaxial UU | D40: ASTM D 2850 | F40: 1400
B41: ESP02
B42: ESP03
B43: ESP04 | C43: COLAPSO | D43: ASTM D 5333 | F43: 500
B44: CA1 | C44: Calicata 1.5mt prof | D44: - | F44: 150
B45: CA2 | C45: Calicata 3mt prof | D45: - | F45: 300
B46: MOV. | C46: Movilidad | D46: - | F46: 60
...

Sheet PRUEBA 1
G3: 222 | P3: ID CLIENTE | Q3: 1210
B5: CLIENTE: | D5: =VLOOKUP($Q$3,BD_Clientes,2,FALSE) -> BATALLA DE JUNIN S.A.C | J5: PROYECTO1: | L5: =VLOOKUP($Q$3,BD_Clientes,9,FALSE) -> Bicentenario | P5: 222
B6: R.U.C.1: | D6: =VLOOKUP($Q$3,BD_Clientes,3,FALSE) -> 20603173156 | P6: 222
B7: CONTACTO: | D7: =VLOOKUP($Q$3,BD_Clientes,5,FALSE) -> Alondra Neira Salas | J7: UBICACIÓN1: | L7: =VLOOKUP($Q$3,BD_Clientes,10,FALSE) -> Av. José Leguía y Meléndez 301, Pueblo Libr | P7: 222
B8: TELÉFONO DE CONTACTO: | E8: =VLOOKUP($Q$3,BD_Clientes,7,FALSE) -> 977504836 | J8: PERSONAL COMERCIAL: | L8: Silvia Peralta
B9: CORREO: | D9: =VLOOKUP($Q$3,BD_Clientes,8,FALSE) -> calidadbatalladejunin@gmail.com | J9: TELÉFONO DE COMERCIAL: | L9: 982429895
B10: FECHA SOLICITUD: | E10: 45970 | J10: FECHA DE EMISIÓN: | L10: 45970
B11: REFERENCIA: Segùn lo solicitado vìa correo electrònico / Whatsapp / Telèfono / Personalmente.
B12: 1: Información no considerada para las personas naturales.
B13: Por medio de la presente, tenemos el agrado de remitirle nuestra cotización en base a su solicitud, por los servicios de los siguientes ensayos de laboratorio.
B16: CÒDIGO | C16: DESCRIPCIÒN | J16: NORMA | K16: ACREDITADO | L16: COSTO UNITARIO | M16: CANTIDAD | N16: COSTO PARCIAL
B17: SU19 | C17: =VLOOKUP(B17,ENS.!$B$5:$H$167,2,FALSE) -> Próctor modificado | J17: =VLOOKUP(B17,ENS.!$B$5:$H$167,3,FALSE) -> ASTM D1557-12 (Reapproved 2021) | K17: =VLOOKUP(B17,ENS.!$B$5:$H$167,4,FALSE) -> SI | L17: =VLOOKUP(B17,ENS.!$B$5:$H$167,7,FALSE) -> 150 | M17: 1 | N17: =+L17*M17 -> 150
B18: SU20 | C18: =VLOOKUP(B18,ENS.!$B$5:$H$167,2,FALSE) -> Contenido de humedad en suelos | J18: =VLOOKUP(B18,ENS.!$B$5:$H$167,3,FALSE) -> ASTM D2216-19 | K18: =VLOOKUP(B18,ENS.!$B$5:$H$167,4,FALSE) -> SI | L18: =VLOOKUP(B18,ENS.!$B$5:$H$167,7,FALSE) -> 30 | M18: 1 | N18: =+L18*M18 -> 30
B19: SU20A | C19: =VLOOKUP(B19,ENS.!$B$5:$H$167,2,FALSE) -> Contenido de humedad en Roca. | J19: =VLOOKUP(B19,ENS.!$B$5:$H$167,3,FALSE) -> ASTM D2216-19 | K19: =VLOOKUP(B19,ENS.!$B$5:$H$167,4,FALSE) -> NO | L19: =VLOOKUP(B19,ENS.!$B$5:$H$167,7,FALSE) -> 30 | M19: 1 | N19: =+L19*M19 -> 30
B20: SU21 | C20: =VLOOKUP(B20,ENS.!$B$5:$H$167,2,FALSE) -> Equivalente de arena | J20: =VLOOKUP(B20,ENS.!$B$5:$H$167,3,FALSE) -> ASTM D2419-22 | K20: =VLOOKUP(B20,ENS.!$B$5:$H$167,4,FALSE) -> SI | L20: =VLOOKUP(B20,ENS.!$B$5:$H$167,7,FALSE) -> 150 | M20: 1 | N20: =+L20*M20 -> 150
B21: SU19 | C21: =VLOOKUP(B21,ENS.!$B$5:$H$167,2,FALSE) -> Próctor modificado | J21: =VLOOKUP(B21,ENS.!$B$5:$H$167,3,FALSE) -> ASTM D1557-12 (Reapproved 2021) | K21: =VLOOKUP(B21,ENS.!$B$5:$H$167,4,FALSE) -> SI | L21: =VLOOKUP(B21,ENS.!$B$5:$H$167,7,FALSE) -> 150 | M21: 1 | N21: =+L21*M21 -> 150
B22: SU20 | C22: =VLOOKUP(B22,ENS.!$B$5:$H$167,2,FALSE) -> Contenido de humedad en suelos | J22: =VLOOKUP(B22,ENS.!$B$5:$H$167,3,FALSE) -> ASTM D2216-19 | K22: =VLOOKUP(B22,ENS.!$B$5:$H$167,4,FALSE) -> SI | L22: =VLOOKUP(B22,ENS.!$B$5:$H$167,7,FALSE) -> 30 | M22: 11 | N22: =+L22*M22 -> 330
B23: SU20A | C23: =VLOOKUP(B23,ENS.!$B$5:$H$167,2,FALSE) -> Contenido de humedad en Roca. | J23: =VLOOKUP(B23,ENS.!$B$5:$H$167,3,FALSE) -> ASTM D2216-19 | K23: =VLOOKUP(B23,ENS.!$B$5:$H$167,4,FALSE) -> NO | L23: =VLOOKUP(B23,ENS.!$B$5:$H$167,7,FALSE) -> 30 | M23: 1 | N23: =+L23*M23 -> 30
B24: SU21 | C24: =VLOOKUP(B24,ENS.!$B$5:$H$167,2,FALSE) -> Equivalente de arena | J24: =VLOOKUP(B24,ENS.!$B$5:$H$167,3,FALSE) -> ASTM D2419-22 | K24: =VLOOKUP(B24,ENS.!$B$5:$H$167,4,FALSE) -> SI | L24: =VLOOKUP(B24,ENS.!$B$5:$H$167,7,FALSE) -> 150 | M24: 1 | N24: =+L24*M24 -> 150
L25: Costo parcial | N25: =SUM(N17:N24) -> 1020
L26: IGV 18% | N26: =+N25*0.18 -> 183.6
L27: Costo Total (S/) | N27: =+N25+N26 -> 1203.6
B29: VALIDEZ DE LA OFERTA: 30 días calendario. Si la cotización llegó al límite de su validez, solicite una actualización.
B30: CONDICIONES ESPECÍFICAS PARA LOS ENSAYOS DE LABORATORIO: - El cliente deberá de entregar las muestras debidamente identificadas. - El cliente deberá especificar la Norma a ser utilizada para la ejecución del ensayo, caso contrario el laboratorio considera la Norma ASTM y/o NTP vigente de acuerdo con su alcance. - El cliente deberá entregar las muestras en las instalaciones del Laboratorio de Ensayos de Materiales, ubicado en la Av. Rio Marañon N° 763, Los Olivos, Perú
B31: PLAZO ESTIMADO DE EJECUCIÓN DE SERVICIO: - El plazo de entrega de los resultados se estima en 10 días hábiles, este tiempo será evaluado de acuerdo a la cantidad de muestra recepcionada y está sujeto a la programacion enviada por el Laboratorio de Ensayos de Materiales. - El laboratorio enviará un correo de confirmación de recepción y fecha de entrega del informe.
B33: COM-F-01 Página 1 de 2 Versión: 04 (10-11-2025)
B34: CONTRAMUESTRA Al finalizar los ensayos, la muestra sobrante/contramuestra permanecerán en custodia por un tiempo de 10 dias calendario después de emitido el informe de ensayo. Siempre que se trate de una muestra dirimente, las contramuestras serán devueltas a los clientes, previa coordinación y autorización, caso contrario, serán eliminadas si se trata de residuos del ensayo o contramuestras de ensayo.
B35: CONFIDENCIALIDAD: GEOFAL S.A.C mantiene acuerdos de confidencialidad entre el cliente y el laboratorio, la divulgación de la información sin la autorización de las partes, no es permitida. El laboratorio mantiene reserva de la información brindada por el cliente, salvo solicitud de la información por ley, o por entidades gubernamentales inmersos dentro del presente servicio de ensayo.
B36: QUEJAS Y SUGERENCIAS: El plazo máximo para la recepción de quejas relacionadas con un informe técnico es de diez (10) días calendarios, contados a partir de la fecha de emisión del documento correspondiente. Transcurrido dicho plazo, no se aceptarán quejas bajo ninguna circunstancia. En caso de tener alguna queja o sugerencia, lo invitamos a conocer nuestro Proceso de Atención de Quejas, el cual dará inicio 24 horas después de la recepción formal de la queja.
B37: ENTREGA DE INFORME DE ENSAYO: - De acuerdo a los lineamientos de INACAL - DM, los informes de ensayo son emitidos de forma digital con firma electrónica y QR. - La entrega de los informes de ensayo será mediante la plataforma de Intranet de la pagina web www.geofal.com.pe, y se enviará un correo de confirmación al cliente con el usuario y clave para el acceso. Asi mismo el cliente puede ingresar a la gruía deusuario que es visible en la página web. - Geofal no declara conformidad de sus informes de ensayo. - En caso se requiera la modificación del informe de ensayo a consecuencia de los datos proporcionados por el cliente, esta se realizará mediante la emisión de un nuevo informe que tendrá un costo adicional de acuerdo a evaluación.
B38: HORARIO DE ATENCIÓN El horario para recepción de muestra y entrega de informes es de Lunes a Viernes de 8:30am a 1:00pm y 2:00pm a 5:30pm, y Sábado de 8:30am a 12:30pm
B41: CONDICIÓN: | P41: CONDICIONES DE PAGO
B42: RAZON SOCIAL: Geofal S.A.C. RUC: 20549356762 | P42: CONDICIÓN: El pago del servicio se realizara de acuerdo a la valorización mensual
B43: Sírvase realizar el depósito correspondiente de los servicios a nuestra cuenta bancaria: | P43: CONDICIÓN: El pago del servicio deberá ser realizado por Adelantado.
B44: Cuenta de detraccion Banco de La Nación: | P44: CONDICIÓN: El pago del servicio Adelanto el 50% y saldo previo a la entrega del Informe.
B45: - Cuenta de detraccion Banco de La Nación: Nº 00-074-045472 | P45: CONDICIÓN: El pago del servicio Crédito a 7 días, previa orden de servicio.
B46: Cuenta corriente Interbank: | P46: CONDICIÓN: El pago del servicio Crédito a 30 días, previa orden de servicio.
B47: - Cuenta Corriente en Soles de Interbank: Nº 200-3005201096 | P47: CONDICIÓN: El pago del servicio Crédito a 15 días, previa orden de servicio.
B48: - Código Interbancario (CCI) de Interbank: Nº 003-200- 003005201096-31
B49: Cuenta corriente BCP:
...

Sheet CLI.
B2: LISTA DE CLIENTES GEOFAL
B4: ID CLIENTE | C4: CLIENTE | D4: RUC | E4: DIRECCION | F4: CONTACTO | G4: CARGO | H4: TELÉFONO | I4: CORREO | J4: PROYECTO | K4: UBICACIÓN | L4: SERVICIO
B5: 1 | C5: CONSTRUCTORA GALLO SEMINARIO SA | D5: 20268387031 | E5: JR. JUAN DE DIOS BEDOYA S. NRO. 1150 URB. LOS CIPRECES | F5: Roberto Carlos Chiuyari Cusi | G5: - | H5: 936789506 | I5: robertochiuyari@gmail.com | L5: ENSAYO DE LABORATORIO
B6: 2 | C6: CONKRETO INGENIERÍA Y CONSTRUCCIÓN SAC | D6: 20600118197 | E6: CAL.FUENTES MANUEL ATANASIO NRO. 977 URB. CHACARILLA DE SANTA CRUZ | F6: Fresia Guerra | G6: - | H6: - | I6: fresia.guerra@conkreto.net | L6: ENSAYO DE LABORATORIO
B7: 3 | C7: CONSTRUCTURA Y SERVICIOS GENERALES KALLPA SAC | D7: 20515734636 | E7: AV. JOSE PARDO NRO. 434 INT. 1302 , MIRAFLORES | F7: Carlos Murriel | G7: - | H7: 920363423 | I7: c.murriel@inkall.com.pe | L7: ENSAYO DE LABORATORIO
B8: 4 | C8: CJ TELECOM SAC | D8: 20505958111 | E8: CAL.SANTA JUSTINA NRO. 620 URB. PANDO III ETAPA LIMA | F8: Belmarys Rondon | G8: COORDINADOR DE INGENIERÍA | H8: 967765603 | I8: brondon@cj-telecom.com | J8: - | K8: - | L8: ENSAYO DE LABORATORIO
B9: 5 | C9: AZ INVERSIONES INMOBILIARIAS SAC | D9: 20516862506 | E9: AV. JOSE PARDO NRO. 434 INT. 1302 URB. SURQUILLO | F9: Rolando Canta | G9: LOGISTICA | H9: 983510023 | I9: r.canta@inhouse.com.pe | J9: TOP 818 | K9: AV PRINCIPAL 818, SURQUILLO | L9: ENSAYO DE LABORATORIO
B10: 6 | C10: MIRANDA ROQUE | E10: - | F10: Alan Miranda Roque | G10: - | I10: amiranda@mirandaroque.com | L10: ENSAYO DE LABORATORIO
B11: 7 | C11: AZ INVERSIONES INMOBILIARIAS SAC | D11: 20516862506 | E11: AV. JOSE PARDO NRO. 434 INT. 1302 URB. SURQUILLO | F11: Alan Incio | G11: - | H11: 960852630 | I11: a.incio@inhouse.com.pe | J11: - | K11: - | L11: ENSAYO DE LABORATORIO
B12: 8 | C12: AZ INVERSIONES INMOBILIARIAS SAC | D12: 20516862506 | E12: AV. JOSE PARDO NRO. 434 INT. 1302 URB. SURQUILLO | F12: Hernan Tuppia | G12: - | H12: 920363418 | I12: h.tuppia@inhouse.com.pe / htuppia7@gmail.com | J12: EDIFICIO MULTIFAMILIAR TREVITA | K12: JR.MORRO SOLAR N° 336 - SURCO | L12: ENSAYO DE LABORATORIO
B13: 9 | C13: JG3 CONSTRUCCIONES S.A.C | D13: 20505212739 | E13: JR. LOS ALAMOS NRO. 409 URB. EL OLIVAR - CALLAO | F13: Gilmer Garay | G13: - | H13: 968 800 818 | I13: ggaray@jg3construcciones.com | J13: - | K13: - | L13: ENSAYO DE LABORATORIO
B14: 10 | C14: PENTATECH INGENIERIA Y CONSTRUCCION | D14: 20553327971 | E14: CAL.8 DE OCTUBRE NRO. 271 DPTO. 302 URB. SANTA CRUZ - MIRAFLORES | F14: Josselyn Cobeñas Vela | G14: LOGISTICA | H14: 929684224 | I14: logistica2@pentatechasac.com | L14: ENSAYO DE LABORATORIO
B15: 11 | C15: MARIO DANIEL CUBAS ROMERO | D15: - | E15: - | F15: Mario Daniel Cubas Romero | G15: - | H15: 999566333 | I15: mariocubas80@gmail.com | L15: ENSAYO DE LABORATORIO
B16: 12 | C16: CORPORACION IVEDO SAC | D16: 20600836031 | E16: AV. AVIACION NRO. 0412 CAS. CUILLAS | F16: Rocio Mendoza L. | G16: - | H16: 987154818 | I16: rocio.mendoza@ivedosac.com | L16: ENSAYO DE LABORATORIO
B17: 13 | C17: TAC GERENCIA Y CONSTRUCCIONES SAC | D17: 20601237840 | E17: CAL.5 MZA. J LOTE. 22 URB. LOS PINOS LIMA - LIMA - PUENTE PIEDRA | F17: Cristina Tasayco | G17: - | H17: 993688546 | I17: cristina.tasayco@tacgyc.com | L17: ENSAYO DE LABORATORIO
B18: 14 | C18: TREYAL SAC | D18: 20605254331 | E18: ZONA Z HUAYCAN MZA. G LOTE. 1 ASC. DE PRODUCTORES LOS JARDINES DE VILLA - ATE | F18: Elmer Condezo | G18: - | I18: eacondezo@gmail.com | L18: ENSAYO DE LABORATORIO
B19: 15 | C19: B & P DISEÑO E INGENIERIA DEL ACERO SAC | D19: 20523767934 | E19: MZA. D LOTE. 1 ASC. EL MANANTIAL - SAN MARTIN DE PORRES | F19: Liset Maza | G19: - | H19: 4014245 | I19: lmaza@byp-ingenieria.com.pe | L19: ENSAYO DE LABORATORIO
B20: 16 | C20: MINERA LAYTARUMA S.A. | D20: 20125959483 | E20: JR. TIZIANO NRO. 301 URB. SAN BORJA | F20: Marlon Cabanillas | G20: - | H20: 968370132 | I20: marlon.cabanillas@laytaruma.com.pe | L20: ENSAYO DE LABORATORIO
B21: 17 | C21: OC&T | E21: - | F21: Candy Romero Yacolca | G21: - | H21: 934709610 | I21: cromero@ocyt.com.pe | L21: ENSAYO DE LABORATORIO
B22: 18 | C22: CONSTRUCTORA Y MULTISERVICIOS ASHMARK SAC | D22: 20545508398 | E22: JR. RIO CHICAMA NRO. 5637 URB. VILLA NORTE - LOS OLIVOS | F22: Melchor Sanchez | G22: - | H22: 987089525 | I22: melchorsanchez1970@hotmail.com | L22: ENSAYO DE LABORATORIO
B23: 19 | C23: GARI BERRIO | E23: - | F23: Gari Berrio | G23: - | H23: 993184846 | I23: gariberrio@yahoo.es | L23: ENSAYO DE LABORATORIO
B24: 20 | C24: 3X3 INGENIERIA DE LA CONSTRUCCIÓN Y SERVICIOS GENERALES SAC | D24: 20549297570 | E24: AV. JOSE GRANDA NRO. 2412 URB. CONDEVILLA SEÑOR Y VALDIVIESO - SMP | F24: Aristdes Ocmin Paredes | G24: - | H24: 917693170 | I24: aopselva@hotmail.com | L24: ENSAYO DE LABORATORIO
B25: 21 | C25: INVERSIONES INMOBILIARIAS DEL INDICO S.A. | D25: 20514048071 | E25: AV. DEL PINAR NRO. 134 INT. 301 URB. CHACARILLA DEL ESTANQUE - SURCO | F25: Alvaro Morales | G25: - | H25: 963 313 844 | I25: amorales@imagina.com.pe | L25: ENSAYO DE LABORATORIO
B26: 22 | C26: IFIT PERU | D26: 20516233801 | E26: JR. LIMA NRO. 757 LA PERLA, PROV. CONST. DEL CALLAO - CALLAO | F26: Jorge Luis Cabanillas Carpio | G26: - | H26: 978436300 | I26: jcabanillas@ifitperu.net | J26: AMERICAN TOWER PERU S.A | K26: LIMA / PIURA | L26: ENSAYO DE LABORATORIO
B27: 23 | C27: JHONATAN MARCA MEDINA | E27: - | F27: Jhonatan Marca Medina | G27: - | H27: 910529876 | I27: jmarcam@uni.pe | L27: ENSAYO DE LABORATORIO
B28: 24 | C28: C&SG VIRGEN DE GUADALUPE SAC | D28: 20605411372 | E28: - | F28: Juan Jobiniano Medina Arista | G28: - | H28: 938331539 | I28: csg.v.guadalupe.sac@gmail.com | L28: ENSAYO DE LABORATORIO
B29: 25 | C29: JME INGENIERÍA ESTRUCTURAL Y TECNOLOGÍA DE MATERIALES EIRL | D29: 20537919991 | E29: AV. UNIVERSITARIA NORTE NRO. 2713 A.V. SAN JUAN DE DIOS ETP 1 - SMP | F29: Madevelia Valladares Cabello | G29: - | H29: 998845609 | I29: administracion@jme.pe | J29: - | K29: - | L29: ENSAYO DE LABORATORIO
B30: 26 | C30: SANTANDER CONSULTORES Y CONTRATISTAS EIRL | E30: - | F30: Lizeth Chirinos | G30: - | H30: 958345595 | I30: lizett.chirinos@santandercyc.com / lizett.chirinos@gmail.com | L30: ENSAYO DE LABORATORIO
B31: 27 | C31: TECSUR S.A | D31: 20206018411 | E31: PJ. CALANGO NRO. 158 (ALT.CDRA.3 Y 4 AV.P.MIOTTA) - SAN JUAN DE MIRAFLORES | F31: Mishely Castro | G31: DEPARTAMENTO DE COMPRAS | H31: 926687304 | I31: mcastro@tecsur.com.pe | J31: LT60KV PACHACUTEC VES | K31: Av. Los Alamos, Av. Modelo, VES | L31: ENSAYO DE LABORATORIO
B32: 28 | C32: VECTOR CONTRATISTAS GENERALES SAC | D32: 20569090289 | E32: - | G32: - | H32: 917424689 | I32: vectorcgsac@gmail.com | L32: ENSAYO DE LABORATORIO
B33: 29 | C33: CONSTRUCTORA Y CONSULTORIA REMAR SAC | D33: 20601489521 | E33: - | F33: Katiuska | G33: - | H33: 940475009 | I33: katiuscavt@gmail.com | L33: ENSAYO DE LABORATORIO
B34: 30 | C34: PLAYDE S.A.C. | D34: 20541103831 | E34: AV. PROLONGACION JAVIER PRADO MZA. J1 LOTE. 29 INT. B URB. LOS PORTALES - ATE | F34: Miklail Rivera | G34: - | I34: mrivera@playde.pe | L34: ENSAYO DE LABORATORIO
B35: 31 | C35: MJR CONSTRUCCIONES S.A.C. | D35: 20562660896 | E35: CAL.SANDINO MZA. E LOTE. 5, CRUCE DE LAS AV. HUANDOY Y RIO MARAÑON - LOS OLIVOS | F35: Cristian Bobadilla | G35: - | H35: 963338932 | I35: cristiam1925@gmail.com | J35: - | K35: - | L35: ENSAYO DE LABORATORIO
B36: 32 | C36: VIRGEN DE GUADALUPE SAC | D36: 20605411372 | E36: - | F36: Honey Medina Ortiz | G36: - | H36: 937473122 | I36: honeymedinaortiz@gmail.com | L36: ENSAYO DE LABORATORIO
B37: 33 | C37: TELECOM A.V. S.A.C. | D37: 20601508878 | E37: JR. REJALGAR N°1394 DPTO. 401, LOS OLIVOS | F37: Magaly Vela Portocarrero | G37: - | H37: 985998448 | I37: proyectos@telecomav.com.pe | L37: ENSAYO DE LABORATORIO
B38: 34 | C38: CONSORICO JOTAME SAC | D38: 20548536457 | E38: - | F38: Jose Tafur Melendez | G38: - | H38: 963986864 | I38: jotame20@hotmail.com | L38: ENSAYO DE LABORATORIO
B39: 35 | C39: TECSUR S.A | D39: 20206018411 | E39: PJ. CALANGO NRO. 158 (ALT.CDRA.3 Y 4 AV.P.MIOTTA) - SAN JUAN DE MIRAFLORES | F39: Mishely Castro | G39: - | H39: 926687304 | I39: mcastro@tecsur.com.pe | L39: ENSAYO DE LABORATORIO
B40: 36 | C40: CJ CONTRATISTAS ASOCIADOS SAC | D40: 20510303386 | E40: MZA. C LOTE. 16 ASOC VIV JUAN CARLOS NOR - SAN MARTIN DE PORRES | F40: Noris Lucia Aquino Urruchi | G40: - | H40: 968201908 | I40: naquino@cj.com.pe | J40: - | K40: - | L40: ENSAYO DE LABORATORIO
B41: 37 | C41: JUAN VILCHEZ | D41: - | E41: - | F41: Juan Vilchez | G41: - | H41: 986658220 | I41: jvilchez94@hotmail.com | L41: ENSAYO DE LABORATORIO
B42: 38 | C42: TECSUR S.A | D42: 20206018411 | E42: PJ. CALANGO NRO. 158 (ALT.CDRA.3 Y 4 AV.P.MIOTTA) - SAN JUAN DE MIRAFLORES | F42: Nicolas Mendoza Cavero | G42: - | H42: 960641783 | I42: nmendoza@tecsur.com.pe | L42: ENSAYO DE LABORATORIO
...

Sheet ENS.
B2: LISTA DE PRECIOS ENSAYOS DE LABORATORIO
B4: CÓDIGO | C4: DESCRIPCION | D4: NORMA | E4: ACREDITADO | F4: REFERENCIA OTRA NORMA | G4: UBICACIÓN | H4: PRECIO | I4: TIEMPO | J4: COMENTARIOS
C5: ENSAYO ESTÁNDAR SUELO
B6: SU04 | C6: Contenido de humedad con Speedy. | D6: NTP 339.25 | E6: NO | F6: D4944 | G6: LABORATORIO | H6: 30 | I6: 15 minutos
B7: SU19 | C7: Próctor modificado | D7: ASTM D1557-12 (Reapproved 2021) | E7: SI | F7: - | G7: LABORATORIO | H7: 150 | I7: 2 dias | J7: Para realizar el ensayo de proctor se requiere tambien realizar: granulometria SU24 y/o AG19/ peso especifico grueso AG28 / peso relativo del solido SU32 / correccion por grava SU31
B8: SU20 | C8: Contenido de humedad en suelos | D8: ASTM D2216-19 | E8: SI | F8: - | G8: LABORATORIO | H8: 30 | I8: 2 dias
B9: SU20A | C9: Contenido de humedad en Roca. | D9: ASTM D2216-19 | E9: NO | F9: - | G9: LABORATORIO | H9: 30 | I9: 2 dias | J9: No estamos acreditados en este alcance
B10: SU21 | C10: Equivalente de arena | D10: ASTM D2419-22 | E10: SI | F10: - | G10: LABORATORIO | H10: 150 | I10: 3 dias
B11: SU22 | C11: Clasificación suelo SUCS - AASHTO | D11: ASTM D2487-17 (Reapproved 2025) / ASTM D3282-24 | E11: SI | F11: - | G11: LABORATORIO | H11: 20 | I11: 3 dias | J11: Para el ensayo se requiere de granulometria SU24 y/o AG28 y limites SU23
B12: SU23 | C12: Límite líquido y Límite Plástico del Suelo | D12: ASTM D4318-17ε1 | E12: SI | F12: - | G12: LABORATORIO | H12: 90 | I12: 3 dias
B13: SU24 | C13: Análisis granulométrico por tamizado en Suelo | D13: ASTM D6913/D6913M-17 | E13: SI | F13: - | G13: LABORATORIO | H13: 100 | I13: 3 dias
B14: SU30 | C14: Ensayo de Compactación Próctor Estándar. | D14: ASTM D698 | E14: NO | F14: - | G14: LABORATORIO | H14: 150 | I14: 3 dias
B15: SU31 | C15: Corrección de Peso Unitario para Partícula de gran tamaño. | D15: ASTM D4718-87 | E15: NO | F15: - | G15: LABORATORIO | H15: 20 | I15: 3 dias
B16: SU32 | C16: Gravedad específica de los sólidos del suelo. | D16: ASTM D854-14 | E16: NO | F16: - | G16: LABORATORIO | H16: 120 | I16: 3 dias | J16: Si La Muestra Tiene Grava Se Tendria Que Hacer Tambien El Ensayo De Peso Especifico Del Grueso
B17: SU34 | C17: Densidad y peso unitario de muestra suelo | D17: ASTM D 7263 | E17: NO | F17: - | H17: 70 | I17: 3 dias | J17: Esto se repite en roca, xq para contrrol de calidad en roca el cliente solicito el ensayo
B18: SU35 | C18: Densidad del peso unitario máximo del suelo. | D18: NTP 339.137 | E18: NO | F18: - | G18: LABORATORIO | H18: 350 | I18: 3 dias
B19: SU36 | C19: Densidad del peso unitario mínimo del suelo. | D19: NTP 339.138 | E19: NO | F19: - | G19: LABORATORIO | H19: 150 | I19: 3 dias
B20: SU38 | C20: Determinación de sólidos totales suspendidos. | D20: NTP 214.039 | E20: NO | F20: - | G20: LABORATORIO | H20: 150 | I20: 3 dias
B21: SU39 | C21: Análisis granulométrico por hidrómetro (incl. Granulometría por tamizado). | D21: NTP 339.128 1999 (revisada el 2019) | E21: NO | F21: - | G21: LABORATORIO | H21: 350 | I21: 4 dias
C22: ENSAYOS ESPECIALES SUELO
B23: SU05 | C23: Corte Directo. | D23: NTP 339.171 | E23: NO | F23: D3080 | G23: LABORATORIO | H23: 350 | I23: 3 dias | J23: Solicitar al cliente la densidad del suelo. Si el cliente no tiene la densidad, se cotiza tambien el ensayo de proctor con ello hallaremos la densidad del suelo y lo remoldearemos al 95% Maxima densidad seca
B24: SU33 | C24: Resistencia a la Compresión no confinada de suelos cohesivos | D24: NTP 339.167 | E24: NO | F24: ASTM D2166 | G24: LABORATORIO | H24: 250 | I24: 3 dias
B25: SU37 | C25: California Bearing Ratio (CBR) | D25: ASTM D1883-21 | E25: SI | F25: NTP 339.145 | G25: LABORATORIO | H25: 300 | I25: 7 dias
B26: SU38 | C26: CBR INSITU | E26: NO | I26: 1/2 dia
B27: SU40 | C27: Hinchamiento suelo | D27: ASTM D4546-21 | E27: NO | I27: 3 dias
B28: SU41 | C28: Potencial de Colapso en suelo. | D28: ASTM D5333 | E28: NO | F28: - | G28: LABORATORIO | H28: 370 | I28: 3 dias | J28: El Costo De Clasificacion En La Uni 210
B29: SU42 | C29: Conductividad hidráulica en pared rígida (Permeabilidad). | D29: ASTM D2434 | E29: NO | F29: - | G29: LABORATORIO | H29: 530 | I29: 2 dias | J29: Para el ensayo se requiere realizar previo el ensayo de granulometria, limites, clasificación sucs, peso relativo del solido, peso especifico del grueso (solo si tiene grava), adicional ensayo de pasane de la malla 200 menor al 12%.
B30: SU43 | C30: Conductividad hidráulica en pared flexible (Permeabilidad). | D30: ASTM D5084 | E30: NO | F30: - | G30: LABORATORIO | H30: =560+80 -> 640 | I30: 2 dias | J30: Para el ensayo se requiere realizar previo el ensayo de granulometria, limites y clasificación sucs, peso relativo del solido, peso especifico del grueso (solo si tiene grava). Cantidad de muestra: 60 kilos, Tiempo de entrega: 05 días
B31: SU44 | C31: Conductividad térmica / Resistividad térmica | D31: ASTM D5334-14 | E31: NO | F31: - | G31: LABORATORIO | H31: 1500 | I31: 3 dias | J31: Se requiere de ensayos de granulometria, límites y clasificación.
B32: SU45 | C32: Compresión triaxial no consolidado no drenado UU, diametro 75 mm | D32: ASTM D2850 | E32: NO | F32: - | G32: LABORATORIO | H32: 1500 | I32: 3 dias | J32: UU: cuando halla licuacion de suelo (densidad baja, arena fina sin mucho contenido en la malla 200, que no tenga limites, nivel freatico), otro suelo arena muy sueltas cuando se excaven se hace un embudo, arcillas blandas (solo fino, densidades bajas), en conclusion suelos criticos, TIEMPO 1.1/2 DIAS EN ARENA Y ARCILLA
B33: SU46 | C33: Compresión triaxial consolidado no drenado CU, diametro 75 mm | D33: ASTM D4767 | E33: NO | F33: - | G33: LABORATORIO | H33: 2000 | I33: 3 dias | J33: CU: Se realizara cuando el agua nunca se pueda drenar, ejemplo orilla del mar, donde hay nivel freatico, ems para puente, etc. TIEMPO 3 DIAS ARENA Y 4 DIAS ARCILLA
B34: SU47 | C34: Compresión triaxial consolidado drenado CD, diametro 75 mm | D34: ASTM D7181 | E34: NO | F34: - | G34: LABORATORIO | H34: Sujeto a evaluación | I34: 3 dias | J34: CD: Se realiza donde no hay nivel freatico, porque el suelo drena el agua, ejemplo se rompio una tuberia el suelo se inunda esto en un determinado tiempo drenara el agua. TIEMPO 6 DIAS EN ARENA Y ARCILLA
B35: EE01 | C35: Consolidación unidimensional. | D35: ASTM D2435 | E35: NO | F35: - | G35: LABORATORIO | H35: 800 | I35: 7 dias
B36: EE02 | C36: Expansión libre. | D36: ASTM D4546 | E36: NO | F36: - | G36: LABORATORIO | H36: 350 | I36: 3 dias
B37: EE03 | C37: Expansión controlada Método A. | D37: ASTM D4546 | E37: NO | F37: - | G37: LABORATORIO | H37: 670 | I37: 3 dias
C38: ENSAYO QUÍMICO SUELO Y AGUA SUBTERRÁNEO
B39: SU03 | C39: Determinación del PH en Suelo y Agua. | D39: NTP 339.176 | E39: NO | F39: D4972 | G39: LABORATORIO | H39: 70 | I39: 3 dias
B40: SU13 | C40: Sales solubles en Suelos y Agua. | D40: NTP 339.152 | E40: NO | F40: BS 1377 | G40: CAMPO | H40: 80 | I40: 3 dias | J40: Puede variar de acuerdo a la prioridad
B41: SU14 | C41: Cloruros Solubles en Suelos y Agua. | D41: NTP 339.177 | E41: NO | F41: AASHTO T291 | G41: LABORATORIO | H41: 80 | I41: 3 dias
B42: SU15 | C42: Sulfatos Solubles en Suelos y Agua. | D42: NTP 339.178 | E42: NO | F42: AASHTO T290 | G42: LABORATORIO | H42: 120 | I42: 3 dias | J42: Puede variar de acuerdo a la prioridad
...

Sheet COND.
B2: CONDICIONES ESPECIFICAS PARA COTIZACION
B4: MUESTRA DE SUELO Y/O AGREGADO
B5: CONDICIONES ESPECÍFICAS - El cliente proporcionara al laboratorio para realizar el ensayo de suelo y/o agregados la cantidad mínima de 100 kg por cada muestra. - El cliente deberá de entregar las muestras debidamente identificadas. - El cliente deberá especificar la Norma a ser utilizada para la ejecución del ensayo, caso contrario se considera Norma ASTM o NTP vigente de acuerdo con el alcance del laboratorio. - El cliente deberá entregar las muestras en las instalaciones del LEM, ubicado en la Av. Marañón N° 763, Los Olivos, Lima.
B8: MUESTRA AGREGADO PARA DISEÑO MEZCLA
B9: CONDICIONES ESPECÍFICAS - El cliente proporcionara al laboratorio para realizar el diseño de mezcla de concreto la cantidad mínima de 70 kg de agregado grueso, 50 kg de agregado fino, 01 bolsa de cemento y 1 litro aditivo. - El cliente deberá entregar las muestras debidamente identificadas. - El cliente deberá especificar la Norma a ser utilizada para la ejecución del ensayo, caso contrario se considera Norma ASTM o NTP vigente de acuerdo con el alcance del laboratorio. - El cliente deberá entregar las muestras en las instalaciones del LEM, ubicado en la Av. Marañón N° 763, Los Olivos, Lima.
B12: PROBETAS
B13: CONDICIONES ESPECÍFICAS - La emisión de informes de ensayo con acreditación INACAL se realizará solo si la fuerza de falla de la probeta está dentro del rango de 50 kN a 800 kN. - El cliente deberá de entregar las muestras debidamente identificadas. - El cliente deberá especificar la Norma a ser utilizada para la ejecución del ensayo, caso contrario se considera Norma ASTM o NTP vigente de acuerdo con el alcance del laboratorio. - El cliente deberá entregar las muestras en las instalaciones del LEM, ubicado en la Av. Marañón N° 763, Los Olivos, Lima.
B15: DENSIDAD DE CAMPO POR PUNTO
B16: CONDICIONES ESPECÍFICAS - Para programar el ensayo de densidad de campo, la cantidad mínima de puntos por salida es de cuatro (4). - El cliente deberá de programar el servicio, Densidad de campo, con 24 horas de anticipación. - El cliente deberá especificar la Norma a ser utilizada para la ejecución del ensayo, caso contrario se considera Norma ASTM o NTP vigente de acuerdo con el alcance del laboratorio.
B18: DENSIDAD DE CAMPO POR DIA
B19: CONDICIONES ESPECÍFICAS - El servicio de Densidad en campo es por 01 día. - El cliente deberá de programar el servicio, con 24 horas de anticipación. - El servicio de movilización de personal y equipo (Densidad de campo), incluye ida y vuelta. - La movilización del personal técnico y de los equipos dentro del proyecto estarán a cargo del cliente. - El informe de ensayo de densidad de campo serán emitidos por Geofal y estará firmado por un ingeniero civil colegiado. - Los equipos de protección personal (EPP) y SCTR estará a cargo de Geofal. - El horario para los ensayos es de lunes a viernes de 9:00 am a 4:00 pm. - El cliente deberá especificar la Norma a ser utilizada para la ejecución del ensayo, caso contrario se considera Norma ASTM o NTP vigente de acuerdo con el alcance del laboratorio.
B21: DENSIDAD DE CAMPO Y RECOJO MUESTRA (AFIRMADO Y OTROS)
... B42: PLAZO ESTIMADO DE EJECUCIÓN DE SERVICIO - El plazo de entrega de los resultados se estima 08 dias hábiles, este tiempo será evaluado de acuerdo a la cantidad de muestra recepcionada y está sujeto a la programacion enviada por el área de LEM. - El laboratorio enviará un correo de confirmación de recepción y fecha de entrega del informe.

Sheet ING
G3: 41 | P3: ID CLIENTE | Q3: 560
B5: CLIENTE: | D5: =VLOOKUP($Q$3,BD_Clientes,2,FALSE) -> GEOFAL SAC | J5: PROYECTO1: | L5: URB. EL BOSQUE DE LA VICTORIA | P5: 222
B6: R.U.C.1: | D6: =VLOOKUP($Q$3,BD_Clientes,3,FALSE) -> 20549356762 | P6: 222
B7: CONTACTO: | D7: Angela Rosalia Paredes Curi | J7: UBICACIÓN1: | L7: - | P7: 222
B8: TELÉFONO DE CONTACTO: | E8: 913072224 | J8: PERSONAL COMERCIAL: | L8: Silvia Peralta
B9: CORREO: | D9: =VLOOKUP($Q$3,BD_Clientes,8,FALSE) -> ingenieria@geofal.com.pe | J9: TELÉFONO DE COMERCIAL: | L9: 982429895
B10: FECHA SOLICITUD: | E10: 46031 | J10: FECHA DE EMISIÓN: | L10: 46031
B11: REFERENCIA: Segùn lo solicitado vía correo electrónico / Whatsapp / Teléfono / Personalmente.
B12: 1: Información no considerada para las personas naturales.
B13: Por medio de la presente, tenemos el agrado de remitirle nuestra cotización en base a su solicitud, por los servicios de los siguientes ensayos de laboratorio.
B16: CÓDIGO | C16: DESCRIPCIÓN | J16: NORMA | K16: ACREDITADO | L16: COSTO UNITARIO | M16: CANTIDAD | N16: COSTO PARCIAL
C17: ENSAYOS DE LABORATORIO | L17: 900 | M17: 1 | N17: 900
B18: SU24 | C18: =VLOOKUP(B18,ENS.!$B$5:$H$167,2,FALSE) -> Análisis granulométrico por tamizado en Suelo | J18: =VLOOKUP(B18,ENS.!$B$5:$H$167,3,FALSE) -> ASTM D6913/D6913M-17 | K18: =VLOOKUP(B18,ENS.!$B$5:$H$167,4,FALSE) -> SI | M18: 1
B19: SU23 | C19: =VLOOKUP(B19,ENS.!$B$5:$H$167,2,FALSE) -> Límite líquido y Límite Plástico del Suelo | J19: =VLOOKUP(B19,ENS.!$B$5:$H$167,3,FALSE) -> ASTM D4318-17ε1 | K19: =VLOOKUP(B19,ENS.!$B$5:$H$167,4,FALSE) -> SI | M19: 1
B20: SU20 | C20: =VLOOKUP(B20,ENS.!$B$5:$H$167,2,FALSE) -> Contenido de humedad en suelos | J20: =VLOOKUP(B20,ENS.!$B$5:$H$167,3,FALSE) -> ASTM D2216-19 | K20: =VLOOKUP(B20,ENS.!$B$5:$H$167,4,FALSE) -> SI | M20: 1
B21: SU22 | C21: =VLOOKUP(B21,ENS.!$B$5:$H$167,2,FALSE) -> Clasificación suelo SUCS - AASHTO | J21: =VLOOKUP(B21,ENS.!$B$5:$H$167,3,FALSE) -> ASTM D2487-17 (Reapproved 2025) / ASTM D3282-24 | K21: =VLOOKUP(B21,ENS.!$B$5:$H$167,4,FALSE) -> SI | M21: 1
B22: SU13 | C22: =VLOOKUP(B22,ENS.!$B$5:$H$167,2,FALSE) -> Sales solubles en Suelos y Agua. | J22: =VLOOKUP(B22,ENS.!$B$5:$H$167,3,FALSE) -> NTP 339.152 | K22: =VLOOKUP(B22,ENS.!$B$5:$H$167,4,FALSE) -> NO | M22: 1
B23: SU14 | C23: =VLOOKUP(B23,ENS.!$B$5:$H$167,2,FALSE) -> Cloruros Solubles en Suelos y Agua. | J23: =VLOOKUP(B23,ENS.!$B$5:$H$167,3,FALSE) -> NTP 339.177 | K23: =VLOOKUP(B23,ENS.!$B$5:$H$167,4,FALSE) -> NO | M23: 1
B24: SU15 | C24: =VLOOKUP(B24,ENS.!$B$5:$H$167,2,FALSE) -> Sulfatos Solubles en Suelos y Agua. | J24: =VLOOKUP(B24,ENS.!$B$5:$H$167,3,FALSE) -> NTP 339.178 | K24: =VLOOKUP(B24,ENS.!$B$5:$H$167,4,FALSE) -> NO | M24: 1
B25: SU03 | C25: =VLOOKUP(B25,ENS.!$B$5:$H$167,2,FALSE) -> Determinación del PH en Suelo y Agua. | J25: =VLOOKUP(B25,ENS.!$B$5:$H$167,3,FALSE) -> NTP 339.176 | K25: =VLOOKUP(B25,ENS.!$B$5:$H$167,4,FALSE) -> NO | M25: 1
B26: SU05 | C26: =VLOOKUP(B26,ENS.!$B$5:$H$167,2,FALSE) -> Corte Directo. | J26: =VLOOKUP(B26,ENS.!$B$5:$H$167,3,FALSE) -> NTP 339.171 | K26: =VLOOKUP(B26,ENS.!$B$5:$H$167,4,FALSE) -> NO | M26: 1
B27: SU33 | C27: =VLOOKUP(B27,ENS.!$B$5:$H$167,2,FALSE) -> Resistencia a la Compresión no confinada de suelos cohesivos | J27: =VLOOKUP(B27,ENS.!$B$5:$H$167,3,FALSE) -> NTP 339.167 | K27: =VLOOKUP(B27,ENS.!$B$5:$H$167,4,FALSE) -> NO
B28: SU06A | C28: =VLOOKUP(B28,ENS.!$B$5:$H$167,2,FALSE) -> Densidad del suelo IN-SITU, Cono de Arena 6" | J28: =VLOOKUP(B28,ENS.!$B$5:$H$167,3,FALSE) -> NTP 339.143:1999 (revisada el 2019) | K28: =VLOOKUP(B28,ENS.!$B$5:$H$167,4,FALSE) -> SI
B29: RO01 | C29: =VLOOKUP(B29,ENS.!$B$5:$H$167,2,FALSE) -> Carga Puntual (incluye tallado y ensayo 10 especimenes). | J29: =VLOOKUP(B29,ENS.!$B$5:$H$167,3,FALSE) -> ASTM D 5731 | K29: =VLOOKUP(B29,ENS.!$B$5:$H$167,4,FALSE) -> NO
B30: RO02 | C30: =VLOOKUP(B30,ENS.!$B$5:$H$167,2,FALSE) -> Gravedad especifica y absorción de roca. | J30: =VLOOKUP(B30,ENS.!$B$5:$H$167,3,FALSE) -> ASTM D 6473 | K30: =VLOOKUP(B30,ENS.!$B$5:$H$167,4,FALSE) -> NO
B31: AG28 | C31: =VLOOKUP(B31,ENS.!$B$5:$H$167,2,FALSE) -> Gravedad especifica y absorción de agregado grueso | J31: =VLOOKUP(B31,ENS.!$B$5:$H$167,3,FALSE) -> ASTM C127-24 | K31: =VLOOKUP(B31,ENS.!$B$5:$H$167,4,FALSE) -> SI
B32: SU32 | C32: =VLOOKUP(B32,ENS.!$B$5:$H$167,2,FALSE) -> Gravedad específica de los sólidos del suelo. | J32: =VLOOKUP(B32,ENS.!$B$5:$H$167,3,FALSE) -> ASTM D854-14 | K32: =VLOOKUP(B32,ENS.!$B$5:$H$167,4,FALSE) -> NO
B33: SU19 | C33: =VLOOKUP(B33,ENS.!$B$5:$H$167,2,FALSE) -> Próctor modificado | J33: =VLOOKUP(B33,ENS.!$B$5:$H$167,3,FALSE) -> ASTM D1557-12 (Reapproved 2021) | K33: =VLOOKUP(B33,ENS.!$B$5:$H$167,4,FALSE) -> SI
B34: SU37 | C34: =VLOOKUP(B34,ENS.!$B$5:$H$167,2,FALSE) -> California Bearing Ratio (CBR) | J34: =VLOOKUP(B34,ENS.!$B$5:$H$167,3,FALSE) -> ASTM D1883-21 | K34: =VLOOKUP(B34,ENS.!$B$5:$H$167,4,FALSE) -> SI
B35: SU06A | C35: =VLOOKUP(B35,ENS.!$B$5:$H$167,2,FALSE) -> Densidad del suelo IN-SITU, Cono de Arena 6" | J35: =VLOOKUP(B35,ENS.!$B$5:$H$167,3,FALSE) -> NTP 339.143:1999 (revisada el 2019) | K35: =VLOOKUP(B35,ENS.!$B$5:$H$167,4,FALSE) -> SI
B36: SU45 | C36: =VLOOKUP(B36,ENS.!$B$5:$H$167,2,FALSE) -> Compresión triaxial no consolidado no drenado UU, diametro 75 mm | J36: =VLOOKUP(B36,ENS.!$B$5:$H$167,3,FALSE) -> ASTM D2850 | K36: =VLOOKUP(B36,ENS.!$B$5:$H$167,4,FALSE) -> NO
B37: SU46 | C37: =VLOOKUP(B37,ENS.!$B$5:$H$167,2,FALSE) -> Compresión triaxial consolidado no drenado CU, diametro 75 mm | J37: =VLOOKUP(B37,ENS.!$B$5:$H$167,3,FALSE) -> ASTM D4767 | K37: =VLOOKUP(B37,ENS.!$B$5:$H$167,4,FALSE) -> NO
B38: SU47 | C38: =VLOOKUP(B38,ENS.!$B$5:$H$167,2,FALSE) -> Compresión triaxial consolidado drenado CD, diametro 75 mm | J38: =VLOOKUP(B38,ENS.!$B$5:$H$167,3,FALSE) -> ASTM D7181 | K38: =VLOOKUP(B38,ENS.!$B$5:$H$167,4,FALSE) -> NO
L39: Costo parcial | N39: =SUM(N17:N38) -> 900
L40: IGV 18% | N40: =+N39*0.18 -> 162
L41: Costo Total (S/) | N41: =+N39+N40 -> 1062
B43: VALIDEZ DE LA OFERTA: 30 días calendario. Si la cotización llegó al límite de su validez, solicite una actualización.
B44: CONDICIONES ESPECÍFICAS PARA LOS ENSAYOS DE LABORATORIO: - El cliente deberá enviar al laboratorio, para los ensayo en suelos, la cantidad mínima de 30 kg para muestra fina y 70 kg para muestra gruesa. - El cliente deberá de entregar las muestras debidamente identificadas. - El cliente deberá especificar la Norma a ser utilizada para la ejecución del ensayo, caso contrario se considera Norma ASTM o NTP vigente de acuerdo con el alcance del laboratorio. - El cliente deberá entregar las muestras en las instalaciones del LEM, ubicado en la Av. Marañón N° 763, Los Olivos, Lima.
B45: PLAZO ESTIMADO DE EJECUCIÓN DE SERVICIO: - El plazo de entrega de los resultados se estima en 04 días hábiles, este tiempo será evaluado de acuerdo a la cantidad de muestra recepcionada y está sujeto a la programacion enviada por el Laboratorio de Ensayos de Materiales. - El laboratorio enviará un correo de confirmación de recepción y fecha de entrega del informe.
B46: COM-F-01 Página 1 de 2 Versión: 04 (10-11-2025)
...

Sheet PROB7 (2)
G3: 44 | P3: ID CLIENTE | Q3: 1275
B5: CLIENTE: | D5: =VLOOKUP($Q$3,BD_Clientes,2,FALSE) -> INVERSIONES INMOBILIARIAS DE LAS CONDES S.A. (IMAGINA) | J5: PROYECTO1: | L5: =VLOOKUP($Q$3,BD_Clientes,9,FALSE) -> OCEAN BREATH | P5: 222
B6: R.U.C.1: | D6: =VLOOKUP($Q$3,BD_Clientes,3,FALSE) -> 20537745631 | P6: 222
B7: CONTACTO: | D7: =VLOOKUP($Q$3,BD_Clientes,5,FALSE) -> Ing. Vania Carhuamaca | J7: UBICACIÓN1: | L7: =VLOOKUP($Q$3,BD_Clientes,10,FALSE) -> Av. Costanera 2880 - San Miguel | P7: 222
B8: TELÉFONO DE CONTACTO: | E8: =VLOOKUP($Q$3,BD_Clientes,7,FALSE) -> 933372811 | J8: PERSONAL COMERCIAL: | L8: Silvia Peralta
B9: CORREO: | D9: =VLOOKUP($Q$3,BD_Clientes,8,FALSE) -> Vania.Carhuamaca@imagina.pe | J9: TELÉFONO DE COMERCIAL: | L9: 982429895
B10: FECHA SOLICITUD: | E10: 46031 | J10: FECHA DE EMISIÓN: | L10: 46031
B11: REFERENCIA: Según lo solicitado vía correo electrónico / Whatsapp / Teléfono / Personalmente.
B12: 1: Información no considerada para las personas naturales.
B13: Por medio de la presente, tenemos el agrado de remitirle nuestra cotización en base a su solicitud, por los servicios de los siguientes ensayos de laboratorio.
B16: CÓDIGO | C16: DESCRIPCIÓN | J16: NORMA | K16: ACREDITADO | L16: COSTO UNITARIO | M16: CANTIDAD | N16: COSTO PARCIAL
B17: CO12 | C17: =VLOOKUP(B17,ENS.!$B$5:$H$167,2,FALSE) -> Compresión de testigos cilíndricos de concreto | J17: =VLOOKUP(B17,ENS.!$B$5:$H$167,3,FALSE) -> ASTM C39/C39M-24 | K17: =VLOOKUP(B17,ENS.!$B$5:$H$167,4,FALSE) -> SI | L17: =VLOOKUP(B17,ENS.!$B$5:$H$167,7,FALSE) -> 15 | M17: 6 | N17: =+L17*M17 -> 90
B18: SER04 | C18: =VLOOKUP(B18,ENS.!$B$5:$H$167,2,FALSE) -> Movilización | J18: =VLOOKUP(B18,ENS.!$B$5:$H$167,3,FALSE) -> - | K18: =VLOOKUP(B18,ENS.!$B$5:$H$167,4,FALSE) -> NO | L18: 60 | M18: 1 | N18: =+L18*M18 -> 60
L19: Costo parcial | N19: =SUM(N17:N18) -> 150
L20: IGV 18% | N20: =+N19*0.18 -> 27
L21: Costo Total (S/) | N21: =+N19+N20 -> 177
B23: VALIDEZ DE LA OFERTA: 30 días calendario. Si la cotización llegó al límite de su validez, solicite una actualización.
B24: CONDICIONES ESPECÍFICAS PARA LOS ENSAYOS DE LABORATORIO: - Los informes de ensayo serán emitidos bajo la acreditación de INACAL únicamente si la fuerza de falla aplicada a la probeta se encuentra dentro del rango de 50 kN a 800 kN. - La cantidad mínima requerida para el recojo de testigos cilíndricos de concreto es de seis (06) unidades. - El cliente deberá de entregar las muestras debidamente identificadas. - El cliente deberá especificar la Norma a ser utilizada para la ejecución del ensayo, caso contrario se considera Norma ASTM vigente de acuerdo con el alcance del laboratorio.
B25: PLAZO ESTIMADO DE EJECUCIÓN DE SERVICIO: - El plazo de entrega de los resultados se estima de acuerdo a su programación de recepción, este tiempo será evaluado de acuerdo a la cantidad de muestra recepcionada y está sujeto a la programacion enviada por el área de LEM. - El laboratorio enviará un correo de confirmación de recepción y fecha de entrega del informe.
B27: COM-F-01 Página 1 de 2 Versión: 04 (10-11-2025)
B28: CONTRAMUESTRA Al finalizar los ensayos, la muestra sobrante/contramuestra permanecerán en custodia por un tiempo de 10 dias calendario después de emitido el informe de ensayo. Siempre que se trate de una muestra dirimente, las contramuestras serán devueltas a los clientes, previa coordinación y autorización, caso contrario, serán eliminadas si se trata de residuos del ensayo o contramuestras de ensayo.
B29: CONFIDENCIALIDAD: GEOFAL S.A.C mantiene acuerdos de confidencialidad entre el cliente y el laboratorio, la divulgación de la información sin la autorización de las partes, no es permitida. El laboratorio mantiene reserva de la información brindada por el cliente, salvo solicitud de la información por ley, o por entidades gubernamentales inmersos dentro del presente servicio de ensayo.
B30: QUEJAS Y SUGERENCIAS: El plazo máximo para la recepción de quejas relacionadas con un informe técnico es de diez (10) días calendarios, contados a partir de la fecha de emisión del documento correspondiente. Transcurrido dicho plazo, no se aceptarán quejas bajo ninguna circunstancia. En caso de tener alguna queja o sugerencia, lo invitamos a conocer nuestro Proceso de Atención de Quejas, el cual dará inicio 24 horas después de la recepción formal de la queja.
B31: ENTREGA DE INFORME DE ENSAYO: - De acuerdo a los lineamientos de INACAL - DM, los informes de ensayo son emitidos de forma digital con firma electrónica y QR. - La entrega de los informes de ensayo será mediante la plataforma de Intranet de la pagina web www.geofal.com.pe, y se enviará un correo de confirmación al cliente con el usuario y clave para el acceso. Asi mismo el cliente puede ingresar a la gruía deusuario que es visible en la página web. - Geofal no declara conformidad de sus informes de ensayo. - En caso se requiera la modificación del informe de ensayo a consecuencia de los datos proporcionados por el cliente, esta se realizará mediante la emisión de un nuevo informe que tendrá un costo adicional de acuerdo a evaluación.
B32: HORARIO DE ATENCIÓN El horario para recepción de muestra y entrega de informes es de Lunes a Viernes de 8:30am a 1:00pm y 2:00pm a 5:30pm, y Sábado de 8:30am a 12:30pm
B35: CONDICIÓN: El pago del servicio Crédito a 30 días, previa orden de servicio. | P35: CONDICIONES DE PAGO
B36: RAZON SOCIAL: Geofal S.A.C. RUC: 20549356762 | P36: CONDICIÓN: El pago del servicio se realizara de acuerdo a la valorización mensual
B37: Sírvase realizar el depósito correspondiente de los servicios a nuestra cuenta bancaria: | P37: CONDICIÓN: El pago del servicio deberá ser realizado por Adelantado.
B38: Cuenta de detraccion Banco de La Nación: | P38: CONDICIÓN: El pago del servicio Adelanto el 50% y saldo previo a la entrega del Informe.
B39: - Cuenta de detraccion Banco de La Nación: Nº 00-074-045472 | P39: CONDICIÓN: El pago del servicio Crédito a 7 días, previa orden de servicio.
B40: Cuenta corriente Interbank: | P40: CONDICIÓN: El pago del servicio Crédito a 30 días, previa orden de servicio.
B41: - Cuenta Corriente en Soles de Interbank: Nº 200-3005201096 | P41: CONDICIÓN: El pago del servicio Crédito a 15 días, previa orden de servicio.
B42: - Código Interbancario (CCI) de Interbank: Nº 003-200- 003005201096-31
B43: Cuenta corriente BCP:
B44: - Cuenta Corriente en Soles del Banco de Crédito del Perú (BCP): Nº 192 2024 3030 04
B45: - Código Interbancario (CCI) del Banco de Crédito del Perú (BCP): Nº 002-192-002 02430 3004-34
B46: Cuenta corriente BBVA:
B47: - Cuenta Corriente en Soles BBVA: Nº 0011-0174-0100082311-00
B48: - Código Interbancario (CCI) BBVA: Nº 011-174-000100082311-00
B52: La aceptación de la cotización por parte del cliente podrá manifestarse a través de cualquiera de las siguientes acciones: el pago correspondiente al servicio, el envío de la orden de servicio, o el envío de un correo electrónico confirmando la aceptación del servicio según la presente cotización, al correo asesorcomercial@geofal.com.pe y/o mediante mensaje de WhatsApp al número del asesor comercial, en señal de conformidad.
...

Sheet DENS-AG5 (2)
G3: 43 | P3: ID CLIENTE | Q3: 1276
B5: CLIENTE: | D5: =VLOOKUP($Q$3,BD_Clientes,2,FALSE) -> INVERSIONES INMOBILIARIAS DE PUERTO MADERO S.A. (IMAGINA) | J5: PROYECTO1: | L5: =VLOOKUP($Q$3,BD_Clientes,9,FALSE) -> ALTO METRO PARK ETAPA 1 | P5: 222
B6: R.U.C.1: | D6: =VLOOKUP($Q$3,BD_Clientes,3,FALSE) -> 20538391001 | P6: 222
B7: CONTACTO: | D7: =VLOOKUP($Q$3,BD_Clientes,5,FALSE) -> Ing. Luis Montesinos | J7: UBICACIÓN1: | L7: =VLOOKUP($Q$3,BD_Clientes,10,FALSE) -> Av. Óscar R. Benavides 262-264 - Callao | P7: 222
B8: TELÉFONO DE CONTACTO: | E8: =VLOOKUP($Q$3,BD_Clientes,7,FALSE) -> - | J8: PERSONAL COMERCIAL: | L8: Silvia Peralta
B9: CORREO: | D9: =VLOOKUP($Q$3,BD_Clientes,8,FALSE) -> Luis.Montesinos@imagina.pe | J9: TELÉFONO DE COMERCIAL: | L9: 982429895
B10: FECHA SOLICITUD: | E10: 46031 | J10: FECHA DE EMISIÓN: | L10: 46031
B11: REFERENCIA: Segùn lo solicitado vìa correo electrònico / Whatsapp / Teléfono / Personalmente.
B12: 1: Información no considerada para las personas naturales.
B13: Por medio de la presente, tenemos el agrado de remitirle nuestra cotización en base a su solicitud, por los servicios de los siguientes ensayos de laboratorio.
B16: CÓDIGO | C16: DESCRIPCIÓN | J16: NORMA | K16: ACREDITADO | L16: COSTO UNITARIO | M16: CANTIDAD | N16: COSTO PARCIAL
C17: ENSAYOS EN CONCRETO
B18: CO12 | C18: =VLOOKUP(B18,ENS.!$B$5:$H$167,2,FALSE) -> Compresión de testigos cilíndricos de concreto | J18: =VLOOKUP(B18,ENS.!$B$5:$H$167,3,FALSE) -> ASTM C39/C39M-24 | K18: =VLOOKUP(B18,ENS.!$B$5:$H$167,4,FALSE) -> SI | L18: =VLOOKUP(B18,ENS.!$B$5:$H$167,7,FALSE) -> 15 | M18: 1 | N18: =+L18*M18 -> 15
C19: ENSAYO PROCTOR MODIFICADO
B20: SU19 | C20: =VLOOKUP(B20,ENS.!$B$5:$H$167,2,FALSE) -> Próctor modificado | J20: =VLOOKUP(B20,ENS.!$B$5:$H$167,3,FALSE) -> ASTM D1557-12 (Reapproved 2021) | K20: =VLOOKUP(B20,ENS.!$B$5:$H$167,4,FALSE) -> SI | L20: =VLOOKUP(B20,ENS.!$B$5:$H$167,7,FALSE) -> 150 | M20: 1 | N20: =+L20*M20 -> 150
B21: SU32 | C21: =VLOOKUP(B21,ENS.!$B$5:$H$167,2,FALSE) -> Gravedad específica de los sólidos del suelo. | J21: =VLOOKUP(B21,ENS.!$B$5:$H$167,3,FALSE) -> ASTM D854-14 | K21: =VLOOKUP(B21,ENS.!$B$5:$H$167,4,FALSE) -> NO | L21: =VLOOKUP(B21,ENS.!$B$5:$H$167,7,FALSE) -> 120 | M21: 1 | N21: =+L21*M21 -> 120
B22: AG28 | C22: =VLOOKUP(B22,ENS.!$B$5:$H$167,2,FALSE) -> Gravedad especifica y absorción de agregado grueso | J22: =VLOOKUP(B22,ENS.!$B$5:$H$167,3,FALSE) -> ASTM C127-24 | K22: =VLOOKUP(B22,ENS.!$B$5:$H$167,4,FALSE) -> SI | L22: =VLOOKUP(B22,ENS.!$B$5:$H$167,7,FALSE) -> 120 | M22: 1 | N22: =+L22*M22 -> 120
B23: SU24 | C23: =VLOOKUP(B23,ENS.!$B$5:$H$167,2,FALSE) -> Análisis granulométrico por tamizado en Suelo | J23: =VLOOKUP(B23,ENS.!$B$5:$H$167,3,FALSE) -> ASTM D6913/D6913M-17 | K23: =VLOOKUP(B23,ENS.!$B$5:$H$167,4,FALSE) -> SI | L23: =VLOOKUP(B23,ENS.!$B$5:$H$167,7,FALSE) -> 100 | M23: 1 | N23: =+L23*M23 -> 100
C24: ENSAYOS DE CLASIFICACIÓN
B25: SU22 | C25: =VLOOKUP(B25,ENS.!$B$5:$H$167,2,FALSE) -> Clasificación suelo SUCS - AASHTO | J25: =VLOOKUP(B25,ENS.!$B$5:$H$167,3,FALSE) -> ASTM D2487-17 (Reapproved 2025) / ASTM D3282-24 | K25: =VLOOKUP(B25,ENS.!$B$5:$H$167,4,FALSE) -> SI | L25: =VLOOKUP(B25,ENS.!$B$5:$H$167,7,FALSE) -> 20 | M25: 1 | N25: =+L25*M25 -> 20
B26: SU23 | C26: =VLOOKUP(B26,ENS.!$B$5:$H$167,2,FALSE) -> Límite líquido y Límite Plástico del Suelo | J26: =VLOOKUP(B26,ENS.!$B$5:$H$167,3,FALSE) -> ASTM D4318-17ε1 | K26: =VLOOKUP(B26,ENS.!$B$5:$H$167,4,FALSE) -> SI | L26: =VLOOKUP(B26,ENS.!$B$5:$H$167,7,FALSE) -> 90 | M26: 1 | N26: =+L26*M26 -> 90
