Workbook
Name ___CC2: [1]Sucs!$L$6
Name __CC2: [1]Sucs!$L$6
Name _CC1: [2]Sucs!$L$6
Name _CC2: [1]Sucs!$L$6
Name _CU1: [2]Sucs!$L$5
Name _IP1: [2]Sucs!$L$4
Name _L1: #REF!
Name _L1: #REF!
Name _L1: #REF!
Name _L1: #REF!
Name _Ll1: [2]Sucs!$L$3
Name _W1: #REF!
Name _W1: #REF!
Name _W1: #REF!
Name _W1: #REF!
Name Abra: [3]Sucs!$C$3
Name CC: #REF!
Name CC: #REF!
Name CC: 'Sucs '!$L$6
Name CC: #REF!
Name CCf: '[2]Sucs(Fino)'!$L$6
Name CCVB: [4]Sucs!$L$3
Name CM: [5]BGA!$H$9
Name CU: #REF!
Name CU: #REF!
Name CU: 'Sucs '!$L$5
Name CU: #REF!
Name CUf: '[2]Sucs(Fino)'!$L$5
Name hh: #REF!
Name hh: #REF!
Name hh: #REF!
Name IP: #REF!
Name IP: #REF!
Name IP: 'Sucs '!$L$4
Name IP: #REF!
Name IPf: '[2]Sucs(Fino)'!$L$4
Name L: #REF!
Name L: #REF!
Name L: #REF!
Name L: #REF!
Name LIf: '[2]Sucs(Fino)'!$L$3
Name Ll: #REF!
Name Ll: #REF!
Name Ll: 'Sucs '!$L$3
Name Ll: #REF!
Name MORA: [5]BGA!$H$13
Name N_10: #REF!
Name N_10: #REF!
Name N_10: 'Sucs '!$C$5
Name N_10: #REF!
Name N_101: [2]Sucs!$C$5
Name N_10f: '[2]Sucs(Fino)'!$C$5
Name N_200: #REF!
Name N_200: #REF!
Name N_200: 'Sucs '!$C$3
Name N_200: #REF!
Name N_2001: [2]Sucs!$C$3
Name N_200f: '[2]Sucs(Fino)'!$C$3
Name N_40: #REF!
Name N_40: #REF!

Sheet FORMATO
N2: CLIENTE
N3: DIRECCIÓN **
N4: PROYECTO **
N5: UBICACIÓN **
A7: LABORATORIO DE ENSAYO DE MATERIALES | N7: RECEPCIÓN N°
A8: FORMATO N° F-LEM-P-SU-24.01 | N8: F. EMISIÓN
N9: OT N°
D10: MUESTRA | F10: No OT | H10: FECHA ENSAYO | J10: REALIZADO
J11: - | N11: CÓDIGO DE LA MUESTRA
N12: FECHA DE RECEPCIÓN
A13: Standard Test Methods for Particle-Size Distribution (Gradation) of Soils Using Sieve Analysis | N13: FECHA DE EJECUCIÓN
A14: ASTM D6913/D6913M-17 (Reapproved 2025)
N15: CANTERA/SONDAJE **
A16: MÉTODO DE PRUEBA | E16: Descripción de la muestra: | J16: DESCRIBA SI ES TURBO O ORGANICO | N16: N° MUESTRA **
A17: Método "A" | E17: Tipo de muestra : | N17: TIPO DE MUESTRA**
A18: Método "B" | E18: Condición de la muestra:
E19: Tamaño máximo de la particula, Visual (in): | J19: Tamiz Separador (*)
A20: TAMIZADO | E20: Forma de la particula: | J20: No. 4
A21: Fraccionado | J21: (*) si aplica tamizado compuesto
A22: Global | E22: TAMIZADO COMPUESTO (FRACCIONADO) | J22: TAMIZADO SERIE UNICA DE TAMIZ (GLOBAL)
E23: Masa seca porcion gruesa (CP, Md) (g) | J23: Masa seca global (g)
A24: MÉTODO DE MUESTREO | E24: Masa humeda porcion fina (FP, Mm) (g) | J24: Humedad de la subespecie porcion fina
A25: Humedo | E25: Masa seca porcion fina (FP, Md) (g) | J25: Masa humeda (g)
A26: Secado al aire | E26: Masa seca de la muestra (S, Md) (g) | J26: Masa seca (SubS ,Md) (g)
A27: Secado al horno | J27: Contenido de agua (wfp) (%)
E29: PERDIDA ACEPTABLE DURANTE EL LAVADO Y EL TAMIZADO CPL=(((CP,Md-CPw,MD)+CP,Mrpan)/S,Md)
A30: CLASIF. VISUAL MUESTRA | E30: Masa seca de la porcion mas gruesa despues del lavado (CPwMd) (g)
A31: Simbolo | E31: Masa seca retenida en el plato despues de tamizar la porcion mas gruesa (CP, Mrpan) (g)
A32: Nombre | E32: Porcentaje de la porcion más gruesa perdida durante el lavado y tamizado (CPL) (%)
E33: Masa de subespecimen lavado porcion fina (g)
A34: Se excluyó cualquier suelo o material de la muestra | E34: Masa seca de la muestra (S,Md) | J34: El porcentaje de perdida es aceptable si el valor
A35: Describirlo: | J35: de CPL es menor o igual al 0.5%
A37: Se encontro algun problema en la muestra | E37: Proceso de dipersión | K37: Masa retenida en el primer tamiz (g)
A38: Describirlo: | E38: Manual | F38: Baño ultrasónico | H38: Aparato de agitación
A40: Malla | C40: Abertura | D40: Peso | I40: Tabla de pesos mínimos
A41: Tamiz | C41: (mm) | D41: (g)
A42: 3 in | C42: 75
A43: 2 in | C43: 50
A44: 1 1/2 in | C44: 37.5
A45: 1 in | C45: 25
...

Sheet A.Granul
Q2: Metodo de Prueba | R2: -
Q3: Tamizado | R3: - | U3: REALIZADO | V3: - | W3: =+FORMATO!J11 -> 0
Q5: TAMIZADO COMPUESTO (FRACCIONADO) | X5: TAMIZADO SERIE UNICA DE TAMIZ (GLOBAL) | AC5: TM | AD5: MASA MINIMA
R6: Descripcion | T6: Masa humeda (g) | U6: Corregido | V6: Masa seca | Y6: Original | Z6: Corregido | AC6: (in.) | AD6: (g)
A7: LABORATORIO DE ENSAYO DE MATERIALES | Q7: Masa seca porcion gruesa (CP,Md) g | T7: =+FORMATO!H23 -> 0 | U7: =T7+(T7*$Z$14) -> 0 | V7: =U7 -> 0 | X7: Masa Humeda g | Y7: =+IF(R3="Global",FORMATO!K23,FORMATO!K25) -> 0 | Z7: =Y7+($Z$14*Y7) -> 0 | AC7: 3 | AD7: 70000
A8: 0 | Q8: Masa humeda porcion fina (FP,Mm) g | T8: =+FORMATO!H24 -> 0 | U8: =T8+(T8*$Z$14) -> 0 | V8: =U8/(1+Z9/100) -> #DIV/0! | X8: Masa Seca (Subs,Md) g | Y8: =+IF(R3="Global",FORMATO!K23,FORMATO!K26) -> 0 | Z8: =Y8+($Z$14*Y8) -> 0 | AC8: 2 | AD8: 25000
A9: CLIENTE** | B9: : | C9: =+FORMATO!O2 -> 0 | L9: CÓDIGO | M9: : | N9: F-LEM-P-SU-24.02 | Q9: total (S,Md) g | V9: =SUM(V7:V8) -> #DIV/0! | X9: % Humedad (Wfp) | Z9: =((Z7-Z8)/Z8)*100 -> #DIV/0! | AC9: 1.5 | AD9: 10000
A10: DIRECCIÓN ** | B10: : | C10: =+FORMATO!O3 -> 0 | L10: RECEPCIÓN N° | M10: : | N10: =+FORMATO!O7 -> 0 | AC10: 1 | AD10: 3000
A11: PROYECTO ** | B11: : | C11: =+FORMATO!O4 -> 0 | L11: OT N° | M11: : | N11: =+FORMATO!O9 -> 0 | Q11: Datos de ensayo | X11: Correccion por Certificado de Calibración: | AC11: 0.75 | AD11: 1300
A12: UBICACIÓN ** | B12: : | C12: =+FORMATO!O5 -> 0 | L12: FECHA EMISIÓN | M12: : | N12: =+FORMATO!O8 -> 0 | Q12: Masa seca de la muestra (S,Md) g | V12: =IF(R3="Global",Z8,IF(R3="Fraccionada",V9)) -> FALSE | X12: Codigo de Balanza al 0.1g | Z12: Variable 1 | AC12: 3/8 | AD12: 200
A13: ** Datos proporcionados por el cliente | Q13: Masa seca subespecimen porcion fina (Subs,Md) g | V13: =IF(R3="Global","--",IF(R3="Fraccionada",Z8)) -> FALSE | X13: CODIGO | Z13: =+Balanza!B11 -> EQP-0046 | AC13: N°4 | AD13: 200
A14: Standard Test Methods for Particle-Size Distribution (Gradation) of Soils Using Sieve Analysis | Q14: Masa Muestra Lavada subespecimen porcion fina g | V14: =+FORMATO!K33 -> 0 | X14: Corrección | Z14: =+Balanza!B7 -> -3.29e-06 | AC14: - | AD14: -
A15: ASTM D6913/D6913M-17 (Reapproved 2025) | X15: Fecha | Z15: =+Balanza!C12 -> 46132
Q16: PERDIDA ACEPTABLE DURANTE EL LAVADO Y EL TAMIZADO CPL=(((CP,Md-CPw,MD)+CP,Mrpan)/S,Md)
A17: DATOS DE LA MUESTRA | Q17: Masa seca de la porcion mas gruesa despues del lavado (CPwMd) g | U17: =+T7 -> 0 | V17: =U17+(U17*$Z$14) -> 0 | X17: SOLO PARA TAMIZADO COMPUESTO (FRACCIONADO) | AB17: 12.6.2.4
A18: CANTERA/SONDAJE** | D18: : | E18: =+FORMATO!O15 -> 0 | L18: CÓDIGO DE LA MUESTRA | M18: : | N18: =+FORMATO!O11 -> 0 | Q18: Masa seca retenida en el plato despues de tamizar la porcion mas gruesa (CP,Mrpan) g | U18: 0 | V18: =U18+(U18*$Z$14) -> 0 | X18: 2do CP,FRRfirst = 100 (2do CP,FCMRfirst / Subs,Md) | Z18: Original | AA18: Corregido
A19: N° MUESTRA ** | D19: : | E19: =+FORMATO!O16 -> 0 | L19: FECHA DE RECEPCIÓN | M19: : | N19: =+FORMATO!O12 -> 0 | Q19: Porcentaje de la porcion mas gruesa perdida durante el lavado y tamizado (CPL) % | U19: =100*(((V7-V17)+V18)/V9) -> #DIV/0! | V19: =100*(((V7-V17)+V18)/V9) -> #DIV/0! | X19: Masa Retenida en el primer tamiz (2do CP,FCMRfirst) g | Z19: 0 | AA19: =Z19-($Z$14*Z19) -> 0
A20: TIPO DE MUESTRA | D20: : | E20: =+FORMATO!O17 -> 0 | L20: FECHA DE EJECUCIÓN | M20: : | N20: =+FORMATO!O13 -> 0 | O20: =+FORMATO!H11 -> 0 | Q20: Perdidad durante el lavado y tamizado (CPL) | V20: =IF(V19<0.5,"Cumple","No Cumple") -> #DIV/0! | X20: Porcentaje fraccional retenido en el primer tamiz (2do CP,FRRfirst) % | AA20: =100*(AA19/Z8) -> #DIV/0!
A21: LUGAR DE ENSAYO | D21: : | E21: Laboratorio de Ensayo de Materiales | L21: REALIZADO POR | M21: : | N21: =+V3 -> - | X21: Porcetaje de aprobación (PR) | AA21: =IF(AA20<2,"Cumple","No Cumple") -> #DIV/0!
E23: Designación de Tamices | K23: Porcentaje que pasa el tamiz (%) | Q23: Designaciòn de Tamices | S23: Masa retenida en el tamiz | T23: Corregido | U23: Porcenteje Reten. Tamiz | V23: Porcentaje acum. Reten. | W23: Porcentaje que pasa el tamiz | Y23: Tamaño máximo TM: | Z23: 3
E24: Alternativo | I24: Estándar | Q24: Alternativo | R24: Estándar (mm) | S24: (g) | T24: (g) | U24: (%) | V24: (%) | W24: (%) | Y24: Cantidad mínima: | Z24: =+INDEX(AC7:AD14,MATCH(Z23,AC7:AC14,0),2) -> 70000 | AA24: =+IF((V9)>Z24,"Cumple","No Cumple") -> #DIV/0!
E25: 3 in. | I25: 75 mm | K25: =IF($I$66="Método A",FIXED(($W$25),0),FIXED(($W$25),1)) -> #DIV/0! | Q25: 3 in. | R25: 75 | S25: =+FORMATO!E42 -> 0 | T25: =S25+(S25*$Z$14) -> 0 | U25: =T25/$V$12*100 -> #DIV/0! | V25: =U25 -> #DIV/0! | W25: =100-V25 -> #DIV/0!
E26: 2 in. | I26: 50 mm | K26: =IF($I$66="Método A",FIXED(($W$26),0),FIXED(($W$26),1)) -> #DIV/0! | Q26: 2 in. | R26: 50 | S26: =+FORMATO!E43 -> 0 | T26: =S26+(S26*$Z$14) -> 0 | U26: =T26/$V$12*100 -> #DIV/0! | V26: =+V25+U26 -> #DIV/0! | W26: =100-V26 -> #DIV/0!
E27: 1 1/2 in. | I27: 37.5 mm | K27: =IF($I$66="Método A",FIXED(($W$27),0),FIXED(($W$27),1)) -> #DIV/0! | Q27: 1 1/2 in. | R27: 37.5 | S27: =+FORMATO!E44 -> 0 | T27: =S27+(S27*$Z$14) -> 0 | U27: =T27/$V$12*100 -> #DIV/0! | V27: =+V26+U27 -> #DIV/0! | W27: =100-V27 -> #DIV/0!
E28: 1 in. | I28: 25.0 mm | K28: =IF($I$66="Método A",FIXED(($W$28),0),FIXED(($W$28),1)) -> #DIV/0! | Q28: 1 in. | R28: 25 | S28: =+FORMATO!E45 -> 0 | T28: =S28+(S28*$Z$14) -> 0 | U28: =T28/$V$12*100 -> #DIV/0! | V28: =+V27+U28 -> #DIV/0! | W28: =100-V28 -> #DIV/0!
E29: 3/4 in. | I29: 19.0 mm | K29: =IF($I$66="Método A",FIXED(($W$29),0),FIXED(($W$29),1)) -> #DIV/0! | Q29: 3/4 in. | R29: 19 | S29: =+FORMATO!E46 -> 0 | T29: =S29+(S29*$Z$14) -> 0 | U29: =T29/$V$12*100 -> #DIV/0! | V29: =+V28+U29 -> #DIV/0! | W29: =100-V29 -> #DIV/0!
E30: 3/8 in. | I30: 9.5 mm | K30: =IF($I$66="Método A",FIXED(($W$30),0),FIXED(($W$30),1)) -> #DIV/0! | Q30: 3/8 in. | R30: 9.5 | S30: =+FORMATO!E47 -> 0 | T30: =S30+(S30*$Z$14) -> 0 | U30: =T30/$V$12*100 -> #DIV/0! | V30: =+V29+U30 -> #DIV/0! | W30: =100-V30 -> #DIV/0!
E31: No.4 | I31: 4.75 mm | K31: =IF($I$66="Método A",FIXED(($W$31),0),FIXED(($W$31),1)) -> #DIV/0! | Q31: No.4 | R31: 4.75 | S31: =+FORMATO!E48 -> 0 | T31: =S31+(S31*$Z$14) -> 0 | U31: =T31/$V$12*100 -> #DIV/0! | V31: =+V30+U31 -> #DIV/0! | W31: =100-V31 -> #DIV/0!
E32: No. 10 | I32: 2.00 mm | K32: =IF($I$66="Método A",FIXED(($W$32),0),FIXED(($W$32),1)) -> #DIV/0! | Q32: No. 10 | R32: 2 | S32: =+FORMATO!E50 -> 0 | T32: =S32+(S32*$Z$14) -> 0 | U32: =IF($R$3="Fraccionada",T32*$W$31/V$13,IF($R$3="Global",T32/$V$12*100)) -> FALSE | V32: =+V31+U32 -> #DIV/0! | W32: =100-V32 -> #DIV/0!
E33: No. 20 | I33: 850 µm | K33: =IF($I$66="Método A",FIXED(($W$33),0),FIXED(($W$33),1)) -> #DIV/0! | Q33: No. 20 | R33: 0.85 | S33: =+FORMATO!E51 -> 0 | T33: =S33+(S33*$Z$14) -> 0 | U33: =IF($R$3="Fraccionada",T33*$W$31/V$13,IF($R$3="Global",T33/$V$12*100)) -> FALSE | V33: =+V32+U33 -> #DIV/0! | W33: =100-V33 -> #DIV/0!
E34: No. 40 | I34: 425 µm | K34: =IF($I$66="Método A",FIXED(($W$34),0),FIXED(($W$34),1)) -> #DIV/0! | Q34: No. 40 | R34: 0.425 | S34: =+FORMATO!E52 -> 0 | T34: =S34+(S34*$Z$14) -> 0 | U34: =IF($R$3="Fraccionada",T34*$W$31/V$13,IF($R$3="Global",T34/$V$12*100)) -> FALSE | V34: =+V33+U34 -> #DIV/0! | W34: =100-V34 -> #DIV/0!
E35: No. 60 | I35: 250 µm | K35: =IF($I$66="Método A",FIXED(($W$35),0),FIXED(($W$35),1)) -> #DIV/0! | Q35: No. 60 | R35: 0.25 | S35: =+FORMATO!E53 -> 0 | T35: =S35+(S35*$Z$14) -> 0 | U35: =IF($R$3="Fraccionada",T35*$W$31/V$13,IF($R$3="Global",T35/$V$12*100)) -> FALSE | V35: =+V34+U35 -> #DIV/0! | W35: =100-V35 -> #DIV/0!
E36: No. 100 | I36: 150 µm | K36: =IF($I$66="Método A",FIXED(($W$36),0),FIXED(($W$36),1)) -> #DIV/0! | Q36: No. 100 | R36: 0.15 | S36: =+FORMATO!E54 -> 0 | T36: =S36+(S36*$Z$14) -> 0 | U36: =IF($R$3="Fraccionada",T36*$W$31/V$13,IF($R$3="Global",T36/$V$12*100)) -> FALSE | V36: =+V35+U36 -> #DIV/0! | W36: =100-V36 -> #DIV/0!
E37: No. 140 | I37: 106 µm | K37: =IF($I$66="Método A",FIXED(($W$37),0),FIXED(($W$37),1)) -> #DIV/0! | Q37: No. 140 | R37: 0.106 | S37: =+FORMATO!E55 -> 0 | T37: =S37+(S37*$Z$14) -> 0 | U37: =IF($R$3="Fraccionada",T37*$W$31/V$13,IF($R$3="Global",T37/$V$12*100)) -> FALSE | V37: =+V36+U37 -> #DIV/0! | W37: =100-V37 -> #DIV/0!
E38: No. 200 | I38: 75 µm | K38: =IF($I$66="Método A",FIXED(($W$38),0),FIXED(($W$38),1)) -> #DIV/0! | Q38: No. 200 | R38: 0.075 | S38: =+FORMATO!E56 -> 0 | T38: =S38+(S38*$Z$14) -> 0 | U38: =IF($R$3="Fraccionada",T38*$W$31/V$13,IF($R$3="Global",T38/$V$12*100)) -> FALSE | V38: =+V37+U38 -> #DIV/0! | W38: =100-V38 -> #DIV/0!
Q39: < 200 | R39: 0.01 | S39: =+FORMATO!E57 -> 0 | T39: =IF(R3="Fraccionada",(V13-(SUM(T32:T38))),IF(R3="Global",(V12-SUM(T25:T38)))) -> FALSE | U39: =IF($R$3="Fraccionada",T39*$W$31/V$13,IF($R$3="Global",T39/$V$12*100)) -> FALSE | V39: =+V38+U39 -> #DIV/0! | W39: =100-V39 -> #DIV/0!
Q41: Distribución granulométrica
Q43: % GRAVA | R43: =$V$31 -> #DIV/0! | S43: Gruesa | T43: =SUM($U$25:$U$29) -> #DIV/0!
S44: Fina | T44: =SUM($U$30:$U$31) -> #DIV/0!
Q45: % ARENA | R45: =100-(R43+R48) -> #DIV/0! | S45: Gruesa | T45: =SUM($U$32:$U$32) -> 0
...

Sheet Incertidumbre
C1: INFORME DE ESTIMACIÓN DE INCERTIDUMBRE | J1: Código: | K1: F-LEM-P-10.01
J2: Versión: | K2: 3
J3: Fecha: | K3: 46146
J4: Página: | K4: 1 de 1
A6: Método: | B6: Standard Test Methods for Particle-Size Distribution (Gradation) of Soils Using Sieve Analysis
A7: Norma: | B7: ASTM D6913/D6913M-17
A8: Matriz: | B8: Suelo
A9: Mensurando: | B9: Masa de suelo que pasa a travez de un tamiz
A11: Paso 1. Definición del proceso de medición
A13: Variables: | F13: Fórmula:
A15: % Pasa: % pasa el tamiz anterior
A16: Mret: Masa retenida
A17: Mtotal: Masa total
A19: Equipos a utilizar:
A21: Balanza con resolución de lectura de 0.1g
A22: Tamices
A24: Paso 2. Definición de las variables aleatorias
A34: CALCULOS
A35: Fuentes | B35: Valor | C35: Incertidumbre original | D35: Distribución | E35: Incertidumbre Estándar u(xi) | F35: Coeficiente de Sensibilidad | G35: Contribución ui(y) | H35: Incertidumbre Estándar Combinada | I35: Incertidumbre Expandida
A37: Tamiz 3 in | B37: =+(1-(B38/B42))*100 -> #DIV/0! | H37: =SQRT(G38*G38+(G46*G46)+(G42*G42)+(G48*G48)) -> #DIV/0! | I37: =IF(B38=0,"---",(H37*2)) -> ---
A38: M ret acumulado 3 in (g) | B38: =Balanza!D29 -> 0 | D38: --- | E38: =SQRT((E39*E39)+(E40*E40)+(E41*E41)) -> 0.070663522 | F38: =(100/B42) -> #DIV/0! | G38: =(E38*F38) -> #DIV/0!
A39: Repetibilidad de la pesada | C39: =Balanza!$E$29 -> 0 | D39: Normal, K=1 | E39: =C39 -> 0
A40: Certificado de Calibración | C40: =2*(SQRT(Balanza!$B$8+Balanza!$C$8*(POWER(B38,2)))) -> 0.12899612 | D40: Normal, K=2 | E40: =C40/2 -> 0.064498062 | I40: =A38 -> M ret acumulado 3 in (g) | J40: =G38 -> #DIV/0! | K40: =+J40/$J$44 -> #DIV/0!
A41: Resolución | C41: =Balanza!$B$10 -> 0.1 | D41: Rectangular | E41: =(C41/SQRT(3)/2) -> 0.028867513 | I41: =A46 -> Abertura de Tamiz 3 in (mm) | J41: =G46 -> 0.009 | K41: =+J41/$J$44 -> #DIV/0!
A42: M total (g) | B42: =Balanza!$C$25 -> FALSE | D42: --- | E42: =SQRT((E43*E43)+(E44*E44)+(E45*E45)) -> 0.070663522 | F42: =(100*B38)/POWER(B42,2) -> #DIV/0! | G42: =(E42*F42) -> #DIV/0! | I42: =A42 -> M total (g) | J42: =G42 -> #DIV/0! | K42: =+J42/$J$44 -> #DIV/0!
A43: Repetibilidad de la pesada | C43: =Balanza!$D$25 -> 0 | D43: Normal, K=1 | E43: =C43 -> 0 | I43: =A48 -> Factor de presición 3 in | J43: =G48 -> 0 | K43: =+J43/$J$44 -> #DIV/0!
A44: Certificado de Calibración | C44: =2*(SQRT(Balanza!$B$8+Balanza!$C$8*(POWER(B42,2)))) -> 0.12899612 | D44: Normal, K=2 | E44: =C44/2 -> 0.064498062 | J44: =SUM(J40:J43) -> #DIV/0! | K44: =+J44/$J$44 -> #DIV/0!
A45: Resolución | C45: =Balanza!$B$10 -> 0.1 | D45: Rectangular | E45: =(C45/SQRT(3)/2) -> 0.028867513
A46: Abertura de Tamiz 3 in (mm) | B46: 75 | D46: --- | E46: =SQRT(((E47*E47))) -> 0.009 | F46: 1 | G46: =(E46*F46) -> 0.009
A47: Certificado de Calibración | C47: =Balanza!K28 -> 0.018 | D47: Normal, K=2 | E47: =C47/2 -> 0.009
A48: Factor de presición 3 in | B48: =+Balanza!B50 -> 0 | D48: Norma, K=1 | E48: =B48/SQRT(1) -> 0 | F48: 1 | G48: =+F48*E48 -> 0
A50: Tamiz 2 in | B50: =+(1-(B51/B55))*100 -> #DIV/0! | H50: =SQRT(G51*G51+(G59*G59)+(G55*G55)+(G61*G61)) -> #DIV/0! | I50: =IF(B51=0,"---",(H50*2)) -> ---
A51: M ret acumulado 2 in (g) | B51: =Balanza!D30 -> 0 | D51: --- | E51: =SQRT((E52*E52)+(E53*E53)+(E54*E54)) -> 0.070663522 | F51: =(100/B55) -> #DIV/0! | G51: =(E51*F51) -> #DIV/0!
A52: Repetibilidad de la pesada | C52: =Balanza!E30 -> 0 | D52: Normal, K=1 | E52: =C52 -> 0
A53: Certificado de Calibración | C53: =2*(SQRT(Balanza!$B$8+Balanza!$C$8*(POWER(B51,2)))) -> 0.12899612 | D53: Normal, K=2 | E53: =C53/2 -> 0.064498062 | I53: =A51 -> M ret acumulado 2 in (g) | J53: =G51 -> #DIV/0! | K53: =+J53/$J$57 -> #DIV/0!
A54: Resolución | C54: =Balanza!$B$10 -> 0.1 | D54: Rectangular | E54: =(C54/SQRT(3)/2) -> 0.028867513 | I54: =A59 -> Abertura de Tamiz 2 in (mm) | J54: =G59 -> 0.009 | K54: =+J54/$J$57 -> #DIV/0!
A55: M total (g) | B55: =Balanza!$C$25 -> FALSE | D55: --- | E55: =SQRT((E56*E56)+(E57*E57)+(E58*E58)) -> 0.070663522 | F55: =(100*B51)/POWER(B55,2) -> #DIV/0! | G55: =(E55*F55) -> #DIV/0! | I55: =A55 -> M total (g) | J55: =G55 -> #DIV/0! | K55: =+J55/$J$57 -> #DIV/0!
A56: Repetibilidad de la pesada | C56: =Balanza!$D$25 -> 0 | D56: Normal, K=1 | E56: =C56 -> 0 | I56: =A61 -> Factor de presición 2 in | J56: =G61 -> 0 | K56: =+J56/$J$57 -> #DIV/0!
A57: Certificado de Calibración | C57: =2*(SQRT(Balanza!$B$8+Balanza!$C$8*(POWER(B55,2)))) -> 0.12899612 | D57: Normal, K=2 | E57: =C57/2 -> 0.064498062 | J57: =SUM(J53:J56) -> #DIV/0! | K57: =+J57/$J$57 -> #DIV/0!
A58: Resolución | C58: =Balanza!$B$10 -> 0.1 | D58: Rectangular | E58: =(C58/SQRT(3)/2) -> 0.028867513
...

Sheet Balanza
C2: CALIBRACION DE LA BALANZA
A7: Corrección | B7: -3.29e-06
A8: Variables | B8: 0.00416 | C8: 2.43e-10
A9: Ecuación | B9: 2*RAIZ(0.00416+0.000000000243*R2)
A10: Resolución | B10: 0.1 | C10: g
A11: Código | B11: EQP-0046
A12: Fecha ultima calibracion | C12: 46132
A14: ITEM | B14: MES | C14: 20 | D14: 200 | E14: 500 | F14: 1000 | G14: 5000 | H14: 10000
B18: DESV STD | C18: 0 | D18: 0 | E18: 0 | F18: 0 | G18: 0 | H18: 0
B20: Busqueda de Repetibilidad de la masa
J21: CALIBRACION TAMICES
C22: =+C14 -> 20 | D22: =+D14 -> 200 | E22: =+E14 -> 500 | F22: =+F14 -> 1000 | G22: =+G14 -> 5000 | H22: =+H14 -> 10000
C23: =C18 -> 0 | D23: =D18 -> 0 | E23: =E18 -> 0 | F23: =F18 -> 0 | G23: =G18 -> 0 | H23: =H18 -> 0 | J23: Fecha de Calibracion: | L23: 44628
B25: M. total | C25: =A.Granul!V12 -> FALSE | D25: =IF(C25<=$C$22,$C$23,IF(AND(C25>$C$22,C25<=$D$22),$D$23,IF(AND(C25>$D$22,C25<=$E$22),$E$23,IF(AND(C25>$E$22,C25<=$F$22),$F$23,IF(AND(C25>$F$22,C25<=$G$22),$G$23,IF(AND(C25>$G$22,C25<=$H$22),$H$23,$H$23)))))) -> 0
B26: =+A.Granul!R3 -> - | C26: =+A.Granul!V13 -> FALSE | D26: =IF(C26<=$C$22,$C$23,IF(AND(C26>$C$22,C26<=$D$22),$D$23,IF(AND(C26>$D$22,C26<=$E$22),$E$23,IF(AND(C26>$E$22,C26<=$F$22),$F$23,IF(AND(C26>$F$22,C26<=$G$22),$G$23,IF(AND(C26>$G$22,C26<=$H$22),$H$23,$H$23)))))) -> 0
B27: TAMICES | C27: Masa Retenida (g) | D27: Retenida Acumulado (g) | E27: Repetib. | J27: TAMIZ | K27: U(x) (mm) | L27: Datos del certificado
J28: 3 " | K28: =L28/1000 -> 0.018 | L28: 18 | M28: um
B29: 3in | C29: =+A.Granul!T25 -> 0 | D29: =+C29 -> 0 | E29: =IF(D29<=$C$22,$C$23,IF(AND(D29>$C$22,D29<=$D$22),$D$23,IF(AND(D29>$D$22,D29<=$E$22),$E$23,IF(AND(D29>$E$22,D29<=$F$22),$F$23,IF(AND(D29>$F$22,D29<=$G$22),$G$23,IF(AND(D29>$G$22,D29<=$H$22),$H$23,$H$23)))))) -> 0 | J29: 2 " | K29: =L29/1000 -> 0.018 | L29: 18 | M29: um
B30: 2 " | C30: =+A.Granul!T26 -> 0 | D30: =+C30+D29 -> 0 | E30: =IF(D30<=$C$22,$C$23,IF(AND(D30>$C$22,D30<=$D$22),$D$23,IF(AND(D30>$D$22,D30<=$E$22),$E$23,IF(AND(D30>$E$22,D30<=$F$22),$F$23,IF(AND(D30>$F$22,D30<=$G$22),$G$23,IF(AND(D30>$G$22,D30<=$H$22),$H$23,$H$23)))))) -> 0 | J30: 1 1/2 " | K30: =L30/1000 -> 0.018 | L30: 18 | M30: um
B31: 1 1/2 " | C31: =+A.Granul!T27 -> 0 | D31: =+C31+D30 -> 0 | E31: =IF(D31<=$C$22,$C$23,IF(AND(D31>$C$22,D31<=$D$22),$D$23,IF(AND(D31>$D$22,D31<=$E$22),$E$23,IF(AND(D31>$E$22,D31<=$F$22),$F$23,IF(AND(D31>$F$22,D31<=$G$22),$G$23,IF(AND(D31>$G$22,D31<=$H$22),$H$23,$H$23)))))) -> 0 | J31: 1 " | K31: =L31/1000 -> 0.018 | L31: 18 | M31: um
B32: 1 " | C32: =+A.Granul!T28 -> 0 | D32: =+C32+D31 -> 0 | E32: =IF(D32<=$C$22,$C$23,IF(AND(D32>$C$22,D32<=$D$22),$D$23,IF(AND(D32>$D$22,D32<=$E$22),$E$23,IF(AND(D32>$E$22,D32<=$F$22),$F$23,IF(AND(D32>$F$22,D32<=$G$22),$G$23,IF(AND(D32>$G$22,D32<=$H$22),$H$23,$H$23)))))) -> 0 | J32: 3/4" | K32: =L32/1000 -> 0.018 | L32: 18 | M32: um
B33: 3/4" | C33: =+A.Granul!T29 -> 0 | D33: =+C33+D32 -> 0 | E33: =IF(D33<=$C$22,$C$23,IF(AND(D33>$C$22,D33<=$D$22),$D$23,IF(AND(D33>$D$22,D33<=$E$22),$E$23,IF(AND(D33>$E$22,D33<=$F$22),$F$23,IF(AND(D33>$F$22,D33<=$G$22),$G$23,IF(AND(D33>$G$22,D33<=$H$22),$H$23,$H$23)))))) -> 0 | J33: 3/8" | K33: =L33/1000 -> 0.018 | L33: 18 | M33: um
B34: 3/8" | C34: =+A.Granul!T30 -> 0 | D34: =+C34+D33 -> 0 | E34: =IF(D34<=$C$22,$C$23,IF(AND(D34>$C$22,D34<=$D$22),$D$23,IF(AND(D34>$D$22,D34<=$E$22),$E$23,IF(AND(D34>$E$22,D34<=$F$22),$F$23,IF(AND(D34>$F$22,D34<=$G$22),$G$23,IF(AND(D34>$G$22,D34<=$H$22),$H$23,$H$23)))))) -> 0 | J34: Nº 4 | K34: =L34/1000 -> 0.018 | L34: 18 | M34: um
B35: Nº 4 | C35: =+A.Granul!T31 -> 0 | D35: =+C35+D34 -> 0 | E35: =IF(D35<=$C$22,$C$23,IF(AND(D35>$C$22,D35<=$D$22),$D$23,IF(AND(D35>$D$22,D35<=$E$22),$E$23,IF(AND(D35>$E$22,D35<=$F$22),$F$23,IF(AND(D35>$F$22,D35<=$G$22),$G$23,IF(AND(D35>$G$22,D35<=$H$22),$H$23,$H$23)))))) -> 0 | J35: Nº 10 | K35: =L35/1000 -> 0.0065 | L35: 6.5 | M35: um
B36: Nº 10 | C36: =+A.Granul!T32 -> 0 | D36: =IF(B26="Fraccionada",C36,D35+C36) -> 0 | E36: =IF(D36<=$C$22,$C$23,IF(AND(D36>$C$22,D36<=$D$22),$D$23,IF(AND(D36>$D$22,D36<=$E$22),$E$23,IF(AND(D36>$E$22,D36<=$F$22),$F$23,IF(AND(D36>$F$22,D36<=$G$22),$G$23,IF(AND(D36>$G$22,D36<=$H$22),$H$23,$H$23)))))) -> 0 | J36: Nº 20 | K36: =L36/1000 -> 0.0054 | L36: 5.4 | M36: um
B37: Nº 20 | C37: =+A.Granul!T33 -> 0 | D37: =D36+C37 -> 0 | E37: =IF(D37<=$C$22,$C$23,IF(AND(D37>$C$22,D37<=$D$22),$D$23,IF(AND(D37>$D$22,D37<=$E$22),$E$23,IF(AND(D37>$E$22,D37<=$F$22),$F$23,IF(AND(D37>$F$22,D37<=$G$22),$G$23,IF(AND(D37>$G$22,D37<=$H$22),$H$23,$H$23)))))) -> 0 | J37: Nº 40 | K37: =L37/1000 -> 0.0027 | L37: 2.7 | M37: um
B38: Nº 40 | C38: =+A.Granul!T34 -> 0 | D38: =D37+C38 -> 0 | E38: =IF(D38<=$C$22,$C$23,IF(AND(D38>$C$22,D38<=$D$22),$D$23,IF(AND(D38>$D$22,D38<=$E$22),$E$23,IF(AND(D38>$E$22,D38<=$F$22),$F$23,IF(AND(D38>$F$22,D38<=$G$22),$G$23,IF(AND(D38>$G$22,D38<=$H$22),$H$23,$H$23)))))) -> 0 | J38: Nº 60 | K38: =L38/1000 -> 0.0025 | L38: 2.5 | M38: um
B39: Nº 60 | C39: =+A.Granul!T35 -> 0 | D39: =D38+C39 -> 0 | E39: =IF(D39<=$C$22,$C$23,IF(AND(D39>$C$22,D39<=$D$22),$D$23,IF(AND(D39>$D$22,D39<=$E$22),$E$23,IF(AND(D39>$E$22,D39<=$F$22),$F$23,IF(AND(D39>$F$22,D39<=$G$22),$G$23,IF(AND(D39>$G$22,D39<=$H$22),$H$23,$H$23)))))) -> 0 | J39: Nº 100 | K39: =L39/1000 -> 0.0013 | L39: 1.3 | M39: um
B40: Nº 100 | C40: =+A.Granul!T36 -> 0 | D40: =D39+C40 -> 0 | E40: =IF(D40<=$C$22,$C$23,IF(AND(D40>$C$22,D40<=$D$22),$D$23,IF(AND(D40>$D$22,D40<=$E$22),$E$23,IF(AND(D40>$E$22,D40<=$F$22),$F$23,IF(AND(D40>$F$22,D40<=$G$22),$G$23,IF(AND(D40>$G$22,D40<=$H$22),$H$23,$H$23)))))) -> 0 | J40: Nº 140 | K40: =L40/1000 -> 0.0014 | L40: 1.4 | M40: um
B41: Nº 140 | C41: =+A.Granul!T37 -> 0 | D41: =D40+C41 -> 0 | E41: =IF(D41<=$C$22,$C$23,IF(AND(D41>$C$22,D41<=$D$22),$D$23,IF(AND(D41>$D$22,D41<=$E$22),$E$23,IF(AND(D41>$E$22,D41<=$F$22),$F$23,IF(AND(D41>$F$22,D41<=$G$22),$G$23,IF(AND(D41>$G$22,D41<=$H$22),$H$23,$H$23)))))) -> 0 | J41: Nº 200 | K41: =L41/1000 -> 0.0013 | L41: 1.3 | M41: um
B42: Nº 200 | C42: =+A.Granul!T38 -> 0 | D42: =D41+C42 -> 0 | E42: =IF(D42<=$C$22,$C$23,IF(AND(D42>$C$22,D42<=$D$22),$D$23,IF(AND(D42>$D$22,D42<=$E$22),$E$23,IF(AND(D42>$E$22,D42<=$F$22),$F$23,IF(AND(D42>$F$22,D42<=$G$22),$G$23,IF(AND(D42>$G$22,D42<=$H$22),$H$23,$H$23)))))) -> 0
B43: Fondo | C43: =+A.Granul!T39 -> FALSE | D43: =D42+C43 -> 0 | E43: =IF(D43<=$C$22,$C$23,IF(AND(D43>$C$22,D43<=$D$22),$D$23,IF(AND(D43>$D$22,D43<=$E$22),$E$23,IF(AND(D43>$E$22,D43<=$F$22),$F$23,IF(AND(D43>$F$22,D43<=$G$22),$G$23,IF(AND(D43>$G$22,D43<=$H$22),$H$23,$H$23)))))) -> 0
A46: DATA DE ASEGURAMIENTO
A47: Fecha evaluacion | C47: 46167
A49: TAMIZ | B49: Desviacion Estándar Repetibilidad (Sr) | C49: Desviacion Estándar Reproducibilidad (SR)
A50: 3 " | B50: 0 | C50: 0
A51: 2 " | B51: 0 | C51: 0
A52: 1 1/2 " | B52: 0 | C52: 0
A53: 1 " | B53: 0 | C53: 0
A54: 3/4" | B54: 0 | C54: 0
...

Sheet LL-LP
A8: LABORATORIO DE ENSAYO DE MATERIALES
A9: =+K13 -> 10
A11: SOLICITANTE | B11: : | C11: =+A.Granul!F10 -> 0 | I11: CÓDIGO | J11: : | K11: F-LEM-P-SU-11.02
A12: PROYECTO | B12: : | C12: =+A.Granul!F11 -> 0 | I12: N° OT | J12: : | K12: =+A.Granul!N11 -> 0
A13: UBICACIÓN | B13: : | C13: =+A.Granul!F12 -> 0 | I13: N° CERT. | J13: : | K13: 10
A15: METODO DE ENSAYO PARA DETERMINAR EL LIMITE LIQUIDO, LIMITE PLASTICO E INDICE DE PLASTICIDAD DE SUELOS
A16: NORMA NTP 339.129
A18: DATOS DE LA MUESTRA
A19: CANTERA / SONDAJE | B19: : | C19: =+A.Granul!F18 -> 0 | I19: COD. MUESTRA | J19: : | K19: =+A.Granul!N18 -> 0
A20: N° MUESTRA | B20: : | C20: =+A.Granul!F19 -> 0 | I20: FECHA RECEP. | J20: : | K20: =+A.Granul!N19 -> 0 | U20: SI
A21: TIPO DE MUESTRA | B21: : | C21: =+A.Granul!F20 -> 0 | I21: FECHA ENSAYO | J21: : | K21: =+A.Granul!N20 -> 0 | U21: NO
D24: LIMITE LIQUIDO | G24: LIMITE PLASTICO | O24: LIMITE LIQUIDO | Q24: NO | R24: LIMITE PLASTICO | T24: NO
B25: Ensayo | D25: =IF($Q$24="NO","",O25) | E25: =IF($Q$24="NO","",P25) | F25: =IF($Q$24="NO","",Q25) | G25: =IF($T$24="NO","",R25) | H25: =IF($T$24="NO","",S25) | N25: Ensayo | O25: 1 | P25: 2 | Q25: 3 | R25: 1 | S25: 2
B26: Recipiente Nº | D26: =IF($Q$24="NO","",O26) | E26: =IF($Q$24="NO","",P26) | F26: =IF($Q$24="NO","",Q26) | G26: =IF($T$24="NO","",R26) | H26: =IF($T$24="NO","",S26) | N26: Recipiente Nº | O26: 5 | P26: 3 | Q26: 4 | R26: 11 | S26: 10
B27: Nº de Golpes | D27: =IF($Q$24="NO","",O27) | E27: =IF($Q$24="NO","",P27) | F27: =IF($Q$24="NO","",Q27) | N27: Nº de Golpes | O27: 34 | P27: 23 | Q27: 14
B28: R + Suelo Hum. | D28: =IF($Q$24="NO","",O28) | E28: =IF($Q$24="NO","",P28) | F28: =IF($Q$24="NO","",Q28) | G28: =IF($T$24="NO","",R28) | H28: =IF($T$24="NO","",S28) | N28: R + Suelo Hum. | O28: 45.75 | P28: 43.9 | Q28: 43.66 | R28: 23.05 | S28: 18.07
B29: R + Suelo Seco | D29: =IF($Q$24="NO","",O29) | E29: =IF($Q$24="NO","",P29) | F29: =IF($Q$24="NO","",Q29) | G29: =IF($T$24="NO","",R29) | H29: =IF($T$24="NO","",S29) | N29: R + Suelo Seco | O29: 41.37 | P29: 40.03 | Q29: 38.78 | R29: 22.63 | S29: 17.48
B30: Peso Recip. | D30: =IF($Q$24="NO","",O30) | E30: =IF($Q$24="NO","",P30) | F30: =IF($Q$24="NO","",Q30) | G30: =IF($T$24="NO","",R30) | H30: =IF($T$24="NO","",S30) | N30: Peso Recip. | O30: 22.74 | P30: 24.18 | Q30: 19.97 | R30: 19.31 | S30: 13.01
B31: Peso Agua | D31: =IF($Q$24="NO","",O31) | E31: =IF($Q$24="NO","",P31) | F31: =IF($Q$24="NO","",Q31) | G31: =IF($T$24="NO","",R31) | H31: =IF($T$24="NO","",S31) | N31: Peso Agua | O31: =+O28-O29 -> 4.38 | P31: =+P28-P29 -> 3.87 | Q31: =+Q28-Q29 -> 4.88 | R31: =+R28-R29 -> 0.42 | S31: =+S28-S29 -> 0.59
B32: Peso S. Seco | D32: =IF($Q$24="NO","",O32) | E32: =IF($Q$24="NO","",P32) | F32: =IF($Q$24="NO","",Q32) | G32: =IF($T$24="NO","",R32) | H32: =IF($T$24="NO","",S32) | N32: Peso S. Seco | O32: =+O29-O30 -> 18.63 | P32: =+P29-P30 -> 15.85 | Q32: =+Q29-Q30 -> 18.81 | R32: =+R29-R30 -> 3.32 | S32: =+S29-S30 -> 4.47
B33: % de Humedad | D33: =IF($Q$24="NO","",O33) | E33: =IF($Q$24="NO","",P33) | F33: =IF($Q$24="NO","",Q33) | G33: =IF($T$24="NO","",R33) | H33: =IF($T$24="NO","",S33) | N33: % de Humedad | O33: =+O31/O32*100 -> 23.510467 | P33: =+P31/P32*100 -> 24.416404 | Q33: =+Q31/Q32*100 -> 25.943647 | R33: =+R31/R32*100 -> 12.650602 | S33: =+S31/S32*100 -> 13.199105
G35: LL | H35: =+IF(Q24="NO","NP",O40) -> NP | N35: Golp. | O35: % Humed
N36: =+D27 | O36: =+D33
N37: =+E27 | O37: =+E33
G38: LP | H38: =+IF(T24="NO","NP",O42) -> NP | N38: =+F27 | O38: =+F33
N39: 25 | O39: 0
N40: 25 | O40: =P41 -> #VALUE! | P40: =+D33/(1.419-0.3*LOG10(D27)) -> #VALUE! | Q40: =+F33/(1.419-0.3*LOG10(F27)) -> #VALUE!
G41: IP | H41: =IF(T24="NO","NP",H35-H38) -> NP | N41: 10 | O41: =+O40 -> #VALUE! | P41: =+AVERAGE(P40:Q40) -> #VALUE!
N42: LP | O42: =AVERAGE(R33:S33) -> 12.924854
A43: Nota :
N44: Limite Liquido: | O44: =O49 -> 24.296606
N45: 25 | O45: =LOG10(N45) -> 1.39794
O46: =O27 -> 34 | P46: =P27 -> 23 | Q46: =Q27 -> 14
A47: Página 1 de 1 | N47: LOG GOLPES | O47: =LOG10(O46) -> 1.5314789 | P47: =LOG10(P46) -> 1.3617278 | Q47: =LOG10(Q46) -> 1.146128
A48: Versión : 02 (02-01-2021) | N48: Humedad | O48: =O33 -> 23.510467 | P48: =P33 -> 24.416404 | Q48: =Q33 -> 25.943647
O49: =TREND(O48:Q48,O47:Q47,O45) -> 24.296606
A50: WEB: www.geofal.com.pe E-MAIL: laboratorio@geofal.com.pe / geofal.sac@gmail.com Av. Marañon 763, Los Olivos-Lima / Teléfono 01 522-1851

Sheet Sucs 
A1: esa | B1: SISTEMA UNIFICADO DE CLASIFICACION
L2: =+A.Granul!R2 -> -
B3: N 200= | C3: =+A.Granul!W38 -> #DIV/0! | D3: Cu = | E3: =+A.Granul!#REF! -> #REF! | K3: L.L. | L3: =+IF(N_10="NP",0,N_10) -> 0
B4: N 4= | C4: =+A.Granul!W31 -> #DIV/0! | D4: Cc = | E4: =+A.Granul!S65 -> 0 | F4: CLASIFICACION SUCS | G4: =+Q9 -> #DIV/0! | K4: I.P. | L4: =+IF(C6="NP",0,C6) -> 0
B5: L.L.= | C5: =+'LL-LP'!H35 -> NP | K5: CU | L5: =IF(OR(E3="----",E3=""),0,E3) -> #REF!
B6: I.P.= | C6: =+'LL-LP'!H41 -> NP | K6: CC | L6: =IF(OR(E4="----",E4=""),0,E4) -> 0
B8: DIVISIONES MAYORES | E8: SIMBOLO DE GRUPO | F8: NOMBRES TIPICOS | G8: CRITERIOS DE CLASIFICACION PARA SUELOS GRANULARES | L8: CLASIF | M8: SIMBOLOS DOBLES | O8: SIMBOLOS TRIPLES | P8: CLASIFICACION | Q8: SIMBOLO
B9: Suelos de grano grueso (mas del 50 % del material es mayor en tamaño que el tamiz No 200 | C9: Gravas (mas de la mitad de la fracción gruesa es mayor que el tamiz No 4) | D9: Gravas Limpias (poco o ningun fino) | E9: GW | F9: Gravas bien gradadas, mezclas gravosas, poco o ningun fino | G9: Cu > 4 1 < Cc < 3 | L9: =IF(AND(N_200<50,(100-N_40)>=0.5*(100-N_200),N_200<5,CU>=4,CC>=1,CC<=3),"GW","") -> #DIV/0! | M9: =IF(AND(N_200<50,(100-N_40)>=0.5*(100-N_200),N_200>=5,CU>=4,CC>=1,CC<=3,N_200<12,IP>=7,IP>=0.73*(Ll-20)),"GW-GC","") -> #DIV/0! | N9: =IF(AND(N_200<50,(100-N_40)>=0.5*(100-N_200),N_200>=5,CU>=4,CC>=1,CC<=3,N_200<12,OR(IP<4,IP<0.73*(Ll-20))),"GW-GM","") -> #DIV/0! | O9: =IF(AND(N_200<50,(100-N_40)>=0.5*(100-N_200),N_200>=5,CU>=4,CC>=1,CC<=3,N_200<12,IP>=4,IP<7,IP<0.9*(Ll-8),IP>=0.73*(Ll-20)),"GW-GC-GM","") -> #DIV/0! | P9: =+L9&M9&N9&O9 -> #DIV/0! | Q9: =+P9&P10&P11&P12&P13&P14&P15&P16&P17&P18&P19&P20&P21&P22&P23&P24 -> #DIV/0!
E10: GP | F10: Gravas pobremente gradadas,`mezclas grava-arena, pocos o ningun fino | G10: No cumple todos los requisitos de gradadcion para GW | L10: =IF(AND(N_200<50,(100-N_40)>=0.5*(100-N_200),N_200<5,OR(CU<4,CC<1,CC>3)),"GP","") -> #DIV/0! | M10: =IF(AND(N_200<50,(100-N_40)>=0.5*(100-N_200),N_200>=5,OR(CU<4,CC<1,CC>3),N_200<12,IP>=7,IP>=0.73*(Ll-20)),"GP-GC","") -> #DIV/0! | N10: =IF(AND(N_200<50,(100-N_40)>=0.5*(100-N_200),N_200>=5,OR(CU<4,CC<1,CC>3),N_200<12,OR(IP<4,IP<0.73*(Ll-20))),"GP-GM","") -> #DIV/0! | O10: =IF(AND(N_200<50,(100-N_40)>=0.5*(100-N_200),N_200>=5,OR(CU<4,CC<1,CC>3),N_200<12,IP>=4,IP<7,IP<0.9*(Ll-8),IP>=0.73*(Ll-20)),"GP-GC-GM","") -> #DIV/0! | P10: =+L10&M10&N10&O10 -> #DIV/0!
D11: Gravas con finos (cantidad apre- ciable de finos) | E11: GM | F11: Gravas limosas, mezcla grava- arena-limo | G11: Límites de Atteberg por debajo de la linea A o Ip < 4 | H11: A los materiales sobre la linea A con 4 < Ip < 7 se considera de frontera y se les asigna doble símbolo | L11: =IF(AND(N_200<50,(100-N_40)>=0.5*(100-N_200),N_200>=12,OR(IP<4,IP<0.73*(Ll-20))),"GM","") -> #DIV/0! | M11: =IF(AND(N_200<50,(100-N_40)>=0.5*(100-N_200),N_200>=12,IP>=4,IP<7,IP>=0.73*(Ll-20)),"GC-GM","") -> #DIV/0! | P11: =+L11&M11&N11&O11 -> #DIV/0!
E12: GC | F12: Gravas arcillosas, mezcla gravo-areno- arcillosas | G12: Límites de Atteberg por encima de la línea A ó Ip > 7 | L12: =IF(AND(N_200<50,(100-N_40)>=0.5*(100-N_200),N_200>=12,IP>=7,IP>=0.73*(Ll-20)),"GC","") -> #DIV/0! | P12: =+L12&M12&N12&O12 -> #DIV/0!
C13: Arenas (mas de la mitad de la fracción gruesa es menor que el tamiz No 4) | D13: Arenas Limpias (poco o ningun fino) | E13: SW | F13: Arenas bien gradadas, arenas gravosas, pocos o ningun fino | G13: Cu > 6 1 < Cc < 3 | L13: =IF(AND(N_200<50,(100-N_40)<0.5*(100-N_200),N_200<5,CU>=6,CC>=1,CC<=3),"SW","") -> #DIV/0! | M13: =IF(AND(N_200<50,(100-N_40)<0.5*(100-N_200),N_200>=5,CU>=6,CC>=1,CC<=3,N_200<12,IP>=7,IP>=0.73*(Ll-20)),"SW-SC","") -> #DIV/0! | N13: =IF(AND(N_200<50,(100-N_40)<0.5*(100-N_200),N_200>=5,CU>=6,CC>=1,CC<=3,N_200<12,OR(IP<4,IP<0.73*(Ll-20))),"SW-SM","") -> #DIV/0! | O13: =IF(AND(N_200<50,(100-N_40)<0.5*(100-N_200),N_200>=5,CU>=6,CC>=1,CC<=3,N_200<12,IP>=4,IP<7,IP<0.9*(Ll-8),IP>=0.73*(Ll-20)),"SW-SC-SM","") -> #DIV/0! | P13: =+L13&M13&N13&O13 -> #DIV/0!
E14: SP | F14: Arenas pobremente gradadas, arenas gravosas, pocos o ningun fino | G14: No cumple todos los requisitos de gradadcion para SW | L14: =IF(AND(N_200<50,(100-N_40)<0.5*(100-N_200),N_200<5,OR(CU<6,CC<1,CC>3)),"SP","") -> #DIV/0! | M14: =IF(AND(N_200<50,(100-N_40)<0.5*(100-N_200),N_200>=5,OR(CU<6,CC<1,CC>3),N_200<12,IP>=7,IP>=0.73*(Ll-20)),"SP-SC","") -> #DIV/0! | N14: =IF(AND(N_200<50,(100-N_40)<0.5*(100-N_200),N_200>=5,OR(CU<6,CC<1,CC>3),N_200<12,OR(IP<4,IP<0.73*(Ll-20))),"SP-SM","") -> #DIV/0! | O14: =IF(AND(N_200<50,(100-N_40)<0.5*(100-N_200),N_200>=5,OR(CU<6,CC<1,CC>3),N_200<12,IP>=4,IP<7,IP<0.9*(Ll-8),IP>=0.73*(Ll-20)),"SP-SC-SM","") -> #DIV/0! | P14: =+L14&M14&N14&O14 -> #DIV/0!
D15: Arenas con finos (cantidad apre- ciable de finos) | E15: SM | F15: Arenas limosas mezcla de arena-limo | G15: Límites de Atteberg por debajo de la linea A ó Ip < 4 | H15: Si el material está en la zona sombreada con 4 < Ip < 7 se considera de frontera y se les asigna doble símbolo | L15: =IF(AND(N_200<50,(100-N_40)<0.5*(100-N_200),N_200>=12,OR(IP<4,IP<0.73*(Ll-20))),"SM","") -> #DIV/0! | M15: =IF(AND(N_200<50,(100-N_40)<0.5*(100-N_200),N_200>=12,IP>=4,IP<7,IP>=0.73*(Ll-20)),"SC-SM","") -> #DIV/0! | P15: =+L15&M15&N15&O15 -> #DIV/0!
E16: SC | F16: Arenas arcillosas, mezclas arena-arcilla | G16: Límites de Atteberg por encima de la linea A ó Ip > 7 | L16: =IF(AND(N_200<50,(100-N_40)<0.5*(100-N_200),N_200>=12,IP>=7,IP>=0.73*(Ll-20)),"SC","") -> #DIV/0! | P16: =+L16&M16&N16&O16 -> #DIV/0!
B17: Suelos de grano fino (mas del 50 % del material pasa el tamiz No 200 | C17: limos y arcillas (Límite líquido wl<50 | E17: ML | F17: Limos inorgánicos y arena muy finas, polvo de roca, arenas finas limosas o arcillosas, o limos arcillosos con poca plasticidad | G17: 1, Determinar el porcentaje de arenas y gravas de la curva granulometrica. 2, Dependiendo del porcentaje de fino (fracción menor que el tamiz No 200 los suelos gruesos se clasifican como sigue: Menos del 5% - GW, GP, SW, SP Mas del 12 % - GM, GC, SM, SC De 5 a 12 % - casos frontera que requieren doble símbolo | L17: =IF(AND(OR(L2="Inorganico"),N_200>=50,Ll<50,OR(IP<4,AND(IP<0.73*(Ll-20)))),"ML","") -> #DIV/0! | P17: =+L17&M17&N17&O17 -> #DIV/0!
E18: CL | F18: Arcillas inorganicas de plasticidad baja a media, arcillas gravosas, arcillas arenosas, arcillas limosas, arcillas magras. | L18: =IF(AND(OR(L2="Inorganico"),N_200>=50,Ll<50,IP>=7,IP>=0.73*(Ll-20)),"CL","") -> #DIV/0! | P18: =+L18&M18&N18&O18 -> #DIV/0!
E19: OL | F19: Limos organicos, arcillas limosas orgánicas de baja plasticidad | L19: =IF(AND(L2="Organico",N_200>=50,Ll<50,IP<0.73*(Ll-20)),"OL","") -> #DIV/0! | P19: =+L19&M19&N19&O19 -> #DIV/0!
C20: limos y arcillas (Límite líquido wl>50 | E20: MH | F20: Limos inorganicos, suelos limosos o arenosos finos micaceos o diatomaceos, suelos elasticos. | L20: =IF(AND(OR(L2="Inorganico"),N_200>=50,Ll>=50,IP>0,IP<0.73*(Ll-20)),"MH","") -> #DIV/0! | P20: =+L20&M20&N20&O20 -> #DIV/0!
E21: CH | F21: Arcillas inorganicas de alta plasticidad, arcillas grasas. | L21: =IF(AND(OR(L2="Inorganico"),N_200>=50,Ll>=50,IP>=0.73*(Ll-20)),"CH","") -> #DIV/0! | P21: =+L21&M21&N21&O21 -> #DIV/0!
E22: OH | F22: Arcillas organicas de plasticidad media a alta, limos orgánicos | L22: =IF(AND(L2="Organico",N_200>=50,Ll>=50,IP<0.73*(Ll-20)),"OH","") -> #DIV/0! | P22: =+L22&M22&N22&O22 -> #DIV/0!
C23: Suelos Altamen- te orgá- nicos | E23: Pt | F23: Turba o otros suelos altamente organicos | L23: =IF(AND(OR(L2="Inorganico"),N_200>=50,IP>=0.73*(Ll-20),IP>=4,IP<7,IP<0.9*(Ll-8)),"CL-ML","") -> #DIV/0! | P23: =+L23&M23&N23&O23 -> #DIV/0!
L24: =IF(AND(L2="Turba"),"Pt","") | P24: =+L24&M24&N24&O24
A30: % Arena : | B30: =A.Granul!W31-A.Granul!W38 -> #DIV/0!
A31: % Grava : | B31: =A.Granul!W25-A.Granul!W31 -> #DIV/0!
A32: Descripción del suelo
J34: =Q9 -> #DIV/0!
A38: Fraccion de Grava = | B38: =B31 -> #DIV/0! | C38: IP= | D38: ='LL-LP'!H41 -> NP | E38: =IF(D38="","",0.73*('LL-LP'!O44-20)) -> 3.1365222
A39: Fraccionde Arena = | B39: =B30 -> #DIV/0! | C39: F.Arena/ F. Grava = | D39: =IF(B38=0,100,B39/B38) -> #DIV/0!
A40: Fraccion de finos = | B40: =A.Granul!J30 -> 0 | C40: Retenido en 200 = | D40: =100-B40 -> 100
A41: GW | B41: =IF(AND($J$34="GW",$B$39<15),"Grava bien graduada",IF(AND($J$34="GW",$B$39>=15),"Grava bien graduada con arena","")) -> #DIV/0!
A42: GP | B42: =IF(AND($J$34="GP",$B$39<15),"Grava pobremente graduada",IF(AND($J$34="GP",$B$39>=15),"Grava pobremente graduada con arena","")) -> #DIV/0!
A43: GW-GC | B43: =IF(AND($J$34="GW - GC",$B$39<15),"Grava bien graduada con arcilla",IF(AND($J$34="GW - GC",$B$39>=15),"Grava bien graduada con arcilla y arena","")) -> #DIV/0!
A44: GW-GM | B44: =IF(AND($J$34="GW - GM",$B$39<15),"Grava bien graduada con limo",IF(AND($J$34="GW - GM",$B$39>=15),"Grava bien graduada con limo y arena","")) -> #DIV/0!
A45: GP-GC | B45: =IF(AND($J$34="GP - GC",$B$39<15),"Grava pobremente graduada con arcilla",IF(AND($J$34="GP - GC",$B$39>=15),"Grava pobremente graduada con arcilla y arena","")) -> #DIV/0!
A46: GP-GM | B46: =IF(AND($J$34="GP - GM",$B$39<15),"Grava pobremente graduada con limo",IF(AND($J$34="GP - GM",$B$39>=15),"Grava pobremente graduada con limo y arena","")) -> #DIV/0!
A47: GC | B47: =IF(AND($J$34="GC",$B$39<15),"Grava arcillosa",IF(AND($J$34="GC",$B$39>=15),"Grava arcillosa con arena","")) -> #DIV/0!
A48: GC-GM | B48: =IF(AND($J$34="GC - GM",$B$39<15),"Grava limosa arcillosa",IF(AND($J$34="GC - GM",$B$39>=15),"Grava limosa arcillosa con arena","")) -> #DIV/0!
A49: GM | B49: =IF(AND($J$34="GM",$B$39<15),"Grava limosa",IF(AND($J$34="GM",$B$39>=15),"Grava limosa con arena","")) -> #DIV/0!
A50: SW | B50: =IF(AND($J$34="SW",$B$38<15),"Arena bien graduada",IF(AND($J$34="SW",$B$38>=15),"Arena bien graduada con grava","")) -> #DIV/0!
...

Sheet Aashto
B4: CLASIFICACION GENERAL | D4: MATERIALES GRANULARES (35% O MENOS DEL TOTAL PASA EL TAMIZ NO 200) | K4: MATERIALES LIMO-ARCILLOSOS (MAS DEL 35% DEL TOTAL PASA EL TAMIZ No 200)
B5: CLASIFICACION DE GRUPO | D5: A-1 | F5: A-3 | G5: A-2 | K5: A-4 | L5: A-5 | M5: A-6 | N5: A-7
D6: A-1-a | E6: A-1-b | G6: A-2-4 | H6: A-2-5 | I6: A-2-6 | J6: A-2-7 | N6: A-7-5 | O6: A-7-6
B8: Porcentaje de material
B9: que pasa el tamiz
B11: No 10 | C11: =+A.Granul!W32 -> #DIV/0! | D11: 50 max
B12: No 40 | C12: =+A.Granul!W35 -> #DIV/0! | D12: 30 max | E12: 50 max | F12: 51 min
B13: No 200 | C13: =+A.Granul!W38 -> #DIV/0! | D13: 15 max | E13: 25 max | F13: 10 max | G13: 35 max | H13: 35 max | I13: 35 max | J13: 35 max | K13: 36 min | L13: 36 min | M13: 36 min | N13: 36 min | O13: 36 min
B16: Caracteristicas de la
B17: fraccion que pasa el
B18: tamiz No 40
B20: Limite líquido | C20: =+'LL-LP'!H35 -> NP | G20: 40 max | H20: 41 min | I20: 40 max | J20: 41 min | K20: 40 max | L20: 41 min | M20: 40 max | N20: 41 min | O20: 41 min
B21: Indice plástico | C21: =+'LL-LP'!H41 -> NP | D21: 6 max | E21: 6 max | F21: N.P. | G21: 10 max | H21: 10 max | I21: 11 min | J21: 11 min | K21: 10 max | L21: 10 max | M21: 11 min | N21: 11`min | O21: 11`min
B23: Indice de Grupo | C23: =+D38 -> #DIV/0! | D23: 0 | F23: 0 | G23: 0 | I23: 4 max | K23: 8 max | L23: 12 max | M23: 16 max | N23: 20 max | O23: 20 max
E26: CLASIFICACION AASHTO : | J26: =+D31&" "&F38 -> #DIV/0!
D29: =IF(AND(C11<=50,C12<=30,C13<=15,OR(C21<=6,C21="NP"),C23<=0),D6,"--") -> #DIV/0! | E29: =IF(AND(C12<=50,C13<=25,OR(C21<=6,C21="NP"),C23<=0),E6,"--") -> #DIV/0! | F29: =IF(AND(C12>50,C13<=10,OR(C20="N.P.",C20="NP",C20=0),OR(C21="N.P.",C21="NP",C21=0),C23<=0),F5,"--") -> #DIV/0! | G29: =IF(AND(C13<=35,OR(C20<=40,C20="NP"),OR(C21<=10,C21="NP"),C23<=0),G6,"--") -> #DIV/0! | H29: =IF(AND(C13<=35,C20>40,C20<>"NP",C21<=10,C21<>"NP",C23<=0),H6,"--") -> #DIV/0! | I29: =IF(AND(C13<=35,C20<=40,C20<>"NP",C23<=4,C21>10,C21<>"NP"),I6,"--") -> #DIV/0! | J29: =IF(AND(C13<=35,C20>40,C20<>"NP",C21>10,C23<=4,C21<>"NP"),J6,"--") -> #DIV/0! | K29: =IF(AND(C13>35,OR(C20<=40,C20="NP"),OR(C21<=10,C21="NP"),C23<=8),K5,"--") -> #DIV/0! | L29: =IF(AND(C13>35,C20>40,C20<>"NP",C21<=10,C21<>"NP",C23<=12),L5,"--") -> #DIV/0! | M29: =IF(AND(C13>35,C20<=40,C21>10,C23<=16,C21<>"NP"),M5,"--") -> #DIV/0! | N29: =IF(AND(C13>35,C20<>"NP",C20>40,C21<>"NP",C21>10,C23<=20),IF(C20-C21>30,N6,"--"),"--") -> #DIV/0! | O29: =IF(AND(C13>35,C20>40,C20<>"NP",C21>10,C21<>"NP",C23<=20),IF(C20-C21<=30,O6,"--"),"--") -> #DIV/0!
D30: =IF(D29<>"--",D29,"") -> #DIV/0! | E30: =IF(AND(D29="--",E29<>"--"),E29,"") -> #DIV/0! | F30: =IF(AND(D29="--",E29="--",F29<>"--"),F29,"") -> #DIV/0! | G30: =IF(AND(D29="--",E29="--",F29="--",G29<>"--"),G29,"") -> #DIV/0! | H30: =IF(AND(D29="--",E29="--",F29="--",G29="--",H29<>"--"),H29,"") -> #DIV/0! | I30: =IF(AND(D29="--",E29="--",F29="--",G29="--",H29="--",I29<>"--"),I29,"") -> #DIV/0! | J30: =IF(AND(D29="--",E29="--",F29="--",G29="--",H29="--",I29="--",J29<>"--"),J29,"") -> #DIV/0! | K30: =IF(K29<>"--",K29,"") -> #DIV/0! | L30: =IF(AND(K29="--",L29<>"--"),L29,"") -> #DIV/0! | M30: =IF(AND(K29="--",L29="--",M29<>"--"),M29,"") -> #DIV/0! | N30: =IF(AND(K29="--",L29="--",M29="--",N29<>"--"),N29,"") -> #DIV/0! | O30: =IF(AND(K29="--",L29="--",M29="--",N29="--",O29<>"--"),O29,"") -> #DIV/0!
D31: =+D30&E30&F30&G30&H30&I30&J30&K30&L30&M30&N30&O30 -> #DIV/0!
C33: A | D33: =+IF(C13>75,40,IF(C13<35,1,IF(C13<40,40-C13,C13-40))) -> #DIV/0!
C34: B | D34: =+IF(C13>55,40,IF(C13<15,1,C13-15)) -> #DIV/0!
C35: C | D35: =+IF(C20="NP",1,IF(C20>60,20,IF(C20<40,1,C20-40))) -> 1
C36: D | D36: =+IF(C21="NP",1,IF(C21>30,20,IF(C21<10,1,C21-10))) -> 1
C38: =0.2*D33+0.005*D33*D35+0.01*D34*D36 -> #DIV/0! | D38: =ROUND(C38,0) -> #DIV/0! | F38: =+"("&D38&")" -> #DIV/0!

Sheet Hoja1
A2: CODIGO | C2: CONCATENADOS | D2: DESCRIPCION | E2: FC | F2: F. MOLDEO | G2: DIA | H2: DIAMETRO | I2: CARGA | J2: AREA | K2: RESIS. CONCRETO | L2: % RESIS | M2: TIPO DE FALLA
A3: 4400 | B3: =+A3+1 -> 4401 | C3: =A3&"-"&B3 -> 4400-4401 | D3: Columnas C-9;5-3/G.H | E3: 350 | F3: 42347 | G3: 7 | H3: 15.05 | I3: 49900 | J3: =H3*H3*PI()/4 -> 177.89465 | K3: =I3/J3 -> 280.5031 | L3: =+K3/E3 -> 0.80143743 | M3: E
C4: =A4&"-"&B4 -> - | E4: 350 | G4: 7 | H4: 15.06 | I4: 50310 | J4: =H4*H4*PI()/4 -> 178.13113 | K4: =I4/J4 -> 282.43238 | L4: =+K4/E4 -> 0.80694967 | M4: F
A5: =+B3+1 -> 4402 | B5: =+A5+1 -> 4403 | C5: =A5&"-"&B5 -> 4402-4403 | E5: 350 | G5: 14 | H5: 15.04 | I5: 56450 | J5: =H5*H5*PI()/4 -> 177.65832 | K5: =I5/J5 -> 317.74476 | L5: =+K5/E5 -> 0.90784216 | M5: F
C6: =A6&"-"&B6 -> - | E6: 350 | G6: 14 | H6: 15 | I6: 59630 | J6: =H6*H6*PI()/4 -> 176.71459 | K6: =I6/J6 -> 337.43677 | L6: =+K6/E6 -> 0.96410507 | M6: F
A7: =+B5+1 -> 4404 | B7: =+A7+1 -> 4405 | C7: =A7&"-"&B7 -> 4404-4405 | E7: 350 | G7: 28 | H7: 15.11 | I7: 65310 | J7: =H7*H7*PI()/4 -> 179.3159 | K7: =I7/J7 -> 364.21755 | L7: =+K7/E7 -> 1.0406216 | M7: F
C8: =A8&"-"&B8 -> - | E8: 350 | G8: 28 | H8: 15.05 | I8: 64730 | J8: =H8*H8*PI()/4 -> 177.89465 | K8: =I8/J8 -> 363.86705 | L8: =+K8/E8 -> 1.0396201 | M8: E
