Workbook
Name ___CC2: [1]Sucs!$L$6
Name __CC2: [1]Sucs!$L$6
Name _CC1: [2]Sucs!$L$6
Name _CC2: [1]Sucs!$L$6
Name _CU1: [2]Sucs!$L$5
Name _IP1: [2]Sucs!$L$4
Name _L1: #REF!
Name _L1: #REF!
Name _Ll1: [2]Sucs!$L$3
Name _W1: #REF!
Name _W1: #REF!
Name Abra: [3]Sucs!$C$3
Name CC: #REF!
Name CC: #REF!
Name CCf: '[2]Sucs(Fino)'!$L$6
Name CCVB: [4]Sucs!$L$3
Name CM: [5]BGA!$H$9
Name CU: #REF!
Name CU: #REF!
Name CUf: '[2]Sucs(Fino)'!$L$5
Name hh: #REF!
Name hh: #REF!
Name IP: #REF!
Name IP: #REF!
Name IPf: '[2]Sucs(Fino)'!$L$4
Name L: #REF!
Name L: #REF!
Name LIf: '[2]Sucs(Fino)'!$L$3
Name Ll: #REF!
Name Ll: #REF!
Name MORA: [5]BGA!$H$13
Name N_10: #REF!
Name N_10: #REF!
Name N_101: [2]Sucs!$C$5
Name N_10f: '[2]Sucs(Fino)'!$C$5
Name N_200: #REF!
Name N_200: #REF!
Name N_2001: [2]Sucs!$C$3
Name N_200f: '[2]Sucs(Fino)'!$C$3
Name N_40: #REF!
Name N_40: #REF!
Name N_401: [2]Sucs!$C$4
Name N_40f: '[2]Sucs(Fino)'!$C$4
Name PC: [4]Sucs!$C$5
Name TABLA: #REF!
Name TABLA: #REF!
Name tipodegranulometria: '[6]G-LL '!$X$2:$X$3
Name tipodegranulometria: '[6]G-LL '!$X$2:$X$3
Name tipodemateria: '[6]G-LL '!$X$5:$X$6
Name tipodemateria: '[6]G-LL '!$X$5:$X$6
Name W: #REF!
Name W: #REF!

Sheet DENSIDAD
A5: LABORATORIO DE ENSAYO DE MATERIALES
A6: 0
A8: CLIENTE | B8: : | I8: CÓDIGO : | J8: F-LEM-P-SU-06.02
A9: DIRECCIÓN ** | B9: : | I9: RECEPCIÓN N° : | J9: 0
A10: PROYECTO ** | B10: : | I10: OT N° : | J10: 0
A11: UBICACIÓN ** | B11: : | I11: FECHA RECEPCIÓN : | J11: 0
A12: ** Datos proporcionados por el cliente | I12: FECHA EMISIÓN : | J12: 0
A14: SUELOS. MÉTODO DE ENSAYO ESTÁNDAR PARA LA DENSIDAD Y PESO UNITARIO DEL SUELO IN-SITU MEDIANTE EL MÉTODO DEL CONO DE ARENA
A15: NTP 339.143 1999 (revisada el 2019)
A17: Datos Cono | G17: Datos ensayo | I17: Datos material compactado
A18: Identificación Cono N° | D18: : | E18: =+Datos!L2 -> EQ.DENS. 1 | G18: Fecha de ensayo | H18: =+Datos!D8 -> 0 | I18: Norma ensayo de Proctor : | J18: ASTM D1557-12 (Reapproved 2021)
A19: =+Datos!G5 -> Masa de arena embudo y placa | D19: : | E19: =+Datos!I5 -> 0 | F19: g | G19: Ensayado por : | H19: =+Datos!D9 -> - | I19: Método de ensayo : | J19: C
A20: =+Datos!G6 -> Densidad de la arena | D20: : | E20: =+Datos!I6 -> 0 | F20: g/cm3 | I20: Peso Unitario Seco(kN/ m3) : | J20: =+Datos!E4 -> 0
A21: Volumen calibrado cono | D21: : | E21: =+Datos!I7 -> 0 | F21: cm3 | I21: Humedad Optima (%) : | J21: =+Datos!E5 -> 0
I22: Gravedad específica : | J22: =+Datos!E6 -> 0
A24: DESCRIPCIÓN | G24: PRUEBA 1 | H24: PRUEBA 2 | I24: PRUEBA 3 | J24: PRUEBA 4
A25: Ubicación de la prueba** | G25: =+Datos!E13 -> 0 | H25: =+Datos!G13 -> 0 | I25: =+Datos!I13 -> 0 | J25: =+Datos!K13 -> 0
A26: Progresiva/ Cota / Lado** | G26: =+Datos!E14 -> - | H26: =+Datos!G14 -> - | I26: =+Datos!I14 -> - | J26: =+Datos!K14 -> -
A27: Tipo de Muestra(**) | G27: =+Datos!E15 -> - | H27: =+Datos!G15 -> - | I27: =+Datos!I15 -> - | J27: =+Datos!K15 -> -
A28: Descripción visual del suelo | G28: =+Datos!E19 -> 0 | H28: =+Datos!G19 -> 0 | I28: =+Datos!I19 -> 0 | J28: =+Datos!K19 -> 0
A29: Espesor de la capa** | F29: cm | G29: =+Datos!E16 -> - | H29: =+Datos!G16 -> - | I29: =+Datos!I16 -> - | J29: =+Datos!K16 -> -
A30: Volumen del orificio de prueba | F30: cm3 | G30: =Datos!F26 -> #DIV/0! | H30: =Datos!H26 -> #DIV/0! | I30: =Datos!J26 -> #DIV/0! | J30: =Datos!L26 -> #DIV/0!
A31: Tamiz del sobretamaño | G31: =+Datos!E18 -> - | H31: =+Datos!G18 -> - | I31: =+Datos!I18 -> - | J31: =+Datos!K18 -> -
A32: Masa de sobretamaño | F32: g | G32: =+Datos!F30 -> 0 | H32: =+Datos!H30 -> 0 | I32: =+Datos!J30 -> 0 | J32: =+Datos!L30 -> 0
A33: Porcentaje de sobretamaño | F33: % | G33: =+IF(Datos!F31<10, TEXT(ROUND(Datos!F31, 2), "0.00"), TEXT(ROUND(Datos!F31,1),"0.0")) -> #DIV/0! | H33: =+IF(Datos!H31<10, TEXT(ROUND(Datos!H31, 2), "0.00"), TEXT(ROUND(Datos!H31,1),"0.0")) -> #DIV/0! | I33: =+IF(Datos!J31<10, TEXT(ROUND(Datos!J31, 2), "0.00"), TEXT(ROUND(Datos!J31,1),"0.0")) -> #DIV/0! | J33: =+IF(Datos!L31<10, TEXT(ROUND(Datos!L31, 2), "0.00"), TEXT(ROUND(Datos!L31,1),"0.0")) -> #DIV/0!
A34: Densidad húmeda in situ | F34: g/cm3 | G34: =+Datos!F32 -> #DIV/0! | H34: =+Datos!H32 -> #DIV/0! | I34: =+Datos!J32 -> #DIV/0! | J34: =+Datos!L32 -> #DIV/0!
A35: Densidad seca in situ | F35: g/cm3 | G35: =+Datos!F33 -> #DIV/0! | H35: =+Datos!H33 -> #DIV/0! | I35: =+Datos!J33 -> #DIV/0! | J35: =+Datos!L33 -> #DIV/0!
A36: Peso unitario seco in situ | F36: kN/m3 | G36: =+Datos!F34 -> #DIV/0! | H36: =+Datos!H34 -> #DIV/0! | I36: =+Datos!J34 -> #DIV/0! | J36: =+Datos!L34 -> #DIV/0!
A37: GRADO DE COMPACTACIÓN
A38: =+Datos!C38 -> Peso unitario corregido (D4718/D4718M-15(2023)) | F38: kN/m3 | G38: =+Datos!F38 -> #DIV/0! | H38: =+Datos!H38 -> #DIV/0! | I38: =+Datos!J38 -> #DIV/0! | J38: =+Datos!L38 -> #DIV/0!
A39: Porcentaje de compactación | F39: % | G39: =+Datos!F39 -> #DIV/0! | H39: =+Datos!H39 -> #DIV/0! | I39: =+Datos!J39 -> #DIV/0! | J39: =+Datos!L39 -> #DIV/0!
A40: Criterio de aceptación ** | F40: % | G40: =+Datos!F40 -> 0 | H40: =+Datos!H40 -> 0 | I40: =+Datos!J40 -> 0 | J40: =+Datos!L40 -> 0
A41: CONTENIDO DE HUMEDAD
A42: Contenido de agua in situ (ASTM D2216-19) | F42: % | G42: =+Datos!F44 -> 0 | H42: =+Datos!H44 -> 0 | I42: =+Datos!J44 -> 0 | J42: =+Datos!L44 -> 0
A44: Nota:
A45: - El cliente es responsable de los datos de identificación de los puntos de ensayo brindados.
A46: - Los resultados expresados se refieren únicamente al ensayo realizado en dicho momento y en las condiciones especificadas en este documento, por lo que GEOFAL S.A.C. no será responsable por los ensayos realizados con la presente muestra en condiciones distintas a las aquí señaladas.
A47: - GEOFAL S.A.C. no se hace responsable por el uso incorrecto o inadecuado del presente informe.
A48: - Los resultados de los ensayos realizados no deben ser utilizados como una certificación de conformidad con normas de producto o como certificado del sistema de calidad de la entidad que lo produce.
A49: - De conformidad con lo dispuesto por el artículo 1321 del Código Civil, queda establecido que en ningún caso la responsabilidad de GEOFAL S.A.C. será mayor al valor del servicio prestado.
...

Sheet DENSIDAD NATURAL EMS
A7: LABORATORIO DE ENSAYO DE MATERIALES
A8: 115
A10: CLIENTE | B10: : | J10: CÓDIGO: | K10: F-LEM-P-SU-06.02
A11: DIRECCIÓN ** | B11: : | J11: N° OT: | K11: 185
A12: PROYECTO ** | B12: : | J12: F. EMISIÓN : | K12: 44662
A13: UBICACIÓN ** | B13: :
A14: ** Datos proporcionados por el cliente
A15: MÉTODO DE ENSAYO PARA DETERMINAR LA DENSIDAD Y PESO UNITARIO DEL SUELO IN-SITU MEDIANTE EL MÉTODO DEL CONO DE ARENA
A16: NORMA NTP 339.143
A18: PESO ARENA CONO | D18: : | E18: 1704 | J18: CONO N° : | K18: 2
A19: DENSIDAD ARENA | D19: : | E19: 1.422 | J19: FECHA DE ENSAYO : | K19: 43997
A21: ENSAYO Nº | G21: 1 | O21: DENSIAD NATURAL
A22: UBICACIÓN/CALICATA | O22: UBICACION/CALICATA
A23: CAPA/ESTRATO | O23: CAPA/ESTRATO
A24: Peso Inicial de arena | F24: gr | G24: =+R24 -> 7536 | O24: Peso Inicial de arena | Q24: gr | R24: 7536 | T24: 7000 - 7600
A25: Peso Residual arena | F25: gr | G25: =+R25 -> 3212 | O25: Peso Residual arena | Q25: gr | R25: 3212
A26: Peso arena hueco | F26: gr | G26: =G24-G25-$E$18 -> 2620 | O26: Peso arena hueco | Q26: gr | R26: =R24-R25-$E$18 -> 2620
A27: Volumen hueco | F27: cm3 | G27: =+G26/$E$19 -> 1842.4754 | O27: Volumen hueco | Q27: cm3 | R27: =+R26/$E$19 -> 1842.4754 | T27: 1800 - 2100
A28: Peso Suelo Extraido | F28: gr | G28: =+R28 -> 3594 | O28: Peso Suelo Extraido | Q28: gr | R28: 3594
A29: Densidad húmeda | F29: gr/cm3 | G29: =G28/G27 -> 1.9506366 | O29: Densidad húmeda | Q29: gr/cm3 | R29: =R28/R27 -> 1.9506366
A30: Densidad Seca | F30: gr/cm3 | G30: =+G29/(G34+100)% -> 1.8577492 | O30: Densidad Seca | Q30: gr/cm3 | R30: =+R29/(R32+100)% -> 1.8577492
A31: Peso unitario seco | F31: kN/m3 | G31: =G30*9.8066358553 -> 18.21827 | O31: Peso unitario seco | Q31: kN/m3 | R31: =R30*9.8066358553 -> 18.21827
A32: CONTENIDO DE HUMEDAD | O32: humedad (NTP 339.127) | Q32: % | R32: 5
A33: Con Speedy ( NTP 339.250 ) | F33: % | G33: 7 | O33: DENSIAD CORREGIDA
A34: humedad (NTP 339.127) | F34: % | G34: =+R32 -> 5 | O34: Porcentaje de grava | Q34: % | R34: 50.7
O35: Peso de la grava | Q35: gr | R35: =R28*R34/100 -> 1822.158
A36: =+DENSIDAD!#REF! -> #REF! | O36: Densidad de la grava | Q36: gr/cm3 | R36: 2.642
A37: Los puntos de ensayos fueron ubicados e identificada por el solicitante. | O37: Volumen de grava | Q37: cm3 | R37: =R35/R36 -> 689.68887
A38: Medidor de humedad, marca FORNEY, modelo LA-3405-19. | O38: Peso Suelo | Q38: gr | R38: =R28-R35 -> 1771.842
A39: Balanza, capacidad: 15 kg, marca OHAUS, modelo V11P15T. | O39: Volumen del suelo | Q39: cm3 | R39: =R27-R37 -> 1152.7865
A40: Balanza, capacidad: 500 g, marca OHAUS, modelo YA501. | O40: Densidad húmeda | Q40: gr/cm3 | R40: =+R38/R39 -> 1.5370079
A42: =+DENSIDAD!#REF! -> #REF!
A43: =+DENSIDAD!#REF! -> #REF!
A44: =+DENSIDAD!#REF! -> #REF!
A45: =+DENSIDAD!#REF! -> #REF!
K46: Fin del informe
A51: Página 1 de 1
A52: =+DENSIDAD!A57 -> Versión: 05 (2026-05-26)

Sheet Datos
B1: SUELOS. MÉTODO DE ENSAYO PARA DETERMINAR LA DENSIDAD Y PESO UNITARIO DEL SUELO IN-SITU MEDIANTE EL MÉTODO DEL CONO DE ARENA NTP 339.143 1999 (revisada el 2019) | L1: BALANZA UTILIZADA 30KG
L2: EQ.DENS. 1 | M2: =+LOOKUP(L2,L4:L8,M4:M8) -> EQP-0108 | N2: =+LOOKUP(L2,L4:L7,N4:N7) -> -3.42e-06 | Q2: DATO EQUIPO DENSIDADES | V2: TAMAÑO MAX. GRAVA | W2: TAMIZ SOBRETAMAÑO | X2: METODO PROCTOR | Y2: VOLUMEN MINIMO ORIFICIO | Z2: ENSAYO PROCTOR
C3: INFORMACIÓN MAT. COMPACTADO (proctor) | D3: UND | E3: DATOS | G3: EQUIPO DENSIDADES | I3: EQ.DENS. 1 | L3: EQUIPO | M3: CODIGO BALANZA | N3: CORRECCION | O3: FECHA CALIBRACIÓN | Q3: Equipo cono N° | R3: Masa de arena embudo y placa | S3: ρ arena (g/cm3) | T3: Volumen (cm3) | V3: 1 1/2 in | W3: 3/4 in | X3: C | Y3: 2830 | Z3: ASTM D1557-12 (Reapproved 2021)
C4: Peso unitario seco máximo | D4: kN/m3 | E4: 0 | G4: Identificación cono N° | I4: =+LOOKUP(I3,Q11:Q15,R11:R15) -> EQP-0107 | J4: und | L4: EQ.DENS. 1 | M4: =+Balanza!C11 -> EQP-0108 | N4: =+Balanza!C7 -> -3.42e-06 | O4: =+Balanza!C12 -> 46177 | Q4: CONO 1 | R4: 1567 | S4: 1.391 | T4: 1127 | V4: 1 in | W4: 3/8 in | X4: B | Y4: 2120 | Z4: ASTM D698
C5: % humedad óptima | D5: % | E5: 0 | G5: Masa de arena embudo y placa | J5: g | K5: M2 | L5: EQ.DENS. 2 | M5: =+Balanza!Q11 -> EQP-0093 | N5: =+Balanza!Q7 -> 2.31e-05 | O5: =+Balanza!Q12 -> 46160 | Q5: CONO 2 | R5: 1505 | S5: 1.392 | T5: 1081 | V5: 3/4 in | W5: N°4 | X5: A | Y5: 2120 | Z5: NTP 339.141:1999 (Revisado 2014)
C6: Gravedad específica( ASTM C127) | D6: - | E6: 0 | G6: Densidad de la arena | J6: (g/cm3) | K6: p1 | L6: EQ.DENS. 3 | M6: EQP-0147 | N6: -7.47e-06 | O6: 46086 | Q6: CONO 3 | R6: 1888 | S6: 1.399 | T6: 1349 | V6: 1/2 in | W6: - | X6: - | Y6: 1420 | Z6: NTP 339.142:1999 (Revisado 2014)
C7: DATOS ENSAYO | G7: Volumen calibrado cono | J7: (cm3) | L7: EQ.DENS. 4 | M7: EQP-0133 | N7: -2.96e-06 | O7: 45931 | Q7: CONO 4 | R7: 1492 | S7: 1.396 | T7: 1069 | V7: 3/8 in | W7: - | X7: - | Y7: 1420 | Z7: -
C8: Fecha de ensayo | D8: 0 | G8: molde calibracion arena | I8: INS-0005 | L8: EQ.DENS. 5 | M8: EQP-0142 | N8: -9.65e-06 | O8: 45981 | Q8: CONO 5 | R8: 1503 | S8: 1.41 | T8: 1066
C9: Ensayado por | D9: - | Q9: EQUIPO DENSIDADES 15/09/25
Q10: EQUIPO | R10: CODIGO CONO
C11: Descripción | D11: Und | E11: 1 | G11: 2 | I11: 3 | K11: 4 | Q11: EQ.DENS. 1 | R11: EQP-0107
E12: Datos | F12: Corrección | G12: Datos | H12: Corrección | I12: Datos | J12: Corrección | K12: Datos | L12: Corrección | Q12: EQ.DENS. 2 | R12: EQP-0096
C13: Ubicación de la prueba* | E13: 0 | G13: 0 | I13: 0 | K13: 0 | Q13: EQ.DENS. 3 | R13: EQP-0034
C14: Progresiva/ Cota / Lado* | E14: - | G14: - | I14: - | K14: - | Q14: EQ.DENS. 4 | R14: EQP-0129
C15: Tipo de Muestra ** | E15: - | G15: - | I15: - | K15: - | M15: BASE-SUBBASE-RELLENO-SUBRASANTE | Q15: EQ.DENS. 5 | R15: EQP-0143
C16: Espesor de la capa* | D16: cm | E16: - | G16: - | I16: - | K16: -
C17: Tamaño Maximo de grava identificado | E17: - | G17: - | I17: - | K17: -
C18: Tamiz del Sobretamaño. | E18: - | G18: - | I18: - | K18: -
C19: Descripción visual del suelo ** | M19: Grava arenosa color beige
C20: Condiciones de entorno (1) | E20: Ninguno | G20: Ninguno | I20: Ninguno | K20: Ninguno
A22: A | C22: Masa inicial del cono mas arena | D22: g | E22: 0 | F22: =E22+($N$2*E22) -> 0 | G22: 0 | H22: =G22+($N$2*G22) -> 0 | I22: 0 | J22: =I22+($N$2*I22) -> 0 | K22: 0 | L22: =K22+($N$2*K22) -> 0
A23: B | C23: Masa Residual del cono mas arena | D23: g | E23: 0 | F23: =E23+($N$2*E23) -> 0 | G23: 0 | H23: =G23+($N$2*G23) -> 0 | I23: 0 | J23: =I23+($N$2*I23) -> 0 | K23: 0 | L23: =K23+($N$2*K23) -> 0
A24: C | B24: M1 | C24: Masa de arena utilizada en el orificio de prueba, el embudo y la placa base | D24: g | F24: =+F22-F23 -> 0 | H24: =+H22-H23 -> 0 | J24: =+J22-J23 -> 0 | L24: =+L22-L23 -> 0
A25: D | B25: M2 | C25: Masa de arena utilizada para llenar el embudo y la placa base | D25: g | F25: =+I5 -> 0 | H25: =+I5 -> 0 | J25: =+I5 -> 0 | L25: =+I5 -> 0
A26: E | B26: V | C26: Volumen del orificio de prueba | D26: cm3 | F26: =+(F24-$F$25)/$I$6 -> #DIV/0! | H26: =+(H24-$H$25)/$I$6 -> #DIV/0! | J26: =+(J24-$J$25)/$I$6 -> #DIV/0! | L26: =+(L24-$L$25)/$I$6 -> #DIV/0! | M26: 4 digitos
C27: Criterio de Aceptación de mínimos Volumenes | E27: =IF(E17="2 in",2830,IF(E17="1 1/2 in",2830,IF(E17="1 in",2120,IF(E17="3/4 in",2120,IF(E17="1/2 in",1420,IF(E17="3/8 in",1420,1420)))))) -> 1420 | F27: =+IF(F26>E27,"Cumple","Justificar") -> #DIV/0! | G27: =IF(G17="2 in",2830,IF(G17="1 1/2 in",2830,IF(G17="1 in",2120,IF(G17="3/4 in",2120,IF(G17="1/2 in",1420,IF(G17="3/8 in",1420,1420)))))) -> 1420 | H27: =+IF(H26>G27,"Cumple","Justificar") -> #DIV/0! | I27: =IF(I17="2 in",2830,IF(I17="1 1/2 in",2830,IF(I17="1 in",2120,IF(I17="3/4 in",2120,IF(I17="1/2 in",1420,IF(I17="3/8 in",1420,1420)))))) -> 1420 | J27: =+IF(J26>I27,"Cumple","Justificar") -> #DIV/0! | K27: =IF(K17="2 in",2830,IF(K17="1 1/2 in",2830,IF(K17="1 in",2120,IF(K17="3/4 in",2120,IF(K17="1/2 in",1420,IF(K17="3/8 in",1420,1420)))))) -> 1420 | L27: =+IF(L26>K27,"Cumple","Justificar") -> #DIV/0!
A28: F | B28: M3 | C28: Masa húmeda de material del orificio de prueba | D28: g | E28: 0 | F28: =E28+($N$2*E28) -> 0 | G28: 0 | H28: =G28+($N$2*G28) -> 0 | I28: 0 | J28: =I28+($N$2*I28) -> 0 | K28: 0 | L28: =K28+($N$2*K28) -> 0
A29: G | B29: M4 | C29: Masa seca de material del orificio de prueba | D29: g | F29: =100*F28/(F44+100) -> 0 | H29: =100*H28/(H44+100) -> 0 | J29: =100*J28/(J44+100) -> 0 | L29: =100*L28/(L44+100) -> 0
A30: H | C30: Masa de sobretamaño | D30: g | E30: 0 | F30: =E30+($N$2*E30) -> 0 | G30: 0 | H30: =G30+($N$2*G30) -> 0 | I30: 0 | J30: =I30+($N$2*I30) -> 0 | K30: 0 | L30: =K30+($N$2*K30) -> 0
A31: I | C31: Porcentaje de Sobretamaño | D31: % | F31: =+(F30/F28)*100 -> #DIV/0! | H31: =+(H30/H28)*100 -> #DIV/0! | J31: =+(J30/J28)*100 -> #DIV/0! | L31: =+(L30/L28)*100 -> #DIV/0! | M31: 3 digitos informe
A32: J | B32: pm | C32: Densidad húmeda in situ | D32: g/cm3 | F32: =+F28/F26 -> #DIV/0! | H32: =+H28/H26 -> #DIV/0! | J32: =+J28/J26 -> #DIV/0! | L32: =+L28/L26 -> #DIV/0! | M32: 3 digito
A33: K | B33: pd | C33: Densidad seca in situ | D33: g/cm3 | F33: =F29/F26 -> #DIV/0! | H33: =H29/H26 -> #DIV/0! | J33: =J29/J26 -> #DIV/0! | L33: =L29/L26 -> #DIV/0! | M33: 3 digito
A34: L | B34: δD | C34: Peso unitario seco in situ | D34: kN/m3 | F34: =+F33*9.802 -> #DIV/0! | H34: =+H33*9.802 -> #DIV/0! | J34: =+J33*9.802 -> #DIV/0! | L34: =+L33*9.802 -> #DIV/0!
B36: GRADO DE COMPACTACIÓN
A37: M | C37: Peso unitario seco laboratorio | D37: kN/m3 | F37: =+$E$4 -> 0 | H37: =+$E$4 -> 0 | J37: =+$E$4 -> 0 | L37: =+$E$4 -> 0 | M37: reporte al 0,1
A38: N | C38: Peso unitario corregido (D4718/D4718M-15(2023)) | D38: kN/m3 | F38: =IF(E6="",F34,IF(E6="-",F34,F34*$E$6*9.802*(100-F31)/((100*$E$6)*9.802-F34*F31))) -> #DIV/0! | H38: =IF(E6="",H34,IF(E6="-",H34,H34*$E$6*9.802*(100-H31)/((100*$E$6)*9.802-H34*H31))) -> #DIV/0! | J38: =IF(E6="",J34,IF(E6="-",J34,J34*$E$6*9.802*(100-J31)/((100*$E$6)*9.802-J34*J31))) -> #DIV/0! | L38: =IF(E6="",L34,IF(E6="-",L34,L34*$E$6*9.802*(100-L31)/((100*$E$6)*9.802-L34*L31))) -> #DIV/0!
C39: Porcentaje compactaciòn | D39: % | F39: =+F38/F37*100 -> #DIV/0! | H39: =+H38/H37*100 -> #DIV/0! | J39: =+J38/J37*100 -> #DIV/0! | L39: =+L38/L37*100 -> #DIV/0!
C40: CRITERIO DE ACEPTACIÓN * | D40: % | F40: 0 | H40: 0 | J40: 0 | L40: 0
B42: CONTENIDO HUMEDAD
B43: W* | C43: Contenido de agua SPEEDY (***) | D43: % | F43: 0 | H43: 0 | J43: 0 | L43: 0
...

Sheet Incertidumbre
C1: INFORME DE ESTIMACIÓN DE INCERTIDUMBRE | N1: Código: | O1: F-LEM-P-10.01
N2: Versión: | O2: 3
N3: Fecha: | O3: 46146
N4: Página: | O4: 1 de 1
B6: Método: | C6: Suelos. Método de ensayo estándar para la densidad y peso unitario del suelo in-situ mediante el método del cono de de arena.
B7: Norma: | C7: NTP 339.143 1999 (revisada el 2019)
B8: Matriz: | C8: Suelos naturales, agregados
B9: Mensurando: | C9: Densidad in-situ
B11: Paso 1. Definición del proceso de medición | K11: Paso 2. Definición de las variables aleatorias
B13: Variables: | F13: Fórmula:
B15: M3 = Masa húmeda del orificio de prueba , g.
B16: V = Volumen del orificio de prueba, cm3.
B17: M4 = Masa seca del orifico de prueba, g.
B18: pm = Densidad húmeda
B19: pd = Densidad seca
B21: Equipos a utilizar:
B23: Balanza con resolución de lectura de 1g
B24: Horno que puea mantener una temperatura uniforme de 110 ± 5°C
B26: PRUEBA 1 | K26: PRUEBA 2 | R26: PRUEBA 3 | Y26: PRUEBA 4
B27: Fuentes | C27: Und | D27: Valor | E27: Incertidumbre Original | F27: Distribución | G27: Incertidumbre Estándar u(xi) | H27: Coeficiente de Sensibilidad | I27: Contribución ui(y) | K27: Valor | L27: Incertidumbre Original | M27: Distribución | N27: Incertidumbre Estándar u(xi) | O27: Coeficiente de Sensibilidad | P27: Contribución ui(y) | R27: Valor | S27: Incertidumbre Original | T27: Distribución | U27: Incertidumbre Estándar u(xi) | V27: Coeficiente de Sensibilidad | W27: Contribución ui(y) | Y27: Valor | Z27: Incertidumbre Original | AA27: Distribución | AB27: Incertidumbre Estándar u(xi) | AC27: Coeficiente de Sensibilidad | AD27: Contribución ui(y)
A28: pm | B28: Densidad húmeda in situ | C28: g/cm3 | D28: =+D29/D33 -> #DIV/0! | K28: =+K29/K33 -> #DIV/0! | R28: =+R29/R33 -> #DIV/0! | Y28: =+Y29/Y33 -> #DIV/0!
A29: M3 | B29: Masa húmeda de material del orificio de prueba | C29: g | D29: =+Datos!F28 -> 0 | E29: --- | F29: --- | G29: =SQRT((G30*G30)+(G31*G31)+(G32*G32)) -> 0.87996212 | H29: =1/D33 -> #DIV/0! | I29: =+H29*G29 -> #DIV/0! | K29: =+Datos!H28 -> 0 | L29: --- | M29: --- | N29: =SQRT((N30*N30)+(N31*N31)+(N32*N32)) -> 0.87996212 | O29: =1/K33 -> #DIV/0! | P29: =+O29*N29 -> #DIV/0! | R29: =+Datos!J28 -> 0 | S29: --- | T29: --- | U29: =SQRT((U30*U30)+(U31*U31)+(U32*U32)) -> 0.87996212 | V29: =1/R33 -> #DIV/0! | W29: =+V29*U29 -> #DIV/0! | Y29: =+Datos!L28 -> 0 | Z29: --- | AA29: --- | AB29: =SQRT((AB30*AB30)+(AB31*AB31)+(AB32*AB32)) -> 0.87996212 | AC29: =1/Y33 -> #DIV/0! | AD29: =+AC29*AB29 -> #DIV/0!
B30: Repetibilidad de la pesada | C30: g | E30: =IF(Datos!$L$2="CONO 1",Balanza!H25,Balanza!V25) -> 0 | F30: Normal, K=1 | G30: =+E30 -> 0 | H30: --- | I30: --- | L30: =IF(Datos!$L$2="CONO 1",Balanza!J25,Balanza!X25) -> 0 | M30: Normal, K=1 | N30: =+L30 -> 0 | O30: --- | P30: --- | S30: =IF(Datos!$L$2="CONO 1",Balanza!L25,Balanza!Z25) -> 0 | T30: Normal, K=1 | U30: =+S30 -> 0 | V30: --- | W30: --- | Z30: =IF(Datos!$L$2="CONO 1",Balanza!N25,Balanza!AB25) -> 0 | AA30: Normal, K=1 | AB30: =+Z30 -> 0 | AC30: --- | AD30: ---
B31: Certificado de Calibración | C31: g | E31: =IF(Datos!$L$2="CONO 1",2*(SQRT(Balanza!$C$8+Balanza!$D$8*(POWER(D29,2)))),2*(SQRT(Balanza!$Q$8+Balanza!$R$8*(POWER(D29,2))))) -> 1.6625282 | F31: Normal, K=2 | G31: =+E31/2 -> 0.8312641 | H31: --- | I31: --- | L31: =IF(Datos!$L$2="CONO 1",2*(SQRT(Balanza!$C$8+Balanza!$D$8*(POWER(K29,2)))),2*(SQRT(Balanza!$Q$8+Balanza!$R$8*(POWER(K29,2))))) -> 1.6625282 | M31: Normal, K=2 | N31: =+L31/2 -> 0.8312641 | O31: --- | P31: --- | S31: =IF(Datos!$L$2="CONO 1",2*(SQRT(Balanza!$C$8+Balanza!$D$8*(POWER(R29,2)))),2*(SQRT(Balanza!$Q$8+Balanza!$R$8*(POWER(R29,2))))) -> 1.6625282 | T31: Normal, K=2 | U31: =+S31/2 -> 0.8312641 | V31: --- | W31: --- | Z31: =IF(Datos!$L$2="CONO 1",2*(SQRT(Balanza!$C$8+Balanza!$D$8*(POWER(Y29,2)))),2*(SQRT(Balanza!$Q$8+Balanza!$R$8*(POWER(Y29,2))))) -> 1.6625282 | AA31: Normal, K=2 | AB31: =+Z31/2 -> 0.8312641 | AC31: --- | AD31: ---
B32: Resolución | C32: g | E32: =IF(Datos!$L$2="CONO 1",Balanza!$C$10,Balanza!$Q$10) -> 1 | F32: Rectangular | G32: =+E32/SQRT(3)/2 -> 0.28867513 | H32: --- | I32: --- | L32: =IF(Datos!$L$2="CONO 1",Balanza!$C$10,Balanza!$Q$10) -> 1 | M32: Rectangular | N32: =+L32/SQRT(3)/2 -> 0.28867513 | O32: --- | P32: --- | S32: =IF(Datos!$L$2="CONO 1",Balanza!$C$10,Balanza!$Q$10) -> 1 | T32: Rectangular | U32: =+S32/SQRT(3)/2 -> 0.28867513 | V32: --- | W32: --- | Z32: =IF(Datos!$L$2="CONO 1",Balanza!$C$10,Balanza!$Q$10) -> 1 | AA32: Rectangular | AB32: =+Z32/SQRT(3)/2 -> 0.28867513 | AC32: --- | AD32: ---
A33: V | B33: Volumen del orificio de prueba | C33: cm3 | D33: =+Datos!F26 -> #DIV/0! | G33: =+I80 -> #DIV/0! | H33: =+D29/D33^2 -> #DIV/0! | I33: =+H33*G33 -> #DIV/0! | K33: =+Datos!H26 -> #DIV/0! | N33: =+P80 -> #DIV/0! | O33: =+K29/K33^2 -> #DIV/0! | P33: =+O33*N33 -> #DIV/0! | R33: =+Datos!J26 -> #DIV/0! | U33: =+W80 -> #DIV/0! | V33: =+R29/R33^2 -> #DIV/0! | W33: =+V33*U33 -> #DIV/0! | Y33: =+Datos!L26 -> #DIV/0! | AB33: =+AD80 -> #DIV/0! | AC33: =+Y29/Y33^2 -> #DIV/0! | AD33: =+AC33*AB33 -> #DIV/0!
B34: factor de presición | C34: g/cm3 | D34: =+Precision!$B$6 -> 0.00289 | F34: Norma, K=1 | G34: =D34/SQRT(1) -> 0.00289 | H34: 1 | I34: =+G34*H34 -> 0.00289 | K34: =+D34 -> 0.00289 | M34: Norma, K=1 | N34: =K34/SQRT(1) -> 0.00289 | O34: 1 | P34: =+N34*O34 -> 0.00289 | R34: =+D34 -> 0.00289 | T34: Norma, K=1 | U34: =R34/SQRT(1) -> 0.00289 | V34: 1 | W34: =+U34*V34 -> 0.00289 | Y34: =+D34 -> 0.00289 | AA34: Norma, K=1 | AB34: =Y34/SQRT(1) -> 0.00289 | AC34: 1 | AD34: =+AB34*AC34 -> 0.00289
B35: Incertidumbre Estándar Combinada | I35: =SQRT(I29^2+I33^2+I34^2) -> #DIV/0! | P35: =SQRT(P29^2+P33^2+P34^2) -> #DIV/0! | W35: =SQRT(W29^2+W33^2+W34^2) -> #DIV/0! | AD35: =SQRT(AD29^2+AD33^2+AD34^2) -> #DIV/0!
B36: Incertidumbre Expandida, K = 2 | H36: g/cm3 | I36: =+I35*2 -> #DIV/0! | O36: g/cm3 | P36: =+P35*2 -> #DIV/0! | V36: g/cm3 | W36: =+W35*2 -> #DIV/0! | AC36: g/cm3 | AD36: =+AD35*2 -> #DIV/0!
B38: Fuentes | C38: Und | D38: Valor | E38: Incertidumbre Original | F38: Distribución | G38: Incertidumbre Estándar u(xi) | H38: Coeficiente de Sensibilidad | I38: Contribución ui(y) | K38: Valor | L38: Incertidumbre Original | M38: Distribución | N38: Incertidumbre Estándar u(xi) | O38: Coeficiente de Sensibilidad | P38: Contribución ui(y) | R38: Valor | S38: Incertidumbre Original | T38: Distribución | U38: Incertidumbre Estándar u(xi) | V38: Coeficiente de Sensibilidad | W38: Contribución ui(y) | Y38: Valor | Z38: Incertidumbre Original | AA38: Distribución | AB38: Incertidumbre Estándar u(xi) | AC38: Coeficiente de Sensibilidad | AD38: Contribución ui(y)
A39: pd | B39: Densidad seca in situ | C39: g/cm3 | D39: =D40/D41 -> #DIV/0! | K39: =K40/K41 -> #DIV/0! | R39: =R40/R41 -> #DIV/0! | Y39: =Y40/Y41 -> #DIV/0!
A40: M4 | B40: Masa seca de material del orificio de prueba | C40: g | D40: =100*D29/(D69+100) -> 0 | E40: --- | F40: --- | G40: =+I70 -> 0.87996212 | H40: =1/D41 -> #DIV/0! | I40: =+G40*H40 -> #DIV/0! | K40: =100*K29/(K69+100) -> 0 | L40: --- | M40: --- | N40: =+P70 -> 0.87996212 | O40: =1/K41 -> #DIV/0! | P40: =+N40*O40 -> #DIV/0! | R40: =100*R29/(R69+100) -> 0 | S40: --- | T40: --- | U40: =+W70 -> 0.87996212 | V40: =1/R41 -> #DIV/0! | W40: =+U40*V40 -> #DIV/0! | Y40: =100*Y29/(Y69+100) -> 0 | Z40: --- | AA40: --- | AB40: =+AD70 -> 0.87996212 | AC40: =1/Y41 -> #DIV/0! | AD40: =+AB40*AC40 -> #DIV/0!
A41: V | B41: Volumen del orificio de prueba | C41: cm3 | D41: =+Datos!F26 -> #DIV/0! | E41: --- | F41: --- | G41: =+I80 -> #DIV/0! | H41: =+D40/D41^2 -> #DIV/0! | I41: =+G41*H41 -> #DIV/0! | K41: =+Datos!H26 -> #DIV/0! | L41: --- | M41: --- | N41: =+P80 -> #DIV/0! | O41: =+K40/K41^2 -> #DIV/0! | P41: =+N41*O41 -> #DIV/0! | R41: =+Datos!J26 -> #DIV/0! | S41: --- | T41: --- | U41: =+W80 -> #DIV/0! | V41: =+R40/R41^2 -> #DIV/0! | W41: =+U41*V41 -> #DIV/0! | Y41: =+Datos!L26 -> #DIV/0! | Z41: --- | AA41: --- | AB41: =+AD80 -> #DIV/0! | AC41: =+Y40/Y41^2 -> #DIV/0! | AD41: =+AB41*AC41 -> #DIV/0!
B42: Incertidumbre Estándar Combinada | I42: =SQRT(I40^2+I41^2) -> #DIV/0! | P42: =SQRT(P40^2+P41^2) -> #DIV/0! | W42: =SQRT(W40^2+W41^2) -> #DIV/0! | AD42: =SQRT(AD40^2+AD41^2) -> #DIV/0!
B43: Incertidumbre Expandida, K = 2 | H43: g/cm3 | I43: =+I42*2 -> #DIV/0! | O43: g/cm3 | P43: =+P42*2 -> #DIV/0! | V43: g/cm3 | W43: =+W42*2 -> #DIV/0! | AC43: g/cm3 | AD43: =+AD42*2 -> #DIV/0!
B45: Fuentes | C45: Und | D45: Valor | E45: Incertidumbre Original | F45: Distribución | G45: Incertidumbre Estándar u(xi) | H45: Coeficiente de Sensibilidad | I45: Contribución ui(y) | K45: Valor | L45: Incertidumbre Original | M45: Distribución | N45: Incertidumbre Estándar u(xi) | O45: Coeficiente de Sensibilidad | P45: Contribución ui(y) | R45: Valor | S45: Incertidumbre Original | T45: Distribución | U45: Incertidumbre Estándar u(xi) | V45: Coeficiente de Sensibilidad | W45: Contribución ui(y) | Y45: Valor | Z45: Incertidumbre Original | AA45: Distribución | AB45: Incertidumbre Estándar u(xi) | AC45: Coeficiente de Sensibilidad | AD45: Contribución ui(y)
B46: Peso unitario seco in situ | C46: kN/m3 | D46: =+D47*9.8066 -> #DIV/0! | K46: =+K47*9.8066 -> #DIV/0! | R46: =+R47*9.8066 -> #DIV/0! | Y46: =+Y47*9.8066 -> #DIV/0!
A47: pd | B47: Densidad seca in situ | C47: g/cm3 | D47: =+D39 -> #DIV/0! | E47: --- | F47: --- | G47: =+I42 -> #DIV/0! | H47: 62.428 | I47: =+G47*H47 -> #DIV/0! | K47: =+K39 -> #DIV/0! | L47: --- | M47: --- | N47: =+P42 -> #DIV/0! | O47: 62.428 | P47: =+N47*O47 -> #DIV/0! | R47: =+R39 -> #DIV/0! | S47: --- | T47: --- | U47: =+W42 -> #DIV/0! | V47: 62.428 | W47: =+U47*V47 -> #DIV/0! | Y47: =+Y39 -> #DIV/0! | Z47: --- | AA47: --- | AB47: =+AD42 -> #DIV/0! | AC47: 62.428 | AD47: =+AB47*AC47 -> #DIV/0!
B48: Incertidumbre Estándar Combinada | I48: =SQRT(I47^2) -> #DIV/0! | P48: =SQRT(P47^2) -> #DIV/0! | W48: =SQRT(W47^2) -> #DIV/0! | AD48: =SQRT(AD47^2) -> #DIV/0!
B49: Incertidumbre Expandida, K = 2 | H49: kN/m3 | I49: =+I48*2 -> #DIV/0! | O49: kN/m3 | P49: =+P48*2 -> #DIV/0! | V49: kN/m3 | W49: =+W48*2 -> #DIV/0! | AC49: kN/m3 | AD49: =+AD48*2 -> #DIV/0!
...

Sheet Balanza
B1: CONO 1 | P1: CONO 2 | AD1: CONO 3 | AR1: CONO 4 | BF1: CONO 5
B6: CALIBRACION DE LA BALANZA | P6: CALIBRACION DE LA BALANZA | AD6: CALIBRACION DE LA BALANZA | AR6: CALIBRACION DE LA BALANZA | BF6: CALIBRACION DE LA BALANZA
B7: Correccion | C7: -3.42e-06 | P7: Correccion | Q7: 2.31e-05 | AD7: Correccion | AE7: -7.47e-06 | AR7: Correccion | AS7: -2.96e-06 | BF7: Correccion | BG7: -9.65e-06
B8: Variables | C8: 1.29 | D8: 8.8e-11 | P8: Variables | Q8: 0.691 | R8: 5.83e-10 | AD8: Variables | AE8: 1.3e-06 | AF8: 7.62e-11 | AR8: Variables | AS8: 0.17 | AT8: 3.81e-05 | BF8: Variables | BG8: 2.53e-07 | BH8: 1.25e-09
B9: Ecuacion | C9: 2*RAIZ(1,29+0.0000000000880xR2) | P9: Ecuacion | Q9: 2*RAIZ(0.691+0.000000000583xR2) | AD9: Ecuacion | AE9: 2*RAIZ(0.0000013+0.0000000000762xR2) | AR9: Ecuacion | AS9: 2*RAIZ(0.17+0.0000381xR2) | BF9: Ecuacion | BG9: 2*RAIZ(0.000000253+0.00000000125xR2)
B10: Resolucion | C10: 1 | P10: Resolucion | Q10: 1 | AD10: Resolucion | AE10: 1 | AR10: Resolucion | AS10: 1 | BF10: Resolucion | BG10: 1
B11: Codigo | C11: EQP-0108 | P11: Codigo | Q11: EQP-0093 | AD11: Codigo | AE11: EQP-0147 | AR11: Codigo | AS11: EQP-0133 | BF11: Codigo | BG11: EQP-0142
B12: Fecha calib. | C12: 46177 | P12: Fecha calib. | Q12: 46160 | AD12: Fecha calib. | AE12: 46086 | AR12: Fecha calib. | AS12: 45931 | BF12: Fecha calib. | BG12: 45981
B13: ITEM | C13: MES | D13: 500 | E13: 1000 | F13: 5000 | G13: 10000 | H13: 15000 | I13: 20000 | P13: ITEM | Q13: MES | R13: 500 | S13: 1000 | T13: 5000 | U13: 10000 | V13: 15000 | AD13: ITEM | AE13: MES | AF13: 500 | AG13: 1000 | AH13: 5000 | AI13: 10000 | AJ13: 15000 | AR13: ITEM | AS13: MES | AT13: 500 | AU13: 1000 | AV13: 5000 | AW13: 10000 | AX13: 15000 | BF13: ITEM | BG13: MES | BH13: 500 | BI13: 1000 | BJ13: 5000 | BK13: 10000 | BL13: 15000
C17: DESV STD | D17: 0 | E17: 0 | F17: 0 | G17: 0 | H17: 0 | I17: 0 | Q17: DESV STD | R17: 0 | S17: 0 | T17: 0 | U17: 0 | V17: 0 | AD17: =COUNT(AD14:AD15) -> 0 | AE17: DESV STD | AF17: =STDEV(AF14:AF15)/SQRT($B$17) -> #DIV/0! | AG17: =STDEV(AG14:AG15)/SQRT($B$17) -> #DIV/0! | AH17: =STDEV(AH14:AH15)/SQRT($B$17) -> #DIV/0! | AI17: =STDEV(AI14:AI15)/SQRT($B$17) -> #DIV/0! | AJ17: =STDEV(AJ14:AJ15)/SQRT($B$17) -> #DIV/0! | AR17: =COUNT(AR14:AR15) -> 0 | AS17: DESV STD | AT17: =STDEV(AT14:AT15)/SQRT($B$17) -> #DIV/0! | AU17: =STDEV(AU14:AU15)/SQRT($B$17) -> #DIV/0! | AV17: =STDEV(AV14:AV15)/SQRT($B$17) -> #DIV/0! | AW17: =STDEV(AW14:AW15)/SQRT($B$17) -> #DIV/0! | AX17: =STDEV(AX14:AX15)/SQRT($B$17) -> #DIV/0! | BF17: =COUNT(BF14:BF15) -> 0 | BG17: DESV STD | BH17: =STDEV(BH14:BH15)/SQRT($B$17) -> #DIV/0! | BI17: =STDEV(BI14:BI15)/SQRT($B$17) -> #DIV/0! | BJ17: =STDEV(BJ14:BJ15)/SQRT($B$17) -> #DIV/0! | BK17: =STDEV(BK14:BK15)/SQRT($B$17) -> #DIV/0! | BL17: =STDEV(BL14:BL15)/SQRT($B$17) -> #DIV/0!
D19: Busqueda de Repetibilidad de la masa | R19: Busqueda de Repetibilidad de la masa | AF19: Busqueda de Repetibilidad de la masa | AT19: Busqueda de Repetibilidad de la masa | BH19: Busqueda de Repetibilidad de la masa
D21: =+D13 -> 500 | E21: =+E13 -> 1000 | F21: =+F13 -> 5000 | G21: =+G13 -> 10000 | H21: =+H13 -> 15000 | I21: 20000 | R21: =+R13 -> 500 | S21: =+S13 -> 1000 | T21: =+T13 -> 5000 | U21: =+U13 -> 10000 | V21: =+V13 -> 15000 | AF21: =+AF13 -> 500 | AG21: =+AG13 -> 1000 | AH21: =+AH13 -> 5000 | AI21: =+AI13 -> 10000 | AJ21: =+AJ13 -> 15000 | AT21: =+AT13 -> 500 | AU21: =+AU13 -> 1000 | AV21: =+AV13 -> 5000 | AW21: =+AW13 -> 10000 | AX21: =+AX13 -> 15000 | BH21: =+BH13 -> 500 | BI21: =+BI13 -> 1000 | BJ21: =+BJ13 -> 5000 | BK21: =+BK13 -> 10000 | BL21: =+BL13 -> 15000
D22: =D17 -> 0 | E22: =E17 -> 0 | F22: =F17 -> 0 | G22: =G17 -> 0 | H22: =H17 -> 0 | I22: =I17 -> 0 | R22: =R17 -> 0 | S22: =S17 -> 0 | T22: =T17 -> 0 | U22: =U17 -> 0 | V22: =V17 -> 0 | AF22: =AF17 -> #DIV/0! | AG22: =AG17 -> #DIV/0! | AH22: =AH17 -> #DIV/0! | AI22: =AI17 -> #DIV/0! | AJ22: =AJ17 -> #DIV/0! | AT22: =AT17 -> #DIV/0! | AU22: =AU17 -> #DIV/0! | AV22: =AV17 -> #DIV/0! | AW22: =AW17 -> #DIV/0! | AX22: =AX17 -> #DIV/0! | BH22: =BH17 -> #DIV/0! | BI22: =BI17 -> #DIV/0! | BJ22: =BJ17 -> #DIV/0! | BK22: =BK17 -> #DIV/0! | BL22: =BL17 -> #DIV/0!
B24: DESCRIPCION | G24: PRUEBA 1 | I24: PRUEBA 2 | K24: PRUEBA 3 | M24: PRUEBA 4 | P24: DESCRIPCION | U24: PRUEBA 1 | W24: PRUEBA 2 | Y24: PRUEBA 3 | AA24: PRUEBA 4 | AD24: DESCRIPCION | AI24: PRUEBA 1 | AK24: PRUEBA 2 | AM24: PRUEBA 3 | AO24: PRUEBA 4 | AR24: DESCRIPCION | AW24: PRUEBA 1 | AY24: PRUEBA 2 | BA24: PRUEBA 3 | BC24: PRUEBA 4 | BF24: DESCRIPCION | BK24: PRUEBA 1 | BM24: PRUEBA 2 | BO24: PRUEBA 3 | BQ24: PRUEBA 4
B25: M3 | C25: Masa húmeda de material del orificio de prueba | F25: g | G25: =+Datos!$F$28 -> 0 | H25: =IF(G25<=$D$21,$D$22,IF(AND(G25>$D$21,G25<=$E$21),$E$22,IF(AND(G25>$E$21,G25<=$F$21),$F$22,IF(AND(G25>$F$21,G25<=$G$21),$G$22,IF(AND(G25>$G$21,G25<=$H$21),$H$22,$H$22))))) -> 0 | I25: =+Datos!$H$28 -> 0 | J25: =IF(I25<=$D$21,$D$22,IF(AND(I25>$D$21,I25<=$E$21),$E$22,IF(AND(I25>$E$21,I25<=$F$21),$F$22,IF(AND(I25>$F$21,I25<=$G$21),$G$22,IF(AND(I25>$G$21,I25<=$H$21),$H$22,$H$22))))) -> 0 | K25: =+Datos!$J$28 -> 0 | L25: =IF(K25<=$D$21,$D$22,IF(AND(K25>$D$21,K25<=$E$21),$E$22,IF(AND(K25>$E$21,K25<=$F$21),$F$22,IF(AND(K25>$F$21,K25<=$G$21),$G$22,IF(AND(K25>$G$21,K25<=$H$21),$H$22,$H$22))))) -> 0 | M25: =+Datos!$L$28 -> 0 | N25: =IF(M25<=$D$21,$D$22,IF(AND(M25>$D$21,M25<=$E$21),$E$22,IF(AND(M25>$E$21,M25<=$F$21),$F$22,IF(AND(M25>$F$21,M25<=$G$21),$G$22,IF(AND(M25>$G$21,M25<=$H$21),$H$22,$H$22))))) -> 0 | P25: M3 | Q25: Masa húmeda de material del orificio de prueba | T25: g | U25: =+Datos!$F$28 -> 0 | V25: =IF(U25<=$R$21,$R$22,IF(AND(U25>$R$21,U25<=$S$21),$S$22,IF(AND(U25>$S$21,U25<=$T$21),$T$22,IF(AND(U25>$T$21,U25<=$U$21),$U$22,IF(AND(U25>$U$21,U25<=$V$21),$V$22,$V$22))))) -> 0 | W25: =+Datos!$H$28 -> 0 | X25: =IF(W25<=$R$21,$R$22,IF(AND(W25>$R$21,W25<=$S$21),$S$22,IF(AND(W25>$S$21,W25<=$T$21),$T$22,IF(AND(W25>$T$21,W25<=$U$21),$U$22,IF(AND(W25>$U$21,W25<=$V$21),$V$22,$V$22))))) -> 0 | Y25: =+Datos!$J$28 -> 0 | Z25: =IF(Y25<=$R$21,$R$22,IF(AND(Y25>$R$21,Y25<=$S$21),$S$22,IF(AND(Y25>$S$21,Y25<=$T$21),$T$22,IF(AND(Y25>$T$21,Y25<=$U$21),$U$22,IF(AND(Y25>$U$21,Y25<=$V$21),$V$22,$V$22))))) -> 0 | AA25: =+Datos!$L$28 -> 0 | AB25: =IF(AA25<=$R$21,$R$22,IF(AND(AA25>$R$21,AA25<=$S$21),$S$22,IF(AND(AA25>$S$21,AA25<=$T$21),$T$22,IF(AND(AA25>$T$21,AA25<=$U$21),$U$22,IF(AND(AA25>$U$21,AA25<=$V$21),$V$22,$V$22))))) -> 0 | AD25: M3 | AE25: Masa húmeda de material del orificio de prueba | AH25: g | AI25: =+Datos!$F$28 -> 0 | AJ25: =IF(AI25<=$R$21,$R$22,IF(AND(AI25>$R$21,AI25<=$S$21),$S$22,IF(AND(AI25>$S$21,AI25<=$T$21),$T$22,IF(AND(AI25>$T$21,AI25<=$U$21),$U$22,IF(AND(AI25>$U$21,AI25<=$V$21),$V$22,$V$22))))) -> 0 | AK25: =+Datos!$H$28 -> 0 | AL25: =IF(AK25<=$R$21,$R$22,IF(AND(AK25>$R$21,AK25<=$S$21),$S$22,IF(AND(AK25>$S$21,AK25<=$T$21),$T$22,IF(AND(AK25>$T$21,AK25<=$U$21),$U$22,IF(AND(AK25>$U$21,AK25<=$V$21),$V$22,$V$22))))) -> 0 | AM25: =+Datos!$J$28 -> 0 | AN25: =IF(AM25<=$R$21,$R$22,IF(AND(AM25>$R$21,AM25<=$S$21),$S$22,IF(AND(AM25>$S$21,AM25<=$T$21),$T$22,IF(AND(AM25>$T$21,AM25<=$U$21),$U$22,IF(AND(AM25>$U$21,AM25<=$V$21),$V$22,$V$22))))) -> 0 | AO25: =+Datos!$L$28 -> 0 | AP25: =IF(AO25<=$R$21,$R$22,IF(AND(AO25>$R$21,AO25<=$S$21),$S$22,IF(AND(AO25>$S$21,AO25<=$T$21),$T$22,IF(AND(AO25>$T$21,AO25<=$U$21),$U$22,IF(AND(AO25>$U$21,AO25<=$V$21),$V$22,$V$22))))) -> 0 | AR25: M3 | AS25: Masa húmeda de material del orificio de prueba | AV25: g | AW25: =+Datos!$F$28 -> 0 | AX25: =IF(AW25<=$R$21,$R$22,IF(AND(AW25>$R$21,AW25<=$S$21),$S$22,IF(AND(AW25>$S$21,AW25<=$T$21),$T$22,IF(AND(AW25>$T$21,AW25<=$U$21),$U$22,IF(AND(AW25>$U$21,AW25<=$V$21),$V$22,$V$22))))) -> 0 | AY25: =+Datos!$H$28 -> 0 | AZ25: =IF(AY25<=$R$21,$R$22,IF(AND(AY25>$R$21,AY25<=$S$21),$S$22,IF(AND(AY25>$S$21,AY25<=$T$21),$T$22,IF(AND(AY25>$T$21,AY25<=$U$21),$U$22,IF(AND(AY25>$U$21,AY25<=$V$21),$V$22,$V$22))))) -> 0 | BA25: =+Datos!$J$28 -> 0 | BB25: =IF(BA25<=$R$21,$R$22,IF(AND(BA25>$R$21,BA25<=$S$21),$S$22,IF(AND(BA25>$S$21,BA25<=$T$21),$T$22,IF(AND(BA25>$T$21,BA25<=$U$21),$U$22,IF(AND(BA25>$U$21,BA25<=$V$21),$V$22,$V$22))))) -> 0 | BC25: =+Datos!$L$28 -> 0 | BD25: =IF(BC25<=$R$21,$R$22,IF(AND(BC25>$R$21,BC25<=$S$21),$S$22,IF(AND(BC25>$S$21,BC25<=$T$21),$T$22,IF(AND(BC25>$T$21,BC25<=$U$21),$U$22,IF(AND(BC25>$U$21,BC25<=$V$21),$V$22,$V$22))))) -> 0 | BF25: M3 | BG25: Masa húmeda de material del orificio de prueba | BJ25: g | BK25: =+Datos!$F$28 -> 0 | BL25: =IF(BK25<=$R$21,$R$22,IF(AND(BK25>$R$21,BK25<=$S$21),$S$22,IF(AND(BK25>$S$21,BK25<=$T$21),$T$22,IF(AND(BK25>$T$21,BK25<=$U$21),$U$22,IF(AND(BK25>$U$21,BK25<=$V$21),$V$22,$V$22))))) -> 0 | BM25: =+Datos!$H$28 -> 0 | BN25: =IF(BM25<=$R$21,$R$22,IF(AND(BM25>$R$21,BM25<=$S$21),$S$22,IF(AND(BM25>$S$21,BM25<=$T$21),$T$22,IF(AND(BM25>$T$21,BM25<=$U$21),$U$22,IF(AND(BM25>$U$21,BM25<=$V$21),$V$22,$V$22))))) -> 0 | BO25: =+Datos!$J$28 -> 0 | BP25: =IF(BO25<=$R$21,$R$22,IF(AND(BO25>$R$21,BO25<=$S$21),$S$22,IF(AND(BO25>$S$21,BO25<=$T$21),$T$22,IF(AND(BO25>$T$21,BO25<=$U$21),$U$22,IF(AND(BO25>$U$21,BO25<=$V$21),$V$22,$V$22))))) -> 0 | BQ25: =+Datos!$L$28 -> 0 | BR25: =IF(BQ25<=$R$21,$R$22,IF(AND(BQ25>$R$21,BQ25<=$S$21),$S$22,IF(AND(BQ25>$S$21,BQ25<=$T$21),$T$22,IF(AND(BQ25>$T$21,BQ25<=$U$21),$U$22,IF(AND(BQ25>$U$21,BQ25<=$V$21),$V$22,$V$22))))) -> 0
B26: A | C26: Masa inicial del cono mas arena | F26: g | G26: =+Datos!$F$22 -> 0 | H26: =IF(G26<=$D$21,$D$22,IF(AND(G26>$D$21,G26<=$E$21),$E$22,IF(AND(G26>$E$21,G26<=$F$21),$F$22,IF(AND(G26>$F$21,G26<=$G$21),$G$22,IF(AND(G26>$G$21,G26<=$H$21),$H$22,$H$22))))) -> 0 | I26: =+Datos!$H$22 -> 0 | J26: =IF(I26<=$D$21,$D$22,IF(AND(I26>$D$21,I26<=$E$21),$E$22,IF(AND(I26>$E$21,I26<=$F$21),$F$22,IF(AND(I26>$F$21,I26<=$G$21),$G$22,IF(AND(I26>$G$21,I26<=$H$21),$H$22,$H$22))))) -> 0 | K26: =+Datos!$J$22 -> 0 | L26: =IF(K26<=$D$21,$D$22,IF(AND(K26>$D$21,K26<=$E$21),$E$22,IF(AND(K26>$E$21,K26<=$F$21),$F$22,IF(AND(K26>$F$21,K26<=$G$21),$G$22,IF(AND(K26>$G$21,K26<=$H$21),$H$22,$H$22))))) -> 0 | M26: =+Datos!$L$22 -> 0 | N26: =IF(M26<=$D$21,$D$22,IF(AND(M26>$D$21,M26<=$E$21),$E$22,IF(AND(M26>$E$21,M26<=$F$21),$F$22,IF(AND(M26>$F$21,M26<=$G$21),$G$22,IF(AND(M26>$G$21,M26<=$H$21),$H$22,$H$22))))) -> 0 | P26: A | Q26: Masa inicial del cono mas arena | T26: g | U26: =+Datos!$F$22 -> 0 | V26: =IF(U26<=$R$21,$R$22,IF(AND(U26>$R$21,U26<=$S$21),$S$22,IF(AND(U26>$S$21,U26<=$T$21),$T$22,IF(AND(U26>$T$21,U26<=$U$21),$U$22,IF(AND(U26>$U$21,U26<=$V$21),$V$22,$V$22))))) -> 0 | W26: =+Datos!$H$22 -> 0 | X26: =IF(W26<=$R$21,$R$22,IF(AND(W26>$R$21,W26<=$S$21),$S$22,IF(AND(W26>$S$21,W26<=$T$21),$T$22,IF(AND(W26>$T$21,W26<=$U$21),$U$22,IF(AND(W26>$U$21,W26<=$V$21),$V$22,$V$22))))) -> 0 | Y26: =+Datos!$J$22 -> 0 | Z26: =IF(Y26<=$R$21,$R$22,IF(AND(Y26>$R$21,Y26<=$S$21),$S$22,IF(AND(Y26>$S$21,Y26<=$T$21),$T$22,IF(AND(Y26>$T$21,Y26<=$U$21),$U$22,IF(AND(Y26>$U$21,Y26<=$V$21),$V$22,$V$22))))) -> 0 | AA26: =+Datos!$L$22 -> 0 | AB26: =IF(AA26<=$R$21,$R$22,IF(AND(AA26>$R$21,AA26<=$S$21),$S$22,IF(AND(AA26>$S$21,AA26<=$T$21),$T$22,IF(AND(AA26>$T$21,AA26<=$U$21),$U$22,IF(AND(AA26>$U$21,AA26<=$V$21),$V$22,$V$22))))) -> 0 | AD26: A | AE26: Masa inicial del cono mas arena | AH26: g | AI26: =+Datos!$F$22 -> 0 | AJ26: =IF(AI26<=$R$21,$R$22,IF(AND(AI26>$R$21,AI26<=$S$21),$S$22,IF(AND(AI26>$S$21,AI26<=$T$21),$T$22,IF(AND(AI26>$T$21,AI26<=$U$21),$U$22,IF(AND(AI26>$U$21,AI26<=$V$21),$V$22,$V$22))))) -> 0 | AK26: =+Datos!$H$22 -> 0 | AL26: =IF(AK26<=$R$21,$R$22,IF(AND(AK26>$R$21,AK26<=$S$21),$S$22,IF(AND(AK26>$S$21,AK26<=$T$21),$T$22,IF(AND(AK26>$T$21,AK26<=$U$21),$U$22,IF(AND(AK26>$U$21,AK26<=$V$21),$V$22,$V$22))))) -> 0 | AM26: =+Datos!$J$22 -> 0 | AN26: =IF(AM26<=$R$21,$R$22,IF(AND(AM26>$R$21,AM26<=$S$21),$S$22,IF(AND(AM26>$S$21,AM26<=$T$21),$T$22,IF(AND(AM26>$T$21,AM26<=$U$21),$U$22,IF(AND(AM26>$U$21,AM26<=$V$21),$V$22,$V$22))))) -> 0 | AO26: =+Datos!$L$22 -> 0 | AP26: =IF(AO26<=$R$21,$R$22,IF(AND(AO26>$R$21,AO26<=$S$21),$S$22,IF(AND(AO26>$S$21,AO26<=$T$21),$T$22,IF(AND(AO26>$T$21,AO26<=$U$21),$U$22,IF(AND(AO26>$U$21,AO26<=$V$21),$V$22,$V$22))))) -> 0 | AR26: A | AS26: Masa inicial del cono mas arena | AV26: g | AW26: =+Datos!$F$22 -> 0 | AX26: =IF(AW26<=$R$21,$R$22,IF(AND(AW26>$R$21,AW26<=$S$21),$S$22,IF(AND(AW26>$S$21,AW26<=$T$21),$T$22,IF(AND(AW26>$T$21,AW26<=$U$21),$U$22,IF(AND(AW26>$U$21,AW26<=$V$21),$V$22,$V$22))))) -> 0 | AY26: =+Datos!$H$22 -> 0 | AZ26: =IF(AY26<=$R$21,$R$22,IF(AND(AY26>$R$21,AY26<=$S$21),$S$22,IF(AND(AY26>$S$21,AY26<=$T$21),$T$22,IF(AND(AY26>$T$21,AY26<=$U$21),$U$22,IF(AND(AY26>$U$21,AY26<=$V$21),$V$22,$V$22))))) -> 0 | BA26: =+Datos!$J$22 -> 0 | BB26: =IF(BA26<=$R$21,$R$22,IF(AND(BA26>$R$21,BA26<=$S$21),$S$22,IF(AND(BA26>$S$21,BA26<=$T$21),$T$22,IF(AND(BA26>$T$21,BA26<=$U$21),$U$22,IF(AND(BA26>$U$21,BA26<=$V$21),$V$22,$V$22))))) -> 0 | BC26: =+Datos!$L$22 -> 0 | BD26: =IF(BC26<=$R$21,$R$22,IF(AND(BC26>$R$21,BC26<=$S$21),$S$22,IF(AND(BC26>$S$21,BC26<=$T$21),$T$22,IF(AND(BC26>$T$21,BC26<=$U$21),$U$22,IF(AND(BC26>$U$21,BC26<=$V$21),$V$22,$V$22))))) -> 0 | BF26: A | BG26: Masa inicial del cono mas arena | BJ26: g | BK26: =+Datos!$F$22 -> 0 | BL26: =IF(BK26<=$R$21,$R$22,IF(AND(BK26>$R$21,BK26<=$S$21),$S$22,IF(AND(BK26>$S$21,BK26<=$T$21),$T$22,IF(AND(BK26>$T$21,BK26<=$U$21),$U$22,IF(AND(BK26>$U$21,BK26<=$V$21),$V$22,$V$22))))) -> 0 | BM26: =+Datos!$H$22 -> 0 | BN26: =IF(BM26<=$R$21,$R$22,IF(AND(BM26>$R$21,BM26<=$S$21),$S$22,IF(AND(BM26>$S$21,BM26<=$T$21),$T$22,IF(AND(BM26>$T$21,BM26<=$U$21),$U$22,IF(AND(BM26>$U$21,BM26<=$V$21),$V$22,$V$22))))) -> 0 | BO26: =+Datos!$J$22 -> 0 | BP26: =IF(BO26<=$R$21,$R$22,IF(AND(BO26>$R$21,BO26<=$S$21),$S$22,IF(AND(BO26>$S$21,BO26<=$T$21),$T$22,IF(AND(BO26>$T$21,BO26<=$U$21),$U$22,IF(AND(BO26>$U$21,BO26<=$V$21),$V$22,$V$22))))) -> 0 | BQ26: =+Datos!$L$22 -> 0 | BR26: =IF(BQ26<=$R$21,$R$22,IF(AND(BQ26>$R$21,BQ26<=$S$21),$S$22,IF(AND(BQ26>$S$21,BQ26<=$T$21),$T$22,IF(AND(BQ26>$T$21,BQ26<=$U$21),$U$22,IF(AND(BQ26>$U$21,BQ26<=$V$21),$V$22,$V$22))))) -> 0
B27: B | C27: Masa Residual de arena | F27: g | G27: =+Datos!$F$23 -> 0 | H27: =IF(G27<=$D$21,$D$22,IF(AND(G27>$D$21,G27<=$E$21),$E$22,IF(AND(G27>$E$21,G27<=$F$21),$F$22,IF(AND(G27>$F$21,G27<=$G$21),$G$22,IF(AND(G27>$G$21,G27<=$H$21),$H$22,$H$22))))) -> 0 | I27: =+Datos!$G$23 -> 0 | J27: =IF(I27<=$D$21,$D$22,IF(AND(I27>$D$21,I27<=$E$21),$E$22,IF(AND(I27>$E$21,I27<=$F$21),$F$22,IF(AND(I27>$F$21,I27<=$G$21),$G$22,IF(AND(I27>$G$21,I27<=$H$21),$H$22,$H$22))))) -> 0 | K27: =+Datos!$J$23 -> 0 | L27: =IF(K27<=$D$21,$D$22,IF(AND(K27>$D$21,K27<=$E$21),$E$22,IF(AND(K27>$E$21,K27<=$F$21),$F$22,IF(AND(K27>$F$21,K27<=$G$21),$G$22,IF(AND(K27>$G$21,K27<=$H$21),$H$22,$H$22))))) -> 0 | M27: =+Datos!$L$23 -> 0 | N27: =IF(M27<=$D$21,$D$22,IF(AND(M27>$D$21,M27<=$E$21),$E$22,IF(AND(M27>$E$21,M27<=$F$21),$F$22,IF(AND(M27>$F$21,M27<=$G$21),$G$22,IF(AND(M27>$G$21,M27<=$H$21),$H$22,$H$22))))) -> 0 | P27: B | Q27: Masa Residual de arena | T27: g | U27: =+Datos!$F$23 -> 0 | V27: =IF(U27<=$R$21,$R$22,IF(AND(U27>$R$21,U27<=$S$21),$S$22,IF(AND(U27>$S$21,U27<=$T$21),$T$22,IF(AND(U27>$T$21,U27<=$U$21),$U$22,IF(AND(U27>$U$21,U27<=$V$21),$V$22,$V$22))))) -> 0 | W27: =+Datos!$G$23 -> 0 | X27: =IF(W27<=$R$21,$R$22,IF(AND(W27>$R$21,W27<=$S$21),$S$22,IF(AND(W27>$S$21,W27<=$T$21),$T$22,IF(AND(W27>$T$21,W27<=$U$21),$U$22,IF(AND(W27>$U$21,W27<=$V$21),$V$22,$V$22))))) -> 0 | Y27: =+Datos!$J$23 -> 0 | Z27: =IF(Y27<=$R$21,$R$22,IF(AND(Y27>$R$21,Y27<=$S$21),$S$22,IF(AND(Y27>$S$21,Y27<=$T$21),$T$22,IF(AND(Y27>$T$21,Y27<=$U$21),$U$22,IF(AND(Y27>$U$21,Y27<=$V$21),$V$22,$V$22))))) -> 0 | AA27: =+Datos!$L$23 -> 0 | AB27: =IF(AA27<=$R$21,$R$22,IF(AND(AA27>$R$21,AA27<=$S$21),$S$22,IF(AND(AA27>$S$21,AA27<=$T$21),$T$22,IF(AND(AA27>$T$21,AA27<=$U$21),$U$22,IF(AND(AA27>$U$21,AA27<=$V$21),$V$22,$V$22))))) -> 0 | AD27: B | AE27: Masa Residual de arena | AH27: g | AI27: =+Datos!$F$23 -> 0 | AJ27: =IF(AI27<=$R$21,$R$22,IF(AND(AI27>$R$21,AI27<=$S$21),$S$22,IF(AND(AI27>$S$21,AI27<=$T$21),$T$22,IF(AND(AI27>$T$21,AI27<=$U$21),$U$22,IF(AND(AI27>$U$21,AI27<=$V$21),$V$22,$V$22))))) -> 0 | AK27: =+Datos!$G$23 -> 0 | AL27: =IF(AK27<=$R$21,$R$22,IF(AND(AK27>$R$21,AK27<=$S$21),$S$22,IF(AND(AK27>$S$21,AK27<=$T$21),$T$22,IF(AND(AK27>$T$21,AK27<=$U$21),$U$22,IF(AND(AK27>$U$21,AK27<=$V$21),$V$22,$V$22))))) -> 0 | AM27: =+Datos!$J$23 -> 0 | AN27: =IF(AM27<=$R$21,$R$22,IF(AND(AM27>$R$21,AM27<=$S$21),$S$22,IF(AND(AM27>$S$21,AM27<=$T$21),$T$22,IF(AND(AM27>$T$21,AM27<=$U$21),$U$22,IF(AND(AM27>$U$21,AM27<=$V$21),$V$22,$V$22))))) -> 0 | AO27: =+Datos!$L$23 -> 0 | AP27: =IF(AO27<=$R$21,$R$22,IF(AND(AO27>$R$21,AO27<=$S$21),$S$22,IF(AND(AO27>$S$21,AO27<=$T$21),$T$22,IF(AND(AO27>$T$21,AO27<=$U$21),$U$22,IF(AND(AO27>$U$21,AO27<=$V$21),$V$22,$V$22))))) -> 0 | AR27: B | AS27: Masa Residual de arena | AV27: g | AW27: =+Datos!$F$23 -> 0 | AX27: =IF(AW27<=$R$21,$R$22,IF(AND(AW27>$R$21,AW27<=$S$21),$S$22,IF(AND(AW27>$S$21,AW27<=$T$21),$T$22,IF(AND(AW27>$T$21,AW27<=$U$21),$U$22,IF(AND(AW27>$U$21,AW27<=$V$21),$V$22,$V$22))))) -> 0 | AY27: =+Datos!$G$23 -> 0 | AZ27: =IF(AY27<=$R$21,$R$22,IF(AND(AY27>$R$21,AY27<=$S$21),$S$22,IF(AND(AY27>$S$21,AY27<=$T$21),$T$22,IF(AND(AY27>$T$21,AY27<=$U$21),$U$22,IF(AND(AY27>$U$21,AY27<=$V$21),$V$22,$V$22))))) -> 0 | BA27: =+Datos!$J$23 -> 0 | BB27: =IF(BA27<=$R$21,$R$22,IF(AND(BA27>$R$21,BA27<=$S$21),$S$22,IF(AND(BA27>$S$21,BA27<=$T$21),$T$22,IF(AND(BA27>$T$21,BA27<=$U$21),$U$22,IF(AND(BA27>$U$21,BA27<=$V$21),$V$22,$V$22))))) -> 0 | BC27: =+Datos!$L$23 -> 0 | BD27: =IF(BC27<=$R$21,$R$22,IF(AND(BC27>$R$21,BC27<=$S$21),$S$22,IF(AND(BC27>$S$21,BC27<=$T$21),$T$22,IF(AND(BC27>$T$21,BC27<=$U$21),$U$22,IF(AND(BC27>$U$21,BC27<=$V$21),$V$22,$V$22))))) -> 0 | BF27: B | BG27: Masa Residual de arena | BJ27: g | BK27: =+Datos!$F$23 -> 0 | BL27: =IF(BK27<=$R$21,$R$22,IF(AND(BK27>$R$21,BK27<=$S$21),$S$22,IF(AND(BK27>$S$21,BK27<=$T$21),$T$22,IF(AND(BK27>$T$21,BK27<=$U$21),$U$22,IF(AND(BK27>$U$21,BK27<=$V$21),$V$22,$V$22))))) -> 0 | BM27: =+Datos!$G$23 -> 0 | BN27: =IF(BM27<=$R$21,$R$22,IF(AND(BM27>$R$21,BM27<=$S$21),$S$22,IF(AND(BM27>$S$21,BM27<=$T$21),$T$22,IF(AND(BM27>$T$21,BM27<=$U$21),$U$22,IF(AND(BM27>$U$21,BM27<=$V$21),$V$22,$V$22))))) -> 0 | BO27: =+Datos!$J$23 -> 0 | BP27: =IF(BO27<=$R$21,$R$22,IF(AND(BO27>$R$21,BO27<=$S$21),$S$22,IF(AND(BO27>$S$21,BO27<=$T$21),$T$22,IF(AND(BO27>$T$21,BO27<=$U$21),$U$22,IF(AND(BO27>$U$21,BO27<=$V$21),$V$22,$V$22))))) -> 0 | BQ27: =+Datos!$L$23 -> 0 | BR27: =IF(BQ27<=$R$21,$R$22,IF(AND(BQ27>$R$21,BQ27<=$S$21),$S$22,IF(AND(BQ27>$S$21,BQ27<=$T$21),$T$22,IF(AND(BQ27>$T$21,BQ27<=$U$21),$U$22,IF(AND(BQ27>$U$21,BQ27<=$V$21),$V$22,$V$22))))) -> 0
B28: M2 | C28: Masa de arena utilizada para llenar el embudo y la placa base (g) | F28: g | G28: =+Datos!$I$5 -> 0 | H28: =IF(G28<=$D$21,$D$22,IF(AND(G28>$D$21,G28<=$E$21),$E$22,IF(AND(G28>$E$21,G28<=$F$21),$F$22,IF(AND(G28>$F$21,G28<=$G$21),$G$22,IF(AND(G28>$G$21,G28<=$H$21),$H$22,$H$22))))) -> 0 | P28: M2 | Q28: Masa de arena utilizada para llenar el embudo y la placa base (g) | T28: g | U28: =+Datos!$I$5 -> 0 | V28: =IF(U28<=$R$21,$R$22,IF(AND(U28>$R$21,U28<=$S$21),$S$22,IF(AND(U28>$S$21,U28<=$T$21),$T$22,IF(AND(U28>$T$21,U28<=$U$21),$U$22,IF(AND(U28>$U$21,U28<=$V$21),$V$22,$V$22))))) -> 0 | AD28: M2 | AE28: Masa de arena utilizada para llenar el embudo y la placa base (g) | AH28: g | AI28: =+Datos!$I$5 -> 0 | AJ28: =IF(AI28<=$R$21,$R$22,IF(AND(AI28>$R$21,AI28<=$S$21),$S$22,IF(AND(AI28>$S$21,AI28<=$T$21),$T$22,IF(AND(AI28>$T$21,AI28<=$U$21),$U$22,IF(AND(AI28>$U$21,AI28<=$V$21),$V$22,$V$22))))) -> 0 | AR28: M2 | AS28: Masa de arena utilizada para llenar el embudo y la placa base (g) | AV28: g | AW28: =+Datos!$I$5 -> 0 | AX28: =IF(AW28<=$R$21,$R$22,IF(AND(AW28>$R$21,AW28<=$S$21),$S$22,IF(AND(AW28>$S$21,AW28<=$T$21),$T$22,IF(AND(AW28>$T$21,AW28<=$U$21),$U$22,IF(AND(AW28>$U$21,AW28<=$V$21),$V$22,$V$22))))) -> 0 | BF28: M2 | BG28: Masa de arena utilizada para llenar el embudo y la placa base (g) | BJ28: g | BK28: =+Datos!$I$5 -> 0 | BL28: =IF(BK28<=$R$21,$R$22,IF(AND(BK28>$R$21,BK28<=$S$21),$S$22,IF(AND(BK28>$S$21,BK28<=$T$21),$T$22,IF(AND(BK28>$T$21,BK28<=$U$21),$U$22,IF(AND(BK28>$U$21,BK28<=$V$21),$V$22,$V$22))))) -> 0

Sheet Precision
A3: Factor de precision DENSIDAD
A4: Fecha de evaluacion: | B4: 45955
A6: Desviacion Estándar Repetibilidad (Sr) | B6: 0.00289
A7: Desviacion Estándar Reproducibilidad (SR) | B7: 0.01053

Sheet Hoja1
A2: CODIGO | C2: CONCATENADOS | D2: DESCRIPCION | E2: FC | F2: F. MOLDEO | G2: DIA | H2: DIAMETRO | I2: CARGA | J2: AREA | K2: RESIS. CONCRETO | L2: % RESIS | M2: TIPO DE FALLA
A3: 4400 | B3: =+A3+1 -> 4401 | C3: =A3&"-"&B3 -> 4400-4401 | D3: Columnas C-9;5-3/G.H | E3: 350 | F3: 42347 | G3: 7 | H3: 15.05 | I3: 49900 | J3: =H3*H3*PI()/4 -> 177.89465 | K3: =I3/J3 -> 280.5031 | L3: =+K3/E3 -> 0.80143743 | M3: E
C4: =A4&"-"&B4 -> - | E4: 350 | G4: 7 | H4: 15.06 | I4: 50310 | J4: =H4*H4*PI()/4 -> 178.13113 | K4: =I4/J4 -> 282.43238 | L4: =+K4/E4 -> 0.80694967 | M4: F
A5: =+B3+1 -> 4402 | B5: =+A5+1 -> 4403 | C5: =A5&"-"&B5 -> 4402-4403 | E5: 350 | G5: 14 | H5: 15.04 | I5: 56450 | J5: =H5*H5*PI()/4 -> 177.65832 | K5: =I5/J5 -> 317.74476 | L5: =+K5/E5 -> 0.90784216 | M5: F
C6: =A6&"-"&B6 -> - | E6: 350 | G6: 14 | H6: 15 | I6: 59630 | J6: =H6*H6*PI()/4 -> 176.71459 | K6: =I6/J6 -> 337.43677 | L6: =+K6/E6 -> 0.96410507 | M6: F
A7: =+B5+1 -> 4404 | B7: =+A7+1 -> 4405 | C7: =A7&"-"&B7 -> 4404-4405 | E7: 350 | G7: 28 | H7: 15.11 | I7: 65310 | J7: =H7*H7*PI()/4 -> 179.3159 | K7: =I7/J7 -> 364.21755 | L7: =+K7/E7 -> 1.0406216 | M7: F
C8: =A8&"-"&B8 -> - | E8: 350 | G8: 28 | H8: 15.05 | I8: 64730 | J8: =H8*H8*PI()/4 -> 177.89465 | K8: =I8/J8 -> 363.86705 | L8: =+K8/E8 -> 1.0396201 | M8: E
